2014-05-05 11:20:13,063 INFO org.apache.hadoop.yarn.server.resourcemanager.ResourceManager: STARTUP_MSG: 
/************************************************************
STARTUP_MSG: Starting ResourceManager
STARTUP_MSG:   host = ip-10-0-0-195/10.0.0.195
STARTUP_MSG:   args = []
STARTUP_MSG:   version = 2.2.0
STARTUP_MSG:   build = Unknown -r Unknown; compiled by 'root' on 2014-05-04T05:58Z
STARTUP_MSG:   java = 1.7.0_51
************************************************************/
2014-05-05 11:20:13,077 INFO org.apache.hadoop.yarn.server.resourcemanager.ResourceManager: registered UNIX signal handlers for [TERM, HUP, INT]
2014-05-05 11:20:13,408 INFO org.apache.hadoop.yarn.server.resourcemanager.security.AMRMTokenSecretManager: Rolling master-key for amrm-tokens
2014-05-05 11:20:13,439 INFO org.apache.hadoop.yarn.server.resourcemanager.security.RMContainerTokenSecretManager: ContainerTokenKeyRollingInterval: 86400000ms and ContainerTokenKeyActivationDelay: 900000ms
2014-05-05 11:20:13,443 INFO org.apache.hadoop.yarn.server.resourcemanager.security.NMTokenSecretManagerInRM: NMTokenKeyRollingInterval: 86400000ms and NMTokenKeyActivationDelay: 900000ms
2014-05-05 11:20:13,450 INFO org.apache.hadoop.yarn.event.AsyncDispatcher: Registering class org.apache.hadoop.yarn.server.resourcemanager.recovery.RMStateStoreEventType for class org.apache.hadoop.yarn.server.resourcemanager.recovery.RMStateStore$ForwardingEventHandler
2014-05-05 11:20:13,957 WARN org.apache.hadoop.util.NativeCodeLoader: Unable to load native-hadoop library for your platform... using builtin-java classes where applicable
2014-05-05 11:20:14,244 INFO org.apache.hadoop.yarn.event.AsyncDispatcher: Registering class org.apache.hadoop.yarn.server.resourcemanager.NodesListManagerEventType for class org.apache.hadoop.yarn.server.resourcemanager.NodesListManager
2014-05-05 11:20:14,430 INFO org.apache.hadoop.yarn.server.resourcemanager.ResourceManager: Using Scheduler: org.apache.hadoop.yarn.server.resourcemanager.scheduler.capacity.CapacityScheduler
2014-05-05 11:20:14,714 INFO org.apache.hadoop.yarn.event.AsyncDispatcher: Registering class org.apache.hadoop.yarn.server.resourcemanager.scheduler.event.SchedulerEventType for class org.apache.hadoop.yarn.server.resourcemanager.ResourceManager$SchedulerEventDispatcher
2014-05-05 11:20:14,724 INFO org.apache.hadoop.yarn.event.AsyncDispatcher: Registering class org.apache.hadoop.yarn.server.resourcemanager.rmapp.RMAppEventType for class org.apache.hadoop.yarn.server.resourcemanager.ResourceManager$ApplicationEventDispatcher
2014-05-05 11:20:14,725 INFO org.apache.hadoop.yarn.event.AsyncDispatcher: Registering class org.apache.hadoop.yarn.server.resourcemanager.rmapp.attempt.RMAppAttemptEventType for class org.apache.hadoop.yarn.server.resourcemanager.ResourceManager$ApplicationAttemptEventDispatcher
2014-05-05 11:20:14,727 INFO org.apache.hadoop.yarn.event.AsyncDispatcher: Registering class org.apache.hadoop.yarn.server.resourcemanager.rmnode.RMNodeEventType for class org.apache.hadoop.yarn.server.resourcemanager.ResourceManager$NodeEventDispatcher
2014-05-05 11:20:14,932 INFO org.apache.hadoop.metrics2.impl.MetricsConfig: loaded properties from hadoop-metrics2.properties
2014-05-05 11:20:15,078 INFO org.apache.hadoop.metrics2.impl.MetricsSystemImpl: Scheduled snapshot period at 10 second(s).
2014-05-05 11:20:15,078 INFO org.apache.hadoop.metrics2.impl.MetricsSystemImpl: ResourceManager metrics system started
2014-05-05 11:20:15,311 INFO org.apache.hadoop.yarn.server.resourcemanager.scheduler.capacity.ParentQueue: root, capacity=1.0, asboluteCapacity=1.0, maxCapacity=1.0, asboluteMaxCapacity=1.0, state=RUNNING, acls=SUBMIT_APPLICATIONS:*ADMINISTER_QUEUE:*
2014-05-05 11:20:15,311 INFO org.apache.hadoop.yarn.server.resourcemanager.scheduler.capacity.ParentQueue: Initialized parent-queue root name=root, fullname=root
2014-05-05 11:20:15,344 INFO org.apache.hadoop.yarn.server.resourcemanager.scheduler.capacity.LeafQueue: Initializing default
capacity = 1.0 [= (float) configuredCapacity / 100 ]
asboluteCapacity = 1.0 [= parentAbsoluteCapacity * capacity ]
maxCapacity = 1.0 [= configuredMaxCapacity ]
absoluteMaxCapacity = 1.0 [= 1.0 maximumCapacity undefined, (parentAbsoluteMaxCapacity * maximumCapacity) / 100 otherwise ]
userLimit = 100 [= configuredUserLimit ]
userLimitFactor = 1.0 [= configuredUserLimitFactor ]
maxApplications = 10000 [= configuredMaximumSystemApplicationsPerQueue or (int)(configuredMaximumSystemApplications * absoluteCapacity)]
maxApplicationsPerUser = 10000 [= (int)(maxApplications * (userLimit / 100.0f) * userLimitFactor) ]
maxActiveApplications = 1 [= max((int)ceil((clusterResourceMemory / minimumAllocation) * maxAMResourcePerQueuePercent * absoluteMaxCapacity),1) ]
maxActiveAppsUsingAbsCap = 1 [= max((int)ceil((clusterResourceMemory / minimumAllocation) *maxAMResourcePercent * absoluteCapacity),1) ]
maxActiveApplicationsPerUser = 1 [= max((int)(maxActiveApplications * (userLimit / 100.0f) * userLimitFactor),1) ]
usedCapacity = 0.0 [= usedResourcesMemory / (clusterResourceMemory * absoluteCapacity)]
absoluteUsedCapacity = 0.0 [= usedResourcesMemory / clusterResourceMemory]
maxAMResourcePerQueuePercent = 0.1 [= configuredMaximumAMResourcePercent ]
minimumAllocationFactor = 0.875 [= (float)(maximumAllocationMemory - minimumAllocationMemory) / maximumAllocationMemory ]
numContainers = 0 [= currentNumContainers ]
state = RUNNING [= configuredState ]
acls = SUBMIT_APPLICATIONS:*ADMINISTER_QUEUE:* [= configuredAcls ]
nodeLocalityDelay = 0

2014-05-05 11:20:15,344 INFO org.apache.hadoop.yarn.server.resourcemanager.scheduler.capacity.CapacityScheduler: Initialized queue: default: capacity=1.0, absoluteCapacity=1.0, usedResources=<memory:0, vCores:0>usedCapacity=0.0, absoluteUsedCapacity=0.0, numApps=0, numContainers=0
2014-05-05 11:20:15,345 INFO org.apache.hadoop.yarn.server.resourcemanager.scheduler.capacity.CapacityScheduler: Initialized queue: root: numChildQueue= 1, capacity=1.0, absoluteCapacity=1.0, usedResources=<memory:0, vCores:0>usedCapacity=0.0, numApps=0, numContainers=0
2014-05-05 11:20:15,345 INFO org.apache.hadoop.yarn.server.resourcemanager.scheduler.capacity.CapacityScheduler: Initialized root queue root: numChildQueue= 1, capacity=1.0, absoluteCapacity=1.0, usedResources=<memory:0, vCores:0>usedCapacity=0.0, numApps=0, numContainers=0
2014-05-05 11:20:15,345 INFO org.apache.hadoop.yarn.server.resourcemanager.scheduler.capacity.CapacityScheduler: Initialized CapacityScheduler with calculator=class org.apache.hadoop.yarn.util.resource.DefaultResourceCalculator, minimumAllocation=<<memory:1024, vCores:1>>, maximumAllocation=<<memory:8192, vCores:32>>
2014-05-05 11:20:15,600 INFO org.apache.hadoop.yarn.event.AsyncDispatcher: Registering class org.apache.hadoop.yarn.server.resourcemanager.RMAppManagerEventType for class org.apache.hadoop.yarn.server.resourcemanager.RMAppManager
2014-05-05 11:20:15,652 INFO org.apache.hadoop.yarn.event.AsyncDispatcher: Registering class org.apache.hadoop.yarn.server.resourcemanager.amlauncher.AMLauncherEventType for class org.apache.hadoop.yarn.server.resourcemanager.amlauncher.ApplicationMasterLauncher
2014-05-05 11:20:15,655 INFO org.apache.hadoop.yarn.server.resourcemanager.RMNMInfo: Registered RMNMInfo MBean
2014-05-05 11:20:15,661 INFO org.apache.hadoop.util.HostsFileReader: Refreshing hosts (include/exclude) list
2014-05-05 11:20:15,679 INFO org.apache.hadoop.yarn.server.resourcemanager.security.AMRMTokenSecretManager: Rolling master-key for amrm-tokens
2014-05-05 11:20:15,680 INFO org.apache.hadoop.yarn.server.resourcemanager.security.RMContainerTokenSecretManager: Rolling master-key for container-tokens
2014-05-05 11:20:15,688 INFO org.apache.hadoop.yarn.server.resourcemanager.security.NMTokenSecretManagerInRM: Rolling master-key for nm-tokens
2014-05-05 11:20:15,772 INFO org.mortbay.log: Logging to org.slf4j.impl.Log4jLoggerAdapter(org.mortbay.log) via org.mortbay.log.Slf4jLog
2014-05-05 11:20:15,845 INFO org.apache.hadoop.http.HttpServer: Added global filter 'safety' (class=org.apache.hadoop.http.HttpServer$QuotingInputFilter)
2014-05-05 11:20:15,848 INFO org.apache.hadoop.http.HttpServer: Added filter static_user_filter (class=org.apache.hadoop.http.lib.StaticUserWebFilter$StaticUserFilter) to context cluster
2014-05-05 11:20:15,848 INFO org.apache.hadoop.http.HttpServer: Added filter static_user_filter (class=org.apache.hadoop.http.lib.StaticUserWebFilter$StaticUserFilter) to context static
2014-05-05 11:20:15,848 INFO org.apache.hadoop.http.HttpServer: Added filter static_user_filter (class=org.apache.hadoop.http.lib.StaticUserWebFilter$StaticUserFilter) to context logs
2014-05-05 11:20:15,853 INFO org.apache.hadoop.http.HttpServer: adding path spec: /cluster/*
2014-05-05 11:20:15,853 INFO org.apache.hadoop.http.HttpServer: adding path spec: /ws/*
2014-05-05 11:20:15,864 INFO org.apache.hadoop.http.HttpServer: Jetty bound to port 8088
2014-05-05 11:20:15,864 INFO org.mortbay.log: jetty-6.1.26
2014-05-05 11:20:15,916 INFO org.mortbay.log: Extract jar:file:/home/ubuntu/PatchedDistro/hadoop-patch/share/hadoop/yarn/hadoop-yarn-common-2.2.0.jar!/webapps/cluster to /tmp/Jetty_ec2.54.186.230.200_us.west.2_compute_amazonaws_com_8088_cluster____.lsgqu1/webapp
2014-05-05 11:20:16,627 INFO org.mortbay.log: Started SelectChannelConnector@ec2-54-186-230-200.us-west-2.compute.amazonaws.com:8088
2014-05-05 11:20:16,627 INFO org.apache.hadoop.yarn.webapp.WebApps: Web app /cluster started at 8088
2014-05-05 11:20:17,775 INFO org.apache.hadoop.yarn.webapp.WebApps: Registered webapp guice modules
2014-05-05 11:20:17,777 INFO org.apache.hadoop.security.token.delegation.AbstractDelegationTokenSecretManager: Updating the current master key for generating delegation tokens
2014-05-05 11:20:17,778 INFO org.apache.hadoop.yarn.server.resourcemanager.security.RMDelegationTokenSecretManager: storing master key with keyID 1
2014-05-05 11:20:17,779 INFO org.apache.hadoop.security.token.delegation.AbstractDelegationTokenSecretManager: Starting expired delegation token remover thread, tokenRemoverScanInterval=60 min(s)
2014-05-05 11:20:17,779 INFO org.apache.hadoop.security.token.delegation.AbstractDelegationTokenSecretManager: Updating the current master key for generating delegation tokens
2014-05-05 11:20:17,779 INFO org.apache.hadoop.yarn.server.resourcemanager.security.RMDelegationTokenSecretManager: storing master key with keyID 2
2014-05-05 11:20:17,832 INFO org.apache.hadoop.ipc.Server: Starting Socket Reader #1 for port 8031
2014-05-05 11:20:17,849 INFO org.apache.hadoop.yarn.factories.impl.pb.RpcServerFactoryPBImpl: Adding protocol org.apache.hadoop.yarn.server.api.ResourceTrackerPB to the server
2014-05-05 11:20:17,850 INFO org.apache.hadoop.ipc.Server: IPC Server Responder: starting
2014-05-05 11:20:17,851 INFO org.apache.hadoop.ipc.Server: IPC Server listener on 8031: starting
2014-05-05 11:20:17,900 INFO org.apache.hadoop.ipc.Server: Starting Socket Reader #1 for port 8030
2014-05-05 11:20:17,982 INFO org.apache.hadoop.yarn.factories.impl.pb.RpcServerFactoryPBImpl: Adding protocol org.apache.hadoop.yarn.api.ApplicationMasterProtocolPB to the server
2014-05-05 11:20:17,982 INFO org.apache.hadoop.ipc.Server: IPC Server listener on 8030: starting
2014-05-05 11:20:17,983 INFO org.apache.hadoop.ipc.Server: IPC Server Responder: starting
2014-05-05 11:20:18,217 INFO org.apache.hadoop.ipc.Server: Starting Socket Reader #1 for port 8032
2014-05-05 11:20:18,220 INFO org.apache.hadoop.yarn.factories.impl.pb.RpcServerFactoryPBImpl: Adding protocol org.apache.hadoop.yarn.api.ApplicationClientProtocolPB to the server
2014-05-05 11:20:18,228 INFO org.apache.hadoop.ipc.Server: IPC Server Responder: starting
2014-05-05 11:20:18,228 INFO org.apache.hadoop.ipc.Server: IPC Server listener on 8032: starting
2014-05-05 11:20:18,410 INFO org.apache.hadoop.yarn.util.RackResolver: Resolved ip-10-0-0-200.us-west-2.compute.internal to /default-rack
2014-05-05 11:20:18,410 INFO org.apache.hadoop.yarn.factories.impl.pb.RpcServerFactoryPBImpl: Adding protocol org.apache.hadoop.yarn.server.api.ResourceManagerAdministrationProtocolPB to the server
2014-05-05 11:20:18,411 INFO org.apache.hadoop.ipc.Server: Starting Socket Reader #1 for port 8033
2014-05-05 11:20:18,411 INFO org.apache.hadoop.ipc.Server: IPC Server Responder: starting
2014-05-05 11:20:18,412 INFO org.apache.hadoop.yarn.util.RackResolver: Resolved ip-10-0-0-193.us-west-2.compute.internal to /default-rack
2014-05-05 11:20:18,415 INFO org.apache.hadoop.yarn.server.resourcemanager.ResourceTrackerService: NodeManager from node ip-10-0-0-200.us-west-2.compute.internal(cmPort: 50306 httpPort: 8042) registered with capability: <memory:8192, vCores:8>, assigned nodeId ip-10-0-0-200.us-west-2.compute.internal:50306
2014-05-05 11:20:18,415 INFO org.apache.hadoop.yarn.util.RackResolver: Resolved nodeb to /default-rack
2014-05-05 11:20:18,415 INFO org.apache.hadoop.yarn.server.resourcemanager.ResourceTrackerService: NodeManager from node nodeb(cmPort: 55128 httpPort: 8042) registered with capability: <memory:8192, vCores:8>, assigned nodeId nodeb:55128
2014-05-05 11:20:18,424 INFO org.apache.hadoop.yarn.server.resourcemanager.ResourceTrackerService: NodeManager from node ip-10-0-0-193.us-west-2.compute.internal(cmPort: 45027 httpPort: 8042) registered with capability: <memory:8192, vCores:8>, assigned nodeId ip-10-0-0-193.us-west-2.compute.internal:45027
2014-05-05 11:20:18,427 INFO org.apache.hadoop.ipc.Server: IPC Server listener on 8033: starting
2014-05-05 11:20:18,444 INFO org.apache.hadoop.yarn.server.resourcemanager.rmnode.RMNodeImpl: ip-10-0-0-193.us-west-2.compute.internal:45027 Node Transitioned from NEW to RUNNING
2014-05-05 11:20:18,444 INFO org.apache.hadoop.yarn.server.resourcemanager.rmnode.RMNodeImpl: ip-10-0-0-200.us-west-2.compute.internal:50306 Node Transitioned from NEW to RUNNING
2014-05-05 11:20:18,444 INFO org.apache.hadoop.yarn.server.resourcemanager.rmnode.RMNodeImpl: nodeb:55128 Node Transitioned from NEW to RUNNING
2014-05-05 11:20:18,447 INFO org.apache.hadoop.yarn.server.resourcemanager.scheduler.capacity.CapacityScheduler: Added node ip-10-0-0-193.us-west-2.compute.internal:45027 clusterResource: <memory:8192, vCores:8>
2014-05-05 11:20:18,450 INFO org.apache.hadoop.yarn.server.resourcemanager.scheduler.capacity.CapacityScheduler: Added node ip-10-0-0-200.us-west-2.compute.internal:50306 clusterResource: <memory:16384, vCores:16>
2014-05-05 11:20:18,450 INFO org.apache.hadoop.yarn.server.resourcemanager.scheduler.capacity.CapacityScheduler: Added node nodeb:55128 clusterResource: <memory:24576, vCores:24>
2014-05-05 11:20:19,969 INFO org.apache.hadoop.yarn.util.RackResolver: Resolved nodea to /default-rack
2014-05-05 11:20:19,970 INFO org.apache.hadoop.yarn.server.resourcemanager.ResourceTrackerService: NodeManager from node nodea(cmPort: 58674 httpPort: 8042) registered with capability: <memory:8192, vCores:8>, assigned nodeId nodea:58674
2014-05-05 11:20:19,970 INFO org.apache.hadoop.yarn.server.resourcemanager.rmnode.RMNodeImpl: nodea:58674 Node Transitioned from NEW to RUNNING
2014-05-05 11:20:19,970 INFO org.apache.hadoop.yarn.server.resourcemanager.scheduler.capacity.CapacityScheduler: Added node nodea:58674 clusterResource: <memory:32768, vCores:32>
2014-05-05 11:22:19,159 ERROR org.apache.hadoop.yarn.server.resourcemanager.ResourceManager: RECEIVED SIGNAL 15: SIGTERM
2014-05-05 11:22:19,170 INFO org.mortbay.log: Stopped SelectChannelConnector@ec2-54-186-230-200.us-west-2.compute.amazonaws.com:8088
2014-05-05 11:22:19,273 ERROR org.apache.hadoop.security.token.delegation.AbstractDelegationTokenSecretManager: InterruptedExcpetion recieved for ExpiredTokenRemover thread java.lang.InterruptedException: sleep interrupted
2014-05-05 11:22:19,274 INFO org.apache.hadoop.metrics2.impl.MetricsSystemImpl: Stopping ResourceManager metrics system...
2014-05-05 11:22:19,275 INFO org.apache.hadoop.metrics2.impl.MetricsSystemImpl: ResourceManager metrics system stopped.
2014-05-05 11:22:19,276 INFO org.apache.hadoop.metrics2.impl.MetricsSystemImpl: ResourceManager metrics system shutdown complete.
2014-05-05 11:22:19,276 WARN org.apache.hadoop.yarn.server.resourcemanager.amlauncher.ApplicationMasterLauncher: org.apache.hadoop.yarn.server.resourcemanager.amlauncher.ApplicationMasterLauncher$LauncherThread interrupted. Returning.
2014-05-05 11:22:19,276 INFO org.apache.hadoop.ipc.Server: Stopping server on 8033
2014-05-05 11:22:19,277 INFO org.apache.hadoop.ipc.Server: Stopping IPC Server listener on 8033
2014-05-05 11:22:19,277 INFO org.apache.hadoop.ipc.Server: Stopping IPC Server Responder
2014-05-05 11:22:19,277 INFO org.apache.hadoop.ipc.Server: Stopping server on 8032
2014-05-05 11:22:19,281 INFO org.apache.hadoop.ipc.Server: Stopping IPC Server Responder
2014-05-05 11:22:19,282 INFO org.apache.hadoop.ipc.Server: Stopping IPC Server listener on 8032
2014-05-05 11:22:19,283 INFO org.apache.hadoop.ipc.Server: Stopping server on 8030
2014-05-05 11:22:19,287 INFO org.apache.hadoop.ipc.Server: Stopping IPC Server listener on 8030
2014-05-05 11:22:19,290 INFO org.apache.hadoop.ipc.Server: Stopping IPC Server Responder
2014-05-05 11:22:19,290 INFO org.apache.hadoop.ipc.Server: Stopping server on 8031
2014-05-05 11:22:19,294 INFO org.apache.hadoop.ipc.Server: Stopping IPC Server listener on 8031
2014-05-05 11:22:19,298 INFO org.apache.hadoop.ipc.Server: Stopping IPC Server Responder
2014-05-05 11:22:19,299 ERROR org.apache.hadoop.yarn.server.resourcemanager.ResourceManager: Returning, interrupted : java.lang.InterruptedException
2014-05-05 11:22:19,299 INFO org.apache.hadoop.yarn.util.AbstractLivelinessMonitor: AMLivelinessMonitor thread interrupted
2014-05-05 11:22:19,300 INFO org.apache.hadoop.yarn.util.AbstractLivelinessMonitor: AMLivelinessMonitor thread interrupted
2014-05-05 11:22:19,299 INFO org.apache.hadoop.yarn.util.AbstractLivelinessMonitor: NMLivelinessMonitor thread interrupted
2014-05-05 11:22:19,299 INFO org.apache.hadoop.yarn.util.AbstractLivelinessMonitor: org.apache.hadoop.yarn.server.resourcemanager.rmcontainer.ContainerAllocationExpirer thread interrupted
2014-05-05 11:22:19,301 INFO org.apache.hadoop.yarn.server.resourcemanager.ResourceManager: SHUTDOWN_MSG: 
/************************************************************
SHUTDOWN_MSG: Shutting down ResourceManager at ip-10-0-0-195/10.0.0.195
************************************************************/
2014-05-05 11:23:36,030 INFO org.apache.hadoop.yarn.server.resourcemanager.ResourceManager: STARTUP_MSG: 
/************************************************************
STARTUP_MSG: Starting ResourceManager
STARTUP_MSG:   host = ip-10-0-0-195/10.0.0.195
STARTUP_MSG:   args = []
STARTUP_MSG:   version = 2.2.0
STARTUP_MSG:   build = Unknown -r Unknown; compiled by 'root' on 2014-05-04T05:58Z
STARTUP_MSG:   java = 1.7.0_51
************************************************************/
2014-05-05 11:23:36,039 INFO org.apache.hadoop.yarn.server.resourcemanager.ResourceManager: registered UNIX signal handlers for [TERM, HUP, INT]
2014-05-05 11:23:36,366 INFO org.apache.hadoop.yarn.server.resourcemanager.security.AMRMTokenSecretManager: Rolling master-key for amrm-tokens
2014-05-05 11:23:36,381 INFO org.apache.hadoop.yarn.server.resourcemanager.security.RMContainerTokenSecretManager: ContainerTokenKeyRollingInterval: 86400000ms and ContainerTokenKeyActivationDelay: 900000ms
2014-05-05 11:23:36,385 INFO org.apache.hadoop.yarn.server.resourcemanager.security.NMTokenSecretManagerInRM: NMTokenKeyRollingInterval: 86400000ms and NMTokenKeyActivationDelay: 900000ms
2014-05-05 11:23:36,392 INFO org.apache.hadoop.yarn.event.AsyncDispatcher: Registering class org.apache.hadoop.yarn.server.resourcemanager.recovery.RMStateStoreEventType for class org.apache.hadoop.yarn.server.resourcemanager.recovery.RMStateStore$ForwardingEventHandler
2014-05-05 11:23:36,732 WARN org.apache.hadoop.util.NativeCodeLoader: Unable to load native-hadoop library for your platform... using builtin-java classes where applicable
2014-05-05 11:23:37,126 INFO org.apache.hadoop.yarn.event.AsyncDispatcher: Registering class org.apache.hadoop.yarn.server.resourcemanager.NodesListManagerEventType for class org.apache.hadoop.yarn.server.resourcemanager.NodesListManager
2014-05-05 11:23:37,309 INFO org.apache.hadoop.yarn.server.resourcemanager.ResourceManager: Using Scheduler: org.apache.hadoop.yarn.server.resourcemanager.scheduler.capacity.CapacityScheduler
2014-05-05 11:23:37,499 INFO org.apache.hadoop.yarn.event.AsyncDispatcher: Registering class org.apache.hadoop.yarn.server.resourcemanager.scheduler.event.SchedulerEventType for class org.apache.hadoop.yarn.server.resourcemanager.ResourceManager$SchedulerEventDispatcher
2014-05-05 11:23:37,501 INFO org.apache.hadoop.yarn.event.AsyncDispatcher: Registering class org.apache.hadoop.yarn.server.resourcemanager.rmapp.RMAppEventType for class org.apache.hadoop.yarn.server.resourcemanager.ResourceManager$ApplicationEventDispatcher
2014-05-05 11:23:37,502 INFO org.apache.hadoop.yarn.event.AsyncDispatcher: Registering class org.apache.hadoop.yarn.server.resourcemanager.rmapp.attempt.RMAppAttemptEventType for class org.apache.hadoop.yarn.server.resourcemanager.ResourceManager$ApplicationAttemptEventDispatcher
2014-05-05 11:23:37,505 INFO org.apache.hadoop.yarn.event.AsyncDispatcher: Registering class org.apache.hadoop.yarn.server.resourcemanager.rmnode.RMNodeEventType for class org.apache.hadoop.yarn.server.resourcemanager.ResourceManager$NodeEventDispatcher
2014-05-05 11:23:37,705 INFO org.apache.hadoop.metrics2.impl.MetricsConfig: loaded properties from hadoop-metrics2.properties
2014-05-05 11:23:37,831 INFO org.apache.hadoop.metrics2.impl.MetricsSystemImpl: Scheduled snapshot period at 10 second(s).
2014-05-05 11:23:37,831 INFO org.apache.hadoop.metrics2.impl.MetricsSystemImpl: ResourceManager metrics system started
2014-05-05 11:23:38,073 INFO org.apache.hadoop.yarn.server.resourcemanager.scheduler.capacity.ParentQueue: root, capacity=1.0, asboluteCapacity=1.0, maxCapacity=1.0, asboluteMaxCapacity=1.0, state=RUNNING, acls=SUBMIT_APPLICATIONS:*ADMINISTER_QUEUE:*
2014-05-05 11:23:38,073 INFO org.apache.hadoop.yarn.server.resourcemanager.scheduler.capacity.ParentQueue: Initialized parent-queue root name=root, fullname=root
2014-05-05 11:23:38,137 INFO org.apache.hadoop.yarn.server.resourcemanager.scheduler.capacity.LeafQueue: Initializing default
capacity = 1.0 [= (float) configuredCapacity / 100 ]
asboluteCapacity = 1.0 [= parentAbsoluteCapacity * capacity ]
maxCapacity = 1.0 [= configuredMaxCapacity ]
absoluteMaxCapacity = 1.0 [= 1.0 maximumCapacity undefined, (parentAbsoluteMaxCapacity * maximumCapacity) / 100 otherwise ]
userLimit = 100 [= configuredUserLimit ]
userLimitFactor = 1.0 [= configuredUserLimitFactor ]
maxApplications = 10000 [= configuredMaximumSystemApplicationsPerQueue or (int)(configuredMaximumSystemApplications * absoluteCapacity)]
maxApplicationsPerUser = 10000 [= (int)(maxApplications * (userLimit / 100.0f) * userLimitFactor) ]
maxActiveApplications = 1 [= max((int)ceil((clusterResourceMemory / minimumAllocation) * maxAMResourcePerQueuePercent * absoluteMaxCapacity),1) ]
maxActiveAppsUsingAbsCap = 1 [= max((int)ceil((clusterResourceMemory / minimumAllocation) *maxAMResourcePercent * absoluteCapacity),1) ]
maxActiveApplicationsPerUser = 1 [= max((int)(maxActiveApplications * (userLimit / 100.0f) * userLimitFactor),1) ]
usedCapacity = 0.0 [= usedResourcesMemory / (clusterResourceMemory * absoluteCapacity)]
absoluteUsedCapacity = 0.0 [= usedResourcesMemory / clusterResourceMemory]
maxAMResourcePerQueuePercent = 0.1 [= configuredMaximumAMResourcePercent ]
minimumAllocationFactor = 0.875 [= (float)(maximumAllocationMemory - minimumAllocationMemory) / maximumAllocationMemory ]
numContainers = 0 [= currentNumContainers ]
state = RUNNING [= configuredState ]
acls = SUBMIT_APPLICATIONS:*ADMINISTER_QUEUE:* [= configuredAcls ]
nodeLocalityDelay = 0

2014-05-05 11:23:38,137 INFO org.apache.hadoop.yarn.server.resourcemanager.scheduler.capacity.CapacityScheduler: Initialized queue: default: capacity=1.0, absoluteCapacity=1.0, usedResources=<memory:0, vCores:0>usedCapacity=0.0, absoluteUsedCapacity=0.0, numApps=0, numContainers=0
2014-05-05 11:23:38,138 INFO org.apache.hadoop.yarn.server.resourcemanager.scheduler.capacity.CapacityScheduler: Initialized queue: root: numChildQueue= 1, capacity=1.0, absoluteCapacity=1.0, usedResources=<memory:0, vCores:0>usedCapacity=0.0, numApps=0, numContainers=0
2014-05-05 11:23:38,138 INFO org.apache.hadoop.yarn.server.resourcemanager.scheduler.capacity.CapacityScheduler: Initialized root queue root: numChildQueue= 1, capacity=1.0, absoluteCapacity=1.0, usedResources=<memory:0, vCores:0>usedCapacity=0.0, numApps=0, numContainers=0
2014-05-05 11:23:38,138 INFO org.apache.hadoop.yarn.server.resourcemanager.scheduler.capacity.CapacityScheduler: Initialized CapacityScheduler with calculator=class org.apache.hadoop.yarn.util.resource.DefaultResourceCalculator, minimumAllocation=<<memory:1024, vCores:1>>, maximumAllocation=<<memory:8192, vCores:32>>
2014-05-05 11:23:38,321 INFO org.apache.hadoop.yarn.event.AsyncDispatcher: Registering class org.apache.hadoop.yarn.server.resourcemanager.RMAppManagerEventType for class org.apache.hadoop.yarn.server.resourcemanager.RMAppManager
2014-05-05 11:23:38,360 INFO org.apache.hadoop.yarn.event.AsyncDispatcher: Registering class org.apache.hadoop.yarn.server.resourcemanager.amlauncher.AMLauncherEventType for class org.apache.hadoop.yarn.server.resourcemanager.amlauncher.ApplicationMasterLauncher
2014-05-05 11:23:38,384 INFO org.apache.hadoop.yarn.server.resourcemanager.RMNMInfo: Registered RMNMInfo MBean
2014-05-05 11:23:38,385 INFO org.apache.hadoop.util.HostsFileReader: Refreshing hosts (include/exclude) list
2014-05-05 11:23:38,410 INFO org.apache.hadoop.yarn.server.resourcemanager.security.AMRMTokenSecretManager: Rolling master-key for amrm-tokens
2014-05-05 11:23:38,411 INFO org.apache.hadoop.yarn.server.resourcemanager.security.RMContainerTokenSecretManager: Rolling master-key for container-tokens
2014-05-05 11:23:38,417 INFO org.apache.hadoop.yarn.server.resourcemanager.security.NMTokenSecretManagerInRM: Rolling master-key for nm-tokens
2014-05-05 11:23:38,489 INFO org.mortbay.log: Logging to org.slf4j.impl.Log4jLoggerAdapter(org.mortbay.log) via org.mortbay.log.Slf4jLog
2014-05-05 11:23:38,557 INFO org.apache.hadoop.http.HttpServer: Added global filter 'safety' (class=org.apache.hadoop.http.HttpServer$QuotingInputFilter)
2014-05-05 11:23:38,560 INFO org.apache.hadoop.http.HttpServer: Added filter static_user_filter (class=org.apache.hadoop.http.lib.StaticUserWebFilter$StaticUserFilter) to context cluster
2014-05-05 11:23:38,560 INFO org.apache.hadoop.http.HttpServer: Added filter static_user_filter (class=org.apache.hadoop.http.lib.StaticUserWebFilter$StaticUserFilter) to context static
2014-05-05 11:23:38,560 INFO org.apache.hadoop.http.HttpServer: Added filter static_user_filter (class=org.apache.hadoop.http.lib.StaticUserWebFilter$StaticUserFilter) to context logs
2014-05-05 11:23:38,565 INFO org.apache.hadoop.http.HttpServer: adding path spec: /cluster/*
2014-05-05 11:23:38,565 INFO org.apache.hadoop.http.HttpServer: adding path spec: /ws/*
2014-05-05 11:23:38,576 INFO org.apache.hadoop.http.HttpServer: Jetty bound to port 8088
2014-05-05 11:23:38,576 INFO org.mortbay.log: jetty-6.1.26
2014-05-05 11:23:38,622 INFO org.mortbay.log: Extract jar:file:/home/ubuntu/PatchedDistro/hadoop-patch/share/hadoop/yarn/hadoop-yarn-common-2.2.0.jar!/webapps/cluster to /tmp/Jetty_ec2.54.186.230.200_us.west.2_compute_amazonaws_com_8088_cluster____.lsgqu1/webapp
2014-05-05 11:23:39,314 INFO org.mortbay.log: Started SelectChannelConnector@ec2-54-186-230-200.us-west-2.compute.amazonaws.com:8088
2014-05-05 11:23:39,314 INFO org.apache.hadoop.yarn.webapp.WebApps: Web app /cluster started at 8088
2014-05-05 11:23:40,369 INFO org.apache.hadoop.yarn.webapp.WebApps: Registered webapp guice modules
2014-05-05 11:23:40,371 INFO org.apache.hadoop.security.token.delegation.AbstractDelegationTokenSecretManager: Updating the current master key for generating delegation tokens
2014-05-05 11:23:40,372 INFO org.apache.hadoop.yarn.server.resourcemanager.security.RMDelegationTokenSecretManager: storing master key with keyID 1
2014-05-05 11:23:40,373 INFO org.apache.hadoop.security.token.delegation.AbstractDelegationTokenSecretManager: Starting expired delegation token remover thread, tokenRemoverScanInterval=60 min(s)
2014-05-05 11:23:40,373 INFO org.apache.hadoop.security.token.delegation.AbstractDelegationTokenSecretManager: Updating the current master key for generating delegation tokens
2014-05-05 11:23:40,373 INFO org.apache.hadoop.yarn.server.resourcemanager.security.RMDelegationTokenSecretManager: storing master key with keyID 2
2014-05-05 11:23:40,428 INFO org.apache.hadoop.ipc.Server: Starting Socket Reader #1 for port 8031
2014-05-05 11:23:40,444 INFO org.apache.hadoop.yarn.factories.impl.pb.RpcServerFactoryPBImpl: Adding protocol org.apache.hadoop.yarn.server.api.ResourceTrackerPB to the server
2014-05-05 11:23:40,444 INFO org.apache.hadoop.ipc.Server: IPC Server Responder: starting
2014-05-05 11:23:40,445 INFO org.apache.hadoop.ipc.Server: IPC Server listener on 8031: starting
2014-05-05 11:23:40,512 INFO org.apache.hadoop.ipc.Server: Starting Socket Reader #1 for port 8030
2014-05-05 11:23:40,564 INFO org.apache.hadoop.yarn.factories.impl.pb.RpcServerFactoryPBImpl: Adding protocol org.apache.hadoop.yarn.api.ApplicationMasterProtocolPB to the server
2014-05-05 11:23:40,565 INFO org.apache.hadoop.ipc.Server: IPC Server Responder: starting
2014-05-05 11:23:40,565 INFO org.apache.hadoop.ipc.Server: IPC Server listener on 8030: starting
2014-05-05 11:23:40,679 INFO org.apache.hadoop.yarn.factories.impl.pb.RpcServerFactoryPBImpl: Adding protocol org.apache.hadoop.yarn.api.ApplicationClientProtocolPB to the server
2014-05-05 11:23:40,680 INFO org.apache.hadoop.ipc.Server: Starting Socket Reader #1 for port 8032
2014-05-05 11:23:40,680 INFO org.apache.hadoop.ipc.Server: IPC Server Responder: starting
2014-05-05 11:23:40,680 INFO org.apache.hadoop.ipc.Server: IPC Server listener on 8032: starting
2014-05-05 11:23:40,731 INFO org.apache.hadoop.yarn.factories.impl.pb.RpcServerFactoryPBImpl: Adding protocol org.apache.hadoop.yarn.server.api.ResourceManagerAdministrationProtocolPB to the server
2014-05-05 11:23:40,731 INFO org.apache.hadoop.ipc.Server: Starting Socket Reader #1 for port 8033
2014-05-05 11:23:40,731 INFO org.apache.hadoop.ipc.Server: IPC Server Responder: starting
2014-05-05 11:23:40,732 INFO org.apache.hadoop.ipc.Server: IPC Server listener on 8033: starting
2014-05-05 11:23:41,111 INFO org.apache.hadoop.yarn.util.RackResolver: Resolved ip-10-0-0-200.us-west-2.compute.internal to /default-rack
2014-05-05 11:23:41,120 INFO org.apache.hadoop.yarn.server.resourcemanager.ResourceTrackerService: NodeManager from node ip-10-0-0-200.us-west-2.compute.internal(cmPort: 36991 httpPort: 8042) registered with capability: <memory:8192, vCores:8>, assigned nodeId ip-10-0-0-200.us-west-2.compute.internal:36991
2014-05-05 11:23:41,122 INFO org.apache.hadoop.yarn.server.resourcemanager.rmnode.RMNodeImpl: ip-10-0-0-200.us-west-2.compute.internal:36991 Node Transitioned from NEW to RUNNING
2014-05-05 11:23:41,125 INFO org.apache.hadoop.yarn.server.resourcemanager.scheduler.capacity.CapacityScheduler: Added node ip-10-0-0-200.us-west-2.compute.internal:36991 clusterResource: <memory:8192, vCores:8>
2014-05-05 11:23:41,127 INFO org.apache.hadoop.yarn.util.RackResolver: Resolved ip-10-0-0-193.us-west-2.compute.internal to /default-rack
2014-05-05 11:23:41,127 INFO org.apache.hadoop.yarn.server.resourcemanager.ResourceTrackerService: NodeManager from node ip-10-0-0-193.us-west-2.compute.internal(cmPort: 60686 httpPort: 8042) registered with capability: <memory:8192, vCores:8>, assigned nodeId ip-10-0-0-193.us-west-2.compute.internal:60686
2014-05-05 11:23:41,127 INFO org.apache.hadoop.yarn.server.resourcemanager.rmnode.RMNodeImpl: ip-10-0-0-193.us-west-2.compute.internal:60686 Node Transitioned from NEW to RUNNING
2014-05-05 11:23:41,128 INFO org.apache.hadoop.yarn.server.resourcemanager.scheduler.capacity.CapacityScheduler: Added node ip-10-0-0-193.us-west-2.compute.internal:60686 clusterResource: <memory:16384, vCores:16>
2014-05-05 11:23:41,136 INFO org.apache.hadoop.yarn.util.RackResolver: Resolved nodeb to /default-rack
2014-05-05 11:23:41,136 INFO org.apache.hadoop.yarn.server.resourcemanager.ResourceTrackerService: NodeManager from node nodeb(cmPort: 43052 httpPort: 8042) registered with capability: <memory:8192, vCores:8>, assigned nodeId nodeb:43052
2014-05-05 11:23:41,136 INFO org.apache.hadoop.yarn.server.resourcemanager.rmnode.RMNodeImpl: nodeb:43052 Node Transitioned from NEW to RUNNING
2014-05-05 11:23:41,137 INFO org.apache.hadoop.yarn.server.resourcemanager.scheduler.capacity.CapacityScheduler: Added node nodeb:43052 clusterResource: <memory:24576, vCores:24>
2014-05-05 11:23:41,169 INFO org.apache.hadoop.yarn.util.RackResolver: Resolved ip-10-0-0-197.us-west-2.compute.internal to /default-rack
2014-05-05 11:23:41,170 INFO org.apache.hadoop.yarn.server.resourcemanager.ResourceTrackerService: NodeManager from node ip-10-0-0-197.us-west-2.compute.internal(cmPort: 36720 httpPort: 8042) registered with capability: <memory:8192, vCores:8>, assigned nodeId ip-10-0-0-197.us-west-2.compute.internal:36720
2014-05-05 11:23:41,170 INFO org.apache.hadoop.yarn.server.resourcemanager.rmnode.RMNodeImpl: ip-10-0-0-197.us-west-2.compute.internal:36720 Node Transitioned from NEW to RUNNING
2014-05-05 11:23:41,170 INFO org.apache.hadoop.yarn.server.resourcemanager.scheduler.capacity.CapacityScheduler: Added node ip-10-0-0-197.us-west-2.compute.internal:36720 clusterResource: <memory:32768, vCores:32>
2014-05-05 11:23:41,307 INFO org.apache.hadoop.yarn.util.RackResolver: Resolved ip-10-0-0-196.us-west-2.compute.internal to /default-rack
2014-05-05 11:23:41,307 INFO org.apache.hadoop.yarn.server.resourcemanager.ResourceTrackerService: NodeManager from node ip-10-0-0-196.us-west-2.compute.internal(cmPort: 47357 httpPort: 8042) registered with capability: <memory:8192, vCores:8>, assigned nodeId ip-10-0-0-196.us-west-2.compute.internal:47357
2014-05-05 11:23:41,308 INFO org.apache.hadoop.yarn.server.resourcemanager.rmnode.RMNodeImpl: ip-10-0-0-196.us-west-2.compute.internal:47357 Node Transitioned from NEW to RUNNING
2014-05-05 11:23:41,309 INFO org.apache.hadoop.yarn.server.resourcemanager.scheduler.capacity.CapacityScheduler: Added node ip-10-0-0-196.us-west-2.compute.internal:47357 clusterResource: <memory:40960, vCores:40>
2014-05-05 11:23:41,328 INFO org.apache.hadoop.yarn.util.RackResolver: Resolved ip-10-0-0-199.us-west-2.compute.internal to /default-rack
2014-05-05 11:23:41,328 INFO org.apache.hadoop.yarn.server.resourcemanager.ResourceTrackerService: NodeManager from node ip-10-0-0-199.us-west-2.compute.internal(cmPort: 36159 httpPort: 8042) registered with capability: <memory:8192, vCores:8>, assigned nodeId ip-10-0-0-199.us-west-2.compute.internal:36159
2014-05-05 11:23:41,328 INFO org.apache.hadoop.yarn.server.resourcemanager.rmnode.RMNodeImpl: ip-10-0-0-199.us-west-2.compute.internal:36159 Node Transitioned from NEW to RUNNING
2014-05-05 11:23:41,328 INFO org.apache.hadoop.yarn.server.resourcemanager.scheduler.capacity.CapacityScheduler: Added node ip-10-0-0-199.us-west-2.compute.internal:36159 clusterResource: <memory:49152, vCores:48>
2014-05-05 11:23:41,451 INFO org.apache.hadoop.yarn.util.RackResolver: Resolved ip-10-0-0-198.us-west-2.compute.internal to /default-rack
2014-05-05 11:23:41,451 INFO org.apache.hadoop.yarn.server.resourcemanager.ResourceTrackerService: NodeManager from node ip-10-0-0-198.us-west-2.compute.internal(cmPort: 60935 httpPort: 8042) registered with capability: <memory:8192, vCores:8>, assigned nodeId ip-10-0-0-198.us-west-2.compute.internal:60935
2014-05-05 11:23:41,452 INFO org.apache.hadoop.yarn.server.resourcemanager.rmnode.RMNodeImpl: ip-10-0-0-198.us-west-2.compute.internal:60935 Node Transitioned from NEW to RUNNING
2014-05-05 11:23:41,452 INFO org.apache.hadoop.yarn.server.resourcemanager.scheduler.capacity.CapacityScheduler: Added node ip-10-0-0-198.us-west-2.compute.internal:60935 clusterResource: <memory:57344, vCores:56>
2014-05-05 11:23:42,971 INFO org.apache.hadoop.yarn.util.RackResolver: Resolved nodea to /default-rack
2014-05-05 11:23:42,971 INFO org.apache.hadoop.yarn.server.resourcemanager.ResourceTrackerService: NodeManager from node nodea(cmPort: 34521 httpPort: 8042) registered with capability: <memory:8192, vCores:8>, assigned nodeId nodea:34521
2014-05-05 11:23:42,971 INFO org.apache.hadoop.yarn.server.resourcemanager.rmnode.RMNodeImpl: nodea:34521 Node Transitioned from NEW to RUNNING
2014-05-05 11:23:42,971 INFO org.apache.hadoop.yarn.server.resourcemanager.scheduler.capacity.CapacityScheduler: Added node nodea:34521 clusterResource: <memory:65536, vCores:64>
2014-05-05 11:38:52,522 INFO org.apache.hadoop.yarn.server.resourcemanager.ClientRMService: Allocated new applicationId: 1
2014-05-05 11:38:54,363 INFO org.apache.hadoop.yarn.server.resourcemanager.ClientRMService: Application with id 1 submitted by user ubuntu
2014-05-05 11:38:54,364 INFO org.apache.hadoop.yarn.server.resourcemanager.rmapp.RMAppImpl: Storing application with id application_1399289015992_0001
2014-05-05 11:38:54,365 INFO org.apache.hadoop.yarn.server.resourcemanager.RMAuditLogger: USER=ubuntu	IP=10.0.0.195	OPERATION=Submit Application Request	TARGET=ClientRMService	RESULT=SUCCESS	APPID=application_1399289015992_0001
2014-05-05 11:38:54,370 INFO org.apache.hadoop.yarn.server.resourcemanager.rmapp.RMAppImpl: application_1399289015992_0001 State change from NEW to NEW_SAVING
2014-05-05 11:38:54,371 INFO org.apache.hadoop.yarn.server.resourcemanager.recovery.RMStateStore: Storing info for app: application_1399289015992_0001
2014-05-05 11:38:54,384 INFO org.apache.hadoop.yarn.server.resourcemanager.rmapp.RMAppImpl: application_1399289015992_0001 State change from NEW_SAVING to SUBMITTED
2014-05-05 11:38:54,385 INFO org.apache.hadoop.yarn.server.resourcemanager.ApplicationMasterService: Registering app attempt : appattempt_1399289015992_0001_000001
2014-05-05 11:38:54,391 INFO org.apache.hadoop.yarn.server.resourcemanager.rmapp.attempt.RMAppAttemptImpl: appattempt_1399289015992_0001_000001 State change from NEW to SUBMITTED
2014-05-05 11:38:54,406 INFO org.apache.hadoop.yarn.server.resourcemanager.scheduler.capacity.LeafQueue: Application application_1399289015992_0001 from user: ubuntu activated in queue: default
2014-05-05 11:38:54,406 INFO org.apache.hadoop.yarn.server.resourcemanager.scheduler.capacity.LeafQueue: Application added - appId: application_1399289015992_0001 user: org.apache.hadoop.yarn.server.resourcemanager.scheduler.capacity.LeafQueue$User@20880a03, leaf-queue: default #user-pending-applications: 0 #user-active-applications: 1 #queue-pending-applications: 0 #queue-active-applications: 1
2014-05-05 11:38:54,406 INFO org.apache.hadoop.yarn.server.resourcemanager.scheduler.capacity.ParentQueue: Application added - appId: application_1399289015992_0001 user: ubuntu leaf-queue of parent: root #applications: 1
2014-05-05 11:38:54,406 INFO org.apache.hadoop.yarn.server.resourcemanager.scheduler.capacity.CapacityScheduler: Application Submission: appattempt_1399289015992_0001_000001, user: ubuntu queue: default: capacity=1.0, absoluteCapacity=1.0, usedResources=<memory:0, vCores:0>usedCapacity=0.0, absoluteUsedCapacity=0.0, numApps=1, numContainers=0, currently active: 1
2014-05-05 11:38:54,407 INFO org.apache.hadoop.yarn.server.resourcemanager.rmapp.attempt.RMAppAttemptImpl: appattempt_1399289015992_0001_000001 State change from SUBMITTED to SCHEDULED
2014-05-05 11:38:54,408 INFO org.apache.hadoop.yarn.server.resourcemanager.rmapp.RMAppImpl: application_1399289015992_0001 State change from SUBMITTED to ACCEPTED
2014-05-05 11:38:54,442 INFO org.apache.hadoop.yarn.server.resourcemanager.rmcontainer.RMContainerImpl: container_1399289015992_0001_01_000001 Container Transitioned from NEW to ALLOCATED
2014-05-05 11:38:54,442 INFO org.apache.hadoop.yarn.server.resourcemanager.RMAuditLogger: USER=ubuntu	OPERATION=AM Allocated Container	TARGET=SchedulerApp	RESULT=SUCCESS	APPID=application_1399289015992_0001	CONTAINERID=container_1399289015992_0001_01_000001
2014-05-05 11:38:54,442 INFO org.apache.hadoop.yarn.server.resourcemanager.scheduler.common.fica.FiCaSchedulerNode: Assigned container container_1399289015992_0001_01_000001 of capacity <memory:2048, vCores:1> on host ip-10-0-0-193.us-west-2.compute.internal:60686, which currently has 1 containers, <memory:2048, vCores:1> used and <memory:6144, vCores:7> available
2014-05-05 11:38:54,442 INFO org.apache.hadoop.yarn.server.resourcemanager.scheduler.capacity.LeafQueue: assignedContainer application=application_1399289015992_0001 container=Container: [ContainerId: container_1399289015992_0001_01_000001, NodeId: ip-10-0-0-193.us-west-2.compute.internal:60686, NodeHttpAddress: ip-10-0-0-193.us-west-2.compute.internal:8042, Resource: <memory:2048, vCores:1>, Priority: 0, Token: Token { kind: ContainerToken, service: 10.0.0.193:60686 }, ] containerId=container_1399289015992_0001_01_000001 queue=default: capacity=1.0, absoluteCapacity=1.0, usedResources=<memory:0, vCores:0>usedCapacity=0.0, absoluteUsedCapacity=0.0, numApps=1, numContainers=0 usedCapacity=0.0 absoluteUsedCapacity=0.0 used=<memory:0, vCores:0> cluster=<memory:65536, vCores:64>
2014-05-05 11:38:54,442 INFO org.apache.hadoop.yarn.server.resourcemanager.scheduler.capacity.ParentQueue: Re-sorting assigned queue: root.default stats: default: capacity=1.0, absoluteCapacity=1.0, usedResources=<memory:2048, vCores:1>usedCapacity=0.03125, absoluteUsedCapacity=0.03125, numApps=1, numContainers=1
2014-05-05 11:38:54,443 INFO org.apache.hadoop.yarn.server.resourcemanager.scheduler.capacity.ParentQueue: assignedContainer queue=root usedCapacity=0.03125 absoluteUsedCapacity=0.03125 used=<memory:2048, vCores:1> cluster=<memory:65536, vCores:64>
2014-05-05 11:38:54,443 INFO org.apache.hadoop.yarn.server.resourcemanager.rmcontainer.RMContainerImpl: container_1399289015992_0001_01_000001 Container Transitioned from ALLOCATED to ACQUIRED
2014-05-05 11:38:54,445 INFO org.apache.hadoop.yarn.server.resourcemanager.rmapp.attempt.RMAppAttemptImpl: Storing attempt: AppId: application_1399289015992_0001 AttemptId: appattempt_1399289015992_0001_000001 MasterContainer: Container: [ContainerId: container_1399289015992_0001_01_000001, NodeId: ip-10-0-0-193.us-west-2.compute.internal:60686, NodeHttpAddress: ip-10-0-0-193.us-west-2.compute.internal:8042, Resource: <memory:2048, vCores:1>, Priority: 0, Token: Token { kind: ContainerToken, service: 10.0.0.193:60686 }, ]
2014-05-05 11:38:54,449 INFO org.apache.hadoop.yarn.server.resourcemanager.rmapp.attempt.RMAppAttemptImpl: appattempt_1399289015992_0001_000001 State change from SCHEDULED to ALLOCATED_SAVING
2014-05-05 11:38:54,455 INFO org.apache.hadoop.yarn.server.resourcemanager.recovery.RMStateStore: Storing info for attempt: appattempt_1399289015992_0001_000001
2014-05-05 11:38:54,456 INFO org.apache.hadoop.yarn.server.resourcemanager.rmapp.attempt.RMAppAttemptImpl: appattempt_1399289015992_0001_000001 State change from ALLOCATED_SAVING to ALLOCATED
2014-05-05 11:38:54,459 INFO org.apache.hadoop.yarn.server.resourcemanager.amlauncher.AMLauncher: Launching masterappattempt_1399289015992_0001_000001
2014-05-05 11:38:54,501 INFO org.apache.hadoop.yarn.server.resourcemanager.amlauncher.AMLauncher: Setting up container Container: [ContainerId: container_1399289015992_0001_01_000001, NodeId: ip-10-0-0-193.us-west-2.compute.internal:60686, NodeHttpAddress: ip-10-0-0-193.us-west-2.compute.internal:8042, Resource: <memory:2048, vCores:1>, Priority: 0, Token: Token { kind: ContainerToken, service: 10.0.0.193:60686 }, ] for AM appattempt_1399289015992_0001_000001
2014-05-05 11:38:54,502 INFO org.apache.hadoop.yarn.server.resourcemanager.amlauncher.AMLauncher: Command to launch container container_1399289015992_0001_01_000001 : $JAVA_HOME/bin/java -Dlog4j.configuration=container-log4j.properties -Dyarn.app.container.log.dir=<LOG_DIR> -Dyarn.app.container.log.filesize=0 -Dhadoop.root.logger=INFO,CLA  -Xmx1024m org.apache.hadoop.mapreduce.v2.app.MRAppMaster 1><LOG_DIR>/stdout 2><LOG_DIR>/stderr 
2014-05-05 11:38:54,980 INFO org.apache.hadoop.yarn.server.resourcemanager.amlauncher.AMLauncher: Done launching container Container: [ContainerId: container_1399289015992_0001_01_000001, NodeId: ip-10-0-0-193.us-west-2.compute.internal:60686, NodeHttpAddress: ip-10-0-0-193.us-west-2.compute.internal:8042, Resource: <memory:2048, vCores:1>, Priority: 0, Token: Token { kind: ContainerToken, service: 10.0.0.193:60686 }, ] for AM appattempt_1399289015992_0001_000001
2014-05-05 11:38:54,980 INFO org.apache.hadoop.yarn.server.resourcemanager.rmapp.attempt.RMAppAttemptImpl: appattempt_1399289015992_0001_000001 State change from ALLOCATED to LAUNCHED
2014-05-05 11:38:55,487 INFO org.apache.hadoop.yarn.server.resourcemanager.rmcontainer.RMContainerImpl: container_1399289015992_0001_01_000001 Container Transitioned from ACQUIRED to RUNNING
2014-05-05 11:39:04,356 INFO SecurityLogger.org.apache.hadoop.ipc.Server: Auth successful for appattempt_1399289015992_0001_000001 (auth:SIMPLE)
2014-05-05 11:39:04,361 INFO org.apache.hadoop.yarn.server.resourcemanager.ApplicationMasterService: AM registration appattempt_1399289015992_0001_000001
2014-05-05 11:39:04,362 INFO org.apache.hadoop.yarn.server.resourcemanager.RMAuditLogger: USER=ubuntu	IP=10.0.0.193	OPERATION=Register App Master	TARGET=ApplicationMasterService	RESULT=SUCCESS	APPID=application_1399289015992_0001	APPATTEMPTID=appattempt_1399289015992_0001_000001
2014-05-05 11:39:04,363 INFO org.apache.hadoop.yarn.server.resourcemanager.rmapp.attempt.RMAppAttemptImpl: appattempt_1399289015992_0001_000001 State change from LAUNCHED to RUNNING
2014-05-05 11:39:04,363 INFO org.apache.hadoop.yarn.server.resourcemanager.rmapp.RMAppImpl: application_1399289015992_0001 State change from ACCEPTED to RUNNING
2014-05-05 11:39:05,493 INFO org.apache.hadoop.yarn.server.resourcemanager.rmcontainer.RMContainerImpl: container_1399289015992_0001_01_000002 Container Transitioned from NEW to ALLOCATED
2014-05-05 11:39:05,493 INFO org.apache.hadoop.yarn.server.resourcemanager.RMAuditLogger: USER=ubuntu	OPERATION=AM Allocated Container	TARGET=SchedulerApp	RESULT=SUCCESS	APPID=application_1399289015992_0001	CONTAINERID=container_1399289015992_0001_01_000002
2014-05-05 11:39:05,493 INFO org.apache.hadoop.yarn.server.resourcemanager.scheduler.common.fica.FiCaSchedulerNode: Assigned container container_1399289015992_0001_01_000002 of capacity <memory:1024, vCores:1> on host ip-10-0-0-200.us-west-2.compute.internal:36991, which currently has 1 containers, <memory:1024, vCores:1> used and <memory:7168, vCores:7> available
2014-05-05 11:39:05,493 INFO org.apache.hadoop.yarn.server.resourcemanager.scheduler.capacity.LeafQueue: assignedContainer application=application_1399289015992_0001 container=Container: [ContainerId: container_1399289015992_0001_01_000002, NodeId: ip-10-0-0-200.us-west-2.compute.internal:36991, NodeHttpAddress: ip-10-0-0-200.us-west-2.compute.internal:8042, Resource: <memory:1024, vCores:1>, Priority: 20, Token: Token { kind: ContainerToken, service: 10.0.0.200:36991 }, ] containerId=container_1399289015992_0001_01_000002 queue=default: capacity=1.0, absoluteCapacity=1.0, usedResources=<memory:2048, vCores:1>usedCapacity=0.03125, absoluteUsedCapacity=0.03125, numApps=1, numContainers=1 usedCapacity=0.03125 absoluteUsedCapacity=0.03125 used=<memory:2048, vCores:1> cluster=<memory:65536, vCores:64>
2014-05-05 11:39:05,493 INFO org.apache.hadoop.yarn.server.resourcemanager.scheduler.capacity.ParentQueue: Re-sorting assigned queue: root.default stats: default: capacity=1.0, absoluteCapacity=1.0, usedResources=<memory:3072, vCores:2>usedCapacity=0.046875, absoluteUsedCapacity=0.046875, numApps=1, numContainers=2
2014-05-05 11:39:05,493 INFO org.apache.hadoop.yarn.server.resourcemanager.scheduler.capacity.ParentQueue: assignedContainer queue=root usedCapacity=0.046875 absoluteUsedCapacity=0.046875 used=<memory:3072, vCores:2> cluster=<memory:65536, vCores:64>
2014-05-05 11:39:05,494 INFO org.apache.hadoop.yarn.server.resourcemanager.rmcontainer.RMContainerImpl: container_1399289015992_0001_01_000003 Container Transitioned from NEW to ALLOCATED
2014-05-05 11:39:05,494 INFO org.apache.hadoop.yarn.server.resourcemanager.RMAuditLogger: USER=ubuntu	OPERATION=AM Allocated Container	TARGET=SchedulerApp	RESULT=SUCCESS	APPID=application_1399289015992_0001	CONTAINERID=container_1399289015992_0001_01_000003
2014-05-05 11:39:05,494 INFO org.apache.hadoop.yarn.server.resourcemanager.scheduler.common.fica.FiCaSchedulerNode: Assigned container container_1399289015992_0001_01_000003 of capacity <memory:1024, vCores:1> on host ip-10-0-0-200.us-west-2.compute.internal:36991, which currently has 2 containers, <memory:2048, vCores:2> used and <memory:6144, vCores:6> available
2014-05-05 11:39:05,494 INFO org.apache.hadoop.yarn.server.resourcemanager.scheduler.capacity.LeafQueue: assignedContainer application=application_1399289015992_0001 container=Container: [ContainerId: container_1399289015992_0001_01_000003, NodeId: ip-10-0-0-200.us-west-2.compute.internal:36991, NodeHttpAddress: ip-10-0-0-200.us-west-2.compute.internal:8042, Resource: <memory:1024, vCores:1>, Priority: 20, Token: Token { kind: ContainerToken, service: 10.0.0.200:36991 }, ] containerId=container_1399289015992_0001_01_000003 queue=default: capacity=1.0, absoluteCapacity=1.0, usedResources=<memory:3072, vCores:2>usedCapacity=0.046875, absoluteUsedCapacity=0.046875, numApps=1, numContainers=2 usedCapacity=0.046875 absoluteUsedCapacity=0.046875 used=<memory:3072, vCores:2> cluster=<memory:65536, vCores:64>
2014-05-05 11:39:05,494 INFO org.apache.hadoop.yarn.server.resourcemanager.scheduler.capacity.ParentQueue: Re-sorting assigned queue: root.default stats: default: capacity=1.0, absoluteCapacity=1.0, usedResources=<memory:4096, vCores:3>usedCapacity=0.0625, absoluteUsedCapacity=0.0625, numApps=1, numContainers=3
2014-05-05 11:39:05,494 INFO org.apache.hadoop.yarn.server.resourcemanager.scheduler.capacity.ParentQueue: assignedContainer queue=root usedCapacity=0.0625 absoluteUsedCapacity=0.0625 used=<memory:4096, vCores:3> cluster=<memory:65536, vCores:64>
2014-05-05 11:39:05,503 INFO org.apache.hadoop.yarn.server.resourcemanager.rmcontainer.RMContainerImpl: container_1399289015992_0001_01_000004 Container Transitioned from NEW to ALLOCATED
2014-05-05 11:39:05,503 INFO org.apache.hadoop.yarn.server.resourcemanager.RMAuditLogger: USER=ubuntu	OPERATION=AM Allocated Container	TARGET=SchedulerApp	RESULT=SUCCESS	APPID=application_1399289015992_0001	CONTAINERID=container_1399289015992_0001_01_000004
2014-05-05 11:39:05,503 INFO org.apache.hadoop.yarn.server.resourcemanager.scheduler.common.fica.FiCaSchedulerNode: Assigned container container_1399289015992_0001_01_000004 of capacity <memory:1024, vCores:1> on host ip-10-0-0-197.us-west-2.compute.internal:36720, which currently has 1 containers, <memory:1024, vCores:1> used and <memory:7168, vCores:7> available
2014-05-05 11:39:05,504 INFO org.apache.hadoop.yarn.server.resourcemanager.scheduler.capacity.LeafQueue: assignedContainer application=application_1399289015992_0001 container=Container: [ContainerId: container_1399289015992_0001_01_000004, NodeId: ip-10-0-0-197.us-west-2.compute.internal:36720, NodeHttpAddress: ip-10-0-0-197.us-west-2.compute.internal:8042, Resource: <memory:1024, vCores:1>, Priority: 20, Token: Token { kind: ContainerToken, service: 10.0.0.197:36720 }, ] containerId=container_1399289015992_0001_01_000004 queue=default: capacity=1.0, absoluteCapacity=1.0, usedResources=<memory:4096, vCores:3>usedCapacity=0.0625, absoluteUsedCapacity=0.0625, numApps=1, numContainers=3 usedCapacity=0.0625 absoluteUsedCapacity=0.0625 used=<memory:4096, vCores:3> cluster=<memory:65536, vCores:64>
2014-05-05 11:39:05,504 INFO org.apache.hadoop.yarn.server.resourcemanager.scheduler.capacity.ParentQueue: Re-sorting assigned queue: root.default stats: default: capacity=1.0, absoluteCapacity=1.0, usedResources=<memory:5120, vCores:4>usedCapacity=0.078125, absoluteUsedCapacity=0.078125, numApps=1, numContainers=4
2014-05-05 11:39:05,504 INFO org.apache.hadoop.yarn.server.resourcemanager.scheduler.capacity.ParentQueue: assignedContainer queue=root usedCapacity=0.078125 absoluteUsedCapacity=0.078125 used=<memory:5120, vCores:4> cluster=<memory:65536, vCores:64>
2014-05-05 11:39:05,555 INFO org.apache.hadoop.yarn.server.resourcemanager.rmcontainer.RMContainerImpl: container_1399289015992_0001_01_000005 Container Transitioned from NEW to ALLOCATED
2014-05-05 11:39:05,555 INFO org.apache.hadoop.yarn.server.resourcemanager.RMAuditLogger: USER=ubuntu	OPERATION=AM Allocated Container	TARGET=SchedulerApp	RESULT=SUCCESS	APPID=application_1399289015992_0001	CONTAINERID=container_1399289015992_0001_01_000005
2014-05-05 11:39:05,555 INFO org.apache.hadoop.yarn.server.resourcemanager.scheduler.common.fica.FiCaSchedulerNode: Assigned container container_1399289015992_0001_01_000005 of capacity <memory:1024, vCores:1> on host ip-10-0-0-199.us-west-2.compute.internal:36159, which currently has 1 containers, <memory:1024, vCores:1> used and <memory:7168, vCores:7> available
2014-05-05 11:39:05,555 INFO org.apache.hadoop.yarn.server.resourcemanager.scheduler.capacity.LeafQueue: assignedContainer application=application_1399289015992_0001 container=Container: [ContainerId: container_1399289015992_0001_01_000005, NodeId: ip-10-0-0-199.us-west-2.compute.internal:36159, NodeHttpAddress: ip-10-0-0-199.us-west-2.compute.internal:8042, Resource: <memory:1024, vCores:1>, Priority: 20, Token: Token { kind: ContainerToken, service: 10.0.0.199:36159 }, ] containerId=container_1399289015992_0001_01_000005 queue=default: capacity=1.0, absoluteCapacity=1.0, usedResources=<memory:5120, vCores:4>usedCapacity=0.078125, absoluteUsedCapacity=0.078125, numApps=1, numContainers=4 usedCapacity=0.078125 absoluteUsedCapacity=0.078125 used=<memory:5120, vCores:4> cluster=<memory:65536, vCores:64>
2014-05-05 11:39:05,555 INFO org.apache.hadoop.yarn.server.resourcemanager.scheduler.capacity.ParentQueue: Re-sorting assigned queue: root.default stats: default: capacity=1.0, absoluteCapacity=1.0, usedResources=<memory:6144, vCores:5>usedCapacity=0.09375, absoluteUsedCapacity=0.09375, numApps=1, numContainers=5
2014-05-05 11:39:05,555 INFO org.apache.hadoop.yarn.server.resourcemanager.scheduler.capacity.ParentQueue: assignedContainer queue=root usedCapacity=0.09375 absoluteUsedCapacity=0.09375 used=<memory:6144, vCores:5> cluster=<memory:65536, vCores:64>
2014-05-05 11:39:06,475 INFO org.apache.hadoop.yarn.server.resourcemanager.rmcontainer.RMContainerImpl: container_1399289015992_0001_01_000002 Container Transitioned from ALLOCATED to ACQUIRED
2014-05-05 11:39:06,476 INFO org.apache.hadoop.yarn.server.resourcemanager.rmcontainer.RMContainerImpl: container_1399289015992_0001_01_000003 Container Transitioned from ALLOCATED to ACQUIRED
2014-05-05 11:39:06,476 INFO org.apache.hadoop.yarn.server.resourcemanager.rmcontainer.RMContainerImpl: container_1399289015992_0001_01_000004 Container Transitioned from ALLOCATED to ACQUIRED
2014-05-05 11:39:06,476 INFO org.apache.hadoop.yarn.server.resourcemanager.rmcontainer.RMContainerImpl: container_1399289015992_0001_01_000005 Container Transitioned from ALLOCATED to ACQUIRED
2014-05-05 11:39:07,498 INFO org.apache.hadoop.yarn.server.resourcemanager.scheduler.AppSchedulingInfo: checking for deactivate... 
2014-05-05 11:39:07,533 INFO org.apache.hadoop.yarn.server.resourcemanager.rmcontainer.RMContainerImpl: container_1399289015992_0001_01_000004 Container Transitioned from ACQUIRED to RUNNING
2014-05-05 11:39:07,537 INFO org.apache.hadoop.yarn.server.resourcemanager.rmcontainer.RMContainerImpl: container_1399289015992_0001_01_000002 Container Transitioned from ACQUIRED to RUNNING
2014-05-05 11:39:07,537 INFO org.apache.hadoop.yarn.server.resourcemanager.rmcontainer.RMContainerImpl: container_1399289015992_0001_01_000003 Container Transitioned from ACQUIRED to RUNNING
2014-05-05 11:39:07,595 INFO org.apache.hadoop.yarn.server.resourcemanager.rmcontainer.RMContainerImpl: container_1399289015992_0001_01_000005 Container Transitioned from ACQUIRED to RUNNING
2014-05-05 11:39:21,152 INFO org.apache.hadoop.yarn.server.resourcemanager.rmcontainer.RMContainerImpl: container_1399289015992_0001_01_000004 Container Transitioned from RUNNING to COMPLETED
2014-05-05 11:39:21,152 INFO org.apache.hadoop.yarn.server.resourcemanager.scheduler.common.fica.FiCaSchedulerApp: Completed container: container_1399289015992_0001_01_000004 in state: COMPLETED event:FINISHED
2014-05-05 11:39:21,152 INFO org.apache.hadoop.yarn.server.resourcemanager.RMAuditLogger: USER=ubuntu	OPERATION=AM Released Container	TARGET=SchedulerApp	RESULT=SUCCESS	APPID=application_1399289015992_0001	CONTAINERID=container_1399289015992_0001_01_000004
2014-05-05 11:39:21,152 INFO org.apache.hadoop.yarn.server.resourcemanager.scheduler.common.fica.FiCaSchedulerNode: Released container container_1399289015992_0001_01_000004 of capacity <memory:1024, vCores:1> on host ip-10-0-0-197.us-west-2.compute.internal:36720, which currently has 0 containers, <memory:0, vCores:0> used and <memory:8192, vCores:8> available, release resources=true
2014-05-05 11:39:21,152 INFO org.apache.hadoop.yarn.server.resourcemanager.scheduler.capacity.LeafQueue: default used=<memory:5120, vCores:4> numContainers=4 user=ubuntu user-resources=<memory:5120, vCores:4>
2014-05-05 11:39:21,152 INFO org.apache.hadoop.yarn.server.resourcemanager.scheduler.capacity.LeafQueue: completedContainer container=Container: [ContainerId: container_1399289015992_0001_01_000004, NodeId: ip-10-0-0-197.us-west-2.compute.internal:36720, NodeHttpAddress: ip-10-0-0-197.us-west-2.compute.internal:8042, Resource: <memory:1024, vCores:1>, Priority: 20, Token: Token { kind: ContainerToken, service: 10.0.0.197:36720 }, ] resource=<memory:1024, vCores:1> queue=default: capacity=1.0, absoluteCapacity=1.0, usedResources=<memory:5120, vCores:4>usedCapacity=0.078125, absoluteUsedCapacity=0.078125, numApps=1, numContainers=4 usedCapacity=0.078125 absoluteUsedCapacity=0.078125 used=<memory:5120, vCores:4> cluster=<memory:65536, vCores:64>
2014-05-05 11:39:21,152 INFO org.apache.hadoop.yarn.server.resourcemanager.scheduler.capacity.ParentQueue: completedContainer queue=root usedCapacity=0.078125 absoluteUsedCapacity=0.078125 used=<memory:5120, vCores:4> cluster=<memory:65536, vCores:64>
2014-05-05 11:39:21,153 INFO org.apache.hadoop.yarn.server.resourcemanager.scheduler.capacity.ParentQueue: Re-sorting completed queue: root.default stats: default: capacity=1.0, absoluteCapacity=1.0, usedResources=<memory:5120, vCores:4>usedCapacity=0.078125, absoluteUsedCapacity=0.078125, numApps=1, numContainers=4
2014-05-05 11:39:21,153 INFO org.apache.hadoop.yarn.server.resourcemanager.scheduler.capacity.CapacityScheduler: Application appattempt_1399289015992_0001_000001 released container container_1399289015992_0001_01_000004 on node: host: ip-10-0-0-197.us-west-2.compute.internal:36720 #containers=0 available=8192 used=0 with event: FINISHED
2014-05-05 11:39:21,556 INFO org.apache.hadoop.yarn.server.resourcemanager.rmcontainer.RMContainerImpl: container_1399289015992_0001_01_000006 Container Transitioned from NEW to ALLOCATED
2014-05-05 11:39:21,556 INFO org.apache.hadoop.yarn.server.resourcemanager.RMAuditLogger: USER=ubuntu	OPERATION=AM Allocated Container	TARGET=SchedulerApp	RESULT=SUCCESS	APPID=application_1399289015992_0001	CONTAINERID=container_1399289015992_0001_01_000006
2014-05-05 11:39:21,556 INFO org.apache.hadoop.yarn.server.resourcemanager.scheduler.common.fica.FiCaSchedulerNode: Assigned container container_1399289015992_0001_01_000006 of capacity <memory:1024, vCores:1> on host ip-10-0-0-193.us-west-2.compute.internal:60686, which currently has 2 containers, <memory:3072, vCores:2> used and <memory:5120, vCores:6> available
2014-05-05 11:39:21,557 INFO org.apache.hadoop.yarn.server.resourcemanager.scheduler.capacity.LeafQueue: assignedContainer application=application_1399289015992_0001 container=Container: [ContainerId: container_1399289015992_0001_01_000006, NodeId: ip-10-0-0-193.us-west-2.compute.internal:60686, NodeHttpAddress: ip-10-0-0-193.us-west-2.compute.internal:8042, Resource: <memory:1024, vCores:1>, Priority: 10, Token: Token { kind: ContainerToken, service: 10.0.0.193:60686 }, ] containerId=container_1399289015992_0001_01_000006 queue=default: capacity=1.0, absoluteCapacity=1.0, usedResources=<memory:5120, vCores:4>usedCapacity=0.078125, absoluteUsedCapacity=0.078125, numApps=1, numContainers=4 usedCapacity=0.078125 absoluteUsedCapacity=0.078125 used=<memory:5120, vCores:4> cluster=<memory:65536, vCores:64>
2014-05-05 11:39:21,557 INFO org.apache.hadoop.yarn.server.resourcemanager.scheduler.capacity.ParentQueue: Re-sorting assigned queue: root.default stats: default: capacity=1.0, absoluteCapacity=1.0, usedResources=<memory:6144, vCores:5>usedCapacity=0.09375, absoluteUsedCapacity=0.09375, numApps=1, numContainers=5
2014-05-05 11:39:21,557 INFO org.apache.hadoop.yarn.server.resourcemanager.scheduler.capacity.ParentQueue: assignedContainer queue=root usedCapacity=0.09375 absoluteUsedCapacity=0.09375 used=<memory:6144, vCores:5> cluster=<memory:65536, vCores:64>
2014-05-05 11:39:21,577 INFO org.apache.hadoop.yarn.server.resourcemanager.rmcontainer.RMContainerImpl: container_1399289015992_0001_01_000007 Container Transitioned from NEW to ALLOCATED
2014-05-05 11:39:21,577 INFO org.apache.hadoop.yarn.server.resourcemanager.RMAuditLogger: USER=ubuntu	OPERATION=AM Allocated Container	TARGET=SchedulerApp	RESULT=SUCCESS	APPID=application_1399289015992_0001	CONTAINERID=container_1399289015992_0001_01_000007
2014-05-05 11:39:21,578 INFO org.apache.hadoop.yarn.server.resourcemanager.scheduler.common.fica.FiCaSchedulerNode: Assigned container container_1399289015992_0001_01_000007 of capacity <memory:1024, vCores:1> on host ip-10-0-0-196.us-west-2.compute.internal:47357, which currently has 1 containers, <memory:1024, vCores:1> used and <memory:7168, vCores:7> available
2014-05-05 11:39:21,578 INFO org.apache.hadoop.yarn.server.resourcemanager.scheduler.capacity.LeafQueue: assignedContainer application=application_1399289015992_0001 container=Container: [ContainerId: container_1399289015992_0001_01_000007, NodeId: ip-10-0-0-196.us-west-2.compute.internal:47357, NodeHttpAddress: ip-10-0-0-196.us-west-2.compute.internal:8042, Resource: <memory:1024, vCores:1>, Priority: 10, Token: Token { kind: ContainerToken, service: 10.0.0.196:47357 }, ] containerId=container_1399289015992_0001_01_000007 queue=default: capacity=1.0, absoluteCapacity=1.0, usedResources=<memory:6144, vCores:5>usedCapacity=0.09375, absoluteUsedCapacity=0.09375, numApps=1, numContainers=5 usedCapacity=0.09375 absoluteUsedCapacity=0.09375 used=<memory:6144, vCores:5> cluster=<memory:65536, vCores:64>
2014-05-05 11:39:21,578 INFO org.apache.hadoop.yarn.server.resourcemanager.scheduler.capacity.ParentQueue: Re-sorting assigned queue: root.default stats: default: capacity=1.0, absoluteCapacity=1.0, usedResources=<memory:7168, vCores:6>usedCapacity=0.109375, absoluteUsedCapacity=0.109375, numApps=1, numContainers=6
2014-05-05 11:39:21,578 INFO org.apache.hadoop.yarn.server.resourcemanager.scheduler.capacity.ParentQueue: assignedContainer queue=root usedCapacity=0.109375 absoluteUsedCapacity=0.109375 used=<memory:7168, vCores:6> cluster=<memory:65536, vCores:64>
2014-05-05 11:39:21,629 INFO org.apache.hadoop.yarn.server.resourcemanager.rmcontainer.RMContainerImpl: container_1399289015992_0001_01_000008 Container Transitioned from NEW to ALLOCATED
2014-05-05 11:39:21,629 INFO org.apache.hadoop.yarn.server.resourcemanager.RMAuditLogger: USER=ubuntu	OPERATION=AM Allocated Container	TARGET=SchedulerApp	RESULT=SUCCESS	APPID=application_1399289015992_0001	CONTAINERID=container_1399289015992_0001_01_000008
2014-05-05 11:39:21,629 INFO org.apache.hadoop.yarn.server.resourcemanager.scheduler.common.fica.FiCaSchedulerNode: Assigned container container_1399289015992_0001_01_000008 of capacity <memory:1024, vCores:1> on host ip-10-0-0-200.us-west-2.compute.internal:36991, which currently has 3 containers, <memory:3072, vCores:3> used and <memory:5120, vCores:5> available
2014-05-05 11:39:21,629 INFO org.apache.hadoop.yarn.server.resourcemanager.scheduler.capacity.LeafQueue: assignedContainer application=application_1399289015992_0001 container=Container: [ContainerId: container_1399289015992_0001_01_000008, NodeId: ip-10-0-0-200.us-west-2.compute.internal:36991, NodeHttpAddress: ip-10-0-0-200.us-west-2.compute.internal:8042, Resource: <memory:1024, vCores:1>, Priority: 10, Token: Token { kind: ContainerToken, service: 10.0.0.200:36991 }, ] containerId=container_1399289015992_0001_01_000008 queue=default: capacity=1.0, absoluteCapacity=1.0, usedResources=<memory:7168, vCores:6>usedCapacity=0.109375, absoluteUsedCapacity=0.109375, numApps=1, numContainers=6 usedCapacity=0.109375 absoluteUsedCapacity=0.109375 used=<memory:7168, vCores:6> cluster=<memory:65536, vCores:64>
2014-05-05 11:39:21,629 INFO org.apache.hadoop.yarn.server.resourcemanager.scheduler.capacity.ParentQueue: Re-sorting assigned queue: root.default stats: default: capacity=1.0, absoluteCapacity=1.0, usedResources=<memory:8192, vCores:7>usedCapacity=0.125, absoluteUsedCapacity=0.125, numApps=1, numContainers=7
2014-05-05 11:39:21,629 INFO org.apache.hadoop.yarn.server.resourcemanager.scheduler.capacity.ParentQueue: assignedContainer queue=root usedCapacity=0.125 absoluteUsedCapacity=0.125 used=<memory:8192, vCores:7> cluster=<memory:65536, vCores:64>
2014-05-05 11:39:21,727 INFO org.apache.hadoop.yarn.server.resourcemanager.rmcontainer.RMContainerImpl: container_1399289015992_0001_01_000009 Container Transitioned from NEW to ALLOCATED
2014-05-05 11:39:21,727 INFO org.apache.hadoop.yarn.server.resourcemanager.RMAuditLogger: USER=ubuntu	OPERATION=AM Allocated Container	TARGET=SchedulerApp	RESULT=SUCCESS	APPID=application_1399289015992_0001	CONTAINERID=container_1399289015992_0001_01_000009
2014-05-05 11:39:21,727 INFO org.apache.hadoop.yarn.server.resourcemanager.scheduler.common.fica.FiCaSchedulerNode: Assigned container container_1399289015992_0001_01_000009 of capacity <memory:1024, vCores:1> on host ip-10-0-0-198.us-west-2.compute.internal:60935, which currently has 1 containers, <memory:1024, vCores:1> used and <memory:7168, vCores:7> available
2014-05-05 11:39:21,727 INFO org.apache.hadoop.yarn.server.resourcemanager.scheduler.capacity.LeafQueue: assignedContainer application=application_1399289015992_0001 container=Container: [ContainerId: container_1399289015992_0001_01_000009, NodeId: ip-10-0-0-198.us-west-2.compute.internal:60935, NodeHttpAddress: ip-10-0-0-198.us-west-2.compute.internal:8042, Resource: <memory:1024, vCores:1>, Priority: 10, Token: Token { kind: ContainerToken, service: 10.0.0.198:60935 }, ] containerId=container_1399289015992_0001_01_000009 queue=default: capacity=1.0, absoluteCapacity=1.0, usedResources=<memory:8192, vCores:7>usedCapacity=0.125, absoluteUsedCapacity=0.125, numApps=1, numContainers=7 usedCapacity=0.125 absoluteUsedCapacity=0.125 used=<memory:8192, vCores:7> cluster=<memory:65536, vCores:64>
2014-05-05 11:39:21,728 INFO org.apache.hadoop.yarn.server.resourcemanager.scheduler.capacity.ParentQueue: Re-sorting assigned queue: root.default stats: default: capacity=1.0, absoluteCapacity=1.0, usedResources=<memory:9216, vCores:8>usedCapacity=0.140625, absoluteUsedCapacity=0.140625, numApps=1, numContainers=8
2014-05-05 11:39:21,728 INFO org.apache.hadoop.yarn.server.resourcemanager.scheduler.capacity.ParentQueue: assignedContainer queue=root usedCapacity=0.140625 absoluteUsedCapacity=0.140625 used=<memory:9216, vCores:8> cluster=<memory:65536, vCores:64>
2014-05-05 11:39:21,786 INFO org.apache.hadoop.yarn.server.resourcemanager.rmcontainer.RMContainerImpl: container_1399289015992_0001_01_000005 Container Transitioned from RUNNING to COMPLETED
2014-05-05 11:39:21,786 INFO org.apache.hadoop.yarn.server.resourcemanager.scheduler.common.fica.FiCaSchedulerApp: Completed container: container_1399289015992_0001_01_000005 in state: COMPLETED event:FINISHED
2014-05-05 11:39:21,786 INFO org.apache.hadoop.yarn.server.resourcemanager.RMAuditLogger: USER=ubuntu	OPERATION=AM Released Container	TARGET=SchedulerApp	RESULT=SUCCESS	APPID=application_1399289015992_0001	CONTAINERID=container_1399289015992_0001_01_000005
2014-05-05 11:39:21,786 INFO org.apache.hadoop.yarn.server.resourcemanager.scheduler.common.fica.FiCaSchedulerNode: Released container container_1399289015992_0001_01_000005 of capacity <memory:1024, vCores:1> on host ip-10-0-0-199.us-west-2.compute.internal:36159, which currently has 0 containers, <memory:0, vCores:0> used and <memory:8192, vCores:8> available, release resources=true
2014-05-05 11:39:21,786 INFO org.apache.hadoop.yarn.server.resourcemanager.scheduler.capacity.LeafQueue: default used=<memory:8192, vCores:7> numContainers=7 user=ubuntu user-resources=<memory:8192, vCores:7>
2014-05-05 11:39:21,786 INFO org.apache.hadoop.yarn.server.resourcemanager.scheduler.capacity.LeafQueue: completedContainer container=Container: [ContainerId: container_1399289015992_0001_01_000005, NodeId: ip-10-0-0-199.us-west-2.compute.internal:36159, NodeHttpAddress: ip-10-0-0-199.us-west-2.compute.internal:8042, Resource: <memory:1024, vCores:1>, Priority: 20, Token: Token { kind: ContainerToken, service: 10.0.0.199:36159 }, ] resource=<memory:1024, vCores:1> queue=default: capacity=1.0, absoluteCapacity=1.0, usedResources=<memory:8192, vCores:7>usedCapacity=0.125, absoluteUsedCapacity=0.125, numApps=1, numContainers=7 usedCapacity=0.125 absoluteUsedCapacity=0.125 used=<memory:8192, vCores:7> cluster=<memory:65536, vCores:64>
2014-05-05 11:39:21,786 INFO org.apache.hadoop.yarn.server.resourcemanager.scheduler.capacity.ParentQueue: completedContainer queue=root usedCapacity=0.125 absoluteUsedCapacity=0.125 used=<memory:8192, vCores:7> cluster=<memory:65536, vCores:64>
2014-05-05 11:39:21,786 INFO org.apache.hadoop.yarn.server.resourcemanager.scheduler.capacity.ParentQueue: Re-sorting completed queue: root.default stats: default: capacity=1.0, absoluteCapacity=1.0, usedResources=<memory:8192, vCores:7>usedCapacity=0.125, absoluteUsedCapacity=0.125, numApps=1, numContainers=7
2014-05-05 11:39:21,787 INFO org.apache.hadoop.yarn.server.resourcemanager.scheduler.capacity.CapacityScheduler: Application appattempt_1399289015992_0001_000001 released container container_1399289015992_0001_01_000005 on node: host: ip-10-0-0-199.us-west-2.compute.internal:36159 #containers=0 available=8192 used=0 with event: FINISHED
2014-05-05 11:39:21,787 INFO org.apache.hadoop.yarn.server.resourcemanager.rmcontainer.RMContainerImpl: container_1399289015992_0001_01_000010 Container Transitioned from NEW to ALLOCATED
2014-05-05 11:39:21,787 INFO org.apache.hadoop.yarn.server.resourcemanager.RMAuditLogger: USER=ubuntu	OPERATION=AM Allocated Container	TARGET=SchedulerApp	RESULT=SUCCESS	APPID=application_1399289015992_0001	CONTAINERID=container_1399289015992_0001_01_000010
2014-05-05 11:39:21,787 INFO org.apache.hadoop.yarn.server.resourcemanager.scheduler.common.fica.FiCaSchedulerNode: Assigned container container_1399289015992_0001_01_000010 of capacity <memory:1024, vCores:1> on host ip-10-0-0-199.us-west-2.compute.internal:36159, which currently has 1 containers, <memory:1024, vCores:1> used and <memory:7168, vCores:7> available
2014-05-05 11:39:21,787 INFO org.apache.hadoop.yarn.server.resourcemanager.scheduler.capacity.LeafQueue: assignedContainer application=application_1399289015992_0001 container=Container: [ContainerId: container_1399289015992_0001_01_000010, NodeId: ip-10-0-0-199.us-west-2.compute.internal:36159, NodeHttpAddress: ip-10-0-0-199.us-west-2.compute.internal:8042, Resource: <memory:1024, vCores:1>, Priority: 10, Token: Token { kind: ContainerToken, service: 10.0.0.199:36159 }, ] containerId=container_1399289015992_0001_01_000010 queue=default: capacity=1.0, absoluteCapacity=1.0, usedResources=<memory:8192, vCores:7>usedCapacity=0.125, absoluteUsedCapacity=0.125, numApps=1, numContainers=7 usedCapacity=0.125 absoluteUsedCapacity=0.125 used=<memory:8192, vCores:7> cluster=<memory:65536, vCores:64>
2014-05-05 11:39:21,787 INFO org.apache.hadoop.yarn.server.resourcemanager.scheduler.capacity.ParentQueue: Re-sorting assigned queue: root.default stats: default: capacity=1.0, absoluteCapacity=1.0, usedResources=<memory:9216, vCores:8>usedCapacity=0.140625, absoluteUsedCapacity=0.140625, numApps=1, numContainers=8
2014-05-05 11:39:21,787 INFO org.apache.hadoop.yarn.server.resourcemanager.scheduler.capacity.ParentQueue: assignedContainer queue=root usedCapacity=0.140625 absoluteUsedCapacity=0.140625 used=<memory:9216, vCores:8> cluster=<memory:65536, vCores:64>
2014-05-05 11:39:22,153 INFO org.apache.hadoop.yarn.server.resourcemanager.rmcontainer.RMContainerImpl: container_1399289015992_0001_01_000011 Container Transitioned from NEW to ALLOCATED
2014-05-05 11:39:22,153 INFO org.apache.hadoop.yarn.server.resourcemanager.RMAuditLogger: USER=ubuntu	OPERATION=AM Allocated Container	TARGET=SchedulerApp	RESULT=SUCCESS	APPID=application_1399289015992_0001	CONTAINERID=container_1399289015992_0001_01_000011
2014-05-05 11:39:22,153 INFO org.apache.hadoop.yarn.server.resourcemanager.scheduler.common.fica.FiCaSchedulerNode: Assigned container container_1399289015992_0001_01_000011 of capacity <memory:1024, vCores:1> on host ip-10-0-0-197.us-west-2.compute.internal:36720, which currently has 1 containers, <memory:1024, vCores:1> used and <memory:7168, vCores:7> available
2014-05-05 11:39:22,153 INFO org.apache.hadoop.yarn.server.resourcemanager.scheduler.capacity.LeafQueue: assignedContainer application=application_1399289015992_0001 container=Container: [ContainerId: container_1399289015992_0001_01_000011, NodeId: ip-10-0-0-197.us-west-2.compute.internal:36720, NodeHttpAddress: ip-10-0-0-197.us-west-2.compute.internal:8042, Resource: <memory:1024, vCores:1>, Priority: 10, Token: Token { kind: ContainerToken, service: 10.0.0.197:36720 }, ] containerId=container_1399289015992_0001_01_000011 queue=default: capacity=1.0, absoluteCapacity=1.0, usedResources=<memory:9216, vCores:8>usedCapacity=0.140625, absoluteUsedCapacity=0.140625, numApps=1, numContainers=8 usedCapacity=0.140625 absoluteUsedCapacity=0.140625 used=<memory:9216, vCores:8> cluster=<memory:65536, vCores:64>
2014-05-05 11:39:22,153 INFO org.apache.hadoop.yarn.server.resourcemanager.scheduler.capacity.ParentQueue: Re-sorting assigned queue: root.default stats: default: capacity=1.0, absoluteCapacity=1.0, usedResources=<memory:10240, vCores:9>usedCapacity=0.15625, absoluteUsedCapacity=0.15625, numApps=1, numContainers=9
2014-05-05 11:39:22,153 INFO org.apache.hadoop.yarn.server.resourcemanager.scheduler.capacity.ParentQueue: assignedContainer queue=root usedCapacity=0.15625 absoluteUsedCapacity=0.15625 used=<memory:10240, vCores:9> cluster=<memory:65536, vCores:64>
2014-05-05 11:39:22,547 INFO org.apache.hadoop.yarn.server.resourcemanager.rmcontainer.RMContainerImpl: container_1399289015992_0001_01_000006 Container Transitioned from ALLOCATED to ACQUIRED
2014-05-05 11:39:22,547 INFO org.apache.hadoop.yarn.server.resourcemanager.rmcontainer.RMContainerImpl: container_1399289015992_0001_01_000007 Container Transitioned from ALLOCATED to ACQUIRED
2014-05-05 11:39:22,548 INFO org.apache.hadoop.yarn.server.resourcemanager.rmcontainer.RMContainerImpl: container_1399289015992_0001_01_000008 Container Transitioned from ALLOCATED to ACQUIRED
2014-05-05 11:39:22,548 INFO org.apache.hadoop.yarn.server.resourcemanager.rmcontainer.RMContainerImpl: container_1399289015992_0001_01_000009 Container Transitioned from ALLOCATED to ACQUIRED
2014-05-05 11:39:22,548 INFO org.apache.hadoop.yarn.server.resourcemanager.rmcontainer.RMContainerImpl: container_1399289015992_0001_01_000010 Container Transitioned from ALLOCATED to ACQUIRED
2014-05-05 11:39:22,549 INFO org.apache.hadoop.yarn.server.resourcemanager.rmcontainer.RMContainerImpl: container_1399289015992_0001_01_000011 Container Transitioned from ALLOCATED to ACQUIRED
2014-05-05 11:39:22,635 INFO org.apache.hadoop.yarn.server.resourcemanager.rmcontainer.RMContainerImpl: container_1399289015992_0001_01_000008 Container Transitioned from ACQUIRED to RUNNING
2014-05-05 11:39:22,788 INFO org.apache.hadoop.yarn.server.resourcemanager.rmcontainer.RMContainerImpl: container_1399289015992_0001_01_000010 Container Transitioned from ACQUIRED to RUNNING
2014-05-05 11:39:23,175 INFO org.apache.hadoop.yarn.server.resourcemanager.rmcontainer.RMContainerImpl: container_1399289015992_0001_01_000011 Container Transitioned from ACQUIRED to RUNNING
2014-05-05 11:39:23,561 INFO org.apache.hadoop.yarn.server.resourcemanager.rmcontainer.RMContainerImpl: container_1399289015992_0001_01_000006 Container Transitioned from ACQUIRED to RUNNING
2014-05-05 11:39:23,592 INFO org.apache.hadoop.yarn.server.resourcemanager.rmcontainer.RMContainerImpl: container_1399289015992_0001_01_000007 Container Transitioned from ACQUIRED to RUNNING
2014-05-05 11:39:23,593 INFO org.apache.hadoop.yarn.server.resourcemanager.rmcontainer.RMContainerImpl: container_1399289015992_0001_01_000012 Container Transitioned from NEW to ALLOCATED
2014-05-05 11:39:23,593 INFO org.apache.hadoop.yarn.server.resourcemanager.RMAuditLogger: USER=ubuntu	OPERATION=AM Allocated Container	TARGET=SchedulerApp	RESULT=SUCCESS	APPID=application_1399289015992_0001	CONTAINERID=container_1399289015992_0001_01_000012
2014-05-05 11:39:23,593 INFO org.apache.hadoop.yarn.server.resourcemanager.scheduler.common.fica.FiCaSchedulerNode: Assigned container container_1399289015992_0001_01_000012 of capacity <memory:1024, vCores:1> on host ip-10-0-0-196.us-west-2.compute.internal:47357, which currently has 2 containers, <memory:2048, vCores:2> used and <memory:6144, vCores:6> available
2014-05-05 11:39:23,593 INFO org.apache.hadoop.yarn.server.resourcemanager.scheduler.capacity.LeafQueue: assignedContainer application=application_1399289015992_0001 container=Container: [ContainerId: container_1399289015992_0001_01_000012, NodeId: ip-10-0-0-196.us-west-2.compute.internal:47357, NodeHttpAddress: ip-10-0-0-196.us-west-2.compute.internal:8042, Resource: <memory:1024, vCores:1>, Priority: 20, Token: Token { kind: ContainerToken, service: 10.0.0.196:47357 }, ] containerId=container_1399289015992_0001_01_000012 queue=default: capacity=1.0, absoluteCapacity=1.0, usedResources=<memory:10240, vCores:9>usedCapacity=0.15625, absoluteUsedCapacity=0.15625, numApps=1, numContainers=9 usedCapacity=0.15625 absoluteUsedCapacity=0.15625 used=<memory:10240, vCores:9> cluster=<memory:65536, vCores:64>
2014-05-05 11:39:23,594 INFO org.apache.hadoop.yarn.server.resourcemanager.scheduler.capacity.ParentQueue: Re-sorting assigned queue: root.default stats: default: capacity=1.0, absoluteCapacity=1.0, usedResources=<memory:11264, vCores:10>usedCapacity=0.171875, absoluteUsedCapacity=0.171875, numApps=1, numContainers=10
2014-05-05 11:39:23,594 INFO org.apache.hadoop.yarn.server.resourcemanager.scheduler.capacity.ParentQueue: assignedContainer queue=root usedCapacity=0.171875 absoluteUsedCapacity=0.171875 used=<memory:11264, vCores:10> cluster=<memory:65536, vCores:64>
2014-05-05 11:39:23,743 INFO org.apache.hadoop.yarn.server.resourcemanager.rmcontainer.RMContainerImpl: container_1399289015992_0001_01_000009 Container Transitioned from ACQUIRED to RUNNING
2014-05-05 11:39:24,562 INFO org.apache.hadoop.yarn.server.resourcemanager.rmcontainer.RMContainerImpl: container_1399289015992_0001_01_000012 Container Transitioned from ALLOCATED to ACQUIRED
2014-05-05 11:39:24,595 INFO org.apache.hadoop.yarn.server.resourcemanager.rmcontainer.RMContainerImpl: container_1399289015992_0001_01_000012 Container Transitioned from ACQUIRED to RUNNING
2014-05-05 11:39:25,567 INFO org.apache.hadoop.yarn.server.resourcemanager.scheduler.AppSchedulingInfo: checking for deactivate... 
2014-05-05 11:39:26,036 INFO org.apache.hadoop.yarn.server.resourcemanager.rmcontainer.RMContainerImpl: container_1399289015992_0001_01_000003 Container Transitioned from RUNNING to COMPLETED
2014-05-05 11:39:26,036 INFO org.apache.hadoop.yarn.server.resourcemanager.scheduler.common.fica.FiCaSchedulerApp: Completed container: container_1399289015992_0001_01_000003 in state: COMPLETED event:FINISHED
2014-05-05 11:39:26,036 INFO org.apache.hadoop.yarn.server.resourcemanager.RMAuditLogger: USER=ubuntu	OPERATION=AM Released Container	TARGET=SchedulerApp	RESULT=SUCCESS	APPID=application_1399289015992_0001	CONTAINERID=container_1399289015992_0001_01_000003
2014-05-05 11:39:26,036 INFO org.apache.hadoop.yarn.server.resourcemanager.scheduler.common.fica.FiCaSchedulerNode: Released container container_1399289015992_0001_01_000003 of capacity <memory:1024, vCores:1> on host ip-10-0-0-200.us-west-2.compute.internal:36991, which currently has 2 containers, <memory:2048, vCores:2> used and <memory:6144, vCores:6> available, release resources=true
2014-05-05 11:39:26,037 INFO org.apache.hadoop.yarn.server.resourcemanager.scheduler.capacity.LeafQueue: default used=<memory:10240, vCores:9> numContainers=9 user=ubuntu user-resources=<memory:10240, vCores:9>
2014-05-05 11:39:26,037 INFO org.apache.hadoop.yarn.server.resourcemanager.scheduler.capacity.LeafQueue: completedContainer container=Container: [ContainerId: container_1399289015992_0001_01_000003, NodeId: ip-10-0-0-200.us-west-2.compute.internal:36991, NodeHttpAddress: ip-10-0-0-200.us-west-2.compute.internal:8042, Resource: <memory:1024, vCores:1>, Priority: 20, Token: Token { kind: ContainerToken, service: 10.0.0.200:36991 }, ] resource=<memory:1024, vCores:1> queue=default: capacity=1.0, absoluteCapacity=1.0, usedResources=<memory:10240, vCores:9>usedCapacity=0.15625, absoluteUsedCapacity=0.15625, numApps=1, numContainers=9 usedCapacity=0.15625 absoluteUsedCapacity=0.15625 used=<memory:10240, vCores:9> cluster=<memory:65536, vCores:64>
2014-05-05 11:39:26,037 INFO org.apache.hadoop.yarn.server.resourcemanager.scheduler.capacity.ParentQueue: completedContainer queue=root usedCapacity=0.15625 absoluteUsedCapacity=0.15625 used=<memory:10240, vCores:9> cluster=<memory:65536, vCores:64>
2014-05-05 11:39:26,037 INFO org.apache.hadoop.yarn.server.resourcemanager.scheduler.capacity.ParentQueue: Re-sorting completed queue: root.default stats: default: capacity=1.0, absoluteCapacity=1.0, usedResources=<memory:10240, vCores:9>usedCapacity=0.15625, absoluteUsedCapacity=0.15625, numApps=1, numContainers=9
2014-05-05 11:39:26,037 INFO org.apache.hadoop.yarn.server.resourcemanager.scheduler.capacity.CapacityScheduler: Application appattempt_1399289015992_0001_000001 released container container_1399289015992_0001_01_000003 on node: host: ip-10-0-0-200.us-west-2.compute.internal:36991 #containers=2 available=6144 used=2048 with event: FINISHED
2014-05-05 11:39:32,221 INFO org.apache.hadoop.yarn.server.resourcemanager.rmcontainer.RMContainerImpl: container_1399289015992_0001_01_000012 Container Transitioned from RUNNING to COMPLETED
2014-05-05 11:39:32,221 INFO org.apache.hadoop.yarn.server.resourcemanager.scheduler.common.fica.FiCaSchedulerApp: Completed container: container_1399289015992_0001_01_000012 in state: COMPLETED event:FINISHED
2014-05-05 11:39:32,221 INFO org.apache.hadoop.yarn.server.resourcemanager.RMAuditLogger: USER=ubuntu	OPERATION=AM Released Container	TARGET=SchedulerApp	RESULT=SUCCESS	APPID=application_1399289015992_0001	CONTAINERID=container_1399289015992_0001_01_000012
2014-05-05 11:39:32,221 INFO org.apache.hadoop.yarn.server.resourcemanager.scheduler.common.fica.FiCaSchedulerNode: Released container container_1399289015992_0001_01_000012 of capacity <memory:1024, vCores:1> on host ip-10-0-0-196.us-west-2.compute.internal:47357, which currently has 1 containers, <memory:1024, vCores:1> used and <memory:7168, vCores:7> available, release resources=true
2014-05-05 11:39:32,221 INFO org.apache.hadoop.yarn.server.resourcemanager.scheduler.capacity.LeafQueue: default used=<memory:9216, vCores:8> numContainers=8 user=ubuntu user-resources=<memory:9216, vCores:8>
2014-05-05 11:39:32,222 INFO org.apache.hadoop.yarn.server.resourcemanager.scheduler.capacity.LeafQueue: completedContainer container=Container: [ContainerId: container_1399289015992_0001_01_000012, NodeId: ip-10-0-0-196.us-west-2.compute.internal:47357, NodeHttpAddress: ip-10-0-0-196.us-west-2.compute.internal:8042, Resource: <memory:1024, vCores:1>, Priority: 20, Token: Token { kind: ContainerToken, service: 10.0.0.196:47357 }, ] resource=<memory:1024, vCores:1> queue=default: capacity=1.0, absoluteCapacity=1.0, usedResources=<memory:9216, vCores:8>usedCapacity=0.140625, absoluteUsedCapacity=0.140625, numApps=1, numContainers=8 usedCapacity=0.140625 absoluteUsedCapacity=0.140625 used=<memory:9216, vCores:8> cluster=<memory:65536, vCores:64>
2014-05-05 11:39:32,222 INFO org.apache.hadoop.yarn.server.resourcemanager.scheduler.capacity.ParentQueue: completedContainer queue=root usedCapacity=0.140625 absoluteUsedCapacity=0.140625 used=<memory:9216, vCores:8> cluster=<memory:65536, vCores:64>
2014-05-05 11:39:32,222 INFO org.apache.hadoop.yarn.server.resourcemanager.scheduler.capacity.ParentQueue: Re-sorting completed queue: root.default stats: default: capacity=1.0, absoluteCapacity=1.0, usedResources=<memory:9216, vCores:8>usedCapacity=0.140625, absoluteUsedCapacity=0.140625, numApps=1, numContainers=8
2014-05-05 11:39:32,222 INFO org.apache.hadoop.yarn.server.resourcemanager.scheduler.capacity.CapacityScheduler: Application appattempt_1399289015992_0001_000001 released container container_1399289015992_0001_01_000012 on node: host: ip-10-0-0-196.us-west-2.compute.internal:47357 #containers=1 available=7168 used=1024 with event: FINISHED
2014-05-05 11:39:32,222 INFO org.apache.hadoop.yarn.server.resourcemanager.rmcontainer.RMContainerImpl: container_1399289015992_0001_01_000002 Container Transitioned from RUNNING to COMPLETED
2014-05-05 11:39:32,222 INFO org.apache.hadoop.yarn.server.resourcemanager.scheduler.common.fica.FiCaSchedulerApp: Completed container: container_1399289015992_0001_01_000002 in state: COMPLETED event:FINISHED
2014-05-05 11:39:32,222 INFO org.apache.hadoop.yarn.server.resourcemanager.RMAuditLogger: USER=ubuntu	OPERATION=AM Released Container	TARGET=SchedulerApp	RESULT=SUCCESS	APPID=application_1399289015992_0001	CONTAINERID=container_1399289015992_0001_01_000002
2014-05-05 11:39:32,223 INFO org.apache.hadoop.yarn.server.resourcemanager.scheduler.common.fica.FiCaSchedulerNode: Released container container_1399289015992_0001_01_000002 of capacity <memory:1024, vCores:1> on host ip-10-0-0-200.us-west-2.compute.internal:36991, which currently has 1 containers, <memory:1024, vCores:1> used and <memory:7168, vCores:7> available, release resources=true
2014-05-05 11:39:32,223 INFO org.apache.hadoop.yarn.server.resourcemanager.scheduler.capacity.LeafQueue: default used=<memory:8192, vCores:7> numContainers=7 user=ubuntu user-resources=<memory:8192, vCores:7>
2014-05-05 11:39:32,223 INFO org.apache.hadoop.yarn.server.resourcemanager.scheduler.capacity.LeafQueue: completedContainer container=Container: [ContainerId: container_1399289015992_0001_01_000002, NodeId: ip-10-0-0-200.us-west-2.compute.internal:36991, NodeHttpAddress: ip-10-0-0-200.us-west-2.compute.internal:8042, Resource: <memory:1024, vCores:1>, Priority: 20, Token: Token { kind: ContainerToken, service: 10.0.0.200:36991 }, ] resource=<memory:1024, vCores:1> queue=default: capacity=1.0, absoluteCapacity=1.0, usedResources=<memory:8192, vCores:7>usedCapacity=0.125, absoluteUsedCapacity=0.125, numApps=1, numContainers=7 usedCapacity=0.125 absoluteUsedCapacity=0.125 used=<memory:8192, vCores:7> cluster=<memory:65536, vCores:64>
2014-05-05 11:39:32,223 INFO org.apache.hadoop.yarn.server.resourcemanager.scheduler.capacity.ParentQueue: completedContainer queue=root usedCapacity=0.125 absoluteUsedCapacity=0.125 used=<memory:8192, vCores:7> cluster=<memory:65536, vCores:64>
2014-05-05 11:39:32,223 INFO org.apache.hadoop.yarn.server.resourcemanager.scheduler.capacity.ParentQueue: Re-sorting completed queue: root.default stats: default: capacity=1.0, absoluteCapacity=1.0, usedResources=<memory:8192, vCores:7>usedCapacity=0.125, absoluteUsedCapacity=0.125, numApps=1, numContainers=7
2014-05-05 11:39:32,223 INFO org.apache.hadoop.yarn.server.resourcemanager.scheduler.capacity.CapacityScheduler: Application appattempt_1399289015992_0001_000001 released container container_1399289015992_0001_01_000002 on node: host: ip-10-0-0-200.us-west-2.compute.internal:36991 #containers=1 available=7168 used=1024 with event: FINISHED
2014-05-05 11:40:55,427 INFO org.apache.hadoop.yarn.server.webproxy.WebAppProxyServlet: dr.who is accessing unchecked http://ip-10-0-0-193:45943/ which is the app master GUI of application_1399289015992_0001 owned by ubuntu
2014-05-05 11:40:57,473 INFO org.apache.hadoop.yarn.server.webproxy.WebAppProxyServlet: dr.who is accessing unchecked http://ip-10-0-0-193:45943/static/jquery/themes-1.9.1/base/jquery-ui.css which is the app master GUI of application_1399289015992_0001 owned by ubuntu
2014-05-05 11:40:57,472 INFO org.apache.hadoop.yarn.server.webproxy.WebAppProxyServlet: dr.who is accessing unchecked http://ip-10-0-0-193:45943/static/yarn.css which is the app master GUI of application_1399289015992_0001 owned by ubuntu
2014-05-05 11:40:57,475 INFO org.apache.hadoop.yarn.server.webproxy.WebAppProxyServlet: dr.who is accessing unchecked http://ip-10-0-0-193:45943/static/dt-1.9.4/css/jui-dt.css which is the app master GUI of application_1399289015992_0001 owned by ubuntu
2014-05-05 11:40:57,476 INFO org.apache.hadoop.yarn.server.webproxy.WebAppProxyServlet: dr.who is accessing unchecked http://ip-10-0-0-193:45943/static/dt-1.9.4/js/jquery.dataTables.min.js which is the app master GUI of application_1399289015992_0001 owned by ubuntu
2014-05-05 11:40:57,481 INFO org.apache.hadoop.yarn.server.webproxy.WebAppProxyServlet: dr.who is accessing unchecked http://ip-10-0-0-193:45943/static/jquery/jquery-1.8.2.min.js which is the app master GUI of application_1399289015992_0001 owned by ubuntu
2014-05-05 11:40:57,482 INFO org.apache.hadoop.yarn.server.webproxy.WebAppProxyServlet: dr.who is accessing unchecked http://ip-10-0-0-193:45943/static/jquery/jquery-ui-1.9.1.custom.min.js which is the app master GUI of application_1399289015992_0001 owned by ubuntu
2014-05-05 11:40:57,591 INFO org.apache.hadoop.yarn.server.webproxy.WebAppProxyServlet: dr.who is accessing unchecked http://ip-10-0-0-193:45943/static/yarn.dt.plugins.js which is the app master GUI of application_1399289015992_0001 owned by ubuntu
2014-05-05 11:40:57,845 INFO org.apache.hadoop.yarn.server.webproxy.WebAppProxyServlet: dr.who is accessing unchecked http://ip-10-0-0-193:45943/static/jquery/themes-1.9.1/base/images/ui-bg_flat_75_ffffff_40x100.png which is the app master GUI of application_1399289015992_0001 owned by ubuntu
2014-05-05 11:40:57,845 INFO org.apache.hadoop.yarn.server.webproxy.WebAppProxyServlet: dr.who is accessing unchecked http://ip-10-0-0-193:45943/static/jquery/themes-1.9.1/base/images/ui-bg_glass_95_fef1ec_1x400.png which is the app master GUI of application_1399289015992_0001 owned by ubuntu
2014-05-05 11:40:57,846 INFO org.apache.hadoop.yarn.server.webproxy.WebAppProxyServlet: dr.who is accessing unchecked http://ip-10-0-0-193:45943/static/jquery/themes-1.9.1/base/images/ui-bg_highlight-soft_75_cccccc_1x100.png which is the app master GUI of application_1399289015992_0001 owned by ubuntu
2014-05-05 11:40:57,861 INFO org.apache.hadoop.yarn.server.webproxy.WebAppProxyServlet: dr.who is accessing unchecked http://ip-10-0-0-193:45943/static/jquery/themes-1.9.1/base/images/ui-bg_glass_75_e6e6e6_1x400.png which is the app master GUI of application_1399289015992_0001 owned by ubuntu
2014-05-05 11:40:57,862 INFO org.apache.hadoop.yarn.server.webproxy.WebAppProxyServlet: dr.who is accessing unchecked http://ip-10-0-0-193:45943/static/jquery/themes-1.9.1/base/images/ui-bg_glass_65_ffffff_1x400.png which is the app master GUI of application_1399289015992_0001 owned by ubuntu
2014-05-05 11:40:57,865 INFO org.apache.hadoop.yarn.server.webproxy.WebAppProxyServlet: dr.who is accessing unchecked http://ip-10-0-0-193:45943/static/jquery/themes-1.9.1/base/images/ui-icons_888888_256x240.png which is the app master GUI of application_1399289015992_0001 owned by ubuntu
2014-05-05 11:40:57,930 INFO org.apache.hadoop.yarn.server.webproxy.WebAppProxyServlet: dr.who is accessing unchecked http://ip-10-0-0-193:45943/static/jquery/themes-1.9.1/base/images/ui-icons_454545_256x240.png which is the app master GUI of application_1399289015992_0001 owned by ubuntu
2014-05-05 11:40:59,727 INFO org.apache.hadoop.yarn.server.resourcemanager.rmcontainer.RMContainerImpl: container_1399289015992_0001_01_000006 Container Transitioned from RUNNING to COMPLETED
2014-05-05 11:40:59,727 INFO org.apache.hadoop.yarn.server.resourcemanager.scheduler.common.fica.FiCaSchedulerApp: Completed container: container_1399289015992_0001_01_000006 in state: COMPLETED event:FINISHED
2014-05-05 11:40:59,727 INFO org.apache.hadoop.yarn.server.resourcemanager.RMAuditLogger: USER=ubuntu	OPERATION=AM Released Container	TARGET=SchedulerApp	RESULT=SUCCESS	APPID=application_1399289015992_0001	CONTAINERID=container_1399289015992_0001_01_000006
2014-05-05 11:40:59,727 INFO org.apache.hadoop.yarn.server.resourcemanager.scheduler.common.fica.FiCaSchedulerNode: Released container container_1399289015992_0001_01_000006 of capacity <memory:1024, vCores:1> on host ip-10-0-0-193.us-west-2.compute.internal:60686, which currently has 1 containers, <memory:2048, vCores:1> used and <memory:6144, vCores:7> available, release resources=true
2014-05-05 11:40:59,727 INFO org.apache.hadoop.yarn.server.resourcemanager.scheduler.capacity.LeafQueue: default used=<memory:7168, vCores:6> numContainers=6 user=ubuntu user-resources=<memory:7168, vCores:6>
2014-05-05 11:40:59,727 INFO org.apache.hadoop.yarn.server.resourcemanager.scheduler.capacity.LeafQueue: completedContainer container=Container: [ContainerId: container_1399289015992_0001_01_000006, NodeId: ip-10-0-0-193.us-west-2.compute.internal:60686, NodeHttpAddress: ip-10-0-0-193.us-west-2.compute.internal:8042, Resource: <memory:1024, vCores:1>, Priority: 10, Token: Token { kind: ContainerToken, service: 10.0.0.193:60686 }, ] resource=<memory:1024, vCores:1> queue=default: capacity=1.0, absoluteCapacity=1.0, usedResources=<memory:7168, vCores:6>usedCapacity=0.109375, absoluteUsedCapacity=0.109375, numApps=1, numContainers=6 usedCapacity=0.109375 absoluteUsedCapacity=0.109375 used=<memory:7168, vCores:6> cluster=<memory:65536, vCores:64>
2014-05-05 11:40:59,728 INFO org.apache.hadoop.yarn.server.resourcemanager.scheduler.capacity.ParentQueue: completedContainer queue=root usedCapacity=0.109375 absoluteUsedCapacity=0.109375 used=<memory:7168, vCores:6> cluster=<memory:65536, vCores:64>
2014-05-05 11:40:59,728 INFO org.apache.hadoop.yarn.server.resourcemanager.scheduler.capacity.ParentQueue: Re-sorting completed queue: root.default stats: default: capacity=1.0, absoluteCapacity=1.0, usedResources=<memory:7168, vCores:6>usedCapacity=0.109375, absoluteUsedCapacity=0.109375, numApps=1, numContainers=6
2014-05-05 11:40:59,728 INFO org.apache.hadoop.yarn.server.resourcemanager.scheduler.capacity.CapacityScheduler: Application appattempt_1399289015992_0001_000001 released container container_1399289015992_0001_01_000006 on node: host: ip-10-0-0-193.us-west-2.compute.internal:60686 #containers=1 available=6144 used=2048 with event: FINISHED
2014-05-05 11:40:59,763 INFO org.apache.hadoop.yarn.server.webproxy.WebAppProxyServlet: dr.who is accessing unchecked http://ip-10-0-0-193:45943/mapreduce/job/job_1399289015992_0001 which is the app master GUI of application_1399289015992_0001 owned by ubuntu
2014-05-05 11:40:59,973 INFO org.apache.hadoop.yarn.server.webproxy.WebAppProxyServlet: dr.who is accessing unchecked http://ip-10-0-0-193:45943/static/jquery/themes-1.9.1/base/jquery-ui.css which is the app master GUI of application_1399289015992_0001 owned by ubuntu
2014-05-05 11:40:59,974 INFO org.apache.hadoop.yarn.server.webproxy.WebAppProxyServlet: dr.who is accessing unchecked http://ip-10-0-0-193:45943/static/dt-1.9.4/js/jquery.dataTables.min.js which is the app master GUI of application_1399289015992_0001 owned by ubuntu
2014-05-05 11:40:59,975 INFO org.apache.hadoop.yarn.server.webproxy.WebAppProxyServlet: dr.who is accessing unchecked http://ip-10-0-0-193:45943/static/dt-1.9.4/css/jui-dt.css which is the app master GUI of application_1399289015992_0001 owned by ubuntu
2014-05-05 11:40:59,975 INFO org.apache.hadoop.yarn.server.webproxy.WebAppProxyServlet: dr.who is accessing unchecked http://ip-10-0-0-193:45943/static/jquery/jquery-1.8.2.min.js which is the app master GUI of application_1399289015992_0001 owned by ubuntu
2014-05-05 11:40:59,977 INFO org.apache.hadoop.yarn.server.webproxy.WebAppProxyServlet: dr.who is accessing unchecked http://ip-10-0-0-193:45943/static/jquery/jquery-ui-1.9.1.custom.min.js which is the app master GUI of application_1399289015992_0001 owned by ubuntu
2014-05-05 11:40:59,977 INFO org.apache.hadoop.yarn.server.webproxy.WebAppProxyServlet: dr.who is accessing unchecked http://ip-10-0-0-193:45943/static/yarn.css which is the app master GUI of application_1399289015992_0001 owned by ubuntu
2014-05-05 11:41:00,060 INFO org.apache.hadoop.yarn.server.webproxy.WebAppProxyServlet: dr.who is accessing unchecked http://ip-10-0-0-193:45943/static/yarn.dt.plugins.js which is the app master GUI of application_1399289015992_0001 owned by ubuntu
2014-05-05 11:41:00,294 INFO org.apache.hadoop.yarn.server.webproxy.WebAppProxyServlet: dr.who is accessing unchecked http://ip-10-0-0-193:45943/static/jquery/themes-1.9.1/base/images/ui-bg_glass_95_fef1ec_1x400.png which is the app master GUI of application_1399289015992_0001 owned by ubuntu
2014-05-05 11:41:00,296 INFO org.apache.hadoop.yarn.server.webproxy.WebAppProxyServlet: dr.who is accessing unchecked http://ip-10-0-0-193:45943/static/jquery/themes-1.9.1/base/images/ui-bg_highlight-soft_75_cccccc_1x100.png which is the app master GUI of application_1399289015992_0001 owned by ubuntu
2014-05-05 11:41:00,297 INFO org.apache.hadoop.yarn.server.webproxy.WebAppProxyServlet: dr.who is accessing unchecked http://ip-10-0-0-193:45943/static/jquery/themes-1.9.1/base/images/ui-bg_glass_75_e6e6e6_1x400.png which is the app master GUI of application_1399289015992_0001 owned by ubuntu
2014-05-05 11:41:00,301 INFO org.apache.hadoop.yarn.server.webproxy.WebAppProxyServlet: dr.who is accessing unchecked http://ip-10-0-0-193:45943/static/jquery/themes-1.9.1/base/images/ui-bg_flat_75_ffffff_40x100.png which is the app master GUI of application_1399289015992_0001 owned by ubuntu
2014-05-05 11:41:00,305 INFO org.apache.hadoop.yarn.server.webproxy.WebAppProxyServlet: dr.who is accessing unchecked http://ip-10-0-0-193:45943/static/jquery/themes-1.9.1/base/images/ui-icons_888888_256x240.png which is the app master GUI of application_1399289015992_0001 owned by ubuntu
2014-05-05 11:41:00,306 INFO org.apache.hadoop.yarn.server.webproxy.WebAppProxyServlet: dr.who is accessing unchecked http://ip-10-0-0-193:45943/static/jquery/themes-1.9.1/base/images/ui-bg_glass_65_ffffff_1x400.png which is the app master GUI of application_1399289015992_0001 owned by ubuntu
2014-05-05 11:41:00,381 INFO org.apache.hadoop.yarn.server.webproxy.WebAppProxyServlet: dr.who is accessing unchecked http://ip-10-0-0-193:45943/static/jquery/themes-1.9.1/base/images/ui-icons_454545_256x240.png which is the app master GUI of application_1399289015992_0001 owned by ubuntu
2014-05-05 11:41:02,048 INFO org.apache.hadoop.yarn.server.resourcemanager.rmcontainer.RMContainerImpl: container_1399289015992_0001_01_000010 Container Transitioned from RUNNING to COMPLETED
2014-05-05 11:41:02,049 INFO org.apache.hadoop.yarn.server.resourcemanager.scheduler.common.fica.FiCaSchedulerApp: Completed container: container_1399289015992_0001_01_000010 in state: COMPLETED event:FINISHED
2014-05-05 11:41:02,049 INFO org.apache.hadoop.yarn.server.resourcemanager.RMAuditLogger: USER=ubuntu	OPERATION=AM Released Container	TARGET=SchedulerApp	RESULT=SUCCESS	APPID=application_1399289015992_0001	CONTAINERID=container_1399289015992_0001_01_000010
2014-05-05 11:41:02,049 INFO org.apache.hadoop.yarn.server.resourcemanager.scheduler.common.fica.FiCaSchedulerNode: Released container container_1399289015992_0001_01_000010 of capacity <memory:1024, vCores:1> on host ip-10-0-0-199.us-west-2.compute.internal:36159, which currently has 0 containers, <memory:0, vCores:0> used and <memory:8192, vCores:8> available, release resources=true
2014-05-05 11:41:02,049 INFO org.apache.hadoop.yarn.server.resourcemanager.scheduler.capacity.LeafQueue: default used=<memory:6144, vCores:5> numContainers=5 user=ubuntu user-resources=<memory:6144, vCores:5>
2014-05-05 11:41:02,049 INFO org.apache.hadoop.yarn.server.resourcemanager.scheduler.capacity.LeafQueue: completedContainer container=Container: [ContainerId: container_1399289015992_0001_01_000010, NodeId: ip-10-0-0-199.us-west-2.compute.internal:36159, NodeHttpAddress: ip-10-0-0-199.us-west-2.compute.internal:8042, Resource: <memory:1024, vCores:1>, Priority: 10, Token: Token { kind: ContainerToken, service: 10.0.0.199:36159 }, ] resource=<memory:1024, vCores:1> queue=default: capacity=1.0, absoluteCapacity=1.0, usedResources=<memory:6144, vCores:5>usedCapacity=0.09375, absoluteUsedCapacity=0.09375, numApps=1, numContainers=5 usedCapacity=0.09375 absoluteUsedCapacity=0.09375 used=<memory:6144, vCores:5> cluster=<memory:65536, vCores:64>
2014-05-05 11:41:02,049 INFO org.apache.hadoop.yarn.server.resourcemanager.scheduler.capacity.ParentQueue: completedContainer queue=root usedCapacity=0.09375 absoluteUsedCapacity=0.09375 used=<memory:6144, vCores:5> cluster=<memory:65536, vCores:64>
2014-05-05 11:41:02,049 INFO org.apache.hadoop.yarn.server.resourcemanager.scheduler.capacity.ParentQueue: Re-sorting completed queue: root.default stats: default: capacity=1.0, absoluteCapacity=1.0, usedResources=<memory:6144, vCores:5>usedCapacity=0.09375, absoluteUsedCapacity=0.09375, numApps=1, numContainers=5
2014-05-05 11:41:02,049 INFO org.apache.hadoop.yarn.server.resourcemanager.scheduler.capacity.CapacityScheduler: Application appattempt_1399289015992_0001_000001 released container container_1399289015992_0001_01_000010 on node: host: ip-10-0-0-199.us-west-2.compute.internal:36159 #containers=0 available=8192 used=0 with event: FINISHED
2014-05-05 11:41:04,935 INFO org.apache.hadoop.yarn.server.webproxy.WebAppProxyServlet: dr.who is accessing unchecked http://ip-10-0-0-193:45943/mapreduce/job/job_1399289015992_0001 which is the app master GUI of application_1399289015992_0001 owned by ubuntu
2014-05-05 11:41:05,065 INFO org.apache.hadoop.yarn.server.webproxy.WebAppProxyServlet: dr.who is accessing unchecked http://ip-10-0-0-193:45943/static/jquery/themes-1.9.1/base/jquery-ui.css which is the app master GUI of application_1399289015992_0001 owned by ubuntu
2014-05-05 11:41:05,066 INFO org.apache.hadoop.yarn.server.webproxy.WebAppProxyServlet: dr.who is accessing unchecked http://ip-10-0-0-193:45943/static/jquery/jquery-1.8.2.min.js which is the app master GUI of application_1399289015992_0001 owned by ubuntu
2014-05-05 11:41:05,067 INFO org.apache.hadoop.yarn.server.webproxy.WebAppProxyServlet: dr.who is accessing unchecked http://ip-10-0-0-193:45943/static/jquery/jquery-ui-1.9.1.custom.min.js which is the app master GUI of application_1399289015992_0001 owned by ubuntu
2014-05-05 11:41:05,069 INFO org.apache.hadoop.yarn.server.webproxy.WebAppProxyServlet: dr.who is accessing unchecked http://ip-10-0-0-193:45943/static/yarn.css which is the app master GUI of application_1399289015992_0001 owned by ubuntu
2014-05-05 11:41:05,069 INFO org.apache.hadoop.yarn.server.webproxy.WebAppProxyServlet: dr.who is accessing unchecked http://ip-10-0-0-193:45943/static/dt-1.9.4/css/jui-dt.css which is the app master GUI of application_1399289015992_0001 owned by ubuntu
2014-05-05 11:41:05,071 INFO org.apache.hadoop.yarn.server.webproxy.WebAppProxyServlet: dr.who is accessing unchecked http://ip-10-0-0-193:45943/static/dt-1.9.4/js/jquery.dataTables.min.js which is the app master GUI of application_1399289015992_0001 owned by ubuntu
2014-05-05 11:41:05,152 INFO org.apache.hadoop.yarn.server.webproxy.WebAppProxyServlet: dr.who is accessing unchecked http://ip-10-0-0-193:45943/static/yarn.dt.plugins.js which is the app master GUI of application_1399289015992_0001 owned by ubuntu
2014-05-05 11:41:05,402 INFO org.apache.hadoop.yarn.server.webproxy.WebAppProxyServlet: dr.who is accessing unchecked http://ip-10-0-0-193:45943/static/jquery/themes-1.9.1/base/images/ui-bg_flat_75_ffffff_40x100.png which is the app master GUI of application_1399289015992_0001 owned by ubuntu
2014-05-05 11:41:05,402 INFO org.apache.hadoop.yarn.server.webproxy.WebAppProxyServlet: dr.who is accessing unchecked http://ip-10-0-0-193:45943/static/jquery/themes-1.9.1/base/images/ui-bg_glass_95_fef1ec_1x400.png which is the app master GUI of application_1399289015992_0001 owned by ubuntu
2014-05-05 11:41:05,405 INFO org.apache.hadoop.yarn.server.webproxy.WebAppProxyServlet: dr.who is accessing unchecked http://ip-10-0-0-193:45943/static/jquery/themes-1.9.1/base/images/ui-bg_highlight-soft_75_cccccc_1x100.png which is the app master GUI of application_1399289015992_0001 owned by ubuntu
2014-05-05 11:41:05,408 INFO org.apache.hadoop.yarn.server.webproxy.WebAppProxyServlet: dr.who is accessing unchecked http://ip-10-0-0-193:45943/static/jquery/themes-1.9.1/base/images/ui-bg_glass_75_e6e6e6_1x400.png which is the app master GUI of application_1399289015992_0001 owned by ubuntu
2014-05-05 11:41:05,414 INFO org.apache.hadoop.yarn.server.webproxy.WebAppProxyServlet: dr.who is accessing unchecked http://ip-10-0-0-193:45943/static/jquery/themes-1.9.1/base/images/ui-bg_glass_65_ffffff_1x400.png which is the app master GUI of application_1399289015992_0001 owned by ubuntu
2014-05-05 11:41:05,418 INFO org.apache.hadoop.yarn.server.webproxy.WebAppProxyServlet: dr.who is accessing unchecked http://ip-10-0-0-193:45943/static/jquery/themes-1.9.1/base/images/ui-icons_888888_256x240.png which is the app master GUI of application_1399289015992_0001 owned by ubuntu
2014-05-05 11:41:05,481 INFO org.apache.hadoop.yarn.server.webproxy.WebAppProxyServlet: dr.who is accessing unchecked http://ip-10-0-0-193:45943/static/jquery/themes-1.9.1/base/images/ui-icons_454545_256x240.png which is the app master GUI of application_1399289015992_0001 owned by ubuntu
2014-05-05 11:41:06,503 INFO org.apache.hadoop.yarn.server.webproxy.WebAppProxyServlet: dr.who is accessing unchecked http://ip-10-0-0-193:45943/mapreduce/job/job_1399289015992_0001 which is the app master GUI of application_1399289015992_0001 owned by ubuntu
2014-05-05 11:41:06,694 INFO org.apache.hadoop.yarn.server.webproxy.WebAppProxyServlet: dr.who is accessing unchecked http://ip-10-0-0-193:45943/static/yarn.css which is the app master GUI of application_1399289015992_0001 owned by ubuntu
2014-05-05 11:41:06,697 INFO org.apache.hadoop.yarn.server.webproxy.WebAppProxyServlet: dr.who is accessing unchecked http://ip-10-0-0-193:45943/static/dt-1.9.4/js/jquery.dataTables.min.js which is the app master GUI of application_1399289015992_0001 owned by ubuntu
2014-05-05 11:41:06,699 INFO org.apache.hadoop.yarn.server.webproxy.WebAppProxyServlet: dr.who is accessing unchecked http://ip-10-0-0-193:45943/static/jquery/jquery-ui-1.9.1.custom.min.js which is the app master GUI of application_1399289015992_0001 owned by ubuntu
2014-05-05 11:41:06,699 INFO org.apache.hadoop.yarn.server.webproxy.WebAppProxyServlet: dr.who is accessing unchecked http://ip-10-0-0-193:45943/static/jquery/themes-1.9.1/base/jquery-ui.css which is the app master GUI of application_1399289015992_0001 owned by ubuntu
2014-05-05 11:41:06,700 INFO org.apache.hadoop.yarn.server.webproxy.WebAppProxyServlet: dr.who is accessing unchecked http://ip-10-0-0-193:45943/static/dt-1.9.4/css/jui-dt.css which is the app master GUI of application_1399289015992_0001 owned by ubuntu
2014-05-05 11:41:06,701 INFO org.apache.hadoop.yarn.server.webproxy.WebAppProxyServlet: dr.who is accessing unchecked http://ip-10-0-0-193:45943/static/jquery/jquery-1.8.2.min.js which is the app master GUI of application_1399289015992_0001 owned by ubuntu
2014-05-05 11:41:06,775 INFO org.apache.hadoop.yarn.server.webproxy.WebAppProxyServlet: dr.who is accessing unchecked http://ip-10-0-0-193:45943/static/yarn.dt.plugins.js which is the app master GUI of application_1399289015992_0001 owned by ubuntu
2014-05-05 11:41:07,093 INFO org.apache.hadoop.yarn.server.webproxy.WebAppProxyServlet: dr.who is accessing unchecked http://ip-10-0-0-193:45943/static/jquery/themes-1.9.1/base/images/ui-bg_glass_95_fef1ec_1x400.png which is the app master GUI of application_1399289015992_0001 owned by ubuntu
2014-05-05 11:41:07,093 INFO org.apache.hadoop.yarn.server.webproxy.WebAppProxyServlet: dr.who is accessing unchecked http://ip-10-0-0-193:45943/static/jquery/themes-1.9.1/base/images/ui-bg_flat_75_ffffff_40x100.png which is the app master GUI of application_1399289015992_0001 owned by ubuntu
2014-05-05 11:41:07,095 INFO org.apache.hadoop.yarn.server.webproxy.WebAppProxyServlet: dr.who is accessing unchecked http://ip-10-0-0-193:45943/static/jquery/themes-1.9.1/base/images/ui-bg_glass_75_e6e6e6_1x400.png which is the app master GUI of application_1399289015992_0001 owned by ubuntu
2014-05-05 11:41:07,097 INFO org.apache.hadoop.yarn.server.webproxy.WebAppProxyServlet: dr.who is accessing unchecked http://ip-10-0-0-193:45943/static/jquery/themes-1.9.1/base/images/ui-bg_highlight-soft_75_cccccc_1x100.png which is the app master GUI of application_1399289015992_0001 owned by ubuntu
2014-05-05 11:41:07,107 INFO org.apache.hadoop.yarn.server.webproxy.WebAppProxyServlet: dr.who is accessing unchecked http://ip-10-0-0-193:45943/static/jquery/themes-1.9.1/base/images/ui-bg_glass_65_ffffff_1x400.png which is the app master GUI of application_1399289015992_0001 owned by ubuntu
2014-05-05 11:41:07,107 INFO org.apache.hadoop.yarn.server.webproxy.WebAppProxyServlet: dr.who is accessing unchecked http://ip-10-0-0-193:45943/static/jquery/themes-1.9.1/base/images/ui-icons_888888_256x240.png which is the app master GUI of application_1399289015992_0001 owned by ubuntu
2014-05-05 11:41:07,172 INFO org.apache.hadoop.yarn.server.webproxy.WebAppProxyServlet: dr.who is accessing unchecked http://ip-10-0-0-193:45943/static/jquery/themes-1.9.1/base/images/ui-icons_454545_256x240.png which is the app master GUI of application_1399289015992_0001 owned by ubuntu
2014-05-05 11:41:07,822 INFO org.apache.hadoop.yarn.server.resourcemanager.rmcontainer.RMContainerImpl: container_1399289015992_0001_01_000007 Container Transitioned from RUNNING to COMPLETED
2014-05-05 11:41:07,822 INFO org.apache.hadoop.yarn.server.resourcemanager.scheduler.common.fica.FiCaSchedulerApp: Completed container: container_1399289015992_0001_01_000007 in state: COMPLETED event:FINISHED
2014-05-05 11:41:07,822 INFO org.apache.hadoop.yarn.server.resourcemanager.RMAuditLogger: USER=ubuntu	OPERATION=AM Released Container	TARGET=SchedulerApp	RESULT=SUCCESS	APPID=application_1399289015992_0001	CONTAINERID=container_1399289015992_0001_01_000007
2014-05-05 11:41:07,822 INFO org.apache.hadoop.yarn.server.resourcemanager.scheduler.common.fica.FiCaSchedulerNode: Released container container_1399289015992_0001_01_000007 of capacity <memory:1024, vCores:1> on host ip-10-0-0-196.us-west-2.compute.internal:47357, which currently has 0 containers, <memory:0, vCores:0> used and <memory:8192, vCores:8> available, release resources=true
2014-05-05 11:41:07,822 INFO org.apache.hadoop.yarn.server.resourcemanager.scheduler.capacity.LeafQueue: default used=<memory:5120, vCores:4> numContainers=4 user=ubuntu user-resources=<memory:5120, vCores:4>
2014-05-05 11:41:07,822 INFO org.apache.hadoop.yarn.server.resourcemanager.scheduler.capacity.LeafQueue: completedContainer container=Container: [ContainerId: container_1399289015992_0001_01_000007, NodeId: ip-10-0-0-196.us-west-2.compute.internal:47357, NodeHttpAddress: ip-10-0-0-196.us-west-2.compute.internal:8042, Resource: <memory:1024, vCores:1>, Priority: 10, Token: Token { kind: ContainerToken, service: 10.0.0.196:47357 }, ] resource=<memory:1024, vCores:1> queue=default: capacity=1.0, absoluteCapacity=1.0, usedResources=<memory:5120, vCores:4>usedCapacity=0.078125, absoluteUsedCapacity=0.078125, numApps=1, numContainers=4 usedCapacity=0.078125 absoluteUsedCapacity=0.078125 used=<memory:5120, vCores:4> cluster=<memory:65536, vCores:64>
2014-05-05 11:41:07,822 INFO org.apache.hadoop.yarn.server.resourcemanager.scheduler.capacity.ParentQueue: completedContainer queue=root usedCapacity=0.078125 absoluteUsedCapacity=0.078125 used=<memory:5120, vCores:4> cluster=<memory:65536, vCores:64>
2014-05-05 11:41:07,822 INFO org.apache.hadoop.yarn.server.resourcemanager.scheduler.capacity.ParentQueue: Re-sorting completed queue: root.default stats: default: capacity=1.0, absoluteCapacity=1.0, usedResources=<memory:5120, vCores:4>usedCapacity=0.078125, absoluteUsedCapacity=0.078125, numApps=1, numContainers=4
2014-05-05 11:41:07,822 INFO org.apache.hadoop.yarn.server.resourcemanager.scheduler.capacity.CapacityScheduler: Application appattempt_1399289015992_0001_000001 released container container_1399289015992_0001_01_000007 on node: host: ip-10-0-0-196.us-west-2.compute.internal:47357 #containers=0 available=8192 used=0 with event: FINISHED
2014-05-05 11:41:08,701 INFO org.apache.hadoop.yarn.server.webproxy.WebAppProxyServlet: dr.who is accessing unchecked http://ip-10-0-0-193:45943/mapreduce/job/job_1399289015992_0001 which is the app master GUI of application_1399289015992_0001 owned by ubuntu
2014-05-05 11:41:08,779 INFO org.apache.hadoop.yarn.server.resourcemanager.rmcontainer.RMContainerImpl: container_1399289015992_0001_01_000009 Container Transitioned from RUNNING to COMPLETED
2014-05-05 11:41:08,779 INFO org.apache.hadoop.yarn.server.resourcemanager.scheduler.common.fica.FiCaSchedulerApp: Completed container: container_1399289015992_0001_01_000009 in state: COMPLETED event:FINISHED
2014-05-05 11:41:08,779 INFO org.apache.hadoop.yarn.server.resourcemanager.RMAuditLogger: USER=ubuntu	OPERATION=AM Released Container	TARGET=SchedulerApp	RESULT=SUCCESS	APPID=application_1399289015992_0001	CONTAINERID=container_1399289015992_0001_01_000009
2014-05-05 11:41:08,779 INFO org.apache.hadoop.yarn.server.resourcemanager.scheduler.common.fica.FiCaSchedulerNode: Released container container_1399289015992_0001_01_000009 of capacity <memory:1024, vCores:1> on host ip-10-0-0-198.us-west-2.compute.internal:60935, which currently has 0 containers, <memory:0, vCores:0> used and <memory:8192, vCores:8> available, release resources=true
2014-05-05 11:41:08,779 INFO org.apache.hadoop.yarn.server.resourcemanager.scheduler.capacity.LeafQueue: default used=<memory:4096, vCores:3> numContainers=3 user=ubuntu user-resources=<memory:4096, vCores:3>
2014-05-05 11:41:08,779 INFO org.apache.hadoop.yarn.server.resourcemanager.scheduler.capacity.LeafQueue: completedContainer container=Container: [ContainerId: container_1399289015992_0001_01_000009, NodeId: ip-10-0-0-198.us-west-2.compute.internal:60935, NodeHttpAddress: ip-10-0-0-198.us-west-2.compute.internal:8042, Resource: <memory:1024, vCores:1>, Priority: 10, Token: Token { kind: ContainerToken, service: 10.0.0.198:60935 }, ] resource=<memory:1024, vCores:1> queue=default: capacity=1.0, absoluteCapacity=1.0, usedResources=<memory:4096, vCores:3>usedCapacity=0.0625, absoluteUsedCapacity=0.0625, numApps=1, numContainers=3 usedCapacity=0.0625 absoluteUsedCapacity=0.0625 used=<memory:4096, vCores:3> cluster=<memory:65536, vCores:64>
2014-05-05 11:41:08,779 INFO org.apache.hadoop.yarn.server.resourcemanager.scheduler.capacity.ParentQueue: completedContainer queue=root usedCapacity=0.0625 absoluteUsedCapacity=0.0625 used=<memory:4096, vCores:3> cluster=<memory:65536, vCores:64>
2014-05-05 11:41:08,779 INFO org.apache.hadoop.yarn.server.resourcemanager.scheduler.capacity.ParentQueue: Re-sorting completed queue: root.default stats: default: capacity=1.0, absoluteCapacity=1.0, usedResources=<memory:4096, vCores:3>usedCapacity=0.0625, absoluteUsedCapacity=0.0625, numApps=1, numContainers=3
2014-05-05 11:41:08,779 INFO org.apache.hadoop.yarn.server.resourcemanager.scheduler.capacity.CapacityScheduler: Application appattempt_1399289015992_0001_000001 released container container_1399289015992_0001_01_000009 on node: host: ip-10-0-0-198.us-west-2.compute.internal:60935 #containers=0 available=8192 used=0 with event: FINISHED
2014-05-05 11:41:08,915 INFO org.apache.hadoop.yarn.server.webproxy.WebAppProxyServlet: dr.who is accessing unchecked http://ip-10-0-0-193:45943/static/yarn.css which is the app master GUI of application_1399289015992_0001 owned by ubuntu
2014-05-05 11:41:08,916 INFO org.apache.hadoop.yarn.server.webproxy.WebAppProxyServlet: dr.who is accessing unchecked http://ip-10-0-0-193:45943/static/jquery/themes-1.9.1/base/jquery-ui.css which is the app master GUI of application_1399289015992_0001 owned by ubuntu
2014-05-05 11:41:08,918 INFO org.apache.hadoop.yarn.server.webproxy.WebAppProxyServlet: dr.who is accessing unchecked http://ip-10-0-0-193:45943/static/dt-1.9.4/js/jquery.dataTables.min.js which is the app master GUI of application_1399289015992_0001 owned by ubuntu
2014-05-05 11:41:08,918 INFO org.apache.hadoop.yarn.server.webproxy.WebAppProxyServlet: dr.who is accessing unchecked http://ip-10-0-0-193:45943/static/dt-1.9.4/css/jui-dt.css which is the app master GUI of application_1399289015992_0001 owned by ubuntu
2014-05-05 11:41:08,920 INFO org.apache.hadoop.yarn.server.webproxy.WebAppProxyServlet: dr.who is accessing unchecked http://ip-10-0-0-193:45943/static/jquery/jquery-ui-1.9.1.custom.min.js which is the app master GUI of application_1399289015992_0001 owned by ubuntu
2014-05-05 11:41:08,921 INFO org.apache.hadoop.yarn.server.webproxy.WebAppProxyServlet: dr.who is accessing unchecked http://ip-10-0-0-193:45943/static/jquery/jquery-1.8.2.min.js which is the app master GUI of application_1399289015992_0001 owned by ubuntu
2014-05-05 11:41:08,997 INFO org.apache.hadoop.yarn.server.webproxy.WebAppProxyServlet: dr.who is accessing unchecked http://ip-10-0-0-193:45943/static/yarn.dt.plugins.js which is the app master GUI of application_1399289015992_0001 owned by ubuntu
2014-05-05 11:41:09,239 INFO org.apache.hadoop.yarn.server.webproxy.WebAppProxyServlet: dr.who is accessing unchecked http://ip-10-0-0-193:45943/static/jquery/themes-1.9.1/base/images/ui-bg_glass_95_fef1ec_1x400.png which is the app master GUI of application_1399289015992_0001 owned by ubuntu
2014-05-05 11:41:09,239 INFO org.apache.hadoop.yarn.server.webproxy.WebAppProxyServlet: dr.who is accessing unchecked http://ip-10-0-0-193:45943/static/jquery/themes-1.9.1/base/images/ui-bg_flat_75_ffffff_40x100.png which is the app master GUI of application_1399289015992_0001 owned by ubuntu
2014-05-05 11:41:09,241 INFO org.apache.hadoop.yarn.server.webproxy.WebAppProxyServlet: dr.who is accessing unchecked http://ip-10-0-0-193:45943/static/jquery/themes-1.9.1/base/images/ui-bg_glass_75_e6e6e6_1x400.png which is the app master GUI of application_1399289015992_0001 owned by ubuntu
2014-05-05 11:41:09,241 INFO org.apache.hadoop.yarn.server.webproxy.WebAppProxyServlet: dr.who is accessing unchecked http://ip-10-0-0-193:45943/static/jquery/themes-1.9.1/base/images/ui-bg_highlight-soft_75_cccccc_1x100.png which is the app master GUI of application_1399289015992_0001 owned by ubuntu
2014-05-05 11:41:09,250 INFO org.apache.hadoop.yarn.server.webproxy.WebAppProxyServlet: dr.who is accessing unchecked http://ip-10-0-0-193:45943/static/jquery/themes-1.9.1/base/images/ui-bg_glass_65_ffffff_1x400.png which is the app master GUI of application_1399289015992_0001 owned by ubuntu
2014-05-05 11:41:09,252 INFO org.apache.hadoop.yarn.server.webproxy.WebAppProxyServlet: dr.who is accessing unchecked http://ip-10-0-0-193:45943/static/jquery/themes-1.9.1/base/images/ui-icons_888888_256x240.png which is the app master GUI of application_1399289015992_0001 owned by ubuntu
2014-05-05 11:41:09,323 INFO org.apache.hadoop.yarn.server.webproxy.WebAppProxyServlet: dr.who is accessing unchecked http://ip-10-0-0-193:45943/static/jquery/themes-1.9.1/base/images/ui-icons_454545_256x240.png which is the app master GUI of application_1399289015992_0001 owned by ubuntu
2014-05-05 11:41:10,488 INFO org.apache.hadoop.yarn.server.webproxy.WebAppProxyServlet: dr.who is accessing unchecked http://ip-10-0-0-193:45943/mapreduce/job/job_1399289015992_0001 which is the app master GUI of application_1399289015992_0001 owned by ubuntu
2014-05-05 11:41:10,664 INFO org.apache.hadoop.yarn.server.webproxy.WebAppProxyServlet: dr.who is accessing unchecked http://ip-10-0-0-193:45943/static/jquery/themes-1.9.1/base/jquery-ui.css which is the app master GUI of application_1399289015992_0001 owned by ubuntu
2014-05-05 11:41:10,665 INFO org.apache.hadoop.yarn.server.webproxy.WebAppProxyServlet: dr.who is accessing unchecked http://ip-10-0-0-193:45943/static/jquery/jquery-1.8.2.min.js which is the app master GUI of application_1399289015992_0001 owned by ubuntu
2014-05-05 11:41:10,665 INFO org.apache.hadoop.yarn.server.webproxy.WebAppProxyServlet: dr.who is accessing unchecked http://ip-10-0-0-193:45943/static/jquery/jquery-ui-1.9.1.custom.min.js which is the app master GUI of application_1399289015992_0001 owned by ubuntu
2014-05-05 11:41:10,667 INFO org.apache.hadoop.yarn.server.webproxy.WebAppProxyServlet: dr.who is accessing unchecked http://ip-10-0-0-193:45943/static/yarn.css which is the app master GUI of application_1399289015992_0001 owned by ubuntu
2014-05-05 11:41:10,668 INFO org.apache.hadoop.yarn.server.webproxy.WebAppProxyServlet: dr.who is accessing unchecked http://ip-10-0-0-193:45943/static/dt-1.9.4/js/jquery.dataTables.min.js which is the app master GUI of application_1399289015992_0001 owned by ubuntu
2014-05-05 11:41:10,668 INFO org.apache.hadoop.yarn.server.webproxy.WebAppProxyServlet: dr.who is accessing unchecked http://ip-10-0-0-193:45943/static/dt-1.9.4/css/jui-dt.css which is the app master GUI of application_1399289015992_0001 owned by ubuntu
2014-05-05 11:41:10,680 INFO org.apache.hadoop.yarn.server.resourcemanager.rmcontainer.RMContainerImpl: container_1399289015992_0001_01_000011 Container Transitioned from RUNNING to COMPLETED
2014-05-05 11:41:10,680 INFO org.apache.hadoop.yarn.server.resourcemanager.scheduler.common.fica.FiCaSchedulerApp: Completed container: container_1399289015992_0001_01_000011 in state: COMPLETED event:FINISHED
2014-05-05 11:41:10,681 INFO org.apache.hadoop.yarn.server.resourcemanager.RMAuditLogger: USER=ubuntu	OPERATION=AM Released Container	TARGET=SchedulerApp	RESULT=SUCCESS	APPID=application_1399289015992_0001	CONTAINERID=container_1399289015992_0001_01_000011
2014-05-05 11:41:10,681 INFO org.apache.hadoop.yarn.server.resourcemanager.scheduler.common.fica.FiCaSchedulerNode: Released container container_1399289015992_0001_01_000011 of capacity <memory:1024, vCores:1> on host ip-10-0-0-197.us-west-2.compute.internal:36720, which currently has 0 containers, <memory:0, vCores:0> used and <memory:8192, vCores:8> available, release resources=true
2014-05-05 11:41:10,681 INFO org.apache.hadoop.yarn.server.resourcemanager.scheduler.capacity.LeafQueue: default used=<memory:3072, vCores:2> numContainers=2 user=ubuntu user-resources=<memory:3072, vCores:2>
2014-05-05 11:41:10,681 INFO org.apache.hadoop.yarn.server.resourcemanager.scheduler.capacity.LeafQueue: completedContainer container=Container: [ContainerId: container_1399289015992_0001_01_000011, NodeId: ip-10-0-0-197.us-west-2.compute.internal:36720, NodeHttpAddress: ip-10-0-0-197.us-west-2.compute.internal:8042, Resource: <memory:1024, vCores:1>, Priority: 10, Token: Token { kind: ContainerToken, service: 10.0.0.197:36720 }, ] resource=<memory:1024, vCores:1> queue=default: capacity=1.0, absoluteCapacity=1.0, usedResources=<memory:3072, vCores:2>usedCapacity=0.046875, absoluteUsedCapacity=0.046875, numApps=1, numContainers=2 usedCapacity=0.046875 absoluteUsedCapacity=0.046875 used=<memory:3072, vCores:2> cluster=<memory:65536, vCores:64>
2014-05-05 11:41:10,681 INFO org.apache.hadoop.yarn.server.resourcemanager.scheduler.capacity.ParentQueue: completedContainer queue=root usedCapacity=0.046875 absoluteUsedCapacity=0.046875 used=<memory:3072, vCores:2> cluster=<memory:65536, vCores:64>
2014-05-05 11:41:10,681 INFO org.apache.hadoop.yarn.server.resourcemanager.scheduler.capacity.ParentQueue: Re-sorting completed queue: root.default stats: default: capacity=1.0, absoluteCapacity=1.0, usedResources=<memory:3072, vCores:2>usedCapacity=0.046875, absoluteUsedCapacity=0.046875, numApps=1, numContainers=2
2014-05-05 11:41:10,681 INFO org.apache.hadoop.yarn.server.resourcemanager.scheduler.capacity.CapacityScheduler: Application appattempt_1399289015992_0001_000001 released container container_1399289015992_0001_01_000011 on node: host: ip-10-0-0-197.us-west-2.compute.internal:36720 #containers=0 available=8192 used=0 with event: FINISHED
2014-05-05 11:41:10,747 INFO org.apache.hadoop.yarn.server.webproxy.WebAppProxyServlet: dr.who is accessing unchecked http://ip-10-0-0-193:45943/static/yarn.dt.plugins.js which is the app master GUI of application_1399289015992_0001 owned by ubuntu
2014-05-05 11:41:10,977 INFO org.apache.hadoop.yarn.server.webproxy.WebAppProxyServlet: dr.who is accessing unchecked http://ip-10-0-0-193:45943/static/jquery/themes-1.9.1/base/images/ui-bg_glass_75_e6e6e6_1x400.png which is the app master GUI of application_1399289015992_0001 owned by ubuntu
2014-05-05 11:41:10,978 INFO org.apache.hadoop.yarn.server.webproxy.WebAppProxyServlet: dr.who is accessing unchecked http://ip-10-0-0-193:45943/static/jquery/themes-1.9.1/base/images/ui-bg_flat_75_ffffff_40x100.png which is the app master GUI of application_1399289015992_0001 owned by ubuntu
2014-05-05 11:41:10,980 INFO org.apache.hadoop.yarn.server.webproxy.WebAppProxyServlet: dr.who is accessing unchecked http://ip-10-0-0-193:45943/static/jquery/themes-1.9.1/base/images/ui-bg_highlight-soft_75_cccccc_1x100.png which is the app master GUI of application_1399289015992_0001 owned by ubuntu
2014-05-05 11:41:10,980 INFO org.apache.hadoop.yarn.server.webproxy.WebAppProxyServlet: dr.who is accessing unchecked http://ip-10-0-0-193:45943/static/jquery/themes-1.9.1/base/images/ui-bg_glass_95_fef1ec_1x400.png which is the app master GUI of application_1399289015992_0001 owned by ubuntu
2014-05-05 11:41:10,988 INFO org.apache.hadoop.yarn.server.webproxy.WebAppProxyServlet: dr.who is accessing unchecked http://ip-10-0-0-193:45943/static/jquery/themes-1.9.1/base/images/ui-bg_glass_65_ffffff_1x400.png which is the app master GUI of application_1399289015992_0001 owned by ubuntu
2014-05-05 11:41:10,989 INFO org.apache.hadoop.yarn.server.webproxy.WebAppProxyServlet: dr.who is accessing unchecked http://ip-10-0-0-193:45943/static/jquery/themes-1.9.1/base/images/ui-icons_888888_256x240.png which is the app master GUI of application_1399289015992_0001 owned by ubuntu
2014-05-05 11:41:11,003 INFO org.apache.hadoop.yarn.server.resourcemanager.rmcontainer.RMContainerImpl: container_1399289015992_0001_01_000008 Container Transitioned from RUNNING to COMPLETED
2014-05-05 11:41:11,003 INFO org.apache.hadoop.yarn.server.resourcemanager.scheduler.common.fica.FiCaSchedulerApp: Completed container: container_1399289015992_0001_01_000008 in state: COMPLETED event:FINISHED
2014-05-05 11:41:11,004 INFO org.apache.hadoop.yarn.server.resourcemanager.RMAuditLogger: USER=ubuntu	OPERATION=AM Released Container	TARGET=SchedulerApp	RESULT=SUCCESS	APPID=application_1399289015992_0001	CONTAINERID=container_1399289015992_0001_01_000008
2014-05-05 11:41:11,004 INFO org.apache.hadoop.yarn.server.resourcemanager.scheduler.common.fica.FiCaSchedulerNode: Released container container_1399289015992_0001_01_000008 of capacity <memory:1024, vCores:1> on host ip-10-0-0-200.us-west-2.compute.internal:36991, which currently has 0 containers, <memory:0, vCores:0> used and <memory:8192, vCores:8> available, release resources=true
2014-05-05 11:41:11,004 INFO org.apache.hadoop.yarn.server.resourcemanager.scheduler.capacity.LeafQueue: default used=<memory:2048, vCores:1> numContainers=1 user=ubuntu user-resources=<memory:2048, vCores:1>
2014-05-05 11:41:11,004 INFO org.apache.hadoop.yarn.server.resourcemanager.scheduler.capacity.LeafQueue: completedContainer container=Container: [ContainerId: container_1399289015992_0001_01_000008, NodeId: ip-10-0-0-200.us-west-2.compute.internal:36991, NodeHttpAddress: ip-10-0-0-200.us-west-2.compute.internal:8042, Resource: <memory:1024, vCores:1>, Priority: 10, Token: Token { kind: ContainerToken, service: 10.0.0.200:36991 }, ] resource=<memory:1024, vCores:1> queue=default: capacity=1.0, absoluteCapacity=1.0, usedResources=<memory:2048, vCores:1>usedCapacity=0.03125, absoluteUsedCapacity=0.03125, numApps=1, numContainers=1 usedCapacity=0.03125 absoluteUsedCapacity=0.03125 used=<memory:2048, vCores:1> cluster=<memory:65536, vCores:64>
2014-05-05 11:41:11,004 INFO org.apache.hadoop.yarn.server.resourcemanager.scheduler.capacity.ParentQueue: completedContainer queue=root usedCapacity=0.03125 absoluteUsedCapacity=0.03125 used=<memory:2048, vCores:1> cluster=<memory:65536, vCores:64>
2014-05-05 11:41:11,004 INFO org.apache.hadoop.yarn.server.resourcemanager.scheduler.capacity.ParentQueue: Re-sorting completed queue: root.default stats: default: capacity=1.0, absoluteCapacity=1.0, usedResources=<memory:2048, vCores:1>usedCapacity=0.03125, absoluteUsedCapacity=0.03125, numApps=1, numContainers=1
2014-05-05 11:41:11,004 INFO org.apache.hadoop.yarn.server.resourcemanager.scheduler.capacity.CapacityScheduler: Application appattempt_1399289015992_0001_000001 released container container_1399289015992_0001_01_000008 on node: host: ip-10-0-0-200.us-west-2.compute.internal:36991 #containers=0 available=8192 used=0 with event: FINISHED
2014-05-05 11:41:11,055 INFO org.apache.hadoop.yarn.server.webproxy.WebAppProxyServlet: dr.who is accessing unchecked http://ip-10-0-0-193:45943/static/jquery/themes-1.9.1/base/images/ui-icons_454545_256x240.png which is the app master GUI of application_1399289015992_0001 owned by ubuntu
2014-05-05 11:41:12,262 INFO org.apache.hadoop.yarn.server.webproxy.WebAppProxyServlet: dr.who is accessing unchecked http://ip-10-0-0-193:45943/mapreduce/job/job_1399289015992_0001 which is the app master GUI of application_1399289015992_0001 owned by ubuntu
2014-05-05 11:41:12,468 INFO org.apache.hadoop.yarn.server.webproxy.WebAppProxyServlet: dr.who is accessing unchecked http://ip-10-0-0-193:45943/static/dt-1.9.4/css/jui-dt.css which is the app master GUI of application_1399289015992_0001 owned by ubuntu
2014-05-05 11:41:12,470 INFO org.apache.hadoop.yarn.server.webproxy.WebAppProxyServlet: dr.who is accessing unchecked http://ip-10-0-0-193:45943/static/jquery/jquery-ui-1.9.1.custom.min.js which is the app master GUI of application_1399289015992_0001 owned by ubuntu
2014-05-05 11:41:12,471 INFO org.apache.hadoop.yarn.server.webproxy.WebAppProxyServlet: dr.who is accessing unchecked http://ip-10-0-0-193:45943/static/jquery/themes-1.9.1/base/jquery-ui.css which is the app master GUI of application_1399289015992_0001 owned by ubuntu
2014-05-05 11:41:12,472 INFO org.apache.hadoop.yarn.server.webproxy.WebAppProxyServlet: dr.who is accessing unchecked http://ip-10-0-0-193:45943/static/dt-1.9.4/js/jquery.dataTables.min.js which is the app master GUI of application_1399289015992_0001 owned by ubuntu
2014-05-05 11:41:12,473 INFO org.apache.hadoop.yarn.server.webproxy.WebAppProxyServlet: dr.who is accessing unchecked http://ip-10-0-0-193:45943/static/jquery/jquery-1.8.2.min.js which is the app master GUI of application_1399289015992_0001 owned by ubuntu
2014-05-05 11:41:12,474 INFO org.apache.hadoop.yarn.server.webproxy.WebAppProxyServlet: dr.who is accessing unchecked http://ip-10-0-0-193:45943/static/yarn.css which is the app master GUI of application_1399289015992_0001 owned by ubuntu
2014-05-05 11:41:12,554 INFO org.apache.hadoop.yarn.server.webproxy.WebAppProxyServlet: dr.who is accessing unchecked http://ip-10-0-0-193:45943/static/yarn.dt.plugins.js which is the app master GUI of application_1399289015992_0001 owned by ubuntu
2014-05-05 11:41:12,784 INFO org.apache.hadoop.yarn.server.webproxy.WebAppProxyServlet: dr.who is accessing unchecked http://ip-10-0-0-193:45943/static/jquery/themes-1.9.1/base/images/ui-bg_flat_75_ffffff_40x100.png which is the app master GUI of application_1399289015992_0001 owned by ubuntu
2014-05-05 11:41:12,785 INFO org.apache.hadoop.yarn.server.webproxy.WebAppProxyServlet: dr.who is accessing unchecked http://ip-10-0-0-193:45943/static/jquery/themes-1.9.1/base/images/ui-bg_glass_95_fef1ec_1x400.png which is the app master GUI of application_1399289015992_0001 owned by ubuntu
2014-05-05 11:41:12,785 INFO org.apache.hadoop.yarn.server.webproxy.WebAppProxyServlet: dr.who is accessing unchecked http://ip-10-0-0-193:45943/static/jquery/themes-1.9.1/base/images/ui-bg_glass_75_e6e6e6_1x400.png which is the app master GUI of application_1399289015992_0001 owned by ubuntu
2014-05-05 11:41:12,786 INFO org.apache.hadoop.yarn.server.webproxy.WebAppProxyServlet: dr.who is accessing unchecked http://ip-10-0-0-193:45943/static/jquery/themes-1.9.1/base/images/ui-bg_highlight-soft_75_cccccc_1x100.png which is the app master GUI of application_1399289015992_0001 owned by ubuntu
2014-05-05 11:41:12,794 INFO org.apache.hadoop.yarn.server.webproxy.WebAppProxyServlet: dr.who is accessing unchecked http://ip-10-0-0-193:45943/static/jquery/themes-1.9.1/base/images/ui-icons_888888_256x240.png which is the app master GUI of application_1399289015992_0001 owned by ubuntu
2014-05-05 11:41:12,796 INFO org.apache.hadoop.yarn.server.webproxy.WebAppProxyServlet: dr.who is accessing unchecked http://ip-10-0-0-193:45943/static/jquery/themes-1.9.1/base/images/ui-bg_glass_65_ffffff_1x400.png which is the app master GUI of application_1399289015992_0001 owned by ubuntu
2014-05-05 11:41:12,870 INFO org.apache.hadoop.yarn.server.webproxy.WebAppProxyServlet: dr.who is accessing unchecked http://ip-10-0-0-193:45943/static/jquery/themes-1.9.1/base/images/ui-icons_454545_256x240.png which is the app master GUI of application_1399289015992_0001 owned by ubuntu
2014-05-05 11:41:14,086 INFO org.apache.hadoop.yarn.server.webproxy.WebAppProxyServlet: dr.who is accessing unchecked http://ip-10-0-0-193:45943/mapreduce/job/job_1399289015992_0001 which is the app master GUI of application_1399289015992_0001 owned by ubuntu
2014-05-05 11:41:14,201 INFO org.apache.hadoop.yarn.server.webproxy.WebAppProxyServlet: dr.who is accessing unchecked http://ip-10-0-0-193:45943/static/jquery/jquery-1.8.2.min.js which is the app master GUI of application_1399289015992_0001 owned by ubuntu
2014-05-05 11:41:14,201 INFO org.apache.hadoop.yarn.server.webproxy.WebAppProxyServlet: dr.who is accessing unchecked http://ip-10-0-0-193:45943/static/yarn.css which is the app master GUI of application_1399289015992_0001 owned by ubuntu
2014-05-05 11:41:14,203 INFO org.apache.hadoop.yarn.server.webproxy.WebAppProxyServlet: dr.who is accessing unchecked http://ip-10-0-0-193:45943/static/dt-1.9.4/css/jui-dt.css which is the app master GUI of application_1399289015992_0001 owned by ubuntu
2014-05-05 11:41:14,203 INFO org.apache.hadoop.yarn.server.webproxy.WebAppProxyServlet: dr.who is accessing unchecked http://ip-10-0-0-193:45943/static/jquery/jquery-ui-1.9.1.custom.min.js which is the app master GUI of application_1399289015992_0001 owned by ubuntu
2014-05-05 11:41:14,205 INFO org.apache.hadoop.yarn.server.webproxy.WebAppProxyServlet: dr.who is accessing unchecked http://ip-10-0-0-193:45943/static/jquery/themes-1.9.1/base/jquery-ui.css which is the app master GUI of application_1399289015992_0001 owned by ubuntu
2014-05-05 11:41:14,206 INFO org.apache.hadoop.yarn.server.webproxy.WebAppProxyServlet: dr.who is accessing unchecked http://ip-10-0-0-193:45943/static/dt-1.9.4/js/jquery.dataTables.min.js which is the app master GUI of application_1399289015992_0001 owned by ubuntu
2014-05-05 11:41:14,285 INFO org.apache.hadoop.yarn.server.webproxy.WebAppProxyServlet: dr.who is accessing unchecked http://ip-10-0-0-193:45943/static/yarn.dt.plugins.js which is the app master GUI of application_1399289015992_0001 owned by ubuntu
2014-05-05 11:41:14,515 INFO org.apache.hadoop.yarn.server.webproxy.WebAppProxyServlet: dr.who is accessing unchecked http://ip-10-0-0-193:45943/static/jquery/themes-1.9.1/base/images/ui-bg_flat_75_ffffff_40x100.png which is the app master GUI of application_1399289015992_0001 owned by ubuntu
2014-05-05 11:41:14,515 INFO org.apache.hadoop.yarn.server.webproxy.WebAppProxyServlet: dr.who is accessing unchecked http://ip-10-0-0-193:45943/static/jquery/themes-1.9.1/base/images/ui-bg_glass_75_e6e6e6_1x400.png which is the app master GUI of application_1399289015992_0001 owned by ubuntu
2014-05-05 11:41:14,517 INFO org.apache.hadoop.yarn.server.webproxy.WebAppProxyServlet: dr.who is accessing unchecked http://ip-10-0-0-193:45943/static/jquery/themes-1.9.1/base/images/ui-bg_glass_95_fef1ec_1x400.png which is the app master GUI of application_1399289015992_0001 owned by ubuntu
2014-05-05 11:41:14,517 INFO org.apache.hadoop.yarn.server.webproxy.WebAppProxyServlet: dr.who is accessing unchecked http://ip-10-0-0-193:45943/static/jquery/themes-1.9.1/base/images/ui-bg_highlight-soft_75_cccccc_1x100.png which is the app master GUI of application_1399289015992_0001 owned by ubuntu
2014-05-05 11:41:14,527 INFO org.apache.hadoop.yarn.server.webproxy.WebAppProxyServlet: dr.who is accessing unchecked http://ip-10-0-0-193:45943/static/jquery/themes-1.9.1/base/images/ui-bg_glass_65_ffffff_1x400.png which is the app master GUI of application_1399289015992_0001 owned by ubuntu
2014-05-05 11:41:14,528 INFO org.apache.hadoop.yarn.server.webproxy.WebAppProxyServlet: dr.who is accessing unchecked http://ip-10-0-0-193:45943/static/jquery/themes-1.9.1/base/images/ui-icons_888888_256x240.png which is the app master GUI of application_1399289015992_0001 owned by ubuntu
2014-05-05 11:41:14,598 INFO org.apache.hadoop.yarn.server.webproxy.WebAppProxyServlet: dr.who is accessing unchecked http://ip-10-0-0-193:45943/static/jquery/themes-1.9.1/base/images/ui-icons_454545_256x240.png which is the app master GUI of application_1399289015992_0001 owned by ubuntu
2014-05-05 11:41:15,567 INFO org.apache.hadoop.yarn.server.webproxy.WebAppProxyServlet: dr.who is accessing unchecked http://ip-10-0-0-193:45943/mapreduce/job/job_1399289015992_0001 which is the app master GUI of application_1399289015992_0001 owned by ubuntu
2014-05-05 11:41:15,723 INFO org.apache.hadoop.yarn.server.webproxy.WebAppProxyServlet: dr.who is accessing unchecked http://ip-10-0-0-193:45943/static/yarn.css which is the app master GUI of application_1399289015992_0001 owned by ubuntu
2014-05-05 11:41:15,725 INFO org.apache.hadoop.yarn.server.webproxy.WebAppProxyServlet: dr.who is accessing unchecked http://ip-10-0-0-193:45943/static/dt-1.9.4/css/jui-dt.css which is the app master GUI of application_1399289015992_0001 owned by ubuntu
2014-05-05 11:41:15,725 INFO org.apache.hadoop.yarn.server.webproxy.WebAppProxyServlet: dr.who is accessing unchecked http://ip-10-0-0-193:45943/static/jquery/themes-1.9.1/base/jquery-ui.css which is the app master GUI of application_1399289015992_0001 owned by ubuntu
2014-05-05 11:41:15,727 INFO org.apache.hadoop.yarn.server.webproxy.WebAppProxyServlet: dr.who is accessing unchecked http://ip-10-0-0-193:45943/static/jquery/jquery-1.8.2.min.js which is the app master GUI of application_1399289015992_0001 owned by ubuntu
2014-05-05 11:41:15,727 INFO org.apache.hadoop.yarn.server.webproxy.WebAppProxyServlet: dr.who is accessing unchecked http://ip-10-0-0-193:45943/static/jquery/jquery-ui-1.9.1.custom.min.js which is the app master GUI of application_1399289015992_0001 owned by ubuntu
2014-05-05 11:41:15,728 INFO org.apache.hadoop.yarn.server.webproxy.WebAppProxyServlet: dr.who is accessing unchecked http://ip-10-0-0-193:45943/static/dt-1.9.4/js/jquery.dataTables.min.js which is the app master GUI of application_1399289015992_0001 owned by ubuntu
2014-05-05 11:41:15,806 INFO org.apache.hadoop.yarn.server.webproxy.WebAppProxyServlet: dr.who is accessing unchecked http://ip-10-0-0-193:45943/static/yarn.dt.plugins.js which is the app master GUI of application_1399289015992_0001 owned by ubuntu
2014-05-05 11:41:16,041 INFO org.apache.hadoop.yarn.server.webproxy.WebAppProxyServlet: dr.who is accessing unchecked http://ip-10-0-0-193:45943/static/jquery/themes-1.9.1/base/images/ui-bg_glass_95_fef1ec_1x400.png which is the app master GUI of application_1399289015992_0001 owned by ubuntu
2014-05-05 11:41:16,043 INFO org.apache.hadoop.yarn.server.webproxy.WebAppProxyServlet: dr.who is accessing unchecked http://ip-10-0-0-193:45943/static/jquery/themes-1.9.1/base/images/ui-bg_flat_75_ffffff_40x100.png which is the app master GUI of application_1399289015992_0001 owned by ubuntu
2014-05-05 11:41:16,043 INFO org.apache.hadoop.yarn.server.webproxy.WebAppProxyServlet: dr.who is accessing unchecked http://ip-10-0-0-193:45943/static/jquery/themes-1.9.1/base/images/ui-bg_highlight-soft_75_cccccc_1x100.png which is the app master GUI of application_1399289015992_0001 owned by ubuntu
2014-05-05 11:41:16,042 INFO org.apache.hadoop.yarn.server.webproxy.WebAppProxyServlet: dr.who is accessing unchecked http://ip-10-0-0-193:45943/static/jquery/themes-1.9.1/base/images/ui-bg_glass_75_e6e6e6_1x400.png which is the app master GUI of application_1399289015992_0001 owned by ubuntu
2014-05-05 11:41:16,052 INFO org.apache.hadoop.yarn.server.webproxy.WebAppProxyServlet: dr.who is accessing unchecked http://ip-10-0-0-193:45943/static/jquery/themes-1.9.1/base/images/ui-bg_glass_65_ffffff_1x400.png which is the app master GUI of application_1399289015992_0001 owned by ubuntu
2014-05-05 11:41:16,052 INFO org.apache.hadoop.yarn.server.webproxy.WebAppProxyServlet: dr.who is accessing unchecked http://ip-10-0-0-193:45943/static/jquery/themes-1.9.1/base/images/ui-icons_888888_256x240.png which is the app master GUI of application_1399289015992_0001 owned by ubuntu
2014-05-05 11:41:16,119 INFO org.apache.hadoop.yarn.server.webproxy.WebAppProxyServlet: dr.who is accessing unchecked http://ip-10-0-0-193:45943/static/jquery/themes-1.9.1/base/images/ui-icons_454545_256x240.png which is the app master GUI of application_1399289015992_0001 owned by ubuntu
2014-05-05 11:41:17,025 INFO org.apache.hadoop.yarn.server.webproxy.WebAppProxyServlet: dr.who is accessing unchecked http://ip-10-0-0-193:45943/mapreduce/job/job_1399289015992_0001 which is the app master GUI of application_1399289015992_0001 owned by ubuntu
2014-05-05 11:41:17,192 INFO org.apache.hadoop.yarn.server.webproxy.WebAppProxyServlet: dr.who is accessing unchecked http://ip-10-0-0-193:45943/static/yarn.css which is the app master GUI of application_1399289015992_0001 owned by ubuntu
2014-05-05 11:41:17,193 INFO org.apache.hadoop.yarn.server.webproxy.WebAppProxyServlet: dr.who is accessing unchecked http://ip-10-0-0-193:45943/static/dt-1.9.4/css/jui-dt.css which is the app master GUI of application_1399289015992_0001 owned by ubuntu
2014-05-05 11:41:17,195 INFO org.apache.hadoop.yarn.server.webproxy.WebAppProxyServlet: dr.who is accessing unchecked http://ip-10-0-0-193:45943/static/jquery/jquery-1.8.2.min.js which is the app master GUI of application_1399289015992_0001 owned by ubuntu
2014-05-05 11:41:17,195 INFO org.apache.hadoop.yarn.server.webproxy.WebAppProxyServlet: dr.who is accessing unchecked http://ip-10-0-0-193:45943/static/jquery/themes-1.9.1/base/jquery-ui.css which is the app master GUI of application_1399289015992_0001 owned by ubuntu
2014-05-05 11:41:17,197 INFO org.apache.hadoop.yarn.server.webproxy.WebAppProxyServlet: dr.who is accessing unchecked http://ip-10-0-0-193:45943/static/jquery/jquery-ui-1.9.1.custom.min.js which is the app master GUI of application_1399289015992_0001 owned by ubuntu
2014-05-05 11:41:17,197 INFO org.apache.hadoop.yarn.server.webproxy.WebAppProxyServlet: dr.who is accessing unchecked http://ip-10-0-0-193:45943/static/dt-1.9.4/js/jquery.dataTables.min.js which is the app master GUI of application_1399289015992_0001 owned by ubuntu
2014-05-05 11:41:17,269 INFO org.apache.hadoop.yarn.server.webproxy.WebAppProxyServlet: dr.who is accessing unchecked http://ip-10-0-0-193:45943/static/yarn.dt.plugins.js which is the app master GUI of application_1399289015992_0001 owned by ubuntu
2014-05-05 11:41:17,516 INFO org.apache.hadoop.yarn.server.webproxy.WebAppProxyServlet: dr.who is accessing unchecked http://ip-10-0-0-193:45943/static/jquery/themes-1.9.1/base/images/ui-bg_glass_95_fef1ec_1x400.png which is the app master GUI of application_1399289015992_0001 owned by ubuntu
2014-05-05 11:41:17,516 INFO org.apache.hadoop.yarn.server.webproxy.WebAppProxyServlet: dr.who is accessing unchecked http://ip-10-0-0-193:45943/static/jquery/themes-1.9.1/base/images/ui-bg_flat_75_ffffff_40x100.png which is the app master GUI of application_1399289015992_0001 owned by ubuntu
2014-05-05 11:41:17,519 INFO org.apache.hadoop.yarn.server.webproxy.WebAppProxyServlet: dr.who is accessing unchecked http://ip-10-0-0-193:45943/static/jquery/themes-1.9.1/base/images/ui-bg_highlight-soft_75_cccccc_1x100.png which is the app master GUI of application_1399289015992_0001 owned by ubuntu
2014-05-05 11:41:17,519 INFO org.apache.hadoop.yarn.server.webproxy.WebAppProxyServlet: dr.who is accessing unchecked http://ip-10-0-0-193:45943/static/jquery/themes-1.9.1/base/images/ui-bg_glass_75_e6e6e6_1x400.png which is the app master GUI of application_1399289015992_0001 owned by ubuntu
2014-05-05 11:41:17,527 INFO org.apache.hadoop.yarn.server.webproxy.WebAppProxyServlet: dr.who is accessing unchecked http://ip-10-0-0-193:45943/static/jquery/themes-1.9.1/base/images/ui-icons_888888_256x240.png which is the app master GUI of application_1399289015992_0001 owned by ubuntu
2014-05-05 11:41:17,527 INFO org.apache.hadoop.yarn.server.webproxy.WebAppProxyServlet: dr.who is accessing unchecked http://ip-10-0-0-193:45943/static/jquery/themes-1.9.1/base/images/ui-bg_glass_65_ffffff_1x400.png which is the app master GUI of application_1399289015992_0001 owned by ubuntu
2014-05-05 11:41:17,599 INFO org.apache.hadoop.yarn.server.webproxy.WebAppProxyServlet: dr.who is accessing unchecked http://ip-10-0-0-193:45943/static/jquery/themes-1.9.1/base/images/ui-icons_454545_256x240.png which is the app master GUI of application_1399289015992_0001 owned by ubuntu
2014-05-05 11:41:18,071 INFO org.apache.hadoop.yarn.server.webproxy.WebAppProxyServlet: dr.who is accessing unchecked http://ip-10-0-0-193:45943/mapreduce/job/job_1399289015992_0001 which is the app master GUI of application_1399289015992_0001 owned by ubuntu
2014-05-05 11:41:18,182 INFO org.apache.hadoop.yarn.server.webproxy.WebAppProxyServlet: dr.who is accessing unchecked http://ip-10-0-0-193:45943/static/dt-1.9.4/css/jui-dt.css which is the app master GUI of application_1399289015992_0001 owned by ubuntu
2014-05-05 11:41:18,182 INFO org.apache.hadoop.yarn.server.webproxy.WebAppProxyServlet: dr.who is accessing unchecked http://ip-10-0-0-193:45943/static/jquery/jquery-1.8.2.min.js which is the app master GUI of application_1399289015992_0001 owned by ubuntu
2014-05-05 11:41:18,184 INFO org.apache.hadoop.yarn.server.webproxy.WebAppProxyServlet: dr.who is accessing unchecked http://ip-10-0-0-193:45943/static/yarn.css which is the app master GUI of application_1399289015992_0001 owned by ubuntu
2014-05-05 11:41:18,184 INFO org.apache.hadoop.yarn.server.webproxy.WebAppProxyServlet: dr.who is accessing unchecked http://ip-10-0-0-193:45943/static/jquery/themes-1.9.1/base/jquery-ui.css which is the app master GUI of application_1399289015992_0001 owned by ubuntu
2014-05-05 11:41:18,186 INFO org.apache.hadoop.yarn.server.webproxy.WebAppProxyServlet: dr.who is accessing unchecked http://ip-10-0-0-193:45943/static/jquery/jquery-ui-1.9.1.custom.min.js which is the app master GUI of application_1399289015992_0001 owned by ubuntu
2014-05-05 11:41:18,187 INFO org.apache.hadoop.yarn.server.webproxy.WebAppProxyServlet: dr.who is accessing unchecked http://ip-10-0-0-193:45943/static/dt-1.9.4/js/jquery.dataTables.min.js which is the app master GUI of application_1399289015992_0001 owned by ubuntu
2014-05-05 11:41:18,265 INFO org.apache.hadoop.yarn.server.webproxy.WebAppProxyServlet: dr.who is accessing unchecked http://ip-10-0-0-193:45943/static/yarn.dt.plugins.js which is the app master GUI of application_1399289015992_0001 owned by ubuntu
2014-05-05 11:41:18,515 INFO org.apache.hadoop.yarn.server.webproxy.WebAppProxyServlet: dr.who is accessing unchecked http://ip-10-0-0-193:45943/static/jquery/themes-1.9.1/base/images/ui-bg_highlight-soft_75_cccccc_1x100.png which is the app master GUI of application_1399289015992_0001 owned by ubuntu
2014-05-05 11:41:18,515 INFO org.apache.hadoop.yarn.server.webproxy.WebAppProxyServlet: dr.who is accessing unchecked http://ip-10-0-0-193:45943/static/jquery/themes-1.9.1/base/images/ui-bg_glass_95_fef1ec_1x400.png which is the app master GUI of application_1399289015992_0001 owned by ubuntu
2014-05-05 11:41:18,516 INFO org.apache.hadoop.yarn.server.webproxy.WebAppProxyServlet: dr.who is accessing unchecked http://ip-10-0-0-193:45943/static/jquery/themes-1.9.1/base/images/ui-bg_flat_75_ffffff_40x100.png which is the app master GUI of application_1399289015992_0001 owned by ubuntu
2014-05-05 11:41:18,517 INFO org.apache.hadoop.yarn.server.webproxy.WebAppProxyServlet: dr.who is accessing unchecked http://ip-10-0-0-193:45943/static/jquery/themes-1.9.1/base/images/ui-bg_glass_75_e6e6e6_1x400.png which is the app master GUI of application_1399289015992_0001 owned by ubuntu
2014-05-05 11:41:18,524 INFO org.apache.hadoop.yarn.server.webproxy.WebAppProxyServlet: dr.who is accessing unchecked http://ip-10-0-0-193:45943/static/jquery/themes-1.9.1/base/images/ui-bg_glass_65_ffffff_1x400.png which is the app master GUI of application_1399289015992_0001 owned by ubuntu
2014-05-05 11:41:18,526 INFO org.apache.hadoop.yarn.server.webproxy.WebAppProxyServlet: dr.who is accessing unchecked http://ip-10-0-0-193:45943/static/jquery/themes-1.9.1/base/images/ui-icons_888888_256x240.png which is the app master GUI of application_1399289015992_0001 owned by ubuntu
2014-05-05 11:41:18,599 INFO org.apache.hadoop.yarn.server.webproxy.WebAppProxyServlet: dr.who is accessing unchecked http://ip-10-0-0-193:45943/static/jquery/themes-1.9.1/base/images/ui-icons_454545_256x240.png which is the app master GUI of application_1399289015992_0001 owned by ubuntu
2014-05-05 11:41:19,248 INFO org.apache.hadoop.yarn.server.webproxy.WebAppProxyServlet: dr.who is accessing unchecked http://ip-10-0-0-193:45943/mapreduce/job/job_1399289015992_0001 which is the app master GUI of application_1399289015992_0001 owned by ubuntu
2014-05-05 11:41:19,411 INFO org.apache.hadoop.yarn.server.webproxy.WebAppProxyServlet: dr.who is accessing unchecked http://ip-10-0-0-193:45943/static/jquery/jquery-ui-1.9.1.custom.min.js which is the app master GUI of application_1399289015992_0001 owned by ubuntu
2014-05-05 11:41:19,411 INFO org.apache.hadoop.yarn.server.webproxy.WebAppProxyServlet: dr.who is accessing unchecked http://ip-10-0-0-193:45943/static/dt-1.9.4/css/jui-dt.css which is the app master GUI of application_1399289015992_0001 owned by ubuntu
2014-05-05 11:41:19,413 INFO org.apache.hadoop.yarn.server.webproxy.WebAppProxyServlet: dr.who is accessing unchecked http://ip-10-0-0-193:45943/static/yarn.css which is the app master GUI of application_1399289015992_0001 owned by ubuntu
2014-05-05 11:41:19,413 INFO org.apache.hadoop.yarn.server.webproxy.WebAppProxyServlet: dr.who is accessing unchecked http://ip-10-0-0-193:45943/static/jquery/themes-1.9.1/base/jquery-ui.css which is the app master GUI of application_1399289015992_0001 owned by ubuntu
2014-05-05 11:41:19,415 INFO org.apache.hadoop.yarn.server.webproxy.WebAppProxyServlet: dr.who is accessing unchecked http://ip-10-0-0-193:45943/static/dt-1.9.4/js/jquery.dataTables.min.js which is the app master GUI of application_1399289015992_0001 owned by ubuntu
2014-05-05 11:41:19,417 INFO org.apache.hadoop.yarn.server.webproxy.WebAppProxyServlet: dr.who is accessing unchecked http://ip-10-0-0-193:45943/static/jquery/jquery-1.8.2.min.js which is the app master GUI of application_1399289015992_0001 owned by ubuntu
2014-05-05 11:41:19,497 INFO org.apache.hadoop.yarn.server.webproxy.WebAppProxyServlet: dr.who is accessing unchecked http://ip-10-0-0-193:45943/static/yarn.dt.plugins.js which is the app master GUI of application_1399289015992_0001 owned by ubuntu
2014-05-05 11:41:19,754 INFO org.apache.hadoop.yarn.server.webproxy.WebAppProxyServlet: dr.who is accessing unchecked http://ip-10-0-0-193:45943/static/jquery/themes-1.9.1/base/images/ui-bg_glass_95_fef1ec_1x400.png which is the app master GUI of application_1399289015992_0001 owned by ubuntu
2014-05-05 11:41:19,756 INFO org.apache.hadoop.yarn.server.webproxy.WebAppProxyServlet: dr.who is accessing unchecked http://ip-10-0-0-193:45943/static/jquery/themes-1.9.1/base/images/ui-bg_flat_75_ffffff_40x100.png which is the app master GUI of application_1399289015992_0001 owned by ubuntu
2014-05-05 11:41:19,757 INFO org.apache.hadoop.yarn.server.webproxy.WebAppProxyServlet: dr.who is accessing unchecked http://ip-10-0-0-193:45943/static/jquery/themes-1.9.1/base/images/ui-bg_glass_75_e6e6e6_1x400.png which is the app master GUI of application_1399289015992_0001 owned by ubuntu
2014-05-05 11:41:19,758 INFO org.apache.hadoop.yarn.server.webproxy.WebAppProxyServlet: dr.who is accessing unchecked http://ip-10-0-0-193:45943/static/jquery/themes-1.9.1/base/images/ui-bg_highlight-soft_75_cccccc_1x100.png which is the app master GUI of application_1399289015992_0001 owned by ubuntu
2014-05-05 11:41:19,765 INFO org.apache.hadoop.yarn.server.webproxy.WebAppProxyServlet: dr.who is accessing unchecked http://ip-10-0-0-193:45943/static/jquery/themes-1.9.1/base/images/ui-icons_888888_256x240.png which is the app master GUI of application_1399289015992_0001 owned by ubuntu
2014-05-05 11:41:19,765 INFO org.apache.hadoop.yarn.server.webproxy.WebAppProxyServlet: dr.who is accessing unchecked http://ip-10-0-0-193:45943/static/jquery/themes-1.9.1/base/images/ui-bg_glass_65_ffffff_1x400.png which is the app master GUI of application_1399289015992_0001 owned by ubuntu
2014-05-05 11:41:19,832 INFO org.apache.hadoop.yarn.server.webproxy.WebAppProxyServlet: dr.who is accessing unchecked http://ip-10-0-0-193:45943/static/jquery/themes-1.9.1/base/images/ui-icons_454545_256x240.png which is the app master GUI of application_1399289015992_0001 owned by ubuntu
2014-05-05 11:41:21,359 INFO org.apache.hadoop.yarn.server.webproxy.WebAppProxyServlet: dr.who is accessing unchecked http://ip-10-0-0-193:45943/mapreduce/job/job_1399289015992_0001 which is the app master GUI of application_1399289015992_0001 owned by ubuntu
2014-05-05 11:41:21,472 INFO org.apache.hadoop.yarn.server.webproxy.WebAppProxyServlet: dr.who is accessing unchecked http://ip-10-0-0-193:45943/static/yarn.css which is the app master GUI of application_1399289015992_0001 owned by ubuntu
2014-05-05 11:41:21,472 INFO org.apache.hadoop.yarn.server.webproxy.WebAppProxyServlet: dr.who is accessing unchecked http://ip-10-0-0-193:45943/static/jquery/themes-1.9.1/base/jquery-ui.css which is the app master GUI of application_1399289015992_0001 owned by ubuntu
2014-05-05 11:41:21,473 INFO org.apache.hadoop.yarn.server.webproxy.WebAppProxyServlet: dr.who is accessing unchecked http://ip-10-0-0-193:45943/static/dt-1.9.4/css/jui-dt.css which is the app master GUI of application_1399289015992_0001 owned by ubuntu
2014-05-05 11:41:21,474 INFO org.apache.hadoop.yarn.server.webproxy.WebAppProxyServlet: dr.who is accessing unchecked http://ip-10-0-0-193:45943/static/jquery/jquery-1.8.2.min.js which is the app master GUI of application_1399289015992_0001 owned by ubuntu
2014-05-05 11:41:21,475 INFO org.apache.hadoop.yarn.server.webproxy.WebAppProxyServlet: dr.who is accessing unchecked http://ip-10-0-0-193:45943/static/jquery/jquery-ui-1.9.1.custom.min.js which is the app master GUI of application_1399289015992_0001 owned by ubuntu
2014-05-05 11:41:21,476 INFO org.apache.hadoop.yarn.server.webproxy.WebAppProxyServlet: dr.who is accessing unchecked http://ip-10-0-0-193:45943/static/dt-1.9.4/js/jquery.dataTables.min.js which is the app master GUI of application_1399289015992_0001 owned by ubuntu
2014-05-05 11:41:21,557 INFO org.apache.hadoop.yarn.server.webproxy.WebAppProxyServlet: dr.who is accessing unchecked http://ip-10-0-0-193:45943/static/yarn.dt.plugins.js which is the app master GUI of application_1399289015992_0001 owned by ubuntu
2014-05-05 11:41:21,796 INFO org.apache.hadoop.yarn.server.webproxy.WebAppProxyServlet: dr.who is accessing unchecked http://ip-10-0-0-193:45943/static/jquery/themes-1.9.1/base/images/ui-bg_glass_95_fef1ec_1x400.png which is the app master GUI of application_1399289015992_0001 owned by ubuntu
2014-05-05 11:41:21,796 INFO org.apache.hadoop.yarn.server.webproxy.WebAppProxyServlet: dr.who is accessing unchecked http://ip-10-0-0-193:45943/static/jquery/themes-1.9.1/base/images/ui-bg_glass_75_e6e6e6_1x400.png which is the app master GUI of application_1399289015992_0001 owned by ubuntu
2014-05-05 11:41:21,798 INFO org.apache.hadoop.yarn.server.webproxy.WebAppProxyServlet: dr.who is accessing unchecked http://ip-10-0-0-193:45943/static/jquery/themes-1.9.1/base/images/ui-bg_highlight-soft_75_cccccc_1x100.png which is the app master GUI of application_1399289015992_0001 owned by ubuntu
2014-05-05 11:41:21,798 INFO org.apache.hadoop.yarn.server.webproxy.WebAppProxyServlet: dr.who is accessing unchecked http://ip-10-0-0-193:45943/static/jquery/themes-1.9.1/base/images/ui-bg_flat_75_ffffff_40x100.png which is the app master GUI of application_1399289015992_0001 owned by ubuntu
2014-05-05 11:41:21,804 INFO org.apache.hadoop.yarn.server.webproxy.WebAppProxyServlet: dr.who is accessing unchecked http://ip-10-0-0-193:45943/static/jquery/themes-1.9.1/base/images/ui-icons_888888_256x240.png which is the app master GUI of application_1399289015992_0001 owned by ubuntu
2014-05-05 11:41:21,816 INFO org.apache.hadoop.yarn.server.webproxy.WebAppProxyServlet: dr.who is accessing unchecked http://ip-10-0-0-193:45943/static/jquery/themes-1.9.1/base/images/ui-bg_glass_65_ffffff_1x400.png which is the app master GUI of application_1399289015992_0001 owned by ubuntu
2014-05-05 11:41:21,878 INFO org.apache.hadoop.yarn.server.webproxy.WebAppProxyServlet: dr.who is accessing unchecked http://ip-10-0-0-193:45943/static/jquery/themes-1.9.1/base/images/ui-icons_454545_256x240.png which is the app master GUI of application_1399289015992_0001 owned by ubuntu
2014-05-05 11:41:26,120 INFO org.apache.hadoop.yarn.server.webproxy.WebAppProxyServlet: dr.who is accessing unchecked http://ip-10-0-0-193:45943/mapreduce/job/job_1399289015992_0001 which is the app master GUI of application_1399289015992_0001 owned by ubuntu
2014-05-05 11:41:26,233 INFO org.apache.hadoop.yarn.server.webproxy.WebAppProxyServlet: dr.who is accessing unchecked http://ip-10-0-0-193:45943/static/jquery/jquery-1.8.2.min.js which is the app master GUI of application_1399289015992_0001 owned by ubuntu
2014-05-05 11:41:26,234 INFO org.apache.hadoop.yarn.server.webproxy.WebAppProxyServlet: dr.who is accessing unchecked http://ip-10-0-0-193:45943/static/dt-1.9.4/js/jquery.dataTables.min.js which is the app master GUI of application_1399289015992_0001 owned by ubuntu
2014-05-05 11:41:26,235 INFO org.apache.hadoop.yarn.server.webproxy.WebAppProxyServlet: dr.who is accessing unchecked http://ip-10-0-0-193:45943/static/yarn.css which is the app master GUI of application_1399289015992_0001 owned by ubuntu
2014-05-05 11:41:26,236 INFO org.apache.hadoop.yarn.server.webproxy.WebAppProxyServlet: dr.who is accessing unchecked http://ip-10-0-0-193:45943/static/dt-1.9.4/css/jui-dt.css which is the app master GUI of application_1399289015992_0001 owned by ubuntu
2014-05-05 11:41:26,237 INFO org.apache.hadoop.yarn.server.webproxy.WebAppProxyServlet: dr.who is accessing unchecked http://ip-10-0-0-193:45943/static/jquery/themes-1.9.1/base/jquery-ui.css which is the app master GUI of application_1399289015992_0001 owned by ubuntu
2014-05-05 11:41:26,237 INFO org.apache.hadoop.yarn.server.webproxy.WebAppProxyServlet: dr.who is accessing unchecked http://ip-10-0-0-193:45943/static/jquery/jquery-ui-1.9.1.custom.min.js which is the app master GUI of application_1399289015992_0001 owned by ubuntu
2014-05-05 11:41:26,319 INFO org.apache.hadoop.yarn.server.webproxy.WebAppProxyServlet: dr.who is accessing unchecked http://ip-10-0-0-193:45943/static/yarn.dt.plugins.js which is the app master GUI of application_1399289015992_0001 owned by ubuntu
2014-05-05 11:41:26,550 INFO org.apache.hadoop.yarn.server.webproxy.WebAppProxyServlet: dr.who is accessing unchecked http://ip-10-0-0-193:45943/static/jquery/themes-1.9.1/base/images/ui-bg_glass_95_fef1ec_1x400.png which is the app master GUI of application_1399289015992_0001 owned by ubuntu
2014-05-05 11:41:26,551 INFO org.apache.hadoop.yarn.server.webproxy.WebAppProxyServlet: dr.who is accessing unchecked http://ip-10-0-0-193:45943/static/jquery/themes-1.9.1/base/images/ui-bg_flat_75_ffffff_40x100.png which is the app master GUI of application_1399289015992_0001 owned by ubuntu
2014-05-05 11:41:26,553 INFO org.apache.hadoop.yarn.server.webproxy.WebAppProxyServlet: dr.who is accessing unchecked http://ip-10-0-0-193:45943/static/jquery/themes-1.9.1/base/images/ui-bg_glass_75_e6e6e6_1x400.png which is the app master GUI of application_1399289015992_0001 owned by ubuntu
2014-05-05 11:41:26,561 INFO org.apache.hadoop.yarn.server.webproxy.WebAppProxyServlet: dr.who is accessing unchecked http://ip-10-0-0-193:45943/static/jquery/themes-1.9.1/base/images/ui-bg_highlight-soft_75_cccccc_1x100.png which is the app master GUI of application_1399289015992_0001 owned by ubuntu
2014-05-05 11:41:26,562 INFO org.apache.hadoop.yarn.server.webproxy.WebAppProxyServlet: dr.who is accessing unchecked http://ip-10-0-0-193:45943/static/jquery/themes-1.9.1/base/images/ui-icons_888888_256x240.png which is the app master GUI of application_1399289015992_0001 owned by ubuntu
2014-05-05 11:41:26,574 INFO org.apache.hadoop.yarn.server.webproxy.WebAppProxyServlet: dr.who is accessing unchecked http://ip-10-0-0-193:45943/static/jquery/themes-1.9.1/base/images/ui-bg_glass_65_ffffff_1x400.png which is the app master GUI of application_1399289015992_0001 owned by ubuntu
2014-05-05 11:41:26,626 INFO org.apache.hadoop.yarn.server.webproxy.WebAppProxyServlet: dr.who is accessing unchecked http://ip-10-0-0-193:45943/static/jquery/themes-1.9.1/base/images/ui-icons_454545_256x240.png which is the app master GUI of application_1399289015992_0001 owned by ubuntu
2014-05-05 11:41:27,378 INFO org.apache.hadoop.yarn.server.webproxy.WebAppProxyServlet: dr.who is accessing unchecked http://ip-10-0-0-193:45943/mapreduce/job/job_1399289015992_0001 which is the app master GUI of application_1399289015992_0001 owned by ubuntu
2014-05-05 11:41:27,541 INFO org.apache.hadoop.yarn.server.webproxy.WebAppProxyServlet: dr.who is accessing unchecked http://ip-10-0-0-193:45943/static/yarn.css which is the app master GUI of application_1399289015992_0001 owned by ubuntu
2014-05-05 11:41:27,542 INFO org.apache.hadoop.yarn.server.webproxy.WebAppProxyServlet: dr.who is accessing unchecked http://ip-10-0-0-193:45943/static/jquery/themes-1.9.1/base/jquery-ui.css which is the app master GUI of application_1399289015992_0001 owned by ubuntu
2014-05-05 11:41:27,543 INFO org.apache.hadoop.yarn.server.webproxy.WebAppProxyServlet: dr.who is accessing unchecked http://ip-10-0-0-193:45943/static/dt-1.9.4/css/jui-dt.css which is the app master GUI of application_1399289015992_0001 owned by ubuntu
2014-05-05 11:41:27,544 INFO org.apache.hadoop.yarn.server.webproxy.WebAppProxyServlet: dr.who is accessing unchecked http://ip-10-0-0-193:45943/static/jquery/jquery-1.8.2.min.js which is the app master GUI of application_1399289015992_0001 owned by ubuntu
2014-05-05 11:41:27,545 INFO org.apache.hadoop.yarn.server.webproxy.WebAppProxyServlet: dr.who is accessing unchecked http://ip-10-0-0-193:45943/static/jquery/jquery-ui-1.9.1.custom.min.js which is the app master GUI of application_1399289015992_0001 owned by ubuntu
2014-05-05 11:41:27,546 INFO org.apache.hadoop.yarn.server.webproxy.WebAppProxyServlet: dr.who is accessing unchecked http://ip-10-0-0-193:45943/static/dt-1.9.4/js/jquery.dataTables.min.js which is the app master GUI of application_1399289015992_0001 owned by ubuntu
2014-05-05 11:41:27,628 INFO org.apache.hadoop.yarn.server.webproxy.WebAppProxyServlet: dr.who is accessing unchecked http://ip-10-0-0-193:45943/static/yarn.dt.plugins.js which is the app master GUI of application_1399289015992_0001 owned by ubuntu
2014-05-05 11:41:27,854 INFO org.apache.hadoop.yarn.server.webproxy.WebAppProxyServlet: dr.who is accessing unchecked http://ip-10-0-0-193:45943/static/jquery/themes-1.9.1/base/images/ui-bg_glass_95_fef1ec_1x400.png which is the app master GUI of application_1399289015992_0001 owned by ubuntu
2014-05-05 11:41:27,858 INFO org.apache.hadoop.yarn.server.webproxy.WebAppProxyServlet: dr.who is accessing unchecked http://ip-10-0-0-193:45943/static/jquery/themes-1.9.1/base/images/ui-bg_highlight-soft_75_cccccc_1x100.png which is the app master GUI of application_1399289015992_0001 owned by ubuntu
2014-05-05 11:41:27,859 INFO org.apache.hadoop.yarn.server.webproxy.WebAppProxyServlet: dr.who is accessing unchecked http://ip-10-0-0-193:45943/static/jquery/themes-1.9.1/base/images/ui-bg_glass_75_e6e6e6_1x400.png which is the app master GUI of application_1399289015992_0001 owned by ubuntu
2014-05-05 11:41:27,859 INFO org.apache.hadoop.yarn.server.webproxy.WebAppProxyServlet: dr.who is accessing unchecked http://ip-10-0-0-193:45943/static/jquery/themes-1.9.1/base/images/ui-bg_flat_75_ffffff_40x100.png which is the app master GUI of application_1399289015992_0001 owned by ubuntu
2014-05-05 11:41:27,869 INFO org.apache.hadoop.yarn.server.webproxy.WebAppProxyServlet: dr.who is accessing unchecked http://ip-10-0-0-193:45943/static/jquery/themes-1.9.1/base/images/ui-icons_888888_256x240.png which is the app master GUI of application_1399289015992_0001 owned by ubuntu
2014-05-05 11:41:27,870 INFO org.apache.hadoop.yarn.server.webproxy.WebAppProxyServlet: dr.who is accessing unchecked http://ip-10-0-0-193:45943/static/jquery/themes-1.9.1/base/images/ui-bg_glass_65_ffffff_1x400.png which is the app master GUI of application_1399289015992_0001 owned by ubuntu
2014-05-05 11:41:27,931 INFO org.apache.hadoop.yarn.server.webproxy.WebAppProxyServlet: dr.who is accessing unchecked http://ip-10-0-0-193:45943/static/jquery/themes-1.9.1/base/images/ui-icons_454545_256x240.png which is the app master GUI of application_1399289015992_0001 owned by ubuntu
2014-05-05 11:41:28,454 INFO org.apache.hadoop.yarn.server.webproxy.WebAppProxyServlet: dr.who is accessing unchecked http://ip-10-0-0-193:45943/mapreduce/job/job_1399289015992_0001 which is the app master GUI of application_1399289015992_0001 owned by ubuntu
2014-05-05 11:41:28,565 INFO org.apache.hadoop.yarn.server.webproxy.WebAppProxyServlet: dr.who is accessing unchecked http://ip-10-0-0-193:45943/static/yarn.css which is the app master GUI of application_1399289015992_0001 owned by ubuntu
2014-05-05 11:41:28,566 INFO org.apache.hadoop.yarn.server.webproxy.WebAppProxyServlet: dr.who is accessing unchecked http://ip-10-0-0-193:45943/static/dt-1.9.4/css/jui-dt.css which is the app master GUI of application_1399289015992_0001 owned by ubuntu
2014-05-05 11:41:28,567 INFO org.apache.hadoop.yarn.server.webproxy.WebAppProxyServlet: dr.who is accessing unchecked http://ip-10-0-0-193:45943/static/jquery/themes-1.9.1/base/jquery-ui.css which is the app master GUI of application_1399289015992_0001 owned by ubuntu
2014-05-05 11:41:28,568 INFO org.apache.hadoop.yarn.server.webproxy.WebAppProxyServlet: dr.who is accessing unchecked http://ip-10-0-0-193:45943/static/jquery/jquery-1.8.2.min.js which is the app master GUI of application_1399289015992_0001 owned by ubuntu
2014-05-05 11:41:28,568 INFO org.apache.hadoop.yarn.server.webproxy.WebAppProxyServlet: dr.who is accessing unchecked http://ip-10-0-0-193:45943/static/dt-1.9.4/js/jquery.dataTables.min.js which is the app master GUI of application_1399289015992_0001 owned by ubuntu
2014-05-05 11:41:28,570 INFO org.apache.hadoop.yarn.server.webproxy.WebAppProxyServlet: dr.who is accessing unchecked http://ip-10-0-0-193:45943/static/jquery/jquery-ui-1.9.1.custom.min.js which is the app master GUI of application_1399289015992_0001 owned by ubuntu
2014-05-05 11:41:28,643 INFO org.apache.hadoop.yarn.server.webproxy.WebAppProxyServlet: dr.who is accessing unchecked http://ip-10-0-0-193:45943/static/yarn.dt.plugins.js which is the app master GUI of application_1399289015992_0001 owned by ubuntu
2014-05-05 11:41:28,882 INFO org.apache.hadoop.yarn.server.webproxy.WebAppProxyServlet: dr.who is accessing unchecked http://ip-10-0-0-193:45943/static/jquery/themes-1.9.1/base/images/ui-bg_glass_95_fef1ec_1x400.png which is the app master GUI of application_1399289015992_0001 owned by ubuntu
2014-05-05 11:41:28,883 INFO org.apache.hadoop.yarn.server.webproxy.WebAppProxyServlet: dr.who is accessing unchecked http://ip-10-0-0-193:45943/static/jquery/themes-1.9.1/base/images/ui-bg_glass_75_e6e6e6_1x400.png which is the app master GUI of application_1399289015992_0001 owned by ubuntu
2014-05-05 11:41:28,885 INFO org.apache.hadoop.yarn.server.webproxy.WebAppProxyServlet: dr.who is accessing unchecked http://ip-10-0-0-193:45943/static/jquery/themes-1.9.1/base/images/ui-bg_flat_75_ffffff_40x100.png which is the app master GUI of application_1399289015992_0001 owned by ubuntu
2014-05-05 11:41:28,885 INFO org.apache.hadoop.yarn.server.webproxy.WebAppProxyServlet: dr.who is accessing unchecked http://ip-10-0-0-193:45943/static/jquery/themes-1.9.1/base/images/ui-bg_highlight-soft_75_cccccc_1x100.png which is the app master GUI of application_1399289015992_0001 owned by ubuntu
2014-05-05 11:41:28,893 INFO org.apache.hadoop.yarn.server.webproxy.WebAppProxyServlet: dr.who is accessing unchecked http://ip-10-0-0-193:45943/static/jquery/themes-1.9.1/base/images/ui-icons_888888_256x240.png which is the app master GUI of application_1399289015992_0001 owned by ubuntu
2014-05-05 11:41:28,896 INFO org.apache.hadoop.yarn.server.webproxy.WebAppProxyServlet: dr.who is accessing unchecked http://ip-10-0-0-193:45943/static/jquery/themes-1.9.1/base/images/ui-bg_glass_65_ffffff_1x400.png which is the app master GUI of application_1399289015992_0001 owned by ubuntu
2014-05-05 11:41:28,962 INFO org.apache.hadoop.yarn.server.webproxy.WebAppProxyServlet: dr.who is accessing unchecked http://ip-10-0-0-193:45943/static/jquery/themes-1.9.1/base/images/ui-icons_454545_256x240.png which is the app master GUI of application_1399289015992_0001 owned by ubuntu
2014-05-05 11:41:29,423 INFO org.apache.hadoop.yarn.server.webproxy.WebAppProxyServlet: dr.who is accessing unchecked http://ip-10-0-0-193:45943/mapreduce/job/job_1399289015992_0001 which is the app master GUI of application_1399289015992_0001 owned by ubuntu
2014-05-05 11:41:29,535 INFO org.apache.hadoop.yarn.server.webproxy.WebAppProxyServlet: dr.who is accessing unchecked http://ip-10-0-0-193:45943/static/yarn.css which is the app master GUI of application_1399289015992_0001 owned by ubuntu
2014-05-05 11:41:29,536 INFO org.apache.hadoop.yarn.server.webproxy.WebAppProxyServlet: dr.who is accessing unchecked http://ip-10-0-0-193:45943/static/jquery/themes-1.9.1/base/jquery-ui.css which is the app master GUI of application_1399289015992_0001 owned by ubuntu
2014-05-05 11:41:29,536 INFO org.apache.hadoop.yarn.server.webproxy.WebAppProxyServlet: dr.who is accessing unchecked http://ip-10-0-0-193:45943/static/dt-1.9.4/css/jui-dt.css which is the app master GUI of application_1399289015992_0001 owned by ubuntu
2014-05-05 11:41:29,538 INFO org.apache.hadoop.yarn.server.webproxy.WebAppProxyServlet: dr.who is accessing unchecked http://ip-10-0-0-193:45943/static/jquery/jquery-ui-1.9.1.custom.min.js which is the app master GUI of application_1399289015992_0001 owned by ubuntu
2014-05-05 11:41:29,538 INFO org.apache.hadoop.yarn.server.webproxy.WebAppProxyServlet: dr.who is accessing unchecked http://ip-10-0-0-193:45943/static/dt-1.9.4/js/jquery.dataTables.min.js which is the app master GUI of application_1399289015992_0001 owned by ubuntu
2014-05-05 11:41:29,540 INFO org.apache.hadoop.yarn.server.webproxy.WebAppProxyServlet: dr.who is accessing unchecked http://ip-10-0-0-193:45943/static/jquery/jquery-1.8.2.min.js which is the app master GUI of application_1399289015992_0001 owned by ubuntu
2014-05-05 11:41:29,615 INFO org.apache.hadoop.yarn.server.webproxy.WebAppProxyServlet: dr.who is accessing unchecked http://ip-10-0-0-193:45943/static/yarn.dt.plugins.js which is the app master GUI of application_1399289015992_0001 owned by ubuntu
2014-05-05 11:41:29,851 INFO org.apache.hadoop.yarn.server.webproxy.WebAppProxyServlet: dr.who is accessing unchecked http://ip-10-0-0-193:45943/static/jquery/themes-1.9.1/base/images/ui-bg_glass_95_fef1ec_1x400.png which is the app master GUI of application_1399289015992_0001 owned by ubuntu
2014-05-05 11:41:29,853 INFO org.apache.hadoop.yarn.server.webproxy.WebAppProxyServlet: dr.who is accessing unchecked http://ip-10-0-0-193:45943/static/jquery/themes-1.9.1/base/images/ui-bg_flat_75_ffffff_40x100.png which is the app master GUI of application_1399289015992_0001 owned by ubuntu
2014-05-05 11:41:29,854 INFO org.apache.hadoop.yarn.server.webproxy.WebAppProxyServlet: dr.who is accessing unchecked http://ip-10-0-0-193:45943/static/jquery/themes-1.9.1/base/images/ui-bg_glass_75_e6e6e6_1x400.png which is the app master GUI of application_1399289015992_0001 owned by ubuntu
2014-05-05 11:41:29,856 INFO org.apache.hadoop.yarn.server.webproxy.WebAppProxyServlet: dr.who is accessing unchecked http://ip-10-0-0-193:45943/static/jquery/themes-1.9.1/base/images/ui-bg_highlight-soft_75_cccccc_1x100.png which is the app master GUI of application_1399289015992_0001 owned by ubuntu
2014-05-05 11:41:29,865 INFO org.apache.hadoop.yarn.server.webproxy.WebAppProxyServlet: dr.who is accessing unchecked http://ip-10-0-0-193:45943/static/jquery/themes-1.9.1/base/images/ui-icons_888888_256x240.png which is the app master GUI of application_1399289015992_0001 owned by ubuntu
2014-05-05 11:41:29,865 INFO org.apache.hadoop.yarn.server.webproxy.WebAppProxyServlet: dr.who is accessing unchecked http://ip-10-0-0-193:45943/static/jquery/themes-1.9.1/base/images/ui-bg_glass_65_ffffff_1x400.png which is the app master GUI of application_1399289015992_0001 owned by ubuntu
2014-05-05 11:41:29,934 INFO org.apache.hadoop.yarn.server.webproxy.WebAppProxyServlet: dr.who is accessing unchecked http://ip-10-0-0-193:45943/static/jquery/themes-1.9.1/base/images/ui-icons_454545_256x240.png which is the app master GUI of application_1399289015992_0001 owned by ubuntu
2014-05-05 11:41:33,766 INFO org.apache.hadoop.yarn.server.webproxy.WebAppProxyServlet: dr.who is accessing unchecked http://ip-10-0-0-193:45943/mapreduce/job/job_1399289015992_0001 which is the app master GUI of application_1399289015992_0001 owned by ubuntu
2014-05-05 11:41:33,926 INFO org.apache.hadoop.yarn.server.webproxy.WebAppProxyServlet: dr.who is accessing unchecked http://ip-10-0-0-193:45943/static/yarn.css which is the app master GUI of application_1399289015992_0001 owned by ubuntu
2014-05-05 11:41:33,926 INFO org.apache.hadoop.yarn.server.webproxy.WebAppProxyServlet: dr.who is accessing unchecked http://ip-10-0-0-193:45943/static/dt-1.9.4/css/jui-dt.css which is the app master GUI of application_1399289015992_0001 owned by ubuntu
2014-05-05 11:41:33,928 INFO org.apache.hadoop.yarn.server.webproxy.WebAppProxyServlet: dr.who is accessing unchecked http://ip-10-0-0-193:45943/static/dt-1.9.4/js/jquery.dataTables.min.js which is the app master GUI of application_1399289015992_0001 owned by ubuntu
2014-05-05 11:41:33,928 INFO org.apache.hadoop.yarn.server.webproxy.WebAppProxyServlet: dr.who is accessing unchecked http://ip-10-0-0-193:45943/static/jquery/jquery-ui-1.9.1.custom.min.js which is the app master GUI of application_1399289015992_0001 owned by ubuntu
2014-05-05 11:41:33,929 INFO org.apache.hadoop.yarn.server.webproxy.WebAppProxyServlet: dr.who is accessing unchecked http://ip-10-0-0-193:45943/static/jquery/themes-1.9.1/base/jquery-ui.css which is the app master GUI of application_1399289015992_0001 owned by ubuntu
2014-05-05 11:41:33,931 INFO org.apache.hadoop.yarn.server.webproxy.WebAppProxyServlet: dr.who is accessing unchecked http://ip-10-0-0-193:45943/static/jquery/jquery-1.8.2.min.js which is the app master GUI of application_1399289015992_0001 owned by ubuntu
2014-05-05 11:41:34,013 INFO org.apache.hadoop.yarn.server.webproxy.WebAppProxyServlet: dr.who is accessing unchecked http://ip-10-0-0-193:45943/static/yarn.dt.plugins.js which is the app master GUI of application_1399289015992_0001 owned by ubuntu
2014-05-05 11:41:34,244 INFO org.apache.hadoop.yarn.server.webproxy.WebAppProxyServlet: dr.who is accessing unchecked http://ip-10-0-0-193:45943/static/jquery/themes-1.9.1/base/images/ui-bg_glass_95_fef1ec_1x400.png which is the app master GUI of application_1399289015992_0001 owned by ubuntu
2014-05-05 11:41:34,246 INFO org.apache.hadoop.yarn.server.webproxy.WebAppProxyServlet: dr.who is accessing unchecked http://ip-10-0-0-193:45943/static/jquery/themes-1.9.1/base/images/ui-bg_flat_75_ffffff_40x100.png which is the app master GUI of application_1399289015992_0001 owned by ubuntu
2014-05-05 11:41:34,246 INFO org.apache.hadoop.yarn.server.webproxy.WebAppProxyServlet: dr.who is accessing unchecked http://ip-10-0-0-193:45943/static/jquery/themes-1.9.1/base/images/ui-bg_glass_75_e6e6e6_1x400.png which is the app master GUI of application_1399289015992_0001 owned by ubuntu
2014-05-05 11:41:34,247 INFO org.apache.hadoop.yarn.server.webproxy.WebAppProxyServlet: dr.who is accessing unchecked http://ip-10-0-0-193:45943/static/jquery/themes-1.9.1/base/images/ui-bg_highlight-soft_75_cccccc_1x100.png which is the app master GUI of application_1399289015992_0001 owned by ubuntu
2014-05-05 11:41:34,255 INFO org.apache.hadoop.yarn.server.webproxy.WebAppProxyServlet: dr.who is accessing unchecked http://ip-10-0-0-193:45943/static/jquery/themes-1.9.1/base/images/ui-bg_glass_65_ffffff_1x400.png which is the app master GUI of application_1399289015992_0001 owned by ubuntu
2014-05-05 11:41:34,258 INFO org.apache.hadoop.yarn.server.webproxy.WebAppProxyServlet: dr.who is accessing unchecked http://ip-10-0-0-193:45943/static/jquery/themes-1.9.1/base/images/ui-icons_888888_256x240.png which is the app master GUI of application_1399289015992_0001 owned by ubuntu
2014-05-05 11:41:34,327 INFO org.apache.hadoop.yarn.server.webproxy.WebAppProxyServlet: dr.who is accessing unchecked http://ip-10-0-0-193:45943/static/jquery/themes-1.9.1/base/images/ui-icons_454545_256x240.png which is the app master GUI of application_1399289015992_0001 owned by ubuntu
2014-05-05 11:41:34,716 INFO org.apache.hadoop.yarn.server.webproxy.WebAppProxyServlet: dr.who is accessing unchecked http://ip-10-0-0-193:45943/mapreduce/job/job_1399289015992_0001 which is the app master GUI of application_1399289015992_0001 owned by ubuntu
2014-05-05 11:41:34,879 INFO org.apache.hadoop.yarn.server.webproxy.WebAppProxyServlet: dr.who is accessing unchecked http://ip-10-0-0-193:45943/static/yarn.css which is the app master GUI of application_1399289015992_0001 owned by ubuntu
2014-05-05 11:41:34,879 INFO org.apache.hadoop.yarn.server.webproxy.WebAppProxyServlet: dr.who is accessing unchecked http://ip-10-0-0-193:45943/static/jquery/themes-1.9.1/base/jquery-ui.css which is the app master GUI of application_1399289015992_0001 owned by ubuntu
2014-05-05 11:41:34,880 INFO org.apache.hadoop.yarn.server.webproxy.WebAppProxyServlet: dr.who is accessing unchecked http://ip-10-0-0-193:45943/static/dt-1.9.4/js/jquery.dataTables.min.js which is the app master GUI of application_1399289015992_0001 owned by ubuntu
2014-05-05 11:41:34,881 INFO org.apache.hadoop.yarn.server.webproxy.WebAppProxyServlet: dr.who is accessing unchecked http://ip-10-0-0-193:45943/static/jquery/jquery-1.8.2.min.js which is the app master GUI of application_1399289015992_0001 owned by ubuntu
2014-05-05 11:41:34,882 INFO org.apache.hadoop.yarn.server.webproxy.WebAppProxyServlet: dr.who is accessing unchecked http://ip-10-0-0-193:45943/static/dt-1.9.4/css/jui-dt.css which is the app master GUI of application_1399289015992_0001 owned by ubuntu
2014-05-05 11:41:34,883 INFO org.apache.hadoop.yarn.server.webproxy.WebAppProxyServlet: dr.who is accessing unchecked http://ip-10-0-0-193:45943/static/jquery/jquery-ui-1.9.1.custom.min.js which is the app master GUI of application_1399289015992_0001 owned by ubuntu
2014-05-05 11:41:34,961 INFO org.apache.hadoop.yarn.server.webproxy.WebAppProxyServlet: dr.who is accessing unchecked http://ip-10-0-0-193:45943/static/yarn.dt.plugins.js which is the app master GUI of application_1399289015992_0001 owned by ubuntu
2014-05-05 11:41:35,197 INFO org.apache.hadoop.yarn.server.webproxy.WebAppProxyServlet: dr.who is accessing unchecked http://ip-10-0-0-193:45943/static/jquery/themes-1.9.1/base/images/ui-bg_glass_95_fef1ec_1x400.png which is the app master GUI of application_1399289015992_0001 owned by ubuntu
2014-05-05 11:41:35,198 INFO org.apache.hadoop.yarn.server.webproxy.WebAppProxyServlet: dr.who is accessing unchecked http://ip-10-0-0-193:45943/static/jquery/themes-1.9.1/base/images/ui-bg_highlight-soft_75_cccccc_1x100.png which is the app master GUI of application_1399289015992_0001 owned by ubuntu
2014-05-05 11:41:35,198 INFO org.apache.hadoop.yarn.server.webproxy.WebAppProxyServlet: dr.who is accessing unchecked http://ip-10-0-0-193:45943/static/jquery/themes-1.9.1/base/images/ui-bg_flat_75_ffffff_40x100.png which is the app master GUI of application_1399289015992_0001 owned by ubuntu
2014-05-05 11:41:35,197 INFO org.apache.hadoop.yarn.server.webproxy.WebAppProxyServlet: dr.who is accessing unchecked http://ip-10-0-0-193:45943/static/jquery/themes-1.9.1/base/images/ui-bg_glass_75_e6e6e6_1x400.png which is the app master GUI of application_1399289015992_0001 owned by ubuntu
2014-05-05 11:41:35,206 INFO org.apache.hadoop.yarn.server.webproxy.WebAppProxyServlet: dr.who is accessing unchecked http://ip-10-0-0-193:45943/static/jquery/themes-1.9.1/base/images/ui-icons_888888_256x240.png which is the app master GUI of application_1399289015992_0001 owned by ubuntu
2014-05-05 11:41:35,207 INFO org.apache.hadoop.yarn.server.webproxy.WebAppProxyServlet: dr.who is accessing unchecked http://ip-10-0-0-193:45943/static/jquery/themes-1.9.1/base/images/ui-bg_glass_65_ffffff_1x400.png which is the app master GUI of application_1399289015992_0001 owned by ubuntu
2014-05-05 11:41:35,278 INFO org.apache.hadoop.yarn.server.webproxy.WebAppProxyServlet: dr.who is accessing unchecked http://ip-10-0-0-193:45943/static/jquery/themes-1.9.1/base/images/ui-icons_454545_256x240.png which is the app master GUI of application_1399289015992_0001 owned by ubuntu
2014-05-05 11:41:41,106 INFO org.apache.hadoop.yarn.server.webproxy.WebAppProxyServlet: dr.who is accessing unchecked http://ip-10-0-0-193:45943/static/jquery/themes-1.9.1/base/images/ui-icons_454545_256x240.png which is the app master GUI of application_1399289015992_0001 owned by ubuntu
2014-05-05 11:41:41,107 INFO org.apache.hadoop.yarn.server.webproxy.WebAppProxyServlet: dr.who is accessing unchecked http://ip-10-0-0-193:45943/static/jquery/themes-1.9.1/base/images/ui-bg_glass_75_dadada_1x400.png which is the app master GUI of application_1399289015992_0001 owned by ubuntu
2014-05-05 11:42:05,295 INFO org.apache.hadoop.yarn.server.resourcemanager.rmapp.attempt.RMAppAttemptImpl: appattempt_1399289015992_0001_000001 State change from RUNNING to FINISHING
2014-05-05 11:42:05,295 INFO org.apache.hadoop.yarn.server.resourcemanager.rmapp.RMAppImpl: Removing application with id application_1399289015992_0001
2014-05-05 11:42:05,296 INFO org.apache.hadoop.yarn.server.resourcemanager.rmapp.RMAppImpl: application_1399289015992_0001 State change from RUNNING to REMOVING
2014-05-05 11:42:05,296 INFO org.apache.hadoop.yarn.server.resourcemanager.recovery.RMStateStore: Removing info for app: application_1399289015992_0001
2014-05-05 11:42:05,296 INFO org.apache.hadoop.yarn.server.resourcemanager.rmapp.RMAppImpl: application_1399289015992_0001 State change from REMOVING to FINISHING
2014-05-05 11:42:11,846 INFO org.apache.hadoop.yarn.server.resourcemanager.rmcontainer.RMContainerImpl: container_1399289015992_0001_01_000001 Container Transitioned from RUNNING to COMPLETED
2014-05-05 11:42:11,846 INFO org.apache.hadoop.yarn.server.resourcemanager.ApplicationMasterService: Unregistering app attempt : appattempt_1399289015992_0001_000001
2014-05-05 11:42:11,846 INFO org.apache.hadoop.yarn.server.resourcemanager.scheduler.common.fica.FiCaSchedulerApp: Completed container: container_1399289015992_0001_01_000001 in state: COMPLETED event:FINISHED
2014-05-05 11:42:11,846 INFO org.apache.hadoop.yarn.server.resourcemanager.RMAuditLogger: USER=ubuntu	OPERATION=AM Released Container	TARGET=SchedulerApp	RESULT=SUCCESS	APPID=application_1399289015992_0001	CONTAINERID=container_1399289015992_0001_01_000001
2014-05-05 11:42:11,846 INFO org.apache.hadoop.yarn.server.resourcemanager.scheduler.common.fica.FiCaSchedulerNode: Released container container_1399289015992_0001_01_000001 of capacity <memory:2048, vCores:1> on host ip-10-0-0-193.us-west-2.compute.internal:60686, which currently has 0 containers, <memory:0, vCores:0> used and <memory:8192, vCores:8> available, release resources=true
2014-05-05 11:42:11,846 INFO org.apache.hadoop.yarn.server.resourcemanager.scheduler.capacity.LeafQueue: default used=<memory:0, vCores:0> numContainers=0 user=ubuntu user-resources=<memory:0, vCores:0>
2014-05-05 11:42:11,847 INFO org.apache.hadoop.yarn.server.resourcemanager.scheduler.capacity.LeafQueue: completedContainer container=Container: [ContainerId: container_1399289015992_0001_01_000001, NodeId: ip-10-0-0-193.us-west-2.compute.internal:60686, NodeHttpAddress: ip-10-0-0-193.us-west-2.compute.internal:8042, Resource: <memory:2048, vCores:1>, Priority: 0, Token: Token { kind: ContainerToken, service: 10.0.0.193:60686 }, ] resource=<memory:2048, vCores:1> queue=default: capacity=1.0, absoluteCapacity=1.0, usedResources=<memory:0, vCores:0>usedCapacity=0.0, absoluteUsedCapacity=0.0, numApps=1, numContainers=0 usedCapacity=0.0 absoluteUsedCapacity=0.0 used=<memory:0, vCores:0> cluster=<memory:65536, vCores:64>
2014-05-05 11:42:11,847 INFO org.apache.hadoop.yarn.server.resourcemanager.scheduler.capacity.ParentQueue: completedContainer queue=root usedCapacity=0.0 absoluteUsedCapacity=0.0 used=<memory:0, vCores:0> cluster=<memory:65536, vCores:64>
2014-05-05 11:42:11,847 INFO org.apache.hadoop.yarn.server.resourcemanager.scheduler.capacity.ParentQueue: Re-sorting completed queue: root.default stats: default: capacity=1.0, absoluteCapacity=1.0, usedResources=<memory:0, vCores:0>usedCapacity=0.0, absoluteUsedCapacity=0.0, numApps=1, numContainers=0
2014-05-05 11:42:11,847 INFO org.apache.hadoop.yarn.server.resourcemanager.scheduler.capacity.CapacityScheduler: Application appattempt_1399289015992_0001_000001 released container container_1399289015992_0001_01_000001 on node: host: ip-10-0-0-193.us-west-2.compute.internal:60686 #containers=0 available=8192 used=0 with event: FINISHED
2014-05-05 11:42:11,848 INFO org.apache.hadoop.yarn.server.resourcemanager.rmapp.attempt.RMAppAttemptImpl: appattempt_1399289015992_0001_000001 State change from FINISHING to FINISHED
2014-05-05 11:42:11,849 INFO org.apache.hadoop.yarn.server.resourcemanager.rmapp.RMAppImpl: application_1399289015992_0001 State change from FINISHING to FINISHED
2014-05-05 11:42:11,850 INFO org.apache.hadoop.yarn.server.resourcemanager.scheduler.capacity.CapacityScheduler: Application appattempt_1399289015992_0001_000001 is done. finalState=FINISHED
2014-05-05 11:42:11,850 INFO org.apache.hadoop.yarn.server.resourcemanager.scheduler.AppSchedulingInfo: Application application_1399289015992_0001 requests cleared
2014-05-05 11:42:11,850 INFO org.apache.hadoop.yarn.server.resourcemanager.RMAuditLogger: USER=ubuntu	OPERATION=Application Finished - Succeeded	TARGET=RMAppManager	RESULT=SUCCESS	APPID=application_1399289015992_0001
2014-05-05 11:42:11,851 INFO org.apache.hadoop.yarn.server.resourcemanager.scheduler.capacity.LeafQueue: Application removed - appId: application_1399289015992_0001 user: ubuntu queue: default #user-pending-applications: 0 #user-active-applications: 0 #queue-pending-applications: 0 #queue-active-applications: 0
2014-05-05 11:42:11,851 INFO org.apache.hadoop.yarn.server.resourcemanager.scheduler.capacity.ParentQueue: Application removed - appId: application_1399289015992_0001 user: ubuntu leaf-queue of parent: root #applications: 0
2014-05-05 11:42:11,852 INFO org.apache.hadoop.yarn.server.resourcemanager.amlauncher.AMLauncher: Cleaning master appattempt_1399289015992_0001_000001
2014-05-05 11:42:11,853 INFO org.apache.hadoop.yarn.server.resourcemanager.RMAppManager$ApplicationSummary: appId=application_1399289015992_0001,name=hints||path:/in1m||num reduce:8,user=ubuntu,queue=default,state=FINISHED,trackingUrl=ec2-54-186-230-200.us-west-2.compute.amazonaws.com:8088/proxy/application_1399289015992_0001/jobhistory/job/job_1399289015992_0001,appMasterHost=ip-10-0-0-193,startTime=1399289934362,finishTime=1399290125296,finalStatus=KILLED
2014-05-05 11:42:55,529 INFO org.apache.hadoop.yarn.server.resourcemanager.ClientRMService: Allocated new applicationId: 2
2014-05-05 11:42:57,884 INFO org.apache.hadoop.yarn.server.resourcemanager.ClientRMService: Application with id 2 submitted by user ubuntu
2014-05-05 11:42:57,884 INFO org.apache.hadoop.yarn.server.resourcemanager.rmapp.RMAppImpl: Storing application with id application_1399289015992_0002
2014-05-05 11:42:57,884 INFO org.apache.hadoop.yarn.server.resourcemanager.rmapp.RMAppImpl: application_1399289015992_0002 State change from NEW to NEW_SAVING
2014-05-05 11:42:57,884 INFO org.apache.hadoop.yarn.server.resourcemanager.recovery.RMStateStore: Storing info for app: application_1399289015992_0002
2014-05-05 11:42:57,884 INFO org.apache.hadoop.yarn.server.resourcemanager.RMAuditLogger: USER=ubuntu	IP=10.0.0.195	OPERATION=Submit Application Request	TARGET=ClientRMService	RESULT=SUCCESS	APPID=application_1399289015992_0002
2014-05-05 11:42:57,886 INFO org.apache.hadoop.yarn.server.resourcemanager.rmapp.RMAppImpl: application_1399289015992_0002 State change from NEW_SAVING to SUBMITTED
2014-05-05 11:42:57,886 INFO org.apache.hadoop.yarn.server.resourcemanager.ApplicationMasterService: Registering app attempt : appattempt_1399289015992_0002_000001
2014-05-05 11:42:57,886 INFO org.apache.hadoop.yarn.server.resourcemanager.rmapp.attempt.RMAppAttemptImpl: appattempt_1399289015992_0002_000001 State change from NEW to SUBMITTED
2014-05-05 11:42:57,886 INFO org.apache.hadoop.yarn.server.resourcemanager.scheduler.capacity.LeafQueue: Application application_1399289015992_0002 from user: ubuntu activated in queue: default
2014-05-05 11:42:57,886 INFO org.apache.hadoop.yarn.server.resourcemanager.scheduler.capacity.LeafQueue: Application added - appId: application_1399289015992_0002 user: org.apache.hadoop.yarn.server.resourcemanager.scheduler.capacity.LeafQueue$User@2c7bf31a, leaf-queue: default #user-pending-applications: 0 #user-active-applications: 1 #queue-pending-applications: 0 #queue-active-applications: 1
2014-05-05 11:42:57,886 INFO org.apache.hadoop.yarn.server.resourcemanager.scheduler.capacity.ParentQueue: Application added - appId: application_1399289015992_0002 user: ubuntu leaf-queue of parent: root #applications: 1
2014-05-05 11:42:57,887 INFO org.apache.hadoop.yarn.server.resourcemanager.scheduler.capacity.CapacityScheduler: Application Submission: appattempt_1399289015992_0002_000001, user: ubuntu queue: default: capacity=1.0, absoluteCapacity=1.0, usedResources=<memory:0, vCores:0>usedCapacity=0.0, absoluteUsedCapacity=0.0, numApps=1, numContainers=0, currently active: 1
2014-05-05 11:42:57,887 INFO org.apache.hadoop.yarn.server.resourcemanager.rmapp.attempt.RMAppAttemptImpl: appattempt_1399289015992_0002_000001 State change from SUBMITTED to SCHEDULED
2014-05-05 11:42:57,887 INFO org.apache.hadoop.yarn.server.resourcemanager.rmapp.RMAppImpl: application_1399289015992_0002 State change from SUBMITTED to ACCEPTED
2014-05-05 11:42:57,908 INFO org.apache.hadoop.yarn.server.resourcemanager.rmcontainer.RMContainerImpl: container_1399289015992_0002_01_000001 Container Transitioned from NEW to ALLOCATED
2014-05-05 11:42:57,908 INFO org.apache.hadoop.yarn.server.resourcemanager.RMAuditLogger: USER=ubuntu	OPERATION=AM Allocated Container	TARGET=SchedulerApp	RESULT=SUCCESS	APPID=application_1399289015992_0002	CONTAINERID=container_1399289015992_0002_01_000001
2014-05-05 11:42:57,908 INFO org.apache.hadoop.yarn.server.resourcemanager.scheduler.common.fica.FiCaSchedulerNode: Assigned container container_1399289015992_0002_01_000001 of capacity <memory:2048, vCores:1> on host ip-10-0-0-198.us-west-2.compute.internal:60935, which currently has 1 containers, <memory:2048, vCores:1> used and <memory:6144, vCores:7> available
2014-05-05 11:42:57,908 INFO org.apache.hadoop.yarn.server.resourcemanager.scheduler.capacity.LeafQueue: assignedContainer application=application_1399289015992_0002 container=Container: [ContainerId: container_1399289015992_0002_01_000001, NodeId: ip-10-0-0-198.us-west-2.compute.internal:60935, NodeHttpAddress: ip-10-0-0-198.us-west-2.compute.internal:8042, Resource: <memory:2048, vCores:1>, Priority: 0, Token: Token { kind: ContainerToken, service: 10.0.0.198:60935 }, ] containerId=container_1399289015992_0002_01_000001 queue=default: capacity=1.0, absoluteCapacity=1.0, usedResources=<memory:0, vCores:0>usedCapacity=0.0, absoluteUsedCapacity=0.0, numApps=1, numContainers=0 usedCapacity=0.0 absoluteUsedCapacity=0.0 used=<memory:0, vCores:0> cluster=<memory:65536, vCores:64>
2014-05-05 11:42:57,909 INFO org.apache.hadoop.yarn.server.resourcemanager.scheduler.capacity.ParentQueue: Re-sorting assigned queue: root.default stats: default: capacity=1.0, absoluteCapacity=1.0, usedResources=<memory:2048, vCores:1>usedCapacity=0.03125, absoluteUsedCapacity=0.03125, numApps=1, numContainers=1
2014-05-05 11:42:57,909 INFO org.apache.hadoop.yarn.server.resourcemanager.scheduler.capacity.ParentQueue: assignedContainer queue=root usedCapacity=0.03125 absoluteUsedCapacity=0.03125 used=<memory:2048, vCores:1> cluster=<memory:65536, vCores:64>
2014-05-05 11:42:57,909 INFO org.apache.hadoop.yarn.server.resourcemanager.rmcontainer.RMContainerImpl: container_1399289015992_0002_01_000001 Container Transitioned from ALLOCATED to ACQUIRED
2014-05-05 11:42:57,909 INFO org.apache.hadoop.yarn.server.resourcemanager.rmapp.attempt.RMAppAttemptImpl: Storing attempt: AppId: application_1399289015992_0002 AttemptId: appattempt_1399289015992_0002_000001 MasterContainer: Container: [ContainerId: container_1399289015992_0002_01_000001, NodeId: ip-10-0-0-198.us-west-2.compute.internal:60935, NodeHttpAddress: ip-10-0-0-198.us-west-2.compute.internal:8042, Resource: <memory:2048, vCores:1>, Priority: 0, Token: Token { kind: ContainerToken, service: 10.0.0.198:60935 }, ]
2014-05-05 11:42:57,910 INFO org.apache.hadoop.yarn.server.resourcemanager.rmapp.attempt.RMAppAttemptImpl: appattempt_1399289015992_0002_000001 State change from SCHEDULED to ALLOCATED_SAVING
2014-05-05 11:42:57,910 INFO org.apache.hadoop.yarn.server.resourcemanager.recovery.RMStateStore: Storing info for attempt: appattempt_1399289015992_0002_000001
2014-05-05 11:42:57,910 INFO org.apache.hadoop.yarn.server.resourcemanager.rmapp.attempt.RMAppAttemptImpl: appattempt_1399289015992_0002_000001 State change from ALLOCATED_SAVING to ALLOCATED
2014-05-05 11:42:57,910 INFO org.apache.hadoop.yarn.server.resourcemanager.amlauncher.AMLauncher: Launching masterappattempt_1399289015992_0002_000001
2014-05-05 11:42:57,912 INFO org.apache.hadoop.yarn.server.resourcemanager.amlauncher.AMLauncher: Setting up container Container: [ContainerId: container_1399289015992_0002_01_000001, NodeId: ip-10-0-0-198.us-west-2.compute.internal:60935, NodeHttpAddress: ip-10-0-0-198.us-west-2.compute.internal:8042, Resource: <memory:2048, vCores:1>, Priority: 0, Token: Token { kind: ContainerToken, service: 10.0.0.198:60935 }, ] for AM appattempt_1399289015992_0002_000001
2014-05-05 11:42:57,912 INFO org.apache.hadoop.yarn.server.resourcemanager.amlauncher.AMLauncher: Command to launch container container_1399289015992_0002_01_000001 : $JAVA_HOME/bin/java -Dlog4j.configuration=container-log4j.properties -Dyarn.app.container.log.dir=<LOG_DIR> -Dyarn.app.container.log.filesize=0 -Dhadoop.root.logger=INFO,CLA  -Xmx1024m org.apache.hadoop.mapreduce.v2.app.MRAppMaster 1><LOG_DIR>/stdout 2><LOG_DIR>/stderr 
2014-05-05 11:42:57,934 INFO org.apache.hadoop.yarn.server.resourcemanager.amlauncher.AMLauncher: Done launching container Container: [ContainerId: container_1399289015992_0002_01_000001, NodeId: ip-10-0-0-198.us-west-2.compute.internal:60935, NodeHttpAddress: ip-10-0-0-198.us-west-2.compute.internal:8042, Resource: <memory:2048, vCores:1>, Priority: 0, Token: Token { kind: ContainerToken, service: 10.0.0.198:60935 }, ] for AM appattempt_1399289015992_0002_000001
2014-05-05 11:42:57,934 INFO org.apache.hadoop.yarn.server.resourcemanager.rmapp.attempt.RMAppAttemptImpl: appattempt_1399289015992_0002_000001 State change from ALLOCATED to LAUNCHED
2014-05-05 11:42:58,909 INFO org.apache.hadoop.yarn.server.resourcemanager.rmcontainer.RMContainerImpl: container_1399289015992_0002_01_000001 Container Transitioned from ACQUIRED to RUNNING
2014-05-05 11:43:03,777 INFO SecurityLogger.org.apache.hadoop.ipc.Server: Auth successful for appattempt_1399289015992_0002_000001 (auth:SIMPLE)
2014-05-05 11:43:03,781 INFO org.apache.hadoop.yarn.server.resourcemanager.ApplicationMasterService: AM registration appattempt_1399289015992_0002_000001
2014-05-05 11:43:03,781 INFO org.apache.hadoop.yarn.server.resourcemanager.RMAuditLogger: USER=ubuntu	IP=10.0.0.198	OPERATION=Register App Master	TARGET=ApplicationMasterService	RESULT=SUCCESS	APPID=application_1399289015992_0002	APPATTEMPTID=appattempt_1399289015992_0002_000001
2014-05-05 11:43:03,782 INFO org.apache.hadoop.yarn.server.resourcemanager.rmapp.attempt.RMAppAttemptImpl: appattempt_1399289015992_0002_000001 State change from LAUNCHED to RUNNING
2014-05-05 11:43:03,782 INFO org.apache.hadoop.yarn.server.resourcemanager.rmapp.RMAppImpl: application_1399289015992_0002 State change from ACCEPTED to RUNNING
2014-05-05 11:43:04,921 INFO org.apache.hadoop.yarn.server.resourcemanager.rmcontainer.RMContainerImpl: container_1399289015992_0002_01_000002 Container Transitioned from NEW to ALLOCATED
2014-05-05 11:43:04,921 INFO org.apache.hadoop.yarn.server.resourcemanager.RMAuditLogger: USER=ubuntu	OPERATION=AM Allocated Container	TARGET=SchedulerApp	RESULT=SUCCESS	APPID=application_1399289015992_0002	CONTAINERID=container_1399289015992_0002_01_000002
2014-05-05 11:43:04,921 INFO org.apache.hadoop.yarn.server.resourcemanager.scheduler.common.fica.FiCaSchedulerNode: Assigned container container_1399289015992_0002_01_000002 of capacity <memory:1024, vCores:1> on host ip-10-0-0-198.us-west-2.compute.internal:60935, which currently has 2 containers, <memory:3072, vCores:2> used and <memory:5120, vCores:6> available
2014-05-05 11:43:04,921 INFO org.apache.hadoop.yarn.server.resourcemanager.scheduler.capacity.LeafQueue: assignedContainer application=application_1399289015992_0002 container=Container: [ContainerId: container_1399289015992_0002_01_000002, NodeId: ip-10-0-0-198.us-west-2.compute.internal:60935, NodeHttpAddress: ip-10-0-0-198.us-west-2.compute.internal:8042, Resource: <memory:1024, vCores:1>, Priority: 20, Token: Token { kind: ContainerToken, service: 10.0.0.198:60935 }, ] containerId=container_1399289015992_0002_01_000002 queue=default: capacity=1.0, absoluteCapacity=1.0, usedResources=<memory:2048, vCores:1>usedCapacity=0.03125, absoluteUsedCapacity=0.03125, numApps=1, numContainers=1 usedCapacity=0.03125 absoluteUsedCapacity=0.03125 used=<memory:2048, vCores:1> cluster=<memory:65536, vCores:64>
2014-05-05 11:43:04,922 INFO org.apache.hadoop.yarn.server.resourcemanager.scheduler.capacity.ParentQueue: Re-sorting assigned queue: root.default stats: default: capacity=1.0, absoluteCapacity=1.0, usedResources=<memory:3072, vCores:2>usedCapacity=0.046875, absoluteUsedCapacity=0.046875, numApps=1, numContainers=2
2014-05-05 11:43:04,922 INFO org.apache.hadoop.yarn.server.resourcemanager.scheduler.capacity.ParentQueue: assignedContainer queue=root usedCapacity=0.046875 absoluteUsedCapacity=0.046875 used=<memory:3072, vCores:2> cluster=<memory:65536, vCores:64>
2014-05-05 11:43:04,922 INFO org.apache.hadoop.yarn.server.resourcemanager.rmcontainer.RMContainerImpl: container_1399289015992_0002_01_000003 Container Transitioned from NEW to ALLOCATED
2014-05-05 11:43:04,922 INFO org.apache.hadoop.yarn.server.resourcemanager.RMAuditLogger: USER=ubuntu	OPERATION=AM Allocated Container	TARGET=SchedulerApp	RESULT=SUCCESS	APPID=application_1399289015992_0002	CONTAINERID=container_1399289015992_0002_01_000003
2014-05-05 11:43:04,922 INFO org.apache.hadoop.yarn.server.resourcemanager.scheduler.common.fica.FiCaSchedulerNode: Assigned container container_1399289015992_0002_01_000003 of capacity <memory:1024, vCores:1> on host ip-10-0-0-198.us-west-2.compute.internal:60935, which currently has 3 containers, <memory:4096, vCores:3> used and <memory:4096, vCores:5> available
2014-05-05 11:43:04,922 INFO org.apache.hadoop.yarn.server.resourcemanager.scheduler.capacity.LeafQueue: assignedContainer application=application_1399289015992_0002 container=Container: [ContainerId: container_1399289015992_0002_01_000003, NodeId: ip-10-0-0-198.us-west-2.compute.internal:60935, NodeHttpAddress: ip-10-0-0-198.us-west-2.compute.internal:8042, Resource: <memory:1024, vCores:1>, Priority: 20, Token: Token { kind: ContainerToken, service: 10.0.0.198:60935 }, ] containerId=container_1399289015992_0002_01_000003 queue=default: capacity=1.0, absoluteCapacity=1.0, usedResources=<memory:3072, vCores:2>usedCapacity=0.046875, absoluteUsedCapacity=0.046875, numApps=1, numContainers=2 usedCapacity=0.046875 absoluteUsedCapacity=0.046875 used=<memory:3072, vCores:2> cluster=<memory:65536, vCores:64>
2014-05-05 11:43:04,922 INFO org.apache.hadoop.yarn.server.resourcemanager.scheduler.capacity.ParentQueue: Re-sorting assigned queue: root.default stats: default: capacity=1.0, absoluteCapacity=1.0, usedResources=<memory:4096, vCores:3>usedCapacity=0.0625, absoluteUsedCapacity=0.0625, numApps=1, numContainers=3
2014-05-05 11:43:04,922 INFO org.apache.hadoop.yarn.server.resourcemanager.scheduler.capacity.ParentQueue: assignedContainer queue=root usedCapacity=0.0625 absoluteUsedCapacity=0.0625 used=<memory:4096, vCores:3> cluster=<memory:65536, vCores:64>
2014-05-05 11:43:04,946 INFO org.apache.hadoop.yarn.server.resourcemanager.rmcontainer.RMContainerImpl: container_1399289015992_0002_01_000004 Container Transitioned from NEW to ALLOCATED
2014-05-05 11:43:04,947 INFO org.apache.hadoop.yarn.server.resourcemanager.RMAuditLogger: USER=ubuntu	OPERATION=AM Allocated Container	TARGET=SchedulerApp	RESULT=SUCCESS	APPID=application_1399289015992_0002	CONTAINERID=container_1399289015992_0002_01_000004
2014-05-05 11:43:04,947 INFO org.apache.hadoop.yarn.server.resourcemanager.scheduler.common.fica.FiCaSchedulerNode: Assigned container container_1399289015992_0002_01_000004 of capacity <memory:1024, vCores:1> on host nodeb:43052, which currently has 1 containers, <memory:1024, vCores:1> used and <memory:7168, vCores:7> available
2014-05-05 11:43:04,947 INFO org.apache.hadoop.yarn.server.resourcemanager.scheduler.capacity.LeafQueue: assignedContainer application=application_1399289015992_0002 container=Container: [ContainerId: container_1399289015992_0002_01_000004, NodeId: nodeb:43052, NodeHttpAddress: nodeb:8042, Resource: <memory:1024, vCores:1>, Priority: 20, Token: Token { kind: ContainerToken, service: 10.0.0.194:43052 }, ] containerId=container_1399289015992_0002_01_000004 queue=default: capacity=1.0, absoluteCapacity=1.0, usedResources=<memory:4096, vCores:3>usedCapacity=0.0625, absoluteUsedCapacity=0.0625, numApps=1, numContainers=3 usedCapacity=0.0625 absoluteUsedCapacity=0.0625 used=<memory:4096, vCores:3> cluster=<memory:65536, vCores:64>
2014-05-05 11:43:04,947 INFO org.apache.hadoop.yarn.server.resourcemanager.scheduler.capacity.ParentQueue: Re-sorting assigned queue: root.default stats: default: capacity=1.0, absoluteCapacity=1.0, usedResources=<memory:5120, vCores:4>usedCapacity=0.078125, absoluteUsedCapacity=0.078125, numApps=1, numContainers=4
2014-05-05 11:43:04,947 INFO org.apache.hadoop.yarn.server.resourcemanager.scheduler.capacity.ParentQueue: assignedContainer queue=root usedCapacity=0.078125 absoluteUsedCapacity=0.078125 used=<memory:5120, vCores:4> cluster=<memory:65536, vCores:64>
2014-05-05 11:43:04,948 INFO org.apache.hadoop.yarn.server.resourcemanager.rmcontainer.RMContainerImpl: container_1399289015992_0002_01_000005 Container Transitioned from NEW to ALLOCATED
2014-05-05 11:43:04,948 INFO org.apache.hadoop.yarn.server.resourcemanager.RMAuditLogger: USER=ubuntu	OPERATION=AM Allocated Container	TARGET=SchedulerApp	RESULT=SUCCESS	APPID=application_1399289015992_0002	CONTAINERID=container_1399289015992_0002_01_000005
2014-05-05 11:43:04,948 INFO org.apache.hadoop.yarn.server.resourcemanager.scheduler.common.fica.FiCaSchedulerNode: Assigned container container_1399289015992_0002_01_000005 of capacity <memory:1024, vCores:1> on host nodeb:43052, which currently has 2 containers, <memory:2048, vCores:2> used and <memory:6144, vCores:6> available
2014-05-05 11:43:04,948 INFO org.apache.hadoop.yarn.server.resourcemanager.scheduler.capacity.LeafQueue: assignedContainer application=application_1399289015992_0002 container=Container: [ContainerId: container_1399289015992_0002_01_000005, NodeId: nodeb:43052, NodeHttpAddress: nodeb:8042, Resource: <memory:1024, vCores:1>, Priority: 20, Token: Token { kind: ContainerToken, service: 10.0.0.194:43052 }, ] containerId=container_1399289015992_0002_01_000005 queue=default: capacity=1.0, absoluteCapacity=1.0, usedResources=<memory:5120, vCores:4>usedCapacity=0.078125, absoluteUsedCapacity=0.078125, numApps=1, numContainers=4 usedCapacity=0.078125 absoluteUsedCapacity=0.078125 used=<memory:5120, vCores:4> cluster=<memory:65536, vCores:64>
2014-05-05 11:43:04,948 INFO org.apache.hadoop.yarn.server.resourcemanager.scheduler.capacity.ParentQueue: Re-sorting assigned queue: root.default stats: default: capacity=1.0, absoluteCapacity=1.0, usedResources=<memory:6144, vCores:5>usedCapacity=0.09375, absoluteUsedCapacity=0.09375, numApps=1, numContainers=5
2014-05-05 11:43:04,949 INFO org.apache.hadoop.yarn.server.resourcemanager.scheduler.capacity.ParentQueue: assignedContainer queue=root usedCapacity=0.09375 absoluteUsedCapacity=0.09375 used=<memory:6144, vCores:5> cluster=<memory:65536, vCores:64>
2014-05-05 11:43:05,858 INFO org.apache.hadoop.yarn.server.resourcemanager.rmcontainer.RMContainerImpl: container_1399289015992_0002_01_000002 Container Transitioned from ALLOCATED to ACQUIRED
2014-05-05 11:43:05,859 INFO org.apache.hadoop.yarn.server.resourcemanager.rmcontainer.RMContainerImpl: container_1399289015992_0002_01_000003 Container Transitioned from ALLOCATED to ACQUIRED
2014-05-05 11:43:05,859 INFO org.apache.hadoop.yarn.server.resourcemanager.rmcontainer.RMContainerImpl: container_1399289015992_0002_01_000004 Container Transitioned from ALLOCATED to ACQUIRED
2014-05-05 11:43:05,860 INFO org.apache.hadoop.yarn.server.resourcemanager.rmcontainer.RMContainerImpl: container_1399289015992_0002_01_000005 Container Transitioned from ALLOCATED to ACQUIRED
2014-05-05 11:43:06,876 INFO org.apache.hadoop.yarn.server.resourcemanager.scheduler.AppSchedulingInfo: checking for deactivate... 
2014-05-05 11:43:06,926 INFO org.apache.hadoop.yarn.server.resourcemanager.rmcontainer.RMContainerImpl: container_1399289015992_0002_01_000002 Container Transitioned from ACQUIRED to RUNNING
2014-05-05 11:43:06,926 INFO org.apache.hadoop.yarn.server.resourcemanager.rmcontainer.RMContainerImpl: container_1399289015992_0002_01_000003 Container Transitioned from ACQUIRED to RUNNING
2014-05-05 11:43:26,515 INFO org.apache.hadoop.yarn.server.resourcemanager.rmcontainer.RMContainerImpl: container_1399289015992_0002_01_000002 Container Transitioned from RUNNING to COMPLETED
2014-05-05 11:43:26,515 INFO org.apache.hadoop.yarn.server.resourcemanager.scheduler.common.fica.FiCaSchedulerApp: Completed container: container_1399289015992_0002_01_000002 in state: COMPLETED event:FINISHED
2014-05-05 11:43:26,516 INFO org.apache.hadoop.yarn.server.resourcemanager.RMAuditLogger: USER=ubuntu	OPERATION=AM Released Container	TARGET=SchedulerApp	RESULT=SUCCESS	APPID=application_1399289015992_0002	CONTAINERID=container_1399289015992_0002_01_000002
2014-05-05 11:43:26,516 INFO org.apache.hadoop.yarn.server.resourcemanager.scheduler.common.fica.FiCaSchedulerNode: Released container container_1399289015992_0002_01_000002 of capacity <memory:1024, vCores:1> on host ip-10-0-0-198.us-west-2.compute.internal:60935, which currently has 2 containers, <memory:3072, vCores:2> used and <memory:5120, vCores:6> available, release resources=true
2014-05-05 11:43:26,516 INFO org.apache.hadoop.yarn.server.resourcemanager.scheduler.capacity.LeafQueue: default used=<memory:5120, vCores:4> numContainers=4 user=ubuntu user-resources=<memory:5120, vCores:4>
2014-05-05 11:43:26,516 INFO org.apache.hadoop.yarn.server.resourcemanager.scheduler.capacity.LeafQueue: completedContainer container=Container: [ContainerId: container_1399289015992_0002_01_000002, NodeId: ip-10-0-0-198.us-west-2.compute.internal:60935, NodeHttpAddress: ip-10-0-0-198.us-west-2.compute.internal:8042, Resource: <memory:1024, vCores:1>, Priority: 20, Token: Token { kind: ContainerToken, service: 10.0.0.198:60935 }, ] resource=<memory:1024, vCores:1> queue=default: capacity=1.0, absoluteCapacity=1.0, usedResources=<memory:5120, vCores:4>usedCapacity=0.078125, absoluteUsedCapacity=0.078125, numApps=1, numContainers=4 usedCapacity=0.078125 absoluteUsedCapacity=0.078125 used=<memory:5120, vCores:4> cluster=<memory:65536, vCores:64>
2014-05-05 11:43:26,516 INFO org.apache.hadoop.yarn.server.resourcemanager.scheduler.capacity.ParentQueue: completedContainer queue=root usedCapacity=0.078125 absoluteUsedCapacity=0.078125 used=<memory:5120, vCores:4> cluster=<memory:65536, vCores:64>
2014-05-05 11:43:26,516 INFO org.apache.hadoop.yarn.server.resourcemanager.scheduler.capacity.ParentQueue: Re-sorting completed queue: root.default stats: default: capacity=1.0, absoluteCapacity=1.0, usedResources=<memory:5120, vCores:4>usedCapacity=0.078125, absoluteUsedCapacity=0.078125, numApps=1, numContainers=4
2014-05-05 11:43:26,516 INFO org.apache.hadoop.yarn.server.resourcemanager.scheduler.capacity.CapacityScheduler: Application appattempt_1399289015992_0002_000001 released container container_1399289015992_0002_01_000002 on node: host: ip-10-0-0-198.us-west-2.compute.internal:60935 #containers=2 available=5120 used=3072 with event: FINISHED
2014-05-05 11:43:26,516 INFO org.apache.hadoop.yarn.server.resourcemanager.rmcontainer.RMContainerImpl: container_1399289015992_0002_01_000003 Container Transitioned from RUNNING to COMPLETED
2014-05-05 11:43:26,516 INFO org.apache.hadoop.yarn.server.resourcemanager.scheduler.common.fica.FiCaSchedulerApp: Completed container: container_1399289015992_0002_01_000003 in state: COMPLETED event:FINISHED
2014-05-05 11:43:26,516 INFO org.apache.hadoop.yarn.server.resourcemanager.RMAuditLogger: USER=ubuntu	OPERATION=AM Released Container	TARGET=SchedulerApp	RESULT=SUCCESS	APPID=application_1399289015992_0002	CONTAINERID=container_1399289015992_0002_01_000003
2014-05-05 11:43:26,516 INFO org.apache.hadoop.yarn.server.resourcemanager.scheduler.common.fica.FiCaSchedulerNode: Released container container_1399289015992_0002_01_000003 of capacity <memory:1024, vCores:1> on host ip-10-0-0-198.us-west-2.compute.internal:60935, which currently has 1 containers, <memory:2048, vCores:1> used and <memory:6144, vCores:7> available, release resources=true
2014-05-05 11:43:26,517 INFO org.apache.hadoop.yarn.server.resourcemanager.scheduler.capacity.LeafQueue: default used=<memory:4096, vCores:3> numContainers=3 user=ubuntu user-resources=<memory:4096, vCores:3>
2014-05-05 11:43:26,517 INFO org.apache.hadoop.yarn.server.resourcemanager.scheduler.capacity.LeafQueue: completedContainer container=Container: [ContainerId: container_1399289015992_0002_01_000003, NodeId: ip-10-0-0-198.us-west-2.compute.internal:60935, NodeHttpAddress: ip-10-0-0-198.us-west-2.compute.internal:8042, Resource: <memory:1024, vCores:1>, Priority: 20, Token: Token { kind: ContainerToken, service: 10.0.0.198:60935 }, ] resource=<memory:1024, vCores:1> queue=default: capacity=1.0, absoluteCapacity=1.0, usedResources=<memory:4096, vCores:3>usedCapacity=0.0625, absoluteUsedCapacity=0.0625, numApps=1, numContainers=3 usedCapacity=0.0625 absoluteUsedCapacity=0.0625 used=<memory:4096, vCores:3> cluster=<memory:65536, vCores:64>
2014-05-05 11:43:26,517 INFO org.apache.hadoop.yarn.server.resourcemanager.scheduler.capacity.ParentQueue: completedContainer queue=root usedCapacity=0.0625 absoluteUsedCapacity=0.0625 used=<memory:4096, vCores:3> cluster=<memory:65536, vCores:64>
2014-05-05 11:43:26,517 INFO org.apache.hadoop.yarn.server.resourcemanager.scheduler.capacity.ParentQueue: Re-sorting completed queue: root.default stats: default: capacity=1.0, absoluteCapacity=1.0, usedResources=<memory:4096, vCores:3>usedCapacity=0.0625, absoluteUsedCapacity=0.0625, numApps=1, numContainers=3
2014-05-05 11:43:26,517 INFO org.apache.hadoop.yarn.server.resourcemanager.scheduler.capacity.CapacityScheduler: Application appattempt_1399289015992_0002_000001 released container container_1399289015992_0002_01_000003 on node: host: ip-10-0-0-198.us-west-2.compute.internal:60935 #containers=1 available=6144 used=2048 with event: FINISHED
2014-05-05 11:43:26,944 INFO org.apache.hadoop.yarn.server.resourcemanager.rmcontainer.RMContainerImpl: container_1399289015992_0002_01_000006 Container Transitioned from NEW to ALLOCATED
2014-05-05 11:43:26,944 INFO org.apache.hadoop.yarn.server.resourcemanager.RMAuditLogger: USER=ubuntu	OPERATION=AM Allocated Container	TARGET=SchedulerApp	RESULT=SUCCESS	APPID=application_1399289015992_0002	CONTAINERID=container_1399289015992_0002_01_000006
2014-05-05 11:43:26,944 INFO org.apache.hadoop.yarn.server.resourcemanager.scheduler.common.fica.FiCaSchedulerNode: Assigned container container_1399289015992_0002_01_000006 of capacity <memory:1024, vCores:1> on host ip-10-0-0-193.us-west-2.compute.internal:60686, which currently has 1 containers, <memory:1024, vCores:1> used and <memory:7168, vCores:7> available
2014-05-05 11:43:26,944 INFO org.apache.hadoop.yarn.server.resourcemanager.scheduler.capacity.LeafQueue: assignedContainer application=application_1399289015992_0002 container=Container: [ContainerId: container_1399289015992_0002_01_000006, NodeId: ip-10-0-0-193.us-west-2.compute.internal:60686, NodeHttpAddress: ip-10-0-0-193.us-west-2.compute.internal:8042, Resource: <memory:1024, vCores:1>, Priority: 10, Token: Token { kind: ContainerToken, service: 10.0.0.193:60686 }, ] containerId=container_1399289015992_0002_01_000006 queue=default: capacity=1.0, absoluteCapacity=1.0, usedResources=<memory:4096, vCores:3>usedCapacity=0.0625, absoluteUsedCapacity=0.0625, numApps=1, numContainers=3 usedCapacity=0.0625 absoluteUsedCapacity=0.0625 used=<memory:4096, vCores:3> cluster=<memory:65536, vCores:64>
2014-05-05 11:43:26,945 INFO org.apache.hadoop.yarn.server.resourcemanager.scheduler.capacity.ParentQueue: Re-sorting assigned queue: root.default stats: default: capacity=1.0, absoluteCapacity=1.0, usedResources=<memory:5120, vCores:4>usedCapacity=0.078125, absoluteUsedCapacity=0.078125, numApps=1, numContainers=4
2014-05-05 11:43:26,945 INFO org.apache.hadoop.yarn.server.resourcemanager.scheduler.capacity.ParentQueue: assignedContainer queue=root usedCapacity=0.078125 absoluteUsedCapacity=0.078125 used=<memory:5120, vCores:4> cluster=<memory:65536, vCores:64>
2014-05-05 11:43:26,989 INFO org.apache.hadoop.yarn.server.resourcemanager.rmcontainer.RMContainerImpl: container_1399289015992_0002_01_000007 Container Transitioned from NEW to ALLOCATED
2014-05-05 11:43:26,990 INFO org.apache.hadoop.yarn.server.resourcemanager.RMAuditLogger: USER=ubuntu	OPERATION=AM Allocated Container	TARGET=SchedulerApp	RESULT=SUCCESS	APPID=application_1399289015992_0002	CONTAINERID=container_1399289015992_0002_01_000007
2014-05-05 11:43:26,990 INFO org.apache.hadoop.yarn.server.resourcemanager.scheduler.common.fica.FiCaSchedulerNode: Assigned container container_1399289015992_0002_01_000007 of capacity <memory:1024, vCores:1> on host ip-10-0-0-196.us-west-2.compute.internal:47357, which currently has 1 containers, <memory:1024, vCores:1> used and <memory:7168, vCores:7> available
2014-05-05 11:43:26,990 INFO org.apache.hadoop.yarn.server.resourcemanager.scheduler.capacity.LeafQueue: assignedContainer application=application_1399289015992_0002 container=Container: [ContainerId: container_1399289015992_0002_01_000007, NodeId: ip-10-0-0-196.us-west-2.compute.internal:47357, NodeHttpAddress: ip-10-0-0-196.us-west-2.compute.internal:8042, Resource: <memory:1024, vCores:1>, Priority: 10, Token: Token { kind: ContainerToken, service: 10.0.0.196:47357 }, ] containerId=container_1399289015992_0002_01_000007 queue=default: capacity=1.0, absoluteCapacity=1.0, usedResources=<memory:5120, vCores:4>usedCapacity=0.078125, absoluteUsedCapacity=0.078125, numApps=1, numContainers=4 usedCapacity=0.078125 absoluteUsedCapacity=0.078125 used=<memory:5120, vCores:4> cluster=<memory:65536, vCores:64>
2014-05-05 11:43:26,990 INFO org.apache.hadoop.yarn.server.resourcemanager.scheduler.capacity.ParentQueue: Re-sorting assigned queue: root.default stats: default: capacity=1.0, absoluteCapacity=1.0, usedResources=<memory:6144, vCores:5>usedCapacity=0.09375, absoluteUsedCapacity=0.09375, numApps=1, numContainers=5
2014-05-05 11:43:26,990 INFO org.apache.hadoop.yarn.server.resourcemanager.scheduler.capacity.ParentQueue: assignedContainer queue=root usedCapacity=0.09375 absoluteUsedCapacity=0.09375 used=<memory:6144, vCores:5> cluster=<memory:65536, vCores:64>
2014-05-05 11:43:27,173 INFO org.apache.hadoop.yarn.server.resourcemanager.rmcontainer.RMContainerImpl: container_1399289015992_0002_01_000008 Container Transitioned from NEW to ALLOCATED
2014-05-05 11:43:27,173 INFO org.apache.hadoop.yarn.server.resourcemanager.RMAuditLogger: USER=ubuntu	OPERATION=AM Allocated Container	TARGET=SchedulerApp	RESULT=SUCCESS	APPID=application_1399289015992_0002	CONTAINERID=container_1399289015992_0002_01_000008
2014-05-05 11:43:27,173 INFO org.apache.hadoop.yarn.server.resourcemanager.scheduler.common.fica.FiCaSchedulerNode: Assigned container container_1399289015992_0002_01_000008 of capacity <memory:1024, vCores:1> on host ip-10-0-0-200.us-west-2.compute.internal:36991, which currently has 1 containers, <memory:1024, vCores:1> used and <memory:7168, vCores:7> available
2014-05-05 11:43:27,173 INFO org.apache.hadoop.yarn.server.resourcemanager.scheduler.capacity.LeafQueue: assignedContainer application=application_1399289015992_0002 container=Container: [ContainerId: container_1399289015992_0002_01_000008, NodeId: ip-10-0-0-200.us-west-2.compute.internal:36991, NodeHttpAddress: ip-10-0-0-200.us-west-2.compute.internal:8042, Resource: <memory:1024, vCores:1>, Priority: 10, Token: Token { kind: ContainerToken, service: 10.0.0.200:36991 }, ] containerId=container_1399289015992_0002_01_000008 queue=default: capacity=1.0, absoluteCapacity=1.0, usedResources=<memory:6144, vCores:5>usedCapacity=0.09375, absoluteUsedCapacity=0.09375, numApps=1, numContainers=5 usedCapacity=0.09375 absoluteUsedCapacity=0.09375 used=<memory:6144, vCores:5> cluster=<memory:65536, vCores:64>
2014-05-05 11:43:27,173 INFO org.apache.hadoop.yarn.server.resourcemanager.scheduler.capacity.ParentQueue: Re-sorting assigned queue: root.default stats: default: capacity=1.0, absoluteCapacity=1.0, usedResources=<memory:7168, vCores:6>usedCapacity=0.109375, absoluteUsedCapacity=0.109375, numApps=1, numContainers=6
2014-05-05 11:43:27,173 INFO org.apache.hadoop.yarn.server.resourcemanager.scheduler.capacity.ParentQueue: assignedContainer queue=root usedCapacity=0.109375 absoluteUsedCapacity=0.109375 used=<memory:7168, vCores:6> cluster=<memory:65536, vCores:64>
2014-05-05 11:43:27,229 INFO org.apache.hadoop.yarn.server.resourcemanager.rmcontainer.RMContainerImpl: container_1399289015992_0002_01_000009 Container Transitioned from NEW to ALLOCATED
2014-05-05 11:43:27,229 INFO org.apache.hadoop.yarn.server.resourcemanager.RMAuditLogger: USER=ubuntu	OPERATION=AM Allocated Container	TARGET=SchedulerApp	RESULT=SUCCESS	APPID=application_1399289015992_0002	CONTAINERID=container_1399289015992_0002_01_000009
2014-05-05 11:43:27,229 INFO org.apache.hadoop.yarn.server.resourcemanager.scheduler.common.fica.FiCaSchedulerNode: Assigned container container_1399289015992_0002_01_000009 of capacity <memory:1024, vCores:1> on host ip-10-0-0-199.us-west-2.compute.internal:36159, which currently has 1 containers, <memory:1024, vCores:1> used and <memory:7168, vCores:7> available
2014-05-05 11:43:27,230 INFO org.apache.hadoop.yarn.server.resourcemanager.scheduler.capacity.LeafQueue: assignedContainer application=application_1399289015992_0002 container=Container: [ContainerId: container_1399289015992_0002_01_000009, NodeId: ip-10-0-0-199.us-west-2.compute.internal:36159, NodeHttpAddress: ip-10-0-0-199.us-west-2.compute.internal:8042, Resource: <memory:1024, vCores:1>, Priority: 10, Token: Token { kind: ContainerToken, service: 10.0.0.199:36159 }, ] containerId=container_1399289015992_0002_01_000009 queue=default: capacity=1.0, absoluteCapacity=1.0, usedResources=<memory:7168, vCores:6>usedCapacity=0.109375, absoluteUsedCapacity=0.109375, numApps=1, numContainers=6 usedCapacity=0.109375 absoluteUsedCapacity=0.109375 used=<memory:7168, vCores:6> cluster=<memory:65536, vCores:64>
2014-05-05 11:43:27,230 INFO org.apache.hadoop.yarn.server.resourcemanager.scheduler.capacity.ParentQueue: Re-sorting assigned queue: root.default stats: default: capacity=1.0, absoluteCapacity=1.0, usedResources=<memory:8192, vCores:7>usedCapacity=0.125, absoluteUsedCapacity=0.125, numApps=1, numContainers=7
2014-05-05 11:43:27,230 INFO org.apache.hadoop.yarn.server.resourcemanager.scheduler.capacity.ParentQueue: assignedContainer queue=root usedCapacity=0.125 absoluteUsedCapacity=0.125 used=<memory:8192, vCores:7> cluster=<memory:65536, vCores:64>
2014-05-05 11:43:27,539 INFO org.apache.hadoop.yarn.server.resourcemanager.rmcontainer.RMContainerImpl: container_1399289015992_0002_01_000010 Container Transitioned from NEW to ALLOCATED
2014-05-05 11:43:27,539 INFO org.apache.hadoop.yarn.server.resourcemanager.RMAuditLogger: USER=ubuntu	OPERATION=AM Allocated Container	TARGET=SchedulerApp	RESULT=SUCCESS	APPID=application_1399289015992_0002	CONTAINERID=container_1399289015992_0002_01_000010
2014-05-05 11:43:27,539 INFO org.apache.hadoop.yarn.server.resourcemanager.scheduler.common.fica.FiCaSchedulerNode: Assigned container container_1399289015992_0002_01_000010 of capacity <memory:1024, vCores:1> on host ip-10-0-0-198.us-west-2.compute.internal:60935, which currently has 2 containers, <memory:3072, vCores:2> used and <memory:5120, vCores:6> available
2014-05-05 11:43:27,539 INFO org.apache.hadoop.yarn.server.resourcemanager.scheduler.capacity.LeafQueue: assignedContainer application=application_1399289015992_0002 container=Container: [ContainerId: container_1399289015992_0002_01_000010, NodeId: ip-10-0-0-198.us-west-2.compute.internal:60935, NodeHttpAddress: ip-10-0-0-198.us-west-2.compute.internal:8042, Resource: <memory:1024, vCores:1>, Priority: 10, Token: Token { kind: ContainerToken, service: 10.0.0.198:60935 }, ] containerId=container_1399289015992_0002_01_000010 queue=default: capacity=1.0, absoluteCapacity=1.0, usedResources=<memory:8192, vCores:7>usedCapacity=0.125, absoluteUsedCapacity=0.125, numApps=1, numContainers=7 usedCapacity=0.125 absoluteUsedCapacity=0.125 used=<memory:8192, vCores:7> cluster=<memory:65536, vCores:64>
2014-05-05 11:43:27,540 INFO org.apache.hadoop.yarn.server.resourcemanager.scheduler.capacity.ParentQueue: Re-sorting assigned queue: root.default stats: default: capacity=1.0, absoluteCapacity=1.0, usedResources=<memory:9216, vCores:8>usedCapacity=0.140625, absoluteUsedCapacity=0.140625, numApps=1, numContainers=8
2014-05-05 11:43:27,540 INFO org.apache.hadoop.yarn.server.resourcemanager.scheduler.capacity.ParentQueue: assignedContainer queue=root usedCapacity=0.140625 absoluteUsedCapacity=0.140625 used=<memory:9216, vCores:8> cluster=<memory:65536, vCores:64>
2014-05-05 11:43:27,862 INFO org.apache.hadoop.yarn.server.resourcemanager.rmcontainer.RMContainerImpl: container_1399289015992_0002_01_000011 Container Transitioned from NEW to ALLOCATED
2014-05-05 11:43:27,862 INFO org.apache.hadoop.yarn.server.resourcemanager.RMAuditLogger: USER=ubuntu	OPERATION=AM Allocated Container	TARGET=SchedulerApp	RESULT=SUCCESS	APPID=application_1399289015992_0002	CONTAINERID=container_1399289015992_0002_01_000011
2014-05-05 11:43:27,862 INFO org.apache.hadoop.yarn.server.resourcemanager.scheduler.common.fica.FiCaSchedulerNode: Assigned container container_1399289015992_0002_01_000011 of capacity <memory:1024, vCores:1> on host ip-10-0-0-197.us-west-2.compute.internal:36720, which currently has 1 containers, <memory:1024, vCores:1> used and <memory:7168, vCores:7> available
2014-05-05 11:43:27,862 INFO org.apache.hadoop.yarn.server.resourcemanager.scheduler.capacity.LeafQueue: assignedContainer application=application_1399289015992_0002 container=Container: [ContainerId: container_1399289015992_0002_01_000011, NodeId: ip-10-0-0-197.us-west-2.compute.internal:36720, NodeHttpAddress: ip-10-0-0-197.us-west-2.compute.internal:8042, Resource: <memory:1024, vCores:1>, Priority: 10, Token: Token { kind: ContainerToken, service: 10.0.0.197:36720 }, ] containerId=container_1399289015992_0002_01_000011 queue=default: capacity=1.0, absoluteCapacity=1.0, usedResources=<memory:9216, vCores:8>usedCapacity=0.140625, absoluteUsedCapacity=0.140625, numApps=1, numContainers=8 usedCapacity=0.140625 absoluteUsedCapacity=0.140625 used=<memory:9216, vCores:8> cluster=<memory:65536, vCores:64>
2014-05-05 11:43:27,862 INFO org.apache.hadoop.yarn.server.resourcemanager.scheduler.capacity.ParentQueue: Re-sorting assigned queue: root.default stats: default: capacity=1.0, absoluteCapacity=1.0, usedResources=<memory:10240, vCores:9>usedCapacity=0.15625, absoluteUsedCapacity=0.15625, numApps=1, numContainers=9
2014-05-05 11:43:27,862 INFO org.apache.hadoop.yarn.server.resourcemanager.scheduler.capacity.ParentQueue: assignedContainer queue=root usedCapacity=0.15625 absoluteUsedCapacity=0.15625 used=<memory:10240, vCores:9> cluster=<memory:65536, vCores:64>
2014-05-05 11:43:27,943 INFO org.apache.hadoop.yarn.server.resourcemanager.rmcontainer.RMContainerImpl: container_1399289015992_0002_01_000006 Container Transitioned from ALLOCATED to ACQUIRED
2014-05-05 11:43:27,944 INFO org.apache.hadoop.yarn.server.resourcemanager.rmcontainer.RMContainerImpl: container_1399289015992_0002_01_000007 Container Transitioned from ALLOCATED to ACQUIRED
2014-05-05 11:43:27,944 INFO org.apache.hadoop.yarn.server.resourcemanager.rmcontainer.RMContainerImpl: container_1399289015992_0002_01_000008 Container Transitioned from ALLOCATED to ACQUIRED
2014-05-05 11:43:27,944 INFO org.apache.hadoop.yarn.server.resourcemanager.rmcontainer.RMContainerImpl: container_1399289015992_0002_01_000009 Container Transitioned from ALLOCATED to ACQUIRED
2014-05-05 11:43:27,944 INFO org.apache.hadoop.yarn.server.resourcemanager.rmcontainer.RMContainerImpl: container_1399289015992_0002_01_000010 Container Transitioned from ALLOCATED to ACQUIRED
2014-05-05 11:43:27,945 INFO org.apache.hadoop.yarn.server.resourcemanager.rmcontainer.RMContainerImpl: container_1399289015992_0002_01_000011 Container Transitioned from ALLOCATED to ACQUIRED
2014-05-05 11:43:28,175 INFO org.apache.hadoop.yarn.server.resourcemanager.rmcontainer.RMContainerImpl: container_1399289015992_0002_01_000008 Container Transitioned from ACQUIRED to RUNNING
2014-05-05 11:43:28,232 INFO org.apache.hadoop.yarn.server.resourcemanager.rmcontainer.RMContainerImpl: container_1399289015992_0002_01_000009 Container Transitioned from ACQUIRED to RUNNING
2014-05-05 11:43:28,542 INFO org.apache.hadoop.yarn.server.resourcemanager.rmcontainer.RMContainerImpl: container_1399289015992_0002_01_000010 Container Transitioned from ACQUIRED to RUNNING
2014-05-05 11:43:28,863 INFO org.apache.hadoop.yarn.server.resourcemanager.rmcontainer.RMContainerImpl: container_1399289015992_0002_01_000011 Container Transitioned from ACQUIRED to RUNNING
2014-05-05 11:43:28,948 INFO org.apache.hadoop.yarn.server.resourcemanager.rmcontainer.RMContainerImpl: container_1399289015992_0002_01_000006 Container Transitioned from ACQUIRED to RUNNING
2014-05-05 11:43:28,993 INFO org.apache.hadoop.yarn.server.resourcemanager.rmcontainer.RMContainerImpl: container_1399289015992_0002_01_000007 Container Transitioned from ACQUIRED to RUNNING
2014-05-05 11:43:39,206 INFO org.apache.hadoop.yarn.server.resourcemanager.rmcontainer.RMContainerImpl: container_1399289015992_0002_01_000005 Container Transitioned from ACQUIRED to RELEASED
2014-05-05 11:43:39,206 INFO org.apache.hadoop.yarn.server.resourcemanager.scheduler.common.fica.FiCaSchedulerApp: Completed container: container_1399289015992_0002_01_000005 in state: RELEASED event:RELEASED
2014-05-05 11:43:39,206 INFO org.apache.hadoop.yarn.server.resourcemanager.RMAuditLogger: USER=ubuntu	IP=10.0.0.198	OPERATION=AM Released Container	TARGET=SchedulerApp	RESULT=SUCCESS	APPID=application_1399289015992_0002	CONTAINERID=container_1399289015992_0002_01_000005
2014-05-05 11:43:39,206 INFO org.apache.hadoop.yarn.server.resourcemanager.scheduler.common.fica.FiCaSchedulerNode: Released container container_1399289015992_0002_01_000005 of capacity <memory:1024, vCores:1> on host nodeb:43052, which currently has 1 containers, <memory:1024, vCores:1> used and <memory:7168, vCores:7> available, release resources=true
2014-05-05 11:43:39,206 INFO org.apache.hadoop.yarn.server.resourcemanager.scheduler.capacity.LeafQueue: default used=<memory:9216, vCores:8> numContainers=8 user=ubuntu user-resources=<memory:9216, vCores:8>
2014-05-05 11:43:39,206 INFO org.apache.hadoop.yarn.server.resourcemanager.scheduler.capacity.LeafQueue: completedContainer container=Container: [ContainerId: container_1399289015992_0002_01_000005, NodeId: nodeb:43052, NodeHttpAddress: nodeb:8042, Resource: <memory:1024, vCores:1>, Priority: 20, Token: Token { kind: ContainerToken, service: 10.0.0.194:43052 }, ] resource=<memory:1024, vCores:1> queue=default: capacity=1.0, absoluteCapacity=1.0, usedResources=<memory:9216, vCores:8>usedCapacity=0.140625, absoluteUsedCapacity=0.140625, numApps=1, numContainers=8 usedCapacity=0.140625 absoluteUsedCapacity=0.140625 used=<memory:9216, vCores:8> cluster=<memory:65536, vCores:64>
2014-05-05 11:43:39,207 INFO org.apache.hadoop.yarn.server.resourcemanager.scheduler.capacity.ParentQueue: completedContainer queue=root usedCapacity=0.140625 absoluteUsedCapacity=0.140625 used=<memory:9216, vCores:8> cluster=<memory:65536, vCores:64>
2014-05-05 11:43:39,207 INFO org.apache.hadoop.yarn.server.resourcemanager.scheduler.capacity.ParentQueue: Re-sorting completed queue: root.default stats: default: capacity=1.0, absoluteCapacity=1.0, usedResources=<memory:9216, vCores:8>usedCapacity=0.140625, absoluteUsedCapacity=0.140625, numApps=1, numContainers=8
2014-05-05 11:43:39,207 INFO org.apache.hadoop.yarn.server.resourcemanager.scheduler.capacity.CapacityScheduler: Application appattempt_1399289015992_0002_000001 released container container_1399289015992_0002_01_000005 on node: host: nodeb:43052 #containers=1 available=7168 used=1024 with event: RELEASED
2014-05-05 11:43:59,186 INFO org.apache.hadoop.yarn.server.webproxy.WebAppProxyServlet: dr.who is accessing unchecked http://ip-10-0-0-198:52423/ which is the app master GUI of application_1399289015992_0002 owned by ubuntu
2014-05-05 11:44:00,943 INFO org.apache.hadoop.yarn.server.webproxy.WebAppProxyServlet: dr.who is accessing unchecked http://ip-10-0-0-198:52423/static/jquery/jquery-1.8.2.min.js which is the app master GUI of application_1399289015992_0002 owned by ubuntu
2014-05-05 11:44:00,943 INFO org.apache.hadoop.yarn.server.webproxy.WebAppProxyServlet: dr.who is accessing unchecked http://ip-10-0-0-198:52423/static/jquery/themes-1.9.1/base/jquery-ui.css which is the app master GUI of application_1399289015992_0002 owned by ubuntu
2014-05-05 11:44:00,944 INFO org.apache.hadoop.yarn.server.webproxy.WebAppProxyServlet: dr.who is accessing unchecked http://ip-10-0-0-198:52423/static/yarn.css which is the app master GUI of application_1399289015992_0002 owned by ubuntu
2014-05-05 11:44:00,944 INFO org.apache.hadoop.yarn.server.webproxy.WebAppProxyServlet: dr.who is accessing unchecked http://ip-10-0-0-198:52423/static/dt-1.9.4/css/jui-dt.css which is the app master GUI of application_1399289015992_0002 owned by ubuntu
2014-05-05 11:44:00,946 INFO org.apache.hadoop.yarn.server.webproxy.WebAppProxyServlet: dr.who is accessing unchecked http://ip-10-0-0-198:52423/static/dt-1.9.4/js/jquery.dataTables.min.js which is the app master GUI of application_1399289015992_0002 owned by ubuntu
2014-05-05 11:44:00,946 INFO org.apache.hadoop.yarn.server.webproxy.WebAppProxyServlet: dr.who is accessing unchecked http://ip-10-0-0-198:52423/static/jquery/jquery-ui-1.9.1.custom.min.js which is the app master GUI of application_1399289015992_0002 owned by ubuntu
2014-05-05 11:44:01,042 INFO org.apache.hadoop.yarn.server.webproxy.WebAppProxyServlet: dr.who is accessing unchecked http://ip-10-0-0-198:52423/static/yarn.dt.plugins.js which is the app master GUI of application_1399289015992_0002 owned by ubuntu
2014-05-05 11:44:01,297 INFO org.apache.hadoop.yarn.server.webproxy.WebAppProxyServlet: dr.who is accessing unchecked http://ip-10-0-0-198:52423/static/jquery/themes-1.9.1/base/images/ui-bg_glass_95_fef1ec_1x400.png which is the app master GUI of application_1399289015992_0002 owned by ubuntu
2014-05-05 11:44:01,299 INFO org.apache.hadoop.yarn.server.webproxy.WebAppProxyServlet: dr.who is accessing unchecked http://ip-10-0-0-198:52423/static/jquery/themes-1.9.1/base/images/ui-bg_highlight-soft_75_cccccc_1x100.png which is the app master GUI of application_1399289015992_0002 owned by ubuntu
2014-05-05 11:44:01,300 INFO org.apache.hadoop.yarn.server.webproxy.WebAppProxyServlet: dr.who is accessing unchecked http://ip-10-0-0-198:52423/static/jquery/themes-1.9.1/base/images/ui-bg_flat_75_ffffff_40x100.png which is the app master GUI of application_1399289015992_0002 owned by ubuntu
2014-05-05 11:44:01,311 INFO org.apache.hadoop.yarn.server.webproxy.WebAppProxyServlet: dr.who is accessing unchecked http://ip-10-0-0-198:52423/static/jquery/themes-1.9.1/base/images/ui-bg_glass_75_e6e6e6_1x400.png which is the app master GUI of application_1399289015992_0002 owned by ubuntu
2014-05-05 11:44:01,316 INFO org.apache.hadoop.yarn.server.webproxy.WebAppProxyServlet: dr.who is accessing unchecked http://ip-10-0-0-198:52423/static/jquery/themes-1.9.1/base/images/ui-bg_glass_65_ffffff_1x400.png which is the app master GUI of application_1399289015992_0002 owned by ubuntu
2014-05-05 11:44:01,316 INFO org.apache.hadoop.yarn.server.webproxy.WebAppProxyServlet: dr.who is accessing unchecked http://ip-10-0-0-198:52423/static/jquery/themes-1.9.1/base/images/ui-icons_888888_256x240.png which is the app master GUI of application_1399289015992_0002 owned by ubuntu
2014-05-05 11:44:01,389 INFO org.apache.hadoop.yarn.server.webproxy.WebAppProxyServlet: dr.who is accessing unchecked http://ip-10-0-0-198:52423/static/jquery/themes-1.9.1/base/images/ui-icons_454545_256x240.png which is the app master GUI of application_1399289015992_0002 owned by ubuntu
2014-05-05 11:44:07,722 INFO org.apache.hadoop.yarn.server.webproxy.WebAppProxyServlet: dr.who is accessing unchecked http://ip-10-0-0-198:52423/mapreduce/job/job_1399289015992_0002 which is the app master GUI of application_1399289015992_0002 owned by ubuntu
2014-05-05 11:44:07,925 INFO org.apache.hadoop.yarn.server.webproxy.WebAppProxyServlet: dr.who is accessing unchecked http://ip-10-0-0-198:52423/static/yarn.css which is the app master GUI of application_1399289015992_0002 owned by ubuntu
2014-05-05 11:44:07,926 INFO org.apache.hadoop.yarn.server.webproxy.WebAppProxyServlet: dr.who is accessing unchecked http://ip-10-0-0-198:52423/static/jquery/jquery-ui-1.9.1.custom.min.js which is the app master GUI of application_1399289015992_0002 owned by ubuntu
2014-05-05 11:44:07,926 INFO org.apache.hadoop.yarn.server.webproxy.WebAppProxyServlet: dr.who is accessing unchecked http://ip-10-0-0-198:52423/static/dt-1.9.4/css/jui-dt.css which is the app master GUI of application_1399289015992_0002 owned by ubuntu
2014-05-05 11:44:07,925 INFO org.apache.hadoop.yarn.server.webproxy.WebAppProxyServlet: dr.who is accessing unchecked http://ip-10-0-0-198:52423/static/jquery/themes-1.9.1/base/jquery-ui.css which is the app master GUI of application_1399289015992_0002 owned by ubuntu
2014-05-05 11:44:07,929 INFO org.apache.hadoop.yarn.server.webproxy.WebAppProxyServlet: dr.who is accessing unchecked http://ip-10-0-0-198:52423/static/dt-1.9.4/js/jquery.dataTables.min.js which is the app master GUI of application_1399289015992_0002 owned by ubuntu
2014-05-05 11:44:07,929 INFO org.apache.hadoop.yarn.server.webproxy.WebAppProxyServlet: dr.who is accessing unchecked http://ip-10-0-0-198:52423/static/jquery/jquery-1.8.2.min.js which is the app master GUI of application_1399289015992_0002 owned by ubuntu
2014-05-05 11:44:08,007 INFO org.apache.hadoop.yarn.server.webproxy.WebAppProxyServlet: dr.who is accessing unchecked http://ip-10-0-0-198:52423/static/yarn.dt.plugins.js which is the app master GUI of application_1399289015992_0002 owned by ubuntu
2014-05-05 11:44:08,398 INFO org.apache.hadoop.yarn.server.webproxy.WebAppProxyServlet: dr.who is accessing unchecked http://ip-10-0-0-198:52423/static/jquery/themes-1.9.1/base/images/ui-bg_flat_75_ffffff_40x100.png which is the app master GUI of application_1399289015992_0002 owned by ubuntu
2014-05-05 11:44:08,400 INFO org.apache.hadoop.yarn.server.webproxy.WebAppProxyServlet: dr.who is accessing unchecked http://ip-10-0-0-198:52423/static/jquery/themes-1.9.1/base/images/ui-bg_glass_75_e6e6e6_1x400.png which is the app master GUI of application_1399289015992_0002 owned by ubuntu
2014-05-05 11:44:08,401 INFO org.apache.hadoop.yarn.server.webproxy.WebAppProxyServlet: dr.who is accessing unchecked http://ip-10-0-0-198:52423/static/jquery/themes-1.9.1/base/images/ui-bg_glass_95_fef1ec_1x400.png which is the app master GUI of application_1399289015992_0002 owned by ubuntu
2014-05-05 11:44:08,403 INFO org.apache.hadoop.yarn.server.webproxy.WebAppProxyServlet: dr.who is accessing unchecked http://ip-10-0-0-198:52423/static/jquery/themes-1.9.1/base/images/ui-bg_highlight-soft_75_cccccc_1x100.png which is the app master GUI of application_1399289015992_0002 owned by ubuntu
2014-05-05 11:44:08,414 INFO org.apache.hadoop.yarn.server.webproxy.WebAppProxyServlet: dr.who is accessing unchecked http://ip-10-0-0-198:52423/static/jquery/themes-1.9.1/base/images/ui-icons_888888_256x240.png which is the app master GUI of application_1399289015992_0002 owned by ubuntu
2014-05-05 11:44:08,414 INFO org.apache.hadoop.yarn.server.webproxy.WebAppProxyServlet: dr.who is accessing unchecked http://ip-10-0-0-198:52423/static/jquery/themes-1.9.1/base/images/ui-bg_glass_65_ffffff_1x400.png which is the app master GUI of application_1399289015992_0002 owned by ubuntu
2014-05-05 11:44:08,480 INFO org.apache.hadoop.yarn.server.webproxy.WebAppProxyServlet: dr.who is accessing unchecked http://ip-10-0-0-198:52423/static/jquery/themes-1.9.1/base/images/ui-icons_454545_256x240.png which is the app master GUI of application_1399289015992_0002 owned by ubuntu
2014-05-05 11:44:12,255 INFO org.apache.hadoop.yarn.server.resourcemanager.rmcontainer.RMContainerImpl: container_1399289015992_0002_01_000004 Container Transitioned from ACQUIRED to RELEASED
2014-05-05 11:44:12,255 INFO org.apache.hadoop.yarn.server.resourcemanager.scheduler.common.fica.FiCaSchedulerApp: Completed container: container_1399289015992_0002_01_000004 in state: RELEASED event:RELEASED
2014-05-05 11:44:12,256 INFO org.apache.hadoop.yarn.server.resourcemanager.RMAuditLogger: USER=ubuntu	IP=10.0.0.198	OPERATION=AM Released Container	TARGET=SchedulerApp	RESULT=SUCCESS	APPID=application_1399289015992_0002	CONTAINERID=container_1399289015992_0002_01_000004
2014-05-05 11:44:12,256 INFO org.apache.hadoop.yarn.server.resourcemanager.scheduler.common.fica.FiCaSchedulerNode: Released container container_1399289015992_0002_01_000004 of capacity <memory:1024, vCores:1> on host nodeb:43052, which currently has 0 containers, <memory:0, vCores:0> used and <memory:8192, vCores:8> available, release resources=true
2014-05-05 11:44:12,256 INFO org.apache.hadoop.yarn.server.resourcemanager.scheduler.capacity.LeafQueue: default used=<memory:8192, vCores:7> numContainers=7 user=ubuntu user-resources=<memory:8192, vCores:7>
2014-05-05 11:44:12,256 INFO org.apache.hadoop.yarn.server.resourcemanager.scheduler.capacity.LeafQueue: completedContainer container=Container: [ContainerId: container_1399289015992_0002_01_000004, NodeId: nodeb:43052, NodeHttpAddress: nodeb:8042, Resource: <memory:1024, vCores:1>, Priority: 20, Token: Token { kind: ContainerToken, service: 10.0.0.194:43052 }, ] resource=<memory:1024, vCores:1> queue=default: capacity=1.0, absoluteCapacity=1.0, usedResources=<memory:8192, vCores:7>usedCapacity=0.125, absoluteUsedCapacity=0.125, numApps=1, numContainers=7 usedCapacity=0.125 absoluteUsedCapacity=0.125 used=<memory:8192, vCores:7> cluster=<memory:65536, vCores:64>
2014-05-05 11:44:12,256 INFO org.apache.hadoop.yarn.server.resourcemanager.scheduler.capacity.ParentQueue: completedContainer queue=root usedCapacity=0.125 absoluteUsedCapacity=0.125 used=<memory:8192, vCores:7> cluster=<memory:65536, vCores:64>
2014-05-05 11:44:12,256 INFO org.apache.hadoop.yarn.server.resourcemanager.scheduler.capacity.ParentQueue: Re-sorting completed queue: root.default stats: default: capacity=1.0, absoluteCapacity=1.0, usedResources=<memory:8192, vCores:7>usedCapacity=0.125, absoluteUsedCapacity=0.125, numApps=1, numContainers=7
2014-05-05 11:44:12,256 INFO org.apache.hadoop.yarn.server.resourcemanager.scheduler.capacity.CapacityScheduler: Application appattempt_1399289015992_0002_000001 released container container_1399289015992_0002_01_000004 on node: host: nodeb:43052 #containers=0 available=8192 used=0 with event: RELEASED
2014-05-05 11:44:13,073 INFO org.apache.hadoop.yarn.server.webproxy.WebAppProxyServlet: dr.who is accessing unchecked http://ip-10-0-0-198:52423/mapreduce/job/job_1399289015992_0002 which is the app master GUI of application_1399289015992_0002 owned by ubuntu
2014-05-05 11:44:13,256 INFO org.apache.hadoop.yarn.server.webproxy.WebAppProxyServlet: dr.who is accessing unchecked http://ip-10-0-0-198:52423/static/jquery/themes-1.9.1/base/jquery-ui.css which is the app master GUI of application_1399289015992_0002 owned by ubuntu
2014-05-05 11:44:13,256 INFO org.apache.hadoop.yarn.server.webproxy.WebAppProxyServlet: dr.who is accessing unchecked http://ip-10-0-0-198:52423/static/dt-1.9.4/css/jui-dt.css which is the app master GUI of application_1399289015992_0002 owned by ubuntu
2014-05-05 11:44:13,257 INFO org.apache.hadoop.yarn.server.webproxy.WebAppProxyServlet: dr.who is accessing unchecked http://ip-10-0-0-198:52423/static/jquery/jquery-ui-1.9.1.custom.min.js which is the app master GUI of application_1399289015992_0002 owned by ubuntu
2014-05-05 11:44:13,258 INFO org.apache.hadoop.yarn.server.webproxy.WebAppProxyServlet: dr.who is accessing unchecked http://ip-10-0-0-198:52423/static/jquery/jquery-1.8.2.min.js which is the app master GUI of application_1399289015992_0002 owned by ubuntu
2014-05-05 11:44:13,260 INFO org.apache.hadoop.yarn.server.webproxy.WebAppProxyServlet: dr.who is accessing unchecked http://ip-10-0-0-198:52423/static/dt-1.9.4/js/jquery.dataTables.min.js which is the app master GUI of application_1399289015992_0002 owned by ubuntu
2014-05-05 11:44:13,260 INFO org.apache.hadoop.yarn.server.webproxy.WebAppProxyServlet: dr.who is accessing unchecked http://ip-10-0-0-198:52423/static/yarn.css which is the app master GUI of application_1399289015992_0002 owned by ubuntu
2014-05-05 11:44:13,332 INFO org.apache.hadoop.yarn.server.webproxy.WebAppProxyServlet: dr.who is accessing unchecked http://ip-10-0-0-198:52423/static/yarn.dt.plugins.js which is the app master GUI of application_1399289015992_0002 owned by ubuntu
2014-05-05 11:44:13,576 INFO org.apache.hadoop.yarn.server.webproxy.WebAppProxyServlet: dr.who is accessing unchecked http://ip-10-0-0-198:52423/static/jquery/themes-1.9.1/base/images/ui-bg_glass_95_fef1ec_1x400.png which is the app master GUI of application_1399289015992_0002 owned by ubuntu
2014-05-05 11:44:13,580 INFO org.apache.hadoop.yarn.server.webproxy.WebAppProxyServlet: dr.who is accessing unchecked http://ip-10-0-0-198:52423/static/jquery/themes-1.9.1/base/images/ui-bg_highlight-soft_75_cccccc_1x100.png which is the app master GUI of application_1399289015992_0002 owned by ubuntu
2014-05-05 11:44:13,580 INFO org.apache.hadoop.yarn.server.webproxy.WebAppProxyServlet: dr.who is accessing unchecked http://ip-10-0-0-198:52423/static/jquery/themes-1.9.1/base/images/ui-bg_glass_75_e6e6e6_1x400.png which is the app master GUI of application_1399289015992_0002 owned by ubuntu
2014-05-05 11:44:13,577 INFO org.apache.hadoop.yarn.server.webproxy.WebAppProxyServlet: dr.who is accessing unchecked http://ip-10-0-0-198:52423/static/jquery/themes-1.9.1/base/images/ui-bg_flat_75_ffffff_40x100.png which is the app master GUI of application_1399289015992_0002 owned by ubuntu
2014-05-05 11:44:13,588 INFO org.apache.hadoop.yarn.server.webproxy.WebAppProxyServlet: dr.who is accessing unchecked http://ip-10-0-0-198:52423/static/jquery/themes-1.9.1/base/images/ui-icons_888888_256x240.png which is the app master GUI of application_1399289015992_0002 owned by ubuntu
2014-05-05 11:44:13,590 INFO org.apache.hadoop.yarn.server.webproxy.WebAppProxyServlet: dr.who is accessing unchecked http://ip-10-0-0-198:52423/static/jquery/themes-1.9.1/base/images/ui-bg_glass_65_ffffff_1x400.png which is the app master GUI of application_1399289015992_0002 owned by ubuntu
2014-05-05 11:44:13,665 INFO org.apache.hadoop.yarn.server.webproxy.WebAppProxyServlet: dr.who is accessing unchecked http://ip-10-0-0-198:52423/static/jquery/themes-1.9.1/base/images/ui-icons_454545_256x240.png which is the app master GUI of application_1399289015992_0002 owned by ubuntu
2014-05-05 11:44:18,567 INFO org.apache.hadoop.yarn.server.webproxy.WebAppProxyServlet: dr.who is accessing unchecked http://ip-10-0-0-198:52423/mapreduce/job/job_1399289015992_0002 which is the app master GUI of application_1399289015992_0002 owned by ubuntu
2014-05-05 11:44:18,697 INFO org.apache.hadoop.yarn.server.webproxy.WebAppProxyServlet: dr.who is accessing unchecked http://ip-10-0-0-198:52423/static/jquery/jquery-ui-1.9.1.custom.min.js which is the app master GUI of application_1399289015992_0002 owned by ubuntu
2014-05-05 11:44:18,697 INFO org.apache.hadoop.yarn.server.webproxy.WebAppProxyServlet: dr.who is accessing unchecked http://ip-10-0-0-198:52423/static/yarn.css which is the app master GUI of application_1399289015992_0002 owned by ubuntu
2014-05-05 11:44:18,697 INFO org.apache.hadoop.yarn.server.webproxy.WebAppProxyServlet: dr.who is accessing unchecked http://ip-10-0-0-198:52423/static/dt-1.9.4/css/jui-dt.css which is the app master GUI of application_1399289015992_0002 owned by ubuntu
2014-05-05 11:44:18,698 INFO org.apache.hadoop.yarn.server.webproxy.WebAppProxyServlet: dr.who is accessing unchecked http://ip-10-0-0-198:52423/static/jquery/themes-1.9.1/base/jquery-ui.css which is the app master GUI of application_1399289015992_0002 owned by ubuntu
2014-05-05 11:44:18,699 INFO org.apache.hadoop.yarn.server.webproxy.WebAppProxyServlet: dr.who is accessing unchecked http://ip-10-0-0-198:52423/static/jquery/jquery-1.8.2.min.js which is the app master GUI of application_1399289015992_0002 owned by ubuntu
2014-05-05 11:44:18,734 INFO org.apache.hadoop.yarn.server.webproxy.WebAppProxyServlet: dr.who is accessing unchecked http://ip-10-0-0-198:52423/static/dt-1.9.4/js/jquery.dataTables.min.js which is the app master GUI of application_1399289015992_0002 owned by ubuntu
2014-05-05 11:44:18,776 INFO org.apache.hadoop.yarn.server.webproxy.WebAppProxyServlet: dr.who is accessing unchecked http://ip-10-0-0-198:52423/static/yarn.dt.plugins.js which is the app master GUI of application_1399289015992_0002 owned by ubuntu
2014-05-05 11:44:19,086 INFO org.apache.hadoop.yarn.server.webproxy.WebAppProxyServlet: dr.who is accessing unchecked http://ip-10-0-0-198:52423/static/jquery/themes-1.9.1/base/images/ui-bg_glass_75_e6e6e6_1x400.png which is the app master GUI of application_1399289015992_0002 owned by ubuntu
2014-05-05 11:44:19,086 INFO org.apache.hadoop.yarn.server.webproxy.WebAppProxyServlet: dr.who is accessing unchecked http://ip-10-0-0-198:52423/static/jquery/themes-1.9.1/base/images/ui-bg_flat_75_ffffff_40x100.png which is the app master GUI of application_1399289015992_0002 owned by ubuntu
2014-05-05 11:44:19,088 INFO org.apache.hadoop.yarn.server.webproxy.WebAppProxyServlet: dr.who is accessing unchecked http://ip-10-0-0-198:52423/static/jquery/themes-1.9.1/base/images/ui-bg_glass_95_fef1ec_1x400.png which is the app master GUI of application_1399289015992_0002 owned by ubuntu
2014-05-05 11:44:19,089 INFO org.apache.hadoop.yarn.server.webproxy.WebAppProxyServlet: dr.who is accessing unchecked http://ip-10-0-0-198:52423/static/jquery/themes-1.9.1/base/images/ui-bg_highlight-soft_75_cccccc_1x100.png which is the app master GUI of application_1399289015992_0002 owned by ubuntu
2014-05-05 11:44:19,095 INFO org.apache.hadoop.yarn.server.webproxy.WebAppProxyServlet: dr.who is accessing unchecked http://ip-10-0-0-198:52423/static/jquery/themes-1.9.1/base/images/ui-icons_888888_256x240.png which is the app master GUI of application_1399289015992_0002 owned by ubuntu
2014-05-05 11:44:19,095 INFO org.apache.hadoop.yarn.server.webproxy.WebAppProxyServlet: dr.who is accessing unchecked http://ip-10-0-0-198:52423/static/jquery/themes-1.9.1/base/images/ui-bg_glass_65_ffffff_1x400.png which is the app master GUI of application_1399289015992_0002 owned by ubuntu
2014-05-05 11:44:19,166 INFO org.apache.hadoop.yarn.server.webproxy.WebAppProxyServlet: dr.who is accessing unchecked http://ip-10-0-0-198:52423/static/jquery/themes-1.9.1/base/images/ui-icons_454545_256x240.png which is the app master GUI of application_1399289015992_0002 owned by ubuntu
2014-05-05 11:44:21,852 INFO org.apache.hadoop.yarn.server.webproxy.WebAppProxyServlet: dr.who is accessing unchecked http://ip-10-0-0-198:52423/mapreduce/attempts/job_1399289015992_0002/m/FAILED which is the app master GUI of application_1399289015992_0002 owned by ubuntu
2014-05-05 11:44:22,036 INFO org.apache.hadoop.yarn.server.webproxy.WebAppProxyServlet: dr.who is accessing unchecked http://ip-10-0-0-198:52423/static/dt-1.9.4/css/jui-dt.css which is the app master GUI of application_1399289015992_0002 owned by ubuntu
2014-05-05 11:44:22,037 INFO org.apache.hadoop.yarn.server.webproxy.WebAppProxyServlet: dr.who is accessing unchecked http://ip-10-0-0-198:52423/static/jquery/jquery-ui-1.9.1.custom.min.js which is the app master GUI of application_1399289015992_0002 owned by ubuntu
2014-05-05 11:44:22,039 INFO org.apache.hadoop.yarn.server.webproxy.WebAppProxyServlet: dr.who is accessing unchecked http://ip-10-0-0-198:52423/static/dt-1.9.4/js/jquery.dataTables.min.js which is the app master GUI of application_1399289015992_0002 owned by ubuntu
2014-05-05 11:44:22,040 INFO org.apache.hadoop.yarn.server.webproxy.WebAppProxyServlet: dr.who is accessing unchecked http://ip-10-0-0-198:52423/static/yarn.css which is the app master GUI of application_1399289015992_0002 owned by ubuntu
2014-05-05 11:44:22,042 INFO org.apache.hadoop.yarn.server.webproxy.WebAppProxyServlet: dr.who is accessing unchecked http://ip-10-0-0-198:52423/static/jquery/jquery-1.8.2.min.js which is the app master GUI of application_1399289015992_0002 owned by ubuntu
2014-05-05 11:44:22,043 INFO org.apache.hadoop.yarn.server.webproxy.WebAppProxyServlet: dr.who is accessing unchecked http://ip-10-0-0-198:52423/static/jquery/themes-1.9.1/base/jquery-ui.css which is the app master GUI of application_1399289015992_0002 owned by ubuntu
2014-05-05 11:44:22,123 INFO org.apache.hadoop.yarn.server.webproxy.WebAppProxyServlet: dr.who is accessing unchecked http://ip-10-0-0-198:52423/static/yarn.dt.plugins.js which is the app master GUI of application_1399289015992_0002 owned by ubuntu
2014-05-05 11:44:22,481 INFO org.apache.hadoop.yarn.server.webproxy.WebAppProxyServlet: dr.who is accessing unchecked http://ip-10-0-0-198:52423/static/jquery/themes-1.9.1/base/images/ui-bg_glass_95_fef1ec_1x400.png which is the app master GUI of application_1399289015992_0002 owned by ubuntu
2014-05-05 11:44:22,482 INFO org.apache.hadoop.yarn.server.webproxy.WebAppProxyServlet: dr.who is accessing unchecked http://ip-10-0-0-198:52423/static/jquery/themes-1.9.1/base/images/ui-bg_flat_75_ffffff_40x100.png which is the app master GUI of application_1399289015992_0002 owned by ubuntu
2014-05-05 11:44:22,490 INFO org.apache.hadoop.yarn.server.webproxy.WebAppProxyServlet: dr.who is accessing unchecked http://ip-10-0-0-198:52423/static/jquery/themes-1.9.1/base/images/ui-bg_glass_75_e6e6e6_1x400.png which is the app master GUI of application_1399289015992_0002 owned by ubuntu
2014-05-05 11:44:22,492 INFO org.apache.hadoop.yarn.server.webproxy.WebAppProxyServlet: dr.who is accessing unchecked http://ip-10-0-0-198:52423/static/jquery/themes-1.9.1/base/images/ui-bg_glass_65_ffffff_1x400.png which is the app master GUI of application_1399289015992_0002 owned by ubuntu
2014-05-05 11:44:22,493 INFO org.apache.hadoop.yarn.server.webproxy.WebAppProxyServlet: dr.who is accessing unchecked http://ip-10-0-0-198:52423/static/jquery/themes-1.9.1/base/images/ui-icons_454545_256x240.png which is the app master GUI of application_1399289015992_0002 owned by ubuntu
2014-05-05 11:44:22,494 INFO org.apache.hadoop.yarn.server.webproxy.WebAppProxyServlet: dr.who is accessing unchecked http://ip-10-0-0-198:52423/static/jquery/themes-1.9.1/base/images/ui-icons_888888_256x240.png which is the app master GUI of application_1399289015992_0002 owned by ubuntu
2014-05-05 11:44:22,563 INFO org.apache.hadoop.yarn.server.webproxy.WebAppProxyServlet: dr.who is accessing unchecked http://ip-10-0-0-198:52423/static/jquery/themes-1.9.1/base/images/ui-bg_highlight-soft_75_cccccc_1x100.png which is the app master GUI of application_1399289015992_0002 owned by ubuntu
2014-05-05 11:44:35,692 INFO org.apache.hadoop.yarn.server.webproxy.WebAppProxyServlet: dr.who is accessing unchecked http://ip-10-0-0-198:52423/mapreduce/job/job_1399289015992_0002 which is the app master GUI of application_1399289015992_0002 owned by ubuntu
2014-05-05 11:44:35,864 INFO org.apache.hadoop.yarn.server.webproxy.WebAppProxyServlet: dr.who is accessing unchecked http://ip-10-0-0-198:52423/static/yarn.css which is the app master GUI of application_1399289015992_0002 owned by ubuntu
2014-05-05 11:44:35,865 INFO org.apache.hadoop.yarn.server.webproxy.WebAppProxyServlet: dr.who is accessing unchecked http://ip-10-0-0-198:52423/static/dt-1.9.4/css/jui-dt.css which is the app master GUI of application_1399289015992_0002 owned by ubuntu
2014-05-05 11:44:35,866 INFO org.apache.hadoop.yarn.server.webproxy.WebAppProxyServlet: dr.who is accessing unchecked http://ip-10-0-0-198:52423/static/dt-1.9.4/js/jquery.dataTables.min.js which is the app master GUI of application_1399289015992_0002 owned by ubuntu
2014-05-05 11:44:35,864 INFO org.apache.hadoop.yarn.server.webproxy.WebAppProxyServlet: dr.who is accessing unchecked http://ip-10-0-0-198:52423/static/jquery/themes-1.9.1/base/jquery-ui.css which is the app master GUI of application_1399289015992_0002 owned by ubuntu
2014-05-05 11:44:35,867 INFO org.apache.hadoop.yarn.server.webproxy.WebAppProxyServlet: dr.who is accessing unchecked http://ip-10-0-0-198:52423/static/jquery/jquery-ui-1.9.1.custom.min.js which is the app master GUI of application_1399289015992_0002 owned by ubuntu
2014-05-05 11:44:35,868 INFO org.apache.hadoop.yarn.server.webproxy.WebAppProxyServlet: dr.who is accessing unchecked http://ip-10-0-0-198:52423/static/jquery/jquery-1.8.2.min.js which is the app master GUI of application_1399289015992_0002 owned by ubuntu
2014-05-05 11:44:35,949 INFO org.apache.hadoop.yarn.server.webproxy.WebAppProxyServlet: dr.who is accessing unchecked http://ip-10-0-0-198:52423/static/yarn.dt.plugins.js which is the app master GUI of application_1399289015992_0002 owned by ubuntu
2014-05-05 11:44:36,258 INFO org.apache.hadoop.yarn.server.webproxy.WebAppProxyServlet: dr.who is accessing unchecked http://ip-10-0-0-198:52423/static/jquery/themes-1.9.1/base/images/ui-bg_glass_95_fef1ec_1x400.png which is the app master GUI of application_1399289015992_0002 owned by ubuntu
2014-05-05 11:44:36,263 INFO org.apache.hadoop.yarn.server.webproxy.WebAppProxyServlet: dr.who is accessing unchecked http://ip-10-0-0-198:52423/static/jquery/themes-1.9.1/base/images/ui-bg_glass_75_e6e6e6_1x400.png which is the app master GUI of application_1399289015992_0002 owned by ubuntu
2014-05-05 11:44:36,265 INFO org.apache.hadoop.yarn.server.webproxy.WebAppProxyServlet: dr.who is accessing unchecked http://ip-10-0-0-198:52423/static/jquery/themes-1.9.1/base/images/ui-bg_highlight-soft_75_cccccc_1x100.png which is the app master GUI of application_1399289015992_0002 owned by ubuntu
2014-05-05 11:44:36,265 INFO org.apache.hadoop.yarn.server.webproxy.WebAppProxyServlet: dr.who is accessing unchecked http://ip-10-0-0-198:52423/static/jquery/themes-1.9.1/base/images/ui-bg_flat_75_ffffff_40x100.png which is the app master GUI of application_1399289015992_0002 owned by ubuntu
2014-05-05 11:44:36,271 INFO org.apache.hadoop.yarn.server.webproxy.WebAppProxyServlet: dr.who is accessing unchecked http://ip-10-0-0-198:52423/static/jquery/themes-1.9.1/base/images/ui-icons_888888_256x240.png which is the app master GUI of application_1399289015992_0002 owned by ubuntu
2014-05-05 11:44:36,272 INFO org.apache.hadoop.yarn.server.webproxy.WebAppProxyServlet: dr.who is accessing unchecked http://ip-10-0-0-198:52423/static/jquery/themes-1.9.1/base/images/ui-bg_glass_65_ffffff_1x400.png which is the app master GUI of application_1399289015992_0002 owned by ubuntu
2014-05-05 11:44:36,337 INFO org.apache.hadoop.yarn.server.webproxy.WebAppProxyServlet: dr.who is accessing unchecked http://ip-10-0-0-198:52423/static/jquery/themes-1.9.1/base/images/ui-icons_454545_256x240.png which is the app master GUI of application_1399289015992_0002 owned by ubuntu
2014-05-05 11:44:37,957 INFO org.apache.hadoop.yarn.server.webproxy.WebAppProxyServlet: dr.who is accessing unchecked http://ip-10-0-0-198:52423/mapreduce/job/job_1399289015992_0002 which is the app master GUI of application_1399289015992_0002 owned by ubuntu
2014-05-05 11:44:38,120 INFO org.apache.hadoop.yarn.server.webproxy.WebAppProxyServlet: dr.who is accessing unchecked http://ip-10-0-0-198:52423/static/jquery/themes-1.9.1/base/jquery-ui.css which is the app master GUI of application_1399289015992_0002 owned by ubuntu
2014-05-05 11:44:38,121 INFO org.apache.hadoop.yarn.server.webproxy.WebAppProxyServlet: dr.who is accessing unchecked http://ip-10-0-0-198:52423/static/yarn.css which is the app master GUI of application_1399289015992_0002 owned by ubuntu
2014-05-05 11:44:38,124 INFO org.apache.hadoop.yarn.server.webproxy.WebAppProxyServlet: dr.who is accessing unchecked http://ip-10-0-0-198:52423/static/jquery/jquery-ui-1.9.1.custom.min.js which is the app master GUI of application_1399289015992_0002 owned by ubuntu
2014-05-05 11:44:38,124 INFO org.apache.hadoop.yarn.server.webproxy.WebAppProxyServlet: dr.who is accessing unchecked http://ip-10-0-0-198:52423/static/dt-1.9.4/js/jquery.dataTables.min.js which is the app master GUI of application_1399289015992_0002 owned by ubuntu
2014-05-05 11:44:38,125 INFO org.apache.hadoop.yarn.server.webproxy.WebAppProxyServlet: dr.who is accessing unchecked http://ip-10-0-0-198:52423/static/jquery/jquery-1.8.2.min.js which is the app master GUI of application_1399289015992_0002 owned by ubuntu
2014-05-05 11:44:38,126 INFO org.apache.hadoop.yarn.server.webproxy.WebAppProxyServlet: dr.who is accessing unchecked http://ip-10-0-0-198:52423/static/dt-1.9.4/css/jui-dt.css which is the app master GUI of application_1399289015992_0002 owned by ubuntu
2014-05-05 11:44:38,208 INFO org.apache.hadoop.yarn.server.webproxy.WebAppProxyServlet: dr.who is accessing unchecked http://ip-10-0-0-198:52423/static/yarn.dt.plugins.js which is the app master GUI of application_1399289015992_0002 owned by ubuntu
2014-05-05 11:44:38,511 INFO org.apache.hadoop.yarn.server.webproxy.WebAppProxyServlet: dr.who is accessing unchecked http://ip-10-0-0-198:52423/static/jquery/themes-1.9.1/base/images/ui-bg_flat_75_ffffff_40x100.png which is the app master GUI of application_1399289015992_0002 owned by ubuntu
2014-05-05 11:44:38,511 INFO org.apache.hadoop.yarn.server.webproxy.WebAppProxyServlet: dr.who is accessing unchecked http://ip-10-0-0-198:52423/static/jquery/themes-1.9.1/base/images/ui-bg_glass_95_fef1ec_1x400.png which is the app master GUI of application_1399289015992_0002 owned by ubuntu
2014-05-05 11:44:38,513 INFO org.apache.hadoop.yarn.server.webproxy.WebAppProxyServlet: dr.who is accessing unchecked http://ip-10-0-0-198:52423/static/jquery/themes-1.9.1/base/images/ui-bg_glass_75_e6e6e6_1x400.png which is the app master GUI of application_1399289015992_0002 owned by ubuntu
2014-05-05 11:44:38,514 INFO org.apache.hadoop.yarn.server.webproxy.WebAppProxyServlet: dr.who is accessing unchecked http://ip-10-0-0-198:52423/static/jquery/themes-1.9.1/base/images/ui-bg_highlight-soft_75_cccccc_1x100.png which is the app master GUI of application_1399289015992_0002 owned by ubuntu
2014-05-05 11:44:38,521 INFO org.apache.hadoop.yarn.server.webproxy.WebAppProxyServlet: dr.who is accessing unchecked http://ip-10-0-0-198:52423/static/jquery/themes-1.9.1/base/images/ui-icons_888888_256x240.png which is the app master GUI of application_1399289015992_0002 owned by ubuntu
2014-05-05 11:44:38,522 INFO org.apache.hadoop.yarn.server.webproxy.WebAppProxyServlet: dr.who is accessing unchecked http://ip-10-0-0-198:52423/static/jquery/themes-1.9.1/base/images/ui-bg_glass_65_ffffff_1x400.png which is the app master GUI of application_1399289015992_0002 owned by ubuntu
2014-05-05 11:44:38,592 INFO org.apache.hadoop.yarn.server.webproxy.WebAppProxyServlet: dr.who is accessing unchecked http://ip-10-0-0-198:52423/static/jquery/themes-1.9.1/base/images/ui-icons_454545_256x240.png which is the app master GUI of application_1399289015992_0002 owned by ubuntu
2014-05-05 11:44:40,669 INFO org.apache.hadoop.yarn.server.webproxy.WebAppProxyServlet: dr.who is accessing unchecked http://ip-10-0-0-198:52423/mapreduce/attempts/job_1399289015992_0002/r/RUNNING which is the app master GUI of application_1399289015992_0002 owned by ubuntu
2014-05-05 11:44:40,834 INFO org.apache.hadoop.yarn.server.webproxy.WebAppProxyServlet: dr.who is accessing unchecked http://ip-10-0-0-198:52423/static/dt-1.9.4/css/jui-dt.css which is the app master GUI of application_1399289015992_0002 owned by ubuntu
2014-05-05 11:44:40,834 INFO org.apache.hadoop.yarn.server.webproxy.WebAppProxyServlet: dr.who is accessing unchecked http://ip-10-0-0-198:52423/static/yarn.css which is the app master GUI of application_1399289015992_0002 owned by ubuntu
2014-05-05 11:44:40,836 INFO org.apache.hadoop.yarn.server.webproxy.WebAppProxyServlet: dr.who is accessing unchecked http://ip-10-0-0-198:52423/static/jquery/themes-1.9.1/base/jquery-ui.css which is the app master GUI of application_1399289015992_0002 owned by ubuntu
2014-05-05 11:44:40,836 INFO org.apache.hadoop.yarn.server.webproxy.WebAppProxyServlet: dr.who is accessing unchecked http://ip-10-0-0-198:52423/static/jquery/jquery-ui-1.9.1.custom.min.js which is the app master GUI of application_1399289015992_0002 owned by ubuntu
2014-05-05 11:44:40,838 INFO org.apache.hadoop.yarn.server.webproxy.WebAppProxyServlet: dr.who is accessing unchecked http://ip-10-0-0-198:52423/static/dt-1.9.4/js/jquery.dataTables.min.js which is the app master GUI of application_1399289015992_0002 owned by ubuntu
2014-05-05 11:44:40,838 INFO org.apache.hadoop.yarn.server.webproxy.WebAppProxyServlet: dr.who is accessing unchecked http://ip-10-0-0-198:52423/static/jquery/jquery-1.8.2.min.js which is the app master GUI of application_1399289015992_0002 owned by ubuntu
2014-05-05 11:44:40,918 INFO org.apache.hadoop.yarn.server.webproxy.WebAppProxyServlet: dr.who is accessing unchecked http://ip-10-0-0-198:52423/static/yarn.dt.plugins.js which is the app master GUI of application_1399289015992_0002 owned by ubuntu
2014-05-05 11:44:41,226 INFO org.apache.hadoop.yarn.server.webproxy.WebAppProxyServlet: dr.who is accessing unchecked http://ip-10-0-0-198:52423/static/jquery/themes-1.9.1/base/images/ui-bg_glass_95_fef1ec_1x400.png which is the app master GUI of application_1399289015992_0002 owned by ubuntu
2014-05-05 11:44:41,228 INFO org.apache.hadoop.yarn.server.webproxy.WebAppProxyServlet: dr.who is accessing unchecked http://ip-10-0-0-198:52423/static/jquery/themes-1.9.1/base/images/ui-bg_flat_75_ffffff_40x100.png which is the app master GUI of application_1399289015992_0002 owned by ubuntu
2014-05-05 11:44:41,232 INFO org.apache.hadoop.yarn.server.webproxy.WebAppProxyServlet: dr.who is accessing unchecked http://ip-10-0-0-198:52423/static/jquery/themes-1.9.1/base/images/ui-bg_glass_75_e6e6e6_1x400.png which is the app master GUI of application_1399289015992_0002 owned by ubuntu
2014-05-05 11:44:41,237 INFO org.apache.hadoop.yarn.server.webproxy.WebAppProxyServlet: dr.who is accessing unchecked http://ip-10-0-0-198:52423/static/jquery/themes-1.9.1/base/images/ui-icons_454545_256x240.png which is the app master GUI of application_1399289015992_0002 owned by ubuntu
2014-05-05 11:44:41,237 INFO org.apache.hadoop.yarn.server.webproxy.WebAppProxyServlet: dr.who is accessing unchecked http://ip-10-0-0-198:52423/static/jquery/themes-1.9.1/base/images/ui-bg_glass_65_ffffff_1x400.png which is the app master GUI of application_1399289015992_0002 owned by ubuntu
2014-05-05 11:44:41,239 INFO org.apache.hadoop.yarn.server.webproxy.WebAppProxyServlet: dr.who is accessing unchecked http://ip-10-0-0-198:52423/static/jquery/themes-1.9.1/base/images/ui-icons_888888_256x240.png which is the app master GUI of application_1399289015992_0002 owned by ubuntu
2014-05-05 11:44:41,315 INFO org.apache.hadoop.yarn.server.webproxy.WebAppProxyServlet: dr.who is accessing unchecked http://ip-10-0-0-198:52423/static/jquery/themes-1.9.1/base/images/ui-bg_highlight-soft_75_cccccc_1x100.png which is the app master GUI of application_1399289015992_0002 owned by ubuntu
2014-05-05 11:45:47,762 INFO org.apache.hadoop.yarn.server.webproxy.WebAppProxyServlet: dr.who is accessing unchecked http://ip-10-0-0-198:52423/mapreduce/job/job_1399289015992_0002 which is the app master GUI of application_1399289015992_0002 owned by ubuntu
2014-05-05 11:45:47,944 INFO org.apache.hadoop.yarn.server.webproxy.WebAppProxyServlet: dr.who is accessing unchecked http://ip-10-0-0-198:52423/static/yarn.css which is the app master GUI of application_1399289015992_0002 owned by ubuntu
2014-05-05 11:45:47,947 INFO org.apache.hadoop.yarn.server.webproxy.WebAppProxyServlet: dr.who is accessing unchecked http://ip-10-0-0-198:52423/static/jquery/themes-1.9.1/base/jquery-ui.css which is the app master GUI of application_1399289015992_0002 owned by ubuntu
2014-05-05 11:45:47,947 INFO org.apache.hadoop.yarn.server.webproxy.WebAppProxyServlet: dr.who is accessing unchecked http://ip-10-0-0-198:52423/static/jquery/jquery-1.8.2.min.js which is the app master GUI of application_1399289015992_0002 owned by ubuntu
2014-05-05 11:45:47,948 INFO org.apache.hadoop.yarn.server.webproxy.WebAppProxyServlet: dr.who is accessing unchecked http://ip-10-0-0-198:52423/static/jquery/jquery-ui-1.9.1.custom.min.js which is the app master GUI of application_1399289015992_0002 owned by ubuntu
2014-05-05 11:45:47,949 INFO org.apache.hadoop.yarn.server.webproxy.WebAppProxyServlet: dr.who is accessing unchecked http://ip-10-0-0-198:52423/static/dt-1.9.4/css/jui-dt.css which is the app master GUI of application_1399289015992_0002 owned by ubuntu
2014-05-05 11:45:47,950 INFO org.apache.hadoop.yarn.server.webproxy.WebAppProxyServlet: dr.who is accessing unchecked http://ip-10-0-0-198:52423/static/dt-1.9.4/js/jquery.dataTables.min.js which is the app master GUI of application_1399289015992_0002 owned by ubuntu
2014-05-05 11:45:48,026 INFO org.apache.hadoop.yarn.server.webproxy.WebAppProxyServlet: dr.who is accessing unchecked http://ip-10-0-0-198:52423/static/yarn.dt.plugins.js which is the app master GUI of application_1399289015992_0002 owned by ubuntu
2014-05-05 11:45:48,367 INFO org.apache.hadoop.yarn.server.webproxy.WebAppProxyServlet: dr.who is accessing unchecked http://ip-10-0-0-198:52423/static/jquery/themes-1.9.1/base/images/ui-bg_glass_95_fef1ec_1x400.png which is the app master GUI of application_1399289015992_0002 owned by ubuntu
2014-05-05 11:45:48,369 INFO org.apache.hadoop.yarn.server.webproxy.WebAppProxyServlet: dr.who is accessing unchecked http://ip-10-0-0-198:52423/static/jquery/themes-1.9.1/base/images/ui-bg_flat_75_ffffff_40x100.png which is the app master GUI of application_1399289015992_0002 owned by ubuntu
2014-05-05 11:45:48,369 INFO org.apache.hadoop.yarn.server.webproxy.WebAppProxyServlet: dr.who is accessing unchecked http://ip-10-0-0-198:52423/static/jquery/themes-1.9.1/base/images/ui-bg_glass_75_e6e6e6_1x400.png which is the app master GUI of application_1399289015992_0002 owned by ubuntu
2014-05-05 11:45:48,372 INFO org.apache.hadoop.yarn.server.webproxy.WebAppProxyServlet: dr.who is accessing unchecked http://ip-10-0-0-198:52423/static/jquery/themes-1.9.1/base/images/ui-bg_highlight-soft_75_cccccc_1x100.png which is the app master GUI of application_1399289015992_0002 owned by ubuntu
2014-05-05 11:45:48,387 INFO org.apache.hadoop.yarn.server.webproxy.WebAppProxyServlet: dr.who is accessing unchecked http://ip-10-0-0-198:52423/static/jquery/themes-1.9.1/base/images/ui-bg_glass_65_ffffff_1x400.png which is the app master GUI of application_1399289015992_0002 owned by ubuntu
2014-05-05 11:45:48,388 INFO org.apache.hadoop.yarn.server.webproxy.WebAppProxyServlet: dr.who is accessing unchecked http://ip-10-0-0-198:52423/static/jquery/themes-1.9.1/base/images/ui-icons_888888_256x240.png which is the app master GUI of application_1399289015992_0002 owned by ubuntu
2014-05-05 11:45:48,444 INFO org.apache.hadoop.yarn.server.webproxy.WebAppProxyServlet: dr.who is accessing unchecked http://ip-10-0-0-198:52423/static/jquery/themes-1.9.1/base/images/ui-icons_454545_256x240.png which is the app master GUI of application_1399289015992_0002 owned by ubuntu
2014-05-05 11:45:48,947 INFO org.apache.hadoop.yarn.server.webproxy.WebAppProxyServlet: dr.who is accessing unchecked http://ip-10-0-0-198:52423/mapreduce/job/job_1399289015992_0002 which is the app master GUI of application_1399289015992_0002 owned by ubuntu
2014-05-05 11:45:49,061 INFO org.apache.hadoop.yarn.server.webproxy.WebAppProxyServlet: dr.who is accessing unchecked http://ip-10-0-0-198:52423/static/yarn.css which is the app master GUI of application_1399289015992_0002 owned by ubuntu
2014-05-05 11:45:49,061 INFO org.apache.hadoop.yarn.server.webproxy.WebAppProxyServlet: dr.who is accessing unchecked http://ip-10-0-0-198:52423/static/jquery/jquery-1.8.2.min.js which is the app master GUI of application_1399289015992_0002 owned by ubuntu
2014-05-05 11:45:49,063 INFO org.apache.hadoop.yarn.server.webproxy.WebAppProxyServlet: dr.who is accessing unchecked http://ip-10-0-0-198:52423/static/jquery/themes-1.9.1/base/jquery-ui.css which is the app master GUI of application_1399289015992_0002 owned by ubuntu
2014-05-05 11:45:49,064 INFO org.apache.hadoop.yarn.server.webproxy.WebAppProxyServlet: dr.who is accessing unchecked http://ip-10-0-0-198:52423/static/dt-1.9.4/js/jquery.dataTables.min.js which is the app master GUI of application_1399289015992_0002 owned by ubuntu
2014-05-05 11:45:49,065 INFO org.apache.hadoop.yarn.server.webproxy.WebAppProxyServlet: dr.who is accessing unchecked http://ip-10-0-0-198:52423/static/jquery/jquery-ui-1.9.1.custom.min.js which is the app master GUI of application_1399289015992_0002 owned by ubuntu
2014-05-05 11:45:49,065 INFO org.apache.hadoop.yarn.server.webproxy.WebAppProxyServlet: dr.who is accessing unchecked http://ip-10-0-0-198:52423/static/dt-1.9.4/css/jui-dt.css which is the app master GUI of application_1399289015992_0002 owned by ubuntu
2014-05-05 11:45:49,144 INFO org.apache.hadoop.yarn.server.webproxy.WebAppProxyServlet: dr.who is accessing unchecked http://ip-10-0-0-198:52423/static/yarn.dt.plugins.js which is the app master GUI of application_1399289015992_0002 owned by ubuntu
2014-05-05 11:45:49,446 INFO org.apache.hadoop.yarn.server.webproxy.WebAppProxyServlet: dr.who is accessing unchecked http://ip-10-0-0-198:52423/static/jquery/themes-1.9.1/base/images/ui-bg_glass_95_fef1ec_1x400.png which is the app master GUI of application_1399289015992_0002 owned by ubuntu
2014-05-05 11:45:49,449 INFO org.apache.hadoop.yarn.server.webproxy.WebAppProxyServlet: dr.who is accessing unchecked http://ip-10-0-0-198:52423/static/jquery/themes-1.9.1/base/images/ui-bg_flat_75_ffffff_40x100.png which is the app master GUI of application_1399289015992_0002 owned by ubuntu
2014-05-05 11:45:49,450 INFO org.apache.hadoop.yarn.server.webproxy.WebAppProxyServlet: dr.who is accessing unchecked http://ip-10-0-0-198:52423/static/jquery/themes-1.9.1/base/images/ui-bg_glass_75_e6e6e6_1x400.png which is the app master GUI of application_1399289015992_0002 owned by ubuntu
2014-05-05 11:45:49,453 INFO org.apache.hadoop.yarn.server.webproxy.WebAppProxyServlet: dr.who is accessing unchecked http://ip-10-0-0-198:52423/static/jquery/themes-1.9.1/base/images/ui-bg_highlight-soft_75_cccccc_1x100.png which is the app master GUI of application_1399289015992_0002 owned by ubuntu
2014-05-05 11:45:49,463 INFO org.apache.hadoop.yarn.server.webproxy.WebAppProxyServlet: dr.who is accessing unchecked http://ip-10-0-0-198:52423/static/jquery/themes-1.9.1/base/images/ui-bg_glass_65_ffffff_1x400.png which is the app master GUI of application_1399289015992_0002 owned by ubuntu
2014-05-05 11:45:49,464 INFO org.apache.hadoop.yarn.server.webproxy.WebAppProxyServlet: dr.who is accessing unchecked http://ip-10-0-0-198:52423/static/jquery/themes-1.9.1/base/images/ui-icons_888888_256x240.png which is the app master GUI of application_1399289015992_0002 owned by ubuntu
2014-05-05 11:45:49,521 INFO org.apache.hadoop.yarn.server.webproxy.WebAppProxyServlet: dr.who is accessing unchecked http://ip-10-0-0-198:52423/static/jquery/themes-1.9.1/base/images/ui-icons_454545_256x240.png which is the app master GUI of application_1399289015992_0002 owned by ubuntu
2014-05-05 11:45:50,605 INFO org.apache.hadoop.yarn.server.webproxy.WebAppProxyServlet: dr.who is accessing unchecked http://ip-10-0-0-198:52423/mapreduce/job/job_1399289015992_0002 which is the app master GUI of application_1399289015992_0002 owned by ubuntu
2014-05-05 11:45:50,718 INFO org.apache.hadoop.yarn.server.webproxy.WebAppProxyServlet: dr.who is accessing unchecked http://ip-10-0-0-198:52423/static/jquery/jquery-1.8.2.min.js which is the app master GUI of application_1399289015992_0002 owned by ubuntu
2014-05-05 11:45:50,719 INFO org.apache.hadoop.yarn.server.webproxy.WebAppProxyServlet: dr.who is accessing unchecked http://ip-10-0-0-198:52423/static/jquery/themes-1.9.1/base/jquery-ui.css which is the app master GUI of application_1399289015992_0002 owned by ubuntu
2014-05-05 11:45:50,720 INFO org.apache.hadoop.yarn.server.webproxy.WebAppProxyServlet: dr.who is accessing unchecked http://ip-10-0-0-198:52423/static/jquery/jquery-ui-1.9.1.custom.min.js which is the app master GUI of application_1399289015992_0002 owned by ubuntu
2014-05-05 11:45:50,722 INFO org.apache.hadoop.yarn.server.webproxy.WebAppProxyServlet: dr.who is accessing unchecked http://ip-10-0-0-198:52423/static/yarn.css which is the app master GUI of application_1399289015992_0002 owned by ubuntu
2014-05-05 11:45:50,718 INFO org.apache.hadoop.yarn.server.webproxy.WebAppProxyServlet: dr.who is accessing unchecked http://ip-10-0-0-198:52423/static/dt-1.9.4/css/jui-dt.css which is the app master GUI of application_1399289015992_0002 owned by ubuntu
2014-05-05 11:45:50,722 INFO org.apache.hadoop.yarn.server.webproxy.WebAppProxyServlet: dr.who is accessing unchecked http://ip-10-0-0-198:52423/static/dt-1.9.4/js/jquery.dataTables.min.js which is the app master GUI of application_1399289015992_0002 owned by ubuntu
2014-05-05 11:45:50,806 INFO org.apache.hadoop.yarn.server.webproxy.WebAppProxyServlet: dr.who is accessing unchecked http://ip-10-0-0-198:52423/static/yarn.dt.plugins.js which is the app master GUI of application_1399289015992_0002 owned by ubuntu
2014-05-05 11:45:51,114 INFO org.apache.hadoop.yarn.server.webproxy.WebAppProxyServlet: dr.who is accessing unchecked http://ip-10-0-0-198:52423/static/jquery/themes-1.9.1/base/images/ui-bg_glass_75_e6e6e6_1x400.png which is the app master GUI of application_1399289015992_0002 owned by ubuntu
2014-05-05 11:45:51,115 INFO org.apache.hadoop.yarn.server.webproxy.WebAppProxyServlet: dr.who is accessing unchecked http://ip-10-0-0-198:52423/static/jquery/themes-1.9.1/base/images/ui-bg_flat_75_ffffff_40x100.png which is the app master GUI of application_1399289015992_0002 owned by ubuntu
2014-05-05 11:45:51,118 INFO org.apache.hadoop.yarn.server.webproxy.WebAppProxyServlet: dr.who is accessing unchecked http://ip-10-0-0-198:52423/static/jquery/themes-1.9.1/base/images/ui-bg_highlight-soft_75_cccccc_1x100.png which is the app master GUI of application_1399289015992_0002 owned by ubuntu
2014-05-05 11:45:51,119 INFO org.apache.hadoop.yarn.server.webproxy.WebAppProxyServlet: dr.who is accessing unchecked http://ip-10-0-0-198:52423/static/jquery/themes-1.9.1/base/images/ui-bg_glass_95_fef1ec_1x400.png which is the app master GUI of application_1399289015992_0002 owned by ubuntu
2014-05-05 11:45:51,125 INFO org.apache.hadoop.yarn.server.webproxy.WebAppProxyServlet: dr.who is accessing unchecked http://ip-10-0-0-198:52423/static/jquery/themes-1.9.1/base/images/ui-icons_888888_256x240.png which is the app master GUI of application_1399289015992_0002 owned by ubuntu
2014-05-05 11:45:51,127 INFO org.apache.hadoop.yarn.server.webproxy.WebAppProxyServlet: dr.who is accessing unchecked http://ip-10-0-0-198:52423/static/jquery/themes-1.9.1/base/images/ui-bg_glass_65_ffffff_1x400.png which is the app master GUI of application_1399289015992_0002 owned by ubuntu
2014-05-05 11:45:51,201 INFO org.apache.hadoop.yarn.server.webproxy.WebAppProxyServlet: dr.who is accessing unchecked http://ip-10-0-0-198:52423/static/jquery/themes-1.9.1/base/images/ui-icons_454545_256x240.png which is the app master GUI of application_1399289015992_0002 owned by ubuntu
2014-05-05 11:45:51,498 INFO org.apache.hadoop.yarn.server.webproxy.WebAppProxyServlet: dr.who is accessing unchecked http://ip-10-0-0-198:52423/mapreduce/job/job_1399289015992_0002 which is the app master GUI of application_1399289015992_0002 owned by ubuntu
2014-05-05 11:45:51,665 INFO org.apache.hadoop.yarn.server.webproxy.WebAppProxyServlet: dr.who is accessing unchecked http://ip-10-0-0-198:52423/static/jquery/themes-1.9.1/base/jquery-ui.css which is the app master GUI of application_1399289015992_0002 owned by ubuntu
2014-05-05 11:45:51,666 INFO org.apache.hadoop.yarn.server.webproxy.WebAppProxyServlet: dr.who is accessing unchecked http://ip-10-0-0-198:52423/static/jquery/jquery-ui-1.9.1.custom.min.js which is the app master GUI of application_1399289015992_0002 owned by ubuntu
2014-05-05 11:45:51,666 INFO org.apache.hadoop.yarn.server.webproxy.WebAppProxyServlet: dr.who is accessing unchecked http://ip-10-0-0-198:52423/static/jquery/jquery-1.8.2.min.js which is the app master GUI of application_1399289015992_0002 owned by ubuntu
2014-05-05 11:45:51,667 INFO org.apache.hadoop.yarn.server.webproxy.WebAppProxyServlet: dr.who is accessing unchecked http://ip-10-0-0-198:52423/static/dt-1.9.4/js/jquery.dataTables.min.js which is the app master GUI of application_1399289015992_0002 owned by ubuntu
2014-05-05 11:45:51,668 INFO org.apache.hadoop.yarn.server.webproxy.WebAppProxyServlet: dr.who is accessing unchecked http://ip-10-0-0-198:52423/static/dt-1.9.4/css/jui-dt.css which is the app master GUI of application_1399289015992_0002 owned by ubuntu
2014-05-05 11:45:51,670 INFO org.apache.hadoop.yarn.server.webproxy.WebAppProxyServlet: dr.who is accessing unchecked http://ip-10-0-0-198:52423/static/yarn.css which is the app master GUI of application_1399289015992_0002 owned by ubuntu
2014-05-05 11:45:51,747 INFO org.apache.hadoop.yarn.server.webproxy.WebAppProxyServlet: dr.who is accessing unchecked http://ip-10-0-0-198:52423/static/yarn.dt.plugins.js which is the app master GUI of application_1399289015992_0002 owned by ubuntu
2014-05-05 11:45:52,050 INFO org.apache.hadoop.yarn.server.webproxy.WebAppProxyServlet: dr.who is accessing unchecked http://ip-10-0-0-198:52423/static/jquery/themes-1.9.1/base/images/ui-bg_flat_75_ffffff_40x100.png which is the app master GUI of application_1399289015992_0002 owned by ubuntu
2014-05-05 11:45:52,050 INFO org.apache.hadoop.yarn.server.webproxy.WebAppProxyServlet: dr.who is accessing unchecked http://ip-10-0-0-198:52423/static/jquery/themes-1.9.1/base/images/ui-bg_glass_95_fef1ec_1x400.png which is the app master GUI of application_1399289015992_0002 owned by ubuntu
2014-05-05 11:45:52,126 INFO org.apache.hadoop.yarn.server.webproxy.WebAppProxyServlet: dr.who is accessing unchecked http://ip-10-0-0-198:52423/static/jquery/themes-1.9.1/base/images/ui-icons_454545_256x240.png which is the app master GUI of application_1399289015992_0002 owned by ubuntu
2014-05-05 11:45:52,076 INFO org.apache.hadoop.yarn.server.webproxy.WebAppProxyServlet: dr.who is accessing unchecked http://ip-10-0-0-198:52423/static/jquery/themes-1.9.1/base/images/ui-bg_glass_65_ffffff_1x400.png which is the app master GUI of application_1399289015992_0002 owned by ubuntu
2014-05-05 11:45:52,075 INFO org.apache.hadoop.yarn.server.webproxy.WebAppProxyServlet: dr.who is accessing unchecked http://ip-10-0-0-198:52423/static/jquery/themes-1.9.1/base/images/ui-icons_888888_256x240.png which is the app master GUI of application_1399289015992_0002 owned by ubuntu
2014-05-05 11:45:52,064 INFO org.apache.hadoop.yarn.server.webproxy.WebAppProxyServlet: dr.who is accessing unchecked http://ip-10-0-0-198:52423/static/jquery/themes-1.9.1/base/images/ui-bg_highlight-soft_75_cccccc_1x100.png which is the app master GUI of application_1399289015992_0002 owned by ubuntu
2014-05-05 11:45:52,062 INFO org.apache.hadoop.yarn.server.webproxy.WebAppProxyServlet: dr.who is accessing unchecked http://ip-10-0-0-198:52423/static/jquery/themes-1.9.1/base/images/ui-bg_glass_75_e6e6e6_1x400.png which is the app master GUI of application_1399289015992_0002 owned by ubuntu
2014-05-05 11:45:52,481 INFO org.apache.hadoop.yarn.server.webproxy.WebAppProxyServlet: dr.who is accessing unchecked http://ip-10-0-0-198:52423/mapreduce/job/job_1399289015992_0002 which is the app master GUI of application_1399289015992_0002 owned by ubuntu
2014-05-05 11:45:52,593 INFO org.apache.hadoop.yarn.server.webproxy.WebAppProxyServlet: dr.who is accessing unchecked http://ip-10-0-0-198:52423/static/yarn.css which is the app master GUI of application_1399289015992_0002 owned by ubuntu
2014-05-05 11:45:52,595 INFO org.apache.hadoop.yarn.server.webproxy.WebAppProxyServlet: dr.who is accessing unchecked http://ip-10-0-0-198:52423/static/dt-1.9.4/css/jui-dt.css which is the app master GUI of application_1399289015992_0002 owned by ubuntu
2014-05-05 11:45:52,595 INFO org.apache.hadoop.yarn.server.webproxy.WebAppProxyServlet: dr.who is accessing unchecked http://ip-10-0-0-198:52423/static/jquery/jquery-1.8.2.min.js which is the app master GUI of application_1399289015992_0002 owned by ubuntu
2014-05-05 11:45:52,596 INFO org.apache.hadoop.yarn.server.webproxy.WebAppProxyServlet: dr.who is accessing unchecked http://ip-10-0-0-198:52423/static/jquery/jquery-ui-1.9.1.custom.min.js which is the app master GUI of application_1399289015992_0002 owned by ubuntu
2014-05-05 11:45:52,598 INFO org.apache.hadoop.yarn.server.webproxy.WebAppProxyServlet: dr.who is accessing unchecked http://ip-10-0-0-198:52423/static/dt-1.9.4/js/jquery.dataTables.min.js which is the app master GUI of application_1399289015992_0002 owned by ubuntu
2014-05-05 11:45:52,600 INFO org.apache.hadoop.yarn.server.webproxy.WebAppProxyServlet: dr.who is accessing unchecked http://ip-10-0-0-198:52423/static/jquery/themes-1.9.1/base/jquery-ui.css which is the app master GUI of application_1399289015992_0002 owned by ubuntu
2014-05-05 11:45:52,679 INFO org.apache.hadoop.yarn.server.webproxy.WebAppProxyServlet: dr.who is accessing unchecked http://ip-10-0-0-198:52423/static/yarn.dt.plugins.js which is the app master GUI of application_1399289015992_0002 owned by ubuntu
2014-05-05 11:45:52,977 INFO org.apache.hadoop.yarn.server.webproxy.WebAppProxyServlet: dr.who is accessing unchecked http://ip-10-0-0-198:52423/static/jquery/themes-1.9.1/base/images/ui-bg_glass_95_fef1ec_1x400.png which is the app master GUI of application_1399289015992_0002 owned by ubuntu
2014-05-05 11:45:52,980 INFO org.apache.hadoop.yarn.server.webproxy.WebAppProxyServlet: dr.who is accessing unchecked http://ip-10-0-0-198:52423/static/jquery/themes-1.9.1/base/images/ui-bg_flat_75_ffffff_40x100.png which is the app master GUI of application_1399289015992_0002 owned by ubuntu
2014-05-05 11:45:52,980 INFO org.apache.hadoop.yarn.server.webproxy.WebAppProxyServlet: dr.who is accessing unchecked http://ip-10-0-0-198:52423/static/jquery/themes-1.9.1/base/images/ui-bg_highlight-soft_75_cccccc_1x100.png which is the app master GUI of application_1399289015992_0002 owned by ubuntu
2014-05-05 11:45:52,981 INFO org.apache.hadoop.yarn.server.webproxy.WebAppProxyServlet: dr.who is accessing unchecked http://ip-10-0-0-198:52423/static/jquery/themes-1.9.1/base/images/ui-bg_glass_75_e6e6e6_1x400.png which is the app master GUI of application_1399289015992_0002 owned by ubuntu
2014-05-05 11:45:52,989 INFO org.apache.hadoop.yarn.server.webproxy.WebAppProxyServlet: dr.who is accessing unchecked http://ip-10-0-0-198:52423/static/jquery/themes-1.9.1/base/images/ui-icons_888888_256x240.png which is the app master GUI of application_1399289015992_0002 owned by ubuntu
2014-05-05 11:45:52,991 INFO org.apache.hadoop.yarn.server.webproxy.WebAppProxyServlet: dr.who is accessing unchecked http://ip-10-0-0-198:52423/static/jquery/themes-1.9.1/base/images/ui-bg_glass_65_ffffff_1x400.png which is the app master GUI of application_1399289015992_0002 owned by ubuntu
2014-05-05 11:45:53,056 INFO org.apache.hadoop.yarn.server.webproxy.WebAppProxyServlet: dr.who is accessing unchecked http://ip-10-0-0-198:52423/static/jquery/themes-1.9.1/base/images/ui-icons_454545_256x240.png which is the app master GUI of application_1399289015992_0002 owned by ubuntu
2014-05-05 11:45:53,554 INFO org.apache.hadoop.yarn.server.webproxy.WebAppProxyServlet: dr.who is accessing unchecked http://ip-10-0-0-198:52423/mapreduce/job/job_1399289015992_0002 which is the app master GUI of application_1399289015992_0002 owned by ubuntu
2014-05-05 11:45:53,746 INFO org.apache.hadoop.yarn.server.webproxy.WebAppProxyServlet: dr.who is accessing unchecked http://ip-10-0-0-198:52423/static/dt-1.9.4/js/jquery.dataTables.min.js which is the app master GUI of application_1399289015992_0002 owned by ubuntu
2014-05-05 11:45:53,746 INFO org.apache.hadoop.yarn.server.webproxy.WebAppProxyServlet: dr.who is accessing unchecked http://ip-10-0-0-198:52423/static/jquery/jquery-1.8.2.min.js which is the app master GUI of application_1399289015992_0002 owned by ubuntu
2014-05-05 11:45:53,747 INFO org.apache.hadoop.yarn.server.webproxy.WebAppProxyServlet: dr.who is accessing unchecked http://ip-10-0-0-198:52423/static/jquery/jquery-ui-1.9.1.custom.min.js which is the app master GUI of application_1399289015992_0002 owned by ubuntu
2014-05-05 11:45:53,748 INFO org.apache.hadoop.yarn.server.webproxy.WebAppProxyServlet: dr.who is accessing unchecked http://ip-10-0-0-198:52423/static/jquery/themes-1.9.1/base/jquery-ui.css which is the app master GUI of application_1399289015992_0002 owned by ubuntu
2014-05-05 11:45:53,749 INFO org.apache.hadoop.yarn.server.webproxy.WebAppProxyServlet: dr.who is accessing unchecked http://ip-10-0-0-198:52423/static/yarn.css which is the app master GUI of application_1399289015992_0002 owned by ubuntu
2014-05-05 11:45:53,749 INFO org.apache.hadoop.yarn.server.webproxy.WebAppProxyServlet: dr.who is accessing unchecked http://ip-10-0-0-198:52423/static/dt-1.9.4/css/jui-dt.css which is the app master GUI of application_1399289015992_0002 owned by ubuntu
2014-05-05 11:45:53,831 INFO org.apache.hadoop.yarn.server.webproxy.WebAppProxyServlet: dr.who is accessing unchecked http://ip-10-0-0-198:52423/static/yarn.dt.plugins.js which is the app master GUI of application_1399289015992_0002 owned by ubuntu
2014-05-05 11:45:54,136 INFO org.apache.hadoop.yarn.server.webproxy.WebAppProxyServlet: dr.who is accessing unchecked http://ip-10-0-0-198:52423/static/jquery/themes-1.9.1/base/images/ui-bg_glass_95_fef1ec_1x400.png which is the app master GUI of application_1399289015992_0002 owned by ubuntu
2014-05-05 11:45:54,138 INFO org.apache.hadoop.yarn.server.webproxy.WebAppProxyServlet: dr.who is accessing unchecked http://ip-10-0-0-198:52423/static/jquery/themes-1.9.1/base/images/ui-bg_highlight-soft_75_cccccc_1x100.png which is the app master GUI of application_1399289015992_0002 owned by ubuntu
2014-05-05 11:45:54,140 INFO org.apache.hadoop.yarn.server.webproxy.WebAppProxyServlet: dr.who is accessing unchecked http://ip-10-0-0-198:52423/static/jquery/themes-1.9.1/base/images/ui-bg_flat_75_ffffff_40x100.png which is the app master GUI of application_1399289015992_0002 owned by ubuntu
2014-05-05 11:45:54,142 INFO org.apache.hadoop.yarn.server.webproxy.WebAppProxyServlet: dr.who is accessing unchecked http://ip-10-0-0-198:52423/static/jquery/themes-1.9.1/base/images/ui-bg_glass_75_e6e6e6_1x400.png which is the app master GUI of application_1399289015992_0002 owned by ubuntu
2014-05-05 11:45:54,148 INFO org.apache.hadoop.yarn.server.webproxy.WebAppProxyServlet: dr.who is accessing unchecked http://ip-10-0-0-198:52423/static/jquery/themes-1.9.1/base/images/ui-icons_888888_256x240.png which is the app master GUI of application_1399289015992_0002 owned by ubuntu
2014-05-05 11:45:54,149 INFO org.apache.hadoop.yarn.server.webproxy.WebAppProxyServlet: dr.who is accessing unchecked http://ip-10-0-0-198:52423/static/jquery/themes-1.9.1/base/images/ui-bg_glass_65_ffffff_1x400.png which is the app master GUI of application_1399289015992_0002 owned by ubuntu
2014-05-05 11:45:54,217 INFO org.apache.hadoop.yarn.server.webproxy.WebAppProxyServlet: dr.who is accessing unchecked http://ip-10-0-0-198:52423/static/jquery/themes-1.9.1/base/images/ui-icons_454545_256x240.png which is the app master GUI of application_1399289015992_0002 owned by ubuntu
2014-05-05 11:45:54,621 INFO org.apache.hadoop.yarn.server.webproxy.WebAppProxyServlet: dr.who is accessing unchecked http://ip-10-0-0-198:52423/mapreduce/job/job_1399289015992_0002 which is the app master GUI of application_1399289015992_0002 owned by ubuntu
2014-05-05 11:45:54,805 INFO org.apache.hadoop.yarn.server.webproxy.WebAppProxyServlet: dr.who is accessing unchecked http://ip-10-0-0-198:52423/static/jquery/jquery-1.8.2.min.js which is the app master GUI of application_1399289015992_0002 owned by ubuntu
2014-05-05 11:45:54,806 INFO org.apache.hadoop.yarn.server.webproxy.WebAppProxyServlet: dr.who is accessing unchecked http://ip-10-0-0-198:52423/static/dt-1.9.4/css/jui-dt.css which is the app master GUI of application_1399289015992_0002 owned by ubuntu
2014-05-05 11:45:54,807 INFO org.apache.hadoop.yarn.server.webproxy.WebAppProxyServlet: dr.who is accessing unchecked http://ip-10-0-0-198:52423/static/jquery/jquery-ui-1.9.1.custom.min.js which is the app master GUI of application_1399289015992_0002 owned by ubuntu
2014-05-05 11:45:54,805 INFO org.apache.hadoop.yarn.server.webproxy.WebAppProxyServlet: dr.who is accessing unchecked http://ip-10-0-0-198:52423/static/yarn.css which is the app master GUI of application_1399289015992_0002 owned by ubuntu
2014-05-05 11:45:54,809 INFO org.apache.hadoop.yarn.server.webproxy.WebAppProxyServlet: dr.who is accessing unchecked http://ip-10-0-0-198:52423/static/dt-1.9.4/js/jquery.dataTables.min.js which is the app master GUI of application_1399289015992_0002 owned by ubuntu
2014-05-05 11:45:54,811 INFO org.apache.hadoop.yarn.server.webproxy.WebAppProxyServlet: dr.who is accessing unchecked http://ip-10-0-0-198:52423/static/jquery/themes-1.9.1/base/jquery-ui.css which is the app master GUI of application_1399289015992_0002 owned by ubuntu
2014-05-05 11:45:54,882 INFO org.apache.hadoop.yarn.server.webproxy.WebAppProxyServlet: dr.who is accessing unchecked http://ip-10-0-0-198:52423/static/yarn.dt.plugins.js which is the app master GUI of application_1399289015992_0002 owned by ubuntu
2014-05-05 11:45:55,198 INFO org.apache.hadoop.yarn.server.webproxy.WebAppProxyServlet: dr.who is accessing unchecked http://ip-10-0-0-198:52423/static/jquery/themes-1.9.1/base/images/ui-bg_glass_95_fef1ec_1x400.png which is the app master GUI of application_1399289015992_0002 owned by ubuntu
2014-05-05 11:45:55,204 INFO org.apache.hadoop.yarn.server.webproxy.WebAppProxyServlet: dr.who is accessing unchecked http://ip-10-0-0-198:52423/static/jquery/themes-1.9.1/base/images/ui-bg_glass_75_e6e6e6_1x400.png which is the app master GUI of application_1399289015992_0002 owned by ubuntu
2014-05-05 11:45:55,204 INFO org.apache.hadoop.yarn.server.webproxy.WebAppProxyServlet: dr.who is accessing unchecked http://ip-10-0-0-198:52423/static/jquery/themes-1.9.1/base/images/ui-bg_highlight-soft_75_cccccc_1x100.png which is the app master GUI of application_1399289015992_0002 owned by ubuntu
2014-05-05 11:45:55,205 INFO org.apache.hadoop.yarn.server.webproxy.WebAppProxyServlet: dr.who is accessing unchecked http://ip-10-0-0-198:52423/static/jquery/themes-1.9.1/base/images/ui-bg_flat_75_ffffff_40x100.png which is the app master GUI of application_1399289015992_0002 owned by ubuntu
2014-05-05 11:45:55,210 INFO org.apache.hadoop.yarn.server.webproxy.WebAppProxyServlet: dr.who is accessing unchecked http://ip-10-0-0-198:52423/static/jquery/themes-1.9.1/base/images/ui-bg_glass_65_ffffff_1x400.png which is the app master GUI of application_1399289015992_0002 owned by ubuntu
2014-05-05 11:45:55,211 INFO org.apache.hadoop.yarn.server.webproxy.WebAppProxyServlet: dr.who is accessing unchecked http://ip-10-0-0-198:52423/static/jquery/themes-1.9.1/base/images/ui-icons_888888_256x240.png which is the app master GUI of application_1399289015992_0002 owned by ubuntu
2014-05-05 11:45:55,274 INFO org.apache.hadoop.yarn.server.webproxy.WebAppProxyServlet: dr.who is accessing unchecked http://ip-10-0-0-198:52423/static/jquery/themes-1.9.1/base/images/ui-icons_454545_256x240.png which is the app master GUI of application_1399289015992_0002 owned by ubuntu
2014-05-05 11:45:58,434 INFO org.apache.hadoop.yarn.server.webproxy.WebAppProxyServlet: dr.who is accessing unchecked http://ip-10-0-0-198:52423/mapreduce/attempts/job_1399289015992_0002/r/RUNNING which is the app master GUI of application_1399289015992_0002 owned by ubuntu
2014-05-05 11:45:58,631 INFO org.apache.hadoop.yarn.server.webproxy.WebAppProxyServlet: dr.who is accessing unchecked http://ip-10-0-0-198:52423/static/jquery/jquery-1.8.2.min.js which is the app master GUI of application_1399289015992_0002 owned by ubuntu
2014-05-05 11:45:58,631 INFO org.apache.hadoop.yarn.server.webproxy.WebAppProxyServlet: dr.who is accessing unchecked http://ip-10-0-0-198:52423/static/jquery/jquery-ui-1.9.1.custom.min.js which is the app master GUI of application_1399289015992_0002 owned by ubuntu
2014-05-05 11:45:58,632 INFO org.apache.hadoop.yarn.server.webproxy.WebAppProxyServlet: dr.who is accessing unchecked http://ip-10-0-0-198:52423/static/jquery/themes-1.9.1/base/jquery-ui.css which is the app master GUI of application_1399289015992_0002 owned by ubuntu
2014-05-05 11:45:58,633 INFO org.apache.hadoop.yarn.server.webproxy.WebAppProxyServlet: dr.who is accessing unchecked http://ip-10-0-0-198:52423/static/dt-1.9.4/css/jui-dt.css which is the app master GUI of application_1399289015992_0002 owned by ubuntu
2014-05-05 11:45:58,632 INFO org.apache.hadoop.yarn.server.webproxy.WebAppProxyServlet: dr.who is accessing unchecked http://ip-10-0-0-198:52423/static/dt-1.9.4/js/jquery.dataTables.min.js which is the app master GUI of application_1399289015992_0002 owned by ubuntu
2014-05-05 11:45:58,634 INFO org.apache.hadoop.yarn.server.webproxy.WebAppProxyServlet: dr.who is accessing unchecked http://ip-10-0-0-198:52423/static/yarn.css which is the app master GUI of application_1399289015992_0002 owned by ubuntu
2014-05-05 11:45:58,713 INFO org.apache.hadoop.yarn.server.webproxy.WebAppProxyServlet: dr.who is accessing unchecked http://ip-10-0-0-198:52423/static/yarn.dt.plugins.js which is the app master GUI of application_1399289015992_0002 owned by ubuntu
2014-05-05 11:45:59,024 INFO org.apache.hadoop.yarn.server.webproxy.WebAppProxyServlet: dr.who is accessing unchecked http://ip-10-0-0-198:52423/static/jquery/themes-1.9.1/base/images/ui-bg_glass_95_fef1ec_1x400.png which is the app master GUI of application_1399289015992_0002 owned by ubuntu
2014-05-05 11:45:59,025 INFO org.apache.hadoop.yarn.server.webproxy.WebAppProxyServlet: dr.who is accessing unchecked http://ip-10-0-0-198:52423/static/jquery/themes-1.9.1/base/images/ui-bg_flat_75_ffffff_40x100.png which is the app master GUI of application_1399289015992_0002 owned by ubuntu
2014-05-05 11:45:59,037 INFO org.apache.hadoop.yarn.server.webproxy.WebAppProxyServlet: dr.who is accessing unchecked http://ip-10-0-0-198:52423/static/jquery/themes-1.9.1/base/images/ui-icons_454545_256x240.png which is the app master GUI of application_1399289015992_0002 owned by ubuntu
2014-05-05 11:45:59,037 INFO org.apache.hadoop.yarn.server.webproxy.WebAppProxyServlet: dr.who is accessing unchecked http://ip-10-0-0-198:52423/static/jquery/themes-1.9.1/base/images/ui-bg_glass_75_e6e6e6_1x400.png which is the app master GUI of application_1399289015992_0002 owned by ubuntu
2014-05-05 11:45:59,038 INFO org.apache.hadoop.yarn.server.webproxy.WebAppProxyServlet: dr.who is accessing unchecked http://ip-10-0-0-198:52423/static/jquery/themes-1.9.1/base/images/ui-bg_glass_65_ffffff_1x400.png which is the app master GUI of application_1399289015992_0002 owned by ubuntu
2014-05-05 11:45:59,047 INFO org.apache.hadoop.yarn.server.webproxy.WebAppProxyServlet: dr.who is accessing unchecked http://ip-10-0-0-198:52423/static/jquery/themes-1.9.1/base/images/ui-icons_888888_256x240.png which is the app master GUI of application_1399289015992_0002 owned by ubuntu
2014-05-05 11:45:59,100 INFO org.apache.hadoop.yarn.server.webproxy.WebAppProxyServlet: dr.who is accessing unchecked http://ip-10-0-0-198:52423/static/jquery/themes-1.9.1/base/images/ui-bg_highlight-soft_75_cccccc_1x100.png which is the app master GUI of application_1399289015992_0002 owned by ubuntu
2014-05-05 11:46:00,395 INFO org.apache.hadoop.yarn.server.webproxy.WebAppProxyServlet: dr.who is accessing unchecked http://ip-10-0-0-198:52423/mapreduce/attempts/job_1399289015992_0002/r/RUNNING which is the app master GUI of application_1399289015992_0002 owned by ubuntu
2014-05-05 11:46:00,506 INFO org.apache.hadoop.yarn.server.webproxy.WebAppProxyServlet: dr.who is accessing unchecked http://ip-10-0-0-198:52423/static/dt-1.9.4/css/jui-dt.css which is the app master GUI of application_1399289015992_0002 owned by ubuntu
2014-05-05 11:46:00,507 INFO org.apache.hadoop.yarn.server.webproxy.WebAppProxyServlet: dr.who is accessing unchecked http://ip-10-0-0-198:52423/static/jquery/jquery-ui-1.9.1.custom.min.js which is the app master GUI of application_1399289015992_0002 owned by ubuntu
2014-05-05 11:46:00,508 INFO org.apache.hadoop.yarn.server.webproxy.WebAppProxyServlet: dr.who is accessing unchecked http://ip-10-0-0-198:52423/static/dt-1.9.4/js/jquery.dataTables.min.js which is the app master GUI of application_1399289015992_0002 owned by ubuntu
2014-05-05 11:46:00,506 INFO org.apache.hadoop.yarn.server.webproxy.WebAppProxyServlet: dr.who is accessing unchecked http://ip-10-0-0-198:52423/static/jquery/themes-1.9.1/base/jquery-ui.css which is the app master GUI of application_1399289015992_0002 owned by ubuntu
2014-05-05 11:46:00,509 INFO org.apache.hadoop.yarn.server.webproxy.WebAppProxyServlet: dr.who is accessing unchecked http://ip-10-0-0-198:52423/static/yarn.css which is the app master GUI of application_1399289015992_0002 owned by ubuntu
2014-05-05 11:46:00,509 INFO org.apache.hadoop.yarn.server.webproxy.WebAppProxyServlet: dr.who is accessing unchecked http://ip-10-0-0-198:52423/static/jquery/jquery-1.8.2.min.js which is the app master GUI of application_1399289015992_0002 owned by ubuntu
2014-05-05 11:46:00,595 INFO org.apache.hadoop.yarn.server.webproxy.WebAppProxyServlet: dr.who is accessing unchecked http://ip-10-0-0-198:52423/static/yarn.dt.plugins.js which is the app master GUI of application_1399289015992_0002 owned by ubuntu
2014-05-05 11:46:00,902 INFO org.apache.hadoop.yarn.server.webproxy.WebAppProxyServlet: dr.who is accessing unchecked http://ip-10-0-0-198:52423/static/jquery/themes-1.9.1/base/images/ui-bg_glass_95_fef1ec_1x400.png which is the app master GUI of application_1399289015992_0002 owned by ubuntu
2014-05-05 11:46:00,906 INFO org.apache.hadoop.yarn.server.webproxy.WebAppProxyServlet: dr.who is accessing unchecked http://ip-10-0-0-198:52423/static/jquery/themes-1.9.1/base/images/ui-bg_flat_75_ffffff_40x100.png which is the app master GUI of application_1399289015992_0002 owned by ubuntu
2014-05-05 11:46:00,908 INFO org.apache.hadoop.yarn.server.webproxy.WebAppProxyServlet: dr.who is accessing unchecked http://ip-10-0-0-198:52423/static/jquery/themes-1.9.1/base/images/ui-bg_glass_75_e6e6e6_1x400.png which is the app master GUI of application_1399289015992_0002 owned by ubuntu
2014-05-05 11:46:00,913 INFO org.apache.hadoop.yarn.server.webproxy.WebAppProxyServlet: dr.who is accessing unchecked http://ip-10-0-0-198:52423/static/jquery/themes-1.9.1/base/images/ui-bg_glass_65_ffffff_1x400.png which is the app master GUI of application_1399289015992_0002 owned by ubuntu
2014-05-05 11:46:00,913 INFO org.apache.hadoop.yarn.server.webproxy.WebAppProxyServlet: dr.who is accessing unchecked http://ip-10-0-0-198:52423/static/jquery/themes-1.9.1/base/images/ui-icons_888888_256x240.png which is the app master GUI of application_1399289015992_0002 owned by ubuntu
2014-05-05 11:46:00,914 INFO org.apache.hadoop.yarn.server.webproxy.WebAppProxyServlet: dr.who is accessing unchecked http://ip-10-0-0-198:52423/static/jquery/themes-1.9.1/base/images/ui-icons_454545_256x240.png which is the app master GUI of application_1399289015992_0002 owned by ubuntu
2014-05-05 11:46:00,983 INFO org.apache.hadoop.yarn.server.webproxy.WebAppProxyServlet: dr.who is accessing unchecked http://ip-10-0-0-198:52423/static/jquery/themes-1.9.1/base/images/ui-bg_highlight-soft_75_cccccc_1x100.png which is the app master GUI of application_1399289015992_0002 owned by ubuntu
2014-05-05 11:46:01,433 INFO org.apache.hadoop.yarn.server.webproxy.WebAppProxyServlet: dr.who is accessing unchecked http://ip-10-0-0-198:52423/mapreduce/attempts/job_1399289015992_0002/r/RUNNING which is the app master GUI of application_1399289015992_0002 owned by ubuntu
2014-05-05 11:46:01,593 INFO org.apache.hadoop.yarn.server.webproxy.WebAppProxyServlet: dr.who is accessing unchecked http://ip-10-0-0-198:52423/static/yarn.css which is the app master GUI of application_1399289015992_0002 owned by ubuntu
2014-05-05 11:46:01,594 INFO org.apache.hadoop.yarn.server.webproxy.WebAppProxyServlet: dr.who is accessing unchecked http://ip-10-0-0-198:52423/static/jquery/themes-1.9.1/base/jquery-ui.css which is the app master GUI of application_1399289015992_0002 owned by ubuntu
2014-05-05 11:46:01,594 INFO org.apache.hadoop.yarn.server.webproxy.WebAppProxyServlet: dr.who is accessing unchecked http://ip-10-0-0-198:52423/static/dt-1.9.4/css/jui-dt.css which is the app master GUI of application_1399289015992_0002 owned by ubuntu
2014-05-05 11:46:01,595 INFO org.apache.hadoop.yarn.server.webproxy.WebAppProxyServlet: dr.who is accessing unchecked http://ip-10-0-0-198:52423/static/jquery/jquery-1.8.2.min.js which is the app master GUI of application_1399289015992_0002 owned by ubuntu
2014-05-05 11:46:01,596 INFO org.apache.hadoop.yarn.server.webproxy.WebAppProxyServlet: dr.who is accessing unchecked http://ip-10-0-0-198:52423/static/dt-1.9.4/js/jquery.dataTables.min.js which is the app master GUI of application_1399289015992_0002 owned by ubuntu
2014-05-05 11:46:01,596 INFO org.apache.hadoop.yarn.server.webproxy.WebAppProxyServlet: dr.who is accessing unchecked http://ip-10-0-0-198:52423/static/jquery/jquery-ui-1.9.1.custom.min.js which is the app master GUI of application_1399289015992_0002 owned by ubuntu
2014-05-05 11:46:01,677 INFO org.apache.hadoop.yarn.server.webproxy.WebAppProxyServlet: dr.who is accessing unchecked http://ip-10-0-0-198:52423/static/yarn.dt.plugins.js which is the app master GUI of application_1399289015992_0002 owned by ubuntu
2014-05-05 11:46:01,974 INFO org.apache.hadoop.yarn.server.webproxy.WebAppProxyServlet: dr.who is accessing unchecked http://ip-10-0-0-198:52423/static/jquery/themes-1.9.1/base/images/ui-bg_glass_95_fef1ec_1x400.png which is the app master GUI of application_1399289015992_0002 owned by ubuntu
2014-05-05 11:46:01,976 INFO org.apache.hadoop.yarn.server.webproxy.WebAppProxyServlet: dr.who is accessing unchecked http://ip-10-0-0-198:52423/static/jquery/themes-1.9.1/base/images/ui-bg_flat_75_ffffff_40x100.png which is the app master GUI of application_1399289015992_0002 owned by ubuntu
2014-05-05 11:46:01,983 INFO org.apache.hadoop.yarn.server.webproxy.WebAppProxyServlet: dr.who is accessing unchecked http://ip-10-0-0-198:52423/static/jquery/themes-1.9.1/base/images/ui-bg_glass_75_e6e6e6_1x400.png which is the app master GUI of application_1399289015992_0002 owned by ubuntu
2014-05-05 11:46:01,984 INFO org.apache.hadoop.yarn.server.webproxy.WebAppProxyServlet: dr.who is accessing unchecked http://ip-10-0-0-198:52423/static/jquery/themes-1.9.1/base/images/ui-bg_glass_65_ffffff_1x400.png which is the app master GUI of application_1399289015992_0002 owned by ubuntu
2014-05-05 11:46:01,987 INFO org.apache.hadoop.yarn.server.webproxy.WebAppProxyServlet: dr.who is accessing unchecked http://ip-10-0-0-198:52423/static/jquery/themes-1.9.1/base/images/ui-icons_454545_256x240.png which is the app master GUI of application_1399289015992_0002 owned by ubuntu
2014-05-05 11:46:01,987 INFO org.apache.hadoop.yarn.server.webproxy.WebAppProxyServlet: dr.who is accessing unchecked http://ip-10-0-0-198:52423/static/jquery/themes-1.9.1/base/images/ui-icons_888888_256x240.png which is the app master GUI of application_1399289015992_0002 owned by ubuntu
2014-05-05 11:46:02,053 INFO org.apache.hadoop.yarn.server.webproxy.WebAppProxyServlet: dr.who is accessing unchecked http://ip-10-0-0-198:52423/static/jquery/themes-1.9.1/base/images/ui-bg_highlight-soft_75_cccccc_1x100.png which is the app master GUI of application_1399289015992_0002 owned by ubuntu
2014-05-05 11:46:02,604 INFO org.apache.hadoop.yarn.server.webproxy.WebAppProxyServlet: dr.who is accessing unchecked http://ip-10-0-0-198:52423/mapreduce/attempts/job_1399289015992_0002/r/RUNNING which is the app master GUI of application_1399289015992_0002 owned by ubuntu
2014-05-05 11:46:02,773 INFO org.apache.hadoop.yarn.server.webproxy.WebAppProxyServlet: dr.who is accessing unchecked http://ip-10-0-0-198:52423/static/yarn.css which is the app master GUI of application_1399289015992_0002 owned by ubuntu
2014-05-05 11:46:02,775 INFO org.apache.hadoop.yarn.server.webproxy.WebAppProxyServlet: dr.who is accessing unchecked http://ip-10-0-0-198:52423/static/dt-1.9.4/css/jui-dt.css which is the app master GUI of application_1399289015992_0002 owned by ubuntu
2014-05-05 11:46:02,775 INFO org.apache.hadoop.yarn.server.webproxy.WebAppProxyServlet: dr.who is accessing unchecked http://ip-10-0-0-198:52423/static/dt-1.9.4/js/jquery.dataTables.min.js which is the app master GUI of application_1399289015992_0002 owned by ubuntu
2014-05-05 11:46:02,780 INFO org.apache.hadoop.yarn.server.webproxy.WebAppProxyServlet: dr.who is accessing unchecked http://ip-10-0-0-198:52423/static/jquery/jquery-1.8.2.min.js which is the app master GUI of application_1399289015992_0002 owned by ubuntu
2014-05-05 11:46:02,781 INFO org.apache.hadoop.yarn.server.webproxy.WebAppProxyServlet: dr.who is accessing unchecked http://ip-10-0-0-198:52423/static/jquery/themes-1.9.1/base/jquery-ui.css which is the app master GUI of application_1399289015992_0002 owned by ubuntu
2014-05-05 11:46:02,783 INFO org.apache.hadoop.yarn.server.webproxy.WebAppProxyServlet: dr.who is accessing unchecked http://ip-10-0-0-198:52423/static/jquery/jquery-ui-1.9.1.custom.min.js which is the app master GUI of application_1399289015992_0002 owned by ubuntu
2014-05-05 11:46:02,856 INFO org.apache.hadoop.yarn.server.webproxy.WebAppProxyServlet: dr.who is accessing unchecked http://ip-10-0-0-198:52423/static/yarn.dt.plugins.js which is the app master GUI of application_1399289015992_0002 owned by ubuntu
2014-05-05 11:46:03,177 INFO org.apache.hadoop.yarn.server.webproxy.WebAppProxyServlet: dr.who is accessing unchecked http://ip-10-0-0-198:52423/static/jquery/themes-1.9.1/base/images/ui-bg_glass_95_fef1ec_1x400.png which is the app master GUI of application_1399289015992_0002 owned by ubuntu
2014-05-05 11:46:03,178 INFO org.apache.hadoop.yarn.server.webproxy.WebAppProxyServlet: dr.who is accessing unchecked http://ip-10-0-0-198:52423/static/jquery/themes-1.9.1/base/images/ui-bg_flat_75_ffffff_40x100.png which is the app master GUI of application_1399289015992_0002 owned by ubuntu
2014-05-05 11:46:03,184 INFO org.apache.hadoop.yarn.server.webproxy.WebAppProxyServlet: dr.who is accessing unchecked http://ip-10-0-0-198:52423/static/jquery/themes-1.9.1/base/images/ui-bg_glass_75_e6e6e6_1x400.png which is the app master GUI of application_1399289015992_0002 owned by ubuntu
2014-05-05 11:46:03,187 INFO org.apache.hadoop.yarn.server.webproxy.WebAppProxyServlet: dr.who is accessing unchecked http://ip-10-0-0-198:52423/static/jquery/themes-1.9.1/base/images/ui-bg_glass_65_ffffff_1x400.png which is the app master GUI of application_1399289015992_0002 owned by ubuntu
2014-05-05 11:46:03,188 INFO org.apache.hadoop.yarn.server.webproxy.WebAppProxyServlet: dr.who is accessing unchecked http://ip-10-0-0-198:52423/static/jquery/themes-1.9.1/base/images/ui-icons_454545_256x240.png which is the app master GUI of application_1399289015992_0002 owned by ubuntu
2014-05-05 11:46:03,189 INFO org.apache.hadoop.yarn.server.webproxy.WebAppProxyServlet: dr.who is accessing unchecked http://ip-10-0-0-198:52423/static/jquery/themes-1.9.1/base/images/ui-icons_888888_256x240.png which is the app master GUI of application_1399289015992_0002 owned by ubuntu
2014-05-05 11:46:03,260 INFO org.apache.hadoop.yarn.server.webproxy.WebAppProxyServlet: dr.who is accessing unchecked http://ip-10-0-0-198:52423/static/jquery/themes-1.9.1/base/images/ui-bg_highlight-soft_75_cccccc_1x100.png which is the app master GUI of application_1399289015992_0002 owned by ubuntu
2014-05-05 11:46:04,097 INFO org.apache.hadoop.yarn.server.webproxy.WebAppProxyServlet: dr.who is accessing unchecked http://ip-10-0-0-198:52423/mapreduce/attempts/job_1399289015992_0002/r/RUNNING which is the app master GUI of application_1399289015992_0002 owned by ubuntu
2014-05-05 11:46:04,210 INFO org.apache.hadoop.yarn.server.webproxy.WebAppProxyServlet: dr.who is accessing unchecked http://ip-10-0-0-198:52423/static/yarn.css which is the app master GUI of application_1399289015992_0002 owned by ubuntu
2014-05-05 11:46:04,211 INFO org.apache.hadoop.yarn.server.webproxy.WebAppProxyServlet: dr.who is accessing unchecked http://ip-10-0-0-198:52423/static/jquery/themes-1.9.1/base/jquery-ui.css which is the app master GUI of application_1399289015992_0002 owned by ubuntu
2014-05-05 11:46:04,212 INFO org.apache.hadoop.yarn.server.webproxy.WebAppProxyServlet: dr.who is accessing unchecked http://ip-10-0-0-198:52423/static/dt-1.9.4/css/jui-dt.css which is the app master GUI of application_1399289015992_0002 owned by ubuntu
2014-05-05 11:46:04,216 INFO org.apache.hadoop.yarn.server.webproxy.WebAppProxyServlet: dr.who is accessing unchecked http://ip-10-0-0-198:52423/static/dt-1.9.4/js/jquery.dataTables.min.js which is the app master GUI of application_1399289015992_0002 owned by ubuntu
2014-05-05 11:46:04,216 INFO org.apache.hadoop.yarn.server.webproxy.WebAppProxyServlet: dr.who is accessing unchecked http://ip-10-0-0-198:52423/static/jquery/jquery-ui-1.9.1.custom.min.js which is the app master GUI of application_1399289015992_0002 owned by ubuntu
2014-05-05 11:46:04,218 INFO org.apache.hadoop.yarn.server.webproxy.WebAppProxyServlet: dr.who is accessing unchecked http://ip-10-0-0-198:52423/static/jquery/jquery-1.8.2.min.js which is the app master GUI of application_1399289015992_0002 owned by ubuntu
2014-05-05 11:46:04,297 INFO org.apache.hadoop.yarn.server.webproxy.WebAppProxyServlet: dr.who is accessing unchecked http://ip-10-0-0-198:52423/static/yarn.dt.plugins.js which is the app master GUI of application_1399289015992_0002 owned by ubuntu
2014-05-05 11:46:04,551 INFO org.apache.hadoop.yarn.server.webproxy.WebAppProxyServlet: dr.who is accessing unchecked http://ip-10-0-0-198:52423/static/jquery/themes-1.9.1/base/images/ui-bg_flat_75_ffffff_40x100.png which is the app master GUI of application_1399289015992_0002 owned by ubuntu
2014-05-05 11:46:04,552 INFO org.apache.hadoop.yarn.server.webproxy.WebAppProxyServlet: dr.who is accessing unchecked http://ip-10-0-0-198:52423/static/jquery/themes-1.9.1/base/images/ui-bg_glass_95_fef1ec_1x400.png which is the app master GUI of application_1399289015992_0002 owned by ubuntu
2014-05-05 11:46:04,561 INFO org.apache.hadoop.yarn.server.webproxy.WebAppProxyServlet: dr.who is accessing unchecked http://ip-10-0-0-198:52423/static/jquery/themes-1.9.1/base/images/ui-bg_glass_75_e6e6e6_1x400.png which is the app master GUI of application_1399289015992_0002 owned by ubuntu
2014-05-05 11:46:04,561 INFO org.apache.hadoop.yarn.server.webproxy.WebAppProxyServlet: dr.who is accessing unchecked http://ip-10-0-0-198:52423/static/jquery/themes-1.9.1/base/images/ui-bg_glass_65_ffffff_1x400.png which is the app master GUI of application_1399289015992_0002 owned by ubuntu
2014-05-05 11:46:04,563 INFO org.apache.hadoop.yarn.server.webproxy.WebAppProxyServlet: dr.who is accessing unchecked http://ip-10-0-0-198:52423/static/jquery/themes-1.9.1/base/images/ui-icons_454545_256x240.png which is the app master GUI of application_1399289015992_0002 owned by ubuntu
2014-05-05 11:46:04,566 INFO org.apache.hadoop.yarn.server.webproxy.WebAppProxyServlet: dr.who is accessing unchecked http://ip-10-0-0-198:52423/static/jquery/themes-1.9.1/base/images/ui-icons_888888_256x240.png which is the app master GUI of application_1399289015992_0002 owned by ubuntu
2014-05-05 11:46:04,638 INFO org.apache.hadoop.yarn.server.webproxy.WebAppProxyServlet: dr.who is accessing unchecked http://ip-10-0-0-198:52423/static/jquery/themes-1.9.1/base/images/ui-bg_highlight-soft_75_cccccc_1x100.png which is the app master GUI of application_1399289015992_0002 owned by ubuntu
2014-05-05 11:46:32,462 INFO org.apache.hadoop.yarn.server.resourcemanager.scheduler.AppSchedulingInfo: checking for deactivate... 
2014-05-05 11:46:32,462 INFO org.apache.hadoop.yarn.server.resourcemanager.scheduler.AppSchedulingInfo: checking for deactivate... 
2014-05-05 11:46:32,576 INFO org.apache.hadoop.yarn.server.resourcemanager.rmapp.attempt.RMAppAttemptImpl: appattempt_1399289015992_0002_000001 State change from RUNNING to FINISHING
2014-05-05 11:46:32,576 INFO org.apache.hadoop.yarn.server.resourcemanager.rmapp.RMAppImpl: Removing application with id application_1399289015992_0002
2014-05-05 11:46:32,576 INFO org.apache.hadoop.yarn.server.resourcemanager.rmapp.RMAppImpl: application_1399289015992_0002 State change from RUNNING to REMOVING
2014-05-05 11:46:32,576 INFO org.apache.hadoop.yarn.server.resourcemanager.recovery.RMStateStore: Removing info for app: application_1399289015992_0002
2014-05-05 11:46:32,577 INFO org.apache.hadoop.yarn.server.resourcemanager.rmapp.RMAppImpl: application_1399289015992_0002 State change from REMOVING to FINISHING
2014-05-05 11:46:33,287 INFO org.apache.hadoop.yarn.server.resourcemanager.rmcontainer.RMContainerImpl: container_1399289015992_0002_01_000011 Container Transitioned from RUNNING to COMPLETED
2014-05-05 11:46:33,287 INFO org.apache.hadoop.yarn.server.resourcemanager.scheduler.common.fica.FiCaSchedulerApp: Completed container: container_1399289015992_0002_01_000011 in state: COMPLETED event:FINISHED
2014-05-05 11:46:33,287 INFO org.apache.hadoop.yarn.server.resourcemanager.RMAuditLogger: USER=ubuntu	OPERATION=AM Released Container	TARGET=SchedulerApp	RESULT=SUCCESS	APPID=application_1399289015992_0002	CONTAINERID=container_1399289015992_0002_01_000011
2014-05-05 11:46:33,287 INFO org.apache.hadoop.yarn.server.resourcemanager.scheduler.common.fica.FiCaSchedulerNode: Released container container_1399289015992_0002_01_000011 of capacity <memory:1024, vCores:1> on host ip-10-0-0-197.us-west-2.compute.internal:36720, which currently has 0 containers, <memory:0, vCores:0> used and <memory:8192, vCores:8> available, release resources=true
2014-05-05 11:46:33,288 INFO org.apache.hadoop.yarn.server.resourcemanager.scheduler.capacity.LeafQueue: default used=<memory:7168, vCores:6> numContainers=6 user=ubuntu user-resources=<memory:7168, vCores:6>
2014-05-05 11:46:33,288 INFO org.apache.hadoop.yarn.server.resourcemanager.scheduler.capacity.LeafQueue: completedContainer container=Container: [ContainerId: container_1399289015992_0002_01_000011, NodeId: ip-10-0-0-197.us-west-2.compute.internal:36720, NodeHttpAddress: ip-10-0-0-197.us-west-2.compute.internal:8042, Resource: <memory:1024, vCores:1>, Priority: 10, Token: Token { kind: ContainerToken, service: 10.0.0.197:36720 }, ] resource=<memory:1024, vCores:1> queue=default: capacity=1.0, absoluteCapacity=1.0, usedResources=<memory:7168, vCores:6>usedCapacity=0.109375, absoluteUsedCapacity=0.109375, numApps=1, numContainers=6 usedCapacity=0.109375 absoluteUsedCapacity=0.109375 used=<memory:7168, vCores:6> cluster=<memory:65536, vCores:64>
2014-05-05 11:46:33,288 INFO org.apache.hadoop.yarn.server.resourcemanager.scheduler.capacity.ParentQueue: completedContainer queue=root usedCapacity=0.109375 absoluteUsedCapacity=0.109375 used=<memory:7168, vCores:6> cluster=<memory:65536, vCores:64>
2014-05-05 11:46:33,288 INFO org.apache.hadoop.yarn.server.resourcemanager.scheduler.capacity.ParentQueue: Re-sorting completed queue: root.default stats: default: capacity=1.0, absoluteCapacity=1.0, usedResources=<memory:7168, vCores:6>usedCapacity=0.109375, absoluteUsedCapacity=0.109375, numApps=1, numContainers=6
2014-05-05 11:46:33,288 INFO org.apache.hadoop.yarn.server.resourcemanager.scheduler.capacity.CapacityScheduler: Application appattempt_1399289015992_0002_000001 released container container_1399289015992_0002_01_000011 on node: host: ip-10-0-0-197.us-west-2.compute.internal:36720 #containers=0 available=8192 used=0 with event: FINISHED
2014-05-05 11:46:33,288 INFO org.apache.hadoop.yarn.server.resourcemanager.rmcontainer.RMContainerImpl: container_1399289015992_0002_01_000010 Container Transitioned from RUNNING to COMPLETED
2014-05-05 11:46:33,289 INFO org.apache.hadoop.yarn.server.resourcemanager.scheduler.common.fica.FiCaSchedulerApp: Completed container: container_1399289015992_0002_01_000010 in state: COMPLETED event:FINISHED
2014-05-05 11:46:33,289 INFO org.apache.hadoop.yarn.server.resourcemanager.RMAuditLogger: USER=ubuntu	OPERATION=AM Released Container	TARGET=SchedulerApp	RESULT=SUCCESS	APPID=application_1399289015992_0002	CONTAINERID=container_1399289015992_0002_01_000010
2014-05-05 11:46:33,289 INFO org.apache.hadoop.yarn.server.resourcemanager.scheduler.common.fica.FiCaSchedulerNode: Released container container_1399289015992_0002_01_000010 of capacity <memory:1024, vCores:1> on host ip-10-0-0-198.us-west-2.compute.internal:60935, which currently has 1 containers, <memory:2048, vCores:1> used and <memory:6144, vCores:7> available, release resources=true
2014-05-05 11:46:33,289 INFO org.apache.hadoop.yarn.server.resourcemanager.scheduler.capacity.LeafQueue: default used=<memory:6144, vCores:5> numContainers=5 user=ubuntu user-resources=<memory:6144, vCores:5>
2014-05-05 11:46:33,289 INFO org.apache.hadoop.yarn.server.resourcemanager.scheduler.capacity.LeafQueue: completedContainer container=Container: [ContainerId: container_1399289015992_0002_01_000010, NodeId: ip-10-0-0-198.us-west-2.compute.internal:60935, NodeHttpAddress: ip-10-0-0-198.us-west-2.compute.internal:8042, Resource: <memory:1024, vCores:1>, Priority: 10, Token: Token { kind: ContainerToken, service: 10.0.0.198:60935 }, ] resource=<memory:1024, vCores:1> queue=default: capacity=1.0, absoluteCapacity=1.0, usedResources=<memory:6144, vCores:5>usedCapacity=0.09375, absoluteUsedCapacity=0.09375, numApps=1, numContainers=5 usedCapacity=0.09375 absoluteUsedCapacity=0.09375 used=<memory:6144, vCores:5> cluster=<memory:65536, vCores:64>
2014-05-05 11:46:33,289 INFO org.apache.hadoop.yarn.server.resourcemanager.scheduler.capacity.ParentQueue: completedContainer queue=root usedCapacity=0.09375 absoluteUsedCapacity=0.09375 used=<memory:6144, vCores:5> cluster=<memory:65536, vCores:64>
2014-05-05 11:46:33,289 INFO org.apache.hadoop.yarn.server.resourcemanager.scheduler.capacity.ParentQueue: Re-sorting completed queue: root.default stats: default: capacity=1.0, absoluteCapacity=1.0, usedResources=<memory:6144, vCores:5>usedCapacity=0.09375, absoluteUsedCapacity=0.09375, numApps=1, numContainers=5
2014-05-05 11:46:33,289 INFO org.apache.hadoop.yarn.server.resourcemanager.scheduler.capacity.CapacityScheduler: Application appattempt_1399289015992_0002_000001 released container container_1399289015992_0002_01_000010 on node: host: ip-10-0-0-198.us-west-2.compute.internal:60935 #containers=1 available=6144 used=2048 with event: FINISHED
2014-05-05 11:46:33,318 INFO org.apache.hadoop.yarn.server.resourcemanager.rmcontainer.RMContainerImpl: container_1399289015992_0002_01_000006 Container Transitioned from RUNNING to COMPLETED
2014-05-05 11:46:33,318 INFO org.apache.hadoop.yarn.server.resourcemanager.scheduler.common.fica.FiCaSchedulerApp: Completed container: container_1399289015992_0002_01_000006 in state: COMPLETED event:FINISHED
2014-05-05 11:46:33,318 INFO org.apache.hadoop.yarn.server.resourcemanager.RMAuditLogger: USER=ubuntu	OPERATION=AM Released Container	TARGET=SchedulerApp	RESULT=SUCCESS	APPID=application_1399289015992_0002	CONTAINERID=container_1399289015992_0002_01_000006
2014-05-05 11:46:33,318 INFO org.apache.hadoop.yarn.server.resourcemanager.scheduler.common.fica.FiCaSchedulerNode: Released container container_1399289015992_0002_01_000006 of capacity <memory:1024, vCores:1> on host ip-10-0-0-193.us-west-2.compute.internal:60686, which currently has 0 containers, <memory:0, vCores:0> used and <memory:8192, vCores:8> available, release resources=true
2014-05-05 11:46:33,318 INFO org.apache.hadoop.yarn.server.resourcemanager.scheduler.capacity.LeafQueue: default used=<memory:5120, vCores:4> numContainers=4 user=ubuntu user-resources=<memory:5120, vCores:4>
2014-05-05 11:46:33,318 INFO org.apache.hadoop.yarn.server.resourcemanager.scheduler.capacity.LeafQueue: completedContainer container=Container: [ContainerId: container_1399289015992_0002_01_000006, NodeId: ip-10-0-0-193.us-west-2.compute.internal:60686, NodeHttpAddress: ip-10-0-0-193.us-west-2.compute.internal:8042, Resource: <memory:1024, vCores:1>, Priority: 10, Token: Token { kind: ContainerToken, service: 10.0.0.193:60686 }, ] resource=<memory:1024, vCores:1> queue=default: capacity=1.0, absoluteCapacity=1.0, usedResources=<memory:5120, vCores:4>usedCapacity=0.078125, absoluteUsedCapacity=0.078125, numApps=1, numContainers=4 usedCapacity=0.078125 absoluteUsedCapacity=0.078125 used=<memory:5120, vCores:4> cluster=<memory:65536, vCores:64>
2014-05-05 11:46:33,318 INFO org.apache.hadoop.yarn.server.resourcemanager.scheduler.capacity.ParentQueue: completedContainer queue=root usedCapacity=0.078125 absoluteUsedCapacity=0.078125 used=<memory:5120, vCores:4> cluster=<memory:65536, vCores:64>
2014-05-05 11:46:33,318 INFO org.apache.hadoop.yarn.server.resourcemanager.scheduler.capacity.ParentQueue: Re-sorting completed queue: root.default stats: default: capacity=1.0, absoluteCapacity=1.0, usedResources=<memory:5120, vCores:4>usedCapacity=0.078125, absoluteUsedCapacity=0.078125, numApps=1, numContainers=4
2014-05-05 11:46:33,318 INFO org.apache.hadoop.yarn.server.resourcemanager.scheduler.capacity.CapacityScheduler: Application appattempt_1399289015992_0002_000001 released container container_1399289015992_0002_01_000006 on node: host: ip-10-0-0-193.us-west-2.compute.internal:60686 #containers=0 available=8192 used=0 with event: FINISHED
2014-05-05 11:46:33,330 INFO org.apache.hadoop.yarn.server.resourcemanager.rmcontainer.RMContainerImpl: container_1399289015992_0002_01_000009 Container Transitioned from RUNNING to COMPLETED
2014-05-05 11:46:33,330 INFO org.apache.hadoop.yarn.server.resourcemanager.scheduler.common.fica.FiCaSchedulerApp: Completed container: container_1399289015992_0002_01_000009 in state: COMPLETED event:FINISHED
2014-05-05 11:46:33,330 INFO org.apache.hadoop.yarn.server.resourcemanager.RMAuditLogger: USER=ubuntu	OPERATION=AM Released Container	TARGET=SchedulerApp	RESULT=SUCCESS	APPID=application_1399289015992_0002	CONTAINERID=container_1399289015992_0002_01_000009
2014-05-05 11:46:33,330 INFO org.apache.hadoop.yarn.server.resourcemanager.scheduler.common.fica.FiCaSchedulerNode: Released container container_1399289015992_0002_01_000009 of capacity <memory:1024, vCores:1> on host ip-10-0-0-199.us-west-2.compute.internal:36159, which currently has 0 containers, <memory:0, vCores:0> used and <memory:8192, vCores:8> available, release resources=true
2014-05-05 11:46:33,330 INFO org.apache.hadoop.yarn.server.resourcemanager.scheduler.capacity.LeafQueue: default used=<memory:4096, vCores:3> numContainers=3 user=ubuntu user-resources=<memory:4096, vCores:3>
2014-05-05 11:46:33,330 INFO org.apache.hadoop.yarn.server.resourcemanager.scheduler.capacity.LeafQueue: completedContainer container=Container: [ContainerId: container_1399289015992_0002_01_000009, NodeId: ip-10-0-0-199.us-west-2.compute.internal:36159, NodeHttpAddress: ip-10-0-0-199.us-west-2.compute.internal:8042, Resource: <memory:1024, vCores:1>, Priority: 10, Token: Token { kind: ContainerToken, service: 10.0.0.199:36159 }, ] resource=<memory:1024, vCores:1> queue=default: capacity=1.0, absoluteCapacity=1.0, usedResources=<memory:4096, vCores:3>usedCapacity=0.0625, absoluteUsedCapacity=0.0625, numApps=1, numContainers=3 usedCapacity=0.0625 absoluteUsedCapacity=0.0625 used=<memory:4096, vCores:3> cluster=<memory:65536, vCores:64>
2014-05-05 11:46:33,330 INFO org.apache.hadoop.yarn.server.resourcemanager.scheduler.capacity.ParentQueue: completedContainer queue=root usedCapacity=0.0625 absoluteUsedCapacity=0.0625 used=<memory:4096, vCores:3> cluster=<memory:65536, vCores:64>
2014-05-05 11:46:33,330 INFO org.apache.hadoop.yarn.server.resourcemanager.scheduler.capacity.ParentQueue: Re-sorting completed queue: root.default stats: default: capacity=1.0, absoluteCapacity=1.0, usedResources=<memory:4096, vCores:3>usedCapacity=0.0625, absoluteUsedCapacity=0.0625, numApps=1, numContainers=3
2014-05-05 11:46:33,331 INFO org.apache.hadoop.yarn.server.resourcemanager.scheduler.capacity.CapacityScheduler: Application appattempt_1399289015992_0002_000001 released container container_1399289015992_0002_01_000009 on node: host: ip-10-0-0-199.us-west-2.compute.internal:36159 #containers=0 available=8192 used=0 with event: FINISHED
2014-05-05 11:46:33,350 INFO org.apache.hadoop.yarn.server.resourcemanager.rmcontainer.RMContainerImpl: container_1399289015992_0002_01_000008 Container Transitioned from RUNNING to COMPLETED
2014-05-05 11:46:33,350 INFO org.apache.hadoop.yarn.server.resourcemanager.scheduler.common.fica.FiCaSchedulerApp: Completed container: container_1399289015992_0002_01_000008 in state: COMPLETED event:FINISHED
2014-05-05 11:46:33,350 INFO org.apache.hadoop.yarn.server.resourcemanager.RMAuditLogger: USER=ubuntu	OPERATION=AM Released Container	TARGET=SchedulerApp	RESULT=SUCCESS	APPID=application_1399289015992_0002	CONTAINERID=container_1399289015992_0002_01_000008
2014-05-05 11:46:33,350 INFO org.apache.hadoop.yarn.server.resourcemanager.scheduler.common.fica.FiCaSchedulerNode: Released container container_1399289015992_0002_01_000008 of capacity <memory:1024, vCores:1> on host ip-10-0-0-200.us-west-2.compute.internal:36991, which currently has 0 containers, <memory:0, vCores:0> used and <memory:8192, vCores:8> available, release resources=true
2014-05-05 11:46:33,350 INFO org.apache.hadoop.yarn.server.resourcemanager.scheduler.capacity.LeafQueue: default used=<memory:3072, vCores:2> numContainers=2 user=ubuntu user-resources=<memory:3072, vCores:2>
2014-05-05 11:46:33,350 INFO org.apache.hadoop.yarn.server.resourcemanager.scheduler.capacity.LeafQueue: completedContainer container=Container: [ContainerId: container_1399289015992_0002_01_000008, NodeId: ip-10-0-0-200.us-west-2.compute.internal:36991, NodeHttpAddress: ip-10-0-0-200.us-west-2.compute.internal:8042, Resource: <memory:1024, vCores:1>, Priority: 10, Token: Token { kind: ContainerToken, service: 10.0.0.200:36991 }, ] resource=<memory:1024, vCores:1> queue=default: capacity=1.0, absoluteCapacity=1.0, usedResources=<memory:3072, vCores:2>usedCapacity=0.046875, absoluteUsedCapacity=0.046875, numApps=1, numContainers=2 usedCapacity=0.046875 absoluteUsedCapacity=0.046875 used=<memory:3072, vCores:2> cluster=<memory:65536, vCores:64>
2014-05-05 11:46:33,350 INFO org.apache.hadoop.yarn.server.resourcemanager.scheduler.capacity.ParentQueue: completedContainer queue=root usedCapacity=0.046875 absoluteUsedCapacity=0.046875 used=<memory:3072, vCores:2> cluster=<memory:65536, vCores:64>
2014-05-05 11:46:33,350 INFO org.apache.hadoop.yarn.server.resourcemanager.scheduler.capacity.ParentQueue: Re-sorting completed queue: root.default stats: default: capacity=1.0, absoluteCapacity=1.0, usedResources=<memory:3072, vCores:2>usedCapacity=0.046875, absoluteUsedCapacity=0.046875, numApps=1, numContainers=2
2014-05-05 11:46:33,350 INFO org.apache.hadoop.yarn.server.resourcemanager.scheduler.capacity.CapacityScheduler: Application appattempt_1399289015992_0002_000001 released container container_1399289015992_0002_01_000008 on node: host: ip-10-0-0-200.us-west-2.compute.internal:36991 #containers=0 available=8192 used=0 with event: FINISHED
2014-05-05 11:46:33,352 INFO org.apache.hadoop.yarn.server.resourcemanager.rmcontainer.RMContainerImpl: container_1399289015992_0002_01_000007 Container Transitioned from RUNNING to COMPLETED
2014-05-05 11:46:33,352 INFO org.apache.hadoop.yarn.server.resourcemanager.scheduler.common.fica.FiCaSchedulerApp: Completed container: container_1399289015992_0002_01_000007 in state: COMPLETED event:FINISHED
2014-05-05 11:46:33,352 INFO org.apache.hadoop.yarn.server.resourcemanager.RMAuditLogger: USER=ubuntu	OPERATION=AM Released Container	TARGET=SchedulerApp	RESULT=SUCCESS	APPID=application_1399289015992_0002	CONTAINERID=container_1399289015992_0002_01_000007
2014-05-05 11:46:33,352 INFO org.apache.hadoop.yarn.server.resourcemanager.scheduler.common.fica.FiCaSchedulerNode: Released container container_1399289015992_0002_01_000007 of capacity <memory:1024, vCores:1> on host ip-10-0-0-196.us-west-2.compute.internal:47357, which currently has 0 containers, <memory:0, vCores:0> used and <memory:8192, vCores:8> available, release resources=true
2014-05-05 11:46:33,352 INFO org.apache.hadoop.yarn.server.resourcemanager.scheduler.capacity.LeafQueue: default used=<memory:2048, vCores:1> numContainers=1 user=ubuntu user-resources=<memory:2048, vCores:1>
2014-05-05 11:46:33,352 INFO org.apache.hadoop.yarn.server.resourcemanager.scheduler.capacity.LeafQueue: completedContainer container=Container: [ContainerId: container_1399289015992_0002_01_000007, NodeId: ip-10-0-0-196.us-west-2.compute.internal:47357, NodeHttpAddress: ip-10-0-0-196.us-west-2.compute.internal:8042, Resource: <memory:1024, vCores:1>, Priority: 10, Token: Token { kind: ContainerToken, service: 10.0.0.196:47357 }, ] resource=<memory:1024, vCores:1> queue=default: capacity=1.0, absoluteCapacity=1.0, usedResources=<memory:2048, vCores:1>usedCapacity=0.03125, absoluteUsedCapacity=0.03125, numApps=1, numContainers=1 usedCapacity=0.03125 absoluteUsedCapacity=0.03125 used=<memory:2048, vCores:1> cluster=<memory:65536, vCores:64>
2014-05-05 11:46:33,352 INFO org.apache.hadoop.yarn.server.resourcemanager.scheduler.capacity.ParentQueue: completedContainer queue=root usedCapacity=0.03125 absoluteUsedCapacity=0.03125 used=<memory:2048, vCores:1> cluster=<memory:65536, vCores:64>
2014-05-05 11:46:33,352 INFO org.apache.hadoop.yarn.server.resourcemanager.scheduler.capacity.ParentQueue: Re-sorting completed queue: root.default stats: default: capacity=1.0, absoluteCapacity=1.0, usedResources=<memory:2048, vCores:1>usedCapacity=0.03125, absoluteUsedCapacity=0.03125, numApps=1, numContainers=1
2014-05-05 11:46:33,352 INFO org.apache.hadoop.yarn.server.resourcemanager.scheduler.capacity.CapacityScheduler: Application appattempt_1399289015992_0002_000001 released container container_1399289015992_0002_01_000007 on node: host: ip-10-0-0-196.us-west-2.compute.internal:47357 #containers=0 available=8192 used=0 with event: FINISHED
2014-05-05 11:46:39,297 INFO org.apache.hadoop.yarn.server.resourcemanager.rmcontainer.RMContainerImpl: container_1399289015992_0002_01_000001 Container Transitioned from RUNNING to COMPLETED
2014-05-05 11:46:39,297 INFO org.apache.hadoop.yarn.server.resourcemanager.ApplicationMasterService: Unregistering app attempt : appattempt_1399289015992_0002_000001
2014-05-05 11:46:39,297 INFO org.apache.hadoop.yarn.server.resourcemanager.scheduler.common.fica.FiCaSchedulerApp: Completed container: container_1399289015992_0002_01_000001 in state: COMPLETED event:FINISHED
2014-05-05 11:46:39,298 INFO org.apache.hadoop.yarn.server.resourcemanager.rmapp.attempt.RMAppAttemptImpl: appattempt_1399289015992_0002_000001 State change from FINISHING to FINISHED
2014-05-05 11:46:39,298 INFO org.apache.hadoop.yarn.server.resourcemanager.RMAuditLogger: USER=ubuntu	OPERATION=AM Released Container	TARGET=SchedulerApp	RESULT=SUCCESS	APPID=application_1399289015992_0002	CONTAINERID=container_1399289015992_0002_01_000001
2014-05-05 11:46:39,298 INFO org.apache.hadoop.yarn.server.resourcemanager.scheduler.common.fica.FiCaSchedulerNode: Released container container_1399289015992_0002_01_000001 of capacity <memory:2048, vCores:1> on host ip-10-0-0-198.us-west-2.compute.internal:60935, which currently has 0 containers, <memory:0, vCores:0> used and <memory:8192, vCores:8> available, release resources=true
2014-05-05 11:46:39,298 INFO org.apache.hadoop.yarn.server.resourcemanager.rmapp.RMAppImpl: application_1399289015992_0002 State change from FINISHING to FINISHED
2014-05-05 11:46:39,298 INFO org.apache.hadoop.yarn.server.resourcemanager.scheduler.capacity.LeafQueue: default used=<memory:0, vCores:0> numContainers=0 user=ubuntu user-resources=<memory:0, vCores:0>
2014-05-05 11:46:39,298 INFO org.apache.hadoop.yarn.server.resourcemanager.RMAuditLogger: USER=ubuntu	OPERATION=Application Finished - Succeeded	TARGET=RMAppManager	RESULT=SUCCESS	APPID=application_1399289015992_0002
2014-05-05 11:46:39,298 INFO org.apache.hadoop.yarn.server.resourcemanager.scheduler.capacity.LeafQueue: completedContainer container=Container: [ContainerId: container_1399289015992_0002_01_000001, NodeId: ip-10-0-0-198.us-west-2.compute.internal:60935, NodeHttpAddress: ip-10-0-0-198.us-west-2.compute.internal:8042, Resource: <memory:2048, vCores:1>, Priority: 0, Token: Token { kind: ContainerToken, service: 10.0.0.198:60935 }, ] resource=<memory:2048, vCores:1> queue=default: capacity=1.0, absoluteCapacity=1.0, usedResources=<memory:0, vCores:0>usedCapacity=0.0, absoluteUsedCapacity=0.0, numApps=1, numContainers=0 usedCapacity=0.0 absoluteUsedCapacity=0.0 used=<memory:0, vCores:0> cluster=<memory:65536, vCores:64>
2014-05-05 11:46:39,298 INFO org.apache.hadoop.yarn.server.resourcemanager.RMAppManager$ApplicationSummary: appId=application_1399289015992_0002,name=hints||path:/in1m||num reduce:8,user=ubuntu,queue=default,state=FINISHED,trackingUrl=ec2-54-186-230-200.us-west-2.compute.amazonaws.com:8088/proxy/application_1399289015992_0002/jobhistory/job/job_1399289015992_0002,appMasterHost=ip-10-0-0-198,startTime=1399290177883,finishTime=1399290392577,finalStatus=KILLED
2014-05-05 11:46:39,298 INFO org.apache.hadoop.yarn.server.resourcemanager.scheduler.capacity.ParentQueue: completedContainer queue=root usedCapacity=0.0 absoluteUsedCapacity=0.0 used=<memory:0, vCores:0> cluster=<memory:65536, vCores:64>
2014-05-05 11:46:39,304 INFO org.apache.hadoop.yarn.server.resourcemanager.scheduler.capacity.ParentQueue: Re-sorting completed queue: root.default stats: default: capacity=1.0, absoluteCapacity=1.0, usedResources=<memory:0, vCores:0>usedCapacity=0.0, absoluteUsedCapacity=0.0, numApps=1, numContainers=0
2014-05-05 11:46:39,304 INFO org.apache.hadoop.yarn.server.resourcemanager.scheduler.capacity.CapacityScheduler: Application appattempt_1399289015992_0002_000001 released container container_1399289015992_0002_01_000001 on node: host: ip-10-0-0-198.us-west-2.compute.internal:60935 #containers=0 available=8192 used=0 with event: FINISHED
2014-05-05 11:46:39,304 INFO org.apache.hadoop.yarn.server.resourcemanager.scheduler.capacity.CapacityScheduler: Application appattempt_1399289015992_0002_000001 is done. finalState=FINISHED
2014-05-05 11:46:39,304 INFO org.apache.hadoop.yarn.server.resourcemanager.scheduler.AppSchedulingInfo: Application application_1399289015992_0002 requests cleared
2014-05-05 11:46:39,304 INFO org.apache.hadoop.yarn.server.resourcemanager.scheduler.capacity.LeafQueue: Application removed - appId: application_1399289015992_0002 user: ubuntu queue: default #user-pending-applications: 0 #user-active-applications: 0 #queue-pending-applications: 0 #queue-active-applications: 0
2014-05-05 11:46:39,304 INFO org.apache.hadoop.yarn.server.resourcemanager.scheduler.capacity.ParentQueue: Application removed - appId: application_1399289015992_0002 user: ubuntu leaf-queue of parent: root #applications: 0
2014-05-05 11:46:39,305 INFO org.apache.hadoop.yarn.server.resourcemanager.amlauncher.AMLauncher: Cleaning master appattempt_1399289015992_0002_000001
2014-05-05 11:46:47,064 INFO org.apache.hadoop.yarn.server.resourcemanager.ClientRMService: Allocated new applicationId: 3
2014-05-05 11:46:48,472 INFO org.apache.hadoop.yarn.server.resourcemanager.ClientRMService: Application with id 3 submitted by user ubuntu
2014-05-05 11:46:48,472 INFO org.apache.hadoop.yarn.server.resourcemanager.rmapp.RMAppImpl: Storing application with id application_1399289015992_0003
2014-05-05 11:46:48,472 INFO org.apache.hadoop.yarn.server.resourcemanager.rmapp.RMAppImpl: application_1399289015992_0003 State change from NEW to NEW_SAVING
2014-05-05 11:46:48,472 INFO org.apache.hadoop.yarn.server.resourcemanager.recovery.RMStateStore: Storing info for app: application_1399289015992_0003
2014-05-05 11:46:48,472 INFO org.apache.hadoop.yarn.server.resourcemanager.RMAuditLogger: USER=ubuntu	IP=10.0.0.195	OPERATION=Submit Application Request	TARGET=ClientRMService	RESULT=SUCCESS	APPID=application_1399289015992_0003
2014-05-05 11:46:48,473 INFO org.apache.hadoop.yarn.server.resourcemanager.rmapp.RMAppImpl: application_1399289015992_0003 State change from NEW_SAVING to SUBMITTED
2014-05-05 11:46:48,473 INFO org.apache.hadoop.yarn.server.resourcemanager.ApplicationMasterService: Registering app attempt : appattempt_1399289015992_0003_000001
2014-05-05 11:46:48,473 INFO org.apache.hadoop.yarn.server.resourcemanager.rmapp.attempt.RMAppAttemptImpl: appattempt_1399289015992_0003_000001 State change from NEW to SUBMITTED
2014-05-05 11:46:48,473 INFO org.apache.hadoop.yarn.server.resourcemanager.scheduler.capacity.LeafQueue: Application application_1399289015992_0003 from user: ubuntu activated in queue: default
2014-05-05 11:46:48,473 INFO org.apache.hadoop.yarn.server.resourcemanager.scheduler.capacity.LeafQueue: Application added - appId: application_1399289015992_0003 user: org.apache.hadoop.yarn.server.resourcemanager.scheduler.capacity.LeafQueue$User@f4b52ce, leaf-queue: default #user-pending-applications: 0 #user-active-applications: 1 #queue-pending-applications: 0 #queue-active-applications: 1
2014-05-05 11:46:48,474 INFO org.apache.hadoop.yarn.server.resourcemanager.scheduler.capacity.ParentQueue: Application added - appId: application_1399289015992_0003 user: ubuntu leaf-queue of parent: root #applications: 1
2014-05-05 11:46:48,474 INFO org.apache.hadoop.yarn.server.resourcemanager.scheduler.capacity.CapacityScheduler: Application Submission: appattempt_1399289015992_0003_000001, user: ubuntu queue: default: capacity=1.0, absoluteCapacity=1.0, usedResources=<memory:0, vCores:0>usedCapacity=0.0, absoluteUsedCapacity=0.0, numApps=1, numContainers=0, currently active: 1
2014-05-05 11:46:48,474 INFO org.apache.hadoop.yarn.server.resourcemanager.rmapp.attempt.RMAppAttemptImpl: appattempt_1399289015992_0003_000001 State change from SUBMITTED to SCHEDULED
2014-05-05 11:46:48,474 INFO org.apache.hadoop.yarn.server.resourcemanager.rmapp.RMAppImpl: application_1399289015992_0003 State change from SUBMITTED to ACCEPTED
2014-05-05 11:46:48,808 INFO org.apache.hadoop.yarn.server.resourcemanager.rmcontainer.RMContainerImpl: container_1399289015992_0003_01_000001 Container Transitioned from NEW to ALLOCATED
2014-05-05 11:46:48,808 INFO org.apache.hadoop.yarn.server.resourcemanager.RMAuditLogger: USER=ubuntu	OPERATION=AM Allocated Container	TARGET=SchedulerApp	RESULT=SUCCESS	APPID=application_1399289015992_0003	CONTAINERID=container_1399289015992_0003_01_000001
2014-05-05 11:46:48,808 INFO org.apache.hadoop.yarn.server.resourcemanager.scheduler.common.fica.FiCaSchedulerNode: Assigned container container_1399289015992_0003_01_000001 of capacity <memory:2048, vCores:1> on host nodea:34521, which currently has 1 containers, <memory:2048, vCores:1> used and <memory:6144, vCores:7> available
2014-05-05 11:46:48,808 INFO org.apache.hadoop.yarn.server.resourcemanager.scheduler.capacity.LeafQueue: assignedContainer application=application_1399289015992_0003 container=Container: [ContainerId: container_1399289015992_0003_01_000001, NodeId: nodea:34521, NodeHttpAddress: nodea:8042, Resource: <memory:2048, vCores:1>, Priority: 0, Token: Token { kind: ContainerToken, service: 10.0.0.195:34521 }, ] containerId=container_1399289015992_0003_01_000001 queue=default: capacity=1.0, absoluteCapacity=1.0, usedResources=<memory:0, vCores:0>usedCapacity=0.0, absoluteUsedCapacity=0.0, numApps=1, numContainers=0 usedCapacity=0.0 absoluteUsedCapacity=0.0 used=<memory:0, vCores:0> cluster=<memory:65536, vCores:64>
2014-05-05 11:46:48,809 INFO org.apache.hadoop.yarn.server.resourcemanager.scheduler.capacity.ParentQueue: Re-sorting assigned queue: root.default stats: default: capacity=1.0, absoluteCapacity=1.0, usedResources=<memory:2048, vCores:1>usedCapacity=0.03125, absoluteUsedCapacity=0.03125, numApps=1, numContainers=1
2014-05-05 11:46:48,809 INFO org.apache.hadoop.yarn.server.resourcemanager.rmcontainer.RMContainerImpl: container_1399289015992_0003_01_000001 Container Transitioned from ALLOCATED to ACQUIRED
2014-05-05 11:46:48,809 INFO org.apache.hadoop.yarn.server.resourcemanager.scheduler.capacity.ParentQueue: assignedContainer queue=root usedCapacity=0.03125 absoluteUsedCapacity=0.03125 used=<memory:2048, vCores:1> cluster=<memory:65536, vCores:64>
2014-05-05 11:46:48,809 INFO org.apache.hadoop.yarn.server.resourcemanager.rmapp.attempt.RMAppAttemptImpl: Storing attempt: AppId: application_1399289015992_0003 AttemptId: appattempt_1399289015992_0003_000001 MasterContainer: Container: [ContainerId: container_1399289015992_0003_01_000001, NodeId: nodea:34521, NodeHttpAddress: nodea:8042, Resource: <memory:2048, vCores:1>, Priority: 0, Token: Token { kind: ContainerToken, service: 10.0.0.195:34521 }, ]
2014-05-05 11:46:48,809 INFO org.apache.hadoop.yarn.server.resourcemanager.rmapp.attempt.RMAppAttemptImpl: appattempt_1399289015992_0003_000001 State change from SCHEDULED to ALLOCATED_SAVING
2014-05-05 11:46:48,810 INFO org.apache.hadoop.yarn.server.resourcemanager.recovery.RMStateStore: Storing info for attempt: appattempt_1399289015992_0003_000001
2014-05-05 11:46:48,810 INFO org.apache.hadoop.yarn.server.resourcemanager.rmapp.attempt.RMAppAttemptImpl: appattempt_1399289015992_0003_000001 State change from ALLOCATED_SAVING to ALLOCATED
2014-05-05 11:46:48,810 INFO org.apache.hadoop.yarn.server.resourcemanager.amlauncher.AMLauncher: Launching masterappattempt_1399289015992_0003_000001
2014-05-05 11:46:48,811 INFO org.apache.hadoop.yarn.server.resourcemanager.amlauncher.AMLauncher: Setting up container Container: [ContainerId: container_1399289015992_0003_01_000001, NodeId: nodea:34521, NodeHttpAddress: nodea:8042, Resource: <memory:2048, vCores:1>, Priority: 0, Token: Token { kind: ContainerToken, service: 10.0.0.195:34521 }, ] for AM appattempt_1399289015992_0003_000001
2014-05-05 11:46:48,811 INFO org.apache.hadoop.yarn.server.resourcemanager.amlauncher.AMLauncher: Command to launch container container_1399289015992_0003_01_000001 : $JAVA_HOME/bin/java -Dlog4j.configuration=container-log4j.properties -Dyarn.app.container.log.dir=<LOG_DIR> -Dyarn.app.container.log.filesize=0 -Dhadoop.root.logger=INFO,CLA  -Xmx1024m org.apache.hadoop.mapreduce.v2.app.MRAppMaster 1><LOG_DIR>/stdout 2><LOG_DIR>/stderr 
2014-05-05 11:46:49,059 INFO org.apache.hadoop.yarn.server.resourcemanager.amlauncher.AMLauncher: Done launching container Container: [ContainerId: container_1399289015992_0003_01_000001, NodeId: nodea:34521, NodeHttpAddress: nodea:8042, Resource: <memory:2048, vCores:1>, Priority: 0, Token: Token { kind: ContainerToken, service: 10.0.0.195:34521 }, ] for AM appattempt_1399289015992_0003_000001
2014-05-05 11:46:49,059 INFO org.apache.hadoop.yarn.server.resourcemanager.rmapp.attempt.RMAppAttemptImpl: appattempt_1399289015992_0003_000001 State change from ALLOCATED to LAUNCHED
2014-05-05 11:46:49,831 INFO org.apache.hadoop.yarn.server.resourcemanager.rmcontainer.RMContainerImpl: container_1399289015992_0003_01_000001 Container Transitioned from ACQUIRED to RUNNING
2014-05-05 11:46:56,952 INFO SecurityLogger.org.apache.hadoop.ipc.Server: Auth successful for appattempt_1399289015992_0003_000001 (auth:SIMPLE)
2014-05-05 11:46:56,961 INFO org.apache.hadoop.yarn.server.resourcemanager.ApplicationMasterService: AM registration appattempt_1399289015992_0003_000001
2014-05-05 11:46:56,961 INFO org.apache.hadoop.yarn.server.resourcemanager.RMAuditLogger: USER=ubuntu	IP=10.0.0.195	OPERATION=Register App Master	TARGET=ApplicationMasterService	RESULT=SUCCESS	APPID=application_1399289015992_0003	APPATTEMPTID=appattempt_1399289015992_0003_000001
2014-05-05 11:46:56,962 INFO org.apache.hadoop.yarn.server.resourcemanager.rmapp.attempt.RMAppAttemptImpl: appattempt_1399289015992_0003_000001 State change from LAUNCHED to RUNNING
2014-05-05 11:46:56,962 INFO org.apache.hadoop.yarn.server.resourcemanager.rmapp.RMAppImpl: application_1399289015992_0003 State change from ACCEPTED to RUNNING
2014-05-05 11:46:58,281 INFO org.apache.hadoop.yarn.server.resourcemanager.rmcontainer.RMContainerImpl: container_1399289015992_0003_01_000002 Container Transitioned from NEW to ALLOCATED
2014-05-05 11:46:58,281 INFO org.apache.hadoop.yarn.server.resourcemanager.RMAuditLogger: USER=ubuntu	OPERATION=AM Allocated Container	TARGET=SchedulerApp	RESULT=SUCCESS	APPID=application_1399289015992_0003	CONTAINERID=container_1399289015992_0003_01_000002
2014-05-05 11:46:58,281 INFO org.apache.hadoop.yarn.server.resourcemanager.scheduler.common.fica.FiCaSchedulerNode: Assigned container container_1399289015992_0003_01_000002 of capacity <memory:1024, vCores:1> on host nodeb:43052, which currently has 1 containers, <memory:1024, vCores:1> used and <memory:7168, vCores:7> available
2014-05-05 11:46:58,281 INFO org.apache.hadoop.yarn.server.resourcemanager.scheduler.capacity.LeafQueue: assignedContainer application=application_1399289015992_0003 container=Container: [ContainerId: container_1399289015992_0003_01_000002, NodeId: nodeb:43052, NodeHttpAddress: nodeb:8042, Resource: <memory:1024, vCores:1>, Priority: 20, Token: Token { kind: ContainerToken, service: 10.0.0.194:43052 }, ] containerId=container_1399289015992_0003_01_000002 queue=default: capacity=1.0, absoluteCapacity=1.0, usedResources=<memory:2048, vCores:1>usedCapacity=0.03125, absoluteUsedCapacity=0.03125, numApps=1, numContainers=1 usedCapacity=0.03125 absoluteUsedCapacity=0.03125 used=<memory:2048, vCores:1> cluster=<memory:65536, vCores:64>
2014-05-05 11:46:58,281 INFO org.apache.hadoop.yarn.server.resourcemanager.scheduler.capacity.ParentQueue: Re-sorting assigned queue: root.default stats: default: capacity=1.0, absoluteCapacity=1.0, usedResources=<memory:3072, vCores:2>usedCapacity=0.046875, absoluteUsedCapacity=0.046875, numApps=1, numContainers=2
2014-05-05 11:46:58,282 INFO org.apache.hadoop.yarn.server.resourcemanager.scheduler.capacity.ParentQueue: assignedContainer queue=root usedCapacity=0.046875 absoluteUsedCapacity=0.046875 used=<memory:3072, vCores:2> cluster=<memory:65536, vCores:64>
2014-05-05 11:46:58,282 INFO org.apache.hadoop.yarn.server.resourcemanager.rmcontainer.RMContainerImpl: container_1399289015992_0003_01_000003 Container Transitioned from NEW to ALLOCATED
2014-05-05 11:46:58,282 INFO org.apache.hadoop.yarn.server.resourcemanager.RMAuditLogger: USER=ubuntu	OPERATION=AM Allocated Container	TARGET=SchedulerApp	RESULT=SUCCESS	APPID=application_1399289015992_0003	CONTAINERID=container_1399289015992_0003_01_000003
2014-05-05 11:46:58,282 INFO org.apache.hadoop.yarn.server.resourcemanager.scheduler.common.fica.FiCaSchedulerNode: Assigned container container_1399289015992_0003_01_000003 of capacity <memory:1024, vCores:1> on host nodeb:43052, which currently has 2 containers, <memory:2048, vCores:2> used and <memory:6144, vCores:6> available
2014-05-05 11:46:58,282 INFO org.apache.hadoop.yarn.server.resourcemanager.scheduler.capacity.LeafQueue: assignedContainer application=application_1399289015992_0003 container=Container: [ContainerId: container_1399289015992_0003_01_000003, NodeId: nodeb:43052, NodeHttpAddress: nodeb:8042, Resource: <memory:1024, vCores:1>, Priority: 20, Token: Token { kind: ContainerToken, service: 10.0.0.194:43052 }, ] containerId=container_1399289015992_0003_01_000003 queue=default: capacity=1.0, absoluteCapacity=1.0, usedResources=<memory:3072, vCores:2>usedCapacity=0.046875, absoluteUsedCapacity=0.046875, numApps=1, numContainers=2 usedCapacity=0.046875 absoluteUsedCapacity=0.046875 used=<memory:3072, vCores:2> cluster=<memory:65536, vCores:64>
2014-05-05 11:46:58,282 INFO org.apache.hadoop.yarn.server.resourcemanager.scheduler.capacity.ParentQueue: Re-sorting assigned queue: root.default stats: default: capacity=1.0, absoluteCapacity=1.0, usedResources=<memory:4096, vCores:3>usedCapacity=0.0625, absoluteUsedCapacity=0.0625, numApps=1, numContainers=3
2014-05-05 11:46:58,282 INFO org.apache.hadoop.yarn.server.resourcemanager.scheduler.capacity.ParentQueue: assignedContainer queue=root usedCapacity=0.0625 absoluteUsedCapacity=0.0625 used=<memory:4096, vCores:3> cluster=<memory:65536, vCores:64>
2014-05-05 11:46:58,283 INFO org.apache.hadoop.yarn.server.resourcemanager.rmcontainer.RMContainerImpl: container_1399289015992_0003_01_000004 Container Transitioned from NEW to ALLOCATED
2014-05-05 11:46:58,283 INFO org.apache.hadoop.yarn.server.resourcemanager.RMAuditLogger: USER=ubuntu	OPERATION=AM Allocated Container	TARGET=SchedulerApp	RESULT=SUCCESS	APPID=application_1399289015992_0003	CONTAINERID=container_1399289015992_0003_01_000004
2014-05-05 11:46:58,283 INFO org.apache.hadoop.yarn.server.resourcemanager.scheduler.common.fica.FiCaSchedulerNode: Assigned container container_1399289015992_0003_01_000004 of capacity <memory:1024, vCores:1> on host nodeb:43052, which currently has 3 containers, <memory:3072, vCores:3> used and <memory:5120, vCores:5> available
2014-05-05 11:46:58,283 INFO org.apache.hadoop.yarn.server.resourcemanager.scheduler.capacity.LeafQueue: assignedContainer application=application_1399289015992_0003 container=Container: [ContainerId: container_1399289015992_0003_01_000004, NodeId: nodeb:43052, NodeHttpAddress: nodeb:8042, Resource: <memory:1024, vCores:1>, Priority: 20, Token: Token { kind: ContainerToken, service: 10.0.0.194:43052 }, ] containerId=container_1399289015992_0003_01_000004 queue=default: capacity=1.0, absoluteCapacity=1.0, usedResources=<memory:4096, vCores:3>usedCapacity=0.0625, absoluteUsedCapacity=0.0625, numApps=1, numContainers=3 usedCapacity=0.0625 absoluteUsedCapacity=0.0625 used=<memory:4096, vCores:3> cluster=<memory:65536, vCores:64>
2014-05-05 11:46:58,283 INFO org.apache.hadoop.yarn.server.resourcemanager.scheduler.capacity.ParentQueue: Re-sorting assigned queue: root.default stats: default: capacity=1.0, absoluteCapacity=1.0, usedResources=<memory:5120, vCores:4>usedCapacity=0.078125, absoluteUsedCapacity=0.078125, numApps=1, numContainers=4
2014-05-05 11:46:58,283 INFO org.apache.hadoop.yarn.server.resourcemanager.scheduler.capacity.ParentQueue: assignedContainer queue=root usedCapacity=0.078125 absoluteUsedCapacity=0.078125 used=<memory:5120, vCores:4> cluster=<memory:65536, vCores:64>
2014-05-05 11:46:58,283 INFO org.apache.hadoop.yarn.server.resourcemanager.rmcontainer.RMContainerImpl: container_1399289015992_0003_01_000005 Container Transitioned from NEW to ALLOCATED
2014-05-05 11:46:58,283 INFO org.apache.hadoop.yarn.server.resourcemanager.RMAuditLogger: USER=ubuntu	OPERATION=AM Allocated Container	TARGET=SchedulerApp	RESULT=SUCCESS	APPID=application_1399289015992_0003	CONTAINERID=container_1399289015992_0003_01_000005
2014-05-05 11:46:58,283 INFO org.apache.hadoop.yarn.server.resourcemanager.scheduler.common.fica.FiCaSchedulerNode: Assigned container container_1399289015992_0003_01_000005 of capacity <memory:1024, vCores:1> on host nodeb:43052, which currently has 4 containers, <memory:4096, vCores:4> used and <memory:4096, vCores:4> available
2014-05-05 11:46:58,284 INFO org.apache.hadoop.yarn.server.resourcemanager.scheduler.capacity.LeafQueue: assignedContainer application=application_1399289015992_0003 container=Container: [ContainerId: container_1399289015992_0003_01_000005, NodeId: nodeb:43052, NodeHttpAddress: nodeb:8042, Resource: <memory:1024, vCores:1>, Priority: 20, Token: Token { kind: ContainerToken, service: 10.0.0.194:43052 }, ] containerId=container_1399289015992_0003_01_000005 queue=default: capacity=1.0, absoluteCapacity=1.0, usedResources=<memory:5120, vCores:4>usedCapacity=0.078125, absoluteUsedCapacity=0.078125, numApps=1, numContainers=4 usedCapacity=0.078125 absoluteUsedCapacity=0.078125 used=<memory:5120, vCores:4> cluster=<memory:65536, vCores:64>
2014-05-05 11:46:58,284 INFO org.apache.hadoop.yarn.server.resourcemanager.scheduler.capacity.ParentQueue: Re-sorting assigned queue: root.default stats: default: capacity=1.0, absoluteCapacity=1.0, usedResources=<memory:6144, vCores:5>usedCapacity=0.09375, absoluteUsedCapacity=0.09375, numApps=1, numContainers=5
2014-05-05 11:46:58,284 INFO org.apache.hadoop.yarn.server.resourcemanager.scheduler.capacity.ParentQueue: assignedContainer queue=root usedCapacity=0.09375 absoluteUsedCapacity=0.09375 used=<memory:6144, vCores:5> cluster=<memory:65536, vCores:64>
2014-05-05 11:46:59,124 INFO org.apache.hadoop.yarn.server.resourcemanager.rmcontainer.RMContainerImpl: container_1399289015992_0003_01_000002 Container Transitioned from ALLOCATED to ACQUIRED
2014-05-05 11:46:59,124 INFO org.apache.hadoop.yarn.server.resourcemanager.rmcontainer.RMContainerImpl: container_1399289015992_0003_01_000003 Container Transitioned from ALLOCATED to ACQUIRED
2014-05-05 11:46:59,124 INFO org.apache.hadoop.yarn.server.resourcemanager.rmcontainer.RMContainerImpl: container_1399289015992_0003_01_000004 Container Transitioned from ALLOCATED to ACQUIRED
2014-05-05 11:46:59,124 INFO org.apache.hadoop.yarn.server.resourcemanager.rmcontainer.RMContainerImpl: container_1399289015992_0003_01_000005 Container Transitioned from ALLOCATED to ACQUIRED
2014-05-05 11:47:00,139 INFO org.apache.hadoop.yarn.server.resourcemanager.scheduler.AppSchedulingInfo: checking for deactivate... 
2014-05-05 11:47:00,326 INFO org.apache.hadoop.yarn.server.resourcemanager.rmcontainer.RMContainerImpl: container_1399289015992_0003_01_000002 Container Transitioned from ACQUIRED to RUNNING
2014-05-05 11:47:00,326 INFO org.apache.hadoop.yarn.server.resourcemanager.rmcontainer.RMContainerImpl: container_1399289015992_0003_01_000003 Container Transitioned from ACQUIRED to RUNNING
2014-05-05 11:47:00,326 INFO org.apache.hadoop.yarn.server.resourcemanager.rmcontainer.RMContainerImpl: container_1399289015992_0003_01_000004 Container Transitioned from ACQUIRED to RUNNING
2014-05-05 11:47:00,326 INFO org.apache.hadoop.yarn.server.resourcemanager.rmcontainer.RMContainerImpl: container_1399289015992_0003_01_000005 Container Transitioned from ACQUIRED to RUNNING
2014-05-05 11:47:30,361 INFO org.apache.hadoop.yarn.server.resourcemanager.rmcontainer.RMContainerImpl: container_1399289015992_0003_01_000006 Container Transitioned from NEW to ALLOCATED
2014-05-05 11:47:30,362 INFO org.apache.hadoop.yarn.server.resourcemanager.RMAuditLogger: USER=ubuntu	OPERATION=AM Allocated Container	TARGET=SchedulerApp	RESULT=SUCCESS	APPID=application_1399289015992_0003	CONTAINERID=container_1399289015992_0003_01_000006
2014-05-05 11:47:30,362 INFO org.apache.hadoop.yarn.server.resourcemanager.scheduler.common.fica.FiCaSchedulerNode: Assigned container container_1399289015992_0003_01_000006 of capacity <memory:1024, vCores:1> on host ip-10-0-0-197.us-west-2.compute.internal:36720, which currently has 1 containers, <memory:1024, vCores:1> used and <memory:7168, vCores:7> available
2014-05-05 11:47:30,362 INFO org.apache.hadoop.yarn.server.resourcemanager.scheduler.capacity.LeafQueue: assignedContainer application=application_1399289015992_0003 container=Container: [ContainerId: container_1399289015992_0003_01_000006, NodeId: ip-10-0-0-197.us-west-2.compute.internal:36720, NodeHttpAddress: ip-10-0-0-197.us-west-2.compute.internal:8042, Resource: <memory:1024, vCores:1>, Priority: 20, Token: Token { kind: ContainerToken, service: 10.0.0.197:36720 }, ] containerId=container_1399289015992_0003_01_000006 queue=default: capacity=1.0, absoluteCapacity=1.0, usedResources=<memory:6144, vCores:5>usedCapacity=0.09375, absoluteUsedCapacity=0.09375, numApps=1, numContainers=5 usedCapacity=0.09375 absoluteUsedCapacity=0.09375 used=<memory:6144, vCores:5> cluster=<memory:65536, vCores:64>
2014-05-05 11:47:30,362 INFO org.apache.hadoop.yarn.server.resourcemanager.scheduler.capacity.ParentQueue: Re-sorting assigned queue: root.default stats: default: capacity=1.0, absoluteCapacity=1.0, usedResources=<memory:7168, vCores:6>usedCapacity=0.109375, absoluteUsedCapacity=0.109375, numApps=1, numContainers=6
2014-05-05 11:47:30,362 INFO org.apache.hadoop.yarn.server.resourcemanager.scheduler.capacity.ParentQueue: assignedContainer queue=root usedCapacity=0.109375 absoluteUsedCapacity=0.109375 used=<memory:7168, vCores:6> cluster=<memory:65536, vCores:64>
2014-05-05 11:47:30,596 INFO org.apache.hadoop.yarn.server.resourcemanager.rmcontainer.RMContainerImpl: container_1399289015992_0003_01_000005 Container Transitioned from RUNNING to COMPLETED
2014-05-05 11:47:30,596 INFO org.apache.hadoop.yarn.server.resourcemanager.scheduler.common.fica.FiCaSchedulerApp: Completed container: container_1399289015992_0003_01_000005 in state: COMPLETED event:FINISHED
2014-05-05 11:47:30,596 INFO org.apache.hadoop.yarn.server.resourcemanager.RMAuditLogger: USER=ubuntu	OPERATION=AM Released Container	TARGET=SchedulerApp	RESULT=SUCCESS	APPID=application_1399289015992_0003	CONTAINERID=container_1399289015992_0003_01_000005
2014-05-05 11:47:30,596 INFO org.apache.hadoop.yarn.server.resourcemanager.scheduler.common.fica.FiCaSchedulerNode: Released container container_1399289015992_0003_01_000005 of capacity <memory:1024, vCores:1> on host nodeb:43052, which currently has 3 containers, <memory:3072, vCores:3> used and <memory:5120, vCores:5> available, release resources=true
2014-05-05 11:47:30,596 INFO org.apache.hadoop.yarn.server.resourcemanager.scheduler.capacity.LeafQueue: default used=<memory:6144, vCores:5> numContainers=5 user=ubuntu user-resources=<memory:6144, vCores:5>
2014-05-05 11:47:30,597 INFO org.apache.hadoop.yarn.server.resourcemanager.scheduler.capacity.LeafQueue: completedContainer container=Container: [ContainerId: container_1399289015992_0003_01_000005, NodeId: nodeb:43052, NodeHttpAddress: nodeb:8042, Resource: <memory:1024, vCores:1>, Priority: 20, Token: Token { kind: ContainerToken, service: 10.0.0.194:43052 }, ] resource=<memory:1024, vCores:1> queue=default: capacity=1.0, absoluteCapacity=1.0, usedResources=<memory:6144, vCores:5>usedCapacity=0.09375, absoluteUsedCapacity=0.09375, numApps=1, numContainers=5 usedCapacity=0.09375 absoluteUsedCapacity=0.09375 used=<memory:6144, vCores:5> cluster=<memory:65536, vCores:64>
2014-05-05 11:47:30,597 INFO org.apache.hadoop.yarn.server.resourcemanager.scheduler.capacity.ParentQueue: completedContainer queue=root usedCapacity=0.09375 absoluteUsedCapacity=0.09375 used=<memory:6144, vCores:5> cluster=<memory:65536, vCores:64>
2014-05-05 11:47:30,597 INFO org.apache.hadoop.yarn.server.resourcemanager.scheduler.capacity.ParentQueue: Re-sorting completed queue: root.default stats: default: capacity=1.0, absoluteCapacity=1.0, usedResources=<memory:6144, vCores:5>usedCapacity=0.09375, absoluteUsedCapacity=0.09375, numApps=1, numContainers=5
2014-05-05 11:47:30,597 INFO org.apache.hadoop.yarn.server.resourcemanager.scheduler.capacity.CapacityScheduler: Application appattempt_1399289015992_0003_000001 released container container_1399289015992_0003_01_000005 on node: host: nodeb:43052 #containers=3 available=5120 used=3072 with event: FINISHED
2014-05-05 11:47:31,198 INFO org.apache.hadoop.yarn.server.resourcemanager.rmcontainer.RMContainerImpl: container_1399289015992_0003_01_000006 Container Transitioned from ALLOCATED to ACQUIRED
2014-05-05 11:47:31,292 INFO org.apache.hadoop.yarn.server.resourcemanager.rmcontainer.RMContainerImpl: container_1399289015992_0003_01_000007 Container Transitioned from NEW to ALLOCATED
2014-05-05 11:47:31,292 INFO org.apache.hadoop.yarn.server.resourcemanager.RMAuditLogger: USER=ubuntu	OPERATION=AM Allocated Container	TARGET=SchedulerApp	RESULT=SUCCESS	APPID=application_1399289015992_0003	CONTAINERID=container_1399289015992_0003_01_000007
2014-05-05 11:47:31,292 INFO org.apache.hadoop.yarn.server.resourcemanager.scheduler.common.fica.FiCaSchedulerNode: Assigned container container_1399289015992_0003_01_000007 of capacity <memory:1024, vCores:1> on host nodea:34521, which currently has 2 containers, <memory:3072, vCores:2> used and <memory:5120, vCores:6> available
2014-05-05 11:47:31,292 INFO org.apache.hadoop.yarn.server.resourcemanager.scheduler.capacity.LeafQueue: assignedContainer application=application_1399289015992_0003 container=Container: [ContainerId: container_1399289015992_0003_01_000007, NodeId: nodea:34521, NodeHttpAddress: nodea:8042, Resource: <memory:1024, vCores:1>, Priority: 10, Token: Token { kind: ContainerToken, service: 10.0.0.195:34521 }, ] containerId=container_1399289015992_0003_01_000007 queue=default: capacity=1.0, absoluteCapacity=1.0, usedResources=<memory:6144, vCores:5>usedCapacity=0.09375, absoluteUsedCapacity=0.09375, numApps=1, numContainers=5 usedCapacity=0.09375 absoluteUsedCapacity=0.09375 used=<memory:6144, vCores:5> cluster=<memory:65536, vCores:64>
2014-05-05 11:47:31,292 INFO org.apache.hadoop.yarn.server.resourcemanager.scheduler.capacity.ParentQueue: Re-sorting assigned queue: root.default stats: default: capacity=1.0, absoluteCapacity=1.0, usedResources=<memory:7168, vCores:6>usedCapacity=0.109375, absoluteUsedCapacity=0.109375, numApps=1, numContainers=6
2014-05-05 11:47:31,292 INFO org.apache.hadoop.yarn.server.resourcemanager.scheduler.capacity.ParentQueue: assignedContainer queue=root usedCapacity=0.109375 absoluteUsedCapacity=0.109375 used=<memory:7168, vCores:6> cluster=<memory:65536, vCores:64>
2014-05-05 11:47:31,363 INFO org.apache.hadoop.yarn.server.resourcemanager.rmcontainer.RMContainerImpl: container_1399289015992_0003_01_000006 Container Transitioned from ACQUIRED to RUNNING
2014-05-05 11:47:31,603 INFO org.apache.hadoop.yarn.server.resourcemanager.rmcontainer.RMContainerImpl: container_1399289015992_0003_01_000008 Container Transitioned from NEW to ALLOCATED
2014-05-05 11:47:31,603 INFO org.apache.hadoop.yarn.server.resourcemanager.RMAuditLogger: USER=ubuntu	OPERATION=AM Allocated Container	TARGET=SchedulerApp	RESULT=SUCCESS	APPID=application_1399289015992_0003	CONTAINERID=container_1399289015992_0003_01_000008
2014-05-05 11:47:31,603 INFO org.apache.hadoop.yarn.server.resourcemanager.scheduler.common.fica.FiCaSchedulerNode: Assigned container container_1399289015992_0003_01_000008 of capacity <memory:1024, vCores:1> on host nodeb:43052, which currently has 4 containers, <memory:4096, vCores:4> used and <memory:4096, vCores:4> available
2014-05-05 11:47:31,603 INFO org.apache.hadoop.yarn.server.resourcemanager.scheduler.capacity.LeafQueue: assignedContainer application=application_1399289015992_0003 container=Container: [ContainerId: container_1399289015992_0003_01_000008, NodeId: nodeb:43052, NodeHttpAddress: nodeb:8042, Resource: <memory:1024, vCores:1>, Priority: 10, Token: Token { kind: ContainerToken, service: 10.0.0.194:43052 }, ] containerId=container_1399289015992_0003_01_000008 queue=default: capacity=1.0, absoluteCapacity=1.0, usedResources=<memory:7168, vCores:6>usedCapacity=0.109375, absoluteUsedCapacity=0.109375, numApps=1, numContainers=6 usedCapacity=0.109375 absoluteUsedCapacity=0.109375 used=<memory:7168, vCores:6> cluster=<memory:65536, vCores:64>
2014-05-05 11:47:31,603 INFO org.apache.hadoop.yarn.server.resourcemanager.scheduler.capacity.ParentQueue: Re-sorting assigned queue: root.default stats: default: capacity=1.0, absoluteCapacity=1.0, usedResources=<memory:8192, vCores:7>usedCapacity=0.125, absoluteUsedCapacity=0.125, numApps=1, numContainers=7
2014-05-05 11:47:31,603 INFO org.apache.hadoop.yarn.server.resourcemanager.scheduler.capacity.ParentQueue: assignedContainer queue=root usedCapacity=0.125 absoluteUsedCapacity=0.125 used=<memory:8192, vCores:7> cluster=<memory:65536, vCores:64>
2014-05-05 11:47:32,205 INFO org.apache.hadoop.yarn.server.resourcemanager.scheduler.AppSchedulingInfo: checking for deactivate... 
2014-05-05 11:47:32,206 INFO org.apache.hadoop.yarn.server.resourcemanager.rmcontainer.RMContainerImpl: container_1399289015992_0003_01_000007 Container Transitioned from ALLOCATED to ACQUIRED
2014-05-05 11:47:32,206 INFO org.apache.hadoop.yarn.server.resourcemanager.rmcontainer.RMContainerImpl: container_1399289015992_0003_01_000008 Container Transitioned from ALLOCATED to ACQUIRED
2014-05-05 11:47:32,293 INFO org.apache.hadoop.yarn.server.resourcemanager.rmcontainer.RMContainerImpl: container_1399289015992_0003_01_000007 Container Transitioned from ACQUIRED to RUNNING
2014-05-05 11:47:32,606 INFO org.apache.hadoop.yarn.server.resourcemanager.rmcontainer.RMContainerImpl: container_1399289015992_0003_01_000008 Container Transitioned from ACQUIRED to RUNNING
2014-05-05 11:47:41,365 INFO org.apache.hadoop.yarn.server.resourcemanager.rmcontainer.RMContainerImpl: container_1399289015992_0003_01_000002 Container Transitioned from RUNNING to COMPLETED
2014-05-05 11:47:41,365 INFO org.apache.hadoop.yarn.server.resourcemanager.scheduler.common.fica.FiCaSchedulerApp: Completed container: container_1399289015992_0003_01_000002 in state: COMPLETED event:FINISHED
2014-05-05 11:47:41,366 INFO org.apache.hadoop.yarn.server.resourcemanager.RMAuditLogger: USER=ubuntu	OPERATION=AM Released Container	TARGET=SchedulerApp	RESULT=SUCCESS	APPID=application_1399289015992_0003	CONTAINERID=container_1399289015992_0003_01_000002
2014-05-05 11:47:41,366 INFO org.apache.hadoop.yarn.server.resourcemanager.scheduler.common.fica.FiCaSchedulerNode: Released container container_1399289015992_0003_01_000002 of capacity <memory:1024, vCores:1> on host nodeb:43052, which currently has 3 containers, <memory:3072, vCores:3> used and <memory:5120, vCores:5> available, release resources=true
2014-05-05 11:47:41,366 INFO org.apache.hadoop.yarn.server.resourcemanager.scheduler.capacity.LeafQueue: default used=<memory:7168, vCores:6> numContainers=6 user=ubuntu user-resources=<memory:7168, vCores:6>
2014-05-05 11:47:41,366 INFO org.apache.hadoop.yarn.server.resourcemanager.scheduler.capacity.LeafQueue: completedContainer container=Container: [ContainerId: container_1399289015992_0003_01_000002, NodeId: nodeb:43052, NodeHttpAddress: nodeb:8042, Resource: <memory:1024, vCores:1>, Priority: 20, Token: Token { kind: ContainerToken, service: 10.0.0.194:43052 }, ] resource=<memory:1024, vCores:1> queue=default: capacity=1.0, absoluteCapacity=1.0, usedResources=<memory:7168, vCores:6>usedCapacity=0.109375, absoluteUsedCapacity=0.109375, numApps=1, numContainers=6 usedCapacity=0.109375 absoluteUsedCapacity=0.109375 used=<memory:7168, vCores:6> cluster=<memory:65536, vCores:64>
2014-05-05 11:47:41,366 INFO org.apache.hadoop.yarn.server.resourcemanager.scheduler.capacity.ParentQueue: completedContainer queue=root usedCapacity=0.109375 absoluteUsedCapacity=0.109375 used=<memory:7168, vCores:6> cluster=<memory:65536, vCores:64>
2014-05-05 11:47:41,366 INFO org.apache.hadoop.yarn.server.resourcemanager.scheduler.capacity.ParentQueue: Re-sorting completed queue: root.default stats: default: capacity=1.0, absoluteCapacity=1.0, usedResources=<memory:7168, vCores:6>usedCapacity=0.109375, absoluteUsedCapacity=0.109375, numApps=1, numContainers=6
2014-05-05 11:47:41,366 INFO org.apache.hadoop.yarn.server.resourcemanager.scheduler.capacity.CapacityScheduler: Application appattempt_1399289015992_0003_000001 released container container_1399289015992_0003_01_000002 on node: host: nodeb:43052 #containers=3 available=5120 used=3072 with event: FINISHED
2014-05-05 11:47:41,371 INFO org.apache.hadoop.yarn.server.resourcemanager.rmcontainer.RMContainerImpl: container_1399289015992_0003_01_000006 Container Transitioned from RUNNING to COMPLETED
2014-05-05 11:47:41,371 INFO org.apache.hadoop.yarn.server.resourcemanager.scheduler.common.fica.FiCaSchedulerApp: Completed container: container_1399289015992_0003_01_000006 in state: COMPLETED event:FINISHED
2014-05-05 11:47:41,371 INFO org.apache.hadoop.yarn.server.resourcemanager.RMAuditLogger: USER=ubuntu	OPERATION=AM Released Container	TARGET=SchedulerApp	RESULT=SUCCESS	APPID=application_1399289015992_0003	CONTAINERID=container_1399289015992_0003_01_000006
2014-05-05 11:47:41,371 INFO org.apache.hadoop.yarn.server.resourcemanager.scheduler.common.fica.FiCaSchedulerNode: Released container container_1399289015992_0003_01_000006 of capacity <memory:1024, vCores:1> on host ip-10-0-0-197.us-west-2.compute.internal:36720, which currently has 0 containers, <memory:0, vCores:0> used and <memory:8192, vCores:8> available, release resources=true
2014-05-05 11:47:41,371 INFO org.apache.hadoop.yarn.server.resourcemanager.scheduler.capacity.LeafQueue: default used=<memory:6144, vCores:5> numContainers=5 user=ubuntu user-resources=<memory:6144, vCores:5>
2014-05-05 11:47:41,371 INFO org.apache.hadoop.yarn.server.resourcemanager.scheduler.capacity.LeafQueue: completedContainer container=Container: [ContainerId: container_1399289015992_0003_01_000006, NodeId: ip-10-0-0-197.us-west-2.compute.internal:36720, NodeHttpAddress: ip-10-0-0-197.us-west-2.compute.internal:8042, Resource: <memory:1024, vCores:1>, Priority: 20, Token: Token { kind: ContainerToken, service: 10.0.0.197:36720 }, ] resource=<memory:1024, vCores:1> queue=default: capacity=1.0, absoluteCapacity=1.0, usedResources=<memory:6144, vCores:5>usedCapacity=0.09375, absoluteUsedCapacity=0.09375, numApps=1, numContainers=5 usedCapacity=0.09375 absoluteUsedCapacity=0.09375 used=<memory:6144, vCores:5> cluster=<memory:65536, vCores:64>
2014-05-05 11:47:41,371 INFO org.apache.hadoop.yarn.server.resourcemanager.scheduler.capacity.ParentQueue: completedContainer queue=root usedCapacity=0.09375 absoluteUsedCapacity=0.09375 used=<memory:6144, vCores:5> cluster=<memory:65536, vCores:64>
2014-05-05 11:47:41,371 INFO org.apache.hadoop.yarn.server.resourcemanager.scheduler.capacity.ParentQueue: Re-sorting completed queue: root.default stats: default: capacity=1.0, absoluteCapacity=1.0, usedResources=<memory:6144, vCores:5>usedCapacity=0.09375, absoluteUsedCapacity=0.09375, numApps=1, numContainers=5
2014-05-05 11:47:41,371 INFO org.apache.hadoop.yarn.server.resourcemanager.scheduler.capacity.CapacityScheduler: Application appattempt_1399289015992_0003_000001 released container container_1399289015992_0003_01_000006 on node: host: ip-10-0-0-197.us-west-2.compute.internal:36720 #containers=0 available=8192 used=0 with event: FINISHED
2014-05-05 11:47:42,303 INFO org.apache.hadoop.yarn.server.resourcemanager.rmcontainer.RMContainerImpl: container_1399289015992_0003_01_000003 Container Transitioned from RUNNING to COMPLETED
2014-05-05 11:47:42,303 INFO org.apache.hadoop.yarn.server.resourcemanager.scheduler.common.fica.FiCaSchedulerApp: Completed container: container_1399289015992_0003_01_000003 in state: COMPLETED event:FINISHED
2014-05-05 11:47:42,303 INFO org.apache.hadoop.yarn.server.resourcemanager.RMAuditLogger: USER=ubuntu	OPERATION=AM Released Container	TARGET=SchedulerApp	RESULT=SUCCESS	APPID=application_1399289015992_0003	CONTAINERID=container_1399289015992_0003_01_000003
2014-05-05 11:47:42,303 INFO org.apache.hadoop.yarn.server.resourcemanager.scheduler.common.fica.FiCaSchedulerNode: Released container container_1399289015992_0003_01_000003 of capacity <memory:1024, vCores:1> on host nodeb:43052, which currently has 2 containers, <memory:2048, vCores:2> used and <memory:6144, vCores:6> available, release resources=true
2014-05-05 11:47:42,303 INFO org.apache.hadoop.yarn.server.resourcemanager.scheduler.capacity.LeafQueue: default used=<memory:5120, vCores:4> numContainers=4 user=ubuntu user-resources=<memory:5120, vCores:4>
2014-05-05 11:47:42,303 INFO org.apache.hadoop.yarn.server.resourcemanager.scheduler.capacity.LeafQueue: completedContainer container=Container: [ContainerId: container_1399289015992_0003_01_000003, NodeId: nodeb:43052, NodeHttpAddress: nodeb:8042, Resource: <memory:1024, vCores:1>, Priority: 20, Token: Token { kind: ContainerToken, service: 10.0.0.194:43052 }, ] resource=<memory:1024, vCores:1> queue=default: capacity=1.0, absoluteCapacity=1.0, usedResources=<memory:5120, vCores:4>usedCapacity=0.078125, absoluteUsedCapacity=0.078125, numApps=1, numContainers=4 usedCapacity=0.078125 absoluteUsedCapacity=0.078125 used=<memory:5120, vCores:4> cluster=<memory:65536, vCores:64>
2014-05-05 11:47:42,303 INFO org.apache.hadoop.yarn.server.resourcemanager.scheduler.capacity.ParentQueue: completedContainer queue=root usedCapacity=0.078125 absoluteUsedCapacity=0.078125 used=<memory:5120, vCores:4> cluster=<memory:65536, vCores:64>
2014-05-05 11:47:42,303 INFO org.apache.hadoop.yarn.server.resourcemanager.scheduler.capacity.ParentQueue: Re-sorting completed queue: root.default stats: default: capacity=1.0, absoluteCapacity=1.0, usedResources=<memory:5120, vCores:4>usedCapacity=0.078125, absoluteUsedCapacity=0.078125, numApps=1, numContainers=4
2014-05-05 11:47:42,304 INFO org.apache.hadoop.yarn.server.resourcemanager.scheduler.capacity.CapacityScheduler: Application appattempt_1399289015992_0003_000001 released container container_1399289015992_0003_01_000003 on node: host: nodeb:43052 #containers=2 available=6144 used=2048 with event: FINISHED
2014-05-05 11:47:43,305 INFO org.apache.hadoop.yarn.server.resourcemanager.rmcontainer.RMContainerImpl: container_1399289015992_0003_01_000004 Container Transitioned from RUNNING to COMPLETED
2014-05-05 11:47:43,305 INFO org.apache.hadoop.yarn.server.resourcemanager.scheduler.common.fica.FiCaSchedulerApp: Completed container: container_1399289015992_0003_01_000004 in state: COMPLETED event:FINISHED
2014-05-05 11:47:43,305 INFO org.apache.hadoop.yarn.server.resourcemanager.RMAuditLogger: USER=ubuntu	OPERATION=AM Released Container	TARGET=SchedulerApp	RESULT=SUCCESS	APPID=application_1399289015992_0003	CONTAINERID=container_1399289015992_0003_01_000004
2014-05-05 11:47:43,305 INFO org.apache.hadoop.yarn.server.resourcemanager.scheduler.common.fica.FiCaSchedulerNode: Released container container_1399289015992_0003_01_000004 of capacity <memory:1024, vCores:1> on host nodeb:43052, which currently has 1 containers, <memory:1024, vCores:1> used and <memory:7168, vCores:7> available, release resources=true
2014-05-05 11:47:43,305 INFO org.apache.hadoop.yarn.server.resourcemanager.scheduler.capacity.LeafQueue: default used=<memory:4096, vCores:3> numContainers=3 user=ubuntu user-resources=<memory:4096, vCores:3>
2014-05-05 11:47:43,305 INFO org.apache.hadoop.yarn.server.resourcemanager.scheduler.capacity.LeafQueue: completedContainer container=Container: [ContainerId: container_1399289015992_0003_01_000004, NodeId: nodeb:43052, NodeHttpAddress: nodeb:8042, Resource: <memory:1024, vCores:1>, Priority: 20, Token: Token { kind: ContainerToken, service: 10.0.0.194:43052 }, ] resource=<memory:1024, vCores:1> queue=default: capacity=1.0, absoluteCapacity=1.0, usedResources=<memory:4096, vCores:3>usedCapacity=0.0625, absoluteUsedCapacity=0.0625, numApps=1, numContainers=3 usedCapacity=0.0625 absoluteUsedCapacity=0.0625 used=<memory:4096, vCores:3> cluster=<memory:65536, vCores:64>
2014-05-05 11:47:43,305 INFO org.apache.hadoop.yarn.server.resourcemanager.scheduler.capacity.ParentQueue: completedContainer queue=root usedCapacity=0.0625 absoluteUsedCapacity=0.0625 used=<memory:4096, vCores:3> cluster=<memory:65536, vCores:64>
2014-05-05 11:47:43,306 INFO org.apache.hadoop.yarn.server.resourcemanager.scheduler.capacity.ParentQueue: Re-sorting completed queue: root.default stats: default: capacity=1.0, absoluteCapacity=1.0, usedResources=<memory:4096, vCores:3>usedCapacity=0.0625, absoluteUsedCapacity=0.0625, numApps=1, numContainers=3
2014-05-05 11:47:43,306 INFO org.apache.hadoop.yarn.server.resourcemanager.scheduler.capacity.CapacityScheduler: Application appattempt_1399289015992_0003_000001 released container container_1399289015992_0003_01_000004 on node: host: nodeb:43052 #containers=1 available=7168 used=1024 with event: FINISHED
2014-05-05 11:48:02,261 INFO org.apache.hadoop.yarn.server.resourcemanager.rmcontainer.RMContainerImpl: container_1399289015992_0003_01_000007 Container Transitioned from RUNNING to COMPLETED
2014-05-05 11:48:02,261 INFO org.apache.hadoop.yarn.server.resourcemanager.scheduler.common.fica.FiCaSchedulerApp: Completed container: container_1399289015992_0003_01_000007 in state: COMPLETED event:FINISHED
2014-05-05 11:48:02,261 INFO org.apache.hadoop.yarn.server.resourcemanager.RMAuditLogger: USER=ubuntu	OPERATION=AM Released Container	TARGET=SchedulerApp	RESULT=SUCCESS	APPID=application_1399289015992_0003	CONTAINERID=container_1399289015992_0003_01_000007
2014-05-05 11:48:02,261 INFO org.apache.hadoop.yarn.server.resourcemanager.scheduler.common.fica.FiCaSchedulerNode: Released container container_1399289015992_0003_01_000007 of capacity <memory:1024, vCores:1> on host nodea:34521, which currently has 1 containers, <memory:2048, vCores:1> used and <memory:6144, vCores:7> available, release resources=true
2014-05-05 11:48:02,262 INFO org.apache.hadoop.yarn.server.resourcemanager.scheduler.capacity.LeafQueue: default used=<memory:3072, vCores:2> numContainers=2 user=ubuntu user-resources=<memory:3072, vCores:2>
2014-05-05 11:48:02,262 INFO org.apache.hadoop.yarn.server.resourcemanager.scheduler.capacity.LeafQueue: completedContainer container=Container: [ContainerId: container_1399289015992_0003_01_000007, NodeId: nodea:34521, NodeHttpAddress: nodea:8042, Resource: <memory:1024, vCores:1>, Priority: 10, Token: Token { kind: ContainerToken, service: 10.0.0.195:34521 }, ] resource=<memory:1024, vCores:1> queue=default: capacity=1.0, absoluteCapacity=1.0, usedResources=<memory:3072, vCores:2>usedCapacity=0.046875, absoluteUsedCapacity=0.046875, numApps=1, numContainers=2 usedCapacity=0.046875 absoluteUsedCapacity=0.046875 used=<memory:3072, vCores:2> cluster=<memory:65536, vCores:64>
2014-05-05 11:48:02,262 INFO org.apache.hadoop.yarn.server.resourcemanager.scheduler.capacity.ParentQueue: completedContainer queue=root usedCapacity=0.046875 absoluteUsedCapacity=0.046875 used=<memory:3072, vCores:2> cluster=<memory:65536, vCores:64>
2014-05-05 11:48:02,262 INFO org.apache.hadoop.yarn.server.resourcemanager.scheduler.capacity.ParentQueue: Re-sorting completed queue: root.default stats: default: capacity=1.0, absoluteCapacity=1.0, usedResources=<memory:3072, vCores:2>usedCapacity=0.046875, absoluteUsedCapacity=0.046875, numApps=1, numContainers=2
2014-05-05 11:48:02,262 INFO org.apache.hadoop.yarn.server.resourcemanager.scheduler.capacity.CapacityScheduler: Application appattempt_1399289015992_0003_000001 released container container_1399289015992_0003_01_000007 on node: host: nodea:34521 #containers=1 available=6144 used=2048 with event: FINISHED
2014-05-05 11:48:04,632 INFO org.apache.hadoop.yarn.server.resourcemanager.rmcontainer.RMContainerImpl: container_1399289015992_0003_01_000008 Container Transitioned from RUNNING to COMPLETED
2014-05-05 11:48:04,632 INFO org.apache.hadoop.yarn.server.resourcemanager.scheduler.common.fica.FiCaSchedulerApp: Completed container: container_1399289015992_0003_01_000008 in state: COMPLETED event:FINISHED
2014-05-05 11:48:04,632 INFO org.apache.hadoop.yarn.server.resourcemanager.RMAuditLogger: USER=ubuntu	OPERATION=AM Released Container	TARGET=SchedulerApp	RESULT=SUCCESS	APPID=application_1399289015992_0003	CONTAINERID=container_1399289015992_0003_01_000008
2014-05-05 11:48:04,632 INFO org.apache.hadoop.yarn.server.resourcemanager.scheduler.common.fica.FiCaSchedulerNode: Released container container_1399289015992_0003_01_000008 of capacity <memory:1024, vCores:1> on host nodeb:43052, which currently has 0 containers, <memory:0, vCores:0> used and <memory:8192, vCores:8> available, release resources=true
2014-05-05 11:48:04,632 INFO org.apache.hadoop.yarn.server.resourcemanager.scheduler.capacity.LeafQueue: default used=<memory:2048, vCores:1> numContainers=1 user=ubuntu user-resources=<memory:2048, vCores:1>
2014-05-05 11:48:04,632 INFO org.apache.hadoop.yarn.server.resourcemanager.scheduler.capacity.LeafQueue: completedContainer container=Container: [ContainerId: container_1399289015992_0003_01_000008, NodeId: nodeb:43052, NodeHttpAddress: nodeb:8042, Resource: <memory:1024, vCores:1>, Priority: 10, Token: Token { kind: ContainerToken, service: 10.0.0.194:43052 }, ] resource=<memory:1024, vCores:1> queue=default: capacity=1.0, absoluteCapacity=1.0, usedResources=<memory:2048, vCores:1>usedCapacity=0.03125, absoluteUsedCapacity=0.03125, numApps=1, numContainers=1 usedCapacity=0.03125 absoluteUsedCapacity=0.03125 used=<memory:2048, vCores:1> cluster=<memory:65536, vCores:64>
2014-05-05 11:48:04,632 INFO org.apache.hadoop.yarn.server.resourcemanager.scheduler.capacity.ParentQueue: completedContainer queue=root usedCapacity=0.03125 absoluteUsedCapacity=0.03125 used=<memory:2048, vCores:1> cluster=<memory:65536, vCores:64>
2014-05-05 11:48:04,632 INFO org.apache.hadoop.yarn.server.resourcemanager.scheduler.capacity.ParentQueue: Re-sorting completed queue: root.default stats: default: capacity=1.0, absoluteCapacity=1.0, usedResources=<memory:2048, vCores:1>usedCapacity=0.03125, absoluteUsedCapacity=0.03125, numApps=1, numContainers=1
2014-05-05 11:48:04,633 INFO org.apache.hadoop.yarn.server.resourcemanager.scheduler.capacity.CapacityScheduler: Application appattempt_1399289015992_0003_000001 released container container_1399289015992_0003_01_000008 on node: host: nodeb:43052 #containers=0 available=8192 used=0 with event: FINISHED
2014-05-05 11:48:07,429 INFO org.apache.hadoop.yarn.server.webproxy.WebAppProxyServlet: dr.who is accessing unchecked http://ip-10-0-0-195:36093/ which is the app master GUI of application_1399289015992_0003 owned by ubuntu
2014-05-05 11:48:08,346 INFO org.apache.hadoop.yarn.server.webproxy.WebAppProxyServlet: dr.who is accessing unchecked http://ip-10-0-0-195:36093/ which is the app master GUI of application_1399289015992_0003 owned by ubuntu
2014-05-05 11:48:08,946 INFO org.apache.hadoop.yarn.server.webproxy.WebAppProxyServlet: dr.who is accessing unchecked http://ip-10-0-0-195:36093/static/yarn.css which is the app master GUI of application_1399289015992_0003 owned by ubuntu
2014-05-05 11:48:08,946 INFO org.apache.hadoop.yarn.server.webproxy.WebAppProxyServlet: dr.who is accessing unchecked http://ip-10-0-0-195:36093/static/jquery/themes-1.9.1/base/jquery-ui.css which is the app master GUI of application_1399289015992_0003 owned by ubuntu
2014-05-05 11:48:08,948 INFO org.apache.hadoop.yarn.server.webproxy.WebAppProxyServlet: dr.who is accessing unchecked http://ip-10-0-0-195:36093/static/dt-1.9.4/css/jui-dt.css which is the app master GUI of application_1399289015992_0003 owned by ubuntu
2014-05-05 11:48:08,949 INFO org.apache.hadoop.yarn.server.webproxy.WebAppProxyServlet: dr.who is accessing unchecked http://ip-10-0-0-195:36093/static/jquery/jquery-ui-1.9.1.custom.min.js which is the app master GUI of application_1399289015992_0003 owned by ubuntu
2014-05-05 11:48:08,951 INFO org.apache.hadoop.yarn.server.webproxy.WebAppProxyServlet: dr.who is accessing unchecked http://ip-10-0-0-195:36093/static/jquery/jquery-1.8.2.min.js which is the app master GUI of application_1399289015992_0003 owned by ubuntu
2014-05-05 11:48:09,011 INFO org.apache.hadoop.yarn.server.webproxy.WebAppProxyServlet: dr.who is accessing unchecked http://ip-10-0-0-195:36093/static/dt-1.9.4/js/jquery.dataTables.min.js which is the app master GUI of application_1399289015992_0003 owned by ubuntu
2014-05-05 11:48:09,037 INFO org.apache.hadoop.yarn.server.webproxy.WebAppProxyServlet: dr.who is accessing unchecked http://ip-10-0-0-195:36093/static/yarn.dt.plugins.js which is the app master GUI of application_1399289015992_0003 owned by ubuntu
2014-05-05 11:48:09,359 INFO org.apache.hadoop.yarn.server.webproxy.WebAppProxyServlet: dr.who is accessing unchecked http://ip-10-0-0-195:36093/static/jquery/themes-1.9.1/base/images/ui-bg_glass_95_fef1ec_1x400.png which is the app master GUI of application_1399289015992_0003 owned by ubuntu
2014-05-05 11:48:09,360 INFO org.apache.hadoop.yarn.server.webproxy.WebAppProxyServlet: dr.who is accessing unchecked http://ip-10-0-0-195:36093/static/jquery/themes-1.9.1/base/images/ui-bg_highlight-soft_75_cccccc_1x100.png which is the app master GUI of application_1399289015992_0003 owned by ubuntu
2014-05-05 11:48:09,361 INFO org.apache.hadoop.yarn.server.webproxy.WebAppProxyServlet: dr.who is accessing unchecked http://ip-10-0-0-195:36093/static/jquery/themes-1.9.1/base/images/ui-bg_flat_75_ffffff_40x100.png which is the app master GUI of application_1399289015992_0003 owned by ubuntu
2014-05-05 11:48:09,373 INFO org.apache.hadoop.yarn.server.webproxy.WebAppProxyServlet: dr.who is accessing unchecked http://ip-10-0-0-195:36093/static/jquery/themes-1.9.1/base/images/ui-bg_glass_75_e6e6e6_1x400.png which is the app master GUI of application_1399289015992_0003 owned by ubuntu
2014-05-05 11:48:09,373 INFO org.apache.hadoop.yarn.server.webproxy.WebAppProxyServlet: dr.who is accessing unchecked http://ip-10-0-0-195:36093/static/jquery/themes-1.9.1/base/images/ui-icons_888888_256x240.png which is the app master GUI of application_1399289015992_0003 owned by ubuntu
2014-05-05 11:48:09,384 INFO org.apache.hadoop.yarn.server.webproxy.WebAppProxyServlet: dr.who is accessing unchecked http://ip-10-0-0-195:36093/static/jquery/themes-1.9.1/base/images/ui-bg_glass_65_ffffff_1x400.png which is the app master GUI of application_1399289015992_0003 owned by ubuntu
2014-05-05 11:48:09,440 INFO org.apache.hadoop.yarn.server.webproxy.WebAppProxyServlet: dr.who is accessing unchecked http://ip-10-0-0-195:36093/static/jquery/themes-1.9.1/base/images/ui-icons_454545_256x240.png which is the app master GUI of application_1399289015992_0003 owned by ubuntu
2014-05-05 11:48:10,755 INFO org.apache.hadoop.yarn.server.webproxy.WebAppProxyServlet: dr.who is accessing unchecked http://ip-10-0-0-195:36093/ which is the app master GUI of application_1399289015992_0003 owned by ubuntu
2014-05-05 11:48:10,926 INFO org.apache.hadoop.yarn.server.webproxy.WebAppProxyServlet: dr.who is accessing unchecked http://ip-10-0-0-195:36093/static/jquery/jquery-ui-1.9.1.custom.min.js which is the app master GUI of application_1399289015992_0003 owned by ubuntu
2014-05-05 11:48:10,926 INFO org.apache.hadoop.yarn.server.webproxy.WebAppProxyServlet: dr.who is accessing unchecked http://ip-10-0-0-195:36093/static/jquery/themes-1.9.1/base/jquery-ui.css which is the app master GUI of application_1399289015992_0003 owned by ubuntu
2014-05-05 11:48:10,926 INFO org.apache.hadoop.yarn.server.webproxy.WebAppProxyServlet: dr.who is accessing unchecked http://ip-10-0-0-195:36093/static/dt-1.9.4/css/jui-dt.css which is the app master GUI of application_1399289015992_0003 owned by ubuntu
2014-05-05 11:48:10,926 INFO org.apache.hadoop.yarn.server.webproxy.WebAppProxyServlet: dr.who is accessing unchecked http://ip-10-0-0-195:36093/static/jquery/jquery-1.8.2.min.js which is the app master GUI of application_1399289015992_0003 owned by ubuntu
2014-05-05 11:48:10,928 INFO org.apache.hadoop.yarn.server.webproxy.WebAppProxyServlet: dr.who is accessing unchecked http://ip-10-0-0-195:36093/static/dt-1.9.4/js/jquery.dataTables.min.js which is the app master GUI of application_1399289015992_0003 owned by ubuntu
2014-05-05 11:48:10,930 INFO org.apache.hadoop.yarn.server.webproxy.WebAppProxyServlet: dr.who is accessing unchecked http://ip-10-0-0-195:36093/static/yarn.css which is the app master GUI of application_1399289015992_0003 owned by ubuntu
2014-05-05 11:48:11,019 INFO org.apache.hadoop.yarn.server.webproxy.WebAppProxyServlet: dr.who is accessing unchecked http://ip-10-0-0-195:36093/static/yarn.dt.plugins.js which is the app master GUI of application_1399289015992_0003 owned by ubuntu
2014-05-05 11:48:11,362 INFO org.apache.hadoop.yarn.server.webproxy.WebAppProxyServlet: dr.who is accessing unchecked http://ip-10-0-0-195:36093/static/jquery/themes-1.9.1/base/images/ui-bg_glass_95_fef1ec_1x400.png which is the app master GUI of application_1399289015992_0003 owned by ubuntu
2014-05-05 11:48:11,365 INFO org.apache.hadoop.yarn.server.webproxy.WebAppProxyServlet: dr.who is accessing unchecked http://ip-10-0-0-195:36093/static/jquery/themes-1.9.1/base/images/ui-bg_flat_75_ffffff_40x100.png which is the app master GUI of application_1399289015992_0003 owned by ubuntu
2014-05-05 11:48:11,365 INFO org.apache.hadoop.yarn.server.webproxy.WebAppProxyServlet: dr.who is accessing unchecked http://ip-10-0-0-195:36093/static/jquery/themes-1.9.1/base/images/ui-bg_highlight-soft_75_cccccc_1x100.png which is the app master GUI of application_1399289015992_0003 owned by ubuntu
2014-05-05 11:48:11,376 INFO org.apache.hadoop.yarn.server.webproxy.WebAppProxyServlet: dr.who is accessing unchecked http://ip-10-0-0-195:36093/static/jquery/themes-1.9.1/base/images/ui-bg_glass_65_ffffff_1x400.png which is the app master GUI of application_1399289015992_0003 owned by ubuntu
2014-05-05 11:48:11,377 INFO org.apache.hadoop.yarn.server.webproxy.WebAppProxyServlet: dr.who is accessing unchecked http://ip-10-0-0-195:36093/static/jquery/themes-1.9.1/base/images/ui-icons_888888_256x240.png which is the app master GUI of application_1399289015992_0003 owned by ubuntu
2014-05-05 11:48:11,377 INFO org.apache.hadoop.yarn.server.webproxy.WebAppProxyServlet: dr.who is accessing unchecked http://ip-10-0-0-195:36093/static/jquery/themes-1.9.1/base/images/ui-bg_glass_75_e6e6e6_1x400.png which is the app master GUI of application_1399289015992_0003 owned by ubuntu
2014-05-05 11:48:11,442 INFO org.apache.hadoop.yarn.server.webproxy.WebAppProxyServlet: dr.who is accessing unchecked http://ip-10-0-0-195:36093/static/jquery/themes-1.9.1/base/images/ui-icons_454545_256x240.png which is the app master GUI of application_1399289015992_0003 owned by ubuntu
2014-05-05 11:48:12,288 INFO org.apache.hadoop.yarn.server.webproxy.WebAppProxyServlet: dr.who is accessing unchecked http://ip-10-0-0-195:36093/mapreduce/job/job_1399289015992_0003 which is the app master GUI of application_1399289015992_0003 owned by ubuntu
2014-05-05 11:48:12,510 INFO org.apache.hadoop.yarn.server.webproxy.WebAppProxyServlet: dr.who is accessing unchecked http://ip-10-0-0-195:36093/static/yarn.css which is the app master GUI of application_1399289015992_0003 owned by ubuntu
2014-05-05 11:48:12,510 INFO org.apache.hadoop.yarn.server.webproxy.WebAppProxyServlet: dr.who is accessing unchecked http://ip-10-0-0-195:36093/static/jquery/themes-1.9.1/base/jquery-ui.css which is the app master GUI of application_1399289015992_0003 owned by ubuntu
2014-05-05 11:48:12,511 INFO org.apache.hadoop.yarn.server.webproxy.WebAppProxyServlet: dr.who is accessing unchecked http://ip-10-0-0-195:36093/static/dt-1.9.4/js/jquery.dataTables.min.js which is the app master GUI of application_1399289015992_0003 owned by ubuntu
2014-05-05 11:48:12,512 INFO org.apache.hadoop.yarn.server.webproxy.WebAppProxyServlet: dr.who is accessing unchecked http://ip-10-0-0-195:36093/static/jquery/jquery-ui-1.9.1.custom.min.js which is the app master GUI of application_1399289015992_0003 owned by ubuntu
2014-05-05 11:48:12,512 INFO org.apache.hadoop.yarn.server.webproxy.WebAppProxyServlet: dr.who is accessing unchecked http://ip-10-0-0-195:36093/static/jquery/jquery-1.8.2.min.js which is the app master GUI of application_1399289015992_0003 owned by ubuntu
