2014-05-05 03:49:50,310 INFO org.apache.hadoop.yarn.server.resourcemanager.ResourceManager: STARTUP_MSG: 
/************************************************************
STARTUP_MSG: Starting ResourceManager
STARTUP_MSG:   host = ip-10-0-0-158/10.0.0.158
STARTUP_MSG:   args = []
STARTUP_MSG:   version = 2.2.0
STARTUP_MSG:   build = Unknown -r Unknown; compiled by 'root' on 2014-05-04T05:58Z
STARTUP_MSG:   java = 1.7.0_51
************************************************************/
2014-05-05 03:49:50,323 INFO org.apache.hadoop.yarn.server.resourcemanager.ResourceManager: registered UNIX signal handlers for [TERM, HUP, INT]
2014-05-05 03:49:50,654 INFO org.apache.hadoop.yarn.server.resourcemanager.security.AMRMTokenSecretManager: Rolling master-key for amrm-tokens
2014-05-05 03:49:50,670 INFO org.apache.hadoop.yarn.server.resourcemanager.security.RMContainerTokenSecretManager: ContainerTokenKeyRollingInterval: 86400000ms and ContainerTokenKeyActivationDelay: 900000ms
2014-05-05 03:49:50,674 INFO org.apache.hadoop.yarn.server.resourcemanager.security.NMTokenSecretManagerInRM: NMTokenKeyRollingInterval: 86400000ms and NMTokenKeyActivationDelay: 900000ms
2014-05-05 03:49:50,682 INFO org.apache.hadoop.yarn.event.AsyncDispatcher: Registering class org.apache.hadoop.yarn.server.resourcemanager.recovery.RMStateStoreEventType for class org.apache.hadoop.yarn.server.resourcemanager.recovery.RMStateStore$ForwardingEventHandler
2014-05-05 03:49:51,039 WARN org.apache.hadoop.util.NativeCodeLoader: Unable to load native-hadoop library for your platform... using builtin-java classes where applicable
2014-05-05 03:49:51,346 INFO org.apache.hadoop.yarn.event.AsyncDispatcher: Registering class org.apache.hadoop.yarn.server.resourcemanager.NodesListManagerEventType for class org.apache.hadoop.yarn.server.resourcemanager.NodesListManager
2014-05-05 03:49:51,481 INFO org.apache.hadoop.yarn.server.resourcemanager.ResourceManager: Using Scheduler: org.apache.hadoop.yarn.server.resourcemanager.scheduler.capacity.CapacityScheduler
2014-05-05 03:49:51,749 INFO org.apache.hadoop.yarn.event.AsyncDispatcher: Registering class org.apache.hadoop.yarn.server.resourcemanager.scheduler.event.SchedulerEventType for class org.apache.hadoop.yarn.server.resourcemanager.ResourceManager$SchedulerEventDispatcher
2014-05-05 03:49:51,760 INFO org.apache.hadoop.yarn.event.AsyncDispatcher: Registering class org.apache.hadoop.yarn.server.resourcemanager.rmapp.RMAppEventType for class org.apache.hadoop.yarn.server.resourcemanager.ResourceManager$ApplicationEventDispatcher
2014-05-05 03:49:51,762 INFO org.apache.hadoop.yarn.event.AsyncDispatcher: Registering class org.apache.hadoop.yarn.server.resourcemanager.rmapp.attempt.RMAppAttemptEventType for class org.apache.hadoop.yarn.server.resourcemanager.ResourceManager$ApplicationAttemptEventDispatcher
2014-05-05 03:49:51,763 INFO org.apache.hadoop.yarn.event.AsyncDispatcher: Registering class org.apache.hadoop.yarn.server.resourcemanager.rmnode.RMNodeEventType for class org.apache.hadoop.yarn.server.resourcemanager.ResourceManager$NodeEventDispatcher
2014-05-05 03:49:51,993 INFO org.apache.hadoop.metrics2.impl.MetricsConfig: loaded properties from hadoop-metrics2.properties
2014-05-05 03:49:52,122 INFO org.apache.hadoop.metrics2.impl.MetricsSystemImpl: Scheduled snapshot period at 10 second(s).
2014-05-05 03:49:52,122 INFO org.apache.hadoop.metrics2.impl.MetricsSystemImpl: ResourceManager metrics system started
2014-05-05 03:49:52,366 INFO org.apache.hadoop.yarn.server.resourcemanager.scheduler.capacity.ParentQueue: root, capacity=1.0, asboluteCapacity=1.0, maxCapacity=1.0, asboluteMaxCapacity=1.0, state=RUNNING, acls=ADMINISTER_QUEUE:*SUBMIT_APPLICATIONS:*
2014-05-05 03:49:52,367 INFO org.apache.hadoop.yarn.server.resourcemanager.scheduler.capacity.ParentQueue: Initialized parent-queue root name=root, fullname=root
2014-05-05 03:49:52,399 INFO org.apache.hadoop.yarn.server.resourcemanager.scheduler.capacity.LeafQueue: Initializing default
capacity = 1.0 [= (float) configuredCapacity / 100 ]
asboluteCapacity = 1.0 [= parentAbsoluteCapacity * capacity ]
maxCapacity = 1.0 [= configuredMaxCapacity ]
absoluteMaxCapacity = 1.0 [= 1.0 maximumCapacity undefined, (parentAbsoluteMaxCapacity * maximumCapacity) / 100 otherwise ]
userLimit = 100 [= configuredUserLimit ]
userLimitFactor = 1.0 [= configuredUserLimitFactor ]
maxApplications = 10000 [= configuredMaximumSystemApplicationsPerQueue or (int)(configuredMaximumSystemApplications * absoluteCapacity)]
maxApplicationsPerUser = 10000 [= (int)(maxApplications * (userLimit / 100.0f) * userLimitFactor) ]
maxActiveApplications = 1 [= max((int)ceil((clusterResourceMemory / minimumAllocation) * maxAMResourcePerQueuePercent * absoluteMaxCapacity),1) ]
maxActiveAppsUsingAbsCap = 1 [= max((int)ceil((clusterResourceMemory / minimumAllocation) *maxAMResourcePercent * absoluteCapacity),1) ]
maxActiveApplicationsPerUser = 1 [= max((int)(maxActiveApplications * (userLimit / 100.0f) * userLimitFactor),1) ]
usedCapacity = 0.0 [= usedResourcesMemory / (clusterResourceMemory * absoluteCapacity)]
absoluteUsedCapacity = 0.0 [= usedResourcesMemory / clusterResourceMemory]
maxAMResourcePerQueuePercent = 0.1 [= configuredMaximumAMResourcePercent ]
minimumAllocationFactor = 0.875 [= (float)(maximumAllocationMemory - minimumAllocationMemory) / maximumAllocationMemory ]
numContainers = 0 [= currentNumContainers ]
state = RUNNING [= configuredState ]
acls = ADMINISTER_QUEUE:*SUBMIT_APPLICATIONS:* [= configuredAcls ]
nodeLocalityDelay = 0

2014-05-05 03:49:52,400 INFO org.apache.hadoop.yarn.server.resourcemanager.scheduler.capacity.CapacityScheduler: Initialized queue: default: capacity=1.0, absoluteCapacity=1.0, usedResources=<memory:0, vCores:0>usedCapacity=0.0, absoluteUsedCapacity=0.0, numApps=0, numContainers=0
2014-05-05 03:49:52,400 INFO org.apache.hadoop.yarn.server.resourcemanager.scheduler.capacity.CapacityScheduler: Initialized queue: root: numChildQueue= 1, capacity=1.0, absoluteCapacity=1.0, usedResources=<memory:0, vCores:0>usedCapacity=0.0, numApps=0, numContainers=0
2014-05-05 03:49:52,400 INFO org.apache.hadoop.yarn.server.resourcemanager.scheduler.capacity.CapacityScheduler: Initialized root queue root: numChildQueue= 1, capacity=1.0, absoluteCapacity=1.0, usedResources=<memory:0, vCores:0>usedCapacity=0.0, numApps=0, numContainers=0
2014-05-05 03:49:52,400 INFO org.apache.hadoop.yarn.server.resourcemanager.scheduler.capacity.CapacityScheduler: Initialized CapacityScheduler with calculator=class org.apache.hadoop.yarn.util.resource.DefaultResourceCalculator, minimumAllocation=<<memory:1024, vCores:1>>, maximumAllocation=<<memory:8192, vCores:32>>
2014-05-05 03:49:52,596 INFO org.apache.hadoop.yarn.event.AsyncDispatcher: Registering class org.apache.hadoop.yarn.server.resourcemanager.RMAppManagerEventType for class org.apache.hadoop.yarn.server.resourcemanager.RMAppManager
2014-05-05 03:49:52,642 INFO org.apache.hadoop.yarn.event.AsyncDispatcher: Registering class org.apache.hadoop.yarn.server.resourcemanager.amlauncher.AMLauncherEventType for class org.apache.hadoop.yarn.server.resourcemanager.amlauncher.ApplicationMasterLauncher
2014-05-05 03:49:52,645 INFO org.apache.hadoop.yarn.server.resourcemanager.RMNMInfo: Registered RMNMInfo MBean
2014-05-05 03:49:52,646 INFO org.apache.hadoop.util.HostsFileReader: Refreshing hosts (include/exclude) list
2014-05-05 03:49:52,666 INFO org.apache.hadoop.yarn.server.resourcemanager.security.AMRMTokenSecretManager: Rolling master-key for amrm-tokens
2014-05-05 03:49:52,666 INFO org.apache.hadoop.yarn.server.resourcemanager.security.RMContainerTokenSecretManager: Rolling master-key for container-tokens
2014-05-05 03:49:52,670 INFO org.apache.hadoop.yarn.server.resourcemanager.security.NMTokenSecretManagerInRM: Rolling master-key for nm-tokens
2014-05-05 03:49:52,782 INFO org.mortbay.log: Logging to org.slf4j.impl.Log4jLoggerAdapter(org.mortbay.log) via org.mortbay.log.Slf4jLog
2014-05-05 03:49:52,853 INFO org.apache.hadoop.http.HttpServer: Added global filter 'safety' (class=org.apache.hadoop.http.HttpServer$QuotingInputFilter)
2014-05-05 03:49:52,856 INFO org.apache.hadoop.http.HttpServer: Added filter static_user_filter (class=org.apache.hadoop.http.lib.StaticUserWebFilter$StaticUserFilter) to context cluster
2014-05-05 03:49:52,856 INFO org.apache.hadoop.http.HttpServer: Added filter static_user_filter (class=org.apache.hadoop.http.lib.StaticUserWebFilter$StaticUserFilter) to context logs
2014-05-05 03:49:52,857 INFO org.apache.hadoop.http.HttpServer: Added filter static_user_filter (class=org.apache.hadoop.http.lib.StaticUserWebFilter$StaticUserFilter) to context static
2014-05-05 03:49:52,862 INFO org.apache.hadoop.http.HttpServer: adding path spec: /cluster/*
2014-05-05 03:49:52,863 INFO org.apache.hadoop.http.HttpServer: adding path spec: /ws/*
2014-05-05 03:49:52,873 INFO org.apache.hadoop.http.HttpServer: Jetty bound to port 8088
2014-05-05 03:49:52,873 INFO org.mortbay.log: jetty-6.1.26
2014-05-05 03:49:52,928 INFO org.mortbay.log: Extract jar:file:/home/ubuntu/PatchedDistro/hadoop-patch/share/hadoop/yarn/hadoop-yarn-common-2.2.0.jar!/webapps/cluster to /tmp/Jetty_ec2.54.186.230.200_us.west.2_compute_amazonaws_com_8088_cluster____.lsgqu1/webapp
2014-05-05 03:49:53,566 INFO org.mortbay.log: Started SelectChannelConnector@ec2-54-186-230-200.us-west-2.compute.amazonaws.com:8088
2014-05-05 03:49:53,566 INFO org.apache.hadoop.yarn.webapp.WebApps: Web app /cluster started at 8088
2014-05-05 03:49:54,652 INFO org.apache.hadoop.yarn.webapp.WebApps: Registered webapp guice modules
2014-05-05 03:49:54,653 INFO org.apache.hadoop.security.token.delegation.AbstractDelegationTokenSecretManager: Updating the current master key for generating delegation tokens
2014-05-05 03:49:54,654 INFO org.apache.hadoop.yarn.server.resourcemanager.security.RMDelegationTokenSecretManager: storing master key with keyID 1
2014-05-05 03:49:54,656 INFO org.apache.hadoop.security.token.delegation.AbstractDelegationTokenSecretManager: Starting expired delegation token remover thread, tokenRemoverScanInterval=60 min(s)
2014-05-05 03:49:54,656 INFO org.apache.hadoop.security.token.delegation.AbstractDelegationTokenSecretManager: Updating the current master key for generating delegation tokens
2014-05-05 03:49:54,656 INFO org.apache.hadoop.yarn.server.resourcemanager.security.RMDelegationTokenSecretManager: storing master key with keyID 2
2014-05-05 03:49:54,710 INFO org.apache.hadoop.ipc.Server: Starting Socket Reader #1 for port 8031
2014-05-05 03:49:54,728 INFO org.apache.hadoop.yarn.factories.impl.pb.RpcServerFactoryPBImpl: Adding protocol org.apache.hadoop.yarn.server.api.ResourceTrackerPB to the server
2014-05-05 03:49:54,728 INFO org.apache.hadoop.ipc.Server: IPC Server Responder: starting
2014-05-05 03:49:54,730 INFO org.apache.hadoop.ipc.Server: IPC Server listener on 8031: starting
2014-05-05 03:49:54,796 INFO org.apache.hadoop.ipc.Server: Starting Socket Reader #1 for port 8030
2014-05-05 03:49:54,875 INFO org.apache.hadoop.yarn.factories.impl.pb.RpcServerFactoryPBImpl: Adding protocol org.apache.hadoop.yarn.api.ApplicationMasterProtocolPB to the server
2014-05-05 03:49:54,875 INFO org.apache.hadoop.ipc.Server: IPC Server Responder: starting
2014-05-05 03:49:54,881 INFO org.apache.hadoop.ipc.Server: IPC Server listener on 8030: starting
2014-05-05 03:49:55,025 INFO org.apache.hadoop.yarn.factories.impl.pb.RpcServerFactoryPBImpl: Adding protocol org.apache.hadoop.yarn.api.ApplicationClientProtocolPB to the server
2014-05-05 03:49:55,026 INFO org.apache.hadoop.ipc.Server: Starting Socket Reader #1 for port 8032
2014-05-05 03:49:55,026 INFO org.apache.hadoop.ipc.Server: IPC Server Responder: starting
2014-05-05 03:49:55,026 INFO org.apache.hadoop.ipc.Server: IPC Server listener on 8032: starting
2014-05-05 03:49:55,109 INFO org.apache.hadoop.yarn.factories.impl.pb.RpcServerFactoryPBImpl: Adding protocol org.apache.hadoop.yarn.server.api.ResourceManagerAdministrationProtocolPB to the server
2014-05-05 03:49:55,109 INFO org.apache.hadoop.ipc.Server: Starting Socket Reader #1 for port 8033
2014-05-05 03:49:55,109 INFO org.apache.hadoop.ipc.Server: IPC Server Responder: starting
2014-05-05 03:49:55,110 INFO org.apache.hadoop.ipc.Server: IPC Server listener on 8033: starting
2014-05-05 03:49:55,358 INFO org.apache.hadoop.yarn.util.RackResolver: Resolved noded to /default-rack
2014-05-05 03:49:55,362 INFO org.apache.hadoop.yarn.util.RackResolver: Resolved nodeb to /default-rack
2014-05-05 03:49:55,382 INFO org.apache.hadoop.yarn.util.RackResolver: Resolved nodec to /default-rack
2014-05-05 03:49:55,384 INFO org.apache.hadoop.yarn.server.resourcemanager.ResourceTrackerService: NodeManager from node nodeb(cmPort: 41344 httpPort: 8042) registered with capability: <memory:8192, vCores:8>, assigned nodeId nodeb:41344
2014-05-05 03:49:55,393 INFO org.apache.hadoop.yarn.server.resourcemanager.rmnode.RMNodeImpl: noded:54001 Node Transitioned from NEW to RUNNING
2014-05-05 03:49:55,393 INFO org.apache.hadoop.yarn.server.resourcemanager.rmnode.RMNodeImpl: nodeb:41344 Node Transitioned from NEW to RUNNING
2014-05-05 03:49:55,393 INFO org.apache.hadoop.yarn.server.resourcemanager.rmnode.RMNodeImpl: nodec:51351 Node Transitioned from NEW to RUNNING
2014-05-05 03:49:55,393 INFO org.apache.hadoop.yarn.server.resourcemanager.ResourceTrackerService: NodeManager from node noded(cmPort: 54001 httpPort: 8042) registered with capability: <memory:8192, vCores:8>, assigned nodeId noded:54001
2014-05-05 03:49:55,384 INFO org.apache.hadoop.yarn.server.resourcemanager.ResourceTrackerService: NodeManager from node nodec(cmPort: 51351 httpPort: 8042) registered with capability: <memory:8192, vCores:8>, assigned nodeId nodec:51351
2014-05-05 03:49:55,403 INFO org.apache.hadoop.yarn.server.resourcemanager.scheduler.capacity.CapacityScheduler: Added node noded:54001 clusterResource: <memory:8192, vCores:8>
2014-05-05 03:49:55,422 INFO org.apache.hadoop.yarn.server.resourcemanager.scheduler.capacity.CapacityScheduler: Added node nodeb:41344 clusterResource: <memory:16384, vCores:16>
2014-05-05 03:49:55,422 INFO org.apache.hadoop.yarn.server.resourcemanager.scheduler.capacity.CapacityScheduler: Added node nodec:51351 clusterResource: <memory:24576, vCores:24>
2014-05-05 03:49:56,997 INFO org.apache.hadoop.yarn.util.RackResolver: Resolved nodea to /default-rack
2014-05-05 03:49:56,997 INFO org.apache.hadoop.yarn.server.resourcemanager.ResourceTrackerService: NodeManager from node nodea(cmPort: 49324 httpPort: 8042) registered with capability: <memory:8192, vCores:8>, assigned nodeId nodea:49324
2014-05-05 03:49:56,997 INFO org.apache.hadoop.yarn.server.resourcemanager.rmnode.RMNodeImpl: nodea:49324 Node Transitioned from NEW to RUNNING
2014-05-05 03:49:56,997 INFO org.apache.hadoop.yarn.server.resourcemanager.scheduler.capacity.CapacityScheduler: Added node nodea:49324 clusterResource: <memory:32768, vCores:32>
2014-05-05 03:53:56,035 INFO org.apache.hadoop.yarn.server.resourcemanager.ClientRMService: Allocated new applicationId: 1
2014-05-05 03:53:57,872 INFO org.apache.hadoop.yarn.server.resourcemanager.ClientRMService: Application with id 1 submitted by user ubuntu
2014-05-05 03:53:57,873 INFO org.apache.hadoop.yarn.server.resourcemanager.rmapp.RMAppImpl: Storing application with id application_1399261790270_0001
2014-05-05 03:53:57,874 INFO org.apache.hadoop.yarn.server.resourcemanager.RMAuditLogger: USER=ubuntu	IP=10.0.0.158	OPERATION=Submit Application Request	TARGET=ClientRMService	RESULT=SUCCESS	APPID=application_1399261790270_0001
2014-05-05 03:53:57,875 INFO org.apache.hadoop.yarn.server.resourcemanager.rmapp.RMAppImpl: application_1399261790270_0001 State change from NEW to NEW_SAVING
2014-05-05 03:53:57,888 INFO org.apache.hadoop.yarn.server.resourcemanager.recovery.RMStateStore: Storing info for app: application_1399261790270_0001
2014-05-05 03:53:57,899 INFO org.apache.hadoop.yarn.server.resourcemanager.rmapp.RMAppImpl: application_1399261790270_0001 State change from NEW_SAVING to SUBMITTED
2014-05-05 03:53:57,907 INFO org.apache.hadoop.yarn.server.resourcemanager.ApplicationMasterService: Registering app attempt : appattempt_1399261790270_0001_000001
2014-05-05 03:53:57,911 INFO org.apache.hadoop.yarn.server.resourcemanager.rmapp.attempt.RMAppAttemptImpl: appattempt_1399261790270_0001_000001 State change from NEW to SUBMITTED
2014-05-05 03:53:57,929 INFO org.apache.hadoop.yarn.server.resourcemanager.scheduler.capacity.LeafQueue: Application application_1399261790270_0001 from user: ubuntu activated in queue: default
2014-05-05 03:53:57,929 INFO org.apache.hadoop.yarn.server.resourcemanager.scheduler.capacity.LeafQueue: Application added - appId: application_1399261790270_0001 user: org.apache.hadoop.yarn.server.resourcemanager.scheduler.capacity.LeafQueue$User@46e3af42, leaf-queue: default #user-pending-applications: 0 #user-active-applications: 1 #queue-pending-applications: 0 #queue-active-applications: 1
2014-05-05 03:53:57,929 INFO org.apache.hadoop.yarn.server.resourcemanager.scheduler.capacity.ParentQueue: Application added - appId: application_1399261790270_0001 user: ubuntu leaf-queue of parent: root #applications: 1
2014-05-05 03:53:57,929 INFO org.apache.hadoop.yarn.server.resourcemanager.scheduler.capacity.CapacityScheduler: Application Submission: appattempt_1399261790270_0001_000001, user: ubuntu queue: default: capacity=1.0, absoluteCapacity=1.0, usedResources=<memory:0, vCores:0>usedCapacity=0.0, absoluteUsedCapacity=0.0, numApps=1, numContainers=0, currently active: 1
2014-05-05 03:53:57,930 INFO org.apache.hadoop.yarn.server.resourcemanager.rmapp.attempt.RMAppAttemptImpl: appattempt_1399261790270_0001_000001 State change from SUBMITTED to SCHEDULED
2014-05-05 03:53:57,930 INFO org.apache.hadoop.yarn.server.resourcemanager.rmapp.RMAppImpl: application_1399261790270_0001 State change from SUBMITTED to ACCEPTED
2014-05-05 03:53:57,960 INFO org.apache.hadoop.yarn.server.resourcemanager.rmcontainer.RMContainerImpl: container_1399261790270_0001_01_000001 Container Transitioned from NEW to ALLOCATED
2014-05-05 03:53:57,960 INFO org.apache.hadoop.yarn.server.resourcemanager.RMAuditLogger: USER=ubuntu	OPERATION=AM Allocated Container	TARGET=SchedulerApp	RESULT=SUCCESS	APPID=application_1399261790270_0001	CONTAINERID=container_1399261790270_0001_01_000001
2014-05-05 03:53:57,961 INFO org.apache.hadoop.yarn.server.resourcemanager.scheduler.common.fica.FiCaSchedulerNode: Assigned container container_1399261790270_0001_01_000001 of capacity <memory:2048, vCores:1> on host noded:54001, which currently has 1 containers, <memory:2048, vCores:1> used and <memory:6144, vCores:7> available
2014-05-05 03:53:57,961 INFO org.apache.hadoop.yarn.server.resourcemanager.scheduler.capacity.LeafQueue: assignedContainer application=application_1399261790270_0001 container=Container: [ContainerId: container_1399261790270_0001_01_000001, NodeId: noded:54001, NodeHttpAddress: noded:8042, Resource: <memory:2048, vCores:1>, Priority: 0, Token: Token { kind: ContainerToken, service: 10.0.0.180:54001 }, ] containerId=container_1399261790270_0001_01_000001 queue=default: capacity=1.0, absoluteCapacity=1.0, usedResources=<memory:0, vCores:0>usedCapacity=0.0, absoluteUsedCapacity=0.0, numApps=1, numContainers=0 usedCapacity=0.0 absoluteUsedCapacity=0.0 used=<memory:0, vCores:0> cluster=<memory:32768, vCores:32>
2014-05-05 03:53:57,961 INFO org.apache.hadoop.yarn.server.resourcemanager.scheduler.capacity.ParentQueue: Re-sorting assigned queue: root.default stats: default: capacity=1.0, absoluteCapacity=1.0, usedResources=<memory:2048, vCores:1>usedCapacity=0.0625, absoluteUsedCapacity=0.0625, numApps=1, numContainers=1
2014-05-05 03:53:57,961 INFO org.apache.hadoop.yarn.server.resourcemanager.scheduler.capacity.ParentQueue: assignedContainer queue=root usedCapacity=0.0625 absoluteUsedCapacity=0.0625 used=<memory:2048, vCores:1> cluster=<memory:32768, vCores:32>
2014-05-05 03:53:57,962 INFO org.apache.hadoop.yarn.server.resourcemanager.rmcontainer.RMContainerImpl: container_1399261790270_0001_01_000001 Container Transitioned from ALLOCATED to ACQUIRED
2014-05-05 03:53:57,964 INFO org.apache.hadoop.yarn.server.resourcemanager.rmapp.attempt.RMAppAttemptImpl: Storing attempt: AppId: application_1399261790270_0001 AttemptId: appattempt_1399261790270_0001_000001 MasterContainer: Container: [ContainerId: container_1399261790270_0001_01_000001, NodeId: noded:54001, NodeHttpAddress: noded:8042, Resource: <memory:2048, vCores:1>, Priority: 0, Token: Token { kind: ContainerToken, service: 10.0.0.180:54001 }, ]
2014-05-05 03:53:57,968 INFO org.apache.hadoop.yarn.server.resourcemanager.rmapp.attempt.RMAppAttemptImpl: appattempt_1399261790270_0001_000001 State change from SCHEDULED to ALLOCATED_SAVING
2014-05-05 03:53:57,977 INFO org.apache.hadoop.yarn.server.resourcemanager.recovery.RMStateStore: Storing info for attempt: appattempt_1399261790270_0001_000001
2014-05-05 03:53:57,978 INFO org.apache.hadoop.yarn.server.resourcemanager.rmapp.attempt.RMAppAttemptImpl: appattempt_1399261790270_0001_000001 State change from ALLOCATED_SAVING to ALLOCATED
2014-05-05 03:53:57,982 INFO org.apache.hadoop.yarn.server.resourcemanager.amlauncher.AMLauncher: Launching masterappattempt_1399261790270_0001_000001
2014-05-05 03:53:58,037 INFO org.apache.hadoop.yarn.server.resourcemanager.amlauncher.AMLauncher: Setting up container Container: [ContainerId: container_1399261790270_0001_01_000001, NodeId: noded:54001, NodeHttpAddress: noded:8042, Resource: <memory:2048, vCores:1>, Priority: 0, Token: Token { kind: ContainerToken, service: 10.0.0.180:54001 }, ] for AM appattempt_1399261790270_0001_000001
2014-05-05 03:53:58,038 INFO org.apache.hadoop.yarn.server.resourcemanager.amlauncher.AMLauncher: Command to launch container container_1399261790270_0001_01_000001 : $JAVA_HOME/bin/java -Dlog4j.configuration=container-log4j.properties -Dyarn.app.container.log.dir=<LOG_DIR> -Dyarn.app.container.log.filesize=0 -Dhadoop.root.logger=INFO,CLA  -Xmx1024m org.apache.hadoop.mapreduce.v2.app.MRAppMaster 1><LOG_DIR>/stdout 2><LOG_DIR>/stderr 
2014-05-05 03:53:58,366 INFO org.apache.hadoop.yarn.server.resourcemanager.amlauncher.AMLauncher: Done launching container Container: [ContainerId: container_1399261790270_0001_01_000001, NodeId: noded:54001, NodeHttpAddress: noded:8042, Resource: <memory:2048, vCores:1>, Priority: 0, Token: Token { kind: ContainerToken, service: 10.0.0.180:54001 }, ] for AM appattempt_1399261790270_0001_000001
2014-05-05 03:53:58,367 INFO org.apache.hadoop.yarn.server.resourcemanager.rmapp.attempt.RMAppAttemptImpl: appattempt_1399261790270_0001_000001 State change from ALLOCATED to LAUNCHED
2014-05-05 03:53:58,948 INFO org.apache.hadoop.yarn.server.resourcemanager.rmcontainer.RMContainerImpl: container_1399261790270_0001_01_000001 Container Transitioned from ACQUIRED to RUNNING
2014-05-05 03:54:05,202 INFO SecurityLogger.org.apache.hadoop.ipc.Server: Auth successful for appattempt_1399261790270_0001_000001 (auth:SIMPLE)
2014-05-05 03:54:05,213 INFO org.apache.hadoop.yarn.server.resourcemanager.ApplicationMasterService: AM registration appattempt_1399261790270_0001_000001
2014-05-05 03:54:05,213 INFO org.apache.hadoop.yarn.server.resourcemanager.RMAuditLogger: USER=ubuntu	IP=10.0.0.180	OPERATION=Register App Master	TARGET=ApplicationMasterService	RESULT=SUCCESS	APPID=application_1399261790270_0001	APPATTEMPTID=appattempt_1399261790270_0001_000001
2014-05-05 03:54:05,214 INFO org.apache.hadoop.yarn.server.resourcemanager.rmapp.attempt.RMAppAttemptImpl: appattempt_1399261790270_0001_000001 State change from LAUNCHED to RUNNING
2014-05-05 03:54:05,214 INFO org.apache.hadoop.yarn.server.resourcemanager.rmapp.RMAppImpl: application_1399261790270_0001 State change from ACCEPTED to RUNNING
2014-05-05 03:54:06,371 INFO org.apache.hadoop.yarn.server.resourcemanager.rmcontainer.RMContainerImpl: container_1399261790270_0001_01_000002 Container Transitioned from NEW to ALLOCATED
2014-05-05 03:54:06,371 INFO org.apache.hadoop.yarn.server.resourcemanager.RMAuditLogger: USER=ubuntu	OPERATION=AM Allocated Container	TARGET=SchedulerApp	RESULT=SUCCESS	APPID=application_1399261790270_0001	CONTAINERID=container_1399261790270_0001_01_000002
2014-05-05 03:54:06,371 INFO org.apache.hadoop.yarn.server.resourcemanager.scheduler.common.fica.FiCaSchedulerNode: Assigned container container_1399261790270_0001_01_000002 of capacity <memory:1024, vCores:1> on host nodea:49324, which currently has 1 containers, <memory:1024, vCores:1> used and <memory:7168, vCores:7> available
2014-05-05 03:54:06,372 INFO org.apache.hadoop.yarn.server.resourcemanager.scheduler.capacity.LeafQueue: assignedContainer application=application_1399261790270_0001 container=Container: [ContainerId: container_1399261790270_0001_01_000002, NodeId: nodea:49324, NodeHttpAddress: nodea:8042, Resource: <memory:1024, vCores:1>, Priority: 20, Token: Token { kind: ContainerToken, service: 10.0.0.158:49324 }, ] containerId=container_1399261790270_0001_01_000002 queue=default: capacity=1.0, absoluteCapacity=1.0, usedResources=<memory:2048, vCores:1>usedCapacity=0.0625, absoluteUsedCapacity=0.0625, numApps=1, numContainers=1 usedCapacity=0.0625 absoluteUsedCapacity=0.0625 used=<memory:2048, vCores:1> cluster=<memory:32768, vCores:32>
2014-05-05 03:54:06,372 INFO org.apache.hadoop.yarn.server.resourcemanager.scheduler.capacity.ParentQueue: Re-sorting assigned queue: root.default stats: default: capacity=1.0, absoluteCapacity=1.0, usedResources=<memory:3072, vCores:2>usedCapacity=0.09375, absoluteUsedCapacity=0.09375, numApps=1, numContainers=2
2014-05-05 03:54:06,372 INFO org.apache.hadoop.yarn.server.resourcemanager.scheduler.capacity.ParentQueue: assignedContainer queue=root usedCapacity=0.09375 absoluteUsedCapacity=0.09375 used=<memory:3072, vCores:2> cluster=<memory:32768, vCores:32>
2014-05-05 03:54:06,372 INFO org.apache.hadoop.yarn.server.resourcemanager.rmcontainer.RMContainerImpl: container_1399261790270_0001_01_000003 Container Transitioned from NEW to ALLOCATED
2014-05-05 03:54:06,373 INFO org.apache.hadoop.yarn.server.resourcemanager.RMAuditLogger: USER=ubuntu	OPERATION=AM Allocated Container	TARGET=SchedulerApp	RESULT=SUCCESS	APPID=application_1399261790270_0001	CONTAINERID=container_1399261790270_0001_01_000003
2014-05-05 03:54:06,373 INFO org.apache.hadoop.yarn.server.resourcemanager.scheduler.common.fica.FiCaSchedulerNode: Assigned container container_1399261790270_0001_01_000003 of capacity <memory:1024, vCores:1> on host nodea:49324, which currently has 2 containers, <memory:2048, vCores:2> used and <memory:6144, vCores:6> available
2014-05-05 03:54:06,373 INFO org.apache.hadoop.yarn.server.resourcemanager.scheduler.capacity.LeafQueue: assignedContainer application=application_1399261790270_0001 container=Container: [ContainerId: container_1399261790270_0001_01_000003, NodeId: nodea:49324, NodeHttpAddress: nodea:8042, Resource: <memory:1024, vCores:1>, Priority: 20, Token: Token { kind: ContainerToken, service: 10.0.0.158:49324 }, ] containerId=container_1399261790270_0001_01_000003 queue=default: capacity=1.0, absoluteCapacity=1.0, usedResources=<memory:3072, vCores:2>usedCapacity=0.09375, absoluteUsedCapacity=0.09375, numApps=1, numContainers=2 usedCapacity=0.09375 absoluteUsedCapacity=0.09375 used=<memory:3072, vCores:2> cluster=<memory:32768, vCores:32>
2014-05-05 03:54:06,373 INFO org.apache.hadoop.yarn.server.resourcemanager.scheduler.capacity.ParentQueue: Re-sorting assigned queue: root.default stats: default: capacity=1.0, absoluteCapacity=1.0, usedResources=<memory:4096, vCores:3>usedCapacity=0.125, absoluteUsedCapacity=0.125, numApps=1, numContainers=3
2014-05-05 03:54:06,373 INFO org.apache.hadoop.yarn.server.resourcemanager.scheduler.capacity.ParentQueue: assignedContainer queue=root usedCapacity=0.125 absoluteUsedCapacity=0.125 used=<memory:4096, vCores:3> cluster=<memory:32768, vCores:32>
2014-05-05 03:54:06,374 INFO org.apache.hadoop.yarn.server.resourcemanager.rmcontainer.RMContainerImpl: container_1399261790270_0001_01_000004 Container Transitioned from NEW to ALLOCATED
2014-05-05 03:54:06,374 INFO org.apache.hadoop.yarn.server.resourcemanager.RMAuditLogger: USER=ubuntu	OPERATION=AM Allocated Container	TARGET=SchedulerApp	RESULT=SUCCESS	APPID=application_1399261790270_0001	CONTAINERID=container_1399261790270_0001_01_000004
2014-05-05 03:54:06,374 INFO org.apache.hadoop.yarn.server.resourcemanager.scheduler.common.fica.FiCaSchedulerNode: Assigned container container_1399261790270_0001_01_000004 of capacity <memory:1024, vCores:1> on host nodea:49324, which currently has 3 containers, <memory:3072, vCores:3> used and <memory:5120, vCores:5> available
2014-05-05 03:54:06,374 INFO org.apache.hadoop.yarn.server.resourcemanager.scheduler.capacity.LeafQueue: assignedContainer application=application_1399261790270_0001 container=Container: [ContainerId: container_1399261790270_0001_01_000004, NodeId: nodea:49324, NodeHttpAddress: nodea:8042, Resource: <memory:1024, vCores:1>, Priority: 20, Token: Token { kind: ContainerToken, service: 10.0.0.158:49324 }, ] containerId=container_1399261790270_0001_01_000004 queue=default: capacity=1.0, absoluteCapacity=1.0, usedResources=<memory:4096, vCores:3>usedCapacity=0.125, absoluteUsedCapacity=0.125, numApps=1, numContainers=3 usedCapacity=0.125 absoluteUsedCapacity=0.125 used=<memory:4096, vCores:3> cluster=<memory:32768, vCores:32>
2014-05-05 03:54:06,374 INFO org.apache.hadoop.yarn.server.resourcemanager.scheduler.capacity.ParentQueue: Re-sorting assigned queue: root.default stats: default: capacity=1.0, absoluteCapacity=1.0, usedResources=<memory:5120, vCores:4>usedCapacity=0.15625, absoluteUsedCapacity=0.15625, numApps=1, numContainers=4
2014-05-05 03:54:06,374 INFO org.apache.hadoop.yarn.server.resourcemanager.scheduler.capacity.ParentQueue: assignedContainer queue=root usedCapacity=0.15625 absoluteUsedCapacity=0.15625 used=<memory:5120, vCores:4> cluster=<memory:32768, vCores:32>
2014-05-05 03:54:06,375 INFO org.apache.hadoop.yarn.server.resourcemanager.rmcontainer.RMContainerImpl: container_1399261790270_0001_01_000005 Container Transitioned from NEW to ALLOCATED
2014-05-05 03:54:06,375 INFO org.apache.hadoop.yarn.server.resourcemanager.RMAuditLogger: USER=ubuntu	OPERATION=AM Allocated Container	TARGET=SchedulerApp	RESULT=SUCCESS	APPID=application_1399261790270_0001	CONTAINERID=container_1399261790270_0001_01_000005
2014-05-05 03:54:06,375 INFO org.apache.hadoop.yarn.server.resourcemanager.scheduler.common.fica.FiCaSchedulerNode: Assigned container container_1399261790270_0001_01_000005 of capacity <memory:1024, vCores:1> on host nodea:49324, which currently has 4 containers, <memory:4096, vCores:4> used and <memory:4096, vCores:4> available
2014-05-05 03:54:06,375 INFO org.apache.hadoop.yarn.server.resourcemanager.scheduler.capacity.LeafQueue: assignedContainer application=application_1399261790270_0001 container=Container: [ContainerId: container_1399261790270_0001_01_000005, NodeId: nodea:49324, NodeHttpAddress: nodea:8042, Resource: <memory:1024, vCores:1>, Priority: 20, Token: Token { kind: ContainerToken, service: 10.0.0.158:49324 }, ] containerId=container_1399261790270_0001_01_000005 queue=default: capacity=1.0, absoluteCapacity=1.0, usedResources=<memory:5120, vCores:4>usedCapacity=0.15625, absoluteUsedCapacity=0.15625, numApps=1, numContainers=4 usedCapacity=0.15625 absoluteUsedCapacity=0.15625 used=<memory:5120, vCores:4> cluster=<memory:32768, vCores:32>
2014-05-05 03:54:06,375 INFO org.apache.hadoop.yarn.server.resourcemanager.scheduler.capacity.ParentQueue: Re-sorting assigned queue: root.default stats: default: capacity=1.0, absoluteCapacity=1.0, usedResources=<memory:6144, vCores:5>usedCapacity=0.1875, absoluteUsedCapacity=0.1875, numApps=1, numContainers=5
2014-05-05 03:54:06,375 INFO org.apache.hadoop.yarn.server.resourcemanager.scheduler.capacity.ParentQueue: assignedContainer queue=root usedCapacity=0.1875 absoluteUsedCapacity=0.1875 used=<memory:6144, vCores:5> cluster=<memory:32768, vCores:32>
2014-05-05 03:54:07,352 INFO org.apache.hadoop.yarn.server.resourcemanager.rmcontainer.RMContainerImpl: container_1399261790270_0001_01_000002 Container Transitioned from ALLOCATED to ACQUIRED
2014-05-05 03:54:07,352 INFO org.apache.hadoop.yarn.server.resourcemanager.rmcontainer.RMContainerImpl: container_1399261790270_0001_01_000003 Container Transitioned from ALLOCATED to ACQUIRED
2014-05-05 03:54:07,353 INFO org.apache.hadoop.yarn.server.resourcemanager.rmcontainer.RMContainerImpl: container_1399261790270_0001_01_000004 Container Transitioned from ALLOCATED to ACQUIRED
2014-05-05 03:54:07,353 INFO org.apache.hadoop.yarn.server.resourcemanager.rmcontainer.RMContainerImpl: container_1399261790270_0001_01_000005 Container Transitioned from ALLOCATED to ACQUIRED
2014-05-05 03:54:08,375 INFO org.apache.hadoop.yarn.server.resourcemanager.scheduler.AppSchedulingInfo: checking for deactivate... 
2014-05-05 03:54:08,415 INFO org.apache.hadoop.yarn.server.resourcemanager.rmcontainer.RMContainerImpl: container_1399261790270_0001_01_000002 Container Transitioned from ACQUIRED to RUNNING
2014-05-05 03:54:08,415 INFO org.apache.hadoop.yarn.server.resourcemanager.rmcontainer.RMContainerImpl: container_1399261790270_0001_01_000003 Container Transitioned from ACQUIRED to RUNNING
2014-05-05 03:54:08,415 INFO org.apache.hadoop.yarn.server.resourcemanager.rmcontainer.RMContainerImpl: container_1399261790270_0001_01_000004 Container Transitioned from ACQUIRED to RUNNING
2014-05-05 03:54:08,416 INFO org.apache.hadoop.yarn.server.resourcemanager.rmcontainer.RMContainerImpl: container_1399261790270_0001_01_000005 Container Transitioned from ACQUIRED to RUNNING
2014-05-05 03:54:36,910 INFO org.apache.hadoop.yarn.server.resourcemanager.rmcontainer.RMContainerImpl: container_1399261790270_0001_01_000006 Container Transitioned from NEW to ALLOCATED
2014-05-05 03:54:36,911 INFO org.apache.hadoop.yarn.server.resourcemanager.RMAuditLogger: USER=ubuntu	OPERATION=AM Allocated Container	TARGET=SchedulerApp	RESULT=SUCCESS	APPID=application_1399261790270_0001	CONTAINERID=container_1399261790270_0001_01_000006
2014-05-05 03:54:36,911 INFO org.apache.hadoop.yarn.server.resourcemanager.scheduler.common.fica.FiCaSchedulerNode: Assigned container container_1399261790270_0001_01_000006 of capacity <memory:1024, vCores:1> on host nodeb:41344, which currently has 1 containers, <memory:1024, vCores:1> used and <memory:7168, vCores:7> available
2014-05-05 03:54:36,911 INFO org.apache.hadoop.yarn.server.resourcemanager.scheduler.capacity.LeafQueue: assignedContainer application=application_1399261790270_0001 container=Container: [ContainerId: container_1399261790270_0001_01_000006, NodeId: nodeb:41344, NodeHttpAddress: nodeb:8042, Resource: <memory:1024, vCores:1>, Priority: 20, Token: Token { kind: ContainerToken, service: 10.0.0.59:41344 }, ] containerId=container_1399261790270_0001_01_000006 queue=default: capacity=1.0, absoluteCapacity=1.0, usedResources=<memory:6144, vCores:5>usedCapacity=0.1875, absoluteUsedCapacity=0.1875, numApps=1, numContainers=5 usedCapacity=0.1875 absoluteUsedCapacity=0.1875 used=<memory:6144, vCores:5> cluster=<memory:32768, vCores:32>
2014-05-05 03:54:36,911 INFO org.apache.hadoop.yarn.server.resourcemanager.scheduler.capacity.ParentQueue: Re-sorting assigned queue: root.default stats: default: capacity=1.0, absoluteCapacity=1.0, usedResources=<memory:7168, vCores:6>usedCapacity=0.21875, absoluteUsedCapacity=0.21875, numApps=1, numContainers=6
2014-05-05 03:54:36,911 INFO org.apache.hadoop.yarn.server.resourcemanager.scheduler.capacity.ParentQueue: assignedContainer queue=root usedCapacity=0.21875 absoluteUsedCapacity=0.21875 used=<memory:7168, vCores:6> cluster=<memory:32768, vCores:32>
2014-05-05 03:54:36,930 INFO org.apache.hadoop.yarn.server.resourcemanager.rmcontainer.RMContainerImpl: container_1399261790270_0001_01_000005 Container Transitioned from RUNNING to COMPLETED
2014-05-05 03:54:36,930 INFO org.apache.hadoop.yarn.server.resourcemanager.scheduler.common.fica.FiCaSchedulerApp: Completed container: container_1399261790270_0001_01_000005 in state: COMPLETED event:FINISHED
2014-05-05 03:54:36,930 INFO org.apache.hadoop.yarn.server.resourcemanager.RMAuditLogger: USER=ubuntu	OPERATION=AM Released Container	TARGET=SchedulerApp	RESULT=SUCCESS	APPID=application_1399261790270_0001	CONTAINERID=container_1399261790270_0001_01_000005
2014-05-05 03:54:36,931 INFO org.apache.hadoop.yarn.server.resourcemanager.scheduler.common.fica.FiCaSchedulerNode: Released container container_1399261790270_0001_01_000005 of capacity <memory:1024, vCores:1> on host nodea:49324, which currently has 3 containers, <memory:3072, vCores:3> used and <memory:5120, vCores:5> available, release resources=true
2014-05-05 03:54:36,931 INFO org.apache.hadoop.yarn.server.resourcemanager.scheduler.capacity.LeafQueue: default used=<memory:6144, vCores:5> numContainers=5 user=ubuntu user-resources=<memory:6144, vCores:5>
2014-05-05 03:54:36,931 INFO org.apache.hadoop.yarn.server.resourcemanager.scheduler.capacity.LeafQueue: completedContainer container=Container: [ContainerId: container_1399261790270_0001_01_000005, NodeId: nodea:49324, NodeHttpAddress: nodea:8042, Resource: <memory:1024, vCores:1>, Priority: 20, Token: Token { kind: ContainerToken, service: 10.0.0.158:49324 }, ] resource=<memory:1024, vCores:1> queue=default: capacity=1.0, absoluteCapacity=1.0, usedResources=<memory:6144, vCores:5>usedCapacity=0.1875, absoluteUsedCapacity=0.1875, numApps=1, numContainers=5 usedCapacity=0.1875 absoluteUsedCapacity=0.1875 used=<memory:6144, vCores:5> cluster=<memory:32768, vCores:32>
2014-05-05 03:54:36,931 INFO org.apache.hadoop.yarn.server.resourcemanager.scheduler.capacity.ParentQueue: completedContainer queue=root usedCapacity=0.1875 absoluteUsedCapacity=0.1875 used=<memory:6144, vCores:5> cluster=<memory:32768, vCores:32>
2014-05-05 03:54:36,931 INFO org.apache.hadoop.yarn.server.resourcemanager.scheduler.capacity.ParentQueue: Re-sorting completed queue: root.default stats: default: capacity=1.0, absoluteCapacity=1.0, usedResources=<memory:6144, vCores:5>usedCapacity=0.1875, absoluteUsedCapacity=0.1875, numApps=1, numContainers=5
2014-05-05 03:54:36,931 INFO org.apache.hadoop.yarn.server.resourcemanager.scheduler.capacity.CapacityScheduler: Application appattempt_1399261790270_0001_000001 released container container_1399261790270_0001_01_000005 on node: host: nodea:49324 #containers=3 available=5120 used=3072 with event: FINISHED
2014-05-05 03:54:37,514 INFO org.apache.hadoop.yarn.server.resourcemanager.rmcontainer.RMContainerImpl: container_1399261790270_0001_01_000006 Container Transitioned from ALLOCATED to ACQUIRED
2014-05-05 03:54:37,936 INFO org.apache.hadoop.yarn.server.resourcemanager.rmcontainer.RMContainerImpl: container_1399261790270_0001_01_000007 Container Transitioned from NEW to ALLOCATED
2014-05-05 03:54:37,937 INFO org.apache.hadoop.yarn.server.resourcemanager.RMAuditLogger: USER=ubuntu	OPERATION=AM Allocated Container	TARGET=SchedulerApp	RESULT=SUCCESS	APPID=application_1399261790270_0001	CONTAINERID=container_1399261790270_0001_01_000007
2014-05-05 03:54:37,937 INFO org.apache.hadoop.yarn.server.resourcemanager.scheduler.common.fica.FiCaSchedulerNode: Assigned container container_1399261790270_0001_01_000007 of capacity <memory:1024, vCores:1> on host nodea:49324, which currently has 4 containers, <memory:4096, vCores:4> used and <memory:4096, vCores:4> available
2014-05-05 03:54:37,937 INFO org.apache.hadoop.yarn.server.resourcemanager.scheduler.capacity.LeafQueue: assignedContainer application=application_1399261790270_0001 container=Container: [ContainerId: container_1399261790270_0001_01_000007, NodeId: nodea:49324, NodeHttpAddress: nodea:8042, Resource: <memory:1024, vCores:1>, Priority: 10, Token: Token { kind: ContainerToken, service: 10.0.0.158:49324 }, ] containerId=container_1399261790270_0001_01_000007 queue=default: capacity=1.0, absoluteCapacity=1.0, usedResources=<memory:6144, vCores:5>usedCapacity=0.1875, absoluteUsedCapacity=0.1875, numApps=1, numContainers=5 usedCapacity=0.1875 absoluteUsedCapacity=0.1875 used=<memory:6144, vCores:5> cluster=<memory:32768, vCores:32>
2014-05-05 03:54:37,937 INFO org.apache.hadoop.yarn.server.resourcemanager.scheduler.capacity.ParentQueue: Re-sorting assigned queue: root.default stats: default: capacity=1.0, absoluteCapacity=1.0, usedResources=<memory:7168, vCores:6>usedCapacity=0.21875, absoluteUsedCapacity=0.21875, numApps=1, numContainers=6
2014-05-05 03:54:37,937 INFO org.apache.hadoop.yarn.server.resourcemanager.scheduler.capacity.ParentQueue: assignedContainer queue=root usedCapacity=0.21875 absoluteUsedCapacity=0.21875 used=<memory:7168, vCores:6> cluster=<memory:32768, vCores:32>
2014-05-05 03:54:37,938 INFO org.apache.hadoop.yarn.server.resourcemanager.rmcontainer.RMContainerImpl: container_1399261790270_0001_01_000008 Container Transitioned from NEW to ALLOCATED
2014-05-05 03:54:37,938 INFO org.apache.hadoop.yarn.server.resourcemanager.RMAuditLogger: USER=ubuntu	OPERATION=AM Allocated Container	TARGET=SchedulerApp	RESULT=SUCCESS	APPID=application_1399261790270_0001	CONTAINERID=container_1399261790270_0001_01_000008
2014-05-05 03:54:37,938 INFO org.apache.hadoop.yarn.server.resourcemanager.scheduler.common.fica.FiCaSchedulerNode: Assigned container container_1399261790270_0001_01_000008 of capacity <memory:1024, vCores:1> on host nodea:49324, which currently has 5 containers, <memory:5120, vCores:5> used and <memory:3072, vCores:3> available
2014-05-05 03:54:37,939 INFO org.apache.hadoop.yarn.server.resourcemanager.scheduler.capacity.LeafQueue: assignedContainer application=application_1399261790270_0001 container=Container: [ContainerId: container_1399261790270_0001_01_000008, NodeId: nodea:49324, NodeHttpAddress: nodea:8042, Resource: <memory:1024, vCores:1>, Priority: 10, Token: Token { kind: ContainerToken, service: 10.0.0.158:49324 }, ] containerId=container_1399261790270_0001_01_000008 queue=default: capacity=1.0, absoluteCapacity=1.0, usedResources=<memory:7168, vCores:6>usedCapacity=0.21875, absoluteUsedCapacity=0.21875, numApps=1, numContainers=6 usedCapacity=0.21875 absoluteUsedCapacity=0.21875 used=<memory:7168, vCores:6> cluster=<memory:32768, vCores:32>
2014-05-05 03:54:37,939 INFO org.apache.hadoop.yarn.server.resourcemanager.scheduler.capacity.ParentQueue: Re-sorting assigned queue: root.default stats: default: capacity=1.0, absoluteCapacity=1.0, usedResources=<memory:8192, vCores:7>usedCapacity=0.25, absoluteUsedCapacity=0.25, numApps=1, numContainers=7
2014-05-05 03:54:37,939 INFO org.apache.hadoop.yarn.server.resourcemanager.scheduler.capacity.ParentQueue: assignedContainer queue=root usedCapacity=0.25 absoluteUsedCapacity=0.25 used=<memory:8192, vCores:7> cluster=<memory:32768, vCores:32>
2014-05-05 03:54:37,946 INFO org.apache.hadoop.yarn.server.resourcemanager.rmcontainer.RMContainerImpl: container_1399261790270_0001_01_000006 Container Transitioned from ACQUIRED to RUNNING
2014-05-05 03:54:37,947 INFO org.apache.hadoop.yarn.server.resourcemanager.rmcontainer.RMContainerImpl: container_1399261790270_0001_01_000009 Container Transitioned from NEW to ALLOCATED
2014-05-05 03:54:37,947 INFO org.apache.hadoop.yarn.server.resourcemanager.RMAuditLogger: USER=ubuntu	OPERATION=AM Allocated Container	TARGET=SchedulerApp	RESULT=SUCCESS	APPID=application_1399261790270_0001	CONTAINERID=container_1399261790270_0001_01_000009
2014-05-05 03:54:37,947 INFO org.apache.hadoop.yarn.server.resourcemanager.scheduler.common.fica.FiCaSchedulerNode: Assigned container container_1399261790270_0001_01_000009 of capacity <memory:1024, vCores:1> on host nodeb:41344, which currently has 2 containers, <memory:2048, vCores:2> used and <memory:6144, vCores:6> available
2014-05-05 03:54:37,947 INFO org.apache.hadoop.yarn.server.resourcemanager.scheduler.capacity.LeafQueue: assignedContainer application=application_1399261790270_0001 container=Container: [ContainerId: container_1399261790270_0001_01_000009, NodeId: nodeb:41344, NodeHttpAddress: nodeb:8042, Resource: <memory:1024, vCores:1>, Priority: 10, Token: Token { kind: ContainerToken, service: 10.0.0.59:41344 }, ] containerId=container_1399261790270_0001_01_000009 queue=default: capacity=1.0, absoluteCapacity=1.0, usedResources=<memory:8192, vCores:7>usedCapacity=0.25, absoluteUsedCapacity=0.25, numApps=1, numContainers=7 usedCapacity=0.25 absoluteUsedCapacity=0.25 used=<memory:8192, vCores:7> cluster=<memory:32768, vCores:32>
2014-05-05 03:54:37,947 INFO org.apache.hadoop.yarn.server.resourcemanager.scheduler.capacity.ParentQueue: Re-sorting assigned queue: root.default stats: default: capacity=1.0, absoluteCapacity=1.0, usedResources=<memory:9216, vCores:8>usedCapacity=0.28125, absoluteUsedCapacity=0.28125, numApps=1, numContainers=8
2014-05-05 03:54:37,948 INFO org.apache.hadoop.yarn.server.resourcemanager.scheduler.capacity.ParentQueue: assignedContainer queue=root usedCapacity=0.28125 absoluteUsedCapacity=0.28125 used=<memory:9216, vCores:8> cluster=<memory:32768, vCores:32>
2014-05-05 03:54:37,968 INFO org.apache.hadoop.yarn.server.resourcemanager.rmcontainer.RMContainerImpl: container_1399261790270_0001_01_000010 Container Transitioned from NEW to ALLOCATED
2014-05-05 03:54:37,968 INFO org.apache.hadoop.yarn.server.resourcemanager.RMAuditLogger: USER=ubuntu	OPERATION=AM Allocated Container	TARGET=SchedulerApp	RESULT=SUCCESS	APPID=application_1399261790270_0001	CONTAINERID=container_1399261790270_0001_01_000010
2014-05-05 03:54:37,968 INFO org.apache.hadoop.yarn.server.resourcemanager.scheduler.common.fica.FiCaSchedulerNode: Assigned container container_1399261790270_0001_01_000010 of capacity <memory:1024, vCores:1> on host nodeb:41344, which currently has 3 containers, <memory:3072, vCores:3> used and <memory:5120, vCores:5> available
2014-05-05 03:54:37,968 INFO org.apache.hadoop.yarn.server.resourcemanager.scheduler.capacity.LeafQueue: assignedContainer application=application_1399261790270_0001 container=Container: [ContainerId: container_1399261790270_0001_01_000010, NodeId: nodeb:41344, NodeHttpAddress: nodeb:8042, Resource: <memory:1024, vCores:1>, Priority: 10, Token: Token { kind: ContainerToken, service: 10.0.0.59:41344 }, ] containerId=container_1399261790270_0001_01_000010 queue=default: capacity=1.0, absoluteCapacity=1.0, usedResources=<memory:9216, vCores:8>usedCapacity=0.28125, absoluteUsedCapacity=0.28125, numApps=1, numContainers=8 usedCapacity=0.28125 absoluteUsedCapacity=0.28125 used=<memory:9216, vCores:8> cluster=<memory:32768, vCores:32>
2014-05-05 03:54:37,968 INFO org.apache.hadoop.yarn.server.resourcemanager.scheduler.capacity.ParentQueue: Re-sorting assigned queue: root.default stats: default: capacity=1.0, absoluteCapacity=1.0, usedResources=<memory:10240, vCores:9>usedCapacity=0.3125, absoluteUsedCapacity=0.3125, numApps=1, numContainers=9
2014-05-05 03:54:37,969 INFO org.apache.hadoop.yarn.server.resourcemanager.scheduler.capacity.ParentQueue: assignedContainer queue=root usedCapacity=0.3125 absoluteUsedCapacity=0.3125 used=<memory:10240, vCores:9> cluster=<memory:32768, vCores:32>
2014-05-05 03:54:37,976 INFO org.apache.hadoop.yarn.server.resourcemanager.rmcontainer.RMContainerImpl: container_1399261790270_0001_01_000011 Container Transitioned from NEW to ALLOCATED
2014-05-05 03:54:37,976 INFO org.apache.hadoop.yarn.server.resourcemanager.RMAuditLogger: USER=ubuntu	OPERATION=AM Allocated Container	TARGET=SchedulerApp	RESULT=SUCCESS	APPID=application_1399261790270_0001	CONTAINERID=container_1399261790270_0001_01_000011
2014-05-05 03:54:37,976 INFO org.apache.hadoop.yarn.server.resourcemanager.scheduler.common.fica.FiCaSchedulerNode: Assigned container container_1399261790270_0001_01_000011 of capacity <memory:1024, vCores:1> on host nodec:51351, which currently has 1 containers, <memory:1024, vCores:1> used and <memory:7168, vCores:7> available
2014-05-05 03:54:37,977 INFO org.apache.hadoop.yarn.server.resourcemanager.scheduler.capacity.LeafQueue: assignedContainer application=application_1399261790270_0001 container=Container: [ContainerId: container_1399261790270_0001_01_000011, NodeId: nodec:51351, NodeHttpAddress: nodec:8042, Resource: <memory:1024, vCores:1>, Priority: 10, Token: Token { kind: ContainerToken, service: 10.0.0.181:51351 }, ] containerId=container_1399261790270_0001_01_000011 queue=default: capacity=1.0, absoluteCapacity=1.0, usedResources=<memory:10240, vCores:9>usedCapacity=0.3125, absoluteUsedCapacity=0.3125, numApps=1, numContainers=9 usedCapacity=0.3125 absoluteUsedCapacity=0.3125 used=<memory:10240, vCores:9> cluster=<memory:32768, vCores:32>
2014-05-05 03:54:37,977 INFO org.apache.hadoop.yarn.server.resourcemanager.scheduler.capacity.ParentQueue: Re-sorting assigned queue: root.default stats: default: capacity=1.0, absoluteCapacity=1.0, usedResources=<memory:11264, vCores:10>usedCapacity=0.34375, absoluteUsedCapacity=0.34375, numApps=1, numContainers=10
2014-05-05 03:54:37,977 INFO org.apache.hadoop.yarn.server.resourcemanager.scheduler.capacity.ParentQueue: assignedContainer queue=root usedCapacity=0.34375 absoluteUsedCapacity=0.34375 used=<memory:11264, vCores:10> cluster=<memory:32768, vCores:32>
2014-05-05 03:54:37,978 INFO org.apache.hadoop.yarn.server.resourcemanager.rmcontainer.RMContainerImpl: container_1399261790270_0001_01_000012 Container Transitioned from NEW to ALLOCATED
2014-05-05 03:54:37,978 INFO org.apache.hadoop.yarn.server.resourcemanager.RMAuditLogger: USER=ubuntu	OPERATION=AM Allocated Container	TARGET=SchedulerApp	RESULT=SUCCESS	APPID=application_1399261790270_0001	CONTAINERID=container_1399261790270_0001_01_000012
2014-05-05 03:54:37,978 INFO org.apache.hadoop.yarn.server.resourcemanager.scheduler.common.fica.FiCaSchedulerNode: Assigned container container_1399261790270_0001_01_000012 of capacity <memory:1024, vCores:1> on host nodec:51351, which currently has 2 containers, <memory:2048, vCores:2> used and <memory:6144, vCores:6> available
2014-05-05 03:54:37,978 INFO org.apache.hadoop.yarn.server.resourcemanager.scheduler.capacity.LeafQueue: assignedContainer application=application_1399261790270_0001 container=Container: [ContainerId: container_1399261790270_0001_01_000012, NodeId: nodec:51351, NodeHttpAddress: nodec:8042, Resource: <memory:1024, vCores:1>, Priority: 10, Token: Token { kind: ContainerToken, service: 10.0.0.181:51351 }, ] containerId=container_1399261790270_0001_01_000012 queue=default: capacity=1.0, absoluteCapacity=1.0, usedResources=<memory:11264, vCores:10>usedCapacity=0.34375, absoluteUsedCapacity=0.34375, numApps=1, numContainers=10 usedCapacity=0.34375 absoluteUsedCapacity=0.34375 used=<memory:11264, vCores:10> cluster=<memory:32768, vCores:32>
2014-05-05 03:54:37,979 INFO org.apache.hadoop.yarn.server.resourcemanager.scheduler.capacity.ParentQueue: Re-sorting assigned queue: root.default stats: default: capacity=1.0, absoluteCapacity=1.0, usedResources=<memory:12288, vCores:11>usedCapacity=0.375, absoluteUsedCapacity=0.375, numApps=1, numContainers=11
2014-05-05 03:54:37,979 INFO org.apache.hadoop.yarn.server.resourcemanager.scheduler.capacity.ParentQueue: assignedContainer queue=root usedCapacity=0.375 absoluteUsedCapacity=0.375 used=<memory:12288, vCores:11> cluster=<memory:32768, vCores:32>
2014-05-05 03:54:38,061 INFO org.apache.hadoop.yarn.server.resourcemanager.rmcontainer.RMContainerImpl: container_1399261790270_0001_01_000013 Container Transitioned from NEW to ALLOCATED
2014-05-05 03:54:38,062 INFO org.apache.hadoop.yarn.server.resourcemanager.RMAuditLogger: USER=ubuntu	OPERATION=AM Allocated Container	TARGET=SchedulerApp	RESULT=SUCCESS	APPID=application_1399261790270_0001	CONTAINERID=container_1399261790270_0001_01_000013
2014-05-05 03:54:38,062 INFO org.apache.hadoop.yarn.server.resourcemanager.scheduler.common.fica.FiCaSchedulerNode: Assigned container container_1399261790270_0001_01_000013 of capacity <memory:1024, vCores:1> on host noded:54001, which currently has 2 containers, <memory:3072, vCores:2> used and <memory:5120, vCores:6> available
2014-05-05 03:54:38,062 INFO org.apache.hadoop.yarn.server.resourcemanager.scheduler.capacity.LeafQueue: assignedContainer application=application_1399261790270_0001 container=Container: [ContainerId: container_1399261790270_0001_01_000013, NodeId: noded:54001, NodeHttpAddress: noded:8042, Resource: <memory:1024, vCores:1>, Priority: 10, Token: Token { kind: ContainerToken, service: 10.0.0.180:54001 }, ] containerId=container_1399261790270_0001_01_000013 queue=default: capacity=1.0, absoluteCapacity=1.0, usedResources=<memory:12288, vCores:11>usedCapacity=0.375, absoluteUsedCapacity=0.375, numApps=1, numContainers=11 usedCapacity=0.375 absoluteUsedCapacity=0.375 used=<memory:12288, vCores:11> cluster=<memory:32768, vCores:32>
2014-05-05 03:54:38,062 INFO org.apache.hadoop.yarn.server.resourcemanager.scheduler.capacity.ParentQueue: Re-sorting assigned queue: root.default stats: default: capacity=1.0, absoluteCapacity=1.0, usedResources=<memory:13312, vCores:12>usedCapacity=0.40625, absoluteUsedCapacity=0.40625, numApps=1, numContainers=12
2014-05-05 03:54:38,062 INFO org.apache.hadoop.yarn.server.resourcemanager.scheduler.capacity.ParentQueue: assignedContainer queue=root usedCapacity=0.40625 absoluteUsedCapacity=0.40625 used=<memory:13312, vCores:12> cluster=<memory:32768, vCores:32>
2014-05-05 03:54:38,063 INFO org.apache.hadoop.yarn.server.resourcemanager.rmcontainer.RMContainerImpl: container_1399261790270_0001_01_000014 Container Transitioned from NEW to ALLOCATED
2014-05-05 03:54:38,063 INFO org.apache.hadoop.yarn.server.resourcemanager.RMAuditLogger: USER=ubuntu	OPERATION=AM Allocated Container	TARGET=SchedulerApp	RESULT=SUCCESS	APPID=application_1399261790270_0001	CONTAINERID=container_1399261790270_0001_01_000014
2014-05-05 03:54:38,063 INFO org.apache.hadoop.yarn.server.resourcemanager.scheduler.common.fica.FiCaSchedulerNode: Assigned container container_1399261790270_0001_01_000014 of capacity <memory:1024, vCores:1> on host noded:54001, which currently has 3 containers, <memory:4096, vCores:3> used and <memory:4096, vCores:5> available
2014-05-05 03:54:38,064 INFO org.apache.hadoop.yarn.server.resourcemanager.scheduler.capacity.LeafQueue: assignedContainer application=application_1399261790270_0001 container=Container: [ContainerId: container_1399261790270_0001_01_000014, NodeId: noded:54001, NodeHttpAddress: noded:8042, Resource: <memory:1024, vCores:1>, Priority: 10, Token: Token { kind: ContainerToken, service: 10.0.0.180:54001 }, ] containerId=container_1399261790270_0001_01_000014 queue=default: capacity=1.0, absoluteCapacity=1.0, usedResources=<memory:13312, vCores:12>usedCapacity=0.40625, absoluteUsedCapacity=0.40625, numApps=1, numContainers=12 usedCapacity=0.40625 absoluteUsedCapacity=0.40625 used=<memory:13312, vCores:12> cluster=<memory:32768, vCores:32>
2014-05-05 03:54:38,064 INFO org.apache.hadoop.yarn.server.resourcemanager.scheduler.capacity.ParentQueue: Re-sorting assigned queue: root.default stats: default: capacity=1.0, absoluteCapacity=1.0, usedResources=<memory:14336, vCores:13>usedCapacity=0.4375, absoluteUsedCapacity=0.4375, numApps=1, numContainers=13
2014-05-05 03:54:38,064 INFO org.apache.hadoop.yarn.server.resourcemanager.scheduler.capacity.ParentQueue: assignedContainer queue=root usedCapacity=0.4375 absoluteUsedCapacity=0.4375 used=<memory:14336, vCores:13> cluster=<memory:32768, vCores:32>
2014-05-05 03:54:38,525 INFO org.apache.hadoop.yarn.server.resourcemanager.scheduler.AppSchedulingInfo: checking for deactivate... 
2014-05-05 03:54:38,526 INFO org.apache.hadoop.yarn.server.resourcemanager.rmcontainer.RMContainerImpl: container_1399261790270_0001_01_000007 Container Transitioned from ALLOCATED to ACQUIRED
2014-05-05 03:54:38,526 INFO org.apache.hadoop.yarn.server.resourcemanager.rmcontainer.RMContainerImpl: container_1399261790270_0001_01_000008 Container Transitioned from ALLOCATED to ACQUIRED
2014-05-05 03:54:38,527 INFO org.apache.hadoop.yarn.server.resourcemanager.rmcontainer.RMContainerImpl: container_1399261790270_0001_01_000009 Container Transitioned from ALLOCATED to ACQUIRED
2014-05-05 03:54:38,527 INFO org.apache.hadoop.yarn.server.resourcemanager.rmcontainer.RMContainerImpl: container_1399261790270_0001_01_000010 Container Transitioned from ALLOCATED to ACQUIRED
2014-05-05 03:54:38,528 INFO org.apache.hadoop.yarn.server.resourcemanager.rmcontainer.RMContainerImpl: container_1399261790270_0001_01_000011 Container Transitioned from ALLOCATED to ACQUIRED
2014-05-05 03:54:38,528 INFO org.apache.hadoop.yarn.server.resourcemanager.rmcontainer.RMContainerImpl: container_1399261790270_0001_01_000012 Container Transitioned from ALLOCATED to ACQUIRED
2014-05-05 03:54:38,528 INFO org.apache.hadoop.yarn.server.resourcemanager.rmcontainer.RMContainerImpl: container_1399261790270_0001_01_000013 Container Transitioned from ALLOCATED to ACQUIRED
2014-05-05 03:54:38,528 INFO org.apache.hadoop.yarn.server.resourcemanager.rmcontainer.RMContainerImpl: container_1399261790270_0001_01_000014 Container Transitioned from ALLOCATED to ACQUIRED
2014-05-05 03:54:38,940 INFO org.apache.hadoop.yarn.server.resourcemanager.rmcontainer.RMContainerImpl: container_1399261790270_0001_01_000007 Container Transitioned from ACQUIRED to RUNNING
2014-05-05 03:54:38,940 INFO org.apache.hadoop.yarn.server.resourcemanager.rmcontainer.RMContainerImpl: container_1399261790270_0001_01_000008 Container Transitioned from ACQUIRED to RUNNING
2014-05-05 03:54:38,956 INFO org.apache.hadoop.yarn.server.resourcemanager.rmcontainer.RMContainerImpl: container_1399261790270_0001_01_000009 Container Transitioned from ACQUIRED to RUNNING
2014-05-05 03:54:38,956 INFO org.apache.hadoop.yarn.server.resourcemanager.rmcontainer.RMContainerImpl: container_1399261790270_0001_01_000010 Container Transitioned from ACQUIRED to RUNNING
2014-05-05 03:54:39,024 INFO org.apache.hadoop.yarn.server.resourcemanager.rmcontainer.RMContainerImpl: container_1399261790270_0001_01_000011 Container Transitioned from ACQUIRED to RUNNING
2014-05-05 03:54:39,024 INFO org.apache.hadoop.yarn.server.resourcemanager.rmcontainer.RMContainerImpl: container_1399261790270_0001_01_000012 Container Transitioned from ACQUIRED to RUNNING
2014-05-05 03:54:39,064 INFO org.apache.hadoop.yarn.server.resourcemanager.rmcontainer.RMContainerImpl: container_1399261790270_0001_01_000013 Container Transitioned from ACQUIRED to RUNNING
2014-05-05 03:54:39,064 INFO org.apache.hadoop.yarn.server.resourcemanager.rmcontainer.RMContainerImpl: container_1399261790270_0001_01_000014 Container Transitioned from ACQUIRED to RUNNING
2014-05-05 03:54:39,538 INFO org.apache.hadoop.yarn.server.resourcemanager.scheduler.AppSchedulingInfo: checking for deactivate... 
2014-05-05 03:54:52,084 INFO org.apache.hadoop.yarn.server.resourcemanager.rmcontainer.RMContainerImpl: container_1399261790270_0001_01_000002 Container Transitioned from RUNNING to COMPLETED
2014-05-05 03:54:52,084 INFO org.apache.hadoop.yarn.server.resourcemanager.scheduler.common.fica.FiCaSchedulerApp: Completed container: container_1399261790270_0001_01_000002 in state: COMPLETED event:FINISHED
2014-05-05 03:54:52,085 INFO org.apache.hadoop.yarn.server.resourcemanager.RMAuditLogger: USER=ubuntu	OPERATION=AM Released Container	TARGET=SchedulerApp	RESULT=SUCCESS	APPID=application_1399261790270_0001	CONTAINERID=container_1399261790270_0001_01_000002
2014-05-05 03:54:52,085 INFO org.apache.hadoop.yarn.server.resourcemanager.scheduler.common.fica.FiCaSchedulerNode: Released container container_1399261790270_0001_01_000002 of capacity <memory:1024, vCores:1> on host nodea:49324, which currently has 4 containers, <memory:4096, vCores:4> used and <memory:4096, vCores:4> available, release resources=true
2014-05-05 03:54:52,085 INFO org.apache.hadoop.yarn.server.resourcemanager.scheduler.capacity.LeafQueue: default used=<memory:13312, vCores:12> numContainers=12 user=ubuntu user-resources=<memory:13312, vCores:12>
2014-05-05 03:54:52,085 INFO org.apache.hadoop.yarn.server.resourcemanager.scheduler.capacity.LeafQueue: completedContainer container=Container: [ContainerId: container_1399261790270_0001_01_000002, NodeId: nodea:49324, NodeHttpAddress: nodea:8042, Resource: <memory:1024, vCores:1>, Priority: 20, Token: Token { kind: ContainerToken, service: 10.0.0.158:49324 }, ] resource=<memory:1024, vCores:1> queue=default: capacity=1.0, absoluteCapacity=1.0, usedResources=<memory:13312, vCores:12>usedCapacity=0.40625, absoluteUsedCapacity=0.40625, numApps=1, numContainers=12 usedCapacity=0.40625 absoluteUsedCapacity=0.40625 used=<memory:13312, vCores:12> cluster=<memory:32768, vCores:32>
2014-05-05 03:54:52,085 INFO org.apache.hadoop.yarn.server.resourcemanager.scheduler.capacity.ParentQueue: completedContainer queue=root usedCapacity=0.40625 absoluteUsedCapacity=0.40625 used=<memory:13312, vCores:12> cluster=<memory:32768, vCores:32>
2014-05-05 03:54:52,086 INFO org.apache.hadoop.yarn.server.resourcemanager.scheduler.capacity.ParentQueue: Re-sorting completed queue: root.default stats: default: capacity=1.0, absoluteCapacity=1.0, usedResources=<memory:13312, vCores:12>usedCapacity=0.40625, absoluteUsedCapacity=0.40625, numApps=1, numContainers=12
2014-05-05 03:54:52,086 INFO org.apache.hadoop.yarn.server.resourcemanager.scheduler.capacity.CapacityScheduler: Application appattempt_1399261790270_0001_000001 released container container_1399261790270_0001_01_000002 on node: host: nodea:49324 #containers=4 available=4096 used=4096 with event: FINISHED
2014-05-05 03:54:54,260 INFO org.apache.hadoop.yarn.server.resourcemanager.rmcontainer.RMContainerImpl: container_1399261790270_0001_01_000003 Container Transitioned from RUNNING to COMPLETED
2014-05-05 03:54:54,260 INFO org.apache.hadoop.yarn.server.resourcemanager.scheduler.common.fica.FiCaSchedulerApp: Completed container: container_1399261790270_0001_01_000003 in state: COMPLETED event:FINISHED
2014-05-05 03:54:54,260 INFO org.apache.hadoop.yarn.server.resourcemanager.RMAuditLogger: USER=ubuntu	OPERATION=AM Released Container	TARGET=SchedulerApp	RESULT=SUCCESS	APPID=application_1399261790270_0001	CONTAINERID=container_1399261790270_0001_01_000003
2014-05-05 03:54:54,260 INFO org.apache.hadoop.yarn.server.resourcemanager.scheduler.common.fica.FiCaSchedulerNode: Released container container_1399261790270_0001_01_000003 of capacity <memory:1024, vCores:1> on host nodea:49324, which currently has 3 containers, <memory:3072, vCores:3> used and <memory:5120, vCores:5> available, release resources=true
2014-05-05 03:54:54,260 INFO org.apache.hadoop.yarn.server.resourcemanager.scheduler.capacity.LeafQueue: default used=<memory:12288, vCores:11> numContainers=11 user=ubuntu user-resources=<memory:12288, vCores:11>
2014-05-05 03:54:54,260 INFO org.apache.hadoop.yarn.server.resourcemanager.scheduler.capacity.LeafQueue: completedContainer container=Container: [ContainerId: container_1399261790270_0001_01_000003, NodeId: nodea:49324, NodeHttpAddress: nodea:8042, Resource: <memory:1024, vCores:1>, Priority: 20, Token: Token { kind: ContainerToken, service: 10.0.0.158:49324 }, ] resource=<memory:1024, vCores:1> queue=default: capacity=1.0, absoluteCapacity=1.0, usedResources=<memory:12288, vCores:11>usedCapacity=0.375, absoluteUsedCapacity=0.375, numApps=1, numContainers=11 usedCapacity=0.375 absoluteUsedCapacity=0.375 used=<memory:12288, vCores:11> cluster=<memory:32768, vCores:32>
2014-05-05 03:54:54,261 INFO org.apache.hadoop.yarn.server.resourcemanager.scheduler.capacity.ParentQueue: completedContainer queue=root usedCapacity=0.375 absoluteUsedCapacity=0.375 used=<memory:12288, vCores:11> cluster=<memory:32768, vCores:32>
2014-05-05 03:54:54,261 INFO org.apache.hadoop.yarn.server.resourcemanager.scheduler.capacity.ParentQueue: Re-sorting completed queue: root.default stats: default: capacity=1.0, absoluteCapacity=1.0, usedResources=<memory:12288, vCores:11>usedCapacity=0.375, absoluteUsedCapacity=0.375, numApps=1, numContainers=11
2014-05-05 03:54:54,261 INFO org.apache.hadoop.yarn.server.resourcemanager.scheduler.capacity.CapacityScheduler: Application appattempt_1399261790270_0001_000001 released container container_1399261790270_0001_01_000003 on node: host: nodea:49324 #containers=3 available=5120 used=3072 with event: FINISHED
2014-05-05 03:54:54,261 INFO org.apache.hadoop.yarn.server.resourcemanager.rmcontainer.RMContainerImpl: container_1399261790270_0001_01_000004 Container Transitioned from RUNNING to COMPLETED
2014-05-05 03:54:54,261 INFO org.apache.hadoop.yarn.server.resourcemanager.scheduler.common.fica.FiCaSchedulerApp: Completed container: container_1399261790270_0001_01_000004 in state: COMPLETED event:FINISHED
2014-05-05 03:54:54,261 INFO org.apache.hadoop.yarn.server.resourcemanager.RMAuditLogger: USER=ubuntu	OPERATION=AM Released Container	TARGET=SchedulerApp	RESULT=SUCCESS	APPID=application_1399261790270_0001	CONTAINERID=container_1399261790270_0001_01_000004
2014-05-05 03:54:54,261 INFO org.apache.hadoop.yarn.server.resourcemanager.scheduler.common.fica.FiCaSchedulerNode: Released container container_1399261790270_0001_01_000004 of capacity <memory:1024, vCores:1> on host nodea:49324, which currently has 2 containers, <memory:2048, vCores:2> used and <memory:6144, vCores:6> available, release resources=true
2014-05-05 03:54:54,262 INFO org.apache.hadoop.yarn.server.resourcemanager.scheduler.capacity.LeafQueue: default used=<memory:11264, vCores:10> numContainers=10 user=ubuntu user-resources=<memory:11264, vCores:10>
2014-05-05 03:54:54,262 INFO org.apache.hadoop.yarn.server.resourcemanager.scheduler.capacity.LeafQueue: completedContainer container=Container: [ContainerId: container_1399261790270_0001_01_000004, NodeId: nodea:49324, NodeHttpAddress: nodea:8042, Resource: <memory:1024, vCores:1>, Priority: 20, Token: Token { kind: ContainerToken, service: 10.0.0.158:49324 }, ] resource=<memory:1024, vCores:1> queue=default: capacity=1.0, absoluteCapacity=1.0, usedResources=<memory:11264, vCores:10>usedCapacity=0.34375, absoluteUsedCapacity=0.34375, numApps=1, numContainers=10 usedCapacity=0.34375 absoluteUsedCapacity=0.34375 used=<memory:11264, vCores:10> cluster=<memory:32768, vCores:32>
2014-05-05 03:54:54,264 INFO org.apache.hadoop.yarn.server.resourcemanager.scheduler.capacity.ParentQueue: completedContainer queue=root usedCapacity=0.34375 absoluteUsedCapacity=0.34375 used=<memory:11264, vCores:10> cluster=<memory:32768, vCores:32>
2014-05-05 03:54:54,264 INFO org.apache.hadoop.yarn.server.resourcemanager.scheduler.capacity.ParentQueue: Re-sorting completed queue: root.default stats: default: capacity=1.0, absoluteCapacity=1.0, usedResources=<memory:11264, vCores:10>usedCapacity=0.34375, absoluteUsedCapacity=0.34375, numApps=1, numContainers=10
2014-05-05 03:54:54,264 INFO org.apache.hadoop.yarn.server.resourcemanager.scheduler.capacity.CapacityScheduler: Application appattempt_1399261790270_0001_000001 released container container_1399261790270_0001_01_000004 on node: host: nodea:49324 #containers=2 available=6144 used=2048 with event: FINISHED
2014-05-05 03:54:54,268 INFO org.apache.hadoop.yarn.server.resourcemanager.rmcontainer.RMContainerImpl: container_1399261790270_0001_01_000006 Container Transitioned from RUNNING to COMPLETED
2014-05-05 03:54:54,268 INFO org.apache.hadoop.yarn.server.resourcemanager.scheduler.common.fica.FiCaSchedulerApp: Completed container: container_1399261790270_0001_01_000006 in state: COMPLETED event:FINISHED
2014-05-05 03:54:54,268 INFO org.apache.hadoop.yarn.server.resourcemanager.RMAuditLogger: USER=ubuntu	OPERATION=AM Released Container	TARGET=SchedulerApp	RESULT=SUCCESS	APPID=application_1399261790270_0001	CONTAINERID=container_1399261790270_0001_01_000006
2014-05-05 03:54:54,268 INFO org.apache.hadoop.yarn.server.resourcemanager.scheduler.common.fica.FiCaSchedulerNode: Released container container_1399261790270_0001_01_000006 of capacity <memory:1024, vCores:1> on host nodeb:41344, which currently has 2 containers, <memory:2048, vCores:2> used and <memory:6144, vCores:6> available, release resources=true
2014-05-05 03:54:54,268 INFO org.apache.hadoop.yarn.server.resourcemanager.scheduler.capacity.LeafQueue: default used=<memory:10240, vCores:9> numContainers=9 user=ubuntu user-resources=<memory:10240, vCores:9>
2014-05-05 03:54:54,268 INFO org.apache.hadoop.yarn.server.resourcemanager.scheduler.capacity.LeafQueue: completedContainer container=Container: [ContainerId: container_1399261790270_0001_01_000006, NodeId: nodeb:41344, NodeHttpAddress: nodeb:8042, Resource: <memory:1024, vCores:1>, Priority: 20, Token: Token { kind: ContainerToken, service: 10.0.0.59:41344 }, ] resource=<memory:1024, vCores:1> queue=default: capacity=1.0, absoluteCapacity=1.0, usedResources=<memory:10240, vCores:9>usedCapacity=0.3125, absoluteUsedCapacity=0.3125, numApps=1, numContainers=9 usedCapacity=0.3125 absoluteUsedCapacity=0.3125 used=<memory:10240, vCores:9> cluster=<memory:32768, vCores:32>
2014-05-05 03:54:54,268 INFO org.apache.hadoop.yarn.server.resourcemanager.scheduler.capacity.ParentQueue: completedContainer queue=root usedCapacity=0.3125 absoluteUsedCapacity=0.3125 used=<memory:10240, vCores:9> cluster=<memory:32768, vCores:32>
2014-05-05 03:54:54,269 INFO org.apache.hadoop.yarn.server.resourcemanager.scheduler.capacity.ParentQueue: Re-sorting completed queue: root.default stats: default: capacity=1.0, absoluteCapacity=1.0, usedResources=<memory:10240, vCores:9>usedCapacity=0.3125, absoluteUsedCapacity=0.3125, numApps=1, numContainers=9
2014-05-05 03:54:54,269 INFO org.apache.hadoop.yarn.server.resourcemanager.scheduler.capacity.CapacityScheduler: Application appattempt_1399261790270_0001_000001 released container container_1399261790270_0001_01_000006 on node: host: nodeb:41344 #containers=2 available=6144 used=2048 with event: FINISHED
2014-05-05 03:56:36,948 INFO org.apache.hadoop.yarn.server.resourcemanager.rmcontainer.RMContainerImpl: container_1399261790270_0001_01_000011 Container Transitioned from RUNNING to COMPLETED
2014-05-05 03:56:36,948 INFO org.apache.hadoop.yarn.server.resourcemanager.scheduler.common.fica.FiCaSchedulerApp: Completed container: container_1399261790270_0001_01_000011 in state: COMPLETED event:FINISHED
2014-05-05 03:56:36,948 INFO org.apache.hadoop.yarn.server.resourcemanager.RMAuditLogger: USER=ubuntu	OPERATION=AM Released Container	TARGET=SchedulerApp	RESULT=SUCCESS	APPID=application_1399261790270_0001	CONTAINERID=container_1399261790270_0001_01_000011
2014-05-05 03:56:36,948 INFO org.apache.hadoop.yarn.server.resourcemanager.scheduler.common.fica.FiCaSchedulerNode: Released container container_1399261790270_0001_01_000011 of capacity <memory:1024, vCores:1> on host nodec:51351, which currently has 1 containers, <memory:1024, vCores:1> used and <memory:7168, vCores:7> available, release resources=true
2014-05-05 03:56:36,948 INFO org.apache.hadoop.yarn.server.resourcemanager.scheduler.capacity.LeafQueue: default used=<memory:9216, vCores:8> numContainers=8 user=ubuntu user-resources=<memory:9216, vCores:8>
2014-05-05 03:56:36,948 INFO org.apache.hadoop.yarn.server.resourcemanager.scheduler.capacity.LeafQueue: completedContainer container=Container: [ContainerId: container_1399261790270_0001_01_000011, NodeId: nodec:51351, NodeHttpAddress: nodec:8042, Resource: <memory:1024, vCores:1>, Priority: 10, Token: Token { kind: ContainerToken, service: 10.0.0.181:51351 }, ] resource=<memory:1024, vCores:1> queue=default: capacity=1.0, absoluteCapacity=1.0, usedResources=<memory:9216, vCores:8>usedCapacity=0.28125, absoluteUsedCapacity=0.28125, numApps=1, numContainers=8 usedCapacity=0.28125 absoluteUsedCapacity=0.28125 used=<memory:9216, vCores:8> cluster=<memory:32768, vCores:32>
2014-05-05 03:56:36,948 INFO org.apache.hadoop.yarn.server.resourcemanager.scheduler.capacity.ParentQueue: completedContainer queue=root usedCapacity=0.28125 absoluteUsedCapacity=0.28125 used=<memory:9216, vCores:8> cluster=<memory:32768, vCores:32>
2014-05-05 03:56:36,948 INFO org.apache.hadoop.yarn.server.resourcemanager.scheduler.capacity.ParentQueue: Re-sorting completed queue: root.default stats: default: capacity=1.0, absoluteCapacity=1.0, usedResources=<memory:9216, vCores:8>usedCapacity=0.28125, absoluteUsedCapacity=0.28125, numApps=1, numContainers=8
2014-05-05 03:56:36,948 INFO org.apache.hadoop.yarn.server.resourcemanager.scheduler.capacity.CapacityScheduler: Application appattempt_1399261790270_0001_000001 released container container_1399261790270_0001_01_000011 on node: host: nodec:51351 #containers=1 available=7168 used=1024 with event: FINISHED
2014-05-05 03:56:37,950 INFO org.apache.hadoop.yarn.server.resourcemanager.rmcontainer.RMContainerImpl: container_1399261790270_0001_01_000012 Container Transitioned from RUNNING to COMPLETED
2014-05-05 03:56:37,950 INFO org.apache.hadoop.yarn.server.resourcemanager.scheduler.common.fica.FiCaSchedulerApp: Completed container: container_1399261790270_0001_01_000012 in state: COMPLETED event:FINISHED
2014-05-05 03:56:37,950 INFO org.apache.hadoop.yarn.server.resourcemanager.RMAuditLogger: USER=ubuntu	OPERATION=AM Released Container	TARGET=SchedulerApp	RESULT=SUCCESS	APPID=application_1399261790270_0001	CONTAINERID=container_1399261790270_0001_01_000012
2014-05-05 03:56:37,950 INFO org.apache.hadoop.yarn.server.resourcemanager.scheduler.common.fica.FiCaSchedulerNode: Released container container_1399261790270_0001_01_000012 of capacity <memory:1024, vCores:1> on host nodec:51351, which currently has 0 containers, <memory:0, vCores:0> used and <memory:8192, vCores:8> available, release resources=true
2014-05-05 03:56:37,950 INFO org.apache.hadoop.yarn.server.resourcemanager.scheduler.capacity.LeafQueue: default used=<memory:8192, vCores:7> numContainers=7 user=ubuntu user-resources=<memory:8192, vCores:7>
2014-05-05 03:56:37,951 INFO org.apache.hadoop.yarn.server.resourcemanager.scheduler.capacity.LeafQueue: completedContainer container=Container: [ContainerId: container_1399261790270_0001_01_000012, NodeId: nodec:51351, NodeHttpAddress: nodec:8042, Resource: <memory:1024, vCores:1>, Priority: 10, Token: Token { kind: ContainerToken, service: 10.0.0.181:51351 }, ] resource=<memory:1024, vCores:1> queue=default: capacity=1.0, absoluteCapacity=1.0, usedResources=<memory:8192, vCores:7>usedCapacity=0.25, absoluteUsedCapacity=0.25, numApps=1, numContainers=7 usedCapacity=0.25 absoluteUsedCapacity=0.25 used=<memory:8192, vCores:7> cluster=<memory:32768, vCores:32>
2014-05-05 03:56:37,951 INFO org.apache.hadoop.yarn.server.resourcemanager.scheduler.capacity.ParentQueue: completedContainer queue=root usedCapacity=0.25 absoluteUsedCapacity=0.25 used=<memory:8192, vCores:7> cluster=<memory:32768, vCores:32>
2014-05-05 03:56:37,951 INFO org.apache.hadoop.yarn.server.resourcemanager.scheduler.capacity.ParentQueue: Re-sorting completed queue: root.default stats: default: capacity=1.0, absoluteCapacity=1.0, usedResources=<memory:8192, vCores:7>usedCapacity=0.25, absoluteUsedCapacity=0.25, numApps=1, numContainers=7
2014-05-05 03:56:37,951 INFO org.apache.hadoop.yarn.server.resourcemanager.scheduler.capacity.CapacityScheduler: Application appattempt_1399261790270_0001_000001 released container container_1399261790270_0001_01_000012 on node: host: nodec:51351 #containers=0 available=8192 used=0 with event: FINISHED
2014-05-05 03:56:58,659 INFO org.apache.hadoop.yarn.server.resourcemanager.rmcontainer.RMContainerImpl: container_1399261790270_0001_01_000009 Container Transitioned from RUNNING to COMPLETED
2014-05-05 03:56:58,659 INFO org.apache.hadoop.yarn.server.resourcemanager.scheduler.common.fica.FiCaSchedulerApp: Completed container: container_1399261790270_0001_01_000009 in state: COMPLETED event:FINISHED
2014-05-05 03:56:58,660 INFO org.apache.hadoop.yarn.server.resourcemanager.RMAuditLogger: USER=ubuntu	OPERATION=AM Released Container	TARGET=SchedulerApp	RESULT=SUCCESS	APPID=application_1399261790270_0001	CONTAINERID=container_1399261790270_0001_01_000009
2014-05-05 03:56:58,660 INFO org.apache.hadoop.yarn.server.resourcemanager.scheduler.common.fica.FiCaSchedulerNode: Released container container_1399261790270_0001_01_000009 of capacity <memory:1024, vCores:1> on host nodeb:41344, which currently has 1 containers, <memory:1024, vCores:1> used and <memory:7168, vCores:7> available, release resources=true
2014-05-05 03:56:58,660 INFO org.apache.hadoop.yarn.server.resourcemanager.scheduler.capacity.LeafQueue: default used=<memory:7168, vCores:6> numContainers=6 user=ubuntu user-resources=<memory:7168, vCores:6>
2014-05-05 03:56:58,660 INFO org.apache.hadoop.yarn.server.resourcemanager.scheduler.capacity.LeafQueue: completedContainer container=Container: [ContainerId: container_1399261790270_0001_01_000009, NodeId: nodeb:41344, NodeHttpAddress: nodeb:8042, Resource: <memory:1024, vCores:1>, Priority: 10, Token: Token { kind: ContainerToken, service: 10.0.0.59:41344 }, ] resource=<memory:1024, vCores:1> queue=default: capacity=1.0, absoluteCapacity=1.0, usedResources=<memory:7168, vCores:6>usedCapacity=0.21875, absoluteUsedCapacity=0.21875, numApps=1, numContainers=6 usedCapacity=0.21875 absoluteUsedCapacity=0.21875 used=<memory:7168, vCores:6> cluster=<memory:32768, vCores:32>
2014-05-05 03:56:58,660 INFO org.apache.hadoop.yarn.server.resourcemanager.scheduler.capacity.ParentQueue: completedContainer queue=root usedCapacity=0.21875 absoluteUsedCapacity=0.21875 used=<memory:7168, vCores:6> cluster=<memory:32768, vCores:32>
2014-05-05 03:56:58,660 INFO org.apache.hadoop.yarn.server.resourcemanager.scheduler.capacity.ParentQueue: Re-sorting completed queue: root.default stats: default: capacity=1.0, absoluteCapacity=1.0, usedResources=<memory:7168, vCores:6>usedCapacity=0.21875, absoluteUsedCapacity=0.21875, numApps=1, numContainers=6
2014-05-05 03:56:58,660 INFO org.apache.hadoop.yarn.server.resourcemanager.scheduler.capacity.CapacityScheduler: Application appattempt_1399261790270_0001_000001 released container container_1399261790270_0001_01_000009 on node: host: nodeb:41344 #containers=1 available=7168 used=1024 with event: FINISHED
2014-05-05 03:57:02,295 INFO org.apache.hadoop.yarn.server.resourcemanager.rmcontainer.RMContainerImpl: container_1399261790270_0001_01_000010 Container Transitioned from RUNNING to COMPLETED
2014-05-05 03:57:02,295 INFO org.apache.hadoop.yarn.server.resourcemanager.scheduler.common.fica.FiCaSchedulerApp: Completed container: container_1399261790270_0001_01_000010 in state: COMPLETED event:FINISHED
2014-05-05 03:57:02,295 INFO org.apache.hadoop.yarn.server.resourcemanager.RMAuditLogger: USER=ubuntu	OPERATION=AM Released Container	TARGET=SchedulerApp	RESULT=SUCCESS	APPID=application_1399261790270_0001	CONTAINERID=container_1399261790270_0001_01_000010
2014-05-05 03:57:02,295 INFO org.apache.hadoop.yarn.server.resourcemanager.scheduler.common.fica.FiCaSchedulerNode: Released container container_1399261790270_0001_01_000010 of capacity <memory:1024, vCores:1> on host nodeb:41344, which currently has 0 containers, <memory:0, vCores:0> used and <memory:8192, vCores:8> available, release resources=true
2014-05-05 03:57:02,295 INFO org.apache.hadoop.yarn.server.resourcemanager.scheduler.capacity.LeafQueue: default used=<memory:6144, vCores:5> numContainers=5 user=ubuntu user-resources=<memory:6144, vCores:5>
2014-05-05 03:57:02,296 INFO org.apache.hadoop.yarn.server.resourcemanager.scheduler.capacity.LeafQueue: completedContainer container=Container: [ContainerId: container_1399261790270_0001_01_000010, NodeId: nodeb:41344, NodeHttpAddress: nodeb:8042, Resource: <memory:1024, vCores:1>, Priority: 10, Token: Token { kind: ContainerToken, service: 10.0.0.59:41344 }, ] resource=<memory:1024, vCores:1> queue=default: capacity=1.0, absoluteCapacity=1.0, usedResources=<memory:6144, vCores:5>usedCapacity=0.1875, absoluteUsedCapacity=0.1875, numApps=1, numContainers=5 usedCapacity=0.1875 absoluteUsedCapacity=0.1875 used=<memory:6144, vCores:5> cluster=<memory:32768, vCores:32>
2014-05-05 03:57:02,296 INFO org.apache.hadoop.yarn.server.resourcemanager.scheduler.capacity.ParentQueue: completedContainer queue=root usedCapacity=0.1875 absoluteUsedCapacity=0.1875 used=<memory:6144, vCores:5> cluster=<memory:32768, vCores:32>
2014-05-05 03:57:02,296 INFO org.apache.hadoop.yarn.server.resourcemanager.scheduler.capacity.ParentQueue: Re-sorting completed queue: root.default stats: default: capacity=1.0, absoluteCapacity=1.0, usedResources=<memory:6144, vCores:5>usedCapacity=0.1875, absoluteUsedCapacity=0.1875, numApps=1, numContainers=5
2014-05-05 03:57:02,296 INFO org.apache.hadoop.yarn.server.resourcemanager.scheduler.capacity.CapacityScheduler: Application appattempt_1399261790270_0001_000001 released container container_1399261790270_0001_01_000010 on node: host: nodeb:41344 #containers=0 available=8192 used=0 with event: FINISHED
2014-05-05 03:57:03,750 INFO org.apache.hadoop.yarn.server.resourcemanager.rmcontainer.RMContainerImpl: container_1399261790270_0001_01_000007 Container Transitioned from RUNNING to COMPLETED
2014-05-05 03:57:03,750 INFO org.apache.hadoop.yarn.server.resourcemanager.scheduler.common.fica.FiCaSchedulerApp: Completed container: container_1399261790270_0001_01_000007 in state: COMPLETED event:FINISHED
2014-05-05 03:57:03,750 INFO org.apache.hadoop.yarn.server.resourcemanager.RMAuditLogger: USER=ubuntu	OPERATION=AM Released Container	TARGET=SchedulerApp	RESULT=SUCCESS	APPID=application_1399261790270_0001	CONTAINERID=container_1399261790270_0001_01_000007
2014-05-05 03:57:03,750 INFO org.apache.hadoop.yarn.server.resourcemanager.scheduler.common.fica.FiCaSchedulerNode: Released container container_1399261790270_0001_01_000007 of capacity <memory:1024, vCores:1> on host nodea:49324, which currently has 1 containers, <memory:1024, vCores:1> used and <memory:7168, vCores:7> available, release resources=true
2014-05-05 03:57:03,750 INFO org.apache.hadoop.yarn.server.resourcemanager.scheduler.capacity.LeafQueue: default used=<memory:5120, vCores:4> numContainers=4 user=ubuntu user-resources=<memory:5120, vCores:4>
2014-05-05 03:57:03,751 INFO org.apache.hadoop.yarn.server.resourcemanager.scheduler.capacity.LeafQueue: completedContainer container=Container: [ContainerId: container_1399261790270_0001_01_000007, NodeId: nodea:49324, NodeHttpAddress: nodea:8042, Resource: <memory:1024, vCores:1>, Priority: 10, Token: Token { kind: ContainerToken, service: 10.0.0.158:49324 }, ] resource=<memory:1024, vCores:1> queue=default: capacity=1.0, absoluteCapacity=1.0, usedResources=<memory:5120, vCores:4>usedCapacity=0.15625, absoluteUsedCapacity=0.15625, numApps=1, numContainers=4 usedCapacity=0.15625 absoluteUsedCapacity=0.15625 used=<memory:5120, vCores:4> cluster=<memory:32768, vCores:32>
2014-05-05 03:57:03,751 INFO org.apache.hadoop.yarn.server.resourcemanager.scheduler.capacity.ParentQueue: completedContainer queue=root usedCapacity=0.15625 absoluteUsedCapacity=0.15625 used=<memory:5120, vCores:4> cluster=<memory:32768, vCores:32>
2014-05-05 03:57:03,751 INFO org.apache.hadoop.yarn.server.resourcemanager.scheduler.capacity.ParentQueue: Re-sorting completed queue: root.default stats: default: capacity=1.0, absoluteCapacity=1.0, usedResources=<memory:5120, vCores:4>usedCapacity=0.15625, absoluteUsedCapacity=0.15625, numApps=1, numContainers=4
2014-05-05 03:57:03,751 INFO org.apache.hadoop.yarn.server.resourcemanager.scheduler.capacity.CapacityScheduler: Application appattempt_1399261790270_0001_000001 released container container_1399261790270_0001_01_000007 on node: host: nodea:49324 #containers=1 available=7168 used=1024 with event: FINISHED
2014-05-05 03:57:03,837 INFO org.apache.hadoop.yarn.server.resourcemanager.rmcontainer.RMContainerImpl: container_1399261790270_0001_01_000014 Container Transitioned from RUNNING to COMPLETED
2014-05-05 03:57:03,837 INFO org.apache.hadoop.yarn.server.resourcemanager.scheduler.common.fica.FiCaSchedulerApp: Completed container: container_1399261790270_0001_01_000014 in state: COMPLETED event:FINISHED
2014-05-05 03:57:03,837 INFO org.apache.hadoop.yarn.server.resourcemanager.RMAuditLogger: USER=ubuntu	OPERATION=AM Released Container	TARGET=SchedulerApp	RESULT=SUCCESS	APPID=application_1399261790270_0001	CONTAINERID=container_1399261790270_0001_01_000014
2014-05-05 03:57:03,837 INFO org.apache.hadoop.yarn.server.resourcemanager.scheduler.common.fica.FiCaSchedulerNode: Released container container_1399261790270_0001_01_000014 of capacity <memory:1024, vCores:1> on host noded:54001, which currently has 2 containers, <memory:3072, vCores:2> used and <memory:5120, vCores:6> available, release resources=true
2014-05-05 03:57:03,837 INFO org.apache.hadoop.yarn.server.resourcemanager.scheduler.capacity.LeafQueue: default used=<memory:4096, vCores:3> numContainers=3 user=ubuntu user-resources=<memory:4096, vCores:3>
2014-05-05 03:57:03,837 INFO org.apache.hadoop.yarn.server.resourcemanager.scheduler.capacity.LeafQueue: completedContainer container=Container: [ContainerId: container_1399261790270_0001_01_000014, NodeId: noded:54001, NodeHttpAddress: noded:8042, Resource: <memory:1024, vCores:1>, Priority: 10, Token: Token { kind: ContainerToken, service: 10.0.0.180:54001 }, ] resource=<memory:1024, vCores:1> queue=default: capacity=1.0, absoluteCapacity=1.0, usedResources=<memory:4096, vCores:3>usedCapacity=0.125, absoluteUsedCapacity=0.125, numApps=1, numContainers=3 usedCapacity=0.125 absoluteUsedCapacity=0.125 used=<memory:4096, vCores:3> cluster=<memory:32768, vCores:32>
2014-05-05 03:57:03,838 INFO org.apache.hadoop.yarn.server.resourcemanager.scheduler.capacity.ParentQueue: completedContainer queue=root usedCapacity=0.125 absoluteUsedCapacity=0.125 used=<memory:4096, vCores:3> cluster=<memory:32768, vCores:32>
2014-05-05 03:57:03,838 INFO org.apache.hadoop.yarn.server.resourcemanager.scheduler.capacity.ParentQueue: Re-sorting completed queue: root.default stats: default: capacity=1.0, absoluteCapacity=1.0, usedResources=<memory:4096, vCores:3>usedCapacity=0.125, absoluteUsedCapacity=0.125, numApps=1, numContainers=3
2014-05-05 03:57:03,838 INFO org.apache.hadoop.yarn.server.resourcemanager.scheduler.capacity.CapacityScheduler: Application appattempt_1399261790270_0001_000001 released container container_1399261790270_0001_01_000014 on node: host: noded:54001 #containers=2 available=5120 used=3072 with event: FINISHED
2014-05-05 03:57:04,089 INFO org.apache.hadoop.yarn.server.resourcemanager.rmapp.attempt.RMAppAttemptImpl: appattempt_1399261790270_0001_000001 State change from RUNNING to FINISHING
2014-05-05 03:57:04,090 INFO org.apache.hadoop.yarn.server.resourcemanager.rmapp.RMAppImpl: Removing application with id application_1399261790270_0001
2014-05-05 03:57:04,091 INFO org.apache.hadoop.yarn.server.resourcemanager.rmapp.RMAppImpl: application_1399261790270_0001 State change from RUNNING to REMOVING
2014-05-05 03:57:04,091 INFO org.apache.hadoop.yarn.server.resourcemanager.recovery.RMStateStore: Removing info for app: application_1399261790270_0001
2014-05-05 03:57:04,092 INFO org.apache.hadoop.yarn.server.resourcemanager.rmapp.RMAppImpl: application_1399261790270_0001 State change from REMOVING to FINISHING
2014-05-05 03:57:04,752 INFO org.apache.hadoop.yarn.server.resourcemanager.rmcontainer.RMContainerImpl: container_1399261790270_0001_01_000008 Container Transitioned from RUNNING to COMPLETED
2014-05-05 03:57:04,752 INFO org.apache.hadoop.yarn.server.resourcemanager.scheduler.common.fica.FiCaSchedulerApp: Completed container: container_1399261790270_0001_01_000008 in state: COMPLETED event:FINISHED
2014-05-05 03:57:04,752 INFO org.apache.hadoop.yarn.server.resourcemanager.RMAuditLogger: USER=ubuntu	OPERATION=AM Released Container	TARGET=SchedulerApp	RESULT=SUCCESS	APPID=application_1399261790270_0001	CONTAINERID=container_1399261790270_0001_01_000008
2014-05-05 03:57:04,752 INFO org.apache.hadoop.yarn.server.resourcemanager.scheduler.common.fica.FiCaSchedulerNode: Released container container_1399261790270_0001_01_000008 of capacity <memory:1024, vCores:1> on host nodea:49324, which currently has 0 containers, <memory:0, vCores:0> used and <memory:8192, vCores:8> available, release resources=true
2014-05-05 03:57:04,752 INFO org.apache.hadoop.yarn.server.resourcemanager.scheduler.capacity.LeafQueue: default used=<memory:3072, vCores:2> numContainers=2 user=ubuntu user-resources=<memory:3072, vCores:2>
2014-05-05 03:57:04,752 INFO org.apache.hadoop.yarn.server.resourcemanager.scheduler.capacity.LeafQueue: completedContainer container=Container: [ContainerId: container_1399261790270_0001_01_000008, NodeId: nodea:49324, NodeHttpAddress: nodea:8042, Resource: <memory:1024, vCores:1>, Priority: 10, Token: Token { kind: ContainerToken, service: 10.0.0.158:49324 }, ] resource=<memory:1024, vCores:1> queue=default: capacity=1.0, absoluteCapacity=1.0, usedResources=<memory:3072, vCores:2>usedCapacity=0.09375, absoluteUsedCapacity=0.09375, numApps=1, numContainers=2 usedCapacity=0.09375 absoluteUsedCapacity=0.09375 used=<memory:3072, vCores:2> cluster=<memory:32768, vCores:32>
2014-05-05 03:57:04,752 INFO org.apache.hadoop.yarn.server.resourcemanager.scheduler.capacity.ParentQueue: completedContainer queue=root usedCapacity=0.09375 absoluteUsedCapacity=0.09375 used=<memory:3072, vCores:2> cluster=<memory:32768, vCores:32>
2014-05-05 03:57:04,753 INFO org.apache.hadoop.yarn.server.resourcemanager.scheduler.capacity.ParentQueue: Re-sorting completed queue: root.default stats: default: capacity=1.0, absoluteCapacity=1.0, usedResources=<memory:3072, vCores:2>usedCapacity=0.09375, absoluteUsedCapacity=0.09375, numApps=1, numContainers=2
2014-05-05 03:57:04,753 INFO org.apache.hadoop.yarn.server.resourcemanager.scheduler.capacity.CapacityScheduler: Application appattempt_1399261790270_0001_000001 released container container_1399261790270_0001_01_000008 on node: host: nodea:49324 #containers=0 available=8192 used=0 with event: FINISHED
2014-05-05 03:57:04,846 INFO org.apache.hadoop.yarn.server.resourcemanager.rmcontainer.RMContainerImpl: container_1399261790270_0001_01_000013 Container Transitioned from RUNNING to COMPLETED
2014-05-05 03:57:04,846 INFO org.apache.hadoop.yarn.server.resourcemanager.scheduler.common.fica.FiCaSchedulerApp: Completed container: container_1399261790270_0001_01_000013 in state: COMPLETED event:FINISHED
2014-05-05 03:57:04,847 INFO org.apache.hadoop.yarn.server.resourcemanager.RMAuditLogger: USER=ubuntu	OPERATION=AM Released Container	TARGET=SchedulerApp	RESULT=SUCCESS	APPID=application_1399261790270_0001	CONTAINERID=container_1399261790270_0001_01_000013
2014-05-05 03:57:04,847 INFO org.apache.hadoop.yarn.server.resourcemanager.scheduler.common.fica.FiCaSchedulerNode: Released container container_1399261790270_0001_01_000013 of capacity <memory:1024, vCores:1> on host noded:54001, which currently has 1 containers, <memory:2048, vCores:1> used and <memory:6144, vCores:7> available, release resources=true
2014-05-05 03:57:04,847 INFO org.apache.hadoop.yarn.server.resourcemanager.scheduler.capacity.LeafQueue: default used=<memory:2048, vCores:1> numContainers=1 user=ubuntu user-resources=<memory:2048, vCores:1>
2014-05-05 03:57:04,847 INFO org.apache.hadoop.yarn.server.resourcemanager.scheduler.capacity.LeafQueue: completedContainer container=Container: [ContainerId: container_1399261790270_0001_01_000013, NodeId: noded:54001, NodeHttpAddress: noded:8042, Resource: <memory:1024, vCores:1>, Priority: 10, Token: Token { kind: ContainerToken, service: 10.0.0.180:54001 }, ] resource=<memory:1024, vCores:1> queue=default: capacity=1.0, absoluteCapacity=1.0, usedResources=<memory:2048, vCores:1>usedCapacity=0.0625, absoluteUsedCapacity=0.0625, numApps=1, numContainers=1 usedCapacity=0.0625 absoluteUsedCapacity=0.0625 used=<memory:2048, vCores:1> cluster=<memory:32768, vCores:32>
2014-05-05 03:57:04,847 INFO org.apache.hadoop.yarn.server.resourcemanager.scheduler.capacity.ParentQueue: completedContainer queue=root usedCapacity=0.0625 absoluteUsedCapacity=0.0625 used=<memory:2048, vCores:1> cluster=<memory:32768, vCores:32>
2014-05-05 03:57:04,847 INFO org.apache.hadoop.yarn.server.resourcemanager.scheduler.capacity.ParentQueue: Re-sorting completed queue: root.default stats: default: capacity=1.0, absoluteCapacity=1.0, usedResources=<memory:2048, vCores:1>usedCapacity=0.0625, absoluteUsedCapacity=0.0625, numApps=1, numContainers=1
2014-05-05 03:57:04,847 INFO org.apache.hadoop.yarn.server.resourcemanager.scheduler.capacity.CapacityScheduler: Application appattempt_1399261790270_0001_000001 released container container_1399261790270_0001_01_000013 on node: host: noded:54001 #containers=1 available=6144 used=2048 with event: FINISHED
2014-05-05 03:57:10,858 INFO org.apache.hadoop.yarn.server.resourcemanager.rmcontainer.RMContainerImpl: container_1399261790270_0001_01_000001 Container Transitioned from RUNNING to COMPLETED
2014-05-05 03:57:10,858 INFO org.apache.hadoop.yarn.server.resourcemanager.ApplicationMasterService: Unregistering app attempt : appattempt_1399261790270_0001_000001
2014-05-05 03:57:10,858 INFO org.apache.hadoop.yarn.server.resourcemanager.scheduler.common.fica.FiCaSchedulerApp: Completed container: container_1399261790270_0001_01_000001 in state: COMPLETED event:FINISHED
2014-05-05 03:57:10,858 INFO org.apache.hadoop.yarn.server.resourcemanager.RMAuditLogger: USER=ubuntu	OPERATION=AM Released Container	TARGET=SchedulerApp	RESULT=SUCCESS	APPID=application_1399261790270_0001	CONTAINERID=container_1399261790270_0001_01_000001
2014-05-05 03:57:10,858 INFO org.apache.hadoop.yarn.server.resourcemanager.scheduler.common.fica.FiCaSchedulerNode: Released container container_1399261790270_0001_01_000001 of capacity <memory:2048, vCores:1> on host noded:54001, which currently has 0 containers, <memory:0, vCores:0> used and <memory:8192, vCores:8> available, release resources=true
2014-05-05 03:57:10,858 INFO org.apache.hadoop.yarn.server.resourcemanager.scheduler.capacity.LeafQueue: default used=<memory:0, vCores:0> numContainers=0 user=ubuntu user-resources=<memory:0, vCores:0>
2014-05-05 03:57:10,858 INFO org.apache.hadoop.yarn.server.resourcemanager.scheduler.capacity.LeafQueue: completedContainer container=Container: [ContainerId: container_1399261790270_0001_01_000001, NodeId: noded:54001, NodeHttpAddress: noded:8042, Resource: <memory:2048, vCores:1>, Priority: 0, Token: Token { kind: ContainerToken, service: 10.0.0.180:54001 }, ] resource=<memory:2048, vCores:1> queue=default: capacity=1.0, absoluteCapacity=1.0, usedResources=<memory:0, vCores:0>usedCapacity=0.0, absoluteUsedCapacity=0.0, numApps=1, numContainers=0 usedCapacity=0.0 absoluteUsedCapacity=0.0 used=<memory:0, vCores:0> cluster=<memory:32768, vCores:32>
2014-05-05 03:57:10,859 INFO org.apache.hadoop.yarn.server.resourcemanager.scheduler.capacity.ParentQueue: completedContainer queue=root usedCapacity=0.0 absoluteUsedCapacity=0.0 used=<memory:0, vCores:0> cluster=<memory:32768, vCores:32>
2014-05-05 03:57:10,859 INFO org.apache.hadoop.yarn.server.resourcemanager.scheduler.capacity.ParentQueue: Re-sorting completed queue: root.default stats: default: capacity=1.0, absoluteCapacity=1.0, usedResources=<memory:0, vCores:0>usedCapacity=0.0, absoluteUsedCapacity=0.0, numApps=1, numContainers=0
2014-05-05 03:57:10,859 INFO org.apache.hadoop.yarn.server.resourcemanager.scheduler.capacity.CapacityScheduler: Application appattempt_1399261790270_0001_000001 released container container_1399261790270_0001_01_000001 on node: host: noded:54001 #containers=0 available=8192 used=0 with event: FINISHED
2014-05-05 03:57:10,859 INFO org.apache.hadoop.yarn.server.resourcemanager.rmapp.attempt.RMAppAttemptImpl: appattempt_1399261790270_0001_000001 State change from FINISHING to FINISHED
2014-05-05 03:57:10,861 INFO org.apache.hadoop.yarn.server.resourcemanager.rmapp.RMAppImpl: application_1399261790270_0001 State change from FINISHING to FINISHED
2014-05-05 03:57:10,861 INFO org.apache.hadoop.yarn.server.resourcemanager.scheduler.capacity.CapacityScheduler: Application appattempt_1399261790270_0001_000001 is done. finalState=FINISHED
2014-05-05 03:57:10,862 INFO org.apache.hadoop.yarn.server.resourcemanager.scheduler.AppSchedulingInfo: Application application_1399261790270_0001 requests cleared
2014-05-05 03:57:10,862 INFO org.apache.hadoop.yarn.server.resourcemanager.scheduler.capacity.LeafQueue: Application removed - appId: application_1399261790270_0001 user: ubuntu queue: default #user-pending-applications: 0 #user-active-applications: 0 #queue-pending-applications: 0 #queue-active-applications: 0
2014-05-05 03:57:10,862 INFO org.apache.hadoop.yarn.server.resourcemanager.scheduler.capacity.ParentQueue: Application removed - appId: application_1399261790270_0001 user: ubuntu leaf-queue of parent: root #applications: 0
2014-05-05 03:57:10,862 INFO org.apache.hadoop.yarn.server.resourcemanager.RMAuditLogger: USER=ubuntu	OPERATION=Application Finished - Succeeded	TARGET=RMAppManager	RESULT=SUCCESS	APPID=application_1399261790270_0001
2014-05-05 03:57:10,863 INFO org.apache.hadoop.yarn.server.resourcemanager.RMAppManager$ApplicationSummary: appId=application_1399261790270_0001,name=hints||path:/in1m||num reduce:8,user=ubuntu,queue=default,state=FINISHED,trackingUrl=ec2-54-186-230-200.us-west-2.compute.amazonaws.com:8088/proxy/application_1399261790270_0001/jobhistory/job/job_1399261790270_0001,appMasterHost=ip-10-0-0-180,startTime=1399262037871,finishTime=1399262224092,finalStatus=SUCCEEDED
2014-05-05 03:57:10,864 INFO org.apache.hadoop.yarn.server.resourcemanager.amlauncher.AMLauncher: Cleaning master appattempt_1399261790270_0001_000001
2014-05-05 04:05:51,331 INFO org.apache.hadoop.yarn.server.resourcemanager.ClientRMService: Allocated new applicationId: 2
2014-05-05 04:05:52,961 INFO org.apache.hadoop.yarn.server.resourcemanager.ClientRMService: Application with id 2 submitted by user ubuntu
2014-05-05 04:05:52,961 INFO org.apache.hadoop.yarn.server.resourcemanager.RMAuditLogger: USER=ubuntu	IP=10.0.0.158	OPERATION=Submit Application Request	TARGET=ClientRMService	RESULT=SUCCESS	APPID=application_1399261790270_0002
2014-05-05 04:05:52,961 INFO org.apache.hadoop.yarn.server.resourcemanager.rmapp.RMAppImpl: Storing application with id application_1399261790270_0002
2014-05-05 04:05:52,961 INFO org.apache.hadoop.yarn.server.resourcemanager.rmapp.RMAppImpl: application_1399261790270_0002 State change from NEW to NEW_SAVING
2014-05-05 04:05:52,961 INFO org.apache.hadoop.yarn.server.resourcemanager.recovery.RMStateStore: Storing info for app: application_1399261790270_0002
2014-05-05 04:05:52,963 INFO org.apache.hadoop.yarn.server.resourcemanager.rmapp.RMAppImpl: application_1399261790270_0002 State change from NEW_SAVING to SUBMITTED
2014-05-05 04:05:52,963 INFO org.apache.hadoop.yarn.server.resourcemanager.ApplicationMasterService: Registering app attempt : appattempt_1399261790270_0002_000001
2014-05-05 04:05:52,964 INFO org.apache.hadoop.yarn.server.resourcemanager.rmapp.attempt.RMAppAttemptImpl: appattempt_1399261790270_0002_000001 State change from NEW to SUBMITTED
2014-05-05 04:05:52,964 INFO org.apache.hadoop.yarn.server.resourcemanager.scheduler.capacity.LeafQueue: Application application_1399261790270_0002 from user: ubuntu activated in queue: default
2014-05-05 04:05:52,964 INFO org.apache.hadoop.yarn.server.resourcemanager.scheduler.capacity.LeafQueue: Application added - appId: application_1399261790270_0002 user: org.apache.hadoop.yarn.server.resourcemanager.scheduler.capacity.LeafQueue$User@225b8b2f, leaf-queue: default #user-pending-applications: 0 #user-active-applications: 1 #queue-pending-applications: 0 #queue-active-applications: 1
2014-05-05 04:05:52,964 INFO org.apache.hadoop.yarn.server.resourcemanager.scheduler.capacity.ParentQueue: Application added - appId: application_1399261790270_0002 user: ubuntu leaf-queue of parent: root #applications: 1
2014-05-05 04:05:52,964 INFO org.apache.hadoop.yarn.server.resourcemanager.scheduler.capacity.CapacityScheduler: Application Submission: appattempt_1399261790270_0002_000001, user: ubuntu queue: default: capacity=1.0, absoluteCapacity=1.0, usedResources=<memory:0, vCores:0>usedCapacity=0.0, absoluteUsedCapacity=0.0, numApps=1, numContainers=0, currently active: 1
2014-05-05 04:05:52,965 INFO org.apache.hadoop.yarn.server.resourcemanager.rmapp.attempt.RMAppAttemptImpl: appattempt_1399261790270_0002_000001 State change from SUBMITTED to SCHEDULED
2014-05-05 04:05:52,965 INFO org.apache.hadoop.yarn.server.resourcemanager.rmapp.RMAppImpl: application_1399261790270_0002 State change from SUBMITTED to ACCEPTED
2014-05-05 04:05:53,297 INFO org.apache.hadoop.yarn.server.resourcemanager.rmcontainer.RMContainerImpl: container_1399261790270_0002_01_000001 Container Transitioned from NEW to ALLOCATED
2014-05-05 04:05:53,297 INFO org.apache.hadoop.yarn.server.resourcemanager.RMAuditLogger: USER=ubuntu	OPERATION=AM Allocated Container	TARGET=SchedulerApp	RESULT=SUCCESS	APPID=application_1399261790270_0002	CONTAINERID=container_1399261790270_0002_01_000001
2014-05-05 04:05:53,297 INFO org.apache.hadoop.yarn.server.resourcemanager.scheduler.common.fica.FiCaSchedulerNode: Assigned container container_1399261790270_0002_01_000001 of capacity <memory:2048, vCores:1> on host nodea:49324, which currently has 1 containers, <memory:2048, vCores:1> used and <memory:6144, vCores:7> available
2014-05-05 04:05:53,297 INFO org.apache.hadoop.yarn.server.resourcemanager.scheduler.capacity.LeafQueue: assignedContainer application=application_1399261790270_0002 container=Container: [ContainerId: container_1399261790270_0002_01_000001, NodeId: nodea:49324, NodeHttpAddress: nodea:8042, Resource: <memory:2048, vCores:1>, Priority: 0, Token: Token { kind: ContainerToken, service: 10.0.0.158:49324 }, ] containerId=container_1399261790270_0002_01_000001 queue=default: capacity=1.0, absoluteCapacity=1.0, usedResources=<memory:0, vCores:0>usedCapacity=0.0, absoluteUsedCapacity=0.0, numApps=1, numContainers=0 usedCapacity=0.0 absoluteUsedCapacity=0.0 used=<memory:0, vCores:0> cluster=<memory:32768, vCores:32>
2014-05-05 04:05:53,298 INFO org.apache.hadoop.yarn.server.resourcemanager.scheduler.capacity.ParentQueue: Re-sorting assigned queue: root.default stats: default: capacity=1.0, absoluteCapacity=1.0, usedResources=<memory:2048, vCores:1>usedCapacity=0.0625, absoluteUsedCapacity=0.0625, numApps=1, numContainers=1
2014-05-05 04:05:53,298 INFO org.apache.hadoop.yarn.server.resourcemanager.rmcontainer.RMContainerImpl: container_1399261790270_0002_01_000001 Container Transitioned from ALLOCATED to ACQUIRED
2014-05-05 04:05:53,298 INFO org.apache.hadoop.yarn.server.resourcemanager.rmapp.attempt.RMAppAttemptImpl: Storing attempt: AppId: application_1399261790270_0002 AttemptId: appattempt_1399261790270_0002_000001 MasterContainer: Container: [ContainerId: container_1399261790270_0002_01_000001, NodeId: nodea:49324, NodeHttpAddress: nodea:8042, Resource: <memory:2048, vCores:1>, Priority: 0, Token: Token { kind: ContainerToken, service: 10.0.0.158:49324 }, ]
2014-05-05 04:05:53,298 INFO org.apache.hadoop.yarn.server.resourcemanager.rmapp.attempt.RMAppAttemptImpl: appattempt_1399261790270_0002_000001 State change from SCHEDULED to ALLOCATED_SAVING
2014-05-05 04:05:53,298 INFO org.apache.hadoop.yarn.server.resourcemanager.recovery.RMStateStore: Storing info for attempt: appattempt_1399261790270_0002_000001
2014-05-05 04:05:53,299 INFO org.apache.hadoop.yarn.server.resourcemanager.scheduler.capacity.ParentQueue: assignedContainer queue=root usedCapacity=0.0625 absoluteUsedCapacity=0.0625 used=<memory:2048, vCores:1> cluster=<memory:32768, vCores:32>
2014-05-05 04:05:53,299 INFO org.apache.hadoop.yarn.server.resourcemanager.rmapp.attempt.RMAppAttemptImpl: appattempt_1399261790270_0002_000001 State change from ALLOCATED_SAVING to ALLOCATED
2014-05-05 04:05:53,299 INFO org.apache.hadoop.yarn.server.resourcemanager.amlauncher.AMLauncher: Launching masterappattempt_1399261790270_0002_000001
2014-05-05 04:05:53,300 INFO org.apache.hadoop.yarn.server.resourcemanager.amlauncher.AMLauncher: Setting up container Container: [ContainerId: container_1399261790270_0002_01_000001, NodeId: nodea:49324, NodeHttpAddress: nodea:8042, Resource: <memory:2048, vCores:1>, Priority: 0, Token: Token { kind: ContainerToken, service: 10.0.0.158:49324 }, ] for AM appattempt_1399261790270_0002_000001
2014-05-05 04:05:53,301 INFO org.apache.hadoop.yarn.server.resourcemanager.amlauncher.AMLauncher: Command to launch container container_1399261790270_0002_01_000001 : $JAVA_HOME/bin/java -Dlog4j.configuration=container-log4j.properties -Dyarn.app.container.log.dir=<LOG_DIR> -Dyarn.app.container.log.filesize=0 -Dhadoop.root.logger=INFO,CLA  -Xmx1024m org.apache.hadoop.mapreduce.v2.app.MRAppMaster 1><LOG_DIR>/stdout 2><LOG_DIR>/stderr 
2014-05-05 04:05:53,322 INFO org.apache.hadoop.yarn.server.resourcemanager.amlauncher.AMLauncher: Done launching container Container: [ContainerId: container_1399261790270_0002_01_000001, NodeId: nodea:49324, NodeHttpAddress: nodea:8042, Resource: <memory:2048, vCores:1>, Priority: 0, Token: Token { kind: ContainerToken, service: 10.0.0.158:49324 }, ] for AM appattempt_1399261790270_0002_000001
2014-05-05 04:05:53,322 INFO org.apache.hadoop.yarn.server.resourcemanager.rmapp.attempt.RMAppAttemptImpl: appattempt_1399261790270_0002_000001 State change from ALLOCATED to LAUNCHED
2014-05-05 04:05:54,299 INFO org.apache.hadoop.yarn.server.resourcemanager.rmcontainer.RMContainerImpl: container_1399261790270_0002_01_000001 Container Transitioned from ACQUIRED to RUNNING
2014-05-05 04:05:58,477 INFO SecurityLogger.org.apache.hadoop.ipc.Server: Auth successful for appattempt_1399261790270_0002_000001 (auth:SIMPLE)
2014-05-05 04:05:58,483 INFO org.apache.hadoop.yarn.server.resourcemanager.ApplicationMasterService: AM registration appattempt_1399261790270_0002_000001
2014-05-05 04:05:58,483 INFO org.apache.hadoop.yarn.server.resourcemanager.RMAuditLogger: USER=ubuntu	IP=10.0.0.158	OPERATION=Register App Master	TARGET=ApplicationMasterService	RESULT=SUCCESS	APPID=application_1399261790270_0002	APPATTEMPTID=appattempt_1399261790270_0002_000001
2014-05-05 04:05:58,484 INFO org.apache.hadoop.yarn.server.resourcemanager.rmapp.attempt.RMAppAttemptImpl: appattempt_1399261790270_0002_000001 State change from LAUNCHED to RUNNING
2014-05-05 04:05:58,484 INFO org.apache.hadoop.yarn.server.resourcemanager.rmapp.RMAppImpl: application_1399261790270_0002 State change from ACCEPTED to RUNNING
2014-05-05 04:05:59,618 INFO org.apache.hadoop.yarn.server.resourcemanager.rmcontainer.RMContainerImpl: container_1399261790270_0002_01_000002 Container Transitioned from NEW to ALLOCATED
2014-05-05 04:05:59,618 INFO org.apache.hadoop.yarn.server.resourcemanager.RMAuditLogger: USER=ubuntu	OPERATION=AM Allocated Container	TARGET=SchedulerApp	RESULT=SUCCESS	APPID=application_1399261790270_0002	CONTAINERID=container_1399261790270_0002_01_000002
2014-05-05 04:05:59,618 INFO org.apache.hadoop.yarn.server.resourcemanager.scheduler.common.fica.FiCaSchedulerNode: Assigned container container_1399261790270_0002_01_000002 of capacity <memory:1024, vCores:1> on host noded:54001, which currently has 1 containers, <memory:1024, vCores:1> used and <memory:7168, vCores:7> available
2014-05-05 04:05:59,618 INFO org.apache.hadoop.yarn.server.resourcemanager.scheduler.capacity.LeafQueue: assignedContainer application=application_1399261790270_0002 container=Container: [ContainerId: container_1399261790270_0002_01_000002, NodeId: noded:54001, NodeHttpAddress: noded:8042, Resource: <memory:1024, vCores:1>, Priority: 20, Token: Token { kind: ContainerToken, service: 10.0.0.180:54001 }, ] containerId=container_1399261790270_0002_01_000002 queue=default: capacity=1.0, absoluteCapacity=1.0, usedResources=<memory:2048, vCores:1>usedCapacity=0.0625, absoluteUsedCapacity=0.0625, numApps=1, numContainers=1 usedCapacity=0.0625 absoluteUsedCapacity=0.0625 used=<memory:2048, vCores:1> cluster=<memory:32768, vCores:32>
2014-05-05 04:05:59,618 INFO org.apache.hadoop.yarn.server.resourcemanager.scheduler.capacity.ParentQueue: Re-sorting assigned queue: root.default stats: default: capacity=1.0, absoluteCapacity=1.0, usedResources=<memory:3072, vCores:2>usedCapacity=0.09375, absoluteUsedCapacity=0.09375, numApps=1, numContainers=2
2014-05-05 04:05:59,618 INFO org.apache.hadoop.yarn.server.resourcemanager.scheduler.capacity.ParentQueue: assignedContainer queue=root usedCapacity=0.09375 absoluteUsedCapacity=0.09375 used=<memory:3072, vCores:2> cluster=<memory:32768, vCores:32>
2014-05-05 04:05:59,619 INFO org.apache.hadoop.yarn.server.resourcemanager.rmcontainer.RMContainerImpl: container_1399261790270_0002_01_000003 Container Transitioned from NEW to ALLOCATED
2014-05-05 04:05:59,619 INFO org.apache.hadoop.yarn.server.resourcemanager.RMAuditLogger: USER=ubuntu	OPERATION=AM Allocated Container	TARGET=SchedulerApp	RESULT=SUCCESS	APPID=application_1399261790270_0002	CONTAINERID=container_1399261790270_0002_01_000003
2014-05-05 04:05:59,619 INFO org.apache.hadoop.yarn.server.resourcemanager.scheduler.common.fica.FiCaSchedulerNode: Assigned container container_1399261790270_0002_01_000003 of capacity <memory:1024, vCores:1> on host noded:54001, which currently has 2 containers, <memory:2048, vCores:2> used and <memory:6144, vCores:6> available
2014-05-05 04:05:59,619 INFO org.apache.hadoop.yarn.server.resourcemanager.scheduler.capacity.LeafQueue: assignedContainer application=application_1399261790270_0002 container=Container: [ContainerId: container_1399261790270_0002_01_000003, NodeId: noded:54001, NodeHttpAddress: noded:8042, Resource: <memory:1024, vCores:1>, Priority: 20, Token: Token { kind: ContainerToken, service: 10.0.0.180:54001 }, ] containerId=container_1399261790270_0002_01_000003 queue=default: capacity=1.0, absoluteCapacity=1.0, usedResources=<memory:3072, vCores:2>usedCapacity=0.09375, absoluteUsedCapacity=0.09375, numApps=1, numContainers=2 usedCapacity=0.09375 absoluteUsedCapacity=0.09375 used=<memory:3072, vCores:2> cluster=<memory:32768, vCores:32>
2014-05-05 04:05:59,619 INFO org.apache.hadoop.yarn.server.resourcemanager.scheduler.capacity.ParentQueue: Re-sorting assigned queue: root.default stats: default: capacity=1.0, absoluteCapacity=1.0, usedResources=<memory:4096, vCores:3>usedCapacity=0.125, absoluteUsedCapacity=0.125, numApps=1, numContainers=3
2014-05-05 04:05:59,619 INFO org.apache.hadoop.yarn.server.resourcemanager.scheduler.capacity.ParentQueue: assignedContainer queue=root usedCapacity=0.125 absoluteUsedCapacity=0.125 used=<memory:4096, vCores:3> cluster=<memory:32768, vCores:32>
2014-05-05 04:05:59,620 INFO org.apache.hadoop.yarn.server.resourcemanager.rmcontainer.RMContainerImpl: container_1399261790270_0002_01_000004 Container Transitioned from NEW to ALLOCATED
2014-05-05 04:05:59,620 INFO org.apache.hadoop.yarn.server.resourcemanager.RMAuditLogger: USER=ubuntu	OPERATION=AM Allocated Container	TARGET=SchedulerApp	RESULT=SUCCESS	APPID=application_1399261790270_0002	CONTAINERID=container_1399261790270_0002_01_000004
2014-05-05 04:05:59,620 INFO org.apache.hadoop.yarn.server.resourcemanager.scheduler.common.fica.FiCaSchedulerNode: Assigned container container_1399261790270_0002_01_000004 of capacity <memory:1024, vCores:1> on host noded:54001, which currently has 3 containers, <memory:3072, vCores:3> used and <memory:5120, vCores:5> available
2014-05-05 04:05:59,620 INFO org.apache.hadoop.yarn.server.resourcemanager.scheduler.capacity.LeafQueue: assignedContainer application=application_1399261790270_0002 container=Container: [ContainerId: container_1399261790270_0002_01_000004, NodeId: noded:54001, NodeHttpAddress: noded:8042, Resource: <memory:1024, vCores:1>, Priority: 20, Token: Token { kind: ContainerToken, service: 10.0.0.180:54001 }, ] containerId=container_1399261790270_0002_01_000004 queue=default: capacity=1.0, absoluteCapacity=1.0, usedResources=<memory:4096, vCores:3>usedCapacity=0.125, absoluteUsedCapacity=0.125, numApps=1, numContainers=3 usedCapacity=0.125 absoluteUsedCapacity=0.125 used=<memory:4096, vCores:3> cluster=<memory:32768, vCores:32>
2014-05-05 04:05:59,620 INFO org.apache.hadoop.yarn.server.resourcemanager.scheduler.capacity.ParentQueue: Re-sorting assigned queue: root.default stats: default: capacity=1.0, absoluteCapacity=1.0, usedResources=<memory:5120, vCores:4>usedCapacity=0.15625, absoluteUsedCapacity=0.15625, numApps=1, numContainers=4
2014-05-05 04:05:59,620 INFO org.apache.hadoop.yarn.server.resourcemanager.scheduler.capacity.ParentQueue: assignedContainer queue=root usedCapacity=0.15625 absoluteUsedCapacity=0.15625 used=<memory:5120, vCores:4> cluster=<memory:32768, vCores:32>
2014-05-05 04:05:59,621 INFO org.apache.hadoop.yarn.server.resourcemanager.rmcontainer.RMContainerImpl: container_1399261790270_0002_01_000005 Container Transitioned from NEW to ALLOCATED
2014-05-05 04:05:59,621 INFO org.apache.hadoop.yarn.server.resourcemanager.RMAuditLogger: USER=ubuntu	OPERATION=AM Allocated Container	TARGET=SchedulerApp	RESULT=SUCCESS	APPID=application_1399261790270_0002	CONTAINERID=container_1399261790270_0002_01_000005
2014-05-05 04:05:59,621 INFO org.apache.hadoop.yarn.server.resourcemanager.scheduler.common.fica.FiCaSchedulerNode: Assigned container container_1399261790270_0002_01_000005 of capacity <memory:1024, vCores:1> on host noded:54001, which currently has 4 containers, <memory:4096, vCores:4> used and <memory:4096, vCores:4> available
2014-05-05 04:05:59,621 INFO org.apache.hadoop.yarn.server.resourcemanager.scheduler.capacity.LeafQueue: assignedContainer application=application_1399261790270_0002 container=Container: [ContainerId: container_1399261790270_0002_01_000005, NodeId: noded:54001, NodeHttpAddress: noded:8042, Resource: <memory:1024, vCores:1>, Priority: 20, Token: Token { kind: ContainerToken, service: 10.0.0.180:54001 }, ] containerId=container_1399261790270_0002_01_000005 queue=default: capacity=1.0, absoluteCapacity=1.0, usedResources=<memory:5120, vCores:4>usedCapacity=0.15625, absoluteUsedCapacity=0.15625, numApps=1, numContainers=4 usedCapacity=0.15625 absoluteUsedCapacity=0.15625 used=<memory:5120, vCores:4> cluster=<memory:32768, vCores:32>
2014-05-05 04:05:59,621 INFO org.apache.hadoop.yarn.server.resourcemanager.scheduler.capacity.ParentQueue: Re-sorting assigned queue: root.default stats: default: capacity=1.0, absoluteCapacity=1.0, usedResources=<memory:6144, vCores:5>usedCapacity=0.1875, absoluteUsedCapacity=0.1875, numApps=1, numContainers=5
2014-05-05 04:05:59,621 INFO org.apache.hadoop.yarn.server.resourcemanager.scheduler.capacity.ParentQueue: assignedContainer queue=root usedCapacity=0.1875 absoluteUsedCapacity=0.1875 used=<memory:6144, vCores:5> cluster=<memory:32768, vCores:32>
2014-05-05 04:06:00,554 INFO org.apache.hadoop.yarn.server.resourcemanager.rmcontainer.RMContainerImpl: container_1399261790270_0002_01_000002 Container Transitioned from ALLOCATED to ACQUIRED
2014-05-05 04:06:00,554 INFO org.apache.hadoop.yarn.server.resourcemanager.rmcontainer.RMContainerImpl: container_1399261790270_0002_01_000003 Container Transitioned from ALLOCATED to ACQUIRED
2014-05-05 04:06:00,554 INFO org.apache.hadoop.yarn.server.resourcemanager.rmcontainer.RMContainerImpl: container_1399261790270_0002_01_000004 Container Transitioned from ALLOCATED to ACQUIRED
2014-05-05 04:06:00,554 INFO org.apache.hadoop.yarn.server.resourcemanager.rmcontainer.RMContainerImpl: container_1399261790270_0002_01_000005 Container Transitioned from ALLOCATED to ACQUIRED
2014-05-05 04:06:01,568 INFO org.apache.hadoop.yarn.server.resourcemanager.scheduler.AppSchedulingInfo: checking for deactivate... 
2014-05-05 04:06:01,629 INFO org.apache.hadoop.yarn.server.resourcemanager.rmcontainer.RMContainerImpl: container_1399261790270_0002_01_000002 Container Transitioned from ACQUIRED to RUNNING
2014-05-05 04:06:01,629 INFO org.apache.hadoop.yarn.server.resourcemanager.rmcontainer.RMContainerImpl: container_1399261790270_0002_01_000003 Container Transitioned from ACQUIRED to RUNNING
2014-05-05 04:06:01,630 INFO org.apache.hadoop.yarn.server.resourcemanager.rmcontainer.RMContainerImpl: container_1399261790270_0002_01_000004 Container Transitioned from ACQUIRED to RUNNING
2014-05-05 04:06:01,630 INFO org.apache.hadoop.yarn.server.resourcemanager.rmcontainer.RMContainerImpl: container_1399261790270_0002_01_000005 Container Transitioned from ACQUIRED to RUNNING
2014-05-05 04:06:27,770 INFO org.apache.hadoop.yarn.server.resourcemanager.rmcontainer.RMContainerImpl: container_1399261790270_0002_01_000006 Container Transitioned from NEW to ALLOCATED
2014-05-05 04:06:27,770 INFO org.apache.hadoop.yarn.server.resourcemanager.RMAuditLogger: USER=ubuntu	OPERATION=AM Allocated Container	TARGET=SchedulerApp	RESULT=SUCCESS	APPID=application_1399261790270_0002	CONTAINERID=container_1399261790270_0002_01_000006
2014-05-05 04:06:27,771 INFO org.apache.hadoop.yarn.server.resourcemanager.scheduler.common.fica.FiCaSchedulerNode: Assigned container container_1399261790270_0002_01_000006 of capacity <memory:1024, vCores:1> on host nodec:51351, which currently has 1 containers, <memory:1024, vCores:1> used and <memory:7168, vCores:7> available
2014-05-05 04:06:27,771 INFO org.apache.hadoop.yarn.server.resourcemanager.scheduler.capacity.LeafQueue: assignedContainer application=application_1399261790270_0002 container=Container: [ContainerId: container_1399261790270_0002_01_000006, NodeId: nodec:51351, NodeHttpAddress: nodec:8042, Resource: <memory:1024, vCores:1>, Priority: 20, Token: Token { kind: ContainerToken, service: 10.0.0.181:51351 }, ] containerId=container_1399261790270_0002_01_000006 queue=default: capacity=1.0, absoluteCapacity=1.0, usedResources=<memory:6144, vCores:5>usedCapacity=0.1875, absoluteUsedCapacity=0.1875, numApps=1, numContainers=5 usedCapacity=0.1875 absoluteUsedCapacity=0.1875 used=<memory:6144, vCores:5> cluster=<memory:32768, vCores:32>
2014-05-05 04:06:27,771 INFO org.apache.hadoop.yarn.server.resourcemanager.scheduler.capacity.ParentQueue: Re-sorting assigned queue: root.default stats: default: capacity=1.0, absoluteCapacity=1.0, usedResources=<memory:7168, vCores:6>usedCapacity=0.21875, absoluteUsedCapacity=0.21875, numApps=1, numContainers=6
2014-05-05 04:06:27,771 INFO org.apache.hadoop.yarn.server.resourcemanager.scheduler.capacity.ParentQueue: assignedContainer queue=root usedCapacity=0.21875 absoluteUsedCapacity=0.21875 used=<memory:7168, vCores:6> cluster=<memory:32768, vCores:32>
2014-05-05 04:06:27,958 INFO org.apache.hadoop.yarn.server.resourcemanager.rmcontainer.RMContainerImpl: container_1399261790270_0002_01_000005 Container Transitioned from RUNNING to COMPLETED
2014-05-05 04:06:27,958 INFO org.apache.hadoop.yarn.server.resourcemanager.scheduler.common.fica.FiCaSchedulerApp: Completed container: container_1399261790270_0002_01_000005 in state: COMPLETED event:FINISHED
2014-05-05 04:06:27,958 INFO org.apache.hadoop.yarn.server.resourcemanager.RMAuditLogger: USER=ubuntu	OPERATION=AM Released Container	TARGET=SchedulerApp	RESULT=SUCCESS	APPID=application_1399261790270_0002	CONTAINERID=container_1399261790270_0002_01_000005
2014-05-05 04:06:27,958 INFO org.apache.hadoop.yarn.server.resourcemanager.scheduler.common.fica.FiCaSchedulerNode: Released container container_1399261790270_0002_01_000005 of capacity <memory:1024, vCores:1> on host noded:54001, which currently has 3 containers, <memory:3072, vCores:3> used and <memory:5120, vCores:5> available, release resources=true
2014-05-05 04:06:27,958 INFO org.apache.hadoop.yarn.server.resourcemanager.scheduler.capacity.LeafQueue: default used=<memory:6144, vCores:5> numContainers=5 user=ubuntu user-resources=<memory:6144, vCores:5>
2014-05-05 04:06:27,959 INFO org.apache.hadoop.yarn.server.resourcemanager.scheduler.capacity.LeafQueue: completedContainer container=Container: [ContainerId: container_1399261790270_0002_01_000005, NodeId: noded:54001, NodeHttpAddress: noded:8042, Resource: <memory:1024, vCores:1>, Priority: 20, Token: Token { kind: ContainerToken, service: 10.0.0.180:54001 }, ] resource=<memory:1024, vCores:1> queue=default: capacity=1.0, absoluteCapacity=1.0, usedResources=<memory:6144, vCores:5>usedCapacity=0.1875, absoluteUsedCapacity=0.1875, numApps=1, numContainers=5 usedCapacity=0.1875 absoluteUsedCapacity=0.1875 used=<memory:6144, vCores:5> cluster=<memory:32768, vCores:32>
2014-05-05 04:06:27,959 INFO org.apache.hadoop.yarn.server.resourcemanager.scheduler.capacity.ParentQueue: completedContainer queue=root usedCapacity=0.1875 absoluteUsedCapacity=0.1875 used=<memory:6144, vCores:5> cluster=<memory:32768, vCores:32>
2014-05-05 04:06:27,959 INFO org.apache.hadoop.yarn.server.resourcemanager.scheduler.capacity.ParentQueue: Re-sorting completed queue: root.default stats: default: capacity=1.0, absoluteCapacity=1.0, usedResources=<memory:6144, vCores:5>usedCapacity=0.1875, absoluteUsedCapacity=0.1875, numApps=1, numContainers=5
2014-05-05 04:06:27,959 INFO org.apache.hadoop.yarn.server.resourcemanager.scheduler.capacity.CapacityScheduler: Application appattempt_1399261790270_0002_000001 released container container_1399261790270_0002_01_000005 on node: host: noded:54001 #containers=3 available=5120 used=3072 with event: FINISHED
2014-05-05 04:06:28,632 INFO org.apache.hadoop.yarn.server.resourcemanager.rmcontainer.RMContainerImpl: container_1399261790270_0002_01_000006 Container Transitioned from ALLOCATED to ACQUIRED
2014-05-05 04:06:28,772 INFO org.apache.hadoop.yarn.server.resourcemanager.rmcontainer.RMContainerImpl: container_1399261790270_0002_01_000006 Container Transitioned from ACQUIRED to RUNNING
2014-05-05 04:06:28,772 INFO org.apache.hadoop.yarn.server.resourcemanager.rmcontainer.RMContainerImpl: container_1399261790270_0002_01_000007 Container Transitioned from NEW to ALLOCATED
2014-05-05 04:06:28,772 INFO org.apache.hadoop.yarn.server.resourcemanager.RMAuditLogger: USER=ubuntu	OPERATION=AM Allocated Container	TARGET=SchedulerApp	RESULT=SUCCESS	APPID=application_1399261790270_0002	CONTAINERID=container_1399261790270_0002_01_000007
2014-05-05 04:06:28,773 INFO org.apache.hadoop.yarn.server.resourcemanager.scheduler.common.fica.FiCaSchedulerNode: Assigned container container_1399261790270_0002_01_000007 of capacity <memory:1024, vCores:1> on host nodec:51351, which currently has 2 containers, <memory:2048, vCores:2> used and <memory:6144, vCores:6> available
2014-05-05 04:06:28,773 INFO org.apache.hadoop.yarn.server.resourcemanager.scheduler.capacity.LeafQueue: assignedContainer application=application_1399261790270_0002 container=Container: [ContainerId: container_1399261790270_0002_01_000007, NodeId: nodec:51351, NodeHttpAddress: nodec:8042, Resource: <memory:1024, vCores:1>, Priority: 10, Token: Token { kind: ContainerToken, service: 10.0.0.181:51351 }, ] containerId=container_1399261790270_0002_01_000007 queue=default: capacity=1.0, absoluteCapacity=1.0, usedResources=<memory:6144, vCores:5>usedCapacity=0.1875, absoluteUsedCapacity=0.1875, numApps=1, numContainers=5 usedCapacity=0.1875 absoluteUsedCapacity=0.1875 used=<memory:6144, vCores:5> cluster=<memory:32768, vCores:32>
2014-05-05 04:06:28,773 INFO org.apache.hadoop.yarn.server.resourcemanager.scheduler.capacity.ParentQueue: Re-sorting assigned queue: root.default stats: default: capacity=1.0, absoluteCapacity=1.0, usedResources=<memory:7168, vCores:6>usedCapacity=0.21875, absoluteUsedCapacity=0.21875, numApps=1, numContainers=6
2014-05-05 04:06:28,773 INFO org.apache.hadoop.yarn.server.resourcemanager.scheduler.capacity.ParentQueue: assignedContainer queue=root usedCapacity=0.21875 absoluteUsedCapacity=0.21875 used=<memory:7168, vCores:6> cluster=<memory:32768, vCores:32>
2014-05-05 04:06:28,773 INFO org.apache.hadoop.yarn.server.resourcemanager.rmcontainer.RMContainerImpl: container_1399261790270_0002_01_000008 Container Transitioned from NEW to ALLOCATED
2014-05-05 04:06:28,773 INFO org.apache.hadoop.yarn.server.resourcemanager.RMAuditLogger: USER=ubuntu	OPERATION=AM Allocated Container	TARGET=SchedulerApp	RESULT=SUCCESS	APPID=application_1399261790270_0002	CONTAINERID=container_1399261790270_0002_01_000008
2014-05-05 04:06:28,774 INFO org.apache.hadoop.yarn.server.resourcemanager.scheduler.common.fica.FiCaSchedulerNode: Assigned container container_1399261790270_0002_01_000008 of capacity <memory:1024, vCores:1> on host nodec:51351, which currently has 3 containers, <memory:3072, vCores:3> used and <memory:5120, vCores:5> available
2014-05-05 04:06:28,774 INFO org.apache.hadoop.yarn.server.resourcemanager.scheduler.capacity.LeafQueue: assignedContainer application=application_1399261790270_0002 container=Container: [ContainerId: container_1399261790270_0002_01_000008, NodeId: nodec:51351, NodeHttpAddress: nodec:8042, Resource: <memory:1024, vCores:1>, Priority: 10, Token: Token { kind: ContainerToken, service: 10.0.0.181:51351 }, ] containerId=container_1399261790270_0002_01_000008 queue=default: capacity=1.0, absoluteCapacity=1.0, usedResources=<memory:7168, vCores:6>usedCapacity=0.21875, absoluteUsedCapacity=0.21875, numApps=1, numContainers=6 usedCapacity=0.21875 absoluteUsedCapacity=0.21875 used=<memory:7168, vCores:6> cluster=<memory:32768, vCores:32>
2014-05-05 04:06:28,774 INFO org.apache.hadoop.yarn.server.resourcemanager.scheduler.capacity.ParentQueue: Re-sorting assigned queue: root.default stats: default: capacity=1.0, absoluteCapacity=1.0, usedResources=<memory:8192, vCores:7>usedCapacity=0.25, absoluteUsedCapacity=0.25, numApps=1, numContainers=7
2014-05-05 04:06:28,774 INFO org.apache.hadoop.yarn.server.resourcemanager.scheduler.capacity.ParentQueue: assignedContainer queue=root usedCapacity=0.25 absoluteUsedCapacity=0.25 used=<memory:8192, vCores:7> cluster=<memory:32768, vCores:32>
2014-05-05 04:06:28,920 INFO org.apache.hadoop.yarn.server.resourcemanager.rmcontainer.RMContainerImpl: container_1399261790270_0002_01_000009 Container Transitioned from NEW to ALLOCATED
2014-05-05 04:06:28,920 INFO org.apache.hadoop.yarn.server.resourcemanager.RMAuditLogger: USER=ubuntu	OPERATION=AM Allocated Container	TARGET=SchedulerApp	RESULT=SUCCESS	APPID=application_1399261790270_0002	CONTAINERID=container_1399261790270_0002_01_000009
2014-05-05 04:06:28,920 INFO org.apache.hadoop.yarn.server.resourcemanager.scheduler.common.fica.FiCaSchedulerNode: Assigned container container_1399261790270_0002_01_000009 of capacity <memory:1024, vCores:1> on host nodeb:41344, which currently has 1 containers, <memory:1024, vCores:1> used and <memory:7168, vCores:7> available
2014-05-05 04:06:28,920 INFO org.apache.hadoop.yarn.server.resourcemanager.scheduler.capacity.LeafQueue: assignedContainer application=application_1399261790270_0002 container=Container: [ContainerId: container_1399261790270_0002_01_000009, NodeId: nodeb:41344, NodeHttpAddress: nodeb:8042, Resource: <memory:1024, vCores:1>, Priority: 10, Token: Token { kind: ContainerToken, service: 10.0.0.59:41344 }, ] containerId=container_1399261790270_0002_01_000009 queue=default: capacity=1.0, absoluteCapacity=1.0, usedResources=<memory:8192, vCores:7>usedCapacity=0.25, absoluteUsedCapacity=0.25, numApps=1, numContainers=7 usedCapacity=0.25 absoluteUsedCapacity=0.25 used=<memory:8192, vCores:7> cluster=<memory:32768, vCores:32>
2014-05-05 04:06:28,920 INFO org.apache.hadoop.yarn.server.resourcemanager.scheduler.capacity.ParentQueue: Re-sorting assigned queue: root.default stats: default: capacity=1.0, absoluteCapacity=1.0, usedResources=<memory:9216, vCores:8>usedCapacity=0.28125, absoluteUsedCapacity=0.28125, numApps=1, numContainers=8
2014-05-05 04:06:28,920 INFO org.apache.hadoop.yarn.server.resourcemanager.scheduler.capacity.ParentQueue: assignedContainer queue=root usedCapacity=0.28125 absoluteUsedCapacity=0.28125 used=<memory:9216, vCores:8> cluster=<memory:32768, vCores:32>
2014-05-05 04:06:28,920 INFO org.apache.hadoop.yarn.server.resourcemanager.rmcontainer.RMContainerImpl: container_1399261790270_0002_01_000010 Container Transitioned from NEW to ALLOCATED
2014-05-05 04:06:28,921 INFO org.apache.hadoop.yarn.server.resourcemanager.RMAuditLogger: USER=ubuntu	OPERATION=AM Allocated Container	TARGET=SchedulerApp	RESULT=SUCCESS	APPID=application_1399261790270_0002	CONTAINERID=container_1399261790270_0002_01_000010
2014-05-05 04:06:28,921 INFO org.apache.hadoop.yarn.server.resourcemanager.scheduler.common.fica.FiCaSchedulerNode: Assigned container container_1399261790270_0002_01_000010 of capacity <memory:1024, vCores:1> on host nodeb:41344, which currently has 2 containers, <memory:2048, vCores:2> used and <memory:6144, vCores:6> available
2014-05-05 04:06:28,921 INFO org.apache.hadoop.yarn.server.resourcemanager.scheduler.capacity.LeafQueue: assignedContainer application=application_1399261790270_0002 container=Container: [ContainerId: container_1399261790270_0002_01_000010, NodeId: nodeb:41344, NodeHttpAddress: nodeb:8042, Resource: <memory:1024, vCores:1>, Priority: 10, Token: Token { kind: ContainerToken, service: 10.0.0.59:41344 }, ] containerId=container_1399261790270_0002_01_000010 queue=default: capacity=1.0, absoluteCapacity=1.0, usedResources=<memory:9216, vCores:8>usedCapacity=0.28125, absoluteUsedCapacity=0.28125, numApps=1, numContainers=8 usedCapacity=0.28125 absoluteUsedCapacity=0.28125 used=<memory:9216, vCores:8> cluster=<memory:32768, vCores:32>
2014-05-05 04:06:28,921 INFO org.apache.hadoop.yarn.server.resourcemanager.scheduler.capacity.ParentQueue: Re-sorting assigned queue: root.default stats: default: capacity=1.0, absoluteCapacity=1.0, usedResources=<memory:10240, vCores:9>usedCapacity=0.3125, absoluteUsedCapacity=0.3125, numApps=1, numContainers=9
2014-05-05 04:06:28,921 INFO org.apache.hadoop.yarn.server.resourcemanager.scheduler.capacity.ParentQueue: assignedContainer queue=root usedCapacity=0.3125 absoluteUsedCapacity=0.3125 used=<memory:10240, vCores:9> cluster=<memory:32768, vCores:32>
2014-05-05 04:06:28,961 INFO org.apache.hadoop.yarn.server.resourcemanager.rmcontainer.RMContainerImpl: container_1399261790270_0002_01_000011 Container Transitioned from NEW to ALLOCATED
2014-05-05 04:06:28,961 INFO org.apache.hadoop.yarn.server.resourcemanager.RMAuditLogger: USER=ubuntu	OPERATION=AM Allocated Container	TARGET=SchedulerApp	RESULT=SUCCESS	APPID=application_1399261790270_0002	CONTAINERID=container_1399261790270_0002_01_000011
2014-05-05 04:06:28,961 INFO org.apache.hadoop.yarn.server.resourcemanager.scheduler.common.fica.FiCaSchedulerNode: Assigned container container_1399261790270_0002_01_000011 of capacity <memory:1024, vCores:1> on host noded:54001, which currently has 4 containers, <memory:4096, vCores:4> used and <memory:4096, vCores:4> available
2014-05-05 04:06:28,961 INFO org.apache.hadoop.yarn.server.resourcemanager.scheduler.capacity.LeafQueue: assignedContainer application=application_1399261790270_0002 container=Container: [ContainerId: container_1399261790270_0002_01_000011, NodeId: noded:54001, NodeHttpAddress: noded:8042, Resource: <memory:1024, vCores:1>, Priority: 10, Token: Token { kind: ContainerToken, service: 10.0.0.180:54001 }, ] containerId=container_1399261790270_0002_01_000011 queue=default: capacity=1.0, absoluteCapacity=1.0, usedResources=<memory:10240, vCores:9>usedCapacity=0.3125, absoluteUsedCapacity=0.3125, numApps=1, numContainers=9 usedCapacity=0.3125 absoluteUsedCapacity=0.3125 used=<memory:10240, vCores:9> cluster=<memory:32768, vCores:32>
2014-05-05 04:06:28,961 INFO org.apache.hadoop.yarn.server.resourcemanager.scheduler.capacity.ParentQueue: Re-sorting assigned queue: root.default stats: default: capacity=1.0, absoluteCapacity=1.0, usedResources=<memory:11264, vCores:10>usedCapacity=0.34375, absoluteUsedCapacity=0.34375, numApps=1, numContainers=10
2014-05-05 04:06:28,961 INFO org.apache.hadoop.yarn.server.resourcemanager.scheduler.capacity.ParentQueue: assignedContainer queue=root usedCapacity=0.34375 absoluteUsedCapacity=0.34375 used=<memory:11264, vCores:10> cluster=<memory:32768, vCores:32>
2014-05-05 04:06:28,962 INFO org.apache.hadoop.yarn.server.resourcemanager.rmcontainer.RMContainerImpl: container_1399261790270_0002_01_000012 Container Transitioned from NEW to ALLOCATED
2014-05-05 04:06:28,962 INFO org.apache.hadoop.yarn.server.resourcemanager.RMAuditLogger: USER=ubuntu	OPERATION=AM Allocated Container	TARGET=SchedulerApp	RESULT=SUCCESS	APPID=application_1399261790270_0002	CONTAINERID=container_1399261790270_0002_01_000012
2014-05-05 04:06:28,962 INFO org.apache.hadoop.yarn.server.resourcemanager.scheduler.common.fica.FiCaSchedulerNode: Assigned container container_1399261790270_0002_01_000012 of capacity <memory:1024, vCores:1> on host noded:54001, which currently has 5 containers, <memory:5120, vCores:5> used and <memory:3072, vCores:3> available
2014-05-05 04:06:28,962 INFO org.apache.hadoop.yarn.server.resourcemanager.scheduler.capacity.LeafQueue: assignedContainer application=application_1399261790270_0002 container=Container: [ContainerId: container_1399261790270_0002_01_000012, NodeId: noded:54001, NodeHttpAddress: noded:8042, Resource: <memory:1024, vCores:1>, Priority: 10, Token: Token { kind: ContainerToken, service: 10.0.0.180:54001 }, ] containerId=container_1399261790270_0002_01_000012 queue=default: capacity=1.0, absoluteCapacity=1.0, usedResources=<memory:11264, vCores:10>usedCapacity=0.34375, absoluteUsedCapacity=0.34375, numApps=1, numContainers=10 usedCapacity=0.34375 absoluteUsedCapacity=0.34375 used=<memory:11264, vCores:10> cluster=<memory:32768, vCores:32>
2014-05-05 04:06:28,962 INFO org.apache.hadoop.yarn.server.resourcemanager.scheduler.capacity.ParentQueue: Re-sorting assigned queue: root.default stats: default: capacity=1.0, absoluteCapacity=1.0, usedResources=<memory:12288, vCores:11>usedCapacity=0.375, absoluteUsedCapacity=0.375, numApps=1, numContainers=11
2014-05-05 04:06:28,962 INFO org.apache.hadoop.yarn.server.resourcemanager.scheduler.capacity.ParentQueue: assignedContainer queue=root usedCapacity=0.375 absoluteUsedCapacity=0.375 used=<memory:12288, vCores:11> cluster=<memory:32768, vCores:32>
2014-05-05 04:06:29,385 INFO org.apache.hadoop.yarn.server.resourcemanager.rmcontainer.RMContainerImpl: container_1399261790270_0002_01_000013 Container Transitioned from NEW to ALLOCATED
2014-05-05 04:06:29,385 INFO org.apache.hadoop.yarn.server.resourcemanager.RMAuditLogger: USER=ubuntu	OPERATION=AM Allocated Container	TARGET=SchedulerApp	RESULT=SUCCESS	APPID=application_1399261790270_0002	CONTAINERID=container_1399261790270_0002_01_000013
2014-05-05 04:06:29,385 INFO org.apache.hadoop.yarn.server.resourcemanager.scheduler.common.fica.FiCaSchedulerNode: Assigned container container_1399261790270_0002_01_000013 of capacity <memory:1024, vCores:1> on host nodea:49324, which currently has 2 containers, <memory:3072, vCores:2> used and <memory:5120, vCores:6> available
2014-05-05 04:06:29,385 INFO org.apache.hadoop.yarn.server.resourcemanager.scheduler.capacity.LeafQueue: assignedContainer application=application_1399261790270_0002 container=Container: [ContainerId: container_1399261790270_0002_01_000013, NodeId: nodea:49324, NodeHttpAddress: nodea:8042, Resource: <memory:1024, vCores:1>, Priority: 10, Token: Token { kind: ContainerToken, service: 10.0.0.158:49324 }, ] containerId=container_1399261790270_0002_01_000013 queue=default: capacity=1.0, absoluteCapacity=1.0, usedResources=<memory:12288, vCores:11>usedCapacity=0.375, absoluteUsedCapacity=0.375, numApps=1, numContainers=11 usedCapacity=0.375 absoluteUsedCapacity=0.375 used=<memory:12288, vCores:11> cluster=<memory:32768, vCores:32>
2014-05-05 04:06:29,386 INFO org.apache.hadoop.yarn.server.resourcemanager.scheduler.capacity.ParentQueue: Re-sorting assigned queue: root.default stats: default: capacity=1.0, absoluteCapacity=1.0, usedResources=<memory:13312, vCores:12>usedCapacity=0.40625, absoluteUsedCapacity=0.40625, numApps=1, numContainers=12
2014-05-05 04:06:29,386 INFO org.apache.hadoop.yarn.server.resourcemanager.scheduler.capacity.ParentQueue: assignedContainer queue=root usedCapacity=0.40625 absoluteUsedCapacity=0.40625 used=<memory:13312, vCores:12> cluster=<memory:32768, vCores:32>
2014-05-05 04:06:29,386 INFO org.apache.hadoop.yarn.server.resourcemanager.rmcontainer.RMContainerImpl: container_1399261790270_0002_01_000014 Container Transitioned from NEW to ALLOCATED
2014-05-05 04:06:29,386 INFO org.apache.hadoop.yarn.server.resourcemanager.RMAuditLogger: USER=ubuntu	OPERATION=AM Allocated Container	TARGET=SchedulerApp	RESULT=SUCCESS	APPID=application_1399261790270_0002	CONTAINERID=container_1399261790270_0002_01_000014
2014-05-05 04:06:29,386 INFO org.apache.hadoop.yarn.server.resourcemanager.scheduler.common.fica.FiCaSchedulerNode: Assigned container container_1399261790270_0002_01_000014 of capacity <memory:1024, vCores:1> on host nodea:49324, which currently has 3 containers, <memory:4096, vCores:3> used and <memory:4096, vCores:5> available
2014-05-05 04:06:29,386 INFO org.apache.hadoop.yarn.server.resourcemanager.scheduler.capacity.LeafQueue: assignedContainer application=application_1399261790270_0002 container=Container: [ContainerId: container_1399261790270_0002_01_000014, NodeId: nodea:49324, NodeHttpAddress: nodea:8042, Resource: <memory:1024, vCores:1>, Priority: 10, Token: Token { kind: ContainerToken, service: 10.0.0.158:49324 }, ] containerId=container_1399261790270_0002_01_000014 queue=default: capacity=1.0, absoluteCapacity=1.0, usedResources=<memory:13312, vCores:12>usedCapacity=0.40625, absoluteUsedCapacity=0.40625, numApps=1, numContainers=12 usedCapacity=0.40625 absoluteUsedCapacity=0.40625 used=<memory:13312, vCores:12> cluster=<memory:32768, vCores:32>
2014-05-05 04:06:29,386 INFO org.apache.hadoop.yarn.server.resourcemanager.scheduler.capacity.ParentQueue: Re-sorting assigned queue: root.default stats: default: capacity=1.0, absoluteCapacity=1.0, usedResources=<memory:14336, vCores:13>usedCapacity=0.4375, absoluteUsedCapacity=0.4375, numApps=1, numContainers=13
2014-05-05 04:06:29,386 INFO org.apache.hadoop.yarn.server.resourcemanager.scheduler.capacity.ParentQueue: assignedContainer queue=root usedCapacity=0.4375 absoluteUsedCapacity=0.4375 used=<memory:14336, vCores:13> cluster=<memory:32768, vCores:32>
2014-05-05 04:06:29,642 INFO org.apache.hadoop.yarn.server.resourcemanager.scheduler.AppSchedulingInfo: checking for deactivate... 
2014-05-05 04:06:29,643 INFO org.apache.hadoop.yarn.server.resourcemanager.rmcontainer.RMContainerImpl: container_1399261790270_0002_01_000007 Container Transitioned from ALLOCATED to ACQUIRED
2014-05-05 04:06:29,643 INFO org.apache.hadoop.yarn.server.resourcemanager.rmcontainer.RMContainerImpl: container_1399261790270_0002_01_000008 Container Transitioned from ALLOCATED to ACQUIRED
2014-05-05 04:06:29,643 INFO org.apache.hadoop.yarn.server.resourcemanager.rmcontainer.RMContainerImpl: container_1399261790270_0002_01_000009 Container Transitioned from ALLOCATED to ACQUIRED
2014-05-05 04:06:29,644 INFO org.apache.hadoop.yarn.server.resourcemanager.rmcontainer.RMContainerImpl: container_1399261790270_0002_01_000010 Container Transitioned from ALLOCATED to ACQUIRED
2014-05-05 04:06:29,644 INFO org.apache.hadoop.yarn.server.resourcemanager.rmcontainer.RMContainerImpl: container_1399261790270_0002_01_000011 Container Transitioned from ALLOCATED to ACQUIRED
2014-05-05 04:06:29,644 INFO org.apache.hadoop.yarn.server.resourcemanager.rmcontainer.RMContainerImpl: container_1399261790270_0002_01_000012 Container Transitioned from ALLOCATED to ACQUIRED
2014-05-05 04:06:29,644 INFO org.apache.hadoop.yarn.server.resourcemanager.rmcontainer.RMContainerImpl: container_1399261790270_0002_01_000013 Container Transitioned from ALLOCATED to ACQUIRED
2014-05-05 04:06:29,645 INFO org.apache.hadoop.yarn.server.resourcemanager.rmcontainer.RMContainerImpl: container_1399261790270_0002_01_000014 Container Transitioned from ALLOCATED to ACQUIRED
2014-05-05 04:06:29,776 INFO org.apache.hadoop.yarn.server.resourcemanager.rmcontainer.RMContainerImpl: container_1399261790270_0002_01_000007 Container Transitioned from ACQUIRED to RUNNING
2014-05-05 04:06:29,777 INFO org.apache.hadoop.yarn.server.resourcemanager.rmcontainer.RMContainerImpl: container_1399261790270_0002_01_000008 Container Transitioned from ACQUIRED to RUNNING
2014-05-05 04:06:29,922 INFO org.apache.hadoop.yarn.server.resourcemanager.rmcontainer.RMContainerImpl: container_1399261790270_0002_01_000009 Container Transitioned from ACQUIRED to RUNNING
2014-05-05 04:06:29,922 INFO org.apache.hadoop.yarn.server.resourcemanager.rmcontainer.RMContainerImpl: container_1399261790270_0002_01_000010 Container Transitioned from ACQUIRED to RUNNING
2014-05-05 04:06:29,971 INFO org.apache.hadoop.yarn.server.resourcemanager.rmcontainer.RMContainerImpl: container_1399261790270_0002_01_000011 Container Transitioned from ACQUIRED to RUNNING
2014-05-05 04:06:29,972 INFO org.apache.hadoop.yarn.server.resourcemanager.rmcontainer.RMContainerImpl: container_1399261790270_0002_01_000012 Container Transitioned from ACQUIRED to RUNNING
2014-05-05 04:06:30,388 INFO org.apache.hadoop.yarn.server.resourcemanager.rmcontainer.RMContainerImpl: container_1399261790270_0002_01_000013 Container Transitioned from ACQUIRED to RUNNING
2014-05-05 04:06:30,388 INFO org.apache.hadoop.yarn.server.resourcemanager.rmcontainer.RMContainerImpl: container_1399261790270_0002_01_000014 Container Transitioned from ACQUIRED to RUNNING
2014-05-05 04:06:30,651 INFO org.apache.hadoop.yarn.server.resourcemanager.scheduler.AppSchedulingInfo: checking for deactivate... 
2014-05-05 04:06:40,525 INFO org.apache.hadoop.yarn.server.resourcemanager.rmcontainer.RMContainerImpl: container_1399261790270_0002_01_000002 Container Transitioned from RUNNING to COMPLETED
2014-05-05 04:06:40,525 INFO org.apache.hadoop.yarn.server.resourcemanager.scheduler.common.fica.FiCaSchedulerApp: Completed container: container_1399261790270_0002_01_000002 in state: COMPLETED event:FINISHED
2014-05-05 04:06:40,525 INFO org.apache.hadoop.yarn.server.resourcemanager.RMAuditLogger: USER=ubuntu	OPERATION=AM Released Container	TARGET=SchedulerApp	RESULT=SUCCESS	APPID=application_1399261790270_0002	CONTAINERID=container_1399261790270_0002_01_000002
2014-05-05 04:06:40,525 INFO org.apache.hadoop.yarn.server.resourcemanager.scheduler.common.fica.FiCaSchedulerNode: Released container container_1399261790270_0002_01_000002 of capacity <memory:1024, vCores:1> on host noded:54001, which currently has 4 containers, <memory:4096, vCores:4> used and <memory:4096, vCores:4> available, release resources=true
2014-05-05 04:06:40,525 INFO org.apache.hadoop.yarn.server.resourcemanager.scheduler.capacity.LeafQueue: default used=<memory:13312, vCores:12> numContainers=12 user=ubuntu user-resources=<memory:13312, vCores:12>
2014-05-05 04:06:40,526 INFO org.apache.hadoop.yarn.server.resourcemanager.scheduler.capacity.LeafQueue: completedContainer container=Container: [ContainerId: container_1399261790270_0002_01_000002, NodeId: noded:54001, NodeHttpAddress: noded:8042, Resource: <memory:1024, vCores:1>, Priority: 20, Token: Token { kind: ContainerToken, service: 10.0.0.180:54001 }, ] resource=<memory:1024, vCores:1> queue=default: capacity=1.0, absoluteCapacity=1.0, usedResources=<memory:13312, vCores:12>usedCapacity=0.40625, absoluteUsedCapacity=0.40625, numApps=1, numContainers=12 usedCapacity=0.40625 absoluteUsedCapacity=0.40625 used=<memory:13312, vCores:12> cluster=<memory:32768, vCores:32>
2014-05-05 04:06:40,526 INFO org.apache.hadoop.yarn.server.resourcemanager.scheduler.capacity.ParentQueue: completedContainer queue=root usedCapacity=0.40625 absoluteUsedCapacity=0.40625 used=<memory:13312, vCores:12> cluster=<memory:32768, vCores:32>
2014-05-05 04:06:40,526 INFO org.apache.hadoop.yarn.server.resourcemanager.scheduler.capacity.ParentQueue: Re-sorting completed queue: root.default stats: default: capacity=1.0, absoluteCapacity=1.0, usedResources=<memory:13312, vCores:12>usedCapacity=0.40625, absoluteUsedCapacity=0.40625, numApps=1, numContainers=12
2014-05-05 04:06:40,526 INFO org.apache.hadoop.yarn.server.resourcemanager.scheduler.capacity.CapacityScheduler: Application appattempt_1399261790270_0002_000001 released container container_1399261790270_0002_01_000002 on node: host: noded:54001 #containers=4 available=4096 used=4096 with event: FINISHED
2014-05-05 04:06:41,530 INFO org.apache.hadoop.yarn.server.resourcemanager.rmcontainer.RMContainerImpl: container_1399261790270_0002_01_000004 Container Transitioned from RUNNING to COMPLETED
2014-05-05 04:06:41,530 INFO org.apache.hadoop.yarn.server.resourcemanager.scheduler.common.fica.FiCaSchedulerApp: Completed container: container_1399261790270_0002_01_000004 in state: COMPLETED event:FINISHED
2014-05-05 04:06:41,530 INFO org.apache.hadoop.yarn.server.resourcemanager.RMAuditLogger: USER=ubuntu	OPERATION=AM Released Container	TARGET=SchedulerApp	RESULT=SUCCESS	APPID=application_1399261790270_0002	CONTAINERID=container_1399261790270_0002_01_000004
2014-05-05 04:06:41,530 INFO org.apache.hadoop.yarn.server.resourcemanager.scheduler.common.fica.FiCaSchedulerNode: Released container container_1399261790270_0002_01_000004 of capacity <memory:1024, vCores:1> on host noded:54001, which currently has 3 containers, <memory:3072, vCores:3> used and <memory:5120, vCores:5> available, release resources=true
2014-05-05 04:06:41,530 INFO org.apache.hadoop.yarn.server.resourcemanager.scheduler.capacity.LeafQueue: default used=<memory:12288, vCores:11> numContainers=11 user=ubuntu user-resources=<memory:12288, vCores:11>
2014-05-05 04:06:41,530 INFO org.apache.hadoop.yarn.server.resourcemanager.scheduler.capacity.LeafQueue: completedContainer container=Container: [ContainerId: container_1399261790270_0002_01_000004, NodeId: noded:54001, NodeHttpAddress: noded:8042, Resource: <memory:1024, vCores:1>, Priority: 20, Token: Token { kind: ContainerToken, service: 10.0.0.180:54001 }, ] resource=<memory:1024, vCores:1> queue=default: capacity=1.0, absoluteCapacity=1.0, usedResources=<memory:12288, vCores:11>usedCapacity=0.375, absoluteUsedCapacity=0.375, numApps=1, numContainers=11 usedCapacity=0.375 absoluteUsedCapacity=0.375 used=<memory:12288, vCores:11> cluster=<memory:32768, vCores:32>
2014-05-05 04:06:41,531 INFO org.apache.hadoop.yarn.server.resourcemanager.scheduler.capacity.ParentQueue: completedContainer queue=root usedCapacity=0.375 absoluteUsedCapacity=0.375 used=<memory:12288, vCores:11> cluster=<memory:32768, vCores:32>
2014-05-05 04:06:41,531 INFO org.apache.hadoop.yarn.server.resourcemanager.scheduler.capacity.ParentQueue: Re-sorting completed queue: root.default stats: default: capacity=1.0, absoluteCapacity=1.0, usedResources=<memory:12288, vCores:11>usedCapacity=0.375, absoluteUsedCapacity=0.375, numApps=1, numContainers=11
2014-05-05 04:06:41,531 INFO org.apache.hadoop.yarn.server.resourcemanager.scheduler.capacity.CapacityScheduler: Application appattempt_1399261790270_0002_000001 released container container_1399261790270_0002_01_000004 on node: host: noded:54001 #containers=3 available=5120 used=3072 with event: FINISHED
2014-05-05 04:06:45,357 INFO org.apache.hadoop.yarn.server.resourcemanager.rmcontainer.RMContainerImpl: container_1399261790270_0002_01_000003 Container Transitioned from RUNNING to COMPLETED
2014-05-05 04:06:45,357 INFO org.apache.hadoop.yarn.server.resourcemanager.scheduler.common.fica.FiCaSchedulerApp: Completed container: container_1399261790270_0002_01_000003 in state: COMPLETED event:FINISHED
2014-05-05 04:06:45,357 INFO org.apache.hadoop.yarn.server.resourcemanager.RMAuditLogger: USER=ubuntu	OPERATION=AM Released Container	TARGET=SchedulerApp	RESULT=SUCCESS	APPID=application_1399261790270_0002	CONTAINERID=container_1399261790270_0002_01_000003
2014-05-05 04:06:45,357 INFO org.apache.hadoop.yarn.server.resourcemanager.scheduler.common.fica.FiCaSchedulerNode: Released container container_1399261790270_0002_01_000003 of capacity <memory:1024, vCores:1> on host noded:54001, which currently has 2 containers, <memory:2048, vCores:2> used and <memory:6144, vCores:6> available, release resources=true
2014-05-05 04:06:45,358 INFO org.apache.hadoop.yarn.server.resourcemanager.scheduler.capacity.LeafQueue: default used=<memory:11264, vCores:10> numContainers=10 user=ubuntu user-resources=<memory:11264, vCores:10>
2014-05-05 04:06:45,358 INFO org.apache.hadoop.yarn.server.resourcemanager.scheduler.capacity.LeafQueue: completedContainer container=Container: [ContainerId: container_1399261790270_0002_01_000003, NodeId: noded:54001, NodeHttpAddress: noded:8042, Resource: <memory:1024, vCores:1>, Priority: 20, Token: Token { kind: ContainerToken, service: 10.0.0.180:54001 }, ] resource=<memory:1024, vCores:1> queue=default: capacity=1.0, absoluteCapacity=1.0, usedResources=<memory:11264, vCores:10>usedCapacity=0.34375, absoluteUsedCapacity=0.34375, numApps=1, numContainers=10 usedCapacity=0.34375 absoluteUsedCapacity=0.34375 used=<memory:11264, vCores:10> cluster=<memory:32768, vCores:32>
2014-05-05 04:06:45,358 INFO org.apache.hadoop.yarn.server.resourcemanager.scheduler.capacity.ParentQueue: completedContainer queue=root usedCapacity=0.34375 absoluteUsedCapacity=0.34375 used=<memory:11264, vCores:10> cluster=<memory:32768, vCores:32>
2014-05-05 04:06:45,358 INFO org.apache.hadoop.yarn.server.resourcemanager.scheduler.capacity.ParentQueue: Re-sorting completed queue: root.default stats: default: capacity=1.0, absoluteCapacity=1.0, usedResources=<memory:11264, vCores:10>usedCapacity=0.34375, absoluteUsedCapacity=0.34375, numApps=1, numContainers=10
2014-05-05 04:06:45,358 INFO org.apache.hadoop.yarn.server.resourcemanager.scheduler.capacity.CapacityScheduler: Application appattempt_1399261790270_0002_000001 released container container_1399261790270_0002_01_000003 on node: host: noded:54001 #containers=2 available=6144 used=2048 with event: FINISHED
2014-05-05 04:06:45,373 INFO org.apache.hadoop.yarn.server.resourcemanager.rmcontainer.RMContainerImpl: container_1399261790270_0002_01_000006 Container Transitioned from RUNNING to COMPLETED
2014-05-05 04:06:45,373 INFO org.apache.hadoop.yarn.server.resourcemanager.scheduler.common.fica.FiCaSchedulerApp: Completed container: container_1399261790270_0002_01_000006 in state: COMPLETED event:FINISHED
2014-05-05 04:06:45,373 INFO org.apache.hadoop.yarn.server.resourcemanager.RMAuditLogger: USER=ubuntu	OPERATION=AM Released Container	TARGET=SchedulerApp	RESULT=SUCCESS	APPID=application_1399261790270_0002	CONTAINERID=container_1399261790270_0002_01_000006
2014-05-05 04:06:45,374 INFO org.apache.hadoop.yarn.server.resourcemanager.scheduler.common.fica.FiCaSchedulerNode: Released container container_1399261790270_0002_01_000006 of capacity <memory:1024, vCores:1> on host nodec:51351, which currently has 2 containers, <memory:2048, vCores:2> used and <memory:6144, vCores:6> available, release resources=true
2014-05-05 04:06:45,374 INFO org.apache.hadoop.yarn.server.resourcemanager.scheduler.capacity.LeafQueue: default used=<memory:10240, vCores:9> numContainers=9 user=ubuntu user-resources=<memory:10240, vCores:9>
2014-05-05 04:06:45,374 INFO org.apache.hadoop.yarn.server.resourcemanager.scheduler.capacity.LeafQueue: completedContainer container=Container: [ContainerId: container_1399261790270_0002_01_000006, NodeId: nodec:51351, NodeHttpAddress: nodec:8042, Resource: <memory:1024, vCores:1>, Priority: 20, Token: Token { kind: ContainerToken, service: 10.0.0.181:51351 }, ] resource=<memory:1024, vCores:1> queue=default: capacity=1.0, absoluteCapacity=1.0, usedResources=<memory:10240, vCores:9>usedCapacity=0.3125, absoluteUsedCapacity=0.3125, numApps=1, numContainers=9 usedCapacity=0.3125 absoluteUsedCapacity=0.3125 used=<memory:10240, vCores:9> cluster=<memory:32768, vCores:32>
2014-05-05 04:06:45,375 INFO org.apache.hadoop.yarn.server.resourcemanager.scheduler.capacity.ParentQueue: completedContainer queue=root usedCapacity=0.3125 absoluteUsedCapacity=0.3125 used=<memory:10240, vCores:9> cluster=<memory:32768, vCores:32>
2014-05-05 04:06:45,375 INFO org.apache.hadoop.yarn.server.resourcemanager.scheduler.capacity.ParentQueue: Re-sorting completed queue: root.default stats: default: capacity=1.0, absoluteCapacity=1.0, usedResources=<memory:10240, vCores:9>usedCapacity=0.3125, absoluteUsedCapacity=0.3125, numApps=1, numContainers=9
2014-05-05 04:06:45,375 INFO org.apache.hadoop.yarn.server.resourcemanager.scheduler.capacity.CapacityScheduler: Application appattempt_1399261790270_0002_000001 released container container_1399261790270_0002_01_000006 on node: host: nodec:51351 #containers=2 available=6144 used=2048 with event: FINISHED
2014-05-05 04:08:25,263 INFO org.apache.hadoop.yarn.server.resourcemanager.rmcontainer.RMContainerImpl: container_1399261790270_0002_01_000007 Container Transitioned from RUNNING to COMPLETED
2014-05-05 04:08:25,263 INFO org.apache.hadoop.yarn.server.resourcemanager.scheduler.common.fica.FiCaSchedulerApp: Completed container: container_1399261790270_0002_01_000007 in state: COMPLETED event:FINISHED
2014-05-05 04:08:25,263 INFO org.apache.hadoop.yarn.server.resourcemanager.RMAuditLogger: USER=ubuntu	OPERATION=AM Released Container	TARGET=SchedulerApp	RESULT=SUCCESS	APPID=application_1399261790270_0002	CONTAINERID=container_1399261790270_0002_01_000007
2014-05-05 04:08:25,263 INFO org.apache.hadoop.yarn.server.resourcemanager.scheduler.common.fica.FiCaSchedulerNode: Released container container_1399261790270_0002_01_000007 of capacity <memory:1024, vCores:1> on host nodec:51351, which currently has 1 containers, <memory:1024, vCores:1> used and <memory:7168, vCores:7> available, release resources=true
2014-05-05 04:08:25,263 INFO org.apache.hadoop.yarn.server.resourcemanager.scheduler.capacity.LeafQueue: default used=<memory:9216, vCores:8> numContainers=8 user=ubuntu user-resources=<memory:9216, vCores:8>
2014-05-05 04:08:25,263 INFO org.apache.hadoop.yarn.server.resourcemanager.scheduler.capacity.LeafQueue: completedContainer container=Container: [ContainerId: container_1399261790270_0002_01_000007, NodeId: nodec:51351, NodeHttpAddress: nodec:8042, Resource: <memory:1024, vCores:1>, Priority: 10, Token: Token { kind: ContainerToken, service: 10.0.0.181:51351 }, ] resource=<memory:1024, vCores:1> queue=default: capacity=1.0, absoluteCapacity=1.0, usedResources=<memory:9216, vCores:8>usedCapacity=0.28125, absoluteUsedCapacity=0.28125, numApps=1, numContainers=8 usedCapacity=0.28125 absoluteUsedCapacity=0.28125 used=<memory:9216, vCores:8> cluster=<memory:32768, vCores:32>
2014-05-05 04:08:25,263 INFO org.apache.hadoop.yarn.server.resourcemanager.scheduler.capacity.ParentQueue: completedContainer queue=root usedCapacity=0.28125 absoluteUsedCapacity=0.28125 used=<memory:9216, vCores:8> cluster=<memory:32768, vCores:32>
2014-05-05 04:08:25,263 INFO org.apache.hadoop.yarn.server.resourcemanager.scheduler.capacity.ParentQueue: Re-sorting completed queue: root.default stats: default: capacity=1.0, absoluteCapacity=1.0, usedResources=<memory:9216, vCores:8>usedCapacity=0.28125, absoluteUsedCapacity=0.28125, numApps=1, numContainers=8
2014-05-05 04:08:25,263 INFO org.apache.hadoop.yarn.server.resourcemanager.scheduler.capacity.CapacityScheduler: Application appattempt_1399261790270_0002_000001 released container container_1399261790270_0002_01_000007 on node: host: nodec:51351 #containers=1 available=7168 used=1024 with event: FINISHED
2014-05-05 04:08:29,892 INFO org.apache.hadoop.yarn.server.resourcemanager.rmcontainer.RMContainerImpl: container_1399261790270_0002_01_000008 Container Transitioned from RUNNING to COMPLETED
2014-05-05 04:08:29,892 INFO org.apache.hadoop.yarn.server.resourcemanager.scheduler.common.fica.FiCaSchedulerApp: Completed container: container_1399261790270_0002_01_000008 in state: COMPLETED event:FINISHED
2014-05-05 04:08:29,892 INFO org.apache.hadoop.yarn.server.resourcemanager.RMAuditLogger: USER=ubuntu	OPERATION=AM Released Container	TARGET=SchedulerApp	RESULT=SUCCESS	APPID=application_1399261790270_0002	CONTAINERID=container_1399261790270_0002_01_000008
2014-05-05 04:08:29,892 INFO org.apache.hadoop.yarn.server.resourcemanager.scheduler.common.fica.FiCaSchedulerNode: Released container container_1399261790270_0002_01_000008 of capacity <memory:1024, vCores:1> on host nodec:51351, which currently has 0 containers, <memory:0, vCores:0> used and <memory:8192, vCores:8> available, release resources=true
2014-05-05 04:08:29,892 INFO org.apache.hadoop.yarn.server.resourcemanager.scheduler.capacity.LeafQueue: default used=<memory:8192, vCores:7> numContainers=7 user=ubuntu user-resources=<memory:8192, vCores:7>
2014-05-05 04:08:29,893 INFO org.apache.hadoop.yarn.server.resourcemanager.scheduler.capacity.LeafQueue: completedContainer container=Container: [ContainerId: container_1399261790270_0002_01_000008, NodeId: nodec:51351, NodeHttpAddress: nodec:8042, Resource: <memory:1024, vCores:1>, Priority: 10, Token: Token { kind: ContainerToken, service: 10.0.0.181:51351 }, ] resource=<memory:1024, vCores:1> queue=default: capacity=1.0, absoluteCapacity=1.0, usedResources=<memory:8192, vCores:7>usedCapacity=0.25, absoluteUsedCapacity=0.25, numApps=1, numContainers=7 usedCapacity=0.25 absoluteUsedCapacity=0.25 used=<memory:8192, vCores:7> cluster=<memory:32768, vCores:32>
2014-05-05 04:08:29,893 INFO org.apache.hadoop.yarn.server.resourcemanager.scheduler.capacity.ParentQueue: completedContainer queue=root usedCapacity=0.25 absoluteUsedCapacity=0.25 used=<memory:8192, vCores:7> cluster=<memory:32768, vCores:32>
2014-05-05 04:08:29,893 INFO org.apache.hadoop.yarn.server.resourcemanager.scheduler.capacity.ParentQueue: Re-sorting completed queue: root.default stats: default: capacity=1.0, absoluteCapacity=1.0, usedResources=<memory:8192, vCores:7>usedCapacity=0.25, absoluteUsedCapacity=0.25, numApps=1, numContainers=7
2014-05-05 04:08:29,893 INFO org.apache.hadoop.yarn.server.resourcemanager.scheduler.capacity.CapacityScheduler: Application appattempt_1399261790270_0002_000001 released container container_1399261790270_0002_01_000008 on node: host: nodec:51351 #containers=0 available=8192 used=0 with event: FINISHED
2014-05-05 04:09:05,168 INFO org.apache.hadoop.yarn.server.resourcemanager.rmcontainer.RMContainerImpl: container_1399261790270_0002_01_000009 Container Transitioned from RUNNING to COMPLETED
2014-05-05 04:09:05,168 INFO org.apache.hadoop.yarn.server.resourcemanager.scheduler.common.fica.FiCaSchedulerApp: Completed container: container_1399261790270_0002_01_000009 in state: COMPLETED event:FINISHED
2014-05-05 04:09:05,168 INFO org.apache.hadoop.yarn.server.resourcemanager.RMAuditLogger: USER=ubuntu	OPERATION=AM Released Container	TARGET=SchedulerApp	RESULT=SUCCESS	APPID=application_1399261790270_0002	CONTAINERID=container_1399261790270_0002_01_000009
2014-05-05 04:09:05,168 INFO org.apache.hadoop.yarn.server.resourcemanager.scheduler.common.fica.FiCaSchedulerNode: Released container container_1399261790270_0002_01_000009 of capacity <memory:1024, vCores:1> on host nodeb:41344, which currently has 1 containers, <memory:1024, vCores:1> used and <memory:7168, vCores:7> available, release resources=true
2014-05-05 04:09:05,168 INFO org.apache.hadoop.yarn.server.resourcemanager.scheduler.capacity.LeafQueue: default used=<memory:7168, vCores:6> numContainers=6 user=ubuntu user-resources=<memory:7168, vCores:6>
2014-05-05 04:09:05,168 INFO org.apache.hadoop.yarn.server.resourcemanager.scheduler.capacity.LeafQueue: completedContainer container=Container: [ContainerId: container_1399261790270_0002_01_000009, NodeId: nodeb:41344, NodeHttpAddress: nodeb:8042, Resource: <memory:1024, vCores:1>, Priority: 10, Token: Token { kind: ContainerToken, service: 10.0.0.59:41344 }, ] resource=<memory:1024, vCores:1> queue=default: capacity=1.0, absoluteCapacity=1.0, usedResources=<memory:7168, vCores:6>usedCapacity=0.21875, absoluteUsedCapacity=0.21875, numApps=1, numContainers=6 usedCapacity=0.21875 absoluteUsedCapacity=0.21875 used=<memory:7168, vCores:6> cluster=<memory:32768, vCores:32>
2014-05-05 04:09:05,168 INFO org.apache.hadoop.yarn.server.resourcemanager.scheduler.capacity.ParentQueue: completedContainer queue=root usedCapacity=0.21875 absoluteUsedCapacity=0.21875 used=<memory:7168, vCores:6> cluster=<memory:32768, vCores:32>
2014-05-05 04:09:05,169 INFO org.apache.hadoop.yarn.server.resourcemanager.scheduler.capacity.ParentQueue: Re-sorting completed queue: root.default stats: default: capacity=1.0, absoluteCapacity=1.0, usedResources=<memory:7168, vCores:6>usedCapacity=0.21875, absoluteUsedCapacity=0.21875, numApps=1, numContainers=6
2014-05-05 04:09:05,169 INFO org.apache.hadoop.yarn.server.resourcemanager.scheduler.capacity.CapacityScheduler: Application appattempt_1399261790270_0002_000001 released container container_1399261790270_0002_01_000009 on node: host: nodeb:41344 #containers=1 available=7168 used=1024 with event: FINISHED
2014-05-05 04:09:06,170 INFO org.apache.hadoop.yarn.server.resourcemanager.rmcontainer.RMContainerImpl: container_1399261790270_0002_01_000010 Container Transitioned from RUNNING to COMPLETED
2014-05-05 04:09:06,170 INFO org.apache.hadoop.yarn.server.resourcemanager.scheduler.common.fica.FiCaSchedulerApp: Completed container: container_1399261790270_0002_01_000010 in state: COMPLETED event:FINISHED
2014-05-05 04:09:06,170 INFO org.apache.hadoop.yarn.server.resourcemanager.RMAuditLogger: USER=ubuntu	OPERATION=AM Released Container	TARGET=SchedulerApp	RESULT=SUCCESS	APPID=application_1399261790270_0002	CONTAINERID=container_1399261790270_0002_01_000010
2014-05-05 04:09:06,170 INFO org.apache.hadoop.yarn.server.resourcemanager.scheduler.common.fica.FiCaSchedulerNode: Released container container_1399261790270_0002_01_000010 of capacity <memory:1024, vCores:1> on host nodeb:41344, which currently has 0 containers, <memory:0, vCores:0> used and <memory:8192, vCores:8> available, release resources=true
2014-05-05 04:09:06,170 INFO org.apache.hadoop.yarn.server.resourcemanager.scheduler.capacity.LeafQueue: default used=<memory:6144, vCores:5> numContainers=5 user=ubuntu user-resources=<memory:6144, vCores:5>
2014-05-05 04:09:06,170 INFO org.apache.hadoop.yarn.server.resourcemanager.scheduler.capacity.LeafQueue: completedContainer container=Container: [ContainerId: container_1399261790270_0002_01_000010, NodeId: nodeb:41344, NodeHttpAddress: nodeb:8042, Resource: <memory:1024, vCores:1>, Priority: 10, Token: Token { kind: ContainerToken, service: 10.0.0.59:41344 }, ] resource=<memory:1024, vCores:1> queue=default: capacity=1.0, absoluteCapacity=1.0, usedResources=<memory:6144, vCores:5>usedCapacity=0.1875, absoluteUsedCapacity=0.1875, numApps=1, numContainers=5 usedCapacity=0.1875 absoluteUsedCapacity=0.1875 used=<memory:6144, vCores:5> cluster=<memory:32768, vCores:32>
2014-05-05 04:09:06,170 INFO org.apache.hadoop.yarn.server.resourcemanager.scheduler.capacity.ParentQueue: completedContainer queue=root usedCapacity=0.1875 absoluteUsedCapacity=0.1875 used=<memory:6144, vCores:5> cluster=<memory:32768, vCores:32>
2014-05-05 04:09:06,170 INFO org.apache.hadoop.yarn.server.resourcemanager.scheduler.capacity.ParentQueue: Re-sorting completed queue: root.default stats: default: capacity=1.0, absoluteCapacity=1.0, usedResources=<memory:6144, vCores:5>usedCapacity=0.1875, absoluteUsedCapacity=0.1875, numApps=1, numContainers=5
2014-05-05 04:09:06,170 INFO org.apache.hadoop.yarn.server.resourcemanager.scheduler.capacity.CapacityScheduler: Application appattempt_1399261790270_0002_000001 released container container_1399261790270_0002_01_000010 on node: host: nodeb:41344 #containers=0 available=8192 used=0 with event: FINISHED
2014-05-05 04:09:06,465 INFO org.apache.hadoop.yarn.server.resourcemanager.rmcontainer.RMContainerImpl: container_1399261790270_0002_01_000014 Container Transitioned from RUNNING to COMPLETED
2014-05-05 04:09:06,465 INFO org.apache.hadoop.yarn.server.resourcemanager.scheduler.common.fica.FiCaSchedulerApp: Completed container: container_1399261790270_0002_01_000014 in state: COMPLETED event:FINISHED
2014-05-05 04:09:06,466 INFO org.apache.hadoop.yarn.server.resourcemanager.RMAuditLogger: USER=ubuntu	OPERATION=AM Released Container	TARGET=SchedulerApp	RESULT=SUCCESS	APPID=application_1399261790270_0002	CONTAINERID=container_1399261790270_0002_01_000014
2014-05-05 04:09:06,466 INFO org.apache.hadoop.yarn.server.resourcemanager.scheduler.common.fica.FiCaSchedulerNode: Released container container_1399261790270_0002_01_000014 of capacity <memory:1024, vCores:1> on host nodea:49324, which currently has 2 containers, <memory:3072, vCores:2> used and <memory:5120, vCores:6> available, release resources=true
2014-05-05 04:09:06,466 INFO org.apache.hadoop.yarn.server.resourcemanager.scheduler.capacity.LeafQueue: default used=<memory:5120, vCores:4> numContainers=4 user=ubuntu user-resources=<memory:5120, vCores:4>
2014-05-05 04:09:06,466 INFO org.apache.hadoop.yarn.server.resourcemanager.scheduler.capacity.LeafQueue: completedContainer container=Container: [ContainerId: container_1399261790270_0002_01_000014, NodeId: nodea:49324, NodeHttpAddress: nodea:8042, Resource: <memory:1024, vCores:1>, Priority: 10, Token: Token { kind: ContainerToken, service: 10.0.0.158:49324 }, ] resource=<memory:1024, vCores:1> queue=default: capacity=1.0, absoluteCapacity=1.0, usedResources=<memory:5120, vCores:4>usedCapacity=0.15625, absoluteUsedCapacity=0.15625, numApps=1, numContainers=4 usedCapacity=0.15625 absoluteUsedCapacity=0.15625 used=<memory:5120, vCores:4> cluster=<memory:32768, vCores:32>
2014-05-05 04:09:06,466 INFO org.apache.hadoop.yarn.server.resourcemanager.scheduler.capacity.ParentQueue: completedContainer queue=root usedCapacity=0.15625 absoluteUsedCapacity=0.15625 used=<memory:5120, vCores:4> cluster=<memory:32768, vCores:32>
2014-05-05 04:09:06,466 INFO org.apache.hadoop.yarn.server.resourcemanager.scheduler.capacity.ParentQueue: Re-sorting completed queue: root.default stats: default: capacity=1.0, absoluteCapacity=1.0, usedResources=<memory:5120, vCores:4>usedCapacity=0.15625, absoluteUsedCapacity=0.15625, numApps=1, numContainers=4
2014-05-05 04:09:06,466 INFO org.apache.hadoop.yarn.server.resourcemanager.scheduler.capacity.CapacityScheduler: Application appattempt_1399261790270_0002_000001 released container container_1399261790270_0002_01_000014 on node: host: nodea:49324 #containers=2 available=5120 used=3072 with event: FINISHED
2014-05-05 04:09:07,469 INFO org.apache.hadoop.yarn.server.resourcemanager.rmcontainer.RMContainerImpl: container_1399261790270_0002_01_000013 Container Transitioned from RUNNING to COMPLETED
2014-05-05 04:09:07,469 INFO org.apache.hadoop.yarn.server.resourcemanager.scheduler.common.fica.FiCaSchedulerApp: Completed container: container_1399261790270_0002_01_000013 in state: COMPLETED event:FINISHED
2014-05-05 04:09:07,469 INFO org.apache.hadoop.yarn.server.resourcemanager.RMAuditLogger: USER=ubuntu	OPERATION=AM Released Container	TARGET=SchedulerApp	RESULT=SUCCESS	APPID=application_1399261790270_0002	CONTAINERID=container_1399261790270_0002_01_000013
2014-05-05 04:09:07,469 INFO org.apache.hadoop.yarn.server.resourcemanager.scheduler.common.fica.FiCaSchedulerNode: Released container container_1399261790270_0002_01_000013 of capacity <memory:1024, vCores:1> on host nodea:49324, which currently has 1 containers, <memory:2048, vCores:1> used and <memory:6144, vCores:7> available, release resources=true
2014-05-05 04:09:07,469 INFO org.apache.hadoop.yarn.server.resourcemanager.scheduler.capacity.LeafQueue: default used=<memory:4096, vCores:3> numContainers=3 user=ubuntu user-resources=<memory:4096, vCores:3>
2014-05-05 04:09:07,469 INFO org.apache.hadoop.yarn.server.resourcemanager.scheduler.capacity.LeafQueue: completedContainer container=Container: [ContainerId: container_1399261790270_0002_01_000013, NodeId: nodea:49324, NodeHttpAddress: nodea:8042, Resource: <memory:1024, vCores:1>, Priority: 10, Token: Token { kind: ContainerToken, service: 10.0.0.158:49324 }, ] resource=<memory:1024, vCores:1> queue=default: capacity=1.0, absoluteCapacity=1.0, usedResources=<memory:4096, vCores:3>usedCapacity=0.125, absoluteUsedCapacity=0.125, numApps=1, numContainers=3 usedCapacity=0.125 absoluteUsedCapacity=0.125 used=<memory:4096, vCores:3> cluster=<memory:32768, vCores:32>
2014-05-05 04:09:07,469 INFO org.apache.hadoop.yarn.server.resourcemanager.scheduler.capacity.ParentQueue: completedContainer queue=root usedCapacity=0.125 absoluteUsedCapacity=0.125 used=<memory:4096, vCores:3> cluster=<memory:32768, vCores:32>
2014-05-05 04:09:07,469 INFO org.apache.hadoop.yarn.server.resourcemanager.scheduler.capacity.ParentQueue: Re-sorting completed queue: root.default stats: default: capacity=1.0, absoluteCapacity=1.0, usedResources=<memory:4096, vCores:3>usedCapacity=0.125, absoluteUsedCapacity=0.125, numApps=1, numContainers=3
2014-05-05 04:09:07,469 INFO org.apache.hadoop.yarn.server.resourcemanager.scheduler.capacity.CapacityScheduler: Application appattempt_1399261790270_0002_000001 released container container_1399261790270_0002_01_000013 on node: host: nodea:49324 #containers=1 available=6144 used=2048 with event: FINISHED
2014-05-05 04:09:08,866 INFO org.apache.hadoop.yarn.server.resourcemanager.rmcontainer.RMContainerImpl: container_1399261790270_0002_01_000012 Container Transitioned from RUNNING to COMPLETED
2014-05-05 04:09:08,866 INFO org.apache.hadoop.yarn.server.resourcemanager.scheduler.common.fica.FiCaSchedulerApp: Completed container: container_1399261790270_0002_01_000012 in state: COMPLETED event:FINISHED
2014-05-05 04:09:08,866 INFO org.apache.hadoop.yarn.server.resourcemanager.RMAuditLogger: USER=ubuntu	OPERATION=AM Released Container	TARGET=SchedulerApp	RESULT=SUCCESS	APPID=application_1399261790270_0002	CONTAINERID=container_1399261790270_0002_01_000012
2014-05-05 04:09:08,866 INFO org.apache.hadoop.yarn.server.resourcemanager.scheduler.common.fica.FiCaSchedulerNode: Released container container_1399261790270_0002_01_000012 of capacity <memory:1024, vCores:1> on host noded:54001, which currently has 1 containers, <memory:1024, vCores:1> used and <memory:7168, vCores:7> available, release resources=true
2014-05-05 04:09:08,867 INFO org.apache.hadoop.yarn.server.resourcemanager.scheduler.capacity.LeafQueue: default used=<memory:3072, vCores:2> numContainers=2 user=ubuntu user-resources=<memory:3072, vCores:2>
2014-05-05 04:09:08,867 INFO org.apache.hadoop.yarn.server.resourcemanager.scheduler.capacity.LeafQueue: completedContainer container=Container: [ContainerId: container_1399261790270_0002_01_000012, NodeId: noded:54001, NodeHttpAddress: noded:8042, Resource: <memory:1024, vCores:1>, Priority: 10, Token: Token { kind: ContainerToken, service: 10.0.0.180:54001 }, ] resource=<memory:1024, vCores:1> queue=default: capacity=1.0, absoluteCapacity=1.0, usedResources=<memory:3072, vCores:2>usedCapacity=0.09375, absoluteUsedCapacity=0.09375, numApps=1, numContainers=2 usedCapacity=0.09375 absoluteUsedCapacity=0.09375 used=<memory:3072, vCores:2> cluster=<memory:32768, vCores:32>
2014-05-05 04:09:08,867 INFO org.apache.hadoop.yarn.server.resourcemanager.scheduler.capacity.ParentQueue: completedContainer queue=root usedCapacity=0.09375 absoluteUsedCapacity=0.09375 used=<memory:3072, vCores:2> cluster=<memory:32768, vCores:32>
2014-05-05 04:09:08,867 INFO org.apache.hadoop.yarn.server.resourcemanager.scheduler.capacity.ParentQueue: Re-sorting completed queue: root.default stats: default: capacity=1.0, absoluteCapacity=1.0, usedResources=<memory:3072, vCores:2>usedCapacity=0.09375, absoluteUsedCapacity=0.09375, numApps=1, numContainers=2
2014-05-05 04:09:08,867 INFO org.apache.hadoop.yarn.server.resourcemanager.scheduler.capacity.CapacityScheduler: Application appattempt_1399261790270_0002_000001 released container container_1399261790270_0002_01_000012 on node: host: noded:54001 #containers=1 available=7168 used=1024 with event: FINISHED
2014-05-05 04:09:09,103 INFO org.apache.hadoop.yarn.server.resourcemanager.rmapp.attempt.RMAppAttemptImpl: appattempt_1399261790270_0002_000001 State change from RUNNING to FINISHING
2014-05-05 04:09:09,104 INFO org.apache.hadoop.yarn.server.resourcemanager.rmapp.RMAppImpl: Removing application with id application_1399261790270_0002
2014-05-05 04:09:09,104 INFO org.apache.hadoop.yarn.server.resourcemanager.rmapp.RMAppImpl: application_1399261790270_0002 State change from RUNNING to REMOVING
2014-05-05 04:09:09,104 INFO org.apache.hadoop.yarn.server.resourcemanager.recovery.RMStateStore: Removing info for app: application_1399261790270_0002
2014-05-05 04:09:09,104 INFO org.apache.hadoop.yarn.server.resourcemanager.rmapp.RMAppImpl: application_1399261790270_0002 State change from REMOVING to FINISHING
2014-05-05 04:09:09,868 INFO org.apache.hadoop.yarn.server.resourcemanager.rmcontainer.RMContainerImpl: container_1399261790270_0002_01_000011 Container Transitioned from RUNNING to COMPLETED
2014-05-05 04:09:09,868 INFO org.apache.hadoop.yarn.server.resourcemanager.scheduler.common.fica.FiCaSchedulerApp: Completed container: container_1399261790270_0002_01_000011 in state: COMPLETED event:FINISHED
2014-05-05 04:09:09,868 INFO org.apache.hadoop.yarn.server.resourcemanager.RMAuditLogger: USER=ubuntu	OPERATION=AM Released Container	TARGET=SchedulerApp	RESULT=SUCCESS	APPID=application_1399261790270_0002	CONTAINERID=container_1399261790270_0002_01_000011
2014-05-05 04:09:09,868 INFO org.apache.hadoop.yarn.server.resourcemanager.scheduler.common.fica.FiCaSchedulerNode: Released container container_1399261790270_0002_01_000011 of capacity <memory:1024, vCores:1> on host noded:54001, which currently has 0 containers, <memory:0, vCores:0> used and <memory:8192, vCores:8> available, release resources=true
2014-05-05 04:09:09,868 INFO org.apache.hadoop.yarn.server.resourcemanager.scheduler.capacity.LeafQueue: default used=<memory:2048, vCores:1> numContainers=1 user=ubuntu user-resources=<memory:2048, vCores:1>
2014-05-05 04:09:09,868 INFO org.apache.hadoop.yarn.server.resourcemanager.scheduler.capacity.LeafQueue: completedContainer container=Container: [ContainerId: container_1399261790270_0002_01_000011, NodeId: noded:54001, NodeHttpAddress: noded:8042, Resource: <memory:1024, vCores:1>, Priority: 10, Token: Token { kind: ContainerToken, service: 10.0.0.180:54001 }, ] resource=<memory:1024, vCores:1> queue=default: capacity=1.0, absoluteCapacity=1.0, usedResources=<memory:2048, vCores:1>usedCapacity=0.0625, absoluteUsedCapacity=0.0625, numApps=1, numContainers=1 usedCapacity=0.0625 absoluteUsedCapacity=0.0625 used=<memory:2048, vCores:1> cluster=<memory:32768, vCores:32>
2014-05-05 04:09:09,868 INFO org.apache.hadoop.yarn.server.resourcemanager.scheduler.capacity.ParentQueue: completedContainer queue=root usedCapacity=0.0625 absoluteUsedCapacity=0.0625 used=<memory:2048, vCores:1> cluster=<memory:32768, vCores:32>
2014-05-05 04:09:09,868 INFO org.apache.hadoop.yarn.server.resourcemanager.scheduler.capacity.ParentQueue: Re-sorting completed queue: root.default stats: default: capacity=1.0, absoluteCapacity=1.0, usedResources=<memory:2048, vCores:1>usedCapacity=0.0625, absoluteUsedCapacity=0.0625, numApps=1, numContainers=1
2014-05-05 04:09:09,868 INFO org.apache.hadoop.yarn.server.resourcemanager.scheduler.capacity.CapacityScheduler: Application appattempt_1399261790270_0002_000001 released container container_1399261790270_0002_01_000011 on node: host: noded:54001 #containers=0 available=8192 used=0 with event: FINISHED
2014-05-05 04:09:15,494 INFO org.apache.hadoop.yarn.server.resourcemanager.rmcontainer.RMContainerImpl: container_1399261790270_0002_01_000001 Container Transitioned from RUNNING to COMPLETED
2014-05-05 04:09:15,495 INFO org.apache.hadoop.yarn.server.resourcemanager.scheduler.common.fica.FiCaSchedulerApp: Completed container: container_1399261790270_0002_01_000001 in state: COMPLETED event:FINISHED
2014-05-05 04:09:15,495 INFO org.apache.hadoop.yarn.server.resourcemanager.RMAuditLogger: USER=ubuntu	OPERATION=AM Released Container	TARGET=SchedulerApp	RESULT=SUCCESS	APPID=application_1399261790270_0002	CONTAINERID=container_1399261790270_0002_01_000001
2014-05-05 04:09:15,495 INFO org.apache.hadoop.yarn.server.resourcemanager.scheduler.common.fica.FiCaSchedulerNode: Released container container_1399261790270_0002_01_000001 of capacity <memory:2048, vCores:1> on host nodea:49324, which currently has 0 containers, <memory:0, vCores:0> used and <memory:8192, vCores:8> available, release resources=true
2014-05-05 04:09:15,495 INFO org.apache.hadoop.yarn.server.resourcemanager.scheduler.capacity.LeafQueue: default used=<memory:0, vCores:0> numContainers=0 user=ubuntu user-resources=<memory:0, vCores:0>
2014-05-05 04:09:15,495 INFO org.apache.hadoop.yarn.server.resourcemanager.scheduler.capacity.LeafQueue: completedContainer container=Container: [ContainerId: container_1399261790270_0002_01_000001, NodeId: nodea:49324, NodeHttpAddress: nodea:8042, Resource: <memory:2048, vCores:1>, Priority: 0, Token: Token { kind: ContainerToken, service: 10.0.0.158:49324 }, ] resource=<memory:2048, vCores:1> queue=default: capacity=1.0, absoluteCapacity=1.0, usedResources=<memory:0, vCores:0>usedCapacity=0.0, absoluteUsedCapacity=0.0, numApps=1, numContainers=0 usedCapacity=0.0 absoluteUsedCapacity=0.0 used=<memory:0, vCores:0> cluster=<memory:32768, vCores:32>
2014-05-05 04:09:15,495 INFO org.apache.hadoop.yarn.server.resourcemanager.scheduler.capacity.ParentQueue: completedContainer queue=root usedCapacity=0.0 absoluteUsedCapacity=0.0 used=<memory:0, vCores:0> cluster=<memory:32768, vCores:32>
2014-05-05 04:09:15,495 INFO org.apache.hadoop.yarn.server.resourcemanager.scheduler.capacity.ParentQueue: Re-sorting completed queue: root.default stats: default: capacity=1.0, absoluteCapacity=1.0, usedResources=<memory:0, vCores:0>usedCapacity=0.0, absoluteUsedCapacity=0.0, numApps=1, numContainers=0
2014-05-05 04:09:15,495 INFO org.apache.hadoop.yarn.server.resourcemanager.scheduler.capacity.CapacityScheduler: Application appattempt_1399261790270_0002_000001 released container container_1399261790270_0002_01_000001 on node: host: nodea:49324 #containers=0 available=8192 used=0 with event: FINISHED
2014-05-05 04:09:15,495 INFO org.apache.hadoop.yarn.server.resourcemanager.ApplicationMasterService: Unregistering app attempt : appattempt_1399261790270_0002_000001
2014-05-05 04:09:15,496 INFO org.apache.hadoop.yarn.server.resourcemanager.rmapp.attempt.RMAppAttemptImpl: appattempt_1399261790270_0002_000001 State change from FINISHING to FINISHED
2014-05-05 04:09:15,496 INFO org.apache.hadoop.yarn.server.resourcemanager.rmapp.RMAppImpl: application_1399261790270_0002 State change from FINISHING to FINISHED
2014-05-05 04:09:15,496 INFO org.apache.hadoop.yarn.server.resourcemanager.scheduler.capacity.CapacityScheduler: Application appattempt_1399261790270_0002_000001 is done. finalState=FINISHED
2014-05-05 04:09:15,496 INFO org.apache.hadoop.yarn.server.resourcemanager.RMAuditLogger: USER=ubuntu	OPERATION=Application Finished - Succeeded	TARGET=RMAppManager	RESULT=SUCCESS	APPID=application_1399261790270_0002
2014-05-05 04:09:15,496 INFO org.apache.hadoop.yarn.server.resourcemanager.scheduler.AppSchedulingInfo: Application application_1399261790270_0002 requests cleared
2014-05-05 04:09:15,496 INFO org.apache.hadoop.yarn.server.resourcemanager.RMAppManager$ApplicationSummary: appId=application_1399261790270_0002,name=hints||path:/in1m||num reduce:8,user=ubuntu,queue=default,state=FINISHED,trackingUrl=ec2-54-186-230-200.us-west-2.compute.amazonaws.com:8088/proxy/application_1399261790270_0002/jobhistory/job/job_1399261790270_0002,appMasterHost=ip-10-0-0-158,startTime=1399262752960,finishTime=1399262949104,finalStatus=SUCCEEDED
2014-05-05 04:09:15,496 INFO org.apache.hadoop.yarn.server.resourcemanager.scheduler.capacity.LeafQueue: Application removed - appId: application_1399261790270_0002 user: ubuntu queue: default #user-pending-applications: 0 #user-active-applications: 0 #queue-pending-applications: 0 #queue-active-applications: 0
2014-05-05 04:09:15,496 INFO org.apache.hadoop.yarn.server.resourcemanager.scheduler.capacity.ParentQueue: Application removed - appId: application_1399261790270_0002 user: ubuntu leaf-queue of parent: root #applications: 0
2014-05-05 04:09:15,496 INFO org.apache.hadoop.yarn.server.resourcemanager.amlauncher.AMLauncher: Cleaning master appattempt_1399261790270_0002_000001
2014-05-05 04:10:25,898 INFO org.apache.hadoop.yarn.server.webproxy.WebAppProxyServlet: dr.who is accessing unchecked http://nodea:19888/jobhistory/job/job_1399261790270_0002/jobhistory/job/job_1399261790270_0002 which is the app master GUI of application_1399261790270_0002 owned by ubuntu
2014-05-05 04:10:29,014 INFO org.apache.hadoop.yarn.server.webproxy.WebAppProxyServlet: dr.who is accessing unchecked http://nodea:19888/jobhistory/job/job_1399261790270_0002/jobhistory/job/job_1399261790270_0002 which is the app master GUI of application_1399261790270_0002 owned by ubuntu
2014-05-05 04:10:55,556 INFO org.apache.hadoop.yarn.server.resourcemanager.ClientRMService: Allocated new applicationId: 3
2014-05-05 04:10:57,236 INFO org.apache.hadoop.yarn.server.resourcemanager.ClientRMService: Application with id 3 submitted by user ubuntu
2014-05-05 04:10:57,236 INFO org.apache.hadoop.yarn.server.resourcemanager.rmapp.RMAppImpl: Storing application with id application_1399261790270_0003
2014-05-05 04:10:57,236 INFO org.apache.hadoop.yarn.server.resourcemanager.RMAuditLogger: USER=ubuntu	IP=10.0.0.158	OPERATION=Submit Application Request	TARGET=ClientRMService	RESULT=SUCCESS	APPID=application_1399261790270_0003
2014-05-05 04:10:57,236 INFO org.apache.hadoop.yarn.server.resourcemanager.recovery.RMStateStore: Storing info for app: application_1399261790270_0003
2014-05-05 04:10:57,236 INFO org.apache.hadoop.yarn.server.resourcemanager.rmapp.RMAppImpl: application_1399261790270_0003 State change from NEW to NEW_SAVING
2014-05-05 04:10:57,238 INFO org.apache.hadoop.yarn.server.resourcemanager.rmapp.RMAppImpl: application_1399261790270_0003 State change from NEW_SAVING to SUBMITTED
2014-05-05 04:10:57,238 INFO org.apache.hadoop.yarn.server.resourcemanager.ApplicationMasterService: Registering app attempt : appattempt_1399261790270_0003_000001
2014-05-05 04:10:57,238 INFO org.apache.hadoop.yarn.server.resourcemanager.rmapp.attempt.RMAppAttemptImpl: appattempt_1399261790270_0003_000001 State change from NEW to SUBMITTED
2014-05-05 04:10:57,239 INFO org.apache.hadoop.yarn.server.resourcemanager.scheduler.capacity.LeafQueue: Application application_1399261790270_0003 from user: ubuntu activated in queue: default
2014-05-05 04:10:57,239 INFO org.apache.hadoop.yarn.server.resourcemanager.scheduler.capacity.LeafQueue: Application added - appId: application_1399261790270_0003 user: org.apache.hadoop.yarn.server.resourcemanager.scheduler.capacity.LeafQueue$User@51c79d63, leaf-queue: default #user-pending-applications: 0 #user-active-applications: 1 #queue-pending-applications: 0 #queue-active-applications: 1
2014-05-05 04:10:57,239 INFO org.apache.hadoop.yarn.server.resourcemanager.scheduler.capacity.ParentQueue: Application added - appId: application_1399261790270_0003 user: ubuntu leaf-queue of parent: root #applications: 1
2014-05-05 04:10:57,239 INFO org.apache.hadoop.yarn.server.resourcemanager.scheduler.capacity.CapacityScheduler: Application Submission: appattempt_1399261790270_0003_000001, user: ubuntu queue: default: capacity=1.0, absoluteCapacity=1.0, usedResources=<memory:0, vCores:0>usedCapacity=0.0, absoluteUsedCapacity=0.0, numApps=1, numContainers=0, currently active: 1
2014-05-05 04:10:57,239 INFO org.apache.hadoop.yarn.server.resourcemanager.rmapp.attempt.RMAppAttemptImpl: appattempt_1399261790270_0003_000001 State change from SUBMITTED to SCHEDULED
2014-05-05 04:10:57,239 INFO org.apache.hadoop.yarn.server.resourcemanager.rmapp.RMAppImpl: application_1399261790270_0003 State change from SUBMITTED to ACCEPTED
2014-05-05 04:10:57,289 INFO org.apache.hadoop.yarn.server.resourcemanager.rmcontainer.RMContainerImpl: container_1399261790270_0003_01_000001 Container Transitioned from NEW to ALLOCATED
2014-05-05 04:10:57,289 INFO org.apache.hadoop.yarn.server.resourcemanager.RMAuditLogger: USER=ubuntu	OPERATION=AM Allocated Container	TARGET=SchedulerApp	RESULT=SUCCESS	APPID=application_1399261790270_0003	CONTAINERID=container_1399261790270_0003_01_000001
2014-05-05 04:10:57,289 INFO org.apache.hadoop.yarn.server.resourcemanager.scheduler.common.fica.FiCaSchedulerNode: Assigned container container_1399261790270_0003_01_000001 of capacity <memory:2048, vCores:1> on host nodeb:41344, which currently has 1 containers, <memory:2048, vCores:1> used and <memory:6144, vCores:7> available
2014-05-05 04:10:57,289 INFO org.apache.hadoop.yarn.server.resourcemanager.scheduler.capacity.LeafQueue: assignedContainer application=application_1399261790270_0003 container=Container: [ContainerId: container_1399261790270_0003_01_000001, NodeId: nodeb:41344, NodeHttpAddress: nodeb:8042, Resource: <memory:2048, vCores:1>, Priority: 0, Token: Token { kind: ContainerToken, service: 10.0.0.59:41344 }, ] containerId=container_1399261790270_0003_01_000001 queue=default: capacity=1.0, absoluteCapacity=1.0, usedResources=<memory:0, vCores:0>usedCapacity=0.0, absoluteUsedCapacity=0.0, numApps=1, numContainers=0 usedCapacity=0.0 absoluteUsedCapacity=0.0 used=<memory:0, vCores:0> cluster=<memory:32768, vCores:32>
2014-05-05 04:10:57,289 INFO org.apache.hadoop.yarn.server.resourcemanager.scheduler.capacity.ParentQueue: Re-sorting assigned queue: root.default stats: default: capacity=1.0, absoluteCapacity=1.0, usedResources=<memory:2048, vCores:1>usedCapacity=0.0625, absoluteUsedCapacity=0.0625, numApps=1, numContainers=1
2014-05-05 04:10:57,289 INFO org.apache.hadoop.yarn.server.resourcemanager.rmcontainer.RMContainerImpl: container_1399261790270_0003_01_000001 Container Transitioned from ALLOCATED to ACQUIRED
2014-05-05 04:10:57,289 INFO org.apache.hadoop.yarn.server.resourcemanager.scheduler.capacity.ParentQueue: assignedContainer queue=root usedCapacity=0.0625 absoluteUsedCapacity=0.0625 used=<memory:2048, vCores:1> cluster=<memory:32768, vCores:32>
2014-05-05 04:10:57,290 INFO org.apache.hadoop.yarn.server.resourcemanager.rmapp.attempt.RMAppAttemptImpl: Storing attempt: AppId: application_1399261790270_0003 AttemptId: appattempt_1399261790270_0003_000001 MasterContainer: Container: [ContainerId: container_1399261790270_0003_01_000001, NodeId: nodeb:41344, NodeHttpAddress: nodeb:8042, Resource: <memory:2048, vCores:1>, Priority: 0, Token: Token { kind: ContainerToken, service: 10.0.0.59:41344 }, ]
2014-05-05 04:10:57,290 INFO org.apache.hadoop.yarn.server.resourcemanager.rmapp.attempt.RMAppAttemptImpl: appattempt_1399261790270_0003_000001 State change from SCHEDULED to ALLOCATED_SAVING
2014-05-05 04:10:57,290 INFO org.apache.hadoop.yarn.server.resourcemanager.recovery.RMStateStore: Storing info for attempt: appattempt_1399261790270_0003_000001
2014-05-05 04:10:57,290 INFO org.apache.hadoop.yarn.server.resourcemanager.rmapp.attempt.RMAppAttemptImpl: appattempt_1399261790270_0003_000001 State change from ALLOCATED_SAVING to ALLOCATED
2014-05-05 04:10:57,294 INFO org.apache.hadoop.yarn.server.resourcemanager.amlauncher.AMLauncher: Launching masterappattempt_1399261790270_0003_000001
2014-05-05 04:10:57,298 INFO org.apache.hadoop.yarn.server.resourcemanager.amlauncher.AMLauncher: Setting up container Container: [ContainerId: container_1399261790270_0003_01_000001, NodeId: nodeb:41344, NodeHttpAddress: nodeb:8042, Resource: <memory:2048, vCores:1>, Priority: 0, Token: Token { kind: ContainerToken, service: 10.0.0.59:41344 }, ] for AM appattempt_1399261790270_0003_000001
2014-05-05 04:10:57,299 INFO org.apache.hadoop.yarn.server.resourcemanager.amlauncher.AMLauncher: Command to launch container container_1399261790270_0003_01_000001 : $JAVA_HOME/bin/java -Dlog4j.configuration=container-log4j.properties -Dyarn.app.container.log.dir=<LOG_DIR> -Dyarn.app.container.log.filesize=0 -Dhadoop.root.logger=INFO,CLA  -Xmx1024m org.apache.hadoop.mapreduce.v2.app.MRAppMaster 1><LOG_DIR>/stdout 2><LOG_DIR>/stderr 
2014-05-05 04:10:57,315 INFO org.apache.hadoop.yarn.server.resourcemanager.amlauncher.AMLauncher: Done launching container Container: [ContainerId: container_1399261790270_0003_01_000001, NodeId: nodeb:41344, NodeHttpAddress: nodeb:8042, Resource: <memory:2048, vCores:1>, Priority: 0, Token: Token { kind: ContainerToken, service: 10.0.0.59:41344 }, ] for AM appattempt_1399261790270_0003_000001
2014-05-05 04:10:57,315 INFO org.apache.hadoop.yarn.server.resourcemanager.rmapp.attempt.RMAppAttemptImpl: appattempt_1399261790270_0003_000001 State change from ALLOCATED to LAUNCHED
2014-05-05 04:10:58,290 INFO org.apache.hadoop.yarn.server.resourcemanager.rmcontainer.RMContainerImpl: container_1399261790270_0003_01_000001 Container Transitioned from ACQUIRED to RUNNING
2014-05-05 04:11:02,321 INFO SecurityLogger.org.apache.hadoop.ipc.Server: Auth successful for appattempt_1399261790270_0003_000001 (auth:SIMPLE)
2014-05-05 04:11:02,328 INFO org.apache.hadoop.yarn.server.resourcemanager.ApplicationMasterService: AM registration appattempt_1399261790270_0003_000001
2014-05-05 04:11:02,328 INFO org.apache.hadoop.yarn.server.resourcemanager.RMAuditLogger: USER=ubuntu	IP=10.0.0.59	OPERATION=Register App Master	TARGET=ApplicationMasterService	RESULT=SUCCESS	APPID=application_1399261790270_0003	APPATTEMPTID=appattempt_1399261790270_0003_000001
2014-05-05 04:11:02,329 INFO org.apache.hadoop.yarn.server.resourcemanager.rmapp.attempt.RMAppAttemptImpl: appattempt_1399261790270_0003_000001 State change from LAUNCHED to RUNNING
2014-05-05 04:11:02,329 INFO org.apache.hadoop.yarn.server.resourcemanager.rmapp.RMAppImpl: application_1399261790270_0003 State change from ACCEPTED to RUNNING
2014-05-05 04:11:03,602 INFO org.apache.hadoop.yarn.server.resourcemanager.rmcontainer.RMContainerImpl: container_1399261790270_0003_01_000002 Container Transitioned from NEW to ALLOCATED
2014-05-05 04:11:03,603 INFO org.apache.hadoop.yarn.server.resourcemanager.RMAuditLogger: USER=ubuntu	OPERATION=AM Allocated Container	TARGET=SchedulerApp	RESULT=SUCCESS	APPID=application_1399261790270_0003	CONTAINERID=container_1399261790270_0003_01_000002
2014-05-05 04:11:03,603 INFO org.apache.hadoop.yarn.server.resourcemanager.scheduler.common.fica.FiCaSchedulerNode: Assigned container container_1399261790270_0003_01_000002 of capacity <memory:1024, vCores:1> on host nodea:49324, which currently has 1 containers, <memory:1024, vCores:1> used and <memory:7168, vCores:7> available
2014-05-05 04:11:03,603 INFO org.apache.hadoop.yarn.server.resourcemanager.scheduler.capacity.LeafQueue: assignedContainer application=application_1399261790270_0003 container=Container: [ContainerId: container_1399261790270_0003_01_000002, NodeId: nodea:49324, NodeHttpAddress: nodea:8042, Resource: <memory:1024, vCores:1>, Priority: 20, Token: Token { kind: ContainerToken, service: 10.0.0.158:49324 }, ] containerId=container_1399261790270_0003_01_000002 queue=default: capacity=1.0, absoluteCapacity=1.0, usedResources=<memory:2048, vCores:1>usedCapacity=0.0625, absoluteUsedCapacity=0.0625, numApps=1, numContainers=1 usedCapacity=0.0625 absoluteUsedCapacity=0.0625 used=<memory:2048, vCores:1> cluster=<memory:32768, vCores:32>
2014-05-05 04:11:03,603 INFO org.apache.hadoop.yarn.server.resourcemanager.scheduler.capacity.ParentQueue: Re-sorting assigned queue: root.default stats: default: capacity=1.0, absoluteCapacity=1.0, usedResources=<memory:3072, vCores:2>usedCapacity=0.09375, absoluteUsedCapacity=0.09375, numApps=1, numContainers=2
2014-05-05 04:11:03,603 INFO org.apache.hadoop.yarn.server.resourcemanager.scheduler.capacity.ParentQueue: assignedContainer queue=root usedCapacity=0.09375 absoluteUsedCapacity=0.09375 used=<memory:3072, vCores:2> cluster=<memory:32768, vCores:32>
2014-05-05 04:11:03,603 INFO org.apache.hadoop.yarn.server.resourcemanager.rmcontainer.RMContainerImpl: container_1399261790270_0003_01_000003 Container Transitioned from NEW to ALLOCATED
2014-05-05 04:11:03,603 INFO org.apache.hadoop.yarn.server.resourcemanager.RMAuditLogger: USER=ubuntu	OPERATION=AM Allocated Container	TARGET=SchedulerApp	RESULT=SUCCESS	APPID=application_1399261790270_0003	CONTAINERID=container_1399261790270_0003_01_000003
2014-05-05 04:11:03,603 INFO org.apache.hadoop.yarn.server.resourcemanager.scheduler.common.fica.FiCaSchedulerNode: Assigned container container_1399261790270_0003_01_000003 of capacity <memory:1024, vCores:1> on host nodea:49324, which currently has 2 containers, <memory:2048, vCores:2> used and <memory:6144, vCores:6> available
2014-05-05 04:11:03,603 INFO org.apache.hadoop.yarn.server.resourcemanager.scheduler.capacity.LeafQueue: assignedContainer application=application_1399261790270_0003 container=Container: [ContainerId: container_1399261790270_0003_01_000003, NodeId: nodea:49324, NodeHttpAddress: nodea:8042, Resource: <memory:1024, vCores:1>, Priority: 20, Token: Token { kind: ContainerToken, service: 10.0.0.158:49324 }, ] containerId=container_1399261790270_0003_01_000003 queue=default: capacity=1.0, absoluteCapacity=1.0, usedResources=<memory:3072, vCores:2>usedCapacity=0.09375, absoluteUsedCapacity=0.09375, numApps=1, numContainers=2 usedCapacity=0.09375 absoluteUsedCapacity=0.09375 used=<memory:3072, vCores:2> cluster=<memory:32768, vCores:32>
2014-05-05 04:11:03,604 INFO org.apache.hadoop.yarn.server.resourcemanager.scheduler.capacity.ParentQueue: Re-sorting assigned queue: root.default stats: default: capacity=1.0, absoluteCapacity=1.0, usedResources=<memory:4096, vCores:3>usedCapacity=0.125, absoluteUsedCapacity=0.125, numApps=1, numContainers=3
2014-05-05 04:11:03,604 INFO org.apache.hadoop.yarn.server.resourcemanager.scheduler.capacity.ParentQueue: assignedContainer queue=root usedCapacity=0.125 absoluteUsedCapacity=0.125 used=<memory:4096, vCores:3> cluster=<memory:32768, vCores:32>
2014-05-05 04:11:03,604 INFO org.apache.hadoop.yarn.server.resourcemanager.rmcontainer.RMContainerImpl: container_1399261790270_0003_01_000004 Container Transitioned from NEW to ALLOCATED
2014-05-05 04:11:03,604 INFO org.apache.hadoop.yarn.server.resourcemanager.RMAuditLogger: USER=ubuntu	OPERATION=AM Allocated Container	TARGET=SchedulerApp	RESULT=SUCCESS	APPID=application_1399261790270_0003	CONTAINERID=container_1399261790270_0003_01_000004
2014-05-05 04:11:03,604 INFO org.apache.hadoop.yarn.server.resourcemanager.scheduler.common.fica.FiCaSchedulerNode: Assigned container container_1399261790270_0003_01_000004 of capacity <memory:1024, vCores:1> on host nodea:49324, which currently has 3 containers, <memory:3072, vCores:3> used and <memory:5120, vCores:5> available
2014-05-05 04:11:03,604 INFO org.apache.hadoop.yarn.server.resourcemanager.scheduler.capacity.LeafQueue: assignedContainer application=application_1399261790270_0003 container=Container: [ContainerId: container_1399261790270_0003_01_000004, NodeId: nodea:49324, NodeHttpAddress: nodea:8042, Resource: <memory:1024, vCores:1>, Priority: 20, Token: Token { kind: ContainerToken, service: 10.0.0.158:49324 }, ] containerId=container_1399261790270_0003_01_000004 queue=default: capacity=1.0, absoluteCapacity=1.0, usedResources=<memory:4096, vCores:3>usedCapacity=0.125, absoluteUsedCapacity=0.125, numApps=1, numContainers=3 usedCapacity=0.125 absoluteUsedCapacity=0.125 used=<memory:4096, vCores:3> cluster=<memory:32768, vCores:32>
2014-05-05 04:11:03,604 INFO org.apache.hadoop.yarn.server.resourcemanager.scheduler.capacity.ParentQueue: Re-sorting assigned queue: root.default stats: default: capacity=1.0, absoluteCapacity=1.0, usedResources=<memory:5120, vCores:4>usedCapacity=0.15625, absoluteUsedCapacity=0.15625, numApps=1, numContainers=4
2014-05-05 04:11:03,604 INFO org.apache.hadoop.yarn.server.resourcemanager.scheduler.capacity.ParentQueue: assignedContainer queue=root usedCapacity=0.15625 absoluteUsedCapacity=0.15625 used=<memory:5120, vCores:4> cluster=<memory:32768, vCores:32>
2014-05-05 04:11:03,605 INFO org.apache.hadoop.yarn.server.resourcemanager.rmcontainer.RMContainerImpl: container_1399261790270_0003_01_000005 Container Transitioned from NEW to ALLOCATED
2014-05-05 04:11:03,605 INFO org.apache.hadoop.yarn.server.resourcemanager.RMAuditLogger: USER=ubuntu	OPERATION=AM Allocated Container	TARGET=SchedulerApp	RESULT=SUCCESS	APPID=application_1399261790270_0003	CONTAINERID=container_1399261790270_0003_01_000005
2014-05-05 04:11:03,605 INFO org.apache.hadoop.yarn.server.resourcemanager.scheduler.common.fica.FiCaSchedulerNode: Assigned container container_1399261790270_0003_01_000005 of capacity <memory:1024, vCores:1> on host nodea:49324, which currently has 4 containers, <memory:4096, vCores:4> used and <memory:4096, vCores:4> available
2014-05-05 04:11:03,605 INFO org.apache.hadoop.yarn.server.resourcemanager.scheduler.capacity.LeafQueue: assignedContainer application=application_1399261790270_0003 container=Container: [ContainerId: container_1399261790270_0003_01_000005, NodeId: nodea:49324, NodeHttpAddress: nodea:8042, Resource: <memory:1024, vCores:1>, Priority: 20, Token: Token { kind: ContainerToken, service: 10.0.0.158:49324 }, ] containerId=container_1399261790270_0003_01_000005 queue=default: capacity=1.0, absoluteCapacity=1.0, usedResources=<memory:5120, vCores:4>usedCapacity=0.15625, absoluteUsedCapacity=0.15625, numApps=1, numContainers=4 usedCapacity=0.15625 absoluteUsedCapacity=0.15625 used=<memory:5120, vCores:4> cluster=<memory:32768, vCores:32>
2014-05-05 04:11:03,605 INFO org.apache.hadoop.yarn.server.resourcemanager.scheduler.capacity.ParentQueue: Re-sorting assigned queue: root.default stats: default: capacity=1.0, absoluteCapacity=1.0, usedResources=<memory:6144, vCores:5>usedCapacity=0.1875, absoluteUsedCapacity=0.1875, numApps=1, numContainers=5
2014-05-05 04:11:03,605 INFO org.apache.hadoop.yarn.server.resourcemanager.scheduler.capacity.ParentQueue: assignedContainer queue=root usedCapacity=0.1875 absoluteUsedCapacity=0.1875 used=<memory:6144, vCores:5> cluster=<memory:32768, vCores:32>
2014-05-05 04:11:04,393 INFO org.apache.hadoop.yarn.server.resourcemanager.rmcontainer.RMContainerImpl: container_1399261790270_0003_01_000002 Container Transitioned from ALLOCATED to ACQUIRED
2014-05-05 04:11:04,393 INFO org.apache.hadoop.yarn.server.resourcemanager.rmcontainer.RMContainerImpl: container_1399261790270_0003_01_000003 Container Transitioned from ALLOCATED to ACQUIRED
2014-05-05 04:11:04,393 INFO org.apache.hadoop.yarn.server.resourcemanager.rmcontainer.RMContainerImpl: container_1399261790270_0003_01_000004 Container Transitioned from ALLOCATED to ACQUIRED
2014-05-05 04:11:04,393 INFO org.apache.hadoop.yarn.server.resourcemanager.rmcontainer.RMContainerImpl: container_1399261790270_0003_01_000005 Container Transitioned from ALLOCATED to ACQUIRED
2014-05-05 04:11:04,605 INFO org.apache.hadoop.yarn.server.resourcemanager.rmcontainer.RMContainerImpl: container_1399261790270_0003_01_000002 Container Transitioned from ACQUIRED to RUNNING
2014-05-05 04:11:04,605 INFO org.apache.hadoop.yarn.server.resourcemanager.rmcontainer.RMContainerImpl: container_1399261790270_0003_01_000003 Container Transitioned from ACQUIRED to RUNNING
2014-05-05 04:11:04,605 INFO org.apache.hadoop.yarn.server.resourcemanager.rmcontainer.RMContainerImpl: container_1399261790270_0003_01_000004 Container Transitioned from ACQUIRED to RUNNING
2014-05-05 04:11:04,605 INFO org.apache.hadoop.yarn.server.resourcemanager.rmcontainer.RMContainerImpl: container_1399261790270_0003_01_000005 Container Transitioned from ACQUIRED to RUNNING
2014-05-05 04:11:05,407 INFO org.apache.hadoop.yarn.server.resourcemanager.scheduler.AppSchedulingInfo: checking for deactivate... 
2014-05-05 04:11:30,268 INFO org.apache.hadoop.yarn.server.resourcemanager.rmcontainer.RMContainerImpl: container_1399261790270_0003_01_000005 Container Transitioned from RUNNING to COMPLETED
2014-05-05 04:11:30,268 INFO org.apache.hadoop.yarn.server.resourcemanager.scheduler.common.fica.FiCaSchedulerApp: Completed container: container_1399261790270_0003_01_000005 in state: COMPLETED event:FINISHED
2014-05-05 04:11:30,268 INFO org.apache.hadoop.yarn.server.resourcemanager.RMAuditLogger: USER=ubuntu	OPERATION=AM Released Container	TARGET=SchedulerApp	RESULT=SUCCESS	APPID=application_1399261790270_0003	CONTAINERID=container_1399261790270_0003_01_000005
2014-05-05 04:11:30,268 INFO org.apache.hadoop.yarn.server.resourcemanager.scheduler.common.fica.FiCaSchedulerNode: Released container container_1399261790270_0003_01_000005 of capacity <memory:1024, vCores:1> on host nodea:49324, which currently has 3 containers, <memory:3072, vCores:3> used and <memory:5120, vCores:5> available, release resources=true
2014-05-05 04:11:30,268 INFO org.apache.hadoop.yarn.server.resourcemanager.scheduler.capacity.LeafQueue: default used=<memory:5120, vCores:4> numContainers=4 user=ubuntu user-resources=<memory:5120, vCores:4>
2014-05-05 04:11:30,268 INFO org.apache.hadoop.yarn.server.resourcemanager.scheduler.capacity.LeafQueue: completedContainer container=Container: [ContainerId: container_1399261790270_0003_01_000005, NodeId: nodea:49324, NodeHttpAddress: nodea:8042, Resource: <memory:1024, vCores:1>, Priority: 20, Token: Token { kind: ContainerToken, service: 10.0.0.158:49324 }, ] resource=<memory:1024, vCores:1> queue=default: capacity=1.0, absoluteCapacity=1.0, usedResources=<memory:5120, vCores:4>usedCapacity=0.15625, absoluteUsedCapacity=0.15625, numApps=1, numContainers=4 usedCapacity=0.15625 absoluteUsedCapacity=0.15625 used=<memory:5120, vCores:4> cluster=<memory:32768, vCores:32>
2014-05-05 04:11:30,268 INFO org.apache.hadoop.yarn.server.resourcemanager.scheduler.capacity.ParentQueue: completedContainer queue=root usedCapacity=0.15625 absoluteUsedCapacity=0.15625 used=<memory:5120, vCores:4> cluster=<memory:32768, vCores:32>
2014-05-05 04:11:30,268 INFO org.apache.hadoop.yarn.server.resourcemanager.scheduler.capacity.ParentQueue: Re-sorting completed queue: root.default stats: default: capacity=1.0, absoluteCapacity=1.0, usedResources=<memory:5120, vCores:4>usedCapacity=0.15625, absoluteUsedCapacity=0.15625, numApps=1, numContainers=4
2014-05-05 04:11:30,269 INFO org.apache.hadoop.yarn.server.resourcemanager.scheduler.capacity.CapacityScheduler: Application appattempt_1399261790270_0003_000001 released container container_1399261790270_0003_01_000005 on node: host: nodea:49324 #containers=3 available=5120 used=3072 with event: FINISHED
2014-05-05 04:11:30,783 INFO org.apache.hadoop.yarn.server.resourcemanager.rmcontainer.RMContainerImpl: container_1399261790270_0003_01_000006 Container Transitioned from NEW to ALLOCATED
2014-05-05 04:11:30,783 INFO org.apache.hadoop.yarn.server.resourcemanager.RMAuditLogger: USER=ubuntu	OPERATION=AM Allocated Container	TARGET=SchedulerApp	RESULT=SUCCESS	APPID=application_1399261790270_0003	CONTAINERID=container_1399261790270_0003_01_000006
2014-05-05 04:11:30,783 INFO org.apache.hadoop.yarn.server.resourcemanager.scheduler.common.fica.FiCaSchedulerNode: Assigned container container_1399261790270_0003_01_000006 of capacity <memory:1024, vCores:1> on host nodeb:41344, which currently has 2 containers, <memory:3072, vCores:2> used and <memory:5120, vCores:6> available
2014-05-05 04:11:30,784 INFO org.apache.hadoop.yarn.server.resourcemanager.scheduler.capacity.LeafQueue: assignedContainer application=application_1399261790270_0003 container=Container: [ContainerId: container_1399261790270_0003_01_000006, NodeId: nodeb:41344, NodeHttpAddress: nodeb:8042, Resource: <memory:1024, vCores:1>, Priority: 10, Token: Token { kind: ContainerToken, service: 10.0.0.59:41344 }, ] containerId=container_1399261790270_0003_01_000006 queue=default: capacity=1.0, absoluteCapacity=1.0, usedResources=<memory:5120, vCores:4>usedCapacity=0.15625, absoluteUsedCapacity=0.15625, numApps=1, numContainers=4 usedCapacity=0.15625 absoluteUsedCapacity=0.15625 used=<memory:5120, vCores:4> cluster=<memory:32768, vCores:32>
2014-05-05 04:11:30,784 INFO org.apache.hadoop.yarn.server.resourcemanager.scheduler.capacity.ParentQueue: Re-sorting assigned queue: root.default stats: default: capacity=1.0, absoluteCapacity=1.0, usedResources=<memory:6144, vCores:5>usedCapacity=0.1875, absoluteUsedCapacity=0.1875, numApps=1, numContainers=5
2014-05-05 04:11:30,784 INFO org.apache.hadoop.yarn.server.resourcemanager.scheduler.capacity.ParentQueue: assignedContainer queue=root usedCapacity=0.1875 absoluteUsedCapacity=0.1875 used=<memory:6144, vCores:5> cluster=<memory:32768, vCores:32>
2014-05-05 04:11:30,784 INFO org.apache.hadoop.yarn.server.resourcemanager.rmcontainer.RMContainerImpl: container_1399261790270_0003_01_000007 Container Transitioned from NEW to ALLOCATED
2014-05-05 04:11:30,784 INFO org.apache.hadoop.yarn.server.resourcemanager.RMAuditLogger: USER=ubuntu	OPERATION=AM Allocated Container	TARGET=SchedulerApp	RESULT=SUCCESS	APPID=application_1399261790270_0003	CONTAINERID=container_1399261790270_0003_01_000007
2014-05-05 04:11:30,784 INFO org.apache.hadoop.yarn.server.resourcemanager.scheduler.common.fica.FiCaSchedulerNode: Assigned container container_1399261790270_0003_01_000007 of capacity <memory:1024, vCores:1> on host nodeb:41344, which currently has 3 containers, <memory:4096, vCores:3> used and <memory:4096, vCores:5> available
2014-05-05 04:11:30,785 INFO org.apache.hadoop.yarn.server.resourcemanager.scheduler.capacity.LeafQueue: assignedContainer application=application_1399261790270_0003 container=Container: [ContainerId: container_1399261790270_0003_01_000007, NodeId: nodeb:41344, NodeHttpAddress: nodeb:8042, Resource: <memory:1024, vCores:1>, Priority: 10, Token: Token { kind: ContainerToken, service: 10.0.0.59:41344 }, ] containerId=container_1399261790270_0003_01_000007 queue=default: capacity=1.0, absoluteCapacity=1.0, usedResources=<memory:6144, vCores:5>usedCapacity=0.1875, absoluteUsedCapacity=0.1875, numApps=1, numContainers=5 usedCapacity=0.1875 absoluteUsedCapacity=0.1875 used=<memory:6144, vCores:5> cluster=<memory:32768, vCores:32>
2014-05-05 04:11:30,785 INFO org.apache.hadoop.yarn.server.resourcemanager.scheduler.capacity.ParentQueue: Re-sorting assigned queue: root.default stats: default: capacity=1.0, absoluteCapacity=1.0, usedResources=<memory:7168, vCores:6>usedCapacity=0.21875, absoluteUsedCapacity=0.21875, numApps=1, numContainers=6
2014-05-05 04:11:30,785 INFO org.apache.hadoop.yarn.server.resourcemanager.scheduler.capacity.ParentQueue: assignedContainer queue=root usedCapacity=0.21875 absoluteUsedCapacity=0.21875 used=<memory:7168, vCores:6> cluster=<memory:32768, vCores:32>
2014-05-05 04:11:30,786 INFO org.apache.hadoop.yarn.server.resourcemanager.rmcontainer.RMContainerImpl: container_1399261790270_0003_01_000008 Container Transitioned from NEW to ALLOCATED
2014-05-05 04:11:30,786 INFO org.apache.hadoop.yarn.server.resourcemanager.RMAuditLogger: USER=ubuntu	OPERATION=AM Allocated Container	TARGET=SchedulerApp	RESULT=SUCCESS	APPID=application_1399261790270_0003	CONTAINERID=container_1399261790270_0003_01_000008
2014-05-05 04:11:30,786 INFO org.apache.hadoop.yarn.server.resourcemanager.scheduler.common.fica.FiCaSchedulerNode: Assigned container container_1399261790270_0003_01_000008 of capacity <memory:1024, vCores:1> on host nodeb:41344, which currently has 4 containers, <memory:5120, vCores:4> used and <memory:3072, vCores:4> available
2014-05-05 04:11:30,786 INFO org.apache.hadoop.yarn.server.resourcemanager.scheduler.capacity.LeafQueue: assignedContainer application=application_1399261790270_0003 container=Container: [ContainerId: container_1399261790270_0003_01_000008, NodeId: nodeb:41344, NodeHttpAddress: nodeb:8042, Resource: <memory:1024, vCores:1>, Priority: 20, Token: Token { kind: ContainerToken, service: 10.0.0.59:41344 }, ] containerId=container_1399261790270_0003_01_000008 queue=default: capacity=1.0, absoluteCapacity=1.0, usedResources=<memory:7168, vCores:6>usedCapacity=0.21875, absoluteUsedCapacity=0.21875, numApps=1, numContainers=6 usedCapacity=0.21875 absoluteUsedCapacity=0.21875 used=<memory:7168, vCores:6> cluster=<memory:32768, vCores:32>
2014-05-05 04:11:30,786 INFO org.apache.hadoop.yarn.server.resourcemanager.scheduler.capacity.ParentQueue: Re-sorting assigned queue: root.default stats: default: capacity=1.0, absoluteCapacity=1.0, usedResources=<memory:8192, vCores:7>usedCapacity=0.25, absoluteUsedCapacity=0.25, numApps=1, numContainers=7
2014-05-05 04:11:30,786 INFO org.apache.hadoop.yarn.server.resourcemanager.scheduler.capacity.ParentQueue: assignedContainer queue=root usedCapacity=0.25 absoluteUsedCapacity=0.25 used=<memory:8192, vCores:7> cluster=<memory:32768, vCores:32>
2014-05-05 04:11:31,076 INFO org.apache.hadoop.yarn.server.resourcemanager.rmcontainer.RMContainerImpl: container_1399261790270_0003_01_000009 Container Transitioned from NEW to ALLOCATED
2014-05-05 04:11:31,077 INFO org.apache.hadoop.yarn.server.resourcemanager.RMAuditLogger: USER=ubuntu	OPERATION=AM Allocated Container	TARGET=SchedulerApp	RESULT=SUCCESS	APPID=application_1399261790270_0003	CONTAINERID=container_1399261790270_0003_01_000009
2014-05-05 04:11:31,077 INFO org.apache.hadoop.yarn.server.resourcemanager.scheduler.common.fica.FiCaSchedulerNode: Assigned container container_1399261790270_0003_01_000009 of capacity <memory:1024, vCores:1> on host noded:54001, which currently has 1 containers, <memory:1024, vCores:1> used and <memory:7168, vCores:7> available
2014-05-05 04:11:31,077 INFO org.apache.hadoop.yarn.server.resourcemanager.scheduler.capacity.LeafQueue: assignedContainer application=application_1399261790270_0003 container=Container: [ContainerId: container_1399261790270_0003_01_000009, NodeId: noded:54001, NodeHttpAddress: noded:8042, Resource: <memory:1024, vCores:1>, Priority: 10, Token: Token { kind: ContainerToken, service: 10.0.0.180:54001 }, ] containerId=container_1399261790270_0003_01_000009 queue=default: capacity=1.0, absoluteCapacity=1.0, usedResources=<memory:8192, vCores:7>usedCapacity=0.25, absoluteUsedCapacity=0.25, numApps=1, numContainers=7 usedCapacity=0.25 absoluteUsedCapacity=0.25 used=<memory:8192, vCores:7> cluster=<memory:32768, vCores:32>
2014-05-05 04:11:31,077 INFO org.apache.hadoop.yarn.server.resourcemanager.scheduler.capacity.ParentQueue: Re-sorting assigned queue: root.default stats: default: capacity=1.0, absoluteCapacity=1.0, usedResources=<memory:9216, vCores:8>usedCapacity=0.28125, absoluteUsedCapacity=0.28125, numApps=1, numContainers=8
2014-05-05 04:11:31,077 INFO org.apache.hadoop.yarn.server.resourcemanager.scheduler.capacity.ParentQueue: assignedContainer queue=root usedCapacity=0.28125 absoluteUsedCapacity=0.28125 used=<memory:9216, vCores:8> cluster=<memory:32768, vCores:32>
2014-05-05 04:11:31,078 INFO org.apache.hadoop.yarn.server.resourcemanager.rmcontainer.RMContainerImpl: container_1399261790270_0003_01_000010 Container Transitioned from NEW to ALLOCATED
2014-05-05 04:11:31,078 INFO org.apache.hadoop.yarn.server.resourcemanager.RMAuditLogger: USER=ubuntu	OPERATION=AM Allocated Container	TARGET=SchedulerApp	RESULT=SUCCESS	APPID=application_1399261790270_0003	CONTAINERID=container_1399261790270_0003_01_000010
2014-05-05 04:11:31,078 INFO org.apache.hadoop.yarn.server.resourcemanager.scheduler.common.fica.FiCaSchedulerNode: Assigned container container_1399261790270_0003_01_000010 of capacity <memory:1024, vCores:1> on host noded:54001, which currently has 2 containers, <memory:2048, vCores:2> used and <memory:6144, vCores:6> available
2014-05-05 04:11:31,078 INFO org.apache.hadoop.yarn.server.resourcemanager.scheduler.capacity.LeafQueue: assignedContainer application=application_1399261790270_0003 container=Container: [ContainerId: container_1399261790270_0003_01_000010, NodeId: noded:54001, NodeHttpAddress: noded:8042, Resource: <memory:1024, vCores:1>, Priority: 10, Token: Token { kind: ContainerToken, service: 10.0.0.180:54001 }, ] containerId=container_1399261790270_0003_01_000010 queue=default: capacity=1.0, absoluteCapacity=1.0, usedResources=<memory:9216, vCores:8>usedCapacity=0.28125, absoluteUsedCapacity=0.28125, numApps=1, numContainers=8 usedCapacity=0.28125 absoluteUsedCapacity=0.28125 used=<memory:9216, vCores:8> cluster=<memory:32768, vCores:32>
2014-05-05 04:11:31,078 INFO org.apache.hadoop.yarn.server.resourcemanager.scheduler.capacity.ParentQueue: Re-sorting assigned queue: root.default stats: default: capacity=1.0, absoluteCapacity=1.0, usedResources=<memory:10240, vCores:9>usedCapacity=0.3125, absoluteUsedCapacity=0.3125, numApps=1, numContainers=9
2014-05-05 04:11:31,078 INFO org.apache.hadoop.yarn.server.resourcemanager.scheduler.capacity.ParentQueue: assignedContainer queue=root usedCapacity=0.3125 absoluteUsedCapacity=0.3125 used=<memory:10240, vCores:9> cluster=<memory:32768, vCores:32>
2014-05-05 04:11:31,154 INFO org.apache.hadoop.yarn.server.resourcemanager.rmcontainer.RMContainerImpl: container_1399261790270_0003_01_000011 Container Transitioned from NEW to ALLOCATED
2014-05-05 04:11:31,154 INFO org.apache.hadoop.yarn.server.resourcemanager.RMAuditLogger: USER=ubuntu	OPERATION=AM Allocated Container	TARGET=SchedulerApp	RESULT=SUCCESS	APPID=application_1399261790270_0003	CONTAINERID=container_1399261790270_0003_01_000011
2014-05-05 04:11:31,154 INFO org.apache.hadoop.yarn.server.resourcemanager.scheduler.common.fica.FiCaSchedulerNode: Assigned container container_1399261790270_0003_01_000011 of capacity <memory:1024, vCores:1> on host nodec:51351, which currently has 1 containers, <memory:1024, vCores:1> used and <memory:7168, vCores:7> available
2014-05-05 04:11:31,154 INFO org.apache.hadoop.yarn.server.resourcemanager.scheduler.capacity.LeafQueue: assignedContainer application=application_1399261790270_0003 container=Container: [ContainerId: container_1399261790270_0003_01_000011, NodeId: nodec:51351, NodeHttpAddress: nodec:8042, Resource: <memory:1024, vCores:1>, Priority: 10, Token: Token { kind: ContainerToken, service: 10.0.0.181:51351 }, ] containerId=container_1399261790270_0003_01_000011 queue=default: capacity=1.0, absoluteCapacity=1.0, usedResources=<memory:10240, vCores:9>usedCapacity=0.3125, absoluteUsedCapacity=0.3125, numApps=1, numContainers=9 usedCapacity=0.3125 absoluteUsedCapacity=0.3125 used=<memory:10240, vCores:9> cluster=<memory:32768, vCores:32>
2014-05-05 04:11:31,154 INFO org.apache.hadoop.yarn.server.resourcemanager.scheduler.capacity.ParentQueue: Re-sorting assigned queue: root.default stats: default: capacity=1.0, absoluteCapacity=1.0, usedResources=<memory:11264, vCores:10>usedCapacity=0.34375, absoluteUsedCapacity=0.34375, numApps=1, numContainers=10
2014-05-05 04:11:31,154 INFO org.apache.hadoop.yarn.server.resourcemanager.scheduler.capacity.ParentQueue: assignedContainer queue=root usedCapacity=0.34375 absoluteUsedCapacity=0.34375 used=<memory:11264, vCores:10> cluster=<memory:32768, vCores:32>
2014-05-05 04:11:31,155 INFO org.apache.hadoop.yarn.server.resourcemanager.rmcontainer.RMContainerImpl: container_1399261790270_0003_01_000012 Container Transitioned from NEW to ALLOCATED
2014-05-05 04:11:31,155 INFO org.apache.hadoop.yarn.server.resourcemanager.RMAuditLogger: USER=ubuntu	OPERATION=AM Allocated Container	TARGET=SchedulerApp	RESULT=SUCCESS	APPID=application_1399261790270_0003	CONTAINERID=container_1399261790270_0003_01_000012
2014-05-05 04:11:31,155 INFO org.apache.hadoop.yarn.server.resourcemanager.scheduler.common.fica.FiCaSchedulerNode: Assigned container container_1399261790270_0003_01_000012 of capacity <memory:1024, vCores:1> on host nodec:51351, which currently has 2 containers, <memory:2048, vCores:2> used and <memory:6144, vCores:6> available
2014-05-05 04:11:31,155 INFO org.apache.hadoop.yarn.server.resourcemanager.scheduler.capacity.LeafQueue: assignedContainer application=application_1399261790270_0003 container=Container: [ContainerId: container_1399261790270_0003_01_000012, NodeId: nodec:51351, NodeHttpAddress: nodec:8042, Resource: <memory:1024, vCores:1>, Priority: 10, Token: Token { kind: ContainerToken, service: 10.0.0.181:51351 }, ] containerId=container_1399261790270_0003_01_000012 queue=default: capacity=1.0, absoluteCapacity=1.0, usedResources=<memory:11264, vCores:10>usedCapacity=0.34375, absoluteUsedCapacity=0.34375, numApps=1, numContainers=10 usedCapacity=0.34375 absoluteUsedCapacity=0.34375 used=<memory:11264, vCores:10> cluster=<memory:32768, vCores:32>
2014-05-05 04:11:31,155 INFO org.apache.hadoop.yarn.server.resourcemanager.scheduler.capacity.ParentQueue: Re-sorting assigned queue: root.default stats: default: capacity=1.0, absoluteCapacity=1.0, usedResources=<memory:12288, vCores:11>usedCapacity=0.375, absoluteUsedCapacity=0.375, numApps=1, numContainers=11
2014-05-05 04:11:31,155 INFO org.apache.hadoop.yarn.server.resourcemanager.scheduler.capacity.ParentQueue: assignedContainer queue=root usedCapacity=0.375 absoluteUsedCapacity=0.375 used=<memory:12288, vCores:11> cluster=<memory:32768, vCores:32>
2014-05-05 04:11:31,272 INFO org.apache.hadoop.yarn.server.resourcemanager.rmcontainer.RMContainerImpl: container_1399261790270_0003_01_000013 Container Transitioned from NEW to ALLOCATED
2014-05-05 04:11:31,362 INFO org.apache.hadoop.yarn.server.resourcemanager.RMAuditLogger: USER=ubuntu	OPERATION=AM Allocated Container	TARGET=SchedulerApp	RESULT=SUCCESS	APPID=application_1399261790270_0003	CONTAINERID=container_1399261790270_0003_01_000013
2014-05-05 04:11:31,362 INFO org.apache.hadoop.yarn.server.resourcemanager.scheduler.common.fica.FiCaSchedulerNode: Assigned container container_1399261790270_0003_01_000013 of capacity <memory:1024, vCores:1> on host nodea:49324, which currently has 4 containers, <memory:4096, vCores:4> used and <memory:4096, vCores:4> available
2014-05-05 04:11:31,362 INFO org.apache.hadoop.yarn.server.resourcemanager.scheduler.capacity.LeafQueue: assignedContainer application=application_1399261790270_0003 container=Container: [ContainerId: container_1399261790270_0003_01_000013, NodeId: nodea:49324, NodeHttpAddress: nodea:8042, Resource: <memory:1024, vCores:1>, Priority: 10, Token: Token { kind: ContainerToken, service: 10.0.0.158:49324 }, ] containerId=container_1399261790270_0003_01_000013 queue=default: capacity=1.0, absoluteCapacity=1.0, usedResources=<memory:12288, vCores:11>usedCapacity=0.375, absoluteUsedCapacity=0.375, numApps=1, numContainers=11 usedCapacity=0.375 absoluteUsedCapacity=0.375 used=<memory:12288, vCores:11> cluster=<memory:32768, vCores:32>
2014-05-05 04:11:31,362 INFO org.apache.hadoop.yarn.server.resourcemanager.scheduler.capacity.ParentQueue: Re-sorting assigned queue: root.default stats: default: capacity=1.0, absoluteCapacity=1.0, usedResources=<memory:13312, vCores:12>usedCapacity=0.40625, absoluteUsedCapacity=0.40625, numApps=1, numContainers=12
2014-05-05 04:11:31,362 INFO org.apache.hadoop.yarn.server.resourcemanager.scheduler.capacity.ParentQueue: assignedContainer queue=root usedCapacity=0.40625 absoluteUsedCapacity=0.40625 used=<memory:13312, vCores:12> cluster=<memory:32768, vCores:32>
2014-05-05 04:11:31,363 INFO org.apache.hadoop.yarn.server.resourcemanager.rmcontainer.RMContainerImpl: container_1399261790270_0003_01_000014 Container Transitioned from NEW to ALLOCATED
2014-05-05 04:11:31,363 INFO org.apache.hadoop.yarn.server.resourcemanager.RMAuditLogger: USER=ubuntu	OPERATION=AM Allocated Container	TARGET=SchedulerApp	RESULT=SUCCESS	APPID=application_1399261790270_0003	CONTAINERID=container_1399261790270_0003_01_000014
2014-05-05 04:11:31,363 INFO org.apache.hadoop.yarn.server.resourcemanager.scheduler.common.fica.FiCaSchedulerNode: Assigned container container_1399261790270_0003_01_000014 of capacity <memory:1024, vCores:1> on host nodea:49324, which currently has 5 containers, <memory:5120, vCores:5> used and <memory:3072, vCores:3> available
2014-05-05 04:11:31,363 INFO org.apache.hadoop.yarn.server.resourcemanager.scheduler.capacity.LeafQueue: assignedContainer application=application_1399261790270_0003 container=Container: [ContainerId: container_1399261790270_0003_01_000014, NodeId: nodea:49324, NodeHttpAddress: nodea:8042, Resource: <memory:1024, vCores:1>, Priority: 10, Token: Token { kind: ContainerToken, service: 10.0.0.158:49324 }, ] containerId=container_1399261790270_0003_01_000014 queue=default: capacity=1.0, absoluteCapacity=1.0, usedResources=<memory:13312, vCores:12>usedCapacity=0.40625, absoluteUsedCapacity=0.40625, numApps=1, numContainers=12 usedCapacity=0.40625 absoluteUsedCapacity=0.40625 used=<memory:13312, vCores:12> cluster=<memory:32768, vCores:32>
2014-05-05 04:11:31,363 INFO org.apache.hadoop.yarn.server.resourcemanager.scheduler.capacity.ParentQueue: Re-sorting assigned queue: root.default stats: default: capacity=1.0, absoluteCapacity=1.0, usedResources=<memory:14336, vCores:13>usedCapacity=0.4375, absoluteUsedCapacity=0.4375, numApps=1, numContainers=13
2014-05-05 04:11:31,364 INFO org.apache.hadoop.yarn.server.resourcemanager.scheduler.capacity.ParentQueue: assignedContainer queue=root usedCapacity=0.4375 absoluteUsedCapacity=0.4375 used=<memory:14336, vCores:13> cluster=<memory:32768, vCores:32>
2014-05-05 04:11:31,544 INFO org.apache.hadoop.yarn.server.resourcemanager.rmcontainer.RMContainerImpl: container_1399261790270_0003_01_000006 Container Transitioned from ALLOCATED to ACQUIRED
2014-05-05 04:11:31,544 INFO org.apache.hadoop.yarn.server.resourcemanager.rmcontainer.RMContainerImpl: container_1399261790270_0003_01_000007 Container Transitioned from ALLOCATED to ACQUIRED
2014-05-05 04:11:31,545 INFO org.apache.hadoop.yarn.server.resourcemanager.rmcontainer.RMContainerImpl: container_1399261790270_0003_01_000008 Container Transitioned from ALLOCATED to ACQUIRED
2014-05-05 04:11:31,546 INFO org.apache.hadoop.yarn.server.resourcemanager.rmcontainer.RMContainerImpl: container_1399261790270_0003_01_000009 Container Transitioned from ALLOCATED to ACQUIRED
2014-05-05 04:11:31,546 INFO org.apache.hadoop.yarn.server.resourcemanager.rmcontainer.RMContainerImpl: container_1399261790270_0003_01_000010 Container Transitioned from ALLOCATED to ACQUIRED
2014-05-05 04:11:31,546 INFO org.apache.hadoop.yarn.server.resourcemanager.rmcontainer.RMContainerImpl: container_1399261790270_0003_01_000011 Container Transitioned from ALLOCATED to ACQUIRED
2014-05-05 04:11:31,546 INFO org.apache.hadoop.yarn.server.resourcemanager.rmcontainer.RMContainerImpl: container_1399261790270_0003_01_000012 Container Transitioned from ALLOCATED to ACQUIRED
2014-05-05 04:11:31,546 INFO org.apache.hadoop.yarn.server.resourcemanager.rmcontainer.RMContainerImpl: container_1399261790270_0003_01_000013 Container Transitioned from ALLOCATED to ACQUIRED
2014-05-05 04:11:31,547 INFO org.apache.hadoop.yarn.server.resourcemanager.rmcontainer.RMContainerImpl: container_1399261790270_0003_01_000014 Container Transitioned from ALLOCATED to ACQUIRED
2014-05-05 04:11:31,787 INFO org.apache.hadoop.yarn.server.resourcemanager.rmcontainer.RMContainerImpl: container_1399261790270_0003_01_000006 Container Transitioned from ACQUIRED to RUNNING
2014-05-05 04:11:31,787 INFO org.apache.hadoop.yarn.server.resourcemanager.rmcontainer.RMContainerImpl: container_1399261790270_0003_01_000007 Container Transitioned from ACQUIRED to RUNNING
2014-05-05 04:11:31,787 INFO org.apache.hadoop.yarn.server.resourcemanager.rmcontainer.RMContainerImpl: container_1399261790270_0003_01_000008 Container Transitioned from ACQUIRED to RUNNING
2014-05-05 04:11:32,079 INFO org.apache.hadoop.yarn.server.resourcemanager.rmcontainer.RMContainerImpl: container_1399261790270_0003_01_000009 Container Transitioned from ACQUIRED to RUNNING
2014-05-05 04:11:32,079 INFO org.apache.hadoop.yarn.server.resourcemanager.rmcontainer.RMContainerImpl: container_1399261790270_0003_01_000010 Container Transitioned from ACQUIRED to RUNNING
2014-05-05 04:11:32,156 INFO org.apache.hadoop.yarn.server.resourcemanager.rmcontainer.RMContainerImpl: container_1399261790270_0003_01_000011 Container Transitioned from ACQUIRED to RUNNING
2014-05-05 04:11:32,157 INFO org.apache.hadoop.yarn.server.resourcemanager.rmcontainer.RMContainerImpl: container_1399261790270_0003_01_000012 Container Transitioned from ACQUIRED to RUNNING
2014-05-05 04:11:32,275 INFO org.apache.hadoop.yarn.server.resourcemanager.rmcontainer.RMContainerImpl: container_1399261790270_0003_01_000013 Container Transitioned from ACQUIRED to RUNNING
2014-05-05 04:11:32,276 INFO org.apache.hadoop.yarn.server.resourcemanager.rmcontainer.RMContainerImpl: container_1399261790270_0003_01_000014 Container Transitioned from ACQUIRED to RUNNING
2014-05-05 04:11:32,559 INFO org.apache.hadoop.yarn.server.resourcemanager.scheduler.AppSchedulingInfo: checking for deactivate... 
2014-05-05 04:11:32,559 INFO org.apache.hadoop.yarn.server.resourcemanager.scheduler.AppSchedulingInfo: checking for deactivate... 
2014-05-05 04:11:49,507 INFO org.apache.hadoop.yarn.server.resourcemanager.rmcontainer.RMContainerImpl: container_1399261790270_0003_01_000008 Container Transitioned from RUNNING to COMPLETED
2014-05-05 04:11:50,538 INFO org.apache.hadoop.yarn.server.resourcemanager.scheduler.common.fica.FiCaSchedulerApp: Completed container: container_1399261790270_0003_01_000008 in state: COMPLETED event:FINISHED
2014-05-05 04:11:50,538 INFO org.apache.hadoop.yarn.server.resourcemanager.RMAuditLogger: USER=ubuntu	OPERATION=AM Released Container	TARGET=SchedulerApp	RESULT=SUCCESS	APPID=application_1399261790270_0003	CONTAINERID=container_1399261790270_0003_01_000008
2014-05-05 04:11:50,538 INFO org.apache.hadoop.yarn.server.resourcemanager.scheduler.common.fica.FiCaSchedulerNode: Released container container_1399261790270_0003_01_000008 of capacity <memory:1024, vCores:1> on host nodeb:41344, which currently has 3 containers, <memory:4096, vCores:3> used and <memory:4096, vCores:5> available, release resources=true
2014-05-05 04:11:50,538 INFO org.apache.hadoop.yarn.server.resourcemanager.scheduler.capacity.LeafQueue: default used=<memory:13312, vCores:12> numContainers=12 user=ubuntu user-resources=<memory:13312, vCores:12>
2014-05-05 04:11:50,538 INFO org.apache.hadoop.yarn.server.resourcemanager.scheduler.capacity.LeafQueue: completedContainer container=Container: [ContainerId: container_1399261790270_0003_01_000008, NodeId: nodeb:41344, NodeHttpAddress: nodeb:8042, Resource: <memory:1024, vCores:1>, Priority: 20, Token: Token { kind: ContainerToken, service: 10.0.0.59:41344 }, ] resource=<memory:1024, vCores:1> queue=default: capacity=1.0, absoluteCapacity=1.0, usedResources=<memory:13312, vCores:12>usedCapacity=0.40625, absoluteUsedCapacity=0.40625, numApps=1, numContainers=12 usedCapacity=0.40625 absoluteUsedCapacity=0.40625 used=<memory:13312, vCores:12> cluster=<memory:32768, vCores:32>
2014-05-05 04:11:50,539 INFO org.apache.hadoop.yarn.server.resourcemanager.scheduler.capacity.ParentQueue: completedContainer queue=root usedCapacity=0.40625 absoluteUsedCapacity=0.40625 used=<memory:13312, vCores:12> cluster=<memory:32768, vCores:32>
2014-05-05 04:11:50,539 INFO org.apache.hadoop.yarn.server.resourcemanager.scheduler.capacity.ParentQueue: Re-sorting completed queue: root.default stats: default: capacity=1.0, absoluteCapacity=1.0, usedResources=<memory:13312, vCores:12>usedCapacity=0.40625, absoluteUsedCapacity=0.40625, numApps=1, numContainers=12
2014-05-05 04:11:50,539 INFO org.apache.hadoop.yarn.server.resourcemanager.scheduler.capacity.CapacityScheduler: Application appattempt_1399261790270_0003_000001 released container container_1399261790270_0003_01_000008 on node: host: nodeb:41344 #containers=3 available=4096 used=4096 with event: FINISHED
2014-05-05 04:11:50,565 INFO org.apache.hadoop.yarn.server.resourcemanager.rmcontainer.RMContainerImpl: container_1399261790270_0003_01_000004 Container Transitioned from RUNNING to COMPLETED
2014-05-05 04:11:50,565 INFO org.apache.hadoop.yarn.server.resourcemanager.scheduler.common.fica.FiCaSchedulerApp: Completed container: container_1399261790270_0003_01_000004 in state: COMPLETED event:FINISHED
2014-05-05 04:11:50,565 INFO org.apache.hadoop.yarn.server.resourcemanager.RMAuditLogger: USER=ubuntu	OPERATION=AM Released Container	TARGET=SchedulerApp	RESULT=SUCCESS	APPID=application_1399261790270_0003	CONTAINERID=container_1399261790270_0003_01_000004
2014-05-05 04:11:50,565 INFO org.apache.hadoop.yarn.server.resourcemanager.scheduler.common.fica.FiCaSchedulerNode: Released container container_1399261790270_0003_01_000004 of capacity <memory:1024, vCores:1> on host nodea:49324, which currently has 4 containers, <memory:4096, vCores:4> used and <memory:4096, vCores:4> available, release resources=true
2014-05-05 04:11:50,565 INFO org.apache.hadoop.yarn.server.resourcemanager.scheduler.capacity.LeafQueue: default used=<memory:12288, vCores:11> numContainers=11 user=ubuntu user-resources=<memory:12288, vCores:11>
2014-05-05 04:11:50,565 INFO org.apache.hadoop.yarn.server.resourcemanager.scheduler.capacity.LeafQueue: completedContainer container=Container: [ContainerId: container_1399261790270_0003_01_000004, NodeId: nodea:49324, NodeHttpAddress: nodea:8042, Resource: <memory:1024, vCores:1>, Priority: 20, Token: Token { kind: ContainerToken, service: 10.0.0.158:49324 }, ] resource=<memory:1024, vCores:1> queue=default: capacity=1.0, absoluteCapacity=1.0, usedResources=<memory:12288, vCores:11>usedCapacity=0.375, absoluteUsedCapacity=0.375, numApps=1, numContainers=11 usedCapacity=0.375 absoluteUsedCapacity=0.375 used=<memory:12288, vCores:11> cluster=<memory:32768, vCores:32>
2014-05-05 04:11:50,565 INFO org.apache.hadoop.yarn.server.resourcemanager.scheduler.capacity.ParentQueue: completedContainer queue=root usedCapacity=0.375 absoluteUsedCapacity=0.375 used=<memory:12288, vCores:11> cluster=<memory:32768, vCores:32>
2014-05-05 04:11:50,565 INFO org.apache.hadoop.yarn.server.resourcemanager.scheduler.capacity.ParentQueue: Re-sorting completed queue: root.default stats: default: capacity=1.0, absoluteCapacity=1.0, usedResources=<memory:12288, vCores:11>usedCapacity=0.375, absoluteUsedCapacity=0.375, numApps=1, numContainers=11
2014-05-05 04:11:50,565 INFO org.apache.hadoop.yarn.server.resourcemanager.scheduler.capacity.CapacityScheduler: Application appattempt_1399261790270_0003_000001 released container container_1399261790270_0003_01_000004 on node: host: nodea:49324 #containers=4 available=4096 used=4096 with event: FINISHED
2014-05-05 04:11:51,693 INFO org.apache.hadoop.yarn.server.resourcemanager.rmcontainer.RMContainerImpl: container_1399261790270_0003_01_000002 Container Transitioned from RUNNING to COMPLETED
2014-05-05 04:11:51,693 INFO org.apache.hadoop.yarn.server.resourcemanager.scheduler.common.fica.FiCaSchedulerApp: Completed container: container_1399261790270_0003_01_000002 in state: COMPLETED event:FINISHED
2014-05-05 04:11:51,693 INFO org.apache.hadoop.yarn.server.resourcemanager.RMAuditLogger: USER=ubuntu	OPERATION=AM Released Container	TARGET=SchedulerApp	RESULT=SUCCESS	APPID=application_1399261790270_0003	CONTAINERID=container_1399261790270_0003_01_000002
2014-05-05 04:11:51,693 INFO org.apache.hadoop.yarn.server.resourcemanager.scheduler.common.fica.FiCaSchedulerNode: Released container container_1399261790270_0003_01_000002 of capacity <memory:1024, vCores:1> on host nodea:49324, which currently has 3 containers, <memory:3072, vCores:3> used and <memory:5120, vCores:5> available, release resources=true
2014-05-05 04:11:51,694 INFO org.apache.hadoop.yarn.server.resourcemanager.scheduler.capacity.LeafQueue: default used=<memory:11264, vCores:10> numContainers=10 user=ubuntu user-resources=<memory:11264, vCores:10>
2014-05-05 04:11:51,694 INFO org.apache.hadoop.yarn.server.resourcemanager.scheduler.capacity.LeafQueue: completedContainer container=Container: [ContainerId: container_1399261790270_0003_01_000002, NodeId: nodea:49324, NodeHttpAddress: nodea:8042, Resource: <memory:1024, vCores:1>, Priority: 20, Token: Token { kind: ContainerToken, service: 10.0.0.158:49324 }, ] resource=<memory:1024, vCores:1> queue=default: capacity=1.0, absoluteCapacity=1.0, usedResources=<memory:11264, vCores:10>usedCapacity=0.34375, absoluteUsedCapacity=0.34375, numApps=1, numContainers=10 usedCapacity=0.34375 absoluteUsedCapacity=0.34375 used=<memory:11264, vCores:10> cluster=<memory:32768, vCores:32>
2014-05-05 04:11:51,694 INFO org.apache.hadoop.yarn.server.resourcemanager.scheduler.capacity.ParentQueue: completedContainer queue=root usedCapacity=0.34375 absoluteUsedCapacity=0.34375 used=<memory:11264, vCores:10> cluster=<memory:32768, vCores:32>
2014-05-05 04:11:51,694 INFO org.apache.hadoop.yarn.server.resourcemanager.scheduler.capacity.ParentQueue: Re-sorting completed queue: root.default stats: default: capacity=1.0, absoluteCapacity=1.0, usedResources=<memory:11264, vCores:10>usedCapacity=0.34375, absoluteUsedCapacity=0.34375, numApps=1, numContainers=10
2014-05-05 04:11:51,694 INFO org.apache.hadoop.yarn.server.resourcemanager.scheduler.capacity.CapacityScheduler: Application appattempt_1399261790270_0003_000001 released container container_1399261790270_0003_01_000002 on node: host: nodea:49324 #containers=3 available=5120 used=3072 with event: FINISHED
2014-05-05 04:11:51,694 INFO org.apache.hadoop.yarn.server.resourcemanager.rmcontainer.RMContainerImpl: container_1399261790270_0003_01_000003 Container Transitioned from RUNNING to COMPLETED
2014-05-05 04:11:51,694 INFO org.apache.hadoop.yarn.server.resourcemanager.scheduler.common.fica.FiCaSchedulerApp: Completed container: container_1399261790270_0003_01_000003 in state: COMPLETED event:FINISHED
2014-05-05 04:11:51,694 INFO org.apache.hadoop.yarn.server.resourcemanager.RMAuditLogger: USER=ubuntu	OPERATION=AM Released Container	TARGET=SchedulerApp	RESULT=SUCCESS	APPID=application_1399261790270_0003	CONTAINERID=container_1399261790270_0003_01_000003
2014-05-05 04:11:51,694 INFO org.apache.hadoop.yarn.server.resourcemanager.scheduler.common.fica.FiCaSchedulerNode: Released container container_1399261790270_0003_01_000003 of capacity <memory:1024, vCores:1> on host nodea:49324, which currently has 2 containers, <memory:2048, vCores:2> used and <memory:6144, vCores:6> available, release resources=true
2014-05-05 04:11:51,694 INFO org.apache.hadoop.yarn.server.resourcemanager.scheduler.capacity.LeafQueue: default used=<memory:10240, vCores:9> numContainers=9 user=ubuntu user-resources=<memory:10240, vCores:9>
2014-05-05 04:11:51,694 INFO org.apache.hadoop.yarn.server.resourcemanager.scheduler.capacity.LeafQueue: completedContainer container=Container: [ContainerId: container_1399261790270_0003_01_000003, NodeId: nodea:49324, NodeHttpAddress: nodea:8042, Resource: <memory:1024, vCores:1>, Priority: 20, Token: Token { kind: ContainerToken, service: 10.0.0.158:49324 }, ] resource=<memory:1024, vCores:1> queue=default: capacity=1.0, absoluteCapacity=1.0, usedResources=<memory:10240, vCores:9>usedCapacity=0.3125, absoluteUsedCapacity=0.3125, numApps=1, numContainers=9 usedCapacity=0.3125 absoluteUsedCapacity=0.3125 used=<memory:10240, vCores:9> cluster=<memory:32768, vCores:32>
2014-05-05 04:11:51,695 INFO org.apache.hadoop.yarn.server.resourcemanager.scheduler.capacity.ParentQueue: completedContainer queue=root usedCapacity=0.3125 absoluteUsedCapacity=0.3125 used=<memory:10240, vCores:9> cluster=<memory:32768, vCores:32>
2014-05-05 04:11:51,695 INFO org.apache.hadoop.yarn.server.resourcemanager.scheduler.capacity.ParentQueue: Re-sorting completed queue: root.default stats: default: capacity=1.0, absoluteCapacity=1.0, usedResources=<memory:10240, vCores:9>usedCapacity=0.3125, absoluteUsedCapacity=0.3125, numApps=1, numContainers=9
2014-05-05 04:11:51,695 INFO org.apache.hadoop.yarn.server.resourcemanager.scheduler.capacity.CapacityScheduler: Application appattempt_1399261790270_0003_000001 released container container_1399261790270_0003_01_000003 on node: host: nodea:49324 #containers=2 available=6144 used=2048 with event: FINISHED
2014-05-05 04:13:37,060 INFO org.apache.hadoop.yarn.server.resourcemanager.rmcontainer.RMContainerImpl: container_1399261790270_0003_01_000011 Container Transitioned from RUNNING to COMPLETED
2014-05-05 04:13:37,060 INFO org.apache.hadoop.yarn.server.resourcemanager.scheduler.common.fica.FiCaSchedulerApp: Completed container: container_1399261790270_0003_01_000011 in state: COMPLETED event:FINISHED
2014-05-05 04:13:37,060 INFO org.apache.hadoop.yarn.server.resourcemanager.RMAuditLogger: USER=ubuntu	OPERATION=AM Released Container	TARGET=SchedulerApp	RESULT=SUCCESS	APPID=application_1399261790270_0003	CONTAINERID=container_1399261790270_0003_01_000011
2014-05-05 04:13:37,060 INFO org.apache.hadoop.yarn.server.resourcemanager.scheduler.common.fica.FiCaSchedulerNode: Released container container_1399261790270_0003_01_000011 of capacity <memory:1024, vCores:1> on host nodec:51351, which currently has 1 containers, <memory:1024, vCores:1> used and <memory:7168, vCores:7> available, release resources=true
2014-05-05 04:13:37,060 INFO org.apache.hadoop.yarn.server.resourcemanager.scheduler.capacity.LeafQueue: default used=<memory:9216, vCores:8> numContainers=8 user=ubuntu user-resources=<memory:9216, vCores:8>
2014-05-05 04:13:37,060 INFO org.apache.hadoop.yarn.server.resourcemanager.scheduler.capacity.LeafQueue: completedContainer container=Container: [ContainerId: container_1399261790270_0003_01_000011, NodeId: nodec:51351, NodeHttpAddress: nodec:8042, Resource: <memory:1024, vCores:1>, Priority: 10, Token: Token { kind: ContainerToken, service: 10.0.0.181:51351 }, ] resource=<memory:1024, vCores:1> queue=default: capacity=1.0, absoluteCapacity=1.0, usedResources=<memory:9216, vCores:8>usedCapacity=0.28125, absoluteUsedCapacity=0.28125, numApps=1, numContainers=8 usedCapacity=0.28125 absoluteUsedCapacity=0.28125 used=<memory:9216, vCores:8> cluster=<memory:32768, vCores:32>
2014-05-05 04:13:37,060 INFO org.apache.hadoop.yarn.server.resourcemanager.scheduler.capacity.ParentQueue: completedContainer queue=root usedCapacity=0.28125 absoluteUsedCapacity=0.28125 used=<memory:9216, vCores:8> cluster=<memory:32768, vCores:32>
2014-05-05 04:13:37,060 INFO org.apache.hadoop.yarn.server.resourcemanager.scheduler.capacity.ParentQueue: Re-sorting completed queue: root.default stats: default: capacity=1.0, absoluteCapacity=1.0, usedResources=<memory:9216, vCores:8>usedCapacity=0.28125, absoluteUsedCapacity=0.28125, numApps=1, numContainers=8
2014-05-05 04:13:37,060 INFO org.apache.hadoop.yarn.server.resourcemanager.scheduler.capacity.CapacityScheduler: Application appattempt_1399261790270_0003_000001 released container container_1399261790270_0003_01_000011 on node: host: nodec:51351 #containers=1 available=7168 used=1024 with event: FINISHED
2014-05-05 04:13:39,840 INFO org.apache.hadoop.yarn.server.resourcemanager.rmcontainer.RMContainerImpl: container_1399261790270_0003_01_000012 Container Transitioned from RUNNING to COMPLETED
2014-05-05 04:13:39,840 INFO org.apache.hadoop.yarn.server.resourcemanager.scheduler.common.fica.FiCaSchedulerApp: Completed container: container_1399261790270_0003_01_000012 in state: COMPLETED event:FINISHED
2014-05-05 04:13:39,840 INFO org.apache.hadoop.yarn.server.resourcemanager.RMAuditLogger: USER=ubuntu	OPERATION=AM Released Container	TARGET=SchedulerApp	RESULT=SUCCESS	APPID=application_1399261790270_0003	CONTAINERID=container_1399261790270_0003_01_000012
2014-05-05 04:13:39,840 INFO org.apache.hadoop.yarn.server.resourcemanager.scheduler.common.fica.FiCaSchedulerNode: Released container container_1399261790270_0003_01_000012 of capacity <memory:1024, vCores:1> on host nodec:51351, which currently has 0 containers, <memory:0, vCores:0> used and <memory:8192, vCores:8> available, release resources=true
2014-05-05 04:13:39,840 INFO org.apache.hadoop.yarn.server.resourcemanager.scheduler.capacity.LeafQueue: default used=<memory:8192, vCores:7> numContainers=7 user=ubuntu user-resources=<memory:8192, vCores:7>
2014-05-05 04:13:39,840 INFO org.apache.hadoop.yarn.server.resourcemanager.scheduler.capacity.LeafQueue: completedContainer container=Container: [ContainerId: container_1399261790270_0003_01_000012, NodeId: nodec:51351, NodeHttpAddress: nodec:8042, Resource: <memory:1024, vCores:1>, Priority: 10, Token: Token { kind: ContainerToken, service: 10.0.0.181:51351 }, ] resource=<memory:1024, vCores:1> queue=default: capacity=1.0, absoluteCapacity=1.0, usedResources=<memory:8192, vCores:7>usedCapacity=0.25, absoluteUsedCapacity=0.25, numApps=1, numContainers=7 usedCapacity=0.25 absoluteUsedCapacity=0.25 used=<memory:8192, vCores:7> cluster=<memory:32768, vCores:32>
2014-05-05 04:13:39,841 INFO org.apache.hadoop.yarn.server.resourcemanager.scheduler.capacity.ParentQueue: completedContainer queue=root usedCapacity=0.25 absoluteUsedCapacity=0.25 used=<memory:8192, vCores:7> cluster=<memory:32768, vCores:32>
2014-05-05 04:13:39,841 INFO org.apache.hadoop.yarn.server.resourcemanager.scheduler.capacity.ParentQueue: Re-sorting completed queue: root.default stats: default: capacity=1.0, absoluteCapacity=1.0, usedResources=<memory:8192, vCores:7>usedCapacity=0.25, absoluteUsedCapacity=0.25, numApps=1, numContainers=7
2014-05-05 04:13:39,841 INFO org.apache.hadoop.yarn.server.resourcemanager.scheduler.capacity.CapacityScheduler: Application appattempt_1399261790270_0003_000001 released container container_1399261790270_0003_01_000012 on node: host: nodec:51351 #containers=0 available=8192 used=0 with event: FINISHED
2014-05-05 04:14:06,637 INFO org.apache.hadoop.yarn.server.resourcemanager.rmcontainer.RMContainerImpl: container_1399261790270_0003_01_000007 Container Transitioned from RUNNING to COMPLETED
2014-05-05 04:14:06,638 INFO org.apache.hadoop.yarn.server.resourcemanager.scheduler.common.fica.FiCaSchedulerApp: Completed container: container_1399261790270_0003_01_000007 in state: COMPLETED event:FINISHED
2014-05-05 04:14:06,638 INFO org.apache.hadoop.yarn.server.resourcemanager.RMAuditLogger: USER=ubuntu	OPERATION=AM Released Container	TARGET=SchedulerApp	RESULT=SUCCESS	APPID=application_1399261790270_0003	CONTAINERID=container_1399261790270_0003_01_000007
2014-05-05 04:14:06,638 INFO org.apache.hadoop.yarn.server.resourcemanager.scheduler.common.fica.FiCaSchedulerNode: Released container container_1399261790270_0003_01_000007 of capacity <memory:1024, vCores:1> on host nodeb:41344, which currently has 2 containers, <memory:3072, vCores:2> used and <memory:5120, vCores:6> available, release resources=true
2014-05-05 04:14:06,638 INFO org.apache.hadoop.yarn.server.resourcemanager.scheduler.capacity.LeafQueue: default used=<memory:7168, vCores:6> numContainers=6 user=ubuntu user-resources=<memory:7168, vCores:6>
2014-05-05 04:14:06,638 INFO org.apache.hadoop.yarn.server.resourcemanager.scheduler.capacity.LeafQueue: completedContainer container=Container: [ContainerId: container_1399261790270_0003_01_000007, NodeId: nodeb:41344, NodeHttpAddress: nodeb:8042, Resource: <memory:1024, vCores:1>, Priority: 10, Token: Token { kind: ContainerToken, service: 10.0.0.59:41344 }, ] resource=<memory:1024, vCores:1> queue=default: capacity=1.0, absoluteCapacity=1.0, usedResources=<memory:7168, vCores:6>usedCapacity=0.21875, absoluteUsedCapacity=0.21875, numApps=1, numContainers=6 usedCapacity=0.21875 absoluteUsedCapacity=0.21875 used=<memory:7168, vCores:6> cluster=<memory:32768, vCores:32>
2014-05-05 04:14:06,638 INFO org.apache.hadoop.yarn.server.resourcemanager.scheduler.capacity.ParentQueue: completedContainer queue=root usedCapacity=0.21875 absoluteUsedCapacity=0.21875 used=<memory:7168, vCores:6> cluster=<memory:32768, vCores:32>
2014-05-05 04:14:06,638 INFO org.apache.hadoop.yarn.server.resourcemanager.scheduler.capacity.ParentQueue: Re-sorting completed queue: root.default stats: default: capacity=1.0, absoluteCapacity=1.0, usedResources=<memory:7168, vCores:6>usedCapacity=0.21875, absoluteUsedCapacity=0.21875, numApps=1, numContainers=6
2014-05-05 04:14:06,638 INFO org.apache.hadoop.yarn.server.resourcemanager.scheduler.capacity.CapacityScheduler: Application appattempt_1399261790270_0003_000001 released container container_1399261790270_0003_01_000007 on node: host: nodeb:41344 #containers=2 available=5120 used=3072 with event: FINISHED
2014-05-05 04:14:07,639 INFO org.apache.hadoop.yarn.server.resourcemanager.rmcontainer.RMContainerImpl: container_1399261790270_0003_01_000006 Container Transitioned from RUNNING to COMPLETED
2014-05-05 04:14:07,639 INFO org.apache.hadoop.yarn.server.resourcemanager.scheduler.common.fica.FiCaSchedulerApp: Completed container: container_1399261790270_0003_01_000006 in state: COMPLETED event:FINISHED
2014-05-05 04:14:07,640 INFO org.apache.hadoop.yarn.server.resourcemanager.RMAuditLogger: USER=ubuntu	OPERATION=AM Released Container	TARGET=SchedulerApp	RESULT=SUCCESS	APPID=application_1399261790270_0003	CONTAINERID=container_1399261790270_0003_01_000006
2014-05-05 04:14:07,640 INFO org.apache.hadoop.yarn.server.resourcemanager.scheduler.common.fica.FiCaSchedulerNode: Released container container_1399261790270_0003_01_000006 of capacity <memory:1024, vCores:1> on host nodeb:41344, which currently has 1 containers, <memory:2048, vCores:1> used and <memory:6144, vCores:7> available, release resources=true
2014-05-05 04:14:07,640 INFO org.apache.hadoop.yarn.server.resourcemanager.scheduler.capacity.LeafQueue: default used=<memory:6144, vCores:5> numContainers=5 user=ubuntu user-resources=<memory:6144, vCores:5>
2014-05-05 04:14:07,640 INFO org.apache.hadoop.yarn.server.resourcemanager.scheduler.capacity.LeafQueue: completedContainer container=Container: [ContainerId: container_1399261790270_0003_01_000006, NodeId: nodeb:41344, NodeHttpAddress: nodeb:8042, Resource: <memory:1024, vCores:1>, Priority: 10, Token: Token { kind: ContainerToken, service: 10.0.0.59:41344 }, ] resource=<memory:1024, vCores:1> queue=default: capacity=1.0, absoluteCapacity=1.0, usedResources=<memory:6144, vCores:5>usedCapacity=0.1875, absoluteUsedCapacity=0.1875, numApps=1, numContainers=5 usedCapacity=0.1875 absoluteUsedCapacity=0.1875 used=<memory:6144, vCores:5> cluster=<memory:32768, vCores:32>
2014-05-05 04:14:07,640 INFO org.apache.hadoop.yarn.server.resourcemanager.scheduler.capacity.ParentQueue: completedContainer queue=root usedCapacity=0.1875 absoluteUsedCapacity=0.1875 used=<memory:6144, vCores:5> cluster=<memory:32768, vCores:32>
2014-05-05 04:14:07,640 INFO org.apache.hadoop.yarn.server.resourcemanager.scheduler.capacity.ParentQueue: Re-sorting completed queue: root.default stats: default: capacity=1.0, absoluteCapacity=1.0, usedResources=<memory:6144, vCores:5>usedCapacity=0.1875, absoluteUsedCapacity=0.1875, numApps=1, numContainers=5
2014-05-05 04:14:07,640 INFO org.apache.hadoop.yarn.server.resourcemanager.scheduler.capacity.CapacityScheduler: Application appattempt_1399261790270_0003_000001 released container container_1399261790270_0003_01_000006 on node: host: nodeb:41344 #containers=1 available=6144 used=2048 with event: FINISHED
2014-05-05 04:14:10,540 INFO org.apache.hadoop.yarn.server.resourcemanager.rmcontainer.RMContainerImpl: container_1399261790270_0003_01_000010 Container Transitioned from RUNNING to COMPLETED
2014-05-05 04:14:10,540 INFO org.apache.hadoop.yarn.server.resourcemanager.scheduler.common.fica.FiCaSchedulerApp: Completed container: container_1399261790270_0003_01_000010 in state: COMPLETED event:FINISHED
2014-05-05 04:14:10,540 INFO org.apache.hadoop.yarn.server.resourcemanager.RMAuditLogger: USER=ubuntu	OPERATION=AM Released Container	TARGET=SchedulerApp	RESULT=SUCCESS	APPID=application_1399261790270_0003	CONTAINERID=container_1399261790270_0003_01_000010
2014-05-05 04:14:10,540 INFO org.apache.hadoop.yarn.server.resourcemanager.scheduler.common.fica.FiCaSchedulerNode: Released container container_1399261790270_0003_01_000010 of capacity <memory:1024, vCores:1> on host noded:54001, which currently has 1 containers, <memory:1024, vCores:1> used and <memory:7168, vCores:7> available, release resources=true
2014-05-05 04:14:10,540 INFO org.apache.hadoop.yarn.server.resourcemanager.scheduler.capacity.LeafQueue: default used=<memory:5120, vCores:4> numContainers=4 user=ubuntu user-resources=<memory:5120, vCores:4>
2014-05-05 04:14:10,540 INFO org.apache.hadoop.yarn.server.resourcemanager.scheduler.capacity.LeafQueue: completedContainer container=Container: [ContainerId: container_1399261790270_0003_01_000010, NodeId: noded:54001, NodeHttpAddress: noded:8042, Resource: <memory:1024, vCores:1>, Priority: 10, Token: Token { kind: ContainerToken, service: 10.0.0.180:54001 }, ] resource=<memory:1024, vCores:1> queue=default: capacity=1.0, absoluteCapacity=1.0, usedResources=<memory:5120, vCores:4>usedCapacity=0.15625, absoluteUsedCapacity=0.15625, numApps=1, numContainers=4 usedCapacity=0.15625 absoluteUsedCapacity=0.15625 used=<memory:5120, vCores:4> cluster=<memory:32768, vCores:32>
2014-05-05 04:14:10,540 INFO org.apache.hadoop.yarn.server.resourcemanager.scheduler.capacity.ParentQueue: completedContainer queue=root usedCapacity=0.15625 absoluteUsedCapacity=0.15625 used=<memory:5120, vCores:4> cluster=<memory:32768, vCores:32>
2014-05-05 04:14:10,541 INFO org.apache.hadoop.yarn.server.resourcemanager.scheduler.capacity.ParentQueue: Re-sorting completed queue: root.default stats: default: capacity=1.0, absoluteCapacity=1.0, usedResources=<memory:5120, vCores:4>usedCapacity=0.15625, absoluteUsedCapacity=0.15625, numApps=1, numContainers=4
2014-05-05 04:14:10,541 INFO org.apache.hadoop.yarn.server.resourcemanager.scheduler.capacity.CapacityScheduler: Application appattempt_1399261790270_0003_000001 released container container_1399261790270_0003_01_000010 on node: host: noded:54001 #containers=1 available=7168 used=1024 with event: FINISHED
2014-05-05 04:14:10,820 INFO org.apache.hadoop.yarn.server.resourcemanager.rmcontainer.RMContainerImpl: container_1399261790270_0003_01_000014 Container Transitioned from RUNNING to COMPLETED
2014-05-05 04:14:10,820 INFO org.apache.hadoop.yarn.server.resourcemanager.scheduler.common.fica.FiCaSchedulerApp: Completed container: container_1399261790270_0003_01_000014 in state: COMPLETED event:FINISHED
2014-05-05 04:14:10,820 INFO org.apache.hadoop.yarn.server.resourcemanager.RMAuditLogger: USER=ubuntu	OPERATION=AM Released Container	TARGET=SchedulerApp	RESULT=SUCCESS	APPID=application_1399261790270_0003	CONTAINERID=container_1399261790270_0003_01_000014
2014-05-05 04:14:10,821 INFO org.apache.hadoop.yarn.server.resourcemanager.scheduler.common.fica.FiCaSchedulerNode: Released container container_1399261790270_0003_01_000014 of capacity <memory:1024, vCores:1> on host nodea:49324, which currently has 1 containers, <memory:1024, vCores:1> used and <memory:7168, vCores:7> available, release resources=true
2014-05-05 04:14:10,821 INFO org.apache.hadoop.yarn.server.resourcemanager.scheduler.capacity.LeafQueue: default used=<memory:4096, vCores:3> numContainers=3 user=ubuntu user-resources=<memory:4096, vCores:3>
2014-05-05 04:14:10,821 INFO org.apache.hadoop.yarn.server.resourcemanager.scheduler.capacity.LeafQueue: completedContainer container=Container: [ContainerId: container_1399261790270_0003_01_000014, NodeId: nodea:49324, NodeHttpAddress: nodea:8042, Resource: <memory:1024, vCores:1>, Priority: 10, Token: Token { kind: ContainerToken, service: 10.0.0.158:49324 }, ] resource=<memory:1024, vCores:1> queue=default: capacity=1.0, absoluteCapacity=1.0, usedResources=<memory:4096, vCores:3>usedCapacity=0.125, absoluteUsedCapacity=0.125, numApps=1, numContainers=3 usedCapacity=0.125 absoluteUsedCapacity=0.125 used=<memory:4096, vCores:3> cluster=<memory:32768, vCores:32>
2014-05-05 04:14:10,821 INFO org.apache.hadoop.yarn.server.resourcemanager.scheduler.capacity.ParentQueue: completedContainer queue=root usedCapacity=0.125 absoluteUsedCapacity=0.125 used=<memory:4096, vCores:3> cluster=<memory:32768, vCores:32>
2014-05-05 04:14:10,821 INFO org.apache.hadoop.yarn.server.resourcemanager.scheduler.capacity.ParentQueue: Re-sorting completed queue: root.default stats: default: capacity=1.0, absoluteCapacity=1.0, usedResources=<memory:4096, vCores:3>usedCapacity=0.125, absoluteUsedCapacity=0.125, numApps=1, numContainers=3
2014-05-05 04:14:10,821 INFO org.apache.hadoop.yarn.server.resourcemanager.scheduler.capacity.CapacityScheduler: Application appattempt_1399261790270_0003_000001 released container container_1399261790270_0003_01_000014 on node: host: nodea:49324 #containers=1 available=7168 used=1024 with event: FINISHED
2014-05-05 04:14:11,018 INFO org.apache.hadoop.yarn.server.resourcemanager.rmapp.attempt.RMAppAttemptImpl: appattempt_1399261790270_0003_000001 State change from RUNNING to FINISHING
2014-05-05 04:14:11,018 INFO org.apache.hadoop.yarn.server.resourcemanager.rmapp.RMAppImpl: Removing application with id application_1399261790270_0003
2014-05-05 04:14:11,018 INFO org.apache.hadoop.yarn.server.resourcemanager.rmapp.RMAppImpl: application_1399261790270_0003 State change from RUNNING to REMOVING
2014-05-05 04:14:11,018 INFO org.apache.hadoop.yarn.server.resourcemanager.recovery.RMStateStore: Removing info for app: application_1399261790270_0003
2014-05-05 04:14:11,018 INFO org.apache.hadoop.yarn.server.resourcemanager.rmapp.RMAppImpl: application_1399261790270_0003 State change from REMOVING to FINISHING
2014-05-05 04:14:11,542 INFO org.apache.hadoop.yarn.server.resourcemanager.rmcontainer.RMContainerImpl: container_1399261790270_0003_01_000009 Container Transitioned from RUNNING to COMPLETED
2014-05-05 04:14:11,542 INFO org.apache.hadoop.yarn.server.resourcemanager.scheduler.common.fica.FiCaSchedulerApp: Completed container: container_1399261790270_0003_01_000009 in state: COMPLETED event:FINISHED
2014-05-05 04:14:11,542 INFO org.apache.hadoop.yarn.server.resourcemanager.RMAuditLogger: USER=ubuntu	OPERATION=AM Released Container	TARGET=SchedulerApp	RESULT=SUCCESS	APPID=application_1399261790270_0003	CONTAINERID=container_1399261790270_0003_01_000009
2014-05-05 04:14:11,542 INFO org.apache.hadoop.yarn.server.resourcemanager.scheduler.common.fica.FiCaSchedulerNode: Released container container_1399261790270_0003_01_000009 of capacity <memory:1024, vCores:1> on host noded:54001, which currently has 0 containers, <memory:0, vCores:0> used and <memory:8192, vCores:8> available, release resources=true
2014-05-05 04:14:11,542 INFO org.apache.hadoop.yarn.server.resourcemanager.scheduler.capacity.LeafQueue: default used=<memory:3072, vCores:2> numContainers=2 user=ubuntu user-resources=<memory:3072, vCores:2>
2014-05-05 04:14:11,542 INFO org.apache.hadoop.yarn.server.resourcemanager.scheduler.capacity.LeafQueue: completedContainer container=Container: [ContainerId: container_1399261790270_0003_01_000009, NodeId: noded:54001, NodeHttpAddress: noded:8042, Resource: <memory:1024, vCores:1>, Priority: 10, Token: Token { kind: ContainerToken, service: 10.0.0.180:54001 }, ] resource=<memory:1024, vCores:1> queue=default: capacity=1.0, absoluteCapacity=1.0, usedResources=<memory:3072, vCores:2>usedCapacity=0.09375, absoluteUsedCapacity=0.09375, numApps=1, numContainers=2 usedCapacity=0.09375 absoluteUsedCapacity=0.09375 used=<memory:3072, vCores:2> cluster=<memory:32768, vCores:32>
2014-05-05 04:14:11,542 INFO org.apache.hadoop.yarn.server.resourcemanager.scheduler.capacity.ParentQueue: completedContainer queue=root usedCapacity=0.09375 absoluteUsedCapacity=0.09375 used=<memory:3072, vCores:2> cluster=<memory:32768, vCores:32>
2014-05-05 04:14:11,542 INFO org.apache.hadoop.yarn.server.resourcemanager.scheduler.capacity.ParentQueue: Re-sorting completed queue: root.default stats: default: capacity=1.0, absoluteCapacity=1.0, usedResources=<memory:3072, vCores:2>usedCapacity=0.09375, absoluteUsedCapacity=0.09375, numApps=1, numContainers=2
2014-05-05 04:14:11,542 INFO org.apache.hadoop.yarn.server.resourcemanager.scheduler.capacity.CapacityScheduler: Application appattempt_1399261790270_0003_000001 released container container_1399261790270_0003_01_000009 on node: host: noded:54001 #containers=0 available=8192 used=0 with event: FINISHED
2014-05-05 04:14:11,821 INFO org.apache.hadoop.yarn.server.resourcemanager.rmcontainer.RMContainerImpl: container_1399261790270_0003_01_000013 Container Transitioned from RUNNING to COMPLETED
2014-05-05 04:14:11,822 INFO org.apache.hadoop.yarn.server.resourcemanager.scheduler.common.fica.FiCaSchedulerApp: Completed container: container_1399261790270_0003_01_000013 in state: COMPLETED event:FINISHED
2014-05-05 04:14:11,822 INFO org.apache.hadoop.yarn.server.resourcemanager.RMAuditLogger: USER=ubuntu	OPERATION=AM Released Container	TARGET=SchedulerApp	RESULT=SUCCESS	APPID=application_1399261790270_0003	CONTAINERID=container_1399261790270_0003_01_000013
2014-05-05 04:14:11,822 INFO org.apache.hadoop.yarn.server.resourcemanager.scheduler.common.fica.FiCaSchedulerNode: Released container container_1399261790270_0003_01_000013 of capacity <memory:1024, vCores:1> on host nodea:49324, which currently has 0 containers, <memory:0, vCores:0> used and <memory:8192, vCores:8> available, release resources=true
2014-05-05 04:14:11,822 INFO org.apache.hadoop.yarn.server.resourcemanager.scheduler.capacity.LeafQueue: default used=<memory:2048, vCores:1> numContainers=1 user=ubuntu user-resources=<memory:2048, vCores:1>
2014-05-05 04:14:11,822 INFO org.apache.hadoop.yarn.server.resourcemanager.scheduler.capacity.LeafQueue: completedContainer container=Container: [ContainerId: container_1399261790270_0003_01_000013, NodeId: nodea:49324, NodeHttpAddress: nodea:8042, Resource: <memory:1024, vCores:1>, Priority: 10, Token: Token { kind: ContainerToken, service: 10.0.0.158:49324 }, ] resource=<memory:1024, vCores:1> queue=default: capacity=1.0, absoluteCapacity=1.0, usedResources=<memory:2048, vCores:1>usedCapacity=0.0625, absoluteUsedCapacity=0.0625, numApps=1, numContainers=1 usedCapacity=0.0625 absoluteUsedCapacity=0.0625 used=<memory:2048, vCores:1> cluster=<memory:32768, vCores:32>
2014-05-05 04:14:11,822 INFO org.apache.hadoop.yarn.server.resourcemanager.scheduler.capacity.ParentQueue: completedContainer queue=root usedCapacity=0.0625 absoluteUsedCapacity=0.0625 used=<memory:2048, vCores:1> cluster=<memory:32768, vCores:32>
2014-05-05 04:14:11,822 INFO org.apache.hadoop.yarn.server.resourcemanager.scheduler.capacity.ParentQueue: Re-sorting completed queue: root.default stats: default: capacity=1.0, absoluteCapacity=1.0, usedResources=<memory:2048, vCores:1>usedCapacity=0.0625, absoluteUsedCapacity=0.0625, numApps=1, numContainers=1
2014-05-05 04:14:11,822 INFO org.apache.hadoop.yarn.server.resourcemanager.scheduler.capacity.CapacityScheduler: Application appattempt_1399261790270_0003_000001 released container container_1399261790270_0003_01_000013 on node: host: nodea:49324 #containers=0 available=8192 used=0 with event: FINISHED
2014-05-05 04:14:17,653 INFO org.apache.hadoop.yarn.server.resourcemanager.rmcontainer.RMContainerImpl: container_1399261790270_0003_01_000001 Container Transitioned from RUNNING to COMPLETED
2014-05-05 04:14:17,653 INFO org.apache.hadoop.yarn.server.resourcemanager.ApplicationMasterService: Unregistering app attempt : appattempt_1399261790270_0003_000001
2014-05-05 04:14:17,653 INFO org.apache.hadoop.yarn.server.resourcemanager.scheduler.common.fica.FiCaSchedulerApp: Completed container: container_1399261790270_0003_01_000001 in state: COMPLETED event:FINISHED
2014-05-05 04:14:17,653 INFO org.apache.hadoop.yarn.server.resourcemanager.rmapp.attempt.RMAppAttemptImpl: appattempt_1399261790270_0003_000001 State change from FINISHING to FINISHED
2014-05-05 04:14:17,653 INFO org.apache.hadoop.yarn.server.resourcemanager.RMAuditLogger: USER=ubuntu	OPERATION=AM Released Container	TARGET=SchedulerApp	RESULT=SUCCESS	APPID=application_1399261790270_0003	CONTAINERID=container_1399261790270_0003_01_000001
2014-05-05 04:14:17,654 INFO org.apache.hadoop.yarn.server.resourcemanager.rmapp.RMAppImpl: application_1399261790270_0003 State change from FINISHING to FINISHED
2014-05-05 04:14:17,654 INFO org.apache.hadoop.yarn.server.resourcemanager.scheduler.common.fica.FiCaSchedulerNode: Released container container_1399261790270_0003_01_000001 of capacity <memory:2048, vCores:1> on host nodeb:41344, which currently has 0 containers, <memory:0, vCores:0> used and <memory:8192, vCores:8> available, release resources=true
2014-05-05 04:14:17,654 INFO org.apache.hadoop.yarn.server.resourcemanager.scheduler.capacity.LeafQueue: default used=<memory:0, vCores:0> numContainers=0 user=ubuntu user-resources=<memory:0, vCores:0>
2014-05-05 04:14:17,654 INFO org.apache.hadoop.yarn.server.resourcemanager.RMAuditLogger: USER=ubuntu	OPERATION=Application Finished - Succeeded	TARGET=RMAppManager	RESULT=SUCCESS	APPID=application_1399261790270_0003
2014-05-05 04:14:17,654 INFO org.apache.hadoop.yarn.server.resourcemanager.scheduler.capacity.LeafQueue: completedContainer container=Container: [ContainerId: container_1399261790270_0003_01_000001, NodeId: nodeb:41344, NodeHttpAddress: nodeb:8042, Resource: <memory:2048, vCores:1>, Priority: 0, Token: Token { kind: ContainerToken, service: 10.0.0.59:41344 }, ] resource=<memory:2048, vCores:1> queue=default: capacity=1.0, absoluteCapacity=1.0, usedResources=<memory:0, vCores:0>usedCapacity=0.0, absoluteUsedCapacity=0.0, numApps=1, numContainers=0 usedCapacity=0.0 absoluteUsedCapacity=0.0 used=<memory:0, vCores:0> cluster=<memory:32768, vCores:32>
2014-05-05 04:14:17,654 INFO org.apache.hadoop.yarn.server.resourcemanager.scheduler.capacity.ParentQueue: completedContainer queue=root usedCapacity=0.0 absoluteUsedCapacity=0.0 used=<memory:0, vCores:0> cluster=<memory:32768, vCores:32>
2014-05-05 04:14:17,654 INFO org.apache.hadoop.yarn.server.resourcemanager.RMAppManager$ApplicationSummary: appId=application_1399261790270_0003,name=hints||path:/in1m||num reduce:8,user=ubuntu,queue=default,state=FINISHED,trackingUrl=ec2-54-186-230-200.us-west-2.compute.amazonaws.com:8088/proxy/application_1399261790270_0003/jobhistory/job/job_1399261790270_0003,appMasterHost=ip-10-0-0-59,startTime=1399263057236,finishTime=1399263251018,finalStatus=SUCCEEDED
2014-05-05 04:14:17,654 INFO org.apache.hadoop.yarn.server.resourcemanager.scheduler.capacity.ParentQueue: Re-sorting completed queue: root.default stats: default: capacity=1.0, absoluteCapacity=1.0, usedResources=<memory:0, vCores:0>usedCapacity=0.0, absoluteUsedCapacity=0.0, numApps=1, numContainers=0
2014-05-05 04:14:17,658 INFO org.apache.hadoop.yarn.server.resourcemanager.scheduler.capacity.CapacityScheduler: Application appattempt_1399261790270_0003_000001 released container container_1399261790270_0003_01_000001 on node: host: nodeb:41344 #containers=0 available=8192 used=0 with event: FINISHED
2014-05-05 04:14:17,658 INFO org.apache.hadoop.yarn.server.resourcemanager.scheduler.capacity.CapacityScheduler: Application appattempt_1399261790270_0003_000001 is done. finalState=FINISHED
2014-05-05 04:14:17,658 INFO org.apache.hadoop.yarn.server.resourcemanager.amlauncher.AMLauncher: Cleaning master appattempt_1399261790270_0003_000001
2014-05-05 04:14:17,658 INFO org.apache.hadoop.yarn.server.resourcemanager.scheduler.AppSchedulingInfo: Application application_1399261790270_0003 requests cleared
2014-05-05 04:14:17,658 INFO org.apache.hadoop.yarn.server.resourcemanager.scheduler.capacity.LeafQueue: Application removed - appId: application_1399261790270_0003 user: ubuntu queue: default #user-pending-applications: 0 #user-active-applications: 0 #queue-pending-applications: 0 #queue-active-applications: 0
2014-05-05 04:14:17,658 INFO org.apache.hadoop.yarn.server.resourcemanager.scheduler.capacity.ParentQueue: Application removed - appId: application_1399261790270_0003 user: ubuntu leaf-queue of parent: root #applications: 0
2014-05-05 04:15:21,442 INFO org.apache.hadoop.yarn.server.resourcemanager.ClientRMService: Allocated new applicationId: 4
2014-05-05 04:15:22,979 INFO org.apache.hadoop.yarn.server.resourcemanager.ClientRMService: Application with id 4 submitted by user ubuntu
2014-05-05 04:15:22,979 INFO org.apache.hadoop.yarn.server.resourcemanager.rmapp.RMAppImpl: Storing application with id application_1399261790270_0004
2014-05-05 04:15:22,979 INFO org.apache.hadoop.yarn.server.resourcemanager.rmapp.RMAppImpl: application_1399261790270_0004 State change from NEW to NEW_SAVING
2014-05-05 04:15:22,979 INFO org.apache.hadoop.yarn.server.resourcemanager.recovery.RMStateStore: Storing info for app: application_1399261790270_0004
2014-05-05 04:15:22,979 INFO org.apache.hadoop.yarn.server.resourcemanager.RMAuditLogger: USER=ubuntu	IP=10.0.0.158	OPERATION=Submit Application Request	TARGET=ClientRMService	RESULT=SUCCESS	APPID=application_1399261790270_0004
2014-05-05 04:15:22,981 INFO org.apache.hadoop.yarn.server.resourcemanager.rmapp.RMAppImpl: application_1399261790270_0004 State change from NEW_SAVING to SUBMITTED
2014-05-05 04:15:22,981 INFO org.apache.hadoop.yarn.server.resourcemanager.ApplicationMasterService: Registering app attempt : appattempt_1399261790270_0004_000001
2014-05-05 04:15:22,981 INFO org.apache.hadoop.yarn.server.resourcemanager.rmapp.attempt.RMAppAttemptImpl: appattempt_1399261790270_0004_000001 State change from NEW to SUBMITTED
2014-05-05 04:15:22,981 INFO org.apache.hadoop.yarn.server.resourcemanager.scheduler.capacity.LeafQueue: Application application_1399261790270_0004 from user: ubuntu activated in queue: default
2014-05-05 04:15:22,981 INFO org.apache.hadoop.yarn.server.resourcemanager.scheduler.capacity.LeafQueue: Application added - appId: application_1399261790270_0004 user: org.apache.hadoop.yarn.server.resourcemanager.scheduler.capacity.LeafQueue$User@749b475a, leaf-queue: default #user-pending-applications: 0 #user-active-applications: 1 #queue-pending-applications: 0 #queue-active-applications: 1
2014-05-05 04:15:22,982 INFO org.apache.hadoop.yarn.server.resourcemanager.scheduler.capacity.ParentQueue: Application added - appId: application_1399261790270_0004 user: ubuntu leaf-queue of parent: root #applications: 1
2014-05-05 04:15:22,982 INFO org.apache.hadoop.yarn.server.resourcemanager.scheduler.capacity.CapacityScheduler: Application Submission: appattempt_1399261790270_0004_000001, user: ubuntu queue: default: capacity=1.0, absoluteCapacity=1.0, usedResources=<memory:0, vCores:0>usedCapacity=0.0, absoluteUsedCapacity=0.0, numApps=1, numContainers=0, currently active: 1
2014-05-05 04:15:22,982 INFO org.apache.hadoop.yarn.server.resourcemanager.rmapp.attempt.RMAppAttemptImpl: appattempt_1399261790270_0004_000001 State change from SUBMITTED to SCHEDULED
2014-05-05 04:15:22,982 INFO org.apache.hadoop.yarn.server.resourcemanager.rmapp.RMAppImpl: application_1399261790270_0004 State change from SUBMITTED to ACCEPTED
2014-05-05 04:15:23,058 INFO org.apache.hadoop.yarn.server.resourcemanager.rmcontainer.RMContainerImpl: container_1399261790270_0004_01_000001 Container Transitioned from NEW to ALLOCATED
2014-05-05 04:15:23,058 INFO org.apache.hadoop.yarn.server.resourcemanager.RMAuditLogger: USER=ubuntu	OPERATION=AM Allocated Container	TARGET=SchedulerApp	RESULT=SUCCESS	APPID=application_1399261790270_0004	CONTAINERID=container_1399261790270_0004_01_000001
2014-05-05 04:15:23,058 INFO org.apache.hadoop.yarn.server.resourcemanager.scheduler.common.fica.FiCaSchedulerNode: Assigned container container_1399261790270_0004_01_000001 of capacity <memory:2048, vCores:1> on host nodec:51351, which currently has 1 containers, <memory:2048, vCores:1> used and <memory:6144, vCores:7> available
2014-05-05 04:15:23,058 INFO org.apache.hadoop.yarn.server.resourcemanager.scheduler.capacity.LeafQueue: assignedContainer application=application_1399261790270_0004 container=Container: [ContainerId: container_1399261790270_0004_01_000001, NodeId: nodec:51351, NodeHttpAddress: nodec:8042, Resource: <memory:2048, vCores:1>, Priority: 0, Token: Token { kind: ContainerToken, service: 10.0.0.181:51351 }, ] containerId=container_1399261790270_0004_01_000001 queue=default: capacity=1.0, absoluteCapacity=1.0, usedResources=<memory:0, vCores:0>usedCapacity=0.0, absoluteUsedCapacity=0.0, numApps=1, numContainers=0 usedCapacity=0.0 absoluteUsedCapacity=0.0 used=<memory:0, vCores:0> cluster=<memory:32768, vCores:32>
2014-05-05 04:15:23,058 INFO org.apache.hadoop.yarn.server.resourcemanager.rmcontainer.RMContainerImpl: container_1399261790270_0004_01_000001 Container Transitioned from ALLOCATED to ACQUIRED
2014-05-05 04:15:23,058 INFO org.apache.hadoop.yarn.server.resourcemanager.scheduler.capacity.ParentQueue: Re-sorting assigned queue: root.default stats: default: capacity=1.0, absoluteCapacity=1.0, usedResources=<memory:2048, vCores:1>usedCapacity=0.0625, absoluteUsedCapacity=0.0625, numApps=1, numContainers=1
2014-05-05 04:15:23,059 INFO org.apache.hadoop.yarn.server.resourcemanager.rmapp.attempt.RMAppAttemptImpl: Storing attempt: AppId: application_1399261790270_0004 AttemptId: appattempt_1399261790270_0004_000001 MasterContainer: Container: [ContainerId: container_1399261790270_0004_01_000001, NodeId: nodec:51351, NodeHttpAddress: nodec:8042, Resource: <memory:2048, vCores:1>, Priority: 0, Token: Token { kind: ContainerToken, service: 10.0.0.181:51351 }, ]
2014-05-05 04:15:23,059 INFO org.apache.hadoop.yarn.server.resourcemanager.scheduler.capacity.ParentQueue: assignedContainer queue=root usedCapacity=0.0625 absoluteUsedCapacity=0.0625 used=<memory:2048, vCores:1> cluster=<memory:32768, vCores:32>
2014-05-05 04:15:23,059 INFO org.apache.hadoop.yarn.server.resourcemanager.recovery.RMStateStore: Storing info for attempt: appattempt_1399261790270_0004_000001
2014-05-05 04:15:23,059 INFO org.apache.hadoop.yarn.server.resourcemanager.rmapp.attempt.RMAppAttemptImpl: appattempt_1399261790270_0004_000001 State change from SCHEDULED to ALLOCATED_SAVING
2014-05-05 04:15:23,059 INFO org.apache.hadoop.yarn.server.resourcemanager.rmapp.attempt.RMAppAttemptImpl: appattempt_1399261790270_0004_000001 State change from ALLOCATED_SAVING to ALLOCATED
2014-05-05 04:15:23,060 INFO org.apache.hadoop.yarn.server.resourcemanager.amlauncher.AMLauncher: Launching masterappattempt_1399261790270_0004_000001
2014-05-05 04:15:23,061 INFO org.apache.hadoop.yarn.server.resourcemanager.amlauncher.AMLauncher: Setting up container Container: [ContainerId: container_1399261790270_0004_01_000001, NodeId: nodec:51351, NodeHttpAddress: nodec:8042, Resource: <memory:2048, vCores:1>, Priority: 0, Token: Token { kind: ContainerToken, service: 10.0.0.181:51351 }, ] for AM appattempt_1399261790270_0004_000001
2014-05-05 04:15:23,061 INFO org.apache.hadoop.yarn.server.resourcemanager.amlauncher.AMLauncher: Command to launch container container_1399261790270_0004_01_000001 : $JAVA_HOME/bin/java -Dlog4j.configuration=container-log4j.properties -Dyarn.app.container.log.dir=<LOG_DIR> -Dyarn.app.container.log.filesize=0 -Dhadoop.root.logger=INFO,CLA  -Xmx1024m org.apache.hadoop.mapreduce.v2.app.MRAppMaster 1><LOG_DIR>/stdout 2><LOG_DIR>/stderr 
2014-05-05 04:15:23,079 INFO org.apache.hadoop.yarn.server.resourcemanager.amlauncher.AMLauncher: Done launching container Container: [ContainerId: container_1399261790270_0004_01_000001, NodeId: nodec:51351, NodeHttpAddress: nodec:8042, Resource: <memory:2048, vCores:1>, Priority: 0, Token: Token { kind: ContainerToken, service: 10.0.0.181:51351 }, ] for AM appattempt_1399261790270_0004_000001
2014-05-05 04:15:23,079 INFO org.apache.hadoop.yarn.server.resourcemanager.rmapp.attempt.RMAppAttemptImpl: appattempt_1399261790270_0004_000001 State change from ALLOCATED to LAUNCHED
2014-05-05 04:15:24,059 INFO org.apache.hadoop.yarn.server.resourcemanager.rmcontainer.RMContainerImpl: container_1399261790270_0004_01_000001 Container Transitioned from ACQUIRED to RUNNING
2014-05-05 04:15:28,187 INFO SecurityLogger.org.apache.hadoop.ipc.Server: Auth successful for appattempt_1399261790270_0004_000001 (auth:SIMPLE)
2014-05-05 04:15:28,191 INFO org.apache.hadoop.yarn.server.resourcemanager.ApplicationMasterService: AM registration appattempt_1399261790270_0004_000001
2014-05-05 04:15:28,191 INFO org.apache.hadoop.yarn.server.resourcemanager.RMAuditLogger: USER=ubuntu	IP=10.0.0.181	OPERATION=Register App Master	TARGET=ApplicationMasterService	RESULT=SUCCESS	APPID=application_1399261790270_0004	APPATTEMPTID=appattempt_1399261790270_0004_000001
2014-05-05 04:15:28,191 INFO org.apache.hadoop.yarn.server.resourcemanager.rmapp.attempt.RMAppAttemptImpl: appattempt_1399261790270_0004_000001 State change from LAUNCHED to RUNNING
2014-05-05 04:15:28,191 INFO org.apache.hadoop.yarn.server.resourcemanager.rmapp.RMAppImpl: application_1399261790270_0004 State change from ACCEPTED to RUNNING
2014-05-05 04:15:29,648 INFO org.apache.hadoop.yarn.server.resourcemanager.rmcontainer.RMContainerImpl: container_1399261790270_0004_01_000002 Container Transitioned from NEW to ALLOCATED
2014-05-05 04:15:29,648 INFO org.apache.hadoop.yarn.server.resourcemanager.RMAuditLogger: USER=ubuntu	OPERATION=AM Allocated Container	TARGET=SchedulerApp	RESULT=SUCCESS	APPID=application_1399261790270_0004	CONTAINERID=container_1399261790270_0004_01_000002
2014-05-05 04:15:29,648 INFO org.apache.hadoop.yarn.server.resourcemanager.scheduler.common.fica.FiCaSchedulerNode: Assigned container container_1399261790270_0004_01_000002 of capacity <memory:1024, vCores:1> on host noded:54001, which currently has 1 containers, <memory:1024, vCores:1> used and <memory:7168, vCores:7> available
2014-05-05 04:15:29,649 INFO org.apache.hadoop.yarn.server.resourcemanager.scheduler.capacity.LeafQueue: assignedContainer application=application_1399261790270_0004 container=Container: [ContainerId: container_1399261790270_0004_01_000002, NodeId: noded:54001, NodeHttpAddress: noded:8042, Resource: <memory:1024, vCores:1>, Priority: 20, Token: Token { kind: ContainerToken, service: 10.0.0.180:54001 }, ] containerId=container_1399261790270_0004_01_000002 queue=default: capacity=1.0, absoluteCapacity=1.0, usedResources=<memory:2048, vCores:1>usedCapacity=0.0625, absoluteUsedCapacity=0.0625, numApps=1, numContainers=1 usedCapacity=0.0625 absoluteUsedCapacity=0.0625 used=<memory:2048, vCores:1> cluster=<memory:32768, vCores:32>
2014-05-05 04:15:29,649 INFO org.apache.hadoop.yarn.server.resourcemanager.scheduler.capacity.ParentQueue: Re-sorting assigned queue: root.default stats: default: capacity=1.0, absoluteCapacity=1.0, usedResources=<memory:3072, vCores:2>usedCapacity=0.09375, absoluteUsedCapacity=0.09375, numApps=1, numContainers=2
2014-05-05 04:15:29,649 INFO org.apache.hadoop.yarn.server.resourcemanager.scheduler.capacity.ParentQueue: assignedContainer queue=root usedCapacity=0.09375 absoluteUsedCapacity=0.09375 used=<memory:3072, vCores:2> cluster=<memory:32768, vCores:32>
2014-05-05 04:15:29,649 INFO org.apache.hadoop.yarn.server.resourcemanager.rmcontainer.RMContainerImpl: container_1399261790270_0004_01_000003 Container Transitioned from NEW to ALLOCATED
2014-05-05 04:15:29,649 INFO org.apache.hadoop.yarn.server.resourcemanager.RMAuditLogger: USER=ubuntu	OPERATION=AM Allocated Container	TARGET=SchedulerApp	RESULT=SUCCESS	APPID=application_1399261790270_0004	CONTAINERID=container_1399261790270_0004_01_000003
2014-05-05 04:15:29,649 INFO org.apache.hadoop.yarn.server.resourcemanager.scheduler.common.fica.FiCaSchedulerNode: Assigned container container_1399261790270_0004_01_000003 of capacity <memory:1024, vCores:1> on host noded:54001, which currently has 2 containers, <memory:2048, vCores:2> used and <memory:6144, vCores:6> available
2014-05-05 04:15:29,649 INFO org.apache.hadoop.yarn.server.resourcemanager.scheduler.capacity.LeafQueue: assignedContainer application=application_1399261790270_0004 container=Container: [ContainerId: container_1399261790270_0004_01_000003, NodeId: noded:54001, NodeHttpAddress: noded:8042, Resource: <memory:1024, vCores:1>, Priority: 20, Token: Token { kind: ContainerToken, service: 10.0.0.180:54001 }, ] containerId=container_1399261790270_0004_01_000003 queue=default: capacity=1.0, absoluteCapacity=1.0, usedResources=<memory:3072, vCores:2>usedCapacity=0.09375, absoluteUsedCapacity=0.09375, numApps=1, numContainers=2 usedCapacity=0.09375 absoluteUsedCapacity=0.09375 used=<memory:3072, vCores:2> cluster=<memory:32768, vCores:32>
2014-05-05 04:15:29,649 INFO org.apache.hadoop.yarn.server.resourcemanager.scheduler.capacity.ParentQueue: Re-sorting assigned queue: root.default stats: default: capacity=1.0, absoluteCapacity=1.0, usedResources=<memory:4096, vCores:3>usedCapacity=0.125, absoluteUsedCapacity=0.125, numApps=1, numContainers=3
2014-05-05 04:15:29,649 INFO org.apache.hadoop.yarn.server.resourcemanager.scheduler.capacity.ParentQueue: assignedContainer queue=root usedCapacity=0.125 absoluteUsedCapacity=0.125 used=<memory:4096, vCores:3> cluster=<memory:32768, vCores:32>
2014-05-05 04:15:29,650 INFO org.apache.hadoop.yarn.server.resourcemanager.rmcontainer.RMContainerImpl: container_1399261790270_0004_01_000004 Container Transitioned from NEW to ALLOCATED
2014-05-05 04:15:29,650 INFO org.apache.hadoop.yarn.server.resourcemanager.RMAuditLogger: USER=ubuntu	OPERATION=AM Allocated Container	TARGET=SchedulerApp	RESULT=SUCCESS	APPID=application_1399261790270_0004	CONTAINERID=container_1399261790270_0004_01_000004
2014-05-05 04:15:29,650 INFO org.apache.hadoop.yarn.server.resourcemanager.scheduler.common.fica.FiCaSchedulerNode: Assigned container container_1399261790270_0004_01_000004 of capacity <memory:1024, vCores:1> on host noded:54001, which currently has 3 containers, <memory:3072, vCores:3> used and <memory:5120, vCores:5> available
2014-05-05 04:15:29,650 INFO org.apache.hadoop.yarn.server.resourcemanager.scheduler.capacity.LeafQueue: assignedContainer application=application_1399261790270_0004 container=Container: [ContainerId: container_1399261790270_0004_01_000004, NodeId: noded:54001, NodeHttpAddress: noded:8042, Resource: <memory:1024, vCores:1>, Priority: 20, Token: Token { kind: ContainerToken, service: 10.0.0.180:54001 }, ] containerId=container_1399261790270_0004_01_000004 queue=default: capacity=1.0, absoluteCapacity=1.0, usedResources=<memory:4096, vCores:3>usedCapacity=0.125, absoluteUsedCapacity=0.125, numApps=1, numContainers=3 usedCapacity=0.125 absoluteUsedCapacity=0.125 used=<memory:4096, vCores:3> cluster=<memory:32768, vCores:32>
2014-05-05 04:15:29,650 INFO org.apache.hadoop.yarn.server.resourcemanager.scheduler.capacity.ParentQueue: Re-sorting assigned queue: root.default stats: default: capacity=1.0, absoluteCapacity=1.0, usedResources=<memory:5120, vCores:4>usedCapacity=0.15625, absoluteUsedCapacity=0.15625, numApps=1, numContainers=4
2014-05-05 04:15:29,650 INFO org.apache.hadoop.yarn.server.resourcemanager.scheduler.capacity.ParentQueue: assignedContainer queue=root usedCapacity=0.15625 absoluteUsedCapacity=0.15625 used=<memory:5120, vCores:4> cluster=<memory:32768, vCores:32>
2014-05-05 04:15:29,650 INFO org.apache.hadoop.yarn.server.resourcemanager.rmcontainer.RMContainerImpl: container_1399261790270_0004_01_000005 Container Transitioned from NEW to ALLOCATED
2014-05-05 04:15:29,650 INFO org.apache.hadoop.yarn.server.resourcemanager.RMAuditLogger: USER=ubuntu	OPERATION=AM Allocated Container	TARGET=SchedulerApp	RESULT=SUCCESS	APPID=application_1399261790270_0004	CONTAINERID=container_1399261790270_0004_01_000005
2014-05-05 04:15:29,651 INFO org.apache.hadoop.yarn.server.resourcemanager.scheduler.common.fica.FiCaSchedulerNode: Assigned container container_1399261790270_0004_01_000005 of capacity <memory:1024, vCores:1> on host noded:54001, which currently has 4 containers, <memory:4096, vCores:4> used and <memory:4096, vCores:4> available
2014-05-05 04:15:29,651 INFO org.apache.hadoop.yarn.server.resourcemanager.scheduler.capacity.LeafQueue: assignedContainer application=application_1399261790270_0004 container=Container: [ContainerId: container_1399261790270_0004_01_000005, NodeId: noded:54001, NodeHttpAddress: noded:8042, Resource: <memory:1024, vCores:1>, Priority: 20, Token: Token { kind: ContainerToken, service: 10.0.0.180:54001 }, ] containerId=container_1399261790270_0004_01_000005 queue=default: capacity=1.0, absoluteCapacity=1.0, usedResources=<memory:5120, vCores:4>usedCapacity=0.15625, absoluteUsedCapacity=0.15625, numApps=1, numContainers=4 usedCapacity=0.15625 absoluteUsedCapacity=0.15625 used=<memory:5120, vCores:4> cluster=<memory:32768, vCores:32>
2014-05-05 04:15:29,651 INFO org.apache.hadoop.yarn.server.resourcemanager.scheduler.capacity.ParentQueue: Re-sorting assigned queue: root.default stats: default: capacity=1.0, absoluteCapacity=1.0, usedResources=<memory:6144, vCores:5>usedCapacity=0.1875, absoluteUsedCapacity=0.1875, numApps=1, numContainers=5
2014-05-05 04:15:29,651 INFO org.apache.hadoop.yarn.server.resourcemanager.scheduler.capacity.ParentQueue: assignedContainer queue=root usedCapacity=0.1875 absoluteUsedCapacity=0.1875 used=<memory:6144, vCores:5> cluster=<memory:32768, vCores:32>
2014-05-05 04:15:30,281 INFO org.apache.hadoop.yarn.server.resourcemanager.rmcontainer.RMContainerImpl: container_1399261790270_0004_01_000002 Container Transitioned from ALLOCATED to ACQUIRED
2014-05-05 04:15:30,282 INFO org.apache.hadoop.yarn.server.resourcemanager.rmcontainer.RMContainerImpl: container_1399261790270_0004_01_000003 Container Transitioned from ALLOCATED to ACQUIRED
2014-05-05 04:15:30,282 INFO org.apache.hadoop.yarn.server.resourcemanager.rmcontainer.RMContainerImpl: container_1399261790270_0004_01_000004 Container Transitioned from ALLOCATED to ACQUIRED
2014-05-05 04:15:30,282 INFO org.apache.hadoop.yarn.server.resourcemanager.rmcontainer.RMContainerImpl: container_1399261790270_0004_01_000005 Container Transitioned from ALLOCATED to ACQUIRED
2014-05-05 04:15:30,650 INFO org.apache.hadoop.yarn.server.resourcemanager.rmcontainer.RMContainerImpl: container_1399261790270_0004_01_000002 Container Transitioned from ACQUIRED to RUNNING
2014-05-05 04:15:30,651 INFO org.apache.hadoop.yarn.server.resourcemanager.rmcontainer.RMContainerImpl: container_1399261790270_0004_01_000003 Container Transitioned from ACQUIRED to RUNNING
2014-05-05 04:15:30,651 INFO org.apache.hadoop.yarn.server.resourcemanager.rmcontainer.RMContainerImpl: container_1399261790270_0004_01_000004 Container Transitioned from ACQUIRED to RUNNING
2014-05-05 04:15:30,651 INFO org.apache.hadoop.yarn.server.resourcemanager.rmcontainer.RMContainerImpl: container_1399261790270_0004_01_000005 Container Transitioned from ACQUIRED to RUNNING
2014-05-05 04:15:31,298 INFO org.apache.hadoop.yarn.server.resourcemanager.scheduler.AppSchedulingInfo: checking for deactivate... 
2014-05-05 04:15:56,612 INFO org.apache.hadoop.yarn.server.resourcemanager.rmcontainer.RMContainerImpl: container_1399261790270_0004_01_000005 Container Transitioned from RUNNING to COMPLETED
2014-05-05 04:15:56,612 INFO org.apache.hadoop.yarn.server.resourcemanager.scheduler.common.fica.FiCaSchedulerApp: Completed container: container_1399261790270_0004_01_000005 in state: COMPLETED event:FINISHED
2014-05-05 04:15:56,613 INFO org.apache.hadoop.yarn.server.resourcemanager.RMAuditLogger: USER=ubuntu	OPERATION=AM Released Container	TARGET=SchedulerApp	RESULT=SUCCESS	APPID=application_1399261790270_0004	CONTAINERID=container_1399261790270_0004_01_000005
2014-05-05 04:15:56,613 INFO org.apache.hadoop.yarn.server.resourcemanager.scheduler.common.fica.FiCaSchedulerNode: Released container container_1399261790270_0004_01_000005 of capacity <memory:1024, vCores:1> on host noded:54001, which currently has 3 containers, <memory:3072, vCores:3> used and <memory:5120, vCores:5> available, release resources=true
2014-05-05 04:15:56,613 INFO org.apache.hadoop.yarn.server.resourcemanager.scheduler.capacity.LeafQueue: default used=<memory:5120, vCores:4> numContainers=4 user=ubuntu user-resources=<memory:5120, vCores:4>
2014-05-05 04:15:56,613 INFO org.apache.hadoop.yarn.server.resourcemanager.scheduler.capacity.LeafQueue: completedContainer container=Container: [ContainerId: container_1399261790270_0004_01_000005, NodeId: noded:54001, NodeHttpAddress: noded:8042, Resource: <memory:1024, vCores:1>, Priority: 20, Token: Token { kind: ContainerToken, service: 10.0.0.180:54001 }, ] resource=<memory:1024, vCores:1> queue=default: capacity=1.0, absoluteCapacity=1.0, usedResources=<memory:5120, vCores:4>usedCapacity=0.15625, absoluteUsedCapacity=0.15625, numApps=1, numContainers=4 usedCapacity=0.15625 absoluteUsedCapacity=0.15625 used=<memory:5120, vCores:4> cluster=<memory:32768, vCores:32>
2014-05-05 04:15:56,613 INFO org.apache.hadoop.yarn.server.resourcemanager.scheduler.capacity.ParentQueue: completedContainer queue=root usedCapacity=0.15625 absoluteUsedCapacity=0.15625 used=<memory:5120, vCores:4> cluster=<memory:32768, vCores:32>
2014-05-05 04:15:56,613 INFO org.apache.hadoop.yarn.server.resourcemanager.scheduler.capacity.ParentQueue: Re-sorting completed queue: root.default stats: default: capacity=1.0, absoluteCapacity=1.0, usedResources=<memory:5120, vCores:4>usedCapacity=0.15625, absoluteUsedCapacity=0.15625, numApps=1, numContainers=4
2014-05-05 04:15:56,613 INFO org.apache.hadoop.yarn.server.resourcemanager.scheduler.capacity.CapacityScheduler: Application appattempt_1399261790270_0004_000001 released container container_1399261790270_0004_01_000005 on node: host: noded:54001 #containers=3 available=5120 used=3072 with event: FINISHED
2014-05-05 04:15:56,613 INFO org.apache.hadoop.yarn.server.resourcemanager.rmcontainer.RMContainerImpl: container_1399261790270_0004_01_000006 Container Transitioned from NEW to ALLOCATED
2014-05-05 04:15:56,614 INFO org.apache.hadoop.yarn.server.resourcemanager.RMAuditLogger: USER=ubuntu	OPERATION=AM Allocated Container	TARGET=SchedulerApp	RESULT=SUCCESS	APPID=application_1399261790270_0004	CONTAINERID=container_1399261790270_0004_01_000006
2014-05-05 04:15:56,614 INFO org.apache.hadoop.yarn.server.resourcemanager.scheduler.common.fica.FiCaSchedulerNode: Assigned container container_1399261790270_0004_01_000006 of capacity <memory:1024, vCores:1> on host noded:54001, which currently has 4 containers, <memory:4096, vCores:4> used and <memory:4096, vCores:4> available
2014-05-05 04:15:56,614 INFO org.apache.hadoop.yarn.server.resourcemanager.scheduler.capacity.LeafQueue: assignedContainer application=application_1399261790270_0004 container=Container: [ContainerId: container_1399261790270_0004_01_000006, NodeId: noded:54001, NodeHttpAddress: noded:8042, Resource: <memory:1024, vCores:1>, Priority: 20, Token: Token { kind: ContainerToken, service: 10.0.0.180:54001 }, ] containerId=container_1399261790270_0004_01_000006 queue=default: capacity=1.0, absoluteCapacity=1.0, usedResources=<memory:5120, vCores:4>usedCapacity=0.15625, absoluteUsedCapacity=0.15625, numApps=1, numContainers=4 usedCapacity=0.15625 absoluteUsedCapacity=0.15625 used=<memory:5120, vCores:4> cluster=<memory:32768, vCores:32>
2014-05-05 04:15:56,614 INFO org.apache.hadoop.yarn.server.resourcemanager.scheduler.capacity.ParentQueue: Re-sorting assigned queue: root.default stats: default: capacity=1.0, absoluteCapacity=1.0, usedResources=<memory:6144, vCores:5>usedCapacity=0.1875, absoluteUsedCapacity=0.1875, numApps=1, numContainers=5
2014-05-05 04:15:56,614 INFO org.apache.hadoop.yarn.server.resourcemanager.scheduler.capacity.ParentQueue: assignedContainer queue=root usedCapacity=0.1875 absoluteUsedCapacity=0.1875 used=<memory:6144, vCores:5> cluster=<memory:32768, vCores:32>
2014-05-05 04:15:57,354 INFO org.apache.hadoop.yarn.server.resourcemanager.rmcontainer.RMContainerImpl: container_1399261790270_0004_01_000006 Container Transitioned from ALLOCATED to ACQUIRED
2014-05-05 04:15:57,615 INFO org.apache.hadoop.yarn.server.resourcemanager.rmcontainer.RMContainerImpl: container_1399261790270_0004_01_000007 Container Transitioned from NEW to ALLOCATED
2014-05-05 04:15:57,615 INFO org.apache.hadoop.yarn.server.resourcemanager.RMAuditLogger: USER=ubuntu	OPERATION=AM Allocated Container	TARGET=SchedulerApp	RESULT=SUCCESS	APPID=application_1399261790270_0004	CONTAINERID=container_1399261790270_0004_01_000007
2014-05-05 04:15:57,615 INFO org.apache.hadoop.yarn.server.resourcemanager.scheduler.common.fica.FiCaSchedulerNode: Assigned container container_1399261790270_0004_01_000007 of capacity <memory:1024, vCores:1> on host noded:54001, which currently has 5 containers, <memory:5120, vCores:5> used and <memory:3072, vCores:3> available
2014-05-05 04:15:57,615 INFO org.apache.hadoop.yarn.server.resourcemanager.scheduler.capacity.LeafQueue: assignedContainer application=application_1399261790270_0004 container=Container: [ContainerId: container_1399261790270_0004_01_000007, NodeId: noded:54001, NodeHttpAddress: noded:8042, Resource: <memory:1024, vCores:1>, Priority: 10, Token: Token { kind: ContainerToken, service: 10.0.0.180:54001 }, ] containerId=container_1399261790270_0004_01_000007 queue=default: capacity=1.0, absoluteCapacity=1.0, usedResources=<memory:6144, vCores:5>usedCapacity=0.1875, absoluteUsedCapacity=0.1875, numApps=1, numContainers=5 usedCapacity=0.1875 absoluteUsedCapacity=0.1875 used=<memory:6144, vCores:5> cluster=<memory:32768, vCores:32>
2014-05-05 04:15:57,615 INFO org.apache.hadoop.yarn.server.resourcemanager.scheduler.capacity.ParentQueue: Re-sorting assigned queue: root.default stats: default: capacity=1.0, absoluteCapacity=1.0, usedResources=<memory:7168, vCores:6>usedCapacity=0.21875, absoluteUsedCapacity=0.21875, numApps=1, numContainers=6
2014-05-05 04:15:57,615 INFO org.apache.hadoop.yarn.server.resourcemanager.scheduler.capacity.ParentQueue: assignedContainer queue=root usedCapacity=0.21875 absoluteUsedCapacity=0.21875 used=<memory:7168, vCores:6> cluster=<memory:32768, vCores:32>
2014-05-05 04:15:57,615 INFO org.apache.hadoop.yarn.server.resourcemanager.rmcontainer.RMContainerImpl: container_1399261790270_0004_01_000008 Container Transitioned from NEW to ALLOCATED
2014-05-05 04:15:57,616 INFO org.apache.hadoop.yarn.server.resourcemanager.RMAuditLogger: USER=ubuntu	OPERATION=AM Allocated Container	TARGET=SchedulerApp	RESULT=SUCCESS	APPID=application_1399261790270_0004	CONTAINERID=container_1399261790270_0004_01_000008
2014-05-05 04:15:57,616 INFO org.apache.hadoop.yarn.server.resourcemanager.scheduler.common.fica.FiCaSchedulerNode: Assigned container container_1399261790270_0004_01_000008 of capacity <memory:1024, vCores:1> on host noded:54001, which currently has 6 containers, <memory:6144, vCores:6> used and <memory:2048, vCores:2> available
2014-05-05 04:15:57,616 INFO org.apache.hadoop.yarn.server.resourcemanager.scheduler.capacity.LeafQueue: assignedContainer application=application_1399261790270_0004 container=Container: [ContainerId: container_1399261790270_0004_01_000008, NodeId: noded:54001, NodeHttpAddress: noded:8042, Resource: <memory:1024, vCores:1>, Priority: 10, Token: Token { kind: ContainerToken, service: 10.0.0.180:54001 }, ] containerId=container_1399261790270_0004_01_000008 queue=default: capacity=1.0, absoluteCapacity=1.0, usedResources=<memory:7168, vCores:6>usedCapacity=0.21875, absoluteUsedCapacity=0.21875, numApps=1, numContainers=6 usedCapacity=0.21875 absoluteUsedCapacity=0.21875 used=<memory:7168, vCores:6> cluster=<memory:32768, vCores:32>
2014-05-05 04:15:57,616 INFO org.apache.hadoop.yarn.server.resourcemanager.scheduler.capacity.ParentQueue: Re-sorting assigned queue: root.default stats: default: capacity=1.0, absoluteCapacity=1.0, usedResources=<memory:8192, vCores:7>usedCapacity=0.25, absoluteUsedCapacity=0.25, numApps=1, numContainers=7
2014-05-05 04:15:57,616 INFO org.apache.hadoop.yarn.server.resourcemanager.scheduler.capacity.ParentQueue: assignedContainer queue=root usedCapacity=0.25 absoluteUsedCapacity=0.25 used=<memory:8192, vCores:7> cluster=<memory:32768, vCores:32>
2014-05-05 04:15:57,639 INFO org.apache.hadoop.yarn.server.resourcemanager.rmcontainer.RMContainerImpl: container_1399261790270_0004_01_000009 Container Transitioned from NEW to ALLOCATED
2014-05-05 04:15:57,639 INFO org.apache.hadoop.yarn.server.resourcemanager.RMAuditLogger: USER=ubuntu	OPERATION=AM Allocated Container	TARGET=SchedulerApp	RESULT=SUCCESS	APPID=application_1399261790270_0004	CONTAINERID=container_1399261790270_0004_01_000009
2014-05-05 04:15:57,639 INFO org.apache.hadoop.yarn.server.resourcemanager.scheduler.common.fica.FiCaSchedulerNode: Assigned container container_1399261790270_0004_01_000009 of capacity <memory:1024, vCores:1> on host nodec:51351, which currently has 2 containers, <memory:3072, vCores:2> used and <memory:5120, vCores:6> available
2014-05-05 04:15:57,639 INFO org.apache.hadoop.yarn.server.resourcemanager.scheduler.capacity.LeafQueue: assignedContainer application=application_1399261790270_0004 container=Container: [ContainerId: container_1399261790270_0004_01_000009, NodeId: nodec:51351, NodeHttpAddress: nodec:8042, Resource: <memory:1024, vCores:1>, Priority: 10, Token: Token { kind: ContainerToken, service: 10.0.0.181:51351 }, ] containerId=container_1399261790270_0004_01_000009 queue=default: capacity=1.0, absoluteCapacity=1.0, usedResources=<memory:8192, vCores:7>usedCapacity=0.25, absoluteUsedCapacity=0.25, numApps=1, numContainers=7 usedCapacity=0.25 absoluteUsedCapacity=0.25 used=<memory:8192, vCores:7> cluster=<memory:32768, vCores:32>
2014-05-05 04:15:57,639 INFO org.apache.hadoop.yarn.server.resourcemanager.scheduler.capacity.ParentQueue: Re-sorting assigned queue: root.default stats: default: capacity=1.0, absoluteCapacity=1.0, usedResources=<memory:9216, vCores:8>usedCapacity=0.28125, absoluteUsedCapacity=0.28125, numApps=1, numContainers=8
2014-05-05 04:15:57,639 INFO org.apache.hadoop.yarn.server.resourcemanager.scheduler.capacity.ParentQueue: assignedContainer queue=root usedCapacity=0.28125 absoluteUsedCapacity=0.28125 used=<memory:9216, vCores:8> cluster=<memory:32768, vCores:32>
2014-05-05 04:15:57,640 INFO org.apache.hadoop.yarn.server.resourcemanager.rmcontainer.RMContainerImpl: container_1399261790270_0004_01_000010 Container Transitioned from NEW to ALLOCATED
2014-05-05 04:15:57,640 INFO org.apache.hadoop.yarn.server.resourcemanager.RMAuditLogger: USER=ubuntu	OPERATION=AM Allocated Container	TARGET=SchedulerApp	RESULT=SUCCESS	APPID=application_1399261790270_0004	CONTAINERID=container_1399261790270_0004_01_000010
2014-05-05 04:15:57,640 INFO org.apache.hadoop.yarn.server.resourcemanager.scheduler.common.fica.FiCaSchedulerNode: Assigned container container_1399261790270_0004_01_000010 of capacity <memory:1024, vCores:1> on host nodec:51351, which currently has 3 containers, <memory:4096, vCores:3> used and <memory:4096, vCores:5> available
2014-05-05 04:15:57,640 INFO org.apache.hadoop.yarn.server.resourcemanager.scheduler.capacity.LeafQueue: assignedContainer application=application_1399261790270_0004 container=Container: [ContainerId: container_1399261790270_0004_01_000010, NodeId: nodec:51351, NodeHttpAddress: nodec:8042, Resource: <memory:1024, vCores:1>, Priority: 10, Token: Token { kind: ContainerToken, service: 10.0.0.181:51351 }, ] containerId=container_1399261790270_0004_01_000010 queue=default: capacity=1.0, absoluteCapacity=1.0, usedResources=<memory:9216, vCores:8>usedCapacity=0.28125, absoluteUsedCapacity=0.28125, numApps=1, numContainers=8 usedCapacity=0.28125 absoluteUsedCapacity=0.28125 used=<memory:9216, vCores:8> cluster=<memory:32768, vCores:32>
2014-05-05 04:15:57,640 INFO org.apache.hadoop.yarn.server.resourcemanager.scheduler.capacity.ParentQueue: Re-sorting assigned queue: root.default stats: default: capacity=1.0, absoluteCapacity=1.0, usedResources=<memory:10240, vCores:9>usedCapacity=0.3125, absoluteUsedCapacity=0.3125, numApps=1, numContainers=9
2014-05-05 04:15:57,640 INFO org.apache.hadoop.yarn.server.resourcemanager.scheduler.capacity.ParentQueue: assignedContainer queue=root usedCapacity=0.3125 absoluteUsedCapacity=0.3125 used=<memory:10240, vCores:9> cluster=<memory:32768, vCores:32>
2014-05-05 04:15:57,756 INFO org.apache.hadoop.yarn.server.resourcemanager.rmcontainer.RMContainerImpl: container_1399261790270_0004_01_000011 Container Transitioned from NEW to ALLOCATED
2014-05-05 04:15:57,756 INFO org.apache.hadoop.yarn.server.resourcemanager.RMAuditLogger: USER=ubuntu	OPERATION=AM Allocated Container	TARGET=SchedulerApp	RESULT=SUCCESS	APPID=application_1399261790270_0004	CONTAINERID=container_1399261790270_0004_01_000011
2014-05-05 04:15:57,756 INFO org.apache.hadoop.yarn.server.resourcemanager.scheduler.common.fica.FiCaSchedulerNode: Assigned container container_1399261790270_0004_01_000011 of capacity <memory:1024, vCores:1> on host nodeb:41344, which currently has 1 containers, <memory:1024, vCores:1> used and <memory:7168, vCores:7> available
2014-05-05 04:15:57,757 INFO org.apache.hadoop.yarn.server.resourcemanager.scheduler.capacity.LeafQueue: assignedContainer application=application_1399261790270_0004 container=Container: [ContainerId: container_1399261790270_0004_01_000011, NodeId: nodeb:41344, NodeHttpAddress: nodeb:8042, Resource: <memory:1024, vCores:1>, Priority: 10, Token: Token { kind: ContainerToken, service: 10.0.0.59:41344 }, ] containerId=container_1399261790270_0004_01_000011 queue=default: capacity=1.0, absoluteCapacity=1.0, usedResources=<memory:10240, vCores:9>usedCapacity=0.3125, absoluteUsedCapacity=0.3125, numApps=1, numContainers=9 usedCapacity=0.3125 absoluteUsedCapacity=0.3125 used=<memory:10240, vCores:9> cluster=<memory:32768, vCores:32>
2014-05-05 04:15:57,757 INFO org.apache.hadoop.yarn.server.resourcemanager.scheduler.capacity.ParentQueue: Re-sorting assigned queue: root.default stats: default: capacity=1.0, absoluteCapacity=1.0, usedResources=<memory:11264, vCores:10>usedCapacity=0.34375, absoluteUsedCapacity=0.34375, numApps=1, numContainers=10
2014-05-05 04:15:57,757 INFO org.apache.hadoop.yarn.server.resourcemanager.scheduler.capacity.ParentQueue: assignedContainer queue=root usedCapacity=0.34375 absoluteUsedCapacity=0.34375 used=<memory:11264, vCores:10> cluster=<memory:32768, vCores:32>
2014-05-05 04:15:57,757 INFO org.apache.hadoop.yarn.server.resourcemanager.rmcontainer.RMContainerImpl: container_1399261790270_0004_01_000012 Container Transitioned from NEW to ALLOCATED
2014-05-05 04:15:57,757 INFO org.apache.hadoop.yarn.server.resourcemanager.RMAuditLogger: USER=ubuntu	OPERATION=AM Allocated Container	TARGET=SchedulerApp	RESULT=SUCCESS	APPID=application_1399261790270_0004	CONTAINERID=container_1399261790270_0004_01_000012
2014-05-05 04:15:57,757 INFO org.apache.hadoop.yarn.server.resourcemanager.scheduler.common.fica.FiCaSchedulerNode: Assigned container container_1399261790270_0004_01_000012 of capacity <memory:1024, vCores:1> on host nodeb:41344, which currently has 2 containers, <memory:2048, vCores:2> used and <memory:6144, vCores:6> available
2014-05-05 04:15:57,757 INFO org.apache.hadoop.yarn.server.resourcemanager.scheduler.capacity.LeafQueue: assignedContainer application=application_1399261790270_0004 container=Container: [ContainerId: container_1399261790270_0004_01_000012, NodeId: nodeb:41344, NodeHttpAddress: nodeb:8042, Resource: <memory:1024, vCores:1>, Priority: 10, Token: Token { kind: ContainerToken, service: 10.0.0.59:41344 }, ] containerId=container_1399261790270_0004_01_000012 queue=default: capacity=1.0, absoluteCapacity=1.0, usedResources=<memory:11264, vCores:10>usedCapacity=0.34375, absoluteUsedCapacity=0.34375, numApps=1, numContainers=10 usedCapacity=0.34375 absoluteUsedCapacity=0.34375 used=<memory:11264, vCores:10> cluster=<memory:32768, vCores:32>
2014-05-05 04:15:57,757 INFO org.apache.hadoop.yarn.server.resourcemanager.scheduler.capacity.ParentQueue: Re-sorting assigned queue: root.default stats: default: capacity=1.0, absoluteCapacity=1.0, usedResources=<memory:12288, vCores:11>usedCapacity=0.375, absoluteUsedCapacity=0.375, numApps=1, numContainers=11
2014-05-05 04:15:57,757 INFO org.apache.hadoop.yarn.server.resourcemanager.scheduler.capacity.ParentQueue: assignedContainer queue=root usedCapacity=0.375 absoluteUsedCapacity=0.375 used=<memory:12288, vCores:11> cluster=<memory:32768, vCores:32>
2014-05-05 04:15:57,936 INFO org.apache.hadoop.yarn.server.resourcemanager.rmcontainer.RMContainerImpl: container_1399261790270_0004_01_000013 Container Transitioned from NEW to ALLOCATED
2014-05-05 04:15:57,937 INFO org.apache.hadoop.yarn.server.resourcemanager.RMAuditLogger: USER=ubuntu	OPERATION=AM Allocated Container	TARGET=SchedulerApp	RESULT=SUCCESS	APPID=application_1399261790270_0004	CONTAINERID=container_1399261790270_0004_01_000013
2014-05-05 04:15:57,937 INFO org.apache.hadoop.yarn.server.resourcemanager.scheduler.common.fica.FiCaSchedulerNode: Assigned container container_1399261790270_0004_01_000013 of capacity <memory:1024, vCores:1> on host nodea:49324, which currently has 1 containers, <memory:1024, vCores:1> used and <memory:7168, vCores:7> available
2014-05-05 04:15:57,937 INFO org.apache.hadoop.yarn.server.resourcemanager.scheduler.capacity.LeafQueue: assignedContainer application=application_1399261790270_0004 container=Container: [ContainerId: container_1399261790270_0004_01_000013, NodeId: nodea:49324, NodeHttpAddress: nodea:8042, Resource: <memory:1024, vCores:1>, Priority: 10, Token: Token { kind: ContainerToken, service: 10.0.0.158:49324 }, ] containerId=container_1399261790270_0004_01_000013 queue=default: capacity=1.0, absoluteCapacity=1.0, usedResources=<memory:12288, vCores:11>usedCapacity=0.375, absoluteUsedCapacity=0.375, numApps=1, numContainers=11 usedCapacity=0.375 absoluteUsedCapacity=0.375 used=<memory:12288, vCores:11> cluster=<memory:32768, vCores:32>
2014-05-05 04:15:57,937 INFO org.apache.hadoop.yarn.server.resourcemanager.scheduler.capacity.ParentQueue: Re-sorting assigned queue: root.default stats: default: capacity=1.0, absoluteCapacity=1.0, usedResources=<memory:13312, vCores:12>usedCapacity=0.40625, absoluteUsedCapacity=0.40625, numApps=1, numContainers=12
2014-05-05 04:15:57,937 INFO org.apache.hadoop.yarn.server.resourcemanager.scheduler.capacity.ParentQueue: assignedContainer queue=root usedCapacity=0.40625 absoluteUsedCapacity=0.40625 used=<memory:13312, vCores:12> cluster=<memory:32768, vCores:32>
2014-05-05 04:15:57,937 INFO org.apache.hadoop.yarn.server.resourcemanager.rmcontainer.RMContainerImpl: container_1399261790270_0004_01_000014 Container Transitioned from NEW to ALLOCATED
2014-05-05 04:15:57,937 INFO org.apache.hadoop.yarn.server.resourcemanager.RMAuditLogger: USER=ubuntu	OPERATION=AM Allocated Container	TARGET=SchedulerApp	RESULT=SUCCESS	APPID=application_1399261790270_0004	CONTAINERID=container_1399261790270_0004_01_000014
2014-05-05 04:15:57,937 INFO org.apache.hadoop.yarn.server.resourcemanager.scheduler.common.fica.FiCaSchedulerNode: Assigned container container_1399261790270_0004_01_000014 of capacity <memory:1024, vCores:1> on host nodea:49324, which currently has 2 containers, <memory:2048, vCores:2> used and <memory:6144, vCores:6> available
2014-05-05 04:15:57,938 INFO org.apache.hadoop.yarn.server.resourcemanager.scheduler.capacity.LeafQueue: assignedContainer application=application_1399261790270_0004 container=Container: [ContainerId: container_1399261790270_0004_01_000014, NodeId: nodea:49324, NodeHttpAddress: nodea:8042, Resource: <memory:1024, vCores:1>, Priority: 10, Token: Token { kind: ContainerToken, service: 10.0.0.158:49324 }, ] containerId=container_1399261790270_0004_01_000014 queue=default: capacity=1.0, absoluteCapacity=1.0, usedResources=<memory:13312, vCores:12>usedCapacity=0.40625, absoluteUsedCapacity=0.40625, numApps=1, numContainers=12 usedCapacity=0.40625 absoluteUsedCapacity=0.40625 used=<memory:13312, vCores:12> cluster=<memory:32768, vCores:32>
2014-05-05 04:15:57,938 INFO org.apache.hadoop.yarn.server.resourcemanager.scheduler.capacity.ParentQueue: Re-sorting assigned queue: root.default stats: default: capacity=1.0, absoluteCapacity=1.0, usedResources=<memory:14336, vCores:13>usedCapacity=0.4375, absoluteUsedCapacity=0.4375, numApps=1, numContainers=13
2014-05-05 04:15:57,938 INFO org.apache.hadoop.yarn.server.resourcemanager.scheduler.capacity.ParentQueue: assignedContainer queue=root usedCapacity=0.4375 absoluteUsedCapacity=0.4375 used=<memory:14336, vCores:13> cluster=<memory:32768, vCores:32>
2014-05-05 04:15:58,617 INFO org.apache.hadoop.yarn.server.resourcemanager.rmcontainer.RMContainerImpl: container_1399261790270_0004_01_000006 Container Transitioned from ACQUIRED to RUNNING
2014-05-05 04:15:58,665 INFO org.apache.hadoop.yarn.server.resourcemanager.scheduler.AppSchedulingInfo: checking for deactivate... 
2014-05-05 04:15:58,665 INFO org.apache.hadoop.yarn.server.resourcemanager.rmcontainer.RMContainerImpl: container_1399261790270_0004_01_000007 Container Transitioned from ALLOCATED to ACQUIRED
2014-05-05 04:15:58,666 INFO org.apache.hadoop.yarn.server.resourcemanager.rmcontainer.RMContainerImpl: container_1399261790270_0004_01_000008 Container Transitioned from ALLOCATED to ACQUIRED
2014-05-05 04:15:58,666 INFO org.apache.hadoop.yarn.server.resourcemanager.rmcontainer.RMContainerImpl: container_1399261790270_0004_01_000009 Container Transitioned from ALLOCATED to ACQUIRED
2014-05-05 04:15:58,666 INFO org.apache.hadoop.yarn.server.resourcemanager.rmcontainer.RMContainerImpl: container_1399261790270_0004_01_000010 Container Transitioned from ALLOCATED to ACQUIRED
2014-05-05 04:15:58,666 INFO org.apache.hadoop.yarn.server.resourcemanager.rmcontainer.RMContainerImpl: container_1399261790270_0004_01_000011 Container Transitioned from ALLOCATED to ACQUIRED
2014-05-05 04:15:58,667 INFO org.apache.hadoop.yarn.server.resourcemanager.rmcontainer.RMContainerImpl: container_1399261790270_0004_01_000012 Container Transitioned from ALLOCATED to ACQUIRED
2014-05-05 04:15:58,667 INFO org.apache.hadoop.yarn.server.resourcemanager.rmcontainer.RMContainerImpl: container_1399261790270_0004_01_000013 Container Transitioned from ALLOCATED to ACQUIRED
2014-05-05 04:15:58,667 INFO org.apache.hadoop.yarn.server.resourcemanager.rmcontainer.RMContainerImpl: container_1399261790270_0004_01_000014 Container Transitioned from ALLOCATED to ACQUIRED
2014-05-05 04:15:58,760 INFO org.apache.hadoop.yarn.server.resourcemanager.rmcontainer.RMContainerImpl: container_1399261790270_0004_01_000011 Container Transitioned from ACQUIRED to RUNNING
2014-05-05 04:15:58,938 INFO org.apache.hadoop.yarn.server.resourcemanager.rmcontainer.RMContainerImpl: container_1399261790270_0004_01_000013 Container Transitioned from ACQUIRED to RUNNING
2014-05-05 04:15:58,938 INFO org.apache.hadoop.yarn.server.resourcemanager.rmcontainer.RMContainerImpl: container_1399261790270_0004_01_000014 Container Transitioned from ACQUIRED to RUNNING
2014-05-05 04:15:59,620 INFO org.apache.hadoop.yarn.server.resourcemanager.rmcontainer.RMContainerImpl: container_1399261790270_0004_01_000007 Container Transitioned from ACQUIRED to RUNNING
2014-05-05 04:15:59,621 INFO org.apache.hadoop.yarn.server.resourcemanager.rmcontainer.RMContainerImpl: container_1399261790270_0004_01_000008 Container Transitioned from ACQUIRED to RUNNING
2014-05-05 04:15:59,643 INFO org.apache.hadoop.yarn.server.resourcemanager.rmcontainer.RMContainerImpl: container_1399261790270_0004_01_000009 Container Transitioned from ACQUIRED to RUNNING
2014-05-05 04:15:59,643 INFO org.apache.hadoop.yarn.server.resourcemanager.rmcontainer.RMContainerImpl: container_1399261790270_0004_01_000010 Container Transitioned from ACQUIRED to RUNNING
2014-05-05 04:15:59,675 INFO org.apache.hadoop.yarn.server.resourcemanager.scheduler.AppSchedulingInfo: checking for deactivate... 
2014-05-05 04:15:59,763 INFO org.apache.hadoop.yarn.server.resourcemanager.rmcontainer.RMContainerImpl: container_1399261790270_0004_01_000012 Container Transitioned from ACQUIRED to RUNNING
2014-05-05 04:16:13,511 INFO org.apache.hadoop.yarn.server.resourcemanager.rmcontainer.RMContainerImpl: container_1399261790270_0004_01_000002 Container Transitioned from RUNNING to COMPLETED
2014-05-05 04:16:13,511 INFO org.apache.hadoop.yarn.server.resourcemanager.scheduler.common.fica.FiCaSchedulerApp: Completed container: container_1399261790270_0004_01_000002 in state: COMPLETED event:FINISHED
2014-05-05 04:16:13,511 INFO org.apache.hadoop.yarn.server.resourcemanager.RMAuditLogger: USER=ubuntu	OPERATION=AM Released Container	TARGET=SchedulerApp	RESULT=SUCCESS	APPID=application_1399261790270_0004	CONTAINERID=container_1399261790270_0004_01_000002
2014-05-05 04:16:13,511 INFO org.apache.hadoop.yarn.server.resourcemanager.scheduler.common.fica.FiCaSchedulerNode: Released container container_1399261790270_0004_01_000002 of capacity <memory:1024, vCores:1> on host noded:54001, which currently has 5 containers, <memory:5120, vCores:5> used and <memory:3072, vCores:3> available, release resources=true
2014-05-05 04:16:13,511 INFO org.apache.hadoop.yarn.server.resourcemanager.scheduler.capacity.LeafQueue: default used=<memory:13312, vCores:12> numContainers=12 user=ubuntu user-resources=<memory:13312, vCores:12>
2014-05-05 04:16:13,511 INFO org.apache.hadoop.yarn.server.resourcemanager.scheduler.capacity.LeafQueue: completedContainer container=Container: [ContainerId: container_1399261790270_0004_01_000002, NodeId: noded:54001, NodeHttpAddress: noded:8042, Resource: <memory:1024, vCores:1>, Priority: 20, Token: Token { kind: ContainerToken, service: 10.0.0.180:54001 }, ] resource=<memory:1024, vCores:1> queue=default: capacity=1.0, absoluteCapacity=1.0, usedResources=<memory:13312, vCores:12>usedCapacity=0.40625, absoluteUsedCapacity=0.40625, numApps=1, numContainers=12 usedCapacity=0.40625 absoluteUsedCapacity=0.40625 used=<memory:13312, vCores:12> cluster=<memory:32768, vCores:32>
2014-05-05 04:16:13,511 INFO org.apache.hadoop.yarn.server.resourcemanager.scheduler.capacity.ParentQueue: completedContainer queue=root usedCapacity=0.40625 absoluteUsedCapacity=0.40625 used=<memory:13312, vCores:12> cluster=<memory:32768, vCores:32>
2014-05-05 04:16:13,511 INFO org.apache.hadoop.yarn.server.resourcemanager.scheduler.capacity.ParentQueue: Re-sorting completed queue: root.default stats: default: capacity=1.0, absoluteCapacity=1.0, usedResources=<memory:13312, vCores:12>usedCapacity=0.40625, absoluteUsedCapacity=0.40625, numApps=1, numContainers=12
2014-05-05 04:16:13,511 INFO org.apache.hadoop.yarn.server.resourcemanager.scheduler.capacity.CapacityScheduler: Application appattempt_1399261790270_0004_000001 released container container_1399261790270_0004_01_000002 on node: host: noded:54001 #containers=5 available=3072 used=5120 with event: FINISHED
2014-05-05 04:16:15,873 INFO org.apache.hadoop.yarn.server.resourcemanager.rmcontainer.RMContainerImpl: container_1399261790270_0004_01_000004 Container Transitioned from RUNNING to COMPLETED
2014-05-05 04:16:15,873 INFO org.apache.hadoop.yarn.server.resourcemanager.scheduler.common.fica.FiCaSchedulerApp: Completed container: container_1399261790270_0004_01_000004 in state: COMPLETED event:FINISHED
2014-05-05 04:16:15,873 INFO org.apache.hadoop.yarn.server.resourcemanager.RMAuditLogger: USER=ubuntu	OPERATION=AM Released Container	TARGET=SchedulerApp	RESULT=SUCCESS	APPID=application_1399261790270_0004	CONTAINERID=container_1399261790270_0004_01_000004
2014-05-05 04:16:15,873 INFO org.apache.hadoop.yarn.server.resourcemanager.scheduler.common.fica.FiCaSchedulerNode: Released container container_1399261790270_0004_01_000004 of capacity <memory:1024, vCores:1> on host noded:54001, which currently has 4 containers, <memory:4096, vCores:4> used and <memory:4096, vCores:4> available, release resources=true
2014-05-05 04:16:15,874 INFO org.apache.hadoop.yarn.server.resourcemanager.scheduler.capacity.LeafQueue: default used=<memory:12288, vCores:11> numContainers=11 user=ubuntu user-resources=<memory:12288, vCores:11>
2014-05-05 04:16:15,874 INFO org.apache.hadoop.yarn.server.resourcemanager.scheduler.capacity.LeafQueue: completedContainer container=Container: [ContainerId: container_1399261790270_0004_01_000004, NodeId: noded:54001, NodeHttpAddress: noded:8042, Resource: <memory:1024, vCores:1>, Priority: 20, Token: Token { kind: ContainerToken, service: 10.0.0.180:54001 }, ] resource=<memory:1024, vCores:1> queue=default: capacity=1.0, absoluteCapacity=1.0, usedResources=<memory:12288, vCores:11>usedCapacity=0.375, absoluteUsedCapacity=0.375, numApps=1, numContainers=11 usedCapacity=0.375 absoluteUsedCapacity=0.375 used=<memory:12288, vCores:11> cluster=<memory:32768, vCores:32>
2014-05-05 04:16:15,874 INFO org.apache.hadoop.yarn.server.resourcemanager.scheduler.capacity.ParentQueue: completedContainer queue=root usedCapacity=0.375 absoluteUsedCapacity=0.375 used=<memory:12288, vCores:11> cluster=<memory:32768, vCores:32>
2014-05-05 04:16:15,874 INFO org.apache.hadoop.yarn.server.resourcemanager.scheduler.capacity.ParentQueue: Re-sorting completed queue: root.default stats: default: capacity=1.0, absoluteCapacity=1.0, usedResources=<memory:12288, vCores:11>usedCapacity=0.375, absoluteUsedCapacity=0.375, numApps=1, numContainers=11
2014-05-05 04:16:15,874 INFO org.apache.hadoop.yarn.server.resourcemanager.scheduler.capacity.CapacityScheduler: Application appattempt_1399261790270_0004_000001 released container container_1399261790270_0004_01_000004 on node: host: noded:54001 #containers=4 available=4096 used=4096 with event: FINISHED
2014-05-05 04:16:18,744 INFO org.apache.hadoop.yarn.server.resourcemanager.rmcontainer.RMContainerImpl: container_1399261790270_0004_01_000003 Container Transitioned from RUNNING to COMPLETED
2014-05-05 04:16:18,744 INFO org.apache.hadoop.yarn.server.resourcemanager.scheduler.common.fica.FiCaSchedulerApp: Completed container: container_1399261790270_0004_01_000003 in state: COMPLETED event:FINISHED
2014-05-05 04:16:18,744 INFO org.apache.hadoop.yarn.server.resourcemanager.RMAuditLogger: USER=ubuntu	OPERATION=AM Released Container	TARGET=SchedulerApp	RESULT=SUCCESS	APPID=application_1399261790270_0004	CONTAINERID=container_1399261790270_0004_01_000003
2014-05-05 04:16:18,744 INFO org.apache.hadoop.yarn.server.resourcemanager.scheduler.common.fica.FiCaSchedulerNode: Released container container_1399261790270_0004_01_000003 of capacity <memory:1024, vCores:1> on host noded:54001, which currently has 3 containers, <memory:3072, vCores:3> used and <memory:5120, vCores:5> available, release resources=true
2014-05-05 04:16:18,744 INFO org.apache.hadoop.yarn.server.resourcemanager.scheduler.capacity.LeafQueue: default used=<memory:11264, vCores:10> numContainers=10 user=ubuntu user-resources=<memory:11264, vCores:10>
2014-05-05 04:16:18,744 INFO org.apache.hadoop.yarn.server.resourcemanager.scheduler.capacity.LeafQueue: completedContainer container=Container: [ContainerId: container_1399261790270_0004_01_000003, NodeId: noded:54001, NodeHttpAddress: noded:8042, Resource: <memory:1024, vCores:1>, Priority: 20, Token: Token { kind: ContainerToken, service: 10.0.0.180:54001 }, ] resource=<memory:1024, vCores:1> queue=default: capacity=1.0, absoluteCapacity=1.0, usedResources=<memory:11264, vCores:10>usedCapacity=0.34375, absoluteUsedCapacity=0.34375, numApps=1, numContainers=10 usedCapacity=0.34375 absoluteUsedCapacity=0.34375 used=<memory:11264, vCores:10> cluster=<memory:32768, vCores:32>
2014-05-05 04:16:18,744 INFO org.apache.hadoop.yarn.server.resourcemanager.scheduler.capacity.ParentQueue: completedContainer queue=root usedCapacity=0.34375 absoluteUsedCapacity=0.34375 used=<memory:11264, vCores:10> cluster=<memory:32768, vCores:32>
2014-05-05 04:16:18,745 INFO org.apache.hadoop.yarn.server.resourcemanager.scheduler.capacity.ParentQueue: Re-sorting completed queue: root.default stats: default: capacity=1.0, absoluteCapacity=1.0, usedResources=<memory:11264, vCores:10>usedCapacity=0.34375, absoluteUsedCapacity=0.34375, numApps=1, numContainers=10
2014-05-05 04:16:18,745 INFO org.apache.hadoop.yarn.server.resourcemanager.scheduler.capacity.CapacityScheduler: Application appattempt_1399261790270_0004_000001 released container container_1399261790270_0004_01_000003 on node: host: noded:54001 #containers=3 available=5120 used=3072 with event: FINISHED
2014-05-05 04:16:18,745 INFO org.apache.hadoop.yarn.server.resourcemanager.rmcontainer.RMContainerImpl: container_1399261790270_0004_01_000006 Container Transitioned from RUNNING to COMPLETED
2014-05-05 04:16:18,745 INFO org.apache.hadoop.yarn.server.resourcemanager.scheduler.common.fica.FiCaSchedulerApp: Completed container: container_1399261790270_0004_01_000006 in state: COMPLETED event:FINISHED
2014-05-05 04:16:18,745 INFO org.apache.hadoop.yarn.server.resourcemanager.RMAuditLogger: USER=ubuntu	OPERATION=AM Released Container	TARGET=SchedulerApp	RESULT=SUCCESS	APPID=application_1399261790270_0004	CONTAINERID=container_1399261790270_0004_01_000006
2014-05-05 04:16:18,745 INFO org.apache.hadoop.yarn.server.resourcemanager.scheduler.common.fica.FiCaSchedulerNode: Released container container_1399261790270_0004_01_000006 of capacity <memory:1024, vCores:1> on host noded:54001, which currently has 2 containers, <memory:2048, vCores:2> used and <memory:6144, vCores:6> available, release resources=true
2014-05-05 04:16:18,745 INFO org.apache.hadoop.yarn.server.resourcemanager.scheduler.capacity.LeafQueue: default used=<memory:10240, vCores:9> numContainers=9 user=ubuntu user-resources=<memory:10240, vCores:9>
2014-05-05 04:16:18,746 INFO org.apache.hadoop.yarn.server.resourcemanager.scheduler.capacity.LeafQueue: completedContainer container=Container: [ContainerId: container_1399261790270_0004_01_000006, NodeId: noded:54001, NodeHttpAddress: noded:8042, Resource: <memory:1024, vCores:1>, Priority: 20, Token: Token { kind: ContainerToken, service: 10.0.0.180:54001 }, ] resource=<memory:1024, vCores:1> queue=default: capacity=1.0, absoluteCapacity=1.0, usedResources=<memory:10240, vCores:9>usedCapacity=0.3125, absoluteUsedCapacity=0.3125, numApps=1, numContainers=9 usedCapacity=0.3125 absoluteUsedCapacity=0.3125 used=<memory:10240, vCores:9> cluster=<memory:32768, vCores:32>
2014-05-05 04:16:18,746 INFO org.apache.hadoop.yarn.server.resourcemanager.scheduler.capacity.ParentQueue: completedContainer queue=root usedCapacity=0.3125 absoluteUsedCapacity=0.3125 used=<memory:10240, vCores:9> cluster=<memory:32768, vCores:32>
2014-05-05 04:16:18,746 INFO org.apache.hadoop.yarn.server.resourcemanager.scheduler.capacity.ParentQueue: Re-sorting completed queue: root.default stats: default: capacity=1.0, absoluteCapacity=1.0, usedResources=<memory:10240, vCores:9>usedCapacity=0.3125, absoluteUsedCapacity=0.3125, numApps=1, numContainers=9
2014-05-05 04:16:18,746 INFO org.apache.hadoop.yarn.server.resourcemanager.scheduler.capacity.CapacityScheduler: Application appattempt_1399261790270_0004_000001 released container container_1399261790270_0004_01_000006 on node: host: noded:54001 #containers=2 available=6144 used=2048 with event: FINISHED
2014-05-05 04:16:55,971 INFO org.apache.hadoop.yarn.server.resourcemanager.rmcontainer.RMContainerImpl: container_1399261790270_0004_01_000011 Container Transitioned from RUNNING to COMPLETED
2014-05-05 04:16:55,971 INFO org.apache.hadoop.yarn.server.resourcemanager.scheduler.common.fica.FiCaSchedulerApp: Completed container: container_1399261790270_0004_01_000011 in state: COMPLETED event:FINISHED
2014-05-05 04:16:55,971 INFO org.apache.hadoop.yarn.server.resourcemanager.RMAuditLogger: USER=ubuntu	OPERATION=AM Released Container	TARGET=SchedulerApp	RESULT=SUCCESS	APPID=application_1399261790270_0004	CONTAINERID=container_1399261790270_0004_01_000011
2014-05-05 04:16:55,971 INFO org.apache.hadoop.yarn.server.resourcemanager.scheduler.common.fica.FiCaSchedulerNode: Released container container_1399261790270_0004_01_000011 of capacity <memory:1024, vCores:1> on host nodeb:41344, which currently has 1 containers, <memory:1024, vCores:1> used and <memory:7168, vCores:7> available, release resources=true
2014-05-05 04:16:55,971 INFO org.apache.hadoop.yarn.server.resourcemanager.scheduler.capacity.LeafQueue: default used=<memory:9216, vCores:8> numContainers=8 user=ubuntu user-resources=<memory:9216, vCores:8>
2014-05-05 04:16:55,971 INFO org.apache.hadoop.yarn.server.resourcemanager.scheduler.capacity.LeafQueue: completedContainer container=Container: [ContainerId: container_1399261790270_0004_01_000011, NodeId: nodeb:41344, NodeHttpAddress: nodeb:8042, Resource: <memory:1024, vCores:1>, Priority: 10, Token: Token { kind: ContainerToken, service: 10.0.0.59:41344 }, ] resource=<memory:1024, vCores:1> queue=default: capacity=1.0, absoluteCapacity=1.0, usedResources=<memory:9216, vCores:8>usedCapacity=0.28125, absoluteUsedCapacity=0.28125, numApps=1, numContainers=8 usedCapacity=0.28125 absoluteUsedCapacity=0.28125 used=<memory:9216, vCores:8> cluster=<memory:32768, vCores:32>
2014-05-05 04:16:55,972 INFO org.apache.hadoop.yarn.server.resourcemanager.scheduler.capacity.ParentQueue: completedContainer queue=root usedCapacity=0.28125 absoluteUsedCapacity=0.28125 used=<memory:9216, vCores:8> cluster=<memory:32768, vCores:32>
2014-05-05 04:16:55,972 INFO org.apache.hadoop.yarn.server.resourcemanager.scheduler.capacity.ParentQueue: Re-sorting completed queue: root.default stats: default: capacity=1.0, absoluteCapacity=1.0, usedResources=<memory:9216, vCores:8>usedCapacity=0.28125, absoluteUsedCapacity=0.28125, numApps=1, numContainers=8
2014-05-05 04:16:55,972 INFO org.apache.hadoop.yarn.server.resourcemanager.scheduler.capacity.CapacityScheduler: Application appattempt_1399261790270_0004_000001 released container container_1399261790270_0004_01_000011 on node: host: nodeb:41344 #containers=1 available=7168 used=1024 with event: FINISHED
2014-05-05 04:16:56,005 INFO org.apache.hadoop.yarn.server.resourcemanager.rmcontainer.RMContainerImpl: container_1399261790270_0004_01_000010 Container Transitioned from RUNNING to COMPLETED
2014-05-05 04:16:56,006 INFO org.apache.hadoop.yarn.server.resourcemanager.scheduler.common.fica.FiCaSchedulerApp: Completed container: container_1399261790270_0004_01_000010 in state: COMPLETED event:FINISHED
2014-05-05 04:16:56,006 INFO org.apache.hadoop.yarn.server.resourcemanager.RMAuditLogger: USER=ubuntu	OPERATION=AM Released Container	TARGET=SchedulerApp	RESULT=SUCCESS	APPID=application_1399261790270_0004	CONTAINERID=container_1399261790270_0004_01_000010
2014-05-05 04:16:56,006 INFO org.apache.hadoop.yarn.server.resourcemanager.scheduler.common.fica.FiCaSchedulerNode: Released container container_1399261790270_0004_01_000010 of capacity <memory:1024, vCores:1> on host nodec:51351, which currently has 2 containers, <memory:3072, vCores:2> used and <memory:5120, vCores:6> available, release resources=true
2014-05-05 04:16:56,006 INFO org.apache.hadoop.yarn.server.resourcemanager.scheduler.capacity.LeafQueue: default used=<memory:8192, vCores:7> numContainers=7 user=ubuntu user-resources=<memory:8192, vCores:7>
2014-05-05 04:16:56,006 INFO org.apache.hadoop.yarn.server.resourcemanager.scheduler.capacity.LeafQueue: completedContainer container=Container: [ContainerId: container_1399261790270_0004_01_000010, NodeId: nodec:51351, NodeHttpAddress: nodec:8042, Resource: <memory:1024, vCores:1>, Priority: 10, Token: Token { kind: ContainerToken, service: 10.0.0.181:51351 }, ] resource=<memory:1024, vCores:1> queue=default: capacity=1.0, absoluteCapacity=1.0, usedResources=<memory:8192, vCores:7>usedCapacity=0.25, absoluteUsedCapacity=0.25, numApps=1, numContainers=7 usedCapacity=0.25 absoluteUsedCapacity=0.25 used=<memory:8192, vCores:7> cluster=<memory:32768, vCores:32>
2014-05-05 04:16:56,006 INFO org.apache.hadoop.yarn.server.resourcemanager.scheduler.capacity.ParentQueue: completedContainer queue=root usedCapacity=0.25 absoluteUsedCapacity=0.25 used=<memory:8192, vCores:7> cluster=<memory:32768, vCores:32>
2014-05-05 04:16:56,006 INFO org.apache.hadoop.yarn.server.resourcemanager.scheduler.capacity.ParentQueue: Re-sorting completed queue: root.default stats: default: capacity=1.0, absoluteCapacity=1.0, usedResources=<memory:8192, vCores:7>usedCapacity=0.25, absoluteUsedCapacity=0.25, numApps=1, numContainers=7
2014-05-05 04:16:56,006 INFO org.apache.hadoop.yarn.server.resourcemanager.scheduler.capacity.CapacityScheduler: Application appattempt_1399261790270_0004_000001 released container container_1399261790270_0004_01_000010 on node: host: nodec:51351 #containers=2 available=5120 used=3072 with event: FINISHED
2014-05-05 04:16:56,872 INFO org.apache.hadoop.yarn.server.resourcemanager.rmcontainer.RMContainerImpl: container_1399261790270_0004_01_000013 Container Transitioned from RUNNING to COMPLETED
2014-05-05 04:16:56,872 INFO org.apache.hadoop.yarn.server.resourcemanager.scheduler.common.fica.FiCaSchedulerApp: Completed container: container_1399261790270_0004_01_000013 in state: COMPLETED event:FINISHED
2014-05-05 04:16:56,872 INFO org.apache.hadoop.yarn.server.resourcemanager.RMAuditLogger: USER=ubuntu	OPERATION=AM Released Container	TARGET=SchedulerApp	RESULT=SUCCESS	APPID=application_1399261790270_0004	CONTAINERID=container_1399261790270_0004_01_000013
2014-05-05 04:16:56,873 INFO org.apache.hadoop.yarn.server.resourcemanager.scheduler.common.fica.FiCaSchedulerNode: Released container container_1399261790270_0004_01_000013 of capacity <memory:1024, vCores:1> on host nodea:49324, which currently has 1 containers, <memory:1024, vCores:1> used and <memory:7168, vCores:7> available, release resources=true
2014-05-05 04:16:56,873 INFO org.apache.hadoop.yarn.server.resourcemanager.scheduler.capacity.LeafQueue: default used=<memory:7168, vCores:6> numContainers=6 user=ubuntu user-resources=<memory:7168, vCores:6>
2014-05-05 04:16:56,873 INFO org.apache.hadoop.yarn.server.resourcemanager.scheduler.capacity.LeafQueue: completedContainer container=Container: [ContainerId: container_1399261790270_0004_01_000013, NodeId: nodea:49324, NodeHttpAddress: nodea:8042, Resource: <memory:1024, vCores:1>, Priority: 10, Token: Token { kind: ContainerToken, service: 10.0.0.158:49324 }, ] resource=<memory:1024, vCores:1> queue=default: capacity=1.0, absoluteCapacity=1.0, usedResources=<memory:7168, vCores:6>usedCapacity=0.21875, absoluteUsedCapacity=0.21875, numApps=1, numContainers=6 usedCapacity=0.21875 absoluteUsedCapacity=0.21875 used=<memory:7168, vCores:6> cluster=<memory:32768, vCores:32>
2014-05-05 04:16:56,873 INFO org.apache.hadoop.yarn.server.resourcemanager.scheduler.capacity.ParentQueue: completedContainer queue=root usedCapacity=0.21875 absoluteUsedCapacity=0.21875 used=<memory:7168, vCores:6> cluster=<memory:32768, vCores:32>
2014-05-05 04:16:56,873 INFO org.apache.hadoop.yarn.server.resourcemanager.scheduler.capacity.ParentQueue: Re-sorting completed queue: root.default stats: default: capacity=1.0, absoluteCapacity=1.0, usedResources=<memory:7168, vCores:6>usedCapacity=0.21875, absoluteUsedCapacity=0.21875, numApps=1, numContainers=6
2014-05-05 04:16:56,873 INFO org.apache.hadoop.yarn.server.resourcemanager.scheduler.capacity.CapacityScheduler: Application appattempt_1399261790270_0004_000001 released container container_1399261790270_0004_01_000013 on node: host: nodea:49324 #containers=1 available=7168 used=1024 with event: FINISHED
2014-05-05 04:16:56,873 INFO org.apache.hadoop.yarn.server.resourcemanager.rmcontainer.RMContainerImpl: container_1399261790270_0004_01_000014 Container Transitioned from RUNNING to COMPLETED
2014-05-05 04:16:56,873 INFO org.apache.hadoop.yarn.server.resourcemanager.scheduler.common.fica.FiCaSchedulerApp: Completed container: container_1399261790270_0004_01_000014 in state: COMPLETED event:FINISHED
2014-05-05 04:16:56,873 INFO org.apache.hadoop.yarn.server.resourcemanager.RMAuditLogger: USER=ubuntu	OPERATION=AM Released Container	TARGET=SchedulerApp	RESULT=SUCCESS	APPID=application_1399261790270_0004	CONTAINERID=container_1399261790270_0004_01_000014
2014-05-05 04:16:56,873 INFO org.apache.hadoop.yarn.server.resourcemanager.scheduler.common.fica.FiCaSchedulerNode: Released container container_1399261790270_0004_01_000014 of capacity <memory:1024, vCores:1> on host nodea:49324, which currently has 0 containers, <memory:0, vCores:0> used and <memory:8192, vCores:8> available, release resources=true
2014-05-05 04:16:56,873 INFO org.apache.hadoop.yarn.server.resourcemanager.scheduler.capacity.LeafQueue: default used=<memory:6144, vCores:5> numContainers=5 user=ubuntu user-resources=<memory:6144, vCores:5>
2014-05-05 04:16:56,874 INFO org.apache.hadoop.yarn.server.resourcemanager.scheduler.capacity.LeafQueue: completedContainer container=Container: [ContainerId: container_1399261790270_0004_01_000014, NodeId: nodea:49324, NodeHttpAddress: nodea:8042, Resource: <memory:1024, vCores:1>, Priority: 10, Token: Token { kind: ContainerToken, service: 10.0.0.158:49324 }, ] resource=<memory:1024, vCores:1> queue=default: capacity=1.0, absoluteCapacity=1.0, usedResources=<memory:6144, vCores:5>usedCapacity=0.1875, absoluteUsedCapacity=0.1875, numApps=1, numContainers=5 usedCapacity=0.1875 absoluteUsedCapacity=0.1875 used=<memory:6144, vCores:5> cluster=<memory:32768, vCores:32>
2014-05-05 04:16:56,874 INFO org.apache.hadoop.yarn.server.resourcemanager.scheduler.capacity.ParentQueue: completedContainer queue=root usedCapacity=0.1875 absoluteUsedCapacity=0.1875 used=<memory:6144, vCores:5> cluster=<memory:32768, vCores:32>
2014-05-05 04:16:56,874 INFO org.apache.hadoop.yarn.server.resourcemanager.scheduler.capacity.ParentQueue: Re-sorting completed queue: root.default stats: default: capacity=1.0, absoluteCapacity=1.0, usedResources=<memory:6144, vCores:5>usedCapacity=0.1875, absoluteUsedCapacity=0.1875, numApps=1, numContainers=5
2014-05-05 04:16:56,874 INFO org.apache.hadoop.yarn.server.resourcemanager.scheduler.capacity.CapacityScheduler: Application appattempt_1399261790270_0004_000001 released container container_1399261790270_0004_01_000014 on node: host: nodea:49324 #containers=0 available=8192 used=0 with event: FINISHED
2014-05-05 04:16:56,874 INFO org.apache.hadoop.yarn.server.resourcemanager.rmcontainer.RMContainerImpl: container_1399261790270_0004_01_000007 Container Transitioned from RUNNING to COMPLETED
2014-05-05 04:16:56,874 INFO org.apache.hadoop.yarn.server.resourcemanager.scheduler.common.fica.FiCaSchedulerApp: Completed container: container_1399261790270_0004_01_000007 in state: COMPLETED event:FINISHED
2014-05-05 04:16:56,874 INFO org.apache.hadoop.yarn.server.resourcemanager.RMAuditLogger: USER=ubuntu	OPERATION=AM Released Container	TARGET=SchedulerApp	RESULT=SUCCESS	APPID=application_1399261790270_0004	CONTAINERID=container_1399261790270_0004_01_000007
2014-05-05 04:16:56,874 INFO org.apache.hadoop.yarn.server.resourcemanager.scheduler.common.fica.FiCaSchedulerNode: Released container container_1399261790270_0004_01_000007 of capacity <memory:1024, vCores:1> on host noded:54001, which currently has 1 containers, <memory:1024, vCores:1> used and <memory:7168, vCores:7> available, release resources=true
2014-05-05 04:16:56,874 INFO org.apache.hadoop.yarn.server.resourcemanager.scheduler.capacity.LeafQueue: default used=<memory:5120, vCores:4> numContainers=4 user=ubuntu user-resources=<memory:5120, vCores:4>
2014-05-05 04:16:56,874 INFO org.apache.hadoop.yarn.server.resourcemanager.scheduler.capacity.LeafQueue: completedContainer container=Container: [ContainerId: container_1399261790270_0004_01_000007, NodeId: noded:54001, NodeHttpAddress: noded:8042, Resource: <memory:1024, vCores:1>, Priority: 10, Token: Token { kind: ContainerToken, service: 10.0.0.180:54001 }, ] resource=<memory:1024, vCores:1> queue=default: capacity=1.0, absoluteCapacity=1.0, usedResources=<memory:5120, vCores:4>usedCapacity=0.15625, absoluteUsedCapacity=0.15625, numApps=1, numContainers=4 usedCapacity=0.15625 absoluteUsedCapacity=0.15625 used=<memory:5120, vCores:4> cluster=<memory:32768, vCores:32>
2014-05-05 04:16:56,875 INFO org.apache.hadoop.yarn.server.resourcemanager.scheduler.capacity.ParentQueue: completedContainer queue=root usedCapacity=0.15625 absoluteUsedCapacity=0.15625 used=<memory:5120, vCores:4> cluster=<memory:32768, vCores:32>
2014-05-05 04:16:56,875 INFO org.apache.hadoop.yarn.server.resourcemanager.scheduler.capacity.ParentQueue: Re-sorting completed queue: root.default stats: default: capacity=1.0, absoluteCapacity=1.0, usedResources=<memory:5120, vCores:4>usedCapacity=0.15625, absoluteUsedCapacity=0.15625, numApps=1, numContainers=4
2014-05-05 04:16:56,875 INFO org.apache.hadoop.yarn.server.resourcemanager.scheduler.capacity.CapacityScheduler: Application appattempt_1399261790270_0004_000001 released container container_1399261790270_0004_01_000007 on node: host: noded:54001 #containers=1 available=7168 used=1024 with event: FINISHED
2014-05-05 04:16:56,875 INFO org.apache.hadoop.yarn.server.resourcemanager.rmcontainer.RMContainerImpl: container_1399261790270_0004_01_000008 Container Transitioned from RUNNING to COMPLETED
2014-05-05 04:16:56,875 INFO org.apache.hadoop.yarn.server.resourcemanager.scheduler.common.fica.FiCaSchedulerApp: Completed container: container_1399261790270_0004_01_000008 in state: COMPLETED event:FINISHED
2014-05-05 04:16:56,875 INFO org.apache.hadoop.yarn.server.resourcemanager.RMAuditLogger: USER=ubuntu	OPERATION=AM Released Container	TARGET=SchedulerApp	RESULT=SUCCESS	APPID=application_1399261790270_0004	CONTAINERID=container_1399261790270_0004_01_000008
2014-05-05 04:16:56,875 INFO org.apache.hadoop.yarn.server.resourcemanager.scheduler.common.fica.FiCaSchedulerNode: Released container container_1399261790270_0004_01_000008 of capacity <memory:1024, vCores:1> on host noded:54001, which currently has 0 containers, <memory:0, vCores:0> used and <memory:8192, vCores:8> available, release resources=true
2014-05-05 04:16:56,875 INFO org.apache.hadoop.yarn.server.resourcemanager.scheduler.capacity.LeafQueue: default used=<memory:4096, vCores:3> numContainers=3 user=ubuntu user-resources=<memory:4096, vCores:3>
2014-05-05 04:16:56,875 INFO org.apache.hadoop.yarn.server.resourcemanager.scheduler.capacity.LeafQueue: completedContainer container=Container: [ContainerId: container_1399261790270_0004_01_000008, NodeId: noded:54001, NodeHttpAddress: noded:8042, Resource: <memory:1024, vCores:1>, Priority: 10, Token: Token { kind: ContainerToken, service: 10.0.0.180:54001 }, ] resource=<memory:1024, vCores:1> queue=default: capacity=1.0, absoluteCapacity=1.0, usedResources=<memory:4096, vCores:3>usedCapacity=0.125, absoluteUsedCapacity=0.125, numApps=1, numContainers=3 usedCapacity=0.125 absoluteUsedCapacity=0.125 used=<memory:4096, vCores:3> cluster=<memory:32768, vCores:32>
2014-05-05 04:16:56,875 INFO org.apache.hadoop.yarn.server.resourcemanager.scheduler.capacity.ParentQueue: completedContainer queue=root usedCapacity=0.125 absoluteUsedCapacity=0.125 used=<memory:4096, vCores:3> cluster=<memory:32768, vCores:32>
2014-05-05 04:16:56,875 INFO org.apache.hadoop.yarn.server.resourcemanager.scheduler.capacity.ParentQueue: Re-sorting completed queue: root.default stats: default: capacity=1.0, absoluteCapacity=1.0, usedResources=<memory:4096, vCores:3>usedCapacity=0.125, absoluteUsedCapacity=0.125, numApps=1, numContainers=3
2014-05-05 04:16:56,875 INFO org.apache.hadoop.yarn.server.resourcemanager.scheduler.capacity.CapacityScheduler: Application appattempt_1399261790270_0004_000001 released container container_1399261790270_0004_01_000008 on node: host: noded:54001 #containers=0 available=8192 used=0 with event: FINISHED
2014-05-05 04:16:56,973 INFO org.apache.hadoop.yarn.server.resourcemanager.rmcontainer.RMContainerImpl: container_1399261790270_0004_01_000012 Container Transitioned from RUNNING to COMPLETED
2014-05-05 04:16:56,973 INFO org.apache.hadoop.yarn.server.resourcemanager.scheduler.common.fica.FiCaSchedulerApp: Completed container: container_1399261790270_0004_01_000012 in state: COMPLETED event:FINISHED
2014-05-05 04:16:56,973 INFO org.apache.hadoop.yarn.server.resourcemanager.RMAuditLogger: USER=ubuntu	OPERATION=AM Released Container	TARGET=SchedulerApp	RESULT=SUCCESS	APPID=application_1399261790270_0004	CONTAINERID=container_1399261790270_0004_01_000012
2014-05-05 04:16:56,973 INFO org.apache.hadoop.yarn.server.resourcemanager.scheduler.common.fica.FiCaSchedulerNode: Released container container_1399261790270_0004_01_000012 of capacity <memory:1024, vCores:1> on host nodeb:41344, which currently has 0 containers, <memory:0, vCores:0> used and <memory:8192, vCores:8> available, release resources=true
2014-05-05 04:16:56,973 INFO org.apache.hadoop.yarn.server.resourcemanager.scheduler.capacity.LeafQueue: default used=<memory:3072, vCores:2> numContainers=2 user=ubuntu user-resources=<memory:3072, vCores:2>
2014-05-05 04:16:56,973 INFO org.apache.hadoop.yarn.server.resourcemanager.scheduler.capacity.LeafQueue: completedContainer container=Container: [ContainerId: container_1399261790270_0004_01_000012, NodeId: nodeb:41344, NodeHttpAddress: nodeb:8042, Resource: <memory:1024, vCores:1>, Priority: 10, Token: Token { kind: ContainerToken, service: 10.0.0.59:41344 }, ] resource=<memory:1024, vCores:1> queue=default: capacity=1.0, absoluteCapacity=1.0, usedResources=<memory:3072, vCores:2>usedCapacity=0.09375, absoluteUsedCapacity=0.09375, numApps=1, numContainers=2 usedCapacity=0.09375 absoluteUsedCapacity=0.09375 used=<memory:3072, vCores:2> cluster=<memory:32768, vCores:32>
2014-05-05 04:16:56,973 INFO org.apache.hadoop.yarn.server.resourcemanager.scheduler.capacity.ParentQueue: completedContainer queue=root usedCapacity=0.09375 absoluteUsedCapacity=0.09375 used=<memory:3072, vCores:2> cluster=<memory:32768, vCores:32>
2014-05-05 04:16:56,973 INFO org.apache.hadoop.yarn.server.resourcemanager.scheduler.capacity.ParentQueue: Re-sorting completed queue: root.default stats: default: capacity=1.0, absoluteCapacity=1.0, usedResources=<memory:3072, vCores:2>usedCapacity=0.09375, absoluteUsedCapacity=0.09375, numApps=1, numContainers=2
2014-05-05 04:16:56,974 INFO org.apache.hadoop.yarn.server.resourcemanager.scheduler.capacity.CapacityScheduler: Application appattempt_1399261790270_0004_000001 released container container_1399261790270_0004_01_000012 on node: host: nodeb:41344 #containers=0 available=8192 used=0 with event: FINISHED
2014-05-05 04:16:57,008 INFO org.apache.hadoop.yarn.server.resourcemanager.rmcontainer.RMContainerImpl: container_1399261790270_0004_01_000009 Container Transitioned from RUNNING to COMPLETED
2014-05-05 04:16:57,008 INFO org.apache.hadoop.yarn.server.resourcemanager.scheduler.common.fica.FiCaSchedulerApp: Completed container: container_1399261790270_0004_01_000009 in state: COMPLETED event:FINISHED
2014-05-05 04:16:57,008 INFO org.apache.hadoop.yarn.server.resourcemanager.RMAuditLogger: USER=ubuntu	OPERATION=AM Released Container	TARGET=SchedulerApp	RESULT=SUCCESS	APPID=application_1399261790270_0004	CONTAINERID=container_1399261790270_0004_01_000009
2014-05-05 04:16:57,008 INFO org.apache.hadoop.yarn.server.resourcemanager.scheduler.common.fica.FiCaSchedulerNode: Released container container_1399261790270_0004_01_000009 of capacity <memory:1024, vCores:1> on host nodec:51351, which currently has 1 containers, <memory:2048, vCores:1> used and <memory:6144, vCores:7> available, release resources=true
2014-05-05 04:16:57,008 INFO org.apache.hadoop.yarn.server.resourcemanager.scheduler.capacity.LeafQueue: default used=<memory:2048, vCores:1> numContainers=1 user=ubuntu user-resources=<memory:2048, vCores:1>
2014-05-05 04:16:57,009 INFO org.apache.hadoop.yarn.server.resourcemanager.scheduler.capacity.LeafQueue: completedContainer container=Container: [ContainerId: container_1399261790270_0004_01_000009, NodeId: nodec:51351, NodeHttpAddress: nodec:8042, Resource: <memory:1024, vCores:1>, Priority: 10, Token: Token { kind: ContainerToken, service: 10.0.0.181:51351 }, ] resource=<memory:1024, vCores:1> queue=default: capacity=1.0, absoluteCapacity=1.0, usedResources=<memory:2048, vCores:1>usedCapacity=0.0625, absoluteUsedCapacity=0.0625, numApps=1, numContainers=1 usedCapacity=0.0625 absoluteUsedCapacity=0.0625 used=<memory:2048, vCores:1> cluster=<memory:32768, vCores:32>
2014-05-05 04:16:57,009 INFO org.apache.hadoop.yarn.server.resourcemanager.scheduler.capacity.ParentQueue: completedContainer queue=root usedCapacity=0.0625 absoluteUsedCapacity=0.0625 used=<memory:2048, vCores:1> cluster=<memory:32768, vCores:32>
2014-05-05 04:16:57,009 INFO org.apache.hadoop.yarn.server.resourcemanager.scheduler.capacity.ParentQueue: Re-sorting completed queue: root.default stats: default: capacity=1.0, absoluteCapacity=1.0, usedResources=<memory:2048, vCores:1>usedCapacity=0.0625, absoluteUsedCapacity=0.0625, numApps=1, numContainers=1
2014-05-05 04:16:57,009 INFO org.apache.hadoop.yarn.server.resourcemanager.scheduler.capacity.CapacityScheduler: Application appattempt_1399261790270_0004_000001 released container container_1399261790270_0004_01_000009 on node: host: nodec:51351 #containers=1 available=6144 used=2048 with event: FINISHED
2014-05-05 04:18:07,612 ERROR org.apache.hadoop.yarn.server.resourcemanager.ResourceManager: RECEIVED SIGNAL 15: SIGTERM
2014-05-05 04:18:07,617 INFO org.mortbay.log: Stopped SelectChannelConnector@ec2-54-186-230-200.us-west-2.compute.amazonaws.com:8088
2014-05-05 04:18:07,720 ERROR org.apache.hadoop.security.token.delegation.AbstractDelegationTokenSecretManager: InterruptedExcpetion recieved for ExpiredTokenRemover thread java.lang.InterruptedException: sleep interrupted
2014-05-05 04:18:07,721 INFO org.apache.hadoop.metrics2.impl.MetricsSystemImpl: Stopping ResourceManager metrics system...
2014-05-05 04:18:07,723 INFO org.apache.hadoop.metrics2.impl.MetricsSystemImpl: ResourceManager metrics system stopped.
2014-05-05 04:18:07,723 INFO org.apache.hadoop.metrics2.impl.MetricsSystemImpl: ResourceManager metrics system shutdown complete.
2014-05-05 04:18:07,723 WARN org.apache.hadoop.yarn.server.resourcemanager.amlauncher.ApplicationMasterLauncher: org.apache.hadoop.yarn.server.resourcemanager.amlauncher.ApplicationMasterLauncher$LauncherThread interrupted. Returning.
2014-05-05 04:18:07,724 INFO org.apache.hadoop.ipc.Server: Stopping server on 8033
2014-05-05 04:18:07,726 INFO org.apache.hadoop.ipc.Server: Stopping IPC Server listener on 8033
2014-05-05 04:18:07,727 INFO org.apache.hadoop.ipc.Server: Stopping IPC Server Responder
2014-05-05 04:18:07,727 INFO org.apache.hadoop.ipc.Server: Stopping server on 8032
2014-05-05 04:18:07,734 INFO org.apache.hadoop.ipc.Server: Stopping IPC Server listener on 8032
2014-05-05 04:18:07,740 INFO org.apache.hadoop.ipc.Server: Stopping IPC Server Responder
2014-05-05 04:18:07,740 INFO org.apache.hadoop.ipc.Server: Stopping server on 8030
2014-05-05 04:18:07,746 INFO org.apache.hadoop.ipc.Server: Stopping IPC Server listener on 8030
2014-05-05 04:18:07,748 INFO org.apache.hadoop.ipc.Server: Stopping server on 8031
2014-05-05 04:18:07,748 INFO org.apache.hadoop.ipc.Server: Stopping IPC Server Responder
2014-05-05 04:18:07,754 INFO org.apache.hadoop.ipc.Server: Stopping IPC Server listener on 8031
2014-05-05 04:18:07,756 ERROR org.apache.hadoop.yarn.server.resourcemanager.ResourceManager: Returning, interrupted : java.lang.InterruptedException
2014-05-05 04:18:07,756 INFO org.apache.hadoop.yarn.util.AbstractLivelinessMonitor: NMLivelinessMonitor thread interrupted
2014-05-05 04:18:07,756 INFO org.apache.hadoop.ipc.Server: Stopping IPC Server Responder
2014-05-05 04:18:07,756 INFO org.apache.hadoop.yarn.util.AbstractLivelinessMonitor: org.apache.hadoop.yarn.server.resourcemanager.rmcontainer.ContainerAllocationExpirer thread interrupted
2014-05-05 04:18:07,756 INFO org.apache.hadoop.yarn.util.AbstractLivelinessMonitor: AMLivelinessMonitor thread interrupted
2014-05-05 04:18:07,757 INFO org.apache.hadoop.yarn.util.AbstractLivelinessMonitor: AMLivelinessMonitor thread interrupted
2014-05-05 04:18:07,757 INFO org.apache.hadoop.yarn.server.resourcemanager.ResourceManager: SHUTDOWN_MSG: 
/************************************************************
SHUTDOWN_MSG: Shutting down ResourceManager at ip-10-0-0-158/10.0.0.158
************************************************************/
2014-05-05 04:18:38,679 INFO org.apache.hadoop.yarn.server.resourcemanager.ResourceManager: STARTUP_MSG: 
/************************************************************
STARTUP_MSG: Starting ResourceManager
STARTUP_MSG:   host = ip-10-0-0-158/10.0.0.158
STARTUP_MSG:   args = []
STARTUP_MSG:   version = 2.2.0
STARTUP_MSG:   build = Unknown -r Unknown; compiled by 'root' on 2014-05-04T05:58Z
STARTUP_MSG:   java = 1.7.0_51
************************************************************/
2014-05-05 04:18:38,687 INFO org.apache.hadoop.yarn.server.resourcemanager.ResourceManager: registered UNIX signal handlers for [TERM, HUP, INT]
2014-05-05 04:18:39,016 INFO org.apache.hadoop.yarn.server.resourcemanager.security.AMRMTokenSecretManager: Rolling master-key for amrm-tokens
2014-05-05 04:18:39,031 INFO org.apache.hadoop.yarn.server.resourcemanager.security.RMContainerTokenSecretManager: ContainerTokenKeyRollingInterval: 86400000ms and ContainerTokenKeyActivationDelay: 900000ms
2014-05-05 04:18:39,036 INFO org.apache.hadoop.yarn.server.resourcemanager.security.NMTokenSecretManagerInRM: NMTokenKeyRollingInterval: 86400000ms and NMTokenKeyActivationDelay: 900000ms
2014-05-05 04:18:39,044 INFO org.apache.hadoop.yarn.event.AsyncDispatcher: Registering class org.apache.hadoop.yarn.server.resourcemanager.recovery.RMStateStoreEventType for class org.apache.hadoop.yarn.server.resourcemanager.recovery.RMStateStore$ForwardingEventHandler
2014-05-05 04:18:39,415 WARN org.apache.hadoop.util.NativeCodeLoader: Unable to load native-hadoop library for your platform... using builtin-java classes where applicable
2014-05-05 04:18:39,655 INFO org.apache.hadoop.yarn.event.AsyncDispatcher: Registering class org.apache.hadoop.yarn.server.resourcemanager.NodesListManagerEventType for class org.apache.hadoop.yarn.server.resourcemanager.NodesListManager
2014-05-05 04:18:39,778 INFO org.apache.hadoop.yarn.server.resourcemanager.ResourceManager: Using Scheduler: org.apache.hadoop.yarn.server.resourcemanager.scheduler.capacity.CapacityScheduler
2014-05-05 04:18:40,108 INFO org.apache.hadoop.yarn.event.AsyncDispatcher: Registering class org.apache.hadoop.yarn.server.resourcemanager.scheduler.event.SchedulerEventType for class org.apache.hadoop.yarn.server.resourcemanager.ResourceManager$SchedulerEventDispatcher
2014-05-05 04:18:40,110 INFO org.apache.hadoop.yarn.event.AsyncDispatcher: Registering class org.apache.hadoop.yarn.server.resourcemanager.rmapp.RMAppEventType for class org.apache.hadoop.yarn.server.resourcemanager.ResourceManager$ApplicationEventDispatcher
2014-05-05 04:18:40,118 INFO org.apache.hadoop.yarn.event.AsyncDispatcher: Registering class org.apache.hadoop.yarn.server.resourcemanager.rmapp.attempt.RMAppAttemptEventType for class org.apache.hadoop.yarn.server.resourcemanager.ResourceManager$ApplicationAttemptEventDispatcher
2014-05-05 04:18:40,119 INFO org.apache.hadoop.yarn.event.AsyncDispatcher: Registering class org.apache.hadoop.yarn.server.resourcemanager.rmnode.RMNodeEventType for class org.apache.hadoop.yarn.server.resourcemanager.ResourceManager$NodeEventDispatcher
2014-05-05 04:18:40,443 INFO org.apache.hadoop.metrics2.impl.MetricsConfig: loaded properties from hadoop-metrics2.properties
2014-05-05 04:18:40,562 INFO org.apache.hadoop.metrics2.impl.MetricsSystemImpl: Scheduled snapshot period at 10 second(s).
2014-05-05 04:18:40,562 INFO org.apache.hadoop.metrics2.impl.MetricsSystemImpl: ResourceManager metrics system started
2014-05-05 04:18:40,793 INFO org.apache.hadoop.yarn.server.resourcemanager.scheduler.capacity.ParentQueue: root, capacity=1.0, asboluteCapacity=1.0, maxCapacity=1.0, asboluteMaxCapacity=1.0, state=RUNNING, acls=ADMINISTER_QUEUE:*SUBMIT_APPLICATIONS:*
2014-05-05 04:18:40,793 INFO org.apache.hadoop.yarn.server.resourcemanager.scheduler.capacity.ParentQueue: Initialized parent-queue root name=root, fullname=root
2014-05-05 04:18:40,836 INFO org.apache.hadoop.yarn.server.resourcemanager.scheduler.capacity.LeafQueue: Initializing default
capacity = 1.0 [= (float) configuredCapacity / 100 ]
asboluteCapacity = 1.0 [= parentAbsoluteCapacity * capacity ]
maxCapacity = 1.0 [= configuredMaxCapacity ]
absoluteMaxCapacity = 1.0 [= 1.0 maximumCapacity undefined, (parentAbsoluteMaxCapacity * maximumCapacity) / 100 otherwise ]
userLimit = 100 [= configuredUserLimit ]
userLimitFactor = 1.0 [= configuredUserLimitFactor ]
maxApplications = 10000 [= configuredMaximumSystemApplicationsPerQueue or (int)(configuredMaximumSystemApplications * absoluteCapacity)]
maxApplicationsPerUser = 10000 [= (int)(maxApplications * (userLimit / 100.0f) * userLimitFactor) ]
maxActiveApplications = 1 [= max((int)ceil((clusterResourceMemory / minimumAllocation) * maxAMResourcePerQueuePercent * absoluteMaxCapacity),1) ]
maxActiveAppsUsingAbsCap = 1 [= max((int)ceil((clusterResourceMemory / minimumAllocation) *maxAMResourcePercent * absoluteCapacity),1) ]
maxActiveApplicationsPerUser = 1 [= max((int)(maxActiveApplications * (userLimit / 100.0f) * userLimitFactor),1) ]
usedCapacity = 0.0 [= usedResourcesMemory / (clusterResourceMemory * absoluteCapacity)]
absoluteUsedCapacity = 0.0 [= usedResourcesMemory / clusterResourceMemory]
maxAMResourcePerQueuePercent = 0.1 [= configuredMaximumAMResourcePercent ]
minimumAllocationFactor = 0.875 [= (float)(maximumAllocationMemory - minimumAllocationMemory) / maximumAllocationMemory ]
numContainers = 0 [= currentNumContainers ]
state = RUNNING [= configuredState ]
acls = ADMINISTER_QUEUE:*SUBMIT_APPLICATIONS:* [= configuredAcls ]
nodeLocalityDelay = 0

2014-05-05 04:18:40,836 INFO org.apache.hadoop.yarn.server.resourcemanager.scheduler.capacity.CapacityScheduler: Initialized queue: default: capacity=1.0, absoluteCapacity=1.0, usedResources=<memory:0, vCores:0>usedCapacity=0.0, absoluteUsedCapacity=0.0, numApps=0, numContainers=0
2014-05-05 04:18:40,837 INFO org.apache.hadoop.yarn.server.resourcemanager.scheduler.capacity.CapacityScheduler: Initialized queue: root: numChildQueue= 1, capacity=1.0, absoluteCapacity=1.0, usedResources=<memory:0, vCores:0>usedCapacity=0.0, numApps=0, numContainers=0
2014-05-05 04:18:40,837 INFO org.apache.hadoop.yarn.server.resourcemanager.scheduler.capacity.CapacityScheduler: Initialized root queue root: numChildQueue= 1, capacity=1.0, absoluteCapacity=1.0, usedResources=<memory:0, vCores:0>usedCapacity=0.0, numApps=0, numContainers=0
2014-05-05 04:18:40,837 INFO org.apache.hadoop.yarn.server.resourcemanager.scheduler.capacity.CapacityScheduler: Initialized CapacityScheduler with calculator=class org.apache.hadoop.yarn.util.resource.DefaultResourceCalculator, minimumAllocation=<<memory:1024, vCores:1>>, maximumAllocation=<<memory:8192, vCores:32>>
2014-05-05 04:18:41,035 INFO org.apache.hadoop.yarn.event.AsyncDispatcher: Registering class org.apache.hadoop.yarn.server.resourcemanager.RMAppManagerEventType for class org.apache.hadoop.yarn.server.resourcemanager.RMAppManager
2014-05-05 04:18:41,074 INFO org.apache.hadoop.yarn.event.AsyncDispatcher: Registering class org.apache.hadoop.yarn.server.resourcemanager.amlauncher.AMLauncherEventType for class org.apache.hadoop.yarn.server.resourcemanager.amlauncher.ApplicationMasterLauncher
2014-05-05 04:18:41,077 INFO org.apache.hadoop.yarn.server.resourcemanager.RMNMInfo: Registered RMNMInfo MBean
2014-05-05 04:18:41,078 INFO org.apache.hadoop.util.HostsFileReader: Refreshing hosts (include/exclude) list
2014-05-05 04:18:41,086 INFO org.apache.hadoop.yarn.server.resourcemanager.security.AMRMTokenSecretManager: Rolling master-key for amrm-tokens
2014-05-05 04:18:41,086 INFO org.apache.hadoop.yarn.server.resourcemanager.security.RMContainerTokenSecretManager: Rolling master-key for container-tokens
2014-05-05 04:18:41,089 INFO org.apache.hadoop.yarn.server.resourcemanager.security.NMTokenSecretManagerInRM: Rolling master-key for nm-tokens
2014-05-05 04:18:41,181 INFO org.mortbay.log: Logging to org.slf4j.impl.Log4jLoggerAdapter(org.mortbay.log) via org.mortbay.log.Slf4jLog
2014-05-05 04:18:41,252 INFO org.apache.hadoop.http.HttpServer: Added global filter 'safety' (class=org.apache.hadoop.http.HttpServer$QuotingInputFilter)
2014-05-05 04:18:41,255 INFO org.apache.hadoop.http.HttpServer: Added filter static_user_filter (class=org.apache.hadoop.http.lib.StaticUserWebFilter$StaticUserFilter) to context cluster
2014-05-05 04:18:41,255 INFO org.apache.hadoop.http.HttpServer: Added filter static_user_filter (class=org.apache.hadoop.http.lib.StaticUserWebFilter$StaticUserFilter) to context logs
2014-05-05 04:18:41,255 INFO org.apache.hadoop.http.HttpServer: Added filter static_user_filter (class=org.apache.hadoop.http.lib.StaticUserWebFilter$StaticUserFilter) to context static
2014-05-05 04:18:41,261 INFO org.apache.hadoop.http.HttpServer: adding path spec: /cluster/*
2014-05-05 04:18:41,261 INFO org.apache.hadoop.http.HttpServer: adding path spec: /ws/*
2014-05-05 04:18:41,272 INFO org.apache.hadoop.http.HttpServer: Jetty bound to port 8088
2014-05-05 04:18:41,272 INFO org.mortbay.log: jetty-6.1.26
2014-05-05 04:18:41,322 INFO org.mortbay.log: Extract jar:file:/home/ubuntu/PatchedDistro/hadoop-patch/share/hadoop/yarn/hadoop-yarn-common-2.2.0.jar!/webapps/cluster to /tmp/Jetty_ec2.54.186.230.200_us.west.2_compute_amazonaws_com_8088_cluster____.lsgqu1/webapp
2014-05-05 04:18:41,976 INFO org.mortbay.log: Started SelectChannelConnector@ec2-54-186-230-200.us-west-2.compute.amazonaws.com:8088
2014-05-05 04:18:41,976 INFO org.apache.hadoop.yarn.webapp.WebApps: Web app /cluster started at 8088
2014-05-05 04:18:42,726 INFO org.apache.hadoop.yarn.webapp.WebApps: Registered webapp guice modules
2014-05-05 04:18:42,728 INFO org.apache.hadoop.security.token.delegation.AbstractDelegationTokenSecretManager: Updating the current master key for generating delegation tokens
2014-05-05 04:18:42,729 INFO org.apache.hadoop.yarn.server.resourcemanager.security.RMDelegationTokenSecretManager: storing master key with keyID 1
2014-05-05 04:18:42,730 INFO org.apache.hadoop.security.token.delegation.AbstractDelegationTokenSecretManager: Starting expired delegation token remover thread, tokenRemoverScanInterval=60 min(s)
2014-05-05 04:18:42,730 INFO org.apache.hadoop.security.token.delegation.AbstractDelegationTokenSecretManager: Updating the current master key for generating delegation tokens
2014-05-05 04:18:42,730 INFO org.apache.hadoop.yarn.server.resourcemanager.security.RMDelegationTokenSecretManager: storing master key with keyID 2
2014-05-05 04:18:42,786 INFO org.apache.hadoop.ipc.Server: Starting Socket Reader #1 for port 8031
2014-05-05 04:18:42,807 INFO org.apache.hadoop.yarn.factories.impl.pb.RpcServerFactoryPBImpl: Adding protocol org.apache.hadoop.yarn.server.api.ResourceTrackerPB to the server
2014-05-05 04:18:42,807 INFO org.apache.hadoop.ipc.Server: IPC Server Responder: starting
2014-05-05 04:18:42,809 INFO org.apache.hadoop.ipc.Server: IPC Server listener on 8031: starting
2014-05-05 04:18:42,878 INFO org.apache.hadoop.ipc.Server: Starting Socket Reader #1 for port 8030
2014-05-05 04:18:42,939 INFO org.apache.hadoop.yarn.factories.impl.pb.RpcServerFactoryPBImpl: Adding protocol org.apache.hadoop.yarn.api.ApplicationMasterProtocolPB to the server
2014-05-05 04:18:42,940 INFO org.apache.hadoop.ipc.Server: IPC Server Responder: starting
2014-05-05 04:18:42,940 INFO org.apache.hadoop.ipc.Server: IPC Server listener on 8030: starting
2014-05-05 04:18:43,052 INFO org.apache.hadoop.yarn.factories.impl.pb.RpcServerFactoryPBImpl: Adding protocol org.apache.hadoop.yarn.api.ApplicationClientProtocolPB to the server
2014-05-05 04:18:43,052 INFO org.apache.hadoop.ipc.Server: Starting Socket Reader #1 for port 8032
2014-05-05 04:18:43,052 INFO org.apache.hadoop.ipc.Server: IPC Server Responder: starting
2014-05-05 04:18:43,053 INFO org.apache.hadoop.ipc.Server: IPC Server listener on 8032: starting
2014-05-05 04:18:43,109 INFO org.apache.hadoop.yarn.factories.impl.pb.RpcServerFactoryPBImpl: Adding protocol org.apache.hadoop.yarn.server.api.ResourceManagerAdministrationProtocolPB to the server
2014-05-05 04:18:43,110 INFO org.apache.hadoop.ipc.Server: Starting Socket Reader #1 for port 8033
2014-05-05 04:18:43,110 INFO org.apache.hadoop.ipc.Server: IPC Server Responder: starting
2014-05-05 04:18:43,111 INFO org.apache.hadoop.ipc.Server: IPC Server listener on 8033: starting
2014-05-05 04:18:43,685 INFO org.apache.hadoop.yarn.util.RackResolver: Resolved noded to /default-rack
2014-05-05 04:18:43,694 INFO org.apache.hadoop.yarn.server.resourcemanager.rmnode.RMNodeImpl: noded:46745 Node Transitioned from NEW to RUNNING
2014-05-05 04:18:43,694 INFO org.apache.hadoop.yarn.server.resourcemanager.ResourceTrackerService: NodeManager from node noded(cmPort: 46745 httpPort: 8042) registered with capability: <memory:8192, vCores:8>, assigned nodeId noded:46745
2014-05-05 04:18:43,699 INFO org.apache.hadoop.yarn.server.resourcemanager.scheduler.capacity.CapacityScheduler: Added node noded:46745 clusterResource: <memory:8192, vCores:8>
2014-05-05 04:18:43,706 INFO org.apache.hadoop.yarn.util.RackResolver: Resolved nodeb to /default-rack
2014-05-05 04:18:43,706 INFO org.apache.hadoop.yarn.server.resourcemanager.ResourceTrackerService: NodeManager from node nodeb(cmPort: 39246 httpPort: 8042) registered with capability: <memory:8192, vCores:8>, assigned nodeId nodeb:39246
2014-05-05 04:18:43,706 INFO org.apache.hadoop.yarn.server.resourcemanager.rmnode.RMNodeImpl: nodeb:39246 Node Transitioned from NEW to RUNNING
2014-05-05 04:18:43,706 INFO org.apache.hadoop.yarn.server.resourcemanager.scheduler.capacity.CapacityScheduler: Added node nodeb:39246 clusterResource: <memory:16384, vCores:16>
2014-05-05 04:18:43,729 INFO org.apache.hadoop.yarn.util.RackResolver: Resolved nodec to /default-rack
2014-05-05 04:18:43,729 INFO org.apache.hadoop.yarn.server.resourcemanager.ResourceTrackerService: NodeManager from node nodec(cmPort: 35640 httpPort: 8042) registered with capability: <memory:8192, vCores:8>, assigned nodeId nodec:35640
2014-05-05 04:18:43,730 INFO org.apache.hadoop.yarn.server.resourcemanager.rmnode.RMNodeImpl: nodec:35640 Node Transitioned from NEW to RUNNING
2014-05-05 04:18:43,730 INFO org.apache.hadoop.yarn.server.resourcemanager.scheduler.capacity.CapacityScheduler: Added node nodec:35640 clusterResource: <memory:24576, vCores:24>
2014-05-05 04:18:45,245 INFO org.apache.hadoop.yarn.util.RackResolver: Resolved nodea to /default-rack
2014-05-05 04:18:45,245 INFO org.apache.hadoop.yarn.server.resourcemanager.ResourceTrackerService: NodeManager from node nodea(cmPort: 44426 httpPort: 8042) registered with capability: <memory:8192, vCores:8>, assigned nodeId nodea:44426
2014-05-05 04:18:45,245 INFO org.apache.hadoop.yarn.server.resourcemanager.rmnode.RMNodeImpl: nodea:44426 Node Transitioned from NEW to RUNNING
2014-05-05 04:18:45,246 INFO org.apache.hadoop.yarn.server.resourcemanager.scheduler.capacity.CapacityScheduler: Added node nodea:44426 clusterResource: <memory:32768, vCores:32>
2014-05-05 04:18:53,781 ERROR org.apache.hadoop.security.UserGroupInformation: PriviledgedActionException as:ubuntu (auth:SIMPLE) cause:org.apache.hadoop.yarn.exceptions.ApplicationNotFoundException: Application with id 'application_1399261790270_0004' doesn't exist in RM.
2014-05-05 04:18:53,782 INFO org.apache.hadoop.ipc.Server: IPC Server handler 0 on 8032, call org.apache.hadoop.yarn.api.ApplicationClientProtocolPB.getApplicationReport from 10.0.0.158:37248 Call#554 Retry#0: error: org.apache.hadoop.yarn.exceptions.ApplicationNotFoundException: Application with id 'application_1399261790270_0004' doesn't exist in RM.
org.apache.hadoop.yarn.exceptions.ApplicationNotFoundException: Application with id 'application_1399261790270_0004' doesn't exist in RM.
	at org.apache.hadoop.yarn.server.resourcemanager.ClientRMService.getApplicationReport(ClientRMService.java:247)
	at org.apache.hadoop.yarn.api.impl.pb.service.ApplicationClientProtocolPBServiceImpl.getApplicationReport(ApplicationClientProtocolPBServiceImpl.java:120)
	at org.apache.hadoop.yarn.proto.ApplicationClientProtocol$ApplicationClientProtocolService$2.callBlockingMethod(ApplicationClientProtocol.java:241)
	at org.apache.hadoop.ipc.ProtobufRpcEngine$Server$ProtoBufRpcInvoker.call(ProtobufRpcEngine.java:585)
	at org.apache.hadoop.ipc.RPC$Server.call(RPC.java:928)
	at org.apache.hadoop.ipc.Server$Handler$1.run(Server.java:2048)
	at org.apache.hadoop.ipc.Server$Handler$1.run(Server.java:2044)
	at java.security.AccessController.doPrivileged(Native Method)
	at javax.security.auth.Subject.doAs(Subject.java:415)
	at org.apache.hadoop.security.UserGroupInformation.doAs(UserGroupInformation.java:1491)
	at org.apache.hadoop.ipc.Server$Handler.run(Server.java:2042)
2014-05-05 04:18:53,887 ERROR org.apache.hadoop.security.UserGroupInformation: PriviledgedActionException as:ubuntu (auth:SIMPLE) cause:org.apache.hadoop.yarn.exceptions.ApplicationNotFoundException: Application with id 'application_1399261790270_0004' doesn't exist in RM.
2014-05-05 04:18:53,887 INFO org.apache.hadoop.ipc.Server: IPC Server handler 1 on 8032, call org.apache.hadoop.yarn.api.ApplicationClientProtocolPB.getApplicationReport from 10.0.0.158:37248 Call#555 Retry#0: error: org.apache.hadoop.yarn.exceptions.ApplicationNotFoundException: Application with id 'application_1399261790270_0004' doesn't exist in RM.
org.apache.hadoop.yarn.exceptions.ApplicationNotFoundException: Application with id 'application_1399261790270_0004' doesn't exist in RM.
	at org.apache.hadoop.yarn.server.resourcemanager.ClientRMService.getApplicationReport(ClientRMService.java:247)
	at org.apache.hadoop.yarn.api.impl.pb.service.ApplicationClientProtocolPBServiceImpl.getApplicationReport(ApplicationClientProtocolPBServiceImpl.java:120)
	at org.apache.hadoop.yarn.proto.ApplicationClientProtocol$ApplicationClientProtocolService$2.callBlockingMethod(ApplicationClientProtocol.java:241)
	at org.apache.hadoop.ipc.ProtobufRpcEngine$Server$ProtoBufRpcInvoker.call(ProtobufRpcEngine.java:585)
	at org.apache.hadoop.ipc.RPC$Server.call(RPC.java:928)
	at org.apache.hadoop.ipc.Server$Handler$1.run(Server.java:2048)
	at org.apache.hadoop.ipc.Server$Handler$1.run(Server.java:2044)
	at java.security.AccessController.doPrivileged(Native Method)
	at javax.security.auth.Subject.doAs(Subject.java:415)
	at org.apache.hadoop.security.UserGroupInformation.doAs(UserGroupInformation.java:1491)
	at org.apache.hadoop.ipc.Server$Handler.run(Server.java:2042)
2014-05-05 04:18:53,989 ERROR org.apache.hadoop.security.UserGroupInformation: PriviledgedActionException as:ubuntu (auth:SIMPLE) cause:org.apache.hadoop.yarn.exceptions.ApplicationNotFoundException: Application with id 'application_1399261790270_0004' doesn't exist in RM.
2014-05-05 04:18:53,989 INFO org.apache.hadoop.ipc.Server: IPC Server handler 2 on 8032, call org.apache.hadoop.yarn.api.ApplicationClientProtocolPB.getApplicationReport from 10.0.0.158:37248 Call#556 Retry#0: error: org.apache.hadoop.yarn.exceptions.ApplicationNotFoundException: Application with id 'application_1399261790270_0004' doesn't exist in RM.
org.apache.hadoop.yarn.exceptions.ApplicationNotFoundException: Application with id 'application_1399261790270_0004' doesn't exist in RM.
	at org.apache.hadoop.yarn.server.resourcemanager.ClientRMService.getApplicationReport(ClientRMService.java:247)
	at org.apache.hadoop.yarn.api.impl.pb.service.ApplicationClientProtocolPBServiceImpl.getApplicationReport(ApplicationClientProtocolPBServiceImpl.java:120)
	at org.apache.hadoop.yarn.proto.ApplicationClientProtocol$ApplicationClientProtocolService$2.callBlockingMethod(ApplicationClientProtocol.java:241)
	at org.apache.hadoop.ipc.ProtobufRpcEngine$Server$ProtoBufRpcInvoker.call(ProtobufRpcEngine.java:585)
	at org.apache.hadoop.ipc.RPC$Server.call(RPC.java:928)
	at org.apache.hadoop.ipc.Server$Handler$1.run(Server.java:2048)
	at org.apache.hadoop.ipc.Server$Handler$1.run(Server.java:2044)
	at java.security.AccessController.doPrivileged(Native Method)
	at javax.security.auth.Subject.doAs(Subject.java:415)
	at org.apache.hadoop.security.UserGroupInformation.doAs(UserGroupInformation.java:1491)
	at org.apache.hadoop.ipc.Server$Handler.run(Server.java:2042)
2014-05-05 04:20:09,468 INFO org.apache.hadoop.yarn.server.resourcemanager.ClientRMService: Allocated new applicationId: 1
2014-05-05 04:20:11,410 INFO org.apache.hadoop.yarn.server.resourcemanager.ClientRMService: Application with id 1 submitted by user ubuntu
2014-05-05 04:20:11,411 INFO org.apache.hadoop.yarn.server.resourcemanager.rmapp.RMAppImpl: Storing application with id application_1399263518640_0001
2014-05-05 04:20:11,412 INFO org.apache.hadoop.yarn.server.resourcemanager.RMAuditLogger: USER=ubuntu	IP=10.0.0.158	OPERATION=Submit Application Request	TARGET=ClientRMService	RESULT=SUCCESS	APPID=application_1399263518640_0001
2014-05-05 04:20:11,413 INFO org.apache.hadoop.yarn.server.resourcemanager.rmapp.RMAppImpl: application_1399263518640_0001 State change from NEW to NEW_SAVING
2014-05-05 04:20:11,425 INFO org.apache.hadoop.yarn.server.resourcemanager.recovery.RMStateStore: Storing info for app: application_1399263518640_0001
2014-05-05 04:20:11,434 INFO org.apache.hadoop.yarn.server.resourcemanager.rmapp.RMAppImpl: application_1399263518640_0001 State change from NEW_SAVING to SUBMITTED
2014-05-05 04:20:11,434 INFO org.apache.hadoop.yarn.server.resourcemanager.ApplicationMasterService: Registering app attempt : appattempt_1399263518640_0001_000001
2014-05-05 04:20:11,441 INFO org.apache.hadoop.yarn.server.resourcemanager.rmapp.attempt.RMAppAttemptImpl: appattempt_1399263518640_0001_000001 State change from NEW to SUBMITTED
2014-05-05 04:20:11,472 INFO org.apache.hadoop.yarn.server.resourcemanager.scheduler.capacity.LeafQueue: Application application_1399263518640_0001 from user: ubuntu activated in queue: default
2014-05-05 04:20:11,472 INFO org.apache.hadoop.yarn.server.resourcemanager.scheduler.capacity.LeafQueue: Application added - appId: application_1399263518640_0001 user: org.apache.hadoop.yarn.server.resourcemanager.scheduler.capacity.LeafQueue$User@37098a4d, leaf-queue: default #user-pending-applications: 0 #user-active-applications: 1 #queue-pending-applications: 0 #queue-active-applications: 1
2014-05-05 04:20:11,472 INFO org.apache.hadoop.yarn.server.resourcemanager.scheduler.capacity.ParentQueue: Application added - appId: application_1399263518640_0001 user: ubuntu leaf-queue of parent: root #applications: 1
2014-05-05 04:20:11,472 INFO org.apache.hadoop.yarn.server.resourcemanager.scheduler.capacity.CapacityScheduler: Application Submission: appattempt_1399263518640_0001_000001, user: ubuntu queue: default: capacity=1.0, absoluteCapacity=1.0, usedResources=<memory:0, vCores:0>usedCapacity=0.0, absoluteUsedCapacity=0.0, numApps=1, numContainers=0, currently active: 1
2014-05-05 04:20:11,473 INFO org.apache.hadoop.yarn.server.resourcemanager.rmapp.attempt.RMAppAttemptImpl: appattempt_1399263518640_0001_000001 State change from SUBMITTED to SCHEDULED
2014-05-05 04:20:11,473 INFO org.apache.hadoop.yarn.server.resourcemanager.rmapp.RMAppImpl: application_1399263518640_0001 State change from SUBMITTED to ACCEPTED
2014-05-05 04:20:11,953 INFO org.apache.hadoop.yarn.server.resourcemanager.rmcontainer.RMContainerImpl: container_1399263518640_0001_01_000001 Container Transitioned from NEW to ALLOCATED
2014-05-05 04:20:11,953 INFO org.apache.hadoop.yarn.server.resourcemanager.RMAuditLogger: USER=ubuntu	OPERATION=AM Allocated Container	TARGET=SchedulerApp	RESULT=SUCCESS	APPID=application_1399263518640_0001	CONTAINERID=container_1399263518640_0001_01_000001
2014-05-05 04:20:11,954 INFO org.apache.hadoop.yarn.server.resourcemanager.scheduler.common.fica.FiCaSchedulerNode: Assigned container container_1399263518640_0001_01_000001 of capacity <memory:2048, vCores:1> on host nodeb:39246, which currently has 1 containers, <memory:2048, vCores:1> used and <memory:6144, vCores:7> available
2014-05-05 04:20:11,954 INFO org.apache.hadoop.yarn.server.resourcemanager.scheduler.capacity.LeafQueue: assignedContainer application=application_1399263518640_0001 container=Container: [ContainerId: container_1399263518640_0001_01_000001, NodeId: nodeb:39246, NodeHttpAddress: nodeb:8042, Resource: <memory:2048, vCores:1>, Priority: 0, Token: Token { kind: ContainerToken, service: 10.0.0.59:39246 }, ] containerId=container_1399263518640_0001_01_000001 queue=default: capacity=1.0, absoluteCapacity=1.0, usedResources=<memory:0, vCores:0>usedCapacity=0.0, absoluteUsedCapacity=0.0, numApps=1, numContainers=0 usedCapacity=0.0 absoluteUsedCapacity=0.0 used=<memory:0, vCores:0> cluster=<memory:32768, vCores:32>
2014-05-05 04:20:11,954 INFO org.apache.hadoop.yarn.server.resourcemanager.scheduler.capacity.ParentQueue: Re-sorting assigned queue: root.default stats: default: capacity=1.0, absoluteCapacity=1.0, usedResources=<memory:2048, vCores:1>usedCapacity=0.0625, absoluteUsedCapacity=0.0625, numApps=1, numContainers=1
2014-05-05 04:20:11,954 INFO org.apache.hadoop.yarn.server.resourcemanager.scheduler.capacity.ParentQueue: assignedContainer queue=root usedCapacity=0.0625 absoluteUsedCapacity=0.0625 used=<memory:2048, vCores:1> cluster=<memory:32768, vCores:32>
2014-05-05 04:20:11,955 INFO org.apache.hadoop.yarn.server.resourcemanager.rmcontainer.RMContainerImpl: container_1399263518640_0001_01_000001 Container Transitioned from ALLOCATED to ACQUIRED
2014-05-05 04:20:11,957 INFO org.apache.hadoop.yarn.server.resourcemanager.rmapp.attempt.RMAppAttemptImpl: Storing attempt: AppId: application_1399263518640_0001 AttemptId: appattempt_1399263518640_0001_000001 MasterContainer: Container: [ContainerId: container_1399263518640_0001_01_000001, NodeId: nodeb:39246, NodeHttpAddress: nodeb:8042, Resource: <memory:2048, vCores:1>, Priority: 0, Token: Token { kind: ContainerToken, service: 10.0.0.59:39246 }, ]
2014-05-05 04:20:11,961 INFO org.apache.hadoop.yarn.server.resourcemanager.rmapp.attempt.RMAppAttemptImpl: appattempt_1399263518640_0001_000001 State change from SCHEDULED to ALLOCATED_SAVING
2014-05-05 04:20:11,966 INFO org.apache.hadoop.yarn.server.resourcemanager.recovery.RMStateStore: Storing info for attempt: appattempt_1399263518640_0001_000001
2014-05-05 04:20:11,968 INFO org.apache.hadoop.yarn.server.resourcemanager.rmapp.attempt.RMAppAttemptImpl: appattempt_1399263518640_0001_000001 State change from ALLOCATED_SAVING to ALLOCATED
2014-05-05 04:20:11,970 INFO org.apache.hadoop.yarn.server.resourcemanager.amlauncher.AMLauncher: Launching masterappattempt_1399263518640_0001_000001
2014-05-05 04:20:12,001 INFO org.apache.hadoop.yarn.server.resourcemanager.amlauncher.AMLauncher: Setting up container Container: [ContainerId: container_1399263518640_0001_01_000001, NodeId: nodeb:39246, NodeHttpAddress: nodeb:8042, Resource: <memory:2048, vCores:1>, Priority: 0, Token: Token { kind: ContainerToken, service: 10.0.0.59:39246 }, ] for AM appattempt_1399263518640_0001_000001
2014-05-05 04:20:12,002 INFO org.apache.hadoop.yarn.server.resourcemanager.amlauncher.AMLauncher: Command to launch container container_1399263518640_0001_01_000001 : $JAVA_HOME/bin/java -Dlog4j.configuration=container-log4j.properties -Dyarn.app.container.log.dir=<LOG_DIR> -Dyarn.app.container.log.filesize=0 -Dhadoop.root.logger=INFO,CLA  -Xmx1024m org.apache.hadoop.mapreduce.v2.app.MRAppMaster 1><LOG_DIR>/stdout 2><LOG_DIR>/stderr 
2014-05-05 04:20:12,337 INFO org.apache.hadoop.yarn.server.resourcemanager.amlauncher.AMLauncher: Done launching container Container: [ContainerId: container_1399263518640_0001_01_000001, NodeId: nodeb:39246, NodeHttpAddress: nodeb:8042, Resource: <memory:2048, vCores:1>, Priority: 0, Token: Token { kind: ContainerToken, service: 10.0.0.59:39246 }, ] for AM appattempt_1399263518640_0001_000001
2014-05-05 04:20:12,338 INFO org.apache.hadoop.yarn.server.resourcemanager.rmapp.attempt.RMAppAttemptImpl: appattempt_1399263518640_0001_000001 State change from ALLOCATED to LAUNCHED
2014-05-05 04:20:12,959 INFO org.apache.hadoop.yarn.server.resourcemanager.rmcontainer.RMContainerImpl: container_1399263518640_0001_01_000001 Container Transitioned from ACQUIRED to RUNNING
2014-05-05 04:20:18,894 INFO SecurityLogger.org.apache.hadoop.ipc.Server: Auth successful for appattempt_1399263518640_0001_000001 (auth:SIMPLE)
2014-05-05 04:20:18,902 INFO org.apache.hadoop.yarn.server.resourcemanager.ApplicationMasterService: AM registration appattempt_1399263518640_0001_000001
2014-05-05 04:20:18,902 INFO org.apache.hadoop.yarn.server.resourcemanager.RMAuditLogger: USER=ubuntu	IP=10.0.0.59	OPERATION=Register App Master	TARGET=ApplicationMasterService	RESULT=SUCCESS	APPID=application_1399263518640_0001	APPATTEMPTID=appattempt_1399263518640_0001_000001
2014-05-05 04:20:18,903 INFO org.apache.hadoop.yarn.server.resourcemanager.rmapp.attempt.RMAppAttemptImpl: appattempt_1399263518640_0001_000001 State change from LAUNCHED to RUNNING
2014-05-05 04:20:18,903 INFO org.apache.hadoop.yarn.server.resourcemanager.rmapp.RMAppImpl: application_1399263518640_0001 State change from ACCEPTED to RUNNING
2014-05-05 04:20:19,974 INFO org.apache.hadoop.yarn.server.resourcemanager.rmcontainer.RMContainerImpl: container_1399263518640_0001_01_000002 Container Transitioned from NEW to ALLOCATED
2014-05-05 04:20:19,974 INFO org.apache.hadoop.yarn.server.resourcemanager.RMAuditLogger: USER=ubuntu	OPERATION=AM Allocated Container	TARGET=SchedulerApp	RESULT=SUCCESS	APPID=application_1399263518640_0001	CONTAINERID=container_1399263518640_0001_01_000002
2014-05-05 04:20:19,974 INFO org.apache.hadoop.yarn.server.resourcemanager.scheduler.common.fica.FiCaSchedulerNode: Assigned container container_1399263518640_0001_01_000002 of capacity <memory:1024, vCores:1> on host noded:46745, which currently has 1 containers, <memory:1024, vCores:1> used and <memory:7168, vCores:7> available
2014-05-05 04:20:19,974 INFO org.apache.hadoop.yarn.server.resourcemanager.scheduler.capacity.LeafQueue: assignedContainer application=application_1399263518640_0001 container=Container: [ContainerId: container_1399263518640_0001_01_000002, NodeId: noded:46745, NodeHttpAddress: noded:8042, Resource: <memory:1024, vCores:1>, Priority: 20, Token: Token { kind: ContainerToken, service: 10.0.0.180:46745 }, ] containerId=container_1399263518640_0001_01_000002 queue=default: capacity=1.0, absoluteCapacity=1.0, usedResources=<memory:2048, vCores:1>usedCapacity=0.0625, absoluteUsedCapacity=0.0625, numApps=1, numContainers=1 usedCapacity=0.0625 absoluteUsedCapacity=0.0625 used=<memory:2048, vCores:1> cluster=<memory:32768, vCores:32>
2014-05-05 04:20:19,975 INFO org.apache.hadoop.yarn.server.resourcemanager.scheduler.capacity.ParentQueue: Re-sorting assigned queue: root.default stats: default: capacity=1.0, absoluteCapacity=1.0, usedResources=<memory:3072, vCores:2>usedCapacity=0.09375, absoluteUsedCapacity=0.09375, numApps=1, numContainers=2
2014-05-05 04:20:19,975 INFO org.apache.hadoop.yarn.server.resourcemanager.scheduler.capacity.ParentQueue: assignedContainer queue=root usedCapacity=0.09375 absoluteUsedCapacity=0.09375 used=<memory:3072, vCores:2> cluster=<memory:32768, vCores:32>
2014-05-05 04:20:19,976 INFO org.apache.hadoop.yarn.server.resourcemanager.rmcontainer.RMContainerImpl: container_1399263518640_0001_01_000003 Container Transitioned from NEW to ALLOCATED
2014-05-05 04:20:19,976 INFO org.apache.hadoop.yarn.server.resourcemanager.RMAuditLogger: USER=ubuntu	OPERATION=AM Allocated Container	TARGET=SchedulerApp	RESULT=SUCCESS	APPID=application_1399263518640_0001	CONTAINERID=container_1399263518640_0001_01_000003
2014-05-05 04:20:19,976 INFO org.apache.hadoop.yarn.server.resourcemanager.scheduler.common.fica.FiCaSchedulerNode: Assigned container container_1399263518640_0001_01_000003 of capacity <memory:1024, vCores:1> on host noded:46745, which currently has 2 containers, <memory:2048, vCores:2> used and <memory:6144, vCores:6> available
2014-05-05 04:20:19,976 INFO org.apache.hadoop.yarn.server.resourcemanager.scheduler.capacity.LeafQueue: assignedContainer application=application_1399263518640_0001 container=Container: [ContainerId: container_1399263518640_0001_01_000003, NodeId: noded:46745, NodeHttpAddress: noded:8042, Resource: <memory:1024, vCores:1>, Priority: 20, Token: Token { kind: ContainerToken, service: 10.0.0.180:46745 }, ] containerId=container_1399263518640_0001_01_000003 queue=default: capacity=1.0, absoluteCapacity=1.0, usedResources=<memory:3072, vCores:2>usedCapacity=0.09375, absoluteUsedCapacity=0.09375, numApps=1, numContainers=2 usedCapacity=0.09375 absoluteUsedCapacity=0.09375 used=<memory:3072, vCores:2> cluster=<memory:32768, vCores:32>
2014-05-05 04:20:19,976 INFO org.apache.hadoop.yarn.server.resourcemanager.scheduler.capacity.ParentQueue: Re-sorting assigned queue: root.default stats: default: capacity=1.0, absoluteCapacity=1.0, usedResources=<memory:4096, vCores:3>usedCapacity=0.125, absoluteUsedCapacity=0.125, numApps=1, numContainers=3
2014-05-05 04:20:19,976 INFO org.apache.hadoop.yarn.server.resourcemanager.scheduler.capacity.ParentQueue: assignedContainer queue=root usedCapacity=0.125 absoluteUsedCapacity=0.125 used=<memory:4096, vCores:3> cluster=<memory:32768, vCores:32>
2014-05-05 04:20:19,977 INFO org.apache.hadoop.yarn.server.resourcemanager.rmcontainer.RMContainerImpl: container_1399263518640_0001_01_000004 Container Transitioned from NEW to ALLOCATED
2014-05-05 04:20:19,977 INFO org.apache.hadoop.yarn.server.resourcemanager.RMAuditLogger: USER=ubuntu	OPERATION=AM Allocated Container	TARGET=SchedulerApp	RESULT=SUCCESS	APPID=application_1399263518640_0001	CONTAINERID=container_1399263518640_0001_01_000004
2014-05-05 04:20:19,977 INFO org.apache.hadoop.yarn.server.resourcemanager.scheduler.common.fica.FiCaSchedulerNode: Assigned container container_1399263518640_0001_01_000004 of capacity <memory:1024, vCores:1> on host noded:46745, which currently has 3 containers, <memory:3072, vCores:3> used and <memory:5120, vCores:5> available
2014-05-05 04:20:19,977 INFO org.apache.hadoop.yarn.server.resourcemanager.scheduler.capacity.LeafQueue: assignedContainer application=application_1399263518640_0001 container=Container: [ContainerId: container_1399263518640_0001_01_000004, NodeId: noded:46745, NodeHttpAddress: noded:8042, Resource: <memory:1024, vCores:1>, Priority: 20, Token: Token { kind: ContainerToken, service: 10.0.0.180:46745 }, ] containerId=container_1399263518640_0001_01_000004 queue=default: capacity=1.0, absoluteCapacity=1.0, usedResources=<memory:4096, vCores:3>usedCapacity=0.125, absoluteUsedCapacity=0.125, numApps=1, numContainers=3 usedCapacity=0.125 absoluteUsedCapacity=0.125 used=<memory:4096, vCores:3> cluster=<memory:32768, vCores:32>
2014-05-05 04:20:19,978 INFO org.apache.hadoop.yarn.server.resourcemanager.scheduler.capacity.ParentQueue: Re-sorting assigned queue: root.default stats: default: capacity=1.0, absoluteCapacity=1.0, usedResources=<memory:5120, vCores:4>usedCapacity=0.15625, absoluteUsedCapacity=0.15625, numApps=1, numContainers=4
2014-05-05 04:20:19,978 INFO org.apache.hadoop.yarn.server.resourcemanager.scheduler.capacity.ParentQueue: assignedContainer queue=root usedCapacity=0.15625 absoluteUsedCapacity=0.15625 used=<memory:5120, vCores:4> cluster=<memory:32768, vCores:32>
2014-05-05 04:20:19,978 INFO org.apache.hadoop.yarn.server.resourcemanager.rmcontainer.RMContainerImpl: container_1399263518640_0001_01_000005 Container Transitioned from NEW to ALLOCATED
2014-05-05 04:20:19,978 INFO org.apache.hadoop.yarn.server.resourcemanager.RMAuditLogger: USER=ubuntu	OPERATION=AM Allocated Container	TARGET=SchedulerApp	RESULT=SUCCESS	APPID=application_1399263518640_0001	CONTAINERID=container_1399263518640_0001_01_000005
2014-05-05 04:20:19,978 INFO org.apache.hadoop.yarn.server.resourcemanager.scheduler.common.fica.FiCaSchedulerNode: Assigned container container_1399263518640_0001_01_000005 of capacity <memory:1024, vCores:1> on host noded:46745, which currently has 4 containers, <memory:4096, vCores:4> used and <memory:4096, vCores:4> available
2014-05-05 04:20:19,979 INFO org.apache.hadoop.yarn.server.resourcemanager.scheduler.capacity.LeafQueue: assignedContainer application=application_1399263518640_0001 container=Container: [ContainerId: container_1399263518640_0001_01_000005, NodeId: noded:46745, NodeHttpAddress: noded:8042, Resource: <memory:1024, vCores:1>, Priority: 20, Token: Token { kind: ContainerToken, service: 10.0.0.180:46745 }, ] containerId=container_1399263518640_0001_01_000005 queue=default: capacity=1.0, absoluteCapacity=1.0, usedResources=<memory:5120, vCores:4>usedCapacity=0.15625, absoluteUsedCapacity=0.15625, numApps=1, numContainers=4 usedCapacity=0.15625 absoluteUsedCapacity=0.15625 used=<memory:5120, vCores:4> cluster=<memory:32768, vCores:32>
2014-05-05 04:20:19,979 INFO org.apache.hadoop.yarn.server.resourcemanager.scheduler.capacity.ParentQueue: Re-sorting assigned queue: root.default stats: default: capacity=1.0, absoluteCapacity=1.0, usedResources=<memory:6144, vCores:5>usedCapacity=0.1875, absoluteUsedCapacity=0.1875, numApps=1, numContainers=5
2014-05-05 04:20:19,979 INFO org.apache.hadoop.yarn.server.resourcemanager.scheduler.capacity.ParentQueue: assignedContainer queue=root usedCapacity=0.1875 absoluteUsedCapacity=0.1875 used=<memory:6144, vCores:5> cluster=<memory:32768, vCores:32>
2014-05-05 04:20:20,967 INFO org.apache.hadoop.yarn.server.resourcemanager.rmcontainer.RMContainerImpl: container_1399263518640_0001_01_000002 Container Transitioned from ALLOCATED to ACQUIRED
2014-05-05 04:20:20,968 INFO org.apache.hadoop.yarn.server.resourcemanager.rmcontainer.RMContainerImpl: container_1399263518640_0001_01_000003 Container Transitioned from ALLOCATED to ACQUIRED
2014-05-05 04:20:20,968 INFO org.apache.hadoop.yarn.server.resourcemanager.rmcontainer.RMContainerImpl: container_1399263518640_0001_01_000004 Container Transitioned from ALLOCATED to ACQUIRED
2014-05-05 04:20:20,969 INFO org.apache.hadoop.yarn.server.resourcemanager.rmcontainer.RMContainerImpl: container_1399263518640_0001_01_000005 Container Transitioned from ALLOCATED to ACQUIRED
2014-05-05 04:20:21,988 INFO org.apache.hadoop.yarn.server.resourcemanager.scheduler.AppSchedulingInfo: checking for deactivate... 
2014-05-05 04:20:21,995 INFO org.apache.hadoop.yarn.server.resourcemanager.rmcontainer.RMContainerImpl: container_1399263518640_0001_01_000002 Container Transitioned from ACQUIRED to RUNNING
2014-05-05 04:20:21,996 INFO org.apache.hadoop.yarn.server.resourcemanager.rmcontainer.RMContainerImpl: container_1399263518640_0001_01_000003 Container Transitioned from ACQUIRED to RUNNING
2014-05-05 04:20:21,996 INFO org.apache.hadoop.yarn.server.resourcemanager.rmcontainer.RMContainerImpl: container_1399263518640_0001_01_000004 Container Transitioned from ACQUIRED to RUNNING
2014-05-05 04:20:21,996 INFO org.apache.hadoop.yarn.server.resourcemanager.rmcontainer.RMContainerImpl: container_1399263518640_0001_01_000005 Container Transitioned from ACQUIRED to RUNNING
2014-05-05 04:20:50,055 INFO org.apache.hadoop.yarn.server.resourcemanager.rmcontainer.RMContainerImpl: container_1399263518640_0001_01_000006 Container Transitioned from NEW to ALLOCATED
2014-05-05 04:20:50,055 INFO org.apache.hadoop.yarn.server.resourcemanager.RMAuditLogger: USER=ubuntu	OPERATION=AM Allocated Container	TARGET=SchedulerApp	RESULT=SUCCESS	APPID=application_1399263518640_0001	CONTAINERID=container_1399263518640_0001_01_000006
2014-05-05 04:20:50,055 INFO org.apache.hadoop.yarn.server.resourcemanager.scheduler.common.fica.FiCaSchedulerNode: Assigned container container_1399263518640_0001_01_000006 of capacity <memory:1024, vCores:1> on host nodeb:39246, which currently has 2 containers, <memory:3072, vCores:2> used and <memory:5120, vCores:6> available
2014-05-05 04:20:50,055 INFO org.apache.hadoop.yarn.server.resourcemanager.scheduler.capacity.LeafQueue: assignedContainer application=application_1399263518640_0001 container=Container: [ContainerId: container_1399263518640_0001_01_000006, NodeId: nodeb:39246, NodeHttpAddress: nodeb:8042, Resource: <memory:1024, vCores:1>, Priority: 20, Token: Token { kind: ContainerToken, service: 10.0.0.59:39246 }, ] containerId=container_1399263518640_0001_01_000006 queue=default: capacity=1.0, absoluteCapacity=1.0, usedResources=<memory:6144, vCores:5>usedCapacity=0.1875, absoluteUsedCapacity=0.1875, numApps=1, numContainers=5 usedCapacity=0.1875 absoluteUsedCapacity=0.1875 used=<memory:6144, vCores:5> cluster=<memory:32768, vCores:32>
2014-05-05 04:20:50,056 INFO org.apache.hadoop.yarn.server.resourcemanager.scheduler.capacity.ParentQueue: Re-sorting assigned queue: root.default stats: default: capacity=1.0, absoluteCapacity=1.0, usedResources=<memory:7168, vCores:6>usedCapacity=0.21875, absoluteUsedCapacity=0.21875, numApps=1, numContainers=6
2014-05-05 04:20:50,056 INFO org.apache.hadoop.yarn.server.resourcemanager.scheduler.capacity.ParentQueue: assignedContainer queue=root usedCapacity=0.21875 absoluteUsedCapacity=0.21875 used=<memory:7168, vCores:6> cluster=<memory:32768, vCores:32>
2014-05-05 04:20:50,335 INFO org.apache.hadoop.yarn.server.resourcemanager.rmcontainer.RMContainerImpl: container_1399263518640_0001_01_000005 Container Transitioned from RUNNING to COMPLETED
2014-05-05 04:20:50,335 INFO org.apache.hadoop.yarn.server.resourcemanager.scheduler.common.fica.FiCaSchedulerApp: Completed container: container_1399263518640_0001_01_000005 in state: COMPLETED event:FINISHED
2014-05-05 04:20:50,336 INFO org.apache.hadoop.yarn.server.resourcemanager.RMAuditLogger: USER=ubuntu	OPERATION=AM Released Container	TARGET=SchedulerApp	RESULT=SUCCESS	APPID=application_1399263518640_0001	CONTAINERID=container_1399263518640_0001_01_000005
2014-05-05 04:20:50,336 INFO org.apache.hadoop.yarn.server.resourcemanager.scheduler.common.fica.FiCaSchedulerNode: Released container container_1399263518640_0001_01_000005 of capacity <memory:1024, vCores:1> on host noded:46745, which currently has 3 containers, <memory:3072, vCores:3> used and <memory:5120, vCores:5> available, release resources=true
2014-05-05 04:20:50,336 INFO org.apache.hadoop.yarn.server.resourcemanager.scheduler.capacity.LeafQueue: default used=<memory:6144, vCores:5> numContainers=5 user=ubuntu user-resources=<memory:6144, vCores:5>
2014-05-05 04:20:50,336 INFO org.apache.hadoop.yarn.server.resourcemanager.scheduler.capacity.LeafQueue: completedContainer container=Container: [ContainerId: container_1399263518640_0001_01_000005, NodeId: noded:46745, NodeHttpAddress: noded:8042, Resource: <memory:1024, vCores:1>, Priority: 20, Token: Token { kind: ContainerToken, service: 10.0.0.180:46745 }, ] resource=<memory:1024, vCores:1> queue=default: capacity=1.0, absoluteCapacity=1.0, usedResources=<memory:6144, vCores:5>usedCapacity=0.1875, absoluteUsedCapacity=0.1875, numApps=1, numContainers=5 usedCapacity=0.1875 absoluteUsedCapacity=0.1875 used=<memory:6144, vCores:5> cluster=<memory:32768, vCores:32>
2014-05-05 04:20:50,336 INFO org.apache.hadoop.yarn.server.resourcemanager.scheduler.capacity.ParentQueue: completedContainer queue=root usedCapacity=0.1875 absoluteUsedCapacity=0.1875 used=<memory:6144, vCores:5> cluster=<memory:32768, vCores:32>
2014-05-05 04:20:50,336 INFO org.apache.hadoop.yarn.server.resourcemanager.scheduler.capacity.ParentQueue: Re-sorting completed queue: root.default stats: default: capacity=1.0, absoluteCapacity=1.0, usedResources=<memory:6144, vCores:5>usedCapacity=0.1875, absoluteUsedCapacity=0.1875, numApps=1, numContainers=5
2014-05-05 04:20:50,336 INFO org.apache.hadoop.yarn.server.resourcemanager.scheduler.capacity.CapacityScheduler: Application appattempt_1399263518640_0001_000001 released container container_1399263518640_0001_01_000005 on node: host: noded:46745 #containers=3 available=5120 used=3072 with event: FINISHED
2014-05-05 04:20:51,058 INFO org.apache.hadoop.yarn.server.resourcemanager.rmcontainer.RMContainerImpl: container_1399263518640_0001_01_000006 Container Transitioned from ALLOCATED to ACQUIRED
2014-05-05 04:20:51,339 INFO org.apache.hadoop.yarn.server.resourcemanager.rmcontainer.RMContainerImpl: container_1399263518640_0001_01_000007 Container Transitioned from NEW to ALLOCATED
2014-05-05 04:20:51,339 INFO org.apache.hadoop.yarn.server.resourcemanager.RMAuditLogger: USER=ubuntu	OPERATION=AM Allocated Container	TARGET=SchedulerApp	RESULT=SUCCESS	APPID=application_1399263518640_0001	CONTAINERID=container_1399263518640_0001_01_000007
2014-05-05 04:20:51,339 INFO org.apache.hadoop.yarn.server.resourcemanager.scheduler.common.fica.FiCaSchedulerNode: Assigned container container_1399263518640_0001_01_000007 of capacity <memory:1024, vCores:1> on host noded:46745, which currently has 4 containers, <memory:4096, vCores:4> used and <memory:4096, vCores:4> available
2014-05-05 04:20:51,339 INFO org.apache.hadoop.yarn.server.resourcemanager.scheduler.capacity.LeafQueue: assignedContainer application=application_1399263518640_0001 container=Container: [ContainerId: container_1399263518640_0001_01_000007, NodeId: noded:46745, NodeHttpAddress: noded:8042, Resource: <memory:1024, vCores:1>, Priority: 10, Token: Token { kind: ContainerToken, service: 10.0.0.180:46745 }, ] containerId=container_1399263518640_0001_01_000007 queue=default: capacity=1.0, absoluteCapacity=1.0, usedResources=<memory:6144, vCores:5>usedCapacity=0.1875, absoluteUsedCapacity=0.1875, numApps=1, numContainers=5 usedCapacity=0.1875 absoluteUsedCapacity=0.1875 used=<memory:6144, vCores:5> cluster=<memory:32768, vCores:32>
2014-05-05 04:20:51,339 INFO org.apache.hadoop.yarn.server.resourcemanager.scheduler.capacity.ParentQueue: Re-sorting assigned queue: root.default stats: default: capacity=1.0, absoluteCapacity=1.0, usedResources=<memory:7168, vCores:6>usedCapacity=0.21875, absoluteUsedCapacity=0.21875, numApps=1, numContainers=6
2014-05-05 04:20:51,339 INFO org.apache.hadoop.yarn.server.resourcemanager.scheduler.capacity.ParentQueue: assignedContainer queue=root usedCapacity=0.21875 absoluteUsedCapacity=0.21875 used=<memory:7168, vCores:6> cluster=<memory:32768, vCores:32>
2014-05-05 04:20:51,340 INFO org.apache.hadoop.yarn.server.resourcemanager.rmcontainer.RMContainerImpl: container_1399263518640_0001_01_000008 Container Transitioned from NEW to ALLOCATED
2014-05-05 04:20:51,340 INFO org.apache.hadoop.yarn.server.resourcemanager.RMAuditLogger: USER=ubuntu	OPERATION=AM Allocated Container	TARGET=SchedulerApp	RESULT=SUCCESS	APPID=application_1399263518640_0001	CONTAINERID=container_1399263518640_0001_01_000008
2014-05-05 04:20:51,340 INFO org.apache.hadoop.yarn.server.resourcemanager.scheduler.common.fica.FiCaSchedulerNode: Assigned container container_1399263518640_0001_01_000008 of capacity <memory:1024, vCores:1> on host noded:46745, which currently has 5 containers, <memory:5120, vCores:5> used and <memory:3072, vCores:3> available
2014-05-05 04:20:51,340 INFO org.apache.hadoop.yarn.server.resourcemanager.scheduler.capacity.LeafQueue: assignedContainer application=application_1399263518640_0001 container=Container: [ContainerId: container_1399263518640_0001_01_000008, NodeId: noded:46745, NodeHttpAddress: noded:8042, Resource: <memory:1024, vCores:1>, Priority: 10, Token: Token { kind: ContainerToken, service: 10.0.0.180:46745 }, ] containerId=container_1399263518640_0001_01_000008 queue=default: capacity=1.0, absoluteCapacity=1.0, usedResources=<memory:7168, vCores:6>usedCapacity=0.21875, absoluteUsedCapacity=0.21875, numApps=1, numContainers=6 usedCapacity=0.21875 absoluteUsedCapacity=0.21875 used=<memory:7168, vCores:6> cluster=<memory:32768, vCores:32>
2014-05-05 04:20:51,340 INFO org.apache.hadoop.yarn.server.resourcemanager.scheduler.capacity.ParentQueue: Re-sorting assigned queue: root.default stats: default: capacity=1.0, absoluteCapacity=1.0, usedResources=<memory:8192, vCores:7>usedCapacity=0.25, absoluteUsedCapacity=0.25, numApps=1, numContainers=7
2014-05-05 04:20:51,340 INFO org.apache.hadoop.yarn.server.resourcemanager.scheduler.capacity.ParentQueue: assignedContainer queue=root usedCapacity=0.25 absoluteUsedCapacity=0.25 used=<memory:8192, vCores:7> cluster=<memory:32768, vCores:32>
2014-05-05 04:20:51,521 INFO org.apache.hadoop.yarn.server.resourcemanager.rmcontainer.RMContainerImpl: container_1399263518640_0001_01_000009 Container Transitioned from NEW to ALLOCATED
2014-05-05 04:20:51,521 INFO org.apache.hadoop.yarn.server.resourcemanager.RMAuditLogger: USER=ubuntu	OPERATION=AM Allocated Container	TARGET=SchedulerApp	RESULT=SUCCESS	APPID=application_1399263518640_0001	CONTAINERID=container_1399263518640_0001_01_000009
2014-05-05 04:20:51,521 INFO org.apache.hadoop.yarn.server.resourcemanager.scheduler.common.fica.FiCaSchedulerNode: Assigned container container_1399263518640_0001_01_000009 of capacity <memory:1024, vCores:1> on host nodea:44426, which currently has 1 containers, <memory:1024, vCores:1> used and <memory:7168, vCores:7> available
2014-05-05 04:20:51,522 INFO org.apache.hadoop.yarn.server.resourcemanager.scheduler.capacity.LeafQueue: assignedContainer application=application_1399263518640_0001 container=Container: [ContainerId: container_1399263518640_0001_01_000009, NodeId: nodea:44426, NodeHttpAddress: nodea:8042, Resource: <memory:1024, vCores:1>, Priority: 10, Token: Token { kind: ContainerToken, service: 10.0.0.158:44426 }, ] containerId=container_1399263518640_0001_01_000009 queue=default: capacity=1.0, absoluteCapacity=1.0, usedResources=<memory:8192, vCores:7>usedCapacity=0.25, absoluteUsedCapacity=0.25, numApps=1, numContainers=7 usedCapacity=0.25 absoluteUsedCapacity=0.25 used=<memory:8192, vCores:7> cluster=<memory:32768, vCores:32>
2014-05-05 04:20:51,522 INFO org.apache.hadoop.yarn.server.resourcemanager.scheduler.capacity.ParentQueue: Re-sorting assigned queue: root.default stats: default: capacity=1.0, absoluteCapacity=1.0, usedResources=<memory:9216, vCores:8>usedCapacity=0.28125, absoluteUsedCapacity=0.28125, numApps=1, numContainers=8
2014-05-05 04:20:51,522 INFO org.apache.hadoop.yarn.server.resourcemanager.scheduler.capacity.ParentQueue: assignedContainer queue=root usedCapacity=0.28125 absoluteUsedCapacity=0.28125 used=<memory:9216, vCores:8> cluster=<memory:32768, vCores:32>
2014-05-05 04:20:51,523 INFO org.apache.hadoop.yarn.server.resourcemanager.rmcontainer.RMContainerImpl: container_1399263518640_0001_01_000010 Container Transitioned from NEW to ALLOCATED
2014-05-05 04:20:51,523 INFO org.apache.hadoop.yarn.server.resourcemanager.RMAuditLogger: USER=ubuntu	OPERATION=AM Allocated Container	TARGET=SchedulerApp	RESULT=SUCCESS	APPID=application_1399263518640_0001	CONTAINERID=container_1399263518640_0001_01_000010
2014-05-05 04:20:51,523 INFO org.apache.hadoop.yarn.server.resourcemanager.scheduler.common.fica.FiCaSchedulerNode: Assigned container container_1399263518640_0001_01_000010 of capacity <memory:1024, vCores:1> on host nodea:44426, which currently has 2 containers, <memory:2048, vCores:2> used and <memory:6144, vCores:6> available
2014-05-05 04:20:51,523 INFO org.apache.hadoop.yarn.server.resourcemanager.scheduler.capacity.LeafQueue: assignedContainer application=application_1399263518640_0001 container=Container: [ContainerId: container_1399263518640_0001_01_000010, NodeId: nodea:44426, NodeHttpAddress: nodea:8042, Resource: <memory:1024, vCores:1>, Priority: 10, Token: Token { kind: ContainerToken, service: 10.0.0.158:44426 }, ] containerId=container_1399263518640_0001_01_000010 queue=default: capacity=1.0, absoluteCapacity=1.0, usedResources=<memory:9216, vCores:8>usedCapacity=0.28125, absoluteUsedCapacity=0.28125, numApps=1, numContainers=8 usedCapacity=0.28125 absoluteUsedCapacity=0.28125 used=<memory:9216, vCores:8> cluster=<memory:32768, vCores:32>
2014-05-05 04:20:51,523 INFO org.apache.hadoop.yarn.server.resourcemanager.scheduler.capacity.ParentQueue: Re-sorting assigned queue: root.default stats: default: capacity=1.0, absoluteCapacity=1.0, usedResources=<memory:10240, vCores:9>usedCapacity=0.3125, absoluteUsedCapacity=0.3125, numApps=1, numContainers=9
2014-05-05 04:20:51,523 INFO org.apache.hadoop.yarn.server.resourcemanager.scheduler.capacity.ParentQueue: assignedContainer queue=root usedCapacity=0.3125 absoluteUsedCapacity=0.3125 used=<memory:10240, vCores:9> cluster=<memory:32768, vCores:32>
2014-05-05 04:20:52,032 INFO org.apache.hadoop.yarn.server.resourcemanager.rmcontainer.RMContainerImpl: container_1399263518640_0001_01_000011 Container Transitioned from NEW to ALLOCATED
2014-05-05 04:20:52,032 INFO org.apache.hadoop.yarn.server.resourcemanager.RMAuditLogger: USER=ubuntu	OPERATION=AM Allocated Container	TARGET=SchedulerApp	RESULT=SUCCESS	APPID=application_1399263518640_0001	CONTAINERID=container_1399263518640_0001_01_000011
2014-05-05 04:20:52,032 INFO org.apache.hadoop.yarn.server.resourcemanager.scheduler.common.fica.FiCaSchedulerNode: Assigned container container_1399263518640_0001_01_000011 of capacity <memory:1024, vCores:1> on host nodec:35640, which currently has 1 containers, <memory:1024, vCores:1> used and <memory:7168, vCores:7> available
2014-05-05 04:20:52,032 INFO org.apache.hadoop.yarn.server.resourcemanager.scheduler.capacity.LeafQueue: assignedContainer application=application_1399263518640_0001 container=Container: [ContainerId: container_1399263518640_0001_01_000011, NodeId: nodec:35640, NodeHttpAddress: nodec:8042, Resource: <memory:1024, vCores:1>, Priority: 10, Token: Token { kind: ContainerToken, service: 10.0.0.181:35640 }, ] containerId=container_1399263518640_0001_01_000011 queue=default: capacity=1.0, absoluteCapacity=1.0, usedResources=<memory:10240, vCores:9>usedCapacity=0.3125, absoluteUsedCapacity=0.3125, numApps=1, numContainers=9 usedCapacity=0.3125 absoluteUsedCapacity=0.3125 used=<memory:10240, vCores:9> cluster=<memory:32768, vCores:32>
2014-05-05 04:20:52,032 INFO org.apache.hadoop.yarn.server.resourcemanager.scheduler.capacity.ParentQueue: Re-sorting assigned queue: root.default stats: default: capacity=1.0, absoluteCapacity=1.0, usedResources=<memory:11264, vCores:10>usedCapacity=0.34375, absoluteUsedCapacity=0.34375, numApps=1, numContainers=10
2014-05-05 04:20:52,032 INFO org.apache.hadoop.yarn.server.resourcemanager.scheduler.capacity.ParentQueue: assignedContainer queue=root usedCapacity=0.34375 absoluteUsedCapacity=0.34375 used=<memory:11264, vCores:10> cluster=<memory:32768, vCores:32>
