2014-04-21 18:03:59,667 INFO org.apache.hadoop.yarn.server.resourcemanager.ResourceManager: STARTUP_MSG: 
/************************************************************
STARTUP_MSG: Starting ResourceManager
STARTUP_MSG:   host = ip-10-0-0-54/10.0.0.54
STARTUP_MSG:   args = []
STARTUP_MSG:   version = 2.2.0
STARTUP_MSG:   build = Unknown -r Unknown; compiled by 'root' on 2014-04-19T21:33Z
STARTUP_MSG:   java = 1.7.0_51
************************************************************/
2014-04-21 18:03:59,678 INFO org.apache.hadoop.yarn.server.resourcemanager.ResourceManager: registered UNIX signal handlers for [TERM, HUP, INT]
2014-04-21 18:04:00,123 INFO org.apache.hadoop.yarn.server.resourcemanager.security.AMRMTokenSecretManager: Rolling master-key for amrm-tokens
2014-04-21 18:04:00,172 INFO org.apache.hadoop.yarn.server.resourcemanager.security.RMContainerTokenSecretManager: ContainerTokenKeyRollingInterval: 86400000ms and ContainerTokenKeyActivationDelay: 900000ms
2014-04-21 18:04:00,179 INFO org.apache.hadoop.yarn.server.resourcemanager.security.NMTokenSecretManagerInRM: NMTokenKeyRollingInterval: 86400000ms and NMTokenKeyActivationDelay: 900000ms
2014-04-21 18:04:00,205 INFO org.apache.hadoop.yarn.event.AsyncDispatcher: Registering class org.apache.hadoop.yarn.server.resourcemanager.recovery.RMStateStoreEventType for class org.apache.hadoop.yarn.server.resourcemanager.recovery.RMStateStore$ForwardingEventHandler
2014-04-21 18:04:01,022 WARN org.apache.hadoop.util.NativeCodeLoader: Unable to load native-hadoop library for your platform... using builtin-java classes where applicable
2014-04-21 18:04:01,176 INFO org.apache.hadoop.yarn.event.AsyncDispatcher: Registering class org.apache.hadoop.yarn.server.resourcemanager.NodesListManagerEventType for class org.apache.hadoop.yarn.server.resourcemanager.NodesListManager
2014-04-21 18:04:01,303 INFO org.apache.hadoop.yarn.server.resourcemanager.ResourceManager: Using Scheduler: org.apache.hadoop.yarn.server.resourcemanager.scheduler.capacity.CapacityScheduler
2014-04-21 18:04:01,670 INFO org.apache.hadoop.yarn.event.AsyncDispatcher: Registering class org.apache.hadoop.yarn.server.resourcemanager.scheduler.event.SchedulerEventType for class org.apache.hadoop.yarn.server.resourcemanager.ResourceManager$SchedulerEventDispatcher
2014-04-21 18:04:01,677 INFO org.apache.hadoop.yarn.event.AsyncDispatcher: Registering class org.apache.hadoop.yarn.server.resourcemanager.rmapp.RMAppEventType for class org.apache.hadoop.yarn.server.resourcemanager.ResourceManager$ApplicationEventDispatcher
2014-04-21 18:04:01,679 INFO org.apache.hadoop.yarn.event.AsyncDispatcher: Registering class org.apache.hadoop.yarn.server.resourcemanager.rmapp.attempt.RMAppAttemptEventType for class org.apache.hadoop.yarn.server.resourcemanager.ResourceManager$ApplicationAttemptEventDispatcher
2014-04-21 18:04:01,681 INFO org.apache.hadoop.yarn.event.AsyncDispatcher: Registering class org.apache.hadoop.yarn.server.resourcemanager.rmnode.RMNodeEventType for class org.apache.hadoop.yarn.server.resourcemanager.ResourceManager$NodeEventDispatcher
2014-04-21 18:04:02,113 INFO org.apache.hadoop.metrics2.impl.MetricsConfig: loaded properties from hadoop-metrics2.properties
2014-04-21 18:04:02,310 INFO org.apache.hadoop.metrics2.impl.MetricsSystemImpl: Scheduled snapshot period at 10 second(s).
2014-04-21 18:04:02,310 INFO org.apache.hadoop.metrics2.impl.MetricsSystemImpl: ResourceManager metrics system started
2014-04-21 18:04:02,540 INFO org.apache.hadoop.yarn.server.resourcemanager.scheduler.capacity.ParentQueue: root, capacity=1.0, asboluteCapacity=1.0, maxCapacity=1.0, asboluteMaxCapacity=1.0, state=RUNNING, acls=ADMINISTER_QUEUE:*SUBMIT_APPLICATIONS:*
2014-04-21 18:04:02,540 INFO org.apache.hadoop.yarn.server.resourcemanager.scheduler.capacity.ParentQueue: Initialized parent-queue root name=root, fullname=root
2014-04-21 18:04:02,629 INFO org.apache.hadoop.yarn.server.resourcemanager.scheduler.capacity.LeafQueue: Initializing default
capacity = 1.0 [= (float) configuredCapacity / 100 ]
asboluteCapacity = 1.0 [= parentAbsoluteCapacity * capacity ]
maxCapacity = 1.0 [= configuredMaxCapacity ]
absoluteMaxCapacity = 1.0 [= 1.0 maximumCapacity undefined, (parentAbsoluteMaxCapacity * maximumCapacity) / 100 otherwise ]
userLimit = 100 [= configuredUserLimit ]
userLimitFactor = 1.0 [= configuredUserLimitFactor ]
maxApplications = 10000 [= configuredMaximumSystemApplicationsPerQueue or (int)(configuredMaximumSystemApplications * absoluteCapacity)]
maxApplicationsPerUser = 10000 [= (int)(maxApplications * (userLimit / 100.0f) * userLimitFactor) ]
maxActiveApplications = 1 [= max((int)ceil((clusterResourceMemory / minimumAllocation) * maxAMResourcePerQueuePercent * absoluteMaxCapacity),1) ]
maxActiveAppsUsingAbsCap = 1 [= max((int)ceil((clusterResourceMemory / minimumAllocation) *maxAMResourcePercent * absoluteCapacity),1) ]
maxActiveApplicationsPerUser = 1 [= max((int)(maxActiveApplications * (userLimit / 100.0f) * userLimitFactor),1) ]
usedCapacity = 0.0 [= usedResourcesMemory / (clusterResourceMemory * absoluteCapacity)]
absoluteUsedCapacity = 0.0 [= usedResourcesMemory / clusterResourceMemory]
maxAMResourcePerQueuePercent = 0.1 [= configuredMaximumAMResourcePercent ]
minimumAllocationFactor = 0.875 [= (float)(maximumAllocationMemory - minimumAllocationMemory) / maximumAllocationMemory ]
numContainers = 0 [= currentNumContainers ]
state = RUNNING [= configuredState ]
acls = ADMINISTER_QUEUE:*SUBMIT_APPLICATIONS:* [= configuredAcls ]
nodeLocalityDelay = 0

2014-04-21 18:04:02,629 INFO org.apache.hadoop.yarn.server.resourcemanager.scheduler.capacity.CapacityScheduler: Initialized queue: default: capacity=1.0, absoluteCapacity=1.0, usedResources=<memory:0, vCores:0>usedCapacity=0.0, absoluteUsedCapacity=0.0, numApps=0, numContainers=0
2014-04-21 18:04:02,629 INFO org.apache.hadoop.yarn.server.resourcemanager.scheduler.capacity.CapacityScheduler: Initialized queue: root: numChildQueue= 1, capacity=1.0, absoluteCapacity=1.0, usedResources=<memory:0, vCores:0>usedCapacity=0.0, numApps=0, numContainers=0
2014-04-21 18:04:02,629 INFO org.apache.hadoop.yarn.server.resourcemanager.scheduler.capacity.CapacityScheduler: Initialized root queue root: numChildQueue= 1, capacity=1.0, absoluteCapacity=1.0, usedResources=<memory:0, vCores:0>usedCapacity=0.0, numApps=0, numContainers=0
2014-04-21 18:04:02,630 INFO org.apache.hadoop.yarn.server.resourcemanager.scheduler.capacity.CapacityScheduler: Initialized CapacityScheduler with calculator=class org.apache.hadoop.yarn.util.resource.DefaultResourceCalculator, minimumAllocation=<<memory:1024, vCores:1>>, maximumAllocation=<<memory:8192, vCores:32>>
2014-04-21 18:04:02,819 INFO org.apache.hadoop.yarn.event.AsyncDispatcher: Registering class org.apache.hadoop.yarn.server.resourcemanager.RMAppManagerEventType for class org.apache.hadoop.yarn.server.resourcemanager.RMAppManager
2014-04-21 18:04:02,863 INFO org.apache.hadoop.yarn.event.AsyncDispatcher: Registering class org.apache.hadoop.yarn.server.resourcemanager.amlauncher.AMLauncherEventType for class org.apache.hadoop.yarn.server.resourcemanager.amlauncher.ApplicationMasterLauncher
2014-04-21 18:04:02,869 INFO org.apache.hadoop.yarn.server.resourcemanager.RMNMInfo: Registered RMNMInfo MBean
2014-04-21 18:04:02,872 INFO org.apache.hadoop.util.HostsFileReader: Refreshing hosts (include/exclude) list
2014-04-21 18:04:02,892 INFO org.apache.hadoop.yarn.server.resourcemanager.security.AMRMTokenSecretManager: Rolling master-key for amrm-tokens
2014-04-21 18:04:02,892 INFO org.apache.hadoop.yarn.server.resourcemanager.security.RMContainerTokenSecretManager: Rolling master-key for container-tokens
2014-04-21 18:04:02,896 INFO org.apache.hadoop.yarn.server.resourcemanager.security.NMTokenSecretManagerInRM: Rolling master-key for nm-tokens
2014-04-21 18:04:03,006 INFO org.mortbay.log: Logging to org.slf4j.impl.Log4jLoggerAdapter(org.mortbay.log) via org.mortbay.log.Slf4jLog
2014-04-21 18:04:03,093 INFO org.apache.hadoop.http.HttpServer: Added global filter 'safety' (class=org.apache.hadoop.http.HttpServer$QuotingInputFilter)
2014-04-21 18:04:03,098 INFO org.apache.hadoop.http.HttpServer: Added filter static_user_filter (class=org.apache.hadoop.http.lib.StaticUserWebFilter$StaticUserFilter) to context cluster
2014-04-21 18:04:03,098 INFO org.apache.hadoop.http.HttpServer: Added filter static_user_filter (class=org.apache.hadoop.http.lib.StaticUserWebFilter$StaticUserFilter) to context logs
2014-04-21 18:04:03,098 INFO org.apache.hadoop.http.HttpServer: Added filter static_user_filter (class=org.apache.hadoop.http.lib.StaticUserWebFilter$StaticUserFilter) to context static
2014-04-21 18:04:03,105 INFO org.apache.hadoop.http.HttpServer: adding path spec: /cluster/*
2014-04-21 18:04:03,105 INFO org.apache.hadoop.http.HttpServer: adding path spec: /ws/*
2014-04-21 18:04:03,118 INFO org.apache.hadoop.http.HttpServer: Jetty bound to port 8088
2014-04-21 18:04:03,118 INFO org.mortbay.log: jetty-6.1.26
2014-04-21 18:04:03,180 INFO org.mortbay.log: Extract jar:file:/home/ubuntu/PatchedDistro/hadoop-patch/share/hadoop/yarn/hadoop-yarn-common-2.2.0.jar!/webapps/cluster to /tmp/Jetty_ec2.54.187.121.79_us.west.2_compute_amazonaws_com_8088_cluster____.pw60rv/webapp
2014-04-21 18:04:03,896 INFO org.mortbay.log: Started SelectChannelConnector@ec2-54-187-121-79.us-west-2.compute.amazonaws.com:8088
2014-04-21 18:04:03,896 INFO org.apache.hadoop.yarn.webapp.WebApps: Web app /cluster started at 8088
2014-04-21 18:04:04,994 INFO org.apache.hadoop.yarn.webapp.WebApps: Registered webapp guice modules
2014-04-21 18:04:04,996 INFO org.apache.hadoop.security.token.delegation.AbstractDelegationTokenSecretManager: Updating the current master key for generating delegation tokens
2014-04-21 18:04:04,998 INFO org.apache.hadoop.yarn.server.resourcemanager.security.RMDelegationTokenSecretManager: storing master key with keyID 1
2014-04-21 18:04:04,999 INFO org.apache.hadoop.security.token.delegation.AbstractDelegationTokenSecretManager: Starting expired delegation token remover thread, tokenRemoverScanInterval=60 min(s)
2014-04-21 18:04:04,999 INFO org.apache.hadoop.security.token.delegation.AbstractDelegationTokenSecretManager: Updating the current master key for generating delegation tokens
2014-04-21 18:04:04,999 INFO org.apache.hadoop.yarn.server.resourcemanager.security.RMDelegationTokenSecretManager: storing master key with keyID 2
2014-04-21 18:04:05,055 INFO org.apache.hadoop.ipc.Server: Starting Socket Reader #1 for port 8031
2014-04-21 18:04:05,083 INFO org.apache.hadoop.yarn.factories.impl.pb.RpcServerFactoryPBImpl: Adding protocol org.apache.hadoop.yarn.server.api.ResourceTrackerPB to the server
2014-04-21 18:04:05,083 INFO org.apache.hadoop.ipc.Server: IPC Server Responder: starting
2014-04-21 18:04:05,085 INFO org.apache.hadoop.ipc.Server: IPC Server listener on 8031: starting
2014-04-21 18:04:05,172 INFO org.apache.hadoop.ipc.Server: Starting Socket Reader #1 for port 8030
2014-04-21 18:04:05,259 INFO org.apache.hadoop.yarn.factories.impl.pb.RpcServerFactoryPBImpl: Adding protocol org.apache.hadoop.yarn.api.ApplicationMasterProtocolPB to the server
2014-04-21 18:04:05,260 INFO org.apache.hadoop.ipc.Server: IPC Server Responder: starting
2014-04-21 18:04:05,260 INFO org.apache.hadoop.ipc.Server: IPC Server listener on 8030: starting
2014-04-21 18:04:05,390 INFO org.apache.hadoop.yarn.factories.impl.pb.RpcServerFactoryPBImpl: Adding protocol org.apache.hadoop.yarn.api.ApplicationClientProtocolPB to the server
2014-04-21 18:04:05,390 INFO org.apache.hadoop.ipc.Server: Starting Socket Reader #1 for port 8032
2014-04-21 18:04:05,391 INFO org.apache.hadoop.ipc.Server: IPC Server Responder: starting
2014-04-21 18:04:05,391 INFO org.apache.hadoop.ipc.Server: IPC Server listener on 8032: starting
2014-04-21 18:04:05,460 INFO org.apache.hadoop.yarn.factories.impl.pb.RpcServerFactoryPBImpl: Adding protocol org.apache.hadoop.yarn.server.api.ResourceManagerAdministrationProtocolPB to the server
2014-04-21 18:04:05,460 INFO org.apache.hadoop.ipc.Server: Starting Socket Reader #1 for port 8033
2014-04-21 18:04:05,460 INFO org.apache.hadoop.ipc.Server: IPC Server Responder: starting
2014-04-21 18:04:05,465 INFO org.apache.hadoop.ipc.Server: IPC Server listener on 8033: starting
2014-04-21 18:04:05,674 INFO org.apache.hadoop.yarn.util.RackResolver: Resolved nodeb to /default-rack
2014-04-21 18:04:05,682 INFO org.apache.hadoop.yarn.util.RackResolver: Resolved nodec to /default-rack
2014-04-21 18:04:05,693 INFO org.apache.hadoop.yarn.server.resourcemanager.rmnode.RMNodeImpl: nodeb:58333 Node Transitioned from NEW to RUNNING
2014-04-21 18:04:05,693 INFO org.apache.hadoop.yarn.server.resourcemanager.rmnode.RMNodeImpl: nodec:34990 Node Transitioned from NEW to RUNNING
2014-04-21 18:04:05,694 INFO org.apache.hadoop.yarn.server.resourcemanager.ResourceTrackerService: NodeManager from node nodeb(cmPort: 58333 httpPort: 8042) registered with capability: <memory:8192, vCores:8>, assigned nodeId nodeb:58333
2014-04-21 18:04:05,702 INFO org.apache.hadoop.yarn.server.resourcemanager.scheduler.capacity.CapacityScheduler: Added node nodeb:58333 clusterResource: <memory:8192, vCores:8>
2014-04-21 18:04:05,702 INFO org.apache.hadoop.yarn.server.resourcemanager.scheduler.capacity.CapacityScheduler: Added node nodec:34990 clusterResource: <memory:16384, vCores:16>
2014-04-21 18:04:05,702 INFO org.apache.hadoop.yarn.server.resourcemanager.ResourceTrackerService: NodeManager from node nodec(cmPort: 34990 httpPort: 8042) registered with capability: <memory:8192, vCores:8>, assigned nodeId nodec:34990
2014-04-21 18:04:05,719 INFO org.apache.hadoop.yarn.util.RackResolver: Resolved noded to /default-rack
2014-04-21 18:04:05,719 INFO org.apache.hadoop.yarn.server.resourcemanager.ResourceTrackerService: NodeManager from node noded(cmPort: 47267 httpPort: 8042) registered with capability: <memory:8192, vCores:8>, assigned nodeId noded:47267
2014-04-21 18:04:05,719 INFO org.apache.hadoop.yarn.server.resourcemanager.rmnode.RMNodeImpl: noded:47267 Node Transitioned from NEW to RUNNING
2014-04-21 18:04:05,720 INFO org.apache.hadoop.yarn.server.resourcemanager.scheduler.capacity.CapacityScheduler: Added node noded:47267 clusterResource: <memory:24576, vCores:24>
2014-04-21 18:04:07,367 INFO org.apache.hadoop.yarn.util.RackResolver: Resolved nodea to /default-rack
2014-04-21 18:04:07,367 INFO org.apache.hadoop.yarn.server.resourcemanager.ResourceTrackerService: NodeManager from node nodea(cmPort: 47962 httpPort: 8042) registered with capability: <memory:8192, vCores:8>, assigned nodeId nodea:47962
2014-04-21 18:04:07,367 INFO org.apache.hadoop.yarn.server.resourcemanager.rmnode.RMNodeImpl: nodea:47962 Node Transitioned from NEW to RUNNING
2014-04-21 18:04:07,368 INFO org.apache.hadoop.yarn.server.resourcemanager.scheduler.capacity.CapacityScheduler: Added node nodea:47962 clusterResource: <memory:32768, vCores:32>
2014-04-21 18:59:25,660 INFO org.apache.hadoop.yarn.server.resourcemanager.ClientRMService: Allocated new applicationId: 1
2014-04-21 18:59:27,595 INFO org.apache.hadoop.yarn.server.resourcemanager.ClientRMService: Application with id 1 submitted by user ubuntu
2014-04-21 18:59:27,597 INFO org.apache.hadoop.yarn.server.resourcemanager.rmapp.RMAppImpl: Storing application with id application_1398103439608_0001
2014-04-21 18:59:27,598 INFO org.apache.hadoop.yarn.server.resourcemanager.RMAuditLogger: USER=ubuntu	IP=10.0.0.54	OPERATION=Submit Application Request	TARGET=ClientRMService	RESULT=SUCCESS	APPID=application_1398103439608_0001
2014-04-21 18:59:27,599 INFO org.apache.hadoop.yarn.server.resourcemanager.rmapp.RMAppImpl: application_1398103439608_0001 State change from NEW to NEW_SAVING
2014-04-21 18:59:27,607 INFO org.apache.hadoop.yarn.server.resourcemanager.recovery.RMStateStore: Storing info for app: application_1398103439608_0001
2014-04-21 18:59:27,629 INFO org.apache.hadoop.yarn.server.resourcemanager.rmapp.RMAppImpl: application_1398103439608_0001 State change from NEW_SAVING to SUBMITTED
2014-04-21 18:59:27,637 INFO org.apache.hadoop.yarn.server.resourcemanager.ApplicationMasterService: Registering app attempt : appattempt_1398103439608_0001_000001
2014-04-21 18:59:27,670 INFO org.apache.hadoop.yarn.server.resourcemanager.rmapp.attempt.RMAppAttemptImpl: appattempt_1398103439608_0001_000001 State change from NEW to SUBMITTED
2014-04-21 18:59:27,704 INFO org.apache.hadoop.yarn.server.resourcemanager.scheduler.capacity.LeafQueue: Application application_1398103439608_0001 from user: ubuntu activated in queue: default
2014-04-21 18:59:27,704 INFO org.apache.hadoop.yarn.server.resourcemanager.scheduler.capacity.LeafQueue: Application added - appId: application_1398103439608_0001 user: org.apache.hadoop.yarn.server.resourcemanager.scheduler.capacity.LeafQueue$User@1403c543, leaf-queue: default #user-pending-applications: 0 #user-active-applications: 1 #queue-pending-applications: 0 #queue-active-applications: 1
2014-04-21 18:59:27,705 INFO org.apache.hadoop.yarn.server.resourcemanager.scheduler.capacity.ParentQueue: Application added - appId: application_1398103439608_0001 user: ubuntu leaf-queue of parent: root #applications: 1
2014-04-21 18:59:27,705 INFO org.apache.hadoop.yarn.server.resourcemanager.scheduler.capacity.CapacityScheduler: Application Submission: appattempt_1398103439608_0001_000001, user: ubuntu queue: default: capacity=1.0, absoluteCapacity=1.0, usedResources=<memory:0, vCores:0>usedCapacity=0.0, absoluteUsedCapacity=0.0, numApps=1, numContainers=0, currently active: 1
2014-04-21 18:59:27,706 INFO org.apache.hadoop.yarn.server.resourcemanager.rmapp.attempt.RMAppAttemptImpl: appattempt_1398103439608_0001_000001 State change from SUBMITTED to SCHEDULED
2014-04-21 18:59:27,706 INFO org.apache.hadoop.yarn.server.resourcemanager.rmapp.RMAppImpl: application_1398103439608_0001 State change from SUBMITTED to ACCEPTED
2014-04-21 18:59:27,929 INFO org.apache.hadoop.yarn.server.resourcemanager.rmcontainer.RMContainerImpl: container_1398103439608_0001_01_000001 Container Transitioned from NEW to ALLOCATED
2014-04-21 18:59:27,929 INFO org.apache.hadoop.yarn.server.resourcemanager.RMAuditLogger: USER=ubuntu	OPERATION=AM Allocated Container	TARGET=SchedulerApp	RESULT=SUCCESS	APPID=application_1398103439608_0001	CONTAINERID=container_1398103439608_0001_01_000001
2014-04-21 18:59:27,930 INFO org.apache.hadoop.yarn.server.resourcemanager.scheduler.common.fica.FiCaSchedulerNode: Assigned container container_1398103439608_0001_01_000001 of capacity <memory:2048, vCores:1> on host nodeb:58333, which currently has 1 containers, <memory:2048, vCores:1> used and <memory:6144, vCores:7> available
2014-04-21 18:59:27,930 INFO org.apache.hadoop.yarn.server.resourcemanager.scheduler.capacity.LeafQueue: assignedContainer application=application_1398103439608_0001 container=Container: [ContainerId: container_1398103439608_0001_01_000001, NodeId: nodeb:58333, NodeHttpAddress: nodeb:8042, Resource: <memory:2048, vCores:1>, Priority: 0, Token: Token { kind: ContainerToken, service: 10.0.0.199:58333 }, ] containerId=container_1398103439608_0001_01_000001 queue=default: capacity=1.0, absoluteCapacity=1.0, usedResources=<memory:0, vCores:0>usedCapacity=0.0, absoluteUsedCapacity=0.0, numApps=1, numContainers=0 usedCapacity=0.0 absoluteUsedCapacity=0.0 used=<memory:0, vCores:0> cluster=<memory:32768, vCores:32>
2014-04-21 18:59:27,930 INFO org.apache.hadoop.yarn.server.resourcemanager.scheduler.capacity.ParentQueue: Re-sorting assigned queue: root.default stats: default: capacity=1.0, absoluteCapacity=1.0, usedResources=<memory:2048, vCores:1>usedCapacity=0.0625, absoluteUsedCapacity=0.0625, numApps=1, numContainers=1
2014-04-21 18:59:27,932 INFO org.apache.hadoop.yarn.server.resourcemanager.rmcontainer.RMContainerImpl: container_1398103439608_0001_01_000001 Container Transitioned from ALLOCATED to ACQUIRED
2014-04-21 18:59:27,936 INFO org.apache.hadoop.yarn.server.resourcemanager.scheduler.capacity.ParentQueue: assignedContainer queue=root usedCapacity=0.0625 absoluteUsedCapacity=0.0625 used=<memory:2048, vCores:1> cluster=<memory:32768, vCores:32>
2014-04-21 18:59:27,936 INFO org.apache.hadoop.yarn.server.resourcemanager.rmapp.attempt.RMAppAttemptImpl: Storing attempt: AppId: application_1398103439608_0001 AttemptId: appattempt_1398103439608_0001_000001 MasterContainer: Container: [ContainerId: container_1398103439608_0001_01_000001, NodeId: nodeb:58333, NodeHttpAddress: nodeb:8042, Resource: <memory:2048, vCores:1>, Priority: 0, Token: Token { kind: ContainerToken, service: 10.0.0.199:58333 }, ]
2014-04-21 18:59:27,942 INFO org.apache.hadoop.yarn.server.resourcemanager.rmapp.attempt.RMAppAttemptImpl: appattempt_1398103439608_0001_000001 State change from SCHEDULED to ALLOCATED_SAVING
2014-04-21 18:59:27,952 INFO org.apache.hadoop.yarn.server.resourcemanager.recovery.RMStateStore: Storing info for attempt: appattempt_1398103439608_0001_000001
2014-04-21 18:59:27,954 INFO org.apache.hadoop.yarn.server.resourcemanager.rmapp.attempt.RMAppAttemptImpl: appattempt_1398103439608_0001_000001 State change from ALLOCATED_SAVING to ALLOCATED
2014-04-21 18:59:27,959 INFO org.apache.hadoop.yarn.server.resourcemanager.amlauncher.AMLauncher: Launching masterappattempt_1398103439608_0001_000001
2014-04-21 18:59:28,009 INFO org.apache.hadoop.yarn.server.resourcemanager.amlauncher.AMLauncher: Setting up container Container: [ContainerId: container_1398103439608_0001_01_000001, NodeId: nodeb:58333, NodeHttpAddress: nodeb:8042, Resource: <memory:2048, vCores:1>, Priority: 0, Token: Token { kind: ContainerToken, service: 10.0.0.199:58333 }, ] for AM appattempt_1398103439608_0001_000001
2014-04-21 18:59:28,010 INFO org.apache.hadoop.yarn.server.resourcemanager.amlauncher.AMLauncher: Command to launch container container_1398103439608_0001_01_000001 : $JAVA_HOME/bin/java -Dlog4j.configuration=container-log4j.properties -Dyarn.app.container.log.dir=<LOG_DIR> -Dyarn.app.container.log.filesize=0 -Dhadoop.root.logger=INFO,CLA  -Xmx1024m org.apache.hadoop.mapreduce.v2.app.MRAppMaster 1><LOG_DIR>/stdout 2><LOG_DIR>/stderr 
2014-04-21 18:59:28,480 INFO org.apache.hadoop.yarn.server.resourcemanager.amlauncher.AMLauncher: Done launching container Container: [ContainerId: container_1398103439608_0001_01_000001, NodeId: nodeb:58333, NodeHttpAddress: nodeb:8042, Resource: <memory:2048, vCores:1>, Priority: 0, Token: Token { kind: ContainerToken, service: 10.0.0.199:58333 }, ] for AM appattempt_1398103439608_0001_000001
2014-04-21 18:59:28,481 INFO org.apache.hadoop.yarn.server.resourcemanager.rmapp.attempt.RMAppAttemptImpl: appattempt_1398103439608_0001_000001 State change from ALLOCATED to LAUNCHED
2014-04-21 18:59:28,937 INFO org.apache.hadoop.yarn.server.resourcemanager.rmcontainer.RMContainerImpl: container_1398103439608_0001_01_000001 Container Transitioned from ACQUIRED to RUNNING
2014-04-21 18:59:36,862 INFO SecurityLogger.org.apache.hadoop.ipc.Server: Auth successful for appattempt_1398103439608_0001_000001 (auth:SIMPLE)
2014-04-21 18:59:36,875 INFO org.apache.hadoop.yarn.server.resourcemanager.ApplicationMasterService: AM registration appattempt_1398103439608_0001_000001
2014-04-21 18:59:36,876 INFO org.apache.hadoop.yarn.server.resourcemanager.RMAuditLogger: USER=ubuntu	IP=10.0.0.199	OPERATION=Register App Master	TARGET=ApplicationMasterService	RESULT=SUCCESS	APPID=application_1398103439608_0001	APPATTEMPTID=appattempt_1398103439608_0001_000001
2014-04-21 18:59:36,877 INFO org.apache.hadoop.yarn.server.resourcemanager.rmapp.attempt.RMAppAttemptImpl: appattempt_1398103439608_0001_000001 State change from LAUNCHED to RUNNING
2014-04-21 18:59:36,877 INFO org.apache.hadoop.yarn.server.resourcemanager.rmapp.RMAppImpl: application_1398103439608_0001 State change from ACCEPTED to RUNNING
2014-04-21 18:59:37,963 INFO org.apache.hadoop.yarn.server.resourcemanager.rmcontainer.RMContainerImpl: container_1398103439608_0001_01_000002 Container Transitioned from NEW to ALLOCATED
2014-04-21 18:59:37,964 INFO org.apache.hadoop.yarn.server.resourcemanager.RMAuditLogger: USER=ubuntu	OPERATION=AM Allocated Container	TARGET=SchedulerApp	RESULT=SUCCESS	APPID=application_1398103439608_0001	CONTAINERID=container_1398103439608_0001_01_000002
2014-04-21 18:59:37,964 INFO org.apache.hadoop.yarn.server.resourcemanager.scheduler.common.fica.FiCaSchedulerNode: Assigned container container_1398103439608_0001_01_000002 of capacity <memory:1024, vCores:1> on host nodeb:58333, which currently has 2 containers, <memory:3072, vCores:2> used and <memory:5120, vCores:6> available
2014-04-21 18:59:37,964 INFO org.apache.hadoop.yarn.server.resourcemanager.scheduler.capacity.LeafQueue: assignedContainer application=application_1398103439608_0001 container=Container: [ContainerId: container_1398103439608_0001_01_000002, NodeId: nodeb:58333, NodeHttpAddress: nodeb:8042, Resource: <memory:1024, vCores:1>, Priority: 20, Token: Token { kind: ContainerToken, service: 10.0.0.199:58333 }, ] containerId=container_1398103439608_0001_01_000002 queue=default: capacity=1.0, absoluteCapacity=1.0, usedResources=<memory:2048, vCores:1>usedCapacity=0.0625, absoluteUsedCapacity=0.0625, numApps=1, numContainers=1 usedCapacity=0.0625 absoluteUsedCapacity=0.0625 used=<memory:2048, vCores:1> cluster=<memory:32768, vCores:32>
2014-04-21 18:59:37,964 INFO org.apache.hadoop.yarn.server.resourcemanager.scheduler.capacity.ParentQueue: Re-sorting assigned queue: root.default stats: default: capacity=1.0, absoluteCapacity=1.0, usedResources=<memory:3072, vCores:2>usedCapacity=0.09375, absoluteUsedCapacity=0.09375, numApps=1, numContainers=2
2014-04-21 18:59:37,964 INFO org.apache.hadoop.yarn.server.resourcemanager.scheduler.capacity.ParentQueue: assignedContainer queue=root usedCapacity=0.09375 absoluteUsedCapacity=0.09375 used=<memory:3072, vCores:2> cluster=<memory:32768, vCores:32>
2014-04-21 18:59:39,008 INFO org.apache.hadoop.yarn.server.resourcemanager.rmcontainer.RMContainerImpl: container_1398103439608_0001_01_000002 Container Transitioned from ALLOCATED to ACQUIRED
2014-04-21 18:59:39,968 INFO org.apache.hadoop.yarn.server.resourcemanager.rmcontainer.RMContainerImpl: container_1398103439608_0001_01_000002 Container Transitioned from ACQUIRED to RUNNING
2014-04-21 18:59:40,045 INFO org.apache.hadoop.yarn.server.resourcemanager.scheduler.AppSchedulingInfo: checking for deactivate... 
2014-04-21 18:59:52,703 INFO org.apache.hadoop.yarn.server.resourcemanager.rmcontainer.RMContainerImpl: container_1398103439608_0001_01_000002 Container Transitioned from RUNNING to COMPLETED
2014-04-21 18:59:52,704 INFO org.apache.hadoop.yarn.server.resourcemanager.scheduler.common.fica.FiCaSchedulerApp: Completed container: container_1398103439608_0001_01_000002 in state: COMPLETED event:FINISHED
2014-04-21 18:59:52,704 INFO org.apache.hadoop.yarn.server.resourcemanager.RMAuditLogger: USER=ubuntu	OPERATION=AM Released Container	TARGET=SchedulerApp	RESULT=SUCCESS	APPID=application_1398103439608_0001	CONTAINERID=container_1398103439608_0001_01_000002
2014-04-21 18:59:52,704 INFO org.apache.hadoop.yarn.server.resourcemanager.scheduler.common.fica.FiCaSchedulerNode: Released container container_1398103439608_0001_01_000002 of capacity <memory:1024, vCores:1> on host nodeb:58333, which currently has 1 containers, <memory:2048, vCores:1> used and <memory:6144, vCores:7> available, release resources=true
2014-04-21 18:59:52,704 INFO org.apache.hadoop.yarn.server.resourcemanager.scheduler.capacity.LeafQueue: default used=<memory:2048, vCores:1> numContainers=1 user=ubuntu user-resources=<memory:2048, vCores:1>
2014-04-21 18:59:52,704 INFO org.apache.hadoop.yarn.server.resourcemanager.scheduler.capacity.LeafQueue: completedContainer container=Container: [ContainerId: container_1398103439608_0001_01_000002, NodeId: nodeb:58333, NodeHttpAddress: nodeb:8042, Resource: <memory:1024, vCores:1>, Priority: 20, Token: Token { kind: ContainerToken, service: 10.0.0.199:58333 }, ] resource=<memory:1024, vCores:1> queue=default: capacity=1.0, absoluteCapacity=1.0, usedResources=<memory:2048, vCores:1>usedCapacity=0.0625, absoluteUsedCapacity=0.0625, numApps=1, numContainers=1 usedCapacity=0.0625 absoluteUsedCapacity=0.0625 used=<memory:2048, vCores:1> cluster=<memory:32768, vCores:32>
2014-04-21 18:59:52,704 INFO org.apache.hadoop.yarn.server.resourcemanager.scheduler.capacity.ParentQueue: completedContainer queue=root usedCapacity=0.0625 absoluteUsedCapacity=0.0625 used=<memory:2048, vCores:1> cluster=<memory:32768, vCores:32>
2014-04-21 18:59:52,705 INFO org.apache.hadoop.yarn.server.resourcemanager.scheduler.capacity.ParentQueue: Re-sorting completed queue: root.default stats: default: capacity=1.0, absoluteCapacity=1.0, usedResources=<memory:2048, vCores:1>usedCapacity=0.0625, absoluteUsedCapacity=0.0625, numApps=1, numContainers=1
2014-04-21 18:59:52,705 INFO org.apache.hadoop.yarn.server.resourcemanager.scheduler.capacity.CapacityScheduler: Application appattempt_1398103439608_0001_000001 released container container_1398103439608_0001_01_000002 on node: host: nodeb:58333 #containers=1 available=6144 used=2048 with event: FINISHED
2014-04-21 18:59:53,705 INFO org.apache.hadoop.yarn.server.resourcemanager.rmcontainer.RMContainerImpl: container_1398103439608_0001_01_000003 Container Transitioned from NEW to ALLOCATED
2014-04-21 18:59:53,705 INFO org.apache.hadoop.yarn.server.resourcemanager.RMAuditLogger: USER=ubuntu	OPERATION=AM Allocated Container	TARGET=SchedulerApp	RESULT=SUCCESS	APPID=application_1398103439608_0001	CONTAINERID=container_1398103439608_0001_01_000003
2014-04-21 18:59:53,706 INFO org.apache.hadoop.yarn.server.resourcemanager.scheduler.common.fica.FiCaSchedulerNode: Assigned container container_1398103439608_0001_01_000003 of capacity <memory:1024, vCores:1> on host nodeb:58333, which currently has 2 containers, <memory:3072, vCores:2> used and <memory:5120, vCores:6> available
2014-04-21 18:59:53,706 INFO org.apache.hadoop.yarn.server.resourcemanager.scheduler.capacity.LeafQueue: assignedContainer application=application_1398103439608_0001 container=Container: [ContainerId: container_1398103439608_0001_01_000003, NodeId: nodeb:58333, NodeHttpAddress: nodeb:8042, Resource: <memory:1024, vCores:1>, Priority: 10, Token: Token { kind: ContainerToken, service: 10.0.0.199:58333 }, ] containerId=container_1398103439608_0001_01_000003 queue=default: capacity=1.0, absoluteCapacity=1.0, usedResources=<memory:2048, vCores:1>usedCapacity=0.0625, absoluteUsedCapacity=0.0625, numApps=1, numContainers=1 usedCapacity=0.0625 absoluteUsedCapacity=0.0625 used=<memory:2048, vCores:1> cluster=<memory:32768, vCores:32>
2014-04-21 18:59:53,706 INFO org.apache.hadoop.yarn.server.resourcemanager.scheduler.capacity.ParentQueue: Re-sorting assigned queue: root.default stats: default: capacity=1.0, absoluteCapacity=1.0, usedResources=<memory:3072, vCores:2>usedCapacity=0.09375, absoluteUsedCapacity=0.09375, numApps=1, numContainers=2
2014-04-21 18:59:53,706 INFO org.apache.hadoop.yarn.server.resourcemanager.scheduler.capacity.ParentQueue: assignedContainer queue=root usedCapacity=0.09375 absoluteUsedCapacity=0.09375 used=<memory:3072, vCores:2> cluster=<memory:32768, vCores:32>
2014-04-21 18:59:53,952 INFO org.apache.hadoop.yarn.server.resourcemanager.rmcontainer.RMContainerImpl: container_1398103439608_0001_01_000004 Container Transitioned from NEW to ALLOCATED
2014-04-21 18:59:53,952 INFO org.apache.hadoop.yarn.server.resourcemanager.RMAuditLogger: USER=ubuntu	OPERATION=AM Allocated Container	TARGET=SchedulerApp	RESULT=SUCCESS	APPID=application_1398103439608_0001	CONTAINERID=container_1398103439608_0001_01_000004
2014-04-21 18:59:53,952 INFO org.apache.hadoop.yarn.server.resourcemanager.scheduler.common.fica.FiCaSchedulerNode: Assigned container container_1398103439608_0001_01_000004 of capacity <memory:1024, vCores:1> on host nodec:34990, which currently has 1 containers, <memory:1024, vCores:1> used and <memory:7168, vCores:7> available
2014-04-21 18:59:53,952 INFO org.apache.hadoop.yarn.server.resourcemanager.scheduler.capacity.LeafQueue: assignedContainer application=application_1398103439608_0001 container=Container: [ContainerId: container_1398103439608_0001_01_000004, NodeId: nodec:34990, NodeHttpAddress: nodec:8042, Resource: <memory:1024, vCores:1>, Priority: 10, Token: Token { kind: ContainerToken, service: 10.0.0.189:34990 }, ] containerId=container_1398103439608_0001_01_000004 queue=default: capacity=1.0, absoluteCapacity=1.0, usedResources=<memory:3072, vCores:2>usedCapacity=0.09375, absoluteUsedCapacity=0.09375, numApps=1, numContainers=2 usedCapacity=0.09375 absoluteUsedCapacity=0.09375 used=<memory:3072, vCores:2> cluster=<memory:32768, vCores:32>
2014-04-21 18:59:53,953 INFO org.apache.hadoop.yarn.server.resourcemanager.scheduler.capacity.ParentQueue: Re-sorting assigned queue: root.default stats: default: capacity=1.0, absoluteCapacity=1.0, usedResources=<memory:4096, vCores:3>usedCapacity=0.125, absoluteUsedCapacity=0.125, numApps=1, numContainers=3
2014-04-21 18:59:53,953 INFO org.apache.hadoop.yarn.server.resourcemanager.scheduler.capacity.ParentQueue: assignedContainer queue=root usedCapacity=0.125 absoluteUsedCapacity=0.125 used=<memory:4096, vCores:3> cluster=<memory:32768, vCores:32>
2014-04-21 18:59:53,954 INFO org.apache.hadoop.yarn.server.resourcemanager.rmcontainer.RMContainerImpl: container_1398103439608_0001_01_000005 Container Transitioned from NEW to ALLOCATED
2014-04-21 18:59:53,954 INFO org.apache.hadoop.yarn.server.resourcemanager.RMAuditLogger: USER=ubuntu	OPERATION=AM Allocated Container	TARGET=SchedulerApp	RESULT=SUCCESS	APPID=application_1398103439608_0001	CONTAINERID=container_1398103439608_0001_01_000005
2014-04-21 18:59:53,954 INFO org.apache.hadoop.yarn.server.resourcemanager.scheduler.common.fica.FiCaSchedulerNode: Assigned container container_1398103439608_0001_01_000005 of capacity <memory:1024, vCores:1> on host noded:47267, which currently has 1 containers, <memory:1024, vCores:1> used and <memory:7168, vCores:7> available
2014-04-21 18:59:53,954 INFO org.apache.hadoop.yarn.server.resourcemanager.scheduler.capacity.LeafQueue: assignedContainer application=application_1398103439608_0001 container=Container: [ContainerId: container_1398103439608_0001_01_000005, NodeId: noded:47267, NodeHttpAddress: noded:8042, Resource: <memory:1024, vCores:1>, Priority: 10, Token: Token { kind: ContainerToken, service: 10.0.0.193:47267 }, ] containerId=container_1398103439608_0001_01_000005 queue=default: capacity=1.0, absoluteCapacity=1.0, usedResources=<memory:4096, vCores:3>usedCapacity=0.125, absoluteUsedCapacity=0.125, numApps=1, numContainers=3 usedCapacity=0.125 absoluteUsedCapacity=0.125 used=<memory:4096, vCores:3> cluster=<memory:32768, vCores:32>
2014-04-21 18:59:53,954 INFO org.apache.hadoop.yarn.server.resourcemanager.scheduler.capacity.ParentQueue: Re-sorting assigned queue: root.default stats: default: capacity=1.0, absoluteCapacity=1.0, usedResources=<memory:5120, vCores:4>usedCapacity=0.15625, absoluteUsedCapacity=0.15625, numApps=1, numContainers=4
2014-04-21 18:59:53,954 INFO org.apache.hadoop.yarn.server.resourcemanager.scheduler.capacity.ParentQueue: assignedContainer queue=root usedCapacity=0.15625 absoluteUsedCapacity=0.15625 used=<memory:5120, vCores:4> cluster=<memory:32768, vCores:32>
2014-04-21 18:59:53,962 INFO org.apache.hadoop.yarn.server.resourcemanager.rmcontainer.RMContainerImpl: container_1398103439608_0001_01_000006 Container Transitioned from NEW to ALLOCATED
2014-04-21 18:59:53,962 INFO org.apache.hadoop.yarn.server.resourcemanager.RMAuditLogger: USER=ubuntu	OPERATION=AM Allocated Container	TARGET=SchedulerApp	RESULT=SUCCESS	APPID=application_1398103439608_0001	CONTAINERID=container_1398103439608_0001_01_000006
2014-04-21 18:59:53,962 INFO org.apache.hadoop.yarn.server.resourcemanager.scheduler.common.fica.FiCaSchedulerNode: Assigned container container_1398103439608_0001_01_000006 of capacity <memory:1024, vCores:1> on host nodea:47962, which currently has 1 containers, <memory:1024, vCores:1> used and <memory:7168, vCores:7> available
2014-04-21 18:59:53,962 INFO org.apache.hadoop.yarn.server.resourcemanager.scheduler.capacity.LeafQueue: assignedContainer application=application_1398103439608_0001 container=Container: [ContainerId: container_1398103439608_0001_01_000006, NodeId: nodea:47962, NodeHttpAddress: nodea:8042, Resource: <memory:1024, vCores:1>, Priority: 10, Token: Token { kind: ContainerToken, service: 10.0.0.54:47962 }, ] containerId=container_1398103439608_0001_01_000006 queue=default: capacity=1.0, absoluteCapacity=1.0, usedResources=<memory:5120, vCores:4>usedCapacity=0.15625, absoluteUsedCapacity=0.15625, numApps=1, numContainers=4 usedCapacity=0.15625 absoluteUsedCapacity=0.15625 used=<memory:5120, vCores:4> cluster=<memory:32768, vCores:32>
2014-04-21 18:59:53,962 INFO org.apache.hadoop.yarn.server.resourcemanager.scheduler.capacity.ParentQueue: Re-sorting assigned queue: root.default stats: default: capacity=1.0, absoluteCapacity=1.0, usedResources=<memory:6144, vCores:5>usedCapacity=0.1875, absoluteUsedCapacity=0.1875, numApps=1, numContainers=5
2014-04-21 18:59:53,962 INFO org.apache.hadoop.yarn.server.resourcemanager.scheduler.capacity.ParentQueue: assignedContainer queue=root usedCapacity=0.1875 absoluteUsedCapacity=0.1875 used=<memory:6144, vCores:5> cluster=<memory:32768, vCores:32>
2014-04-21 18:59:54,113 INFO org.apache.hadoop.yarn.server.resourcemanager.rmcontainer.RMContainerImpl: container_1398103439608_0001_01_000003 Container Transitioned from ALLOCATED to ACQUIRED
2014-04-21 18:59:54,114 INFO org.apache.hadoop.yarn.server.resourcemanager.rmcontainer.RMContainerImpl: container_1398103439608_0001_01_000004 Container Transitioned from ALLOCATED to ACQUIRED
2014-04-21 18:59:54,114 INFO org.apache.hadoop.yarn.server.resourcemanager.rmcontainer.RMContainerImpl: container_1398103439608_0001_01_000005 Container Transitioned from ALLOCATED to ACQUIRED
2014-04-21 18:59:54,115 INFO org.apache.hadoop.yarn.server.resourcemanager.rmcontainer.RMContainerImpl: container_1398103439608_0001_01_000006 Container Transitioned from ALLOCATED to ACQUIRED
2014-04-21 18:59:54,708 INFO org.apache.hadoop.yarn.server.resourcemanager.rmcontainer.RMContainerImpl: container_1398103439608_0001_01_000003 Container Transitioned from ACQUIRED to RUNNING
2014-04-21 18:59:54,995 INFO org.apache.hadoop.yarn.server.resourcemanager.rmcontainer.RMContainerImpl: container_1398103439608_0001_01_000005 Container Transitioned from ACQUIRED to RUNNING
2014-04-21 18:59:56,133 INFO org.apache.hadoop.yarn.server.resourcemanager.scheduler.AppSchedulingInfo: checking for deactivate... 
2014-04-21 18:59:56,135 INFO org.apache.hadoop.yarn.server.resourcemanager.rmcontainer.RMContainerImpl: container_1398103439608_0001_01_000004 Container Transitioned from ACQUIRED to RUNNING
2014-04-21 19:00:00,662 INFO org.apache.hadoop.yarn.server.resourcemanager.rmapp.attempt.RMAppAttemptImpl: appattempt_1398103439608_0001_000001 State change from RUNNING to FINISHING
2014-04-21 19:00:00,662 INFO org.apache.hadoop.yarn.server.resourcemanager.rmapp.RMAppImpl: Removing application with id application_1398103439608_0001
2014-04-21 19:00:00,664 INFO org.apache.hadoop.yarn.server.resourcemanager.recovery.RMStateStore: Removing info for app: application_1398103439608_0001
2014-04-21 19:00:00,664 INFO org.apache.hadoop.yarn.server.resourcemanager.rmapp.RMAppImpl: application_1398103439608_0001 State change from RUNNING to REMOVING
2014-04-21 19:00:00,665 INFO org.apache.hadoop.yarn.server.resourcemanager.rmapp.RMAppImpl: application_1398103439608_0001 State change from REMOVING to FINISHING
2014-04-21 19:00:00,727 INFO org.apache.hadoop.yarn.server.resourcemanager.rmcontainer.RMContainerImpl: container_1398103439608_0001_01_000003 Container Transitioned from RUNNING to COMPLETED
2014-04-21 19:00:00,727 INFO org.apache.hadoop.yarn.server.resourcemanager.scheduler.common.fica.FiCaSchedulerApp: Completed container: container_1398103439608_0001_01_000003 in state: COMPLETED event:FINISHED
2014-04-21 19:00:00,727 INFO org.apache.hadoop.yarn.server.resourcemanager.RMAuditLogger: USER=ubuntu	OPERATION=AM Released Container	TARGET=SchedulerApp	RESULT=SUCCESS	APPID=application_1398103439608_0001	CONTAINERID=container_1398103439608_0001_01_000003
2014-04-21 19:00:00,728 INFO org.apache.hadoop.yarn.server.resourcemanager.scheduler.common.fica.FiCaSchedulerNode: Released container container_1398103439608_0001_01_000003 of capacity <memory:1024, vCores:1> on host nodeb:58333, which currently has 1 containers, <memory:2048, vCores:1> used and <memory:6144, vCores:7> available, release resources=true
2014-04-21 19:00:00,728 INFO org.apache.hadoop.yarn.server.resourcemanager.scheduler.capacity.LeafQueue: default used=<memory:5120, vCores:4> numContainers=4 user=ubuntu user-resources=<memory:5120, vCores:4>
2014-04-21 19:00:00,728 INFO org.apache.hadoop.yarn.server.resourcemanager.scheduler.capacity.LeafQueue: completedContainer container=Container: [ContainerId: container_1398103439608_0001_01_000003, NodeId: nodeb:58333, NodeHttpAddress: nodeb:8042, Resource: <memory:1024, vCores:1>, Priority: 10, Token: Token { kind: ContainerToken, service: 10.0.0.199:58333 }, ] resource=<memory:1024, vCores:1> queue=default: capacity=1.0, absoluteCapacity=1.0, usedResources=<memory:5120, vCores:4>usedCapacity=0.15625, absoluteUsedCapacity=0.15625, numApps=1, numContainers=4 usedCapacity=0.15625 absoluteUsedCapacity=0.15625 used=<memory:5120, vCores:4> cluster=<memory:32768, vCores:32>
2014-04-21 19:00:00,728 INFO org.apache.hadoop.yarn.server.resourcemanager.scheduler.capacity.ParentQueue: completedContainer queue=root usedCapacity=0.15625 absoluteUsedCapacity=0.15625 used=<memory:5120, vCores:4> cluster=<memory:32768, vCores:32>
2014-04-21 19:00:00,728 INFO org.apache.hadoop.yarn.server.resourcemanager.scheduler.capacity.ParentQueue: Re-sorting completed queue: root.default stats: default: capacity=1.0, absoluteCapacity=1.0, usedResources=<memory:5120, vCores:4>usedCapacity=0.15625, absoluteUsedCapacity=0.15625, numApps=1, numContainers=4
2014-04-21 19:00:00,728 INFO org.apache.hadoop.yarn.server.resourcemanager.scheduler.capacity.CapacityScheduler: Application appattempt_1398103439608_0001_000001 released container container_1398103439608_0001_01_000003 on node: host: nodeb:58333 #containers=1 available=6144 used=2048 with event: FINISHED
2014-04-21 19:00:01,555 INFO org.apache.hadoop.yarn.server.resourcemanager.rmcontainer.RMContainerImpl: container_1398103439608_0001_01_000005 Container Transitioned from RUNNING to COMPLETED
2014-04-21 19:00:01,555 INFO org.apache.hadoop.yarn.server.resourcemanager.scheduler.common.fica.FiCaSchedulerApp: Completed container: container_1398103439608_0001_01_000005 in state: COMPLETED event:FINISHED
2014-04-21 19:00:01,555 INFO org.apache.hadoop.yarn.server.resourcemanager.RMAuditLogger: USER=ubuntu	OPERATION=AM Released Container	TARGET=SchedulerApp	RESULT=SUCCESS	APPID=application_1398103439608_0001	CONTAINERID=container_1398103439608_0001_01_000005
2014-04-21 19:00:01,555 INFO org.apache.hadoop.yarn.server.resourcemanager.scheduler.common.fica.FiCaSchedulerNode: Released container container_1398103439608_0001_01_000005 of capacity <memory:1024, vCores:1> on host noded:47267, which currently has 0 containers, <memory:0, vCores:0> used and <memory:8192, vCores:8> available, release resources=true
2014-04-21 19:00:01,555 INFO org.apache.hadoop.yarn.server.resourcemanager.scheduler.capacity.LeafQueue: default used=<memory:4096, vCores:3> numContainers=3 user=ubuntu user-resources=<memory:4096, vCores:3>
2014-04-21 19:00:01,556 INFO org.apache.hadoop.yarn.server.resourcemanager.scheduler.capacity.LeafQueue: completedContainer container=Container: [ContainerId: container_1398103439608_0001_01_000005, NodeId: noded:47267, NodeHttpAddress: noded:8042, Resource: <memory:1024, vCores:1>, Priority: 10, Token: Token { kind: ContainerToken, service: 10.0.0.193:47267 }, ] resource=<memory:1024, vCores:1> queue=default: capacity=1.0, absoluteCapacity=1.0, usedResources=<memory:4096, vCores:3>usedCapacity=0.125, absoluteUsedCapacity=0.125, numApps=1, numContainers=3 usedCapacity=0.125 absoluteUsedCapacity=0.125 used=<memory:4096, vCores:3> cluster=<memory:32768, vCores:32>
2014-04-21 19:00:01,556 INFO org.apache.hadoop.yarn.server.resourcemanager.scheduler.capacity.ParentQueue: completedContainer queue=root usedCapacity=0.125 absoluteUsedCapacity=0.125 used=<memory:4096, vCores:3> cluster=<memory:32768, vCores:32>
2014-04-21 19:00:01,556 INFO org.apache.hadoop.yarn.server.resourcemanager.scheduler.capacity.ParentQueue: Re-sorting completed queue: root.default stats: default: capacity=1.0, absoluteCapacity=1.0, usedResources=<memory:4096, vCores:3>usedCapacity=0.125, absoluteUsedCapacity=0.125, numApps=1, numContainers=3
2014-04-21 19:00:01,556 INFO org.apache.hadoop.yarn.server.resourcemanager.scheduler.capacity.CapacityScheduler: Application appattempt_1398103439608_0001_000001 released container container_1398103439608_0001_01_000005 on node: host: noded:47267 #containers=0 available=8192 used=0 with event: FINISHED
2014-04-21 19:00:01,619 INFO org.apache.hadoop.yarn.server.resourcemanager.rmcontainer.RMContainerImpl: container_1398103439608_0001_01_000004 Container Transitioned from RUNNING to COMPLETED
2014-04-21 19:00:01,620 INFO org.apache.hadoop.yarn.server.resourcemanager.scheduler.common.fica.FiCaSchedulerApp: Completed container: container_1398103439608_0001_01_000004 in state: COMPLETED event:FINISHED
2014-04-21 19:00:01,620 INFO org.apache.hadoop.yarn.server.resourcemanager.RMAuditLogger: USER=ubuntu	OPERATION=AM Released Container	TARGET=SchedulerApp	RESULT=SUCCESS	APPID=application_1398103439608_0001	CONTAINERID=container_1398103439608_0001_01_000004
2014-04-21 19:00:01,620 INFO org.apache.hadoop.yarn.server.resourcemanager.scheduler.common.fica.FiCaSchedulerNode: Released container container_1398103439608_0001_01_000004 of capacity <memory:1024, vCores:1> on host nodec:34990, which currently has 0 containers, <memory:0, vCores:0> used and <memory:8192, vCores:8> available, release resources=true
2014-04-21 19:00:01,620 INFO org.apache.hadoop.yarn.server.resourcemanager.scheduler.capacity.LeafQueue: default used=<memory:3072, vCores:2> numContainers=2 user=ubuntu user-resources=<memory:3072, vCores:2>
2014-04-21 19:00:01,620 INFO org.apache.hadoop.yarn.server.resourcemanager.scheduler.capacity.LeafQueue: completedContainer container=Container: [ContainerId: container_1398103439608_0001_01_000004, NodeId: nodec:34990, NodeHttpAddress: nodec:8042, Resource: <memory:1024, vCores:1>, Priority: 10, Token: Token { kind: ContainerToken, service: 10.0.0.189:34990 }, ] resource=<memory:1024, vCores:1> queue=default: capacity=1.0, absoluteCapacity=1.0, usedResources=<memory:3072, vCores:2>usedCapacity=0.09375, absoluteUsedCapacity=0.09375, numApps=1, numContainers=2 usedCapacity=0.09375 absoluteUsedCapacity=0.09375 used=<memory:3072, vCores:2> cluster=<memory:32768, vCores:32>
2014-04-21 19:00:01,620 INFO org.apache.hadoop.yarn.server.resourcemanager.scheduler.capacity.ParentQueue: completedContainer queue=root usedCapacity=0.09375 absoluteUsedCapacity=0.09375 used=<memory:3072, vCores:2> cluster=<memory:32768, vCores:32>
2014-04-21 19:00:01,620 INFO org.apache.hadoop.yarn.server.resourcemanager.scheduler.capacity.ParentQueue: Re-sorting completed queue: root.default stats: default: capacity=1.0, absoluteCapacity=1.0, usedResources=<memory:3072, vCores:2>usedCapacity=0.09375, absoluteUsedCapacity=0.09375, numApps=1, numContainers=2
2014-04-21 19:00:01,620 INFO org.apache.hadoop.yarn.server.resourcemanager.scheduler.capacity.CapacityScheduler: Application appattempt_1398103439608_0001_000001 released container container_1398103439608_0001_01_000004 on node: host: nodec:34990 #containers=0 available=8192 used=0 with event: FINISHED
2014-04-21 19:00:07,757 INFO org.apache.hadoop.yarn.server.resourcemanager.rmcontainer.RMContainerImpl: container_1398103439608_0001_01_000001 Container Transitioned from RUNNING to COMPLETED
2014-04-21 19:00:07,757 INFO org.apache.hadoop.yarn.server.resourcemanager.ApplicationMasterService: Unregistering app attempt : appattempt_1398103439608_0001_000001
2014-04-21 19:00:07,757 INFO org.apache.hadoop.yarn.server.resourcemanager.scheduler.common.fica.FiCaSchedulerApp: Completed container: container_1398103439608_0001_01_000001 in state: COMPLETED event:FINISHED
2014-04-21 19:00:07,758 INFO org.apache.hadoop.yarn.server.resourcemanager.RMAuditLogger: USER=ubuntu	OPERATION=AM Released Container	TARGET=SchedulerApp	RESULT=SUCCESS	APPID=application_1398103439608_0001	CONTAINERID=container_1398103439608_0001_01_000001
2014-04-21 19:00:07,758 INFO org.apache.hadoop.yarn.server.resourcemanager.scheduler.common.fica.FiCaSchedulerNode: Released container container_1398103439608_0001_01_000001 of capacity <memory:2048, vCores:1> on host nodeb:58333, which currently has 0 containers, <memory:0, vCores:0> used and <memory:8192, vCores:8> available, release resources=true
2014-04-21 19:00:07,759 INFO org.apache.hadoop.yarn.server.resourcemanager.scheduler.capacity.LeafQueue: default used=<memory:1024, vCores:1> numContainers=1 user=ubuntu user-resources=<memory:1024, vCores:1>
2014-04-21 19:00:07,759 INFO org.apache.hadoop.yarn.server.resourcemanager.scheduler.capacity.LeafQueue: completedContainer container=Container: [ContainerId: container_1398103439608_0001_01_000001, NodeId: nodeb:58333, NodeHttpAddress: nodeb:8042, Resource: <memory:2048, vCores:1>, Priority: 0, Token: Token { kind: ContainerToken, service: 10.0.0.199:58333 }, ] resource=<memory:2048, vCores:1> queue=default: capacity=1.0, absoluteCapacity=1.0, usedResources=<memory:1024, vCores:1>usedCapacity=0.03125, absoluteUsedCapacity=0.03125, numApps=1, numContainers=1 usedCapacity=0.03125 absoluteUsedCapacity=0.03125 used=<memory:1024, vCores:1> cluster=<memory:32768, vCores:32>
2014-04-21 19:00:07,759 INFO org.apache.hadoop.yarn.server.resourcemanager.scheduler.capacity.ParentQueue: completedContainer queue=root usedCapacity=0.03125 absoluteUsedCapacity=0.03125 used=<memory:1024, vCores:1> cluster=<memory:32768, vCores:32>
2014-04-21 19:00:07,759 INFO org.apache.hadoop.yarn.server.resourcemanager.scheduler.capacity.ParentQueue: Re-sorting completed queue: root.default stats: default: capacity=1.0, absoluteCapacity=1.0, usedResources=<memory:1024, vCores:1>usedCapacity=0.03125, absoluteUsedCapacity=0.03125, numApps=1, numContainers=1
2014-04-21 19:00:07,759 INFO org.apache.hadoop.yarn.server.resourcemanager.scheduler.capacity.CapacityScheduler: Application appattempt_1398103439608_0001_000001 released container container_1398103439608_0001_01_000001 on node: host: nodeb:58333 #containers=0 available=8192 used=0 with event: FINISHED
2014-04-21 19:00:07,760 INFO org.apache.hadoop.yarn.server.resourcemanager.rmapp.attempt.RMAppAttemptImpl: appattempt_1398103439608_0001_000001 State change from FINISHING to FINISHED
2014-04-21 19:00:07,762 INFO org.apache.hadoop.yarn.server.resourcemanager.rmapp.RMAppImpl: application_1398103439608_0001 State change from FINISHING to FINISHED
2014-04-21 19:00:07,762 INFO org.apache.hadoop.yarn.server.resourcemanager.scheduler.capacity.CapacityScheduler: Application appattempt_1398103439608_0001_000001 is done. finalState=FINISHED
2014-04-21 19:00:07,763 INFO org.apache.hadoop.yarn.server.resourcemanager.RMAuditLogger: USER=ubuntu	OPERATION=Application Finished - Succeeded	TARGET=RMAppManager	RESULT=SUCCESS	APPID=application_1398103439608_0001
2014-04-21 19:00:07,764 INFO org.apache.hadoop.yarn.server.resourcemanager.rmcontainer.RMContainerImpl: container_1398103439608_0001_01_000006 Container Transitioned from ACQUIRED to KILLED
2014-04-21 19:00:07,764 INFO org.apache.hadoop.yarn.server.resourcemanager.scheduler.common.fica.FiCaSchedulerApp: Completed container: container_1398103439608_0001_01_000006 in state: KILLED event:KILL
2014-04-21 19:00:07,764 INFO org.apache.hadoop.yarn.server.resourcemanager.RMAuditLogger: USER=ubuntu	OPERATION=AM Released Container	TARGET=SchedulerApp	RESULT=SUCCESS	APPID=application_1398103439608_0001	CONTAINERID=container_1398103439608_0001_01_000006
2014-04-21 19:00:07,764 INFO org.apache.hadoop.yarn.server.resourcemanager.scheduler.common.fica.FiCaSchedulerNode: Released container container_1398103439608_0001_01_000006 of capacity <memory:1024, vCores:1> on host nodea:47962, which currently has 0 containers, <memory:0, vCores:0> used and <memory:8192, vCores:8> available, release resources=true
2014-04-21 19:00:07,764 INFO org.apache.hadoop.yarn.server.resourcemanager.scheduler.capacity.LeafQueue: default used=<memory:0, vCores:0> numContainers=0 user=ubuntu user-resources=<memory:0, vCores:0>
2014-04-21 19:00:07,764 INFO org.apache.hadoop.yarn.server.resourcemanager.scheduler.capacity.LeafQueue: completedContainer container=Container: [ContainerId: container_1398103439608_0001_01_000006, NodeId: nodea:47962, NodeHttpAddress: nodea:8042, Resource: <memory:1024, vCores:1>, Priority: 10, Token: Token { kind: ContainerToken, service: 10.0.0.54:47962 }, ] resource=<memory:1024, vCores:1> queue=default: capacity=1.0, absoluteCapacity=1.0, usedResources=<memory:0, vCores:0>usedCapacity=0.0, absoluteUsedCapacity=0.0, numApps=1, numContainers=0 usedCapacity=0.0 absoluteUsedCapacity=0.0 used=<memory:0, vCores:0> cluster=<memory:32768, vCores:32>
2014-04-21 19:00:07,764 INFO org.apache.hadoop.yarn.server.resourcemanager.scheduler.capacity.ParentQueue: completedContainer queue=root usedCapacity=0.0 absoluteUsedCapacity=0.0 used=<memory:0, vCores:0> cluster=<memory:32768, vCores:32>
2014-04-21 19:00:07,765 INFO org.apache.hadoop.yarn.server.resourcemanager.scheduler.capacity.ParentQueue: Re-sorting completed queue: root.default stats: default: capacity=1.0, absoluteCapacity=1.0, usedResources=<memory:0, vCores:0>usedCapacity=0.0, absoluteUsedCapacity=0.0, numApps=1, numContainers=0
2014-04-21 19:00:07,765 INFO org.apache.hadoop.yarn.server.resourcemanager.scheduler.capacity.CapacityScheduler: Application appattempt_1398103439608_0001_000001 released container container_1398103439608_0001_01_000006 on node: host: nodea:47962 #containers=0 available=8192 used=0 with event: KILL
2014-04-21 19:00:07,765 INFO org.apache.hadoop.yarn.server.resourcemanager.RMAppManager$ApplicationSummary: appId=application_1398103439608_0001,name=partitioner||path:/dict||num reduce:4,user=ubuntu,queue=default,state=FINISHED,trackingUrl=ec2-54-187-121-79.us-west-2.compute.amazonaws.com:8088/proxy/application_1398103439608_0001/jobhistory/job/job_1398103439608_0001,appMasterHost=ip-10-0-0-199,startTime=1398106767594,finishTime=1398106800665,finalStatus=FAILED
2014-04-21 19:00:07,766 INFO org.apache.hadoop.yarn.server.resourcemanager.amlauncher.AMLauncher: Cleaning master appattempt_1398103439608_0001_000001
2014-04-21 19:00:07,773 INFO org.apache.hadoop.yarn.server.resourcemanager.scheduler.AppSchedulingInfo: Application application_1398103439608_0001 requests cleared
2014-04-21 19:00:07,773 INFO org.apache.hadoop.yarn.server.resourcemanager.scheduler.capacity.LeafQueue: Application removed - appId: application_1398103439608_0001 user: ubuntu queue: default #user-pending-applications: 0 #user-active-applications: 0 #queue-pending-applications: 0 #queue-active-applications: 0
2014-04-21 19:00:07,773 INFO org.apache.hadoop.yarn.server.resourcemanager.scheduler.capacity.ParentQueue: Application removed - appId: application_1398103439608_0001 user: ubuntu leaf-queue of parent: root #applications: 0
2014-04-21 19:02:38,284 INFO org.apache.hadoop.yarn.server.webproxy.WebAppProxyServlet: dr.who is accessing unchecked http://nodeb:19888/jobhistory/job/job_1398103439608_0001/jobhistory/job/job_1398103439608_0001 which is the app master GUI of application_1398103439608_0001 owned by ubuntu
2014-04-21 19:03:17,175 INFO org.apache.hadoop.yarn.server.resourcemanager.ClientRMService: Allocated new applicationId: 2
2014-04-21 19:03:18,955 INFO org.apache.hadoop.yarn.server.resourcemanager.ClientRMService: Application with id 2 submitted by user ubuntu
2014-04-21 19:03:18,955 INFO org.apache.hadoop.yarn.server.resourcemanager.rmapp.RMAppImpl: Storing application with id application_1398103439608_0002
2014-04-21 19:03:18,956 INFO org.apache.hadoop.yarn.server.resourcemanager.rmapp.RMAppImpl: application_1398103439608_0002 State change from NEW to NEW_SAVING
2014-04-21 19:03:18,956 INFO org.apache.hadoop.yarn.server.resourcemanager.recovery.RMStateStore: Storing info for app: application_1398103439608_0002
2014-04-21 19:03:18,956 INFO org.apache.hadoop.yarn.server.resourcemanager.RMAuditLogger: USER=ubuntu	IP=10.0.0.54	OPERATION=Submit Application Request	TARGET=ClientRMService	RESULT=SUCCESS	APPID=application_1398103439608_0002
2014-04-21 19:03:18,958 INFO org.apache.hadoop.yarn.server.resourcemanager.rmapp.RMAppImpl: application_1398103439608_0002 State change from NEW_SAVING to SUBMITTED
2014-04-21 19:03:18,958 INFO org.apache.hadoop.yarn.server.resourcemanager.ApplicationMasterService: Registering app attempt : appattempt_1398103439608_0002_000001
2014-04-21 19:03:18,959 INFO org.apache.hadoop.yarn.server.resourcemanager.rmapp.attempt.RMAppAttemptImpl: appattempt_1398103439608_0002_000001 State change from NEW to SUBMITTED
2014-04-21 19:03:18,960 INFO org.apache.hadoop.yarn.server.resourcemanager.scheduler.capacity.LeafQueue: Application application_1398103439608_0002 from user: ubuntu activated in queue: default
2014-04-21 19:03:18,960 INFO org.apache.hadoop.yarn.server.resourcemanager.scheduler.capacity.LeafQueue: Application added - appId: application_1398103439608_0002 user: org.apache.hadoop.yarn.server.resourcemanager.scheduler.capacity.LeafQueue$User@39ceb522, leaf-queue: default #user-pending-applications: 0 #user-active-applications: 1 #queue-pending-applications: 0 #queue-active-applications: 1
2014-04-21 19:03:18,960 INFO org.apache.hadoop.yarn.server.resourcemanager.scheduler.capacity.ParentQueue: Application added - appId: application_1398103439608_0002 user: ubuntu leaf-queue of parent: root #applications: 1
2014-04-21 19:03:18,960 INFO org.apache.hadoop.yarn.server.resourcemanager.scheduler.capacity.CapacityScheduler: Application Submission: appattempt_1398103439608_0002_000001, user: ubuntu queue: default: capacity=1.0, absoluteCapacity=1.0, usedResources=<memory:0, vCores:0>usedCapacity=0.0, absoluteUsedCapacity=0.0, numApps=1, numContainers=0, currently active: 1
2014-04-21 19:03:18,960 INFO org.apache.hadoop.yarn.server.resourcemanager.rmapp.attempt.RMAppAttemptImpl: appattempt_1398103439608_0002_000001 State change from SUBMITTED to SCHEDULED
2014-04-21 19:03:18,960 INFO org.apache.hadoop.yarn.server.resourcemanager.rmapp.RMAppImpl: application_1398103439608_0002 State change from SUBMITTED to ACCEPTED
2014-04-21 19:03:19,010 INFO org.apache.hadoop.yarn.server.resourcemanager.rmcontainer.RMContainerImpl: container_1398103439608_0002_01_000001 Container Transitioned from NEW to ALLOCATED
2014-04-21 19:03:19,010 INFO org.apache.hadoop.yarn.server.resourcemanager.RMAuditLogger: USER=ubuntu	OPERATION=AM Allocated Container	TARGET=SchedulerApp	RESULT=SUCCESS	APPID=application_1398103439608_0002	CONTAINERID=container_1398103439608_0002_01_000001
2014-04-21 19:03:19,010 INFO org.apache.hadoop.yarn.server.resourcemanager.scheduler.common.fica.FiCaSchedulerNode: Assigned container container_1398103439608_0002_01_000001 of capacity <memory:2048, vCores:1> on host nodeb:58333, which currently has 1 containers, <memory:2048, vCores:1> used and <memory:6144, vCores:7> available
2014-04-21 19:03:19,010 INFO org.apache.hadoop.yarn.server.resourcemanager.scheduler.capacity.LeafQueue: assignedContainer application=application_1398103439608_0002 container=Container: [ContainerId: container_1398103439608_0002_01_000001, NodeId: nodeb:58333, NodeHttpAddress: nodeb:8042, Resource: <memory:2048, vCores:1>, Priority: 0, Token: Token { kind: ContainerToken, service: 10.0.0.199:58333 }, ] containerId=container_1398103439608_0002_01_000001 queue=default: capacity=1.0, absoluteCapacity=1.0, usedResources=<memory:0, vCores:0>usedCapacity=0.0, absoluteUsedCapacity=0.0, numApps=1, numContainers=0 usedCapacity=0.0 absoluteUsedCapacity=0.0 used=<memory:0, vCores:0> cluster=<memory:32768, vCores:32>
2014-04-21 19:03:19,010 INFO org.apache.hadoop.yarn.server.resourcemanager.scheduler.capacity.ParentQueue: Re-sorting assigned queue: root.default stats: default: capacity=1.0, absoluteCapacity=1.0, usedResources=<memory:2048, vCores:1>usedCapacity=0.0625, absoluteUsedCapacity=0.0625, numApps=1, numContainers=1
2014-04-21 19:03:19,010 INFO org.apache.hadoop.yarn.server.resourcemanager.scheduler.capacity.ParentQueue: assignedContainer queue=root usedCapacity=0.0625 absoluteUsedCapacity=0.0625 used=<memory:2048, vCores:1> cluster=<memory:32768, vCores:32>
2014-04-21 19:03:19,011 INFO org.apache.hadoop.yarn.server.resourcemanager.rmcontainer.RMContainerImpl: container_1398103439608_0002_01_000001 Container Transitioned from ALLOCATED to ACQUIRED
2014-04-21 19:03:19,012 INFO org.apache.hadoop.yarn.server.resourcemanager.rmapp.attempt.RMAppAttemptImpl: Storing attempt: AppId: application_1398103439608_0002 AttemptId: appattempt_1398103439608_0002_000001 MasterContainer: Container: [ContainerId: container_1398103439608_0002_01_000001, NodeId: nodeb:58333, NodeHttpAddress: nodeb:8042, Resource: <memory:2048, vCores:1>, Priority: 0, Token: Token { kind: ContainerToken, service: 10.0.0.199:58333 }, ]
2014-04-21 19:03:19,012 INFO org.apache.hadoop.yarn.server.resourcemanager.recovery.RMStateStore: Storing info for attempt: appattempt_1398103439608_0002_000001
2014-04-21 19:03:19,012 INFO org.apache.hadoop.yarn.server.resourcemanager.rmapp.attempt.RMAppAttemptImpl: appattempt_1398103439608_0002_000001 State change from SCHEDULED to ALLOCATED_SAVING
2014-04-21 19:03:19,013 INFO org.apache.hadoop.yarn.server.resourcemanager.rmapp.attempt.RMAppAttemptImpl: appattempt_1398103439608_0002_000001 State change from ALLOCATED_SAVING to ALLOCATED
2014-04-21 19:03:19,020 INFO org.apache.hadoop.yarn.server.resourcemanager.amlauncher.AMLauncher: Launching masterappattempt_1398103439608_0002_000001
2014-04-21 19:03:19,022 INFO org.apache.hadoop.yarn.server.resourcemanager.amlauncher.AMLauncher: Setting up container Container: [ContainerId: container_1398103439608_0002_01_000001, NodeId: nodeb:58333, NodeHttpAddress: nodeb:8042, Resource: <memory:2048, vCores:1>, Priority: 0, Token: Token { kind: ContainerToken, service: 10.0.0.199:58333 }, ] for AM appattempt_1398103439608_0002_000001
2014-04-21 19:03:19,023 INFO org.apache.hadoop.yarn.server.resourcemanager.amlauncher.AMLauncher: Command to launch container container_1398103439608_0002_01_000001 : $JAVA_HOME/bin/java -Dlog4j.configuration=container-log4j.properties -Dyarn.app.container.log.dir=<LOG_DIR> -Dyarn.app.container.log.filesize=0 -Dhadoop.root.logger=INFO,CLA  -Xmx1024m org.apache.hadoop.mapreduce.v2.app.MRAppMaster 1><LOG_DIR>/stdout 2><LOG_DIR>/stderr 
2014-04-21 19:03:19,049 INFO org.apache.hadoop.yarn.server.resourcemanager.amlauncher.AMLauncher: Done launching container Container: [ContainerId: container_1398103439608_0002_01_000001, NodeId: nodeb:58333, NodeHttpAddress: nodeb:8042, Resource: <memory:2048, vCores:1>, Priority: 0, Token: Token { kind: ContainerToken, service: 10.0.0.199:58333 }, ] for AM appattempt_1398103439608_0002_000001
2014-04-21 19:03:19,049 INFO org.apache.hadoop.yarn.server.resourcemanager.rmapp.attempt.RMAppAttemptImpl: appattempt_1398103439608_0002_000001 State change from ALLOCATED to LAUNCHED
2014-04-21 19:03:20,011 INFO org.apache.hadoop.yarn.server.resourcemanager.rmcontainer.RMContainerImpl: container_1398103439608_0002_01_000001 Container Transitioned from ACQUIRED to RUNNING
2014-04-21 19:03:25,987 INFO SecurityLogger.org.apache.hadoop.ipc.Server: Auth successful for appattempt_1398103439608_0002_000001 (auth:SIMPLE)
2014-04-21 19:03:25,996 INFO org.apache.hadoop.yarn.server.resourcemanager.ApplicationMasterService: AM registration appattempt_1398103439608_0002_000001
2014-04-21 19:03:25,996 INFO org.apache.hadoop.yarn.server.resourcemanager.RMAuditLogger: USER=ubuntu	IP=10.0.0.199	OPERATION=Register App Master	TARGET=ApplicationMasterService	RESULT=SUCCESS	APPID=application_1398103439608_0002	APPATTEMPTID=appattempt_1398103439608_0002_000001
2014-04-21 19:03:25,997 INFO org.apache.hadoop.yarn.server.resourcemanager.rmapp.attempt.RMAppAttemptImpl: appattempt_1398103439608_0002_000001 State change from LAUNCHED to RUNNING
2014-04-21 19:03:25,997 INFO org.apache.hadoop.yarn.server.resourcemanager.rmapp.RMAppImpl: application_1398103439608_0002 State change from ACCEPTED to RUNNING
2014-04-21 19:03:27,214 INFO org.apache.hadoop.yarn.server.resourcemanager.rmcontainer.RMContainerImpl: container_1398103439608_0002_01_000002 Container Transitioned from NEW to ALLOCATED
2014-04-21 19:03:27,214 INFO org.apache.hadoop.yarn.server.resourcemanager.RMAuditLogger: USER=ubuntu	OPERATION=AM Allocated Container	TARGET=SchedulerApp	RESULT=SUCCESS	APPID=application_1398103439608_0002	CONTAINERID=container_1398103439608_0002_01_000002
2014-04-21 19:03:27,214 INFO org.apache.hadoop.yarn.server.resourcemanager.scheduler.common.fica.FiCaSchedulerNode: Assigned container container_1398103439608_0002_01_000002 of capacity <memory:1024, vCores:1> on host nodea:47962, which currently has 1 containers, <memory:1024, vCores:1> used and <memory:7168, vCores:7> available
2014-04-21 19:03:27,214 INFO org.apache.hadoop.yarn.server.resourcemanager.scheduler.capacity.LeafQueue: assignedContainer application=application_1398103439608_0002 container=Container: [ContainerId: container_1398103439608_0002_01_000002, NodeId: nodea:47962, NodeHttpAddress: nodea:8042, Resource: <memory:1024, vCores:1>, Priority: 20, Token: Token { kind: ContainerToken, service: 10.0.0.54:47962 }, ] containerId=container_1398103439608_0002_01_000002 queue=default: capacity=1.0, absoluteCapacity=1.0, usedResources=<memory:2048, vCores:1>usedCapacity=0.0625, absoluteUsedCapacity=0.0625, numApps=1, numContainers=1 usedCapacity=0.0625 absoluteUsedCapacity=0.0625 used=<memory:2048, vCores:1> cluster=<memory:32768, vCores:32>
2014-04-21 19:03:27,214 INFO org.apache.hadoop.yarn.server.resourcemanager.scheduler.capacity.ParentQueue: Re-sorting assigned queue: root.default stats: default: capacity=1.0, absoluteCapacity=1.0, usedResources=<memory:3072, vCores:2>usedCapacity=0.09375, absoluteUsedCapacity=0.09375, numApps=1, numContainers=2
2014-04-21 19:03:27,214 INFO org.apache.hadoop.yarn.server.resourcemanager.scheduler.capacity.ParentQueue: assignedContainer queue=root usedCapacity=0.09375 absoluteUsedCapacity=0.09375 used=<memory:3072, vCores:2> cluster=<memory:32768, vCores:32>
2014-04-21 19:03:28,060 INFO org.apache.hadoop.yarn.server.resourcemanager.rmcontainer.RMContainerImpl: container_1398103439608_0002_01_000002 Container Transitioned from ALLOCATED to ACQUIRED
2014-04-21 19:03:29,080 INFO org.apache.hadoop.yarn.server.resourcemanager.scheduler.AppSchedulingInfo: checking for deactivate... 
2014-04-21 19:03:29,235 INFO org.apache.hadoop.yarn.server.resourcemanager.rmcontainer.RMContainerImpl: container_1398103439608_0002_01_000002 Container Transitioned from ACQUIRED to RUNNING
2014-04-21 19:03:29,501 INFO org.apache.hadoop.yarn.server.webproxy.WebAppProxyServlet: dr.who is accessing unchecked http://ip-10-0-0-199:42563/ which is the app master GUI of application_1398103439608_0002 owned by ubuntu
2014-04-21 19:03:31,629 INFO org.apache.hadoop.yarn.server.webproxy.WebAppProxyServlet: dr.who is accessing unchecked http://ip-10-0-0-199:42563/static/yarn.css which is the app master GUI of application_1398103439608_0002 owned by ubuntu
2014-04-21 19:03:31,644 INFO org.apache.hadoop.yarn.server.webproxy.WebAppProxyServlet: dr.who is accessing unchecked http://ip-10-0-0-199:42563/static/jquery/jquery-ui-1.9.1.custom.min.js which is the app master GUI of application_1398103439608_0002 owned by ubuntu
2014-04-21 19:03:31,635 INFO org.apache.hadoop.yarn.server.webproxy.WebAppProxyServlet: dr.who is accessing unchecked http://ip-10-0-0-199:42563/static/jquery/themes-1.9.1/base/jquery-ui.css which is the app master GUI of application_1398103439608_0002 owned by ubuntu
2014-04-21 19:03:31,633 INFO org.apache.hadoop.yarn.server.webproxy.WebAppProxyServlet: dr.who is accessing unchecked http://ip-10-0-0-199:42563/static/dt-1.9.4/css/jui-dt.css which is the app master GUI of application_1398103439608_0002 owned by ubuntu
2014-04-21 19:03:31,649 INFO org.apache.hadoop.yarn.server.webproxy.WebAppProxyServlet: dr.who is accessing unchecked http://ip-10-0-0-199:42563/static/jquery/jquery-1.8.2.min.js which is the app master GUI of application_1398103439608_0002 owned by ubuntu
2014-04-21 19:03:31,662 INFO org.apache.hadoop.yarn.server.webproxy.WebAppProxyServlet: dr.who is accessing unchecked http://ip-10-0-0-199:42563/static/dt-1.9.4/js/jquery.dataTables.min.js which is the app master GUI of application_1398103439608_0002 owned by ubuntu
2014-04-21 19:03:31,734 INFO org.apache.hadoop.yarn.server.webproxy.WebAppProxyServlet: dr.who is accessing unchecked http://ip-10-0-0-199:42563/static/yarn.dt.plugins.js which is the app master GUI of application_1398103439608_0002 owned by ubuntu
2014-04-21 19:03:32,032 INFO org.apache.hadoop.yarn.server.webproxy.WebAppProxyServlet: dr.who is accessing unchecked http://ip-10-0-0-199:42563/static/jquery/themes-1.9.1/base/images/ui-bg_glass_95_fef1ec_1x400.png which is the app master GUI of application_1398103439608_0002 owned by ubuntu
2014-04-21 19:03:32,034 INFO org.apache.hadoop.yarn.server.webproxy.WebAppProxyServlet: dr.who is accessing unchecked http://ip-10-0-0-199:42563/static/jquery/themes-1.9.1/base/images/ui-bg_flat_75_ffffff_40x100.png which is the app master GUI of application_1398103439608_0002 owned by ubuntu
2014-04-21 19:03:32,036 INFO org.apache.hadoop.yarn.server.webproxy.WebAppProxyServlet: dr.who is accessing unchecked http://ip-10-0-0-199:42563/static/jquery/themes-1.9.1/base/images/ui-bg_highlight-soft_75_cccccc_1x100.png which is the app master GUI of application_1398103439608_0002 owned by ubuntu
2014-04-21 19:03:32,055 INFO org.apache.hadoop.yarn.server.webproxy.WebAppProxyServlet: dr.who is accessing unchecked http://ip-10-0-0-199:42563/static/jquery/themes-1.9.1/base/images/ui-bg_glass_75_e6e6e6_1x400.png which is the app master GUI of application_1398103439608_0002 owned by ubuntu
2014-04-21 19:03:32,059 INFO org.apache.hadoop.yarn.server.webproxy.WebAppProxyServlet: dr.who is accessing unchecked http://ip-10-0-0-199:42563/static/jquery/themes-1.9.1/base/images/ui-bg_glass_65_ffffff_1x400.png which is the app master GUI of application_1398103439608_0002 owned by ubuntu
2014-04-21 19:03:32,062 INFO org.apache.hadoop.yarn.server.webproxy.WebAppProxyServlet: dr.who is accessing unchecked http://ip-10-0-0-199:42563/static/jquery/themes-1.9.1/base/images/ui-icons_888888_256x240.png which is the app master GUI of application_1398103439608_0002 owned by ubuntu
2014-04-21 19:03:32,140 INFO org.apache.hadoop.yarn.server.webproxy.WebAppProxyServlet: dr.who is accessing unchecked http://ip-10-0-0-199:42563/static/jquery/themes-1.9.1/base/images/ui-icons_454545_256x240.png which is the app master GUI of application_1398103439608_0002 owned by ubuntu
2014-04-21 19:03:33,983 INFO org.apache.hadoop.yarn.server.webproxy.WebAppProxyServlet: dr.who is accessing unchecked http://ip-10-0-0-199:42563/mapreduce/job/job_1398103439608_0002 which is the app master GUI of application_1398103439608_0002 owned by ubuntu
2014-04-21 19:03:34,204 INFO org.apache.hadoop.yarn.server.webproxy.WebAppProxyServlet: dr.who is accessing unchecked http://ip-10-0-0-199:42563/static/yarn.css which is the app master GUI of application_1398103439608_0002 owned by ubuntu
2014-04-21 19:03:34,206 INFO org.apache.hadoop.yarn.server.webproxy.WebAppProxyServlet: dr.who is accessing unchecked http://ip-10-0-0-199:42563/static/jquery/themes-1.9.1/base/jquery-ui.css which is the app master GUI of application_1398103439608_0002 owned by ubuntu
2014-04-21 19:03:34,208 INFO org.apache.hadoop.yarn.server.webproxy.WebAppProxyServlet: dr.who is accessing unchecked http://ip-10-0-0-199:42563/static/jquery/jquery-ui-1.9.1.custom.min.js which is the app master GUI of application_1398103439608_0002 owned by ubuntu
2014-04-21 19:03:34,210 INFO org.apache.hadoop.yarn.server.webproxy.WebAppProxyServlet: dr.who is accessing unchecked http://ip-10-0-0-199:42563/static/dt-1.9.4/js/jquery.dataTables.min.js which is the app master GUI of application_1398103439608_0002 owned by ubuntu
2014-04-21 19:03:34,211 INFO org.apache.hadoop.yarn.server.webproxy.WebAppProxyServlet: dr.who is accessing unchecked http://ip-10-0-0-199:42563/static/dt-1.9.4/css/jui-dt.css which is the app master GUI of application_1398103439608_0002 owned by ubuntu
2014-04-21 19:03:34,213 INFO org.apache.hadoop.yarn.server.webproxy.WebAppProxyServlet: dr.who is accessing unchecked http://ip-10-0-0-199:42563/static/jquery/jquery-1.8.2.min.js which is the app master GUI of application_1398103439608_0002 owned by ubuntu
2014-04-21 19:03:34,299 INFO org.apache.hadoop.yarn.server.webproxy.WebAppProxyServlet: dr.who is accessing unchecked http://ip-10-0-0-199:42563/static/yarn.dt.plugins.js which is the app master GUI of application_1398103439608_0002 owned by ubuntu
2014-04-21 19:03:34,543 INFO org.apache.hadoop.yarn.server.webproxy.WebAppProxyServlet: dr.who is accessing unchecked http://ip-10-0-0-199:42563/static/jquery/themes-1.9.1/base/images/ui-bg_glass_95_fef1ec_1x400.png which is the app master GUI of application_1398103439608_0002 owned by ubuntu
2014-04-21 19:03:34,543 INFO org.apache.hadoop.yarn.server.webproxy.WebAppProxyServlet: dr.who is accessing unchecked http://ip-10-0-0-199:42563/static/jquery/themes-1.9.1/base/images/ui-bg_flat_75_ffffff_40x100.png which is the app master GUI of application_1398103439608_0002 owned by ubuntu
2014-04-21 19:03:34,546 INFO org.apache.hadoop.yarn.server.webproxy.WebAppProxyServlet: dr.who is accessing unchecked http://ip-10-0-0-199:42563/static/jquery/themes-1.9.1/base/images/ui-bg_highlight-soft_75_cccccc_1x100.png which is the app master GUI of application_1398103439608_0002 owned by ubuntu
2014-04-21 19:03:34,553 INFO org.apache.hadoop.yarn.server.webproxy.WebAppProxyServlet: dr.who is accessing unchecked http://ip-10-0-0-199:42563/static/jquery/themes-1.9.1/base/images/ui-icons_888888_256x240.png which is the app master GUI of application_1398103439608_0002 owned by ubuntu
2014-04-21 19:03:34,556 INFO org.apache.hadoop.yarn.server.webproxy.WebAppProxyServlet: dr.who is accessing unchecked http://ip-10-0-0-199:42563/static/jquery/themes-1.9.1/base/images/ui-bg_glass_65_ffffff_1x400.png which is the app master GUI of application_1398103439608_0002 owned by ubuntu
2014-04-21 19:03:34,559 INFO org.apache.hadoop.yarn.server.webproxy.WebAppProxyServlet: dr.who is accessing unchecked http://ip-10-0-0-199:42563/static/jquery/themes-1.9.1/base/images/ui-bg_glass_75_e6e6e6_1x400.png which is the app master GUI of application_1398103439608_0002 owned by ubuntu
2014-04-21 19:03:34,633 INFO org.apache.hadoop.yarn.server.webproxy.WebAppProxyServlet: dr.who is accessing unchecked http://ip-10-0-0-199:42563/static/jquery/themes-1.9.1/base/images/ui-icons_454545_256x240.png which is the app master GUI of application_1398103439608_0002 owned by ubuntu
2014-04-21 19:03:44,311 INFO org.apache.hadoop.yarn.server.resourcemanager.rmcontainer.RMContainerImpl: container_1398103439608_0002_01_000002 Container Transitioned from RUNNING to COMPLETED
2014-04-21 19:03:44,311 INFO org.apache.hadoop.yarn.server.resourcemanager.scheduler.common.fica.FiCaSchedulerApp: Completed container: container_1398103439608_0002_01_000002 in state: COMPLETED event:FINISHED
2014-04-21 19:03:44,311 INFO org.apache.hadoop.yarn.server.resourcemanager.RMAuditLogger: USER=ubuntu	OPERATION=AM Released Container	TARGET=SchedulerApp	RESULT=SUCCESS	APPID=application_1398103439608_0002	CONTAINERID=container_1398103439608_0002_01_000002
2014-04-21 19:03:44,311 INFO org.apache.hadoop.yarn.server.resourcemanager.scheduler.common.fica.FiCaSchedulerNode: Released container container_1398103439608_0002_01_000002 of capacity <memory:1024, vCores:1> on host nodea:47962, which currently has 0 containers, <memory:0, vCores:0> used and <memory:8192, vCores:8> available, release resources=true
2014-04-21 19:03:44,311 INFO org.apache.hadoop.yarn.server.resourcemanager.scheduler.capacity.LeafQueue: default used=<memory:2048, vCores:1> numContainers=1 user=ubuntu user-resources=<memory:2048, vCores:1>
2014-04-21 19:03:44,312 INFO org.apache.hadoop.yarn.server.resourcemanager.scheduler.capacity.LeafQueue: completedContainer container=Container: [ContainerId: container_1398103439608_0002_01_000002, NodeId: nodea:47962, NodeHttpAddress: nodea:8042, Resource: <memory:1024, vCores:1>, Priority: 20, Token: Token { kind: ContainerToken, service: 10.0.0.54:47962 }, ] resource=<memory:1024, vCores:1> queue=default: capacity=1.0, absoluteCapacity=1.0, usedResources=<memory:2048, vCores:1>usedCapacity=0.0625, absoluteUsedCapacity=0.0625, numApps=1, numContainers=1 usedCapacity=0.0625 absoluteUsedCapacity=0.0625 used=<memory:2048, vCores:1> cluster=<memory:32768, vCores:32>
2014-04-21 19:03:44,312 INFO org.apache.hadoop.yarn.server.resourcemanager.scheduler.capacity.ParentQueue: completedContainer queue=root usedCapacity=0.0625 absoluteUsedCapacity=0.0625 used=<memory:2048, vCores:1> cluster=<memory:32768, vCores:32>
2014-04-21 19:03:44,312 INFO org.apache.hadoop.yarn.server.resourcemanager.scheduler.capacity.ParentQueue: Re-sorting completed queue: root.default stats: default: capacity=1.0, absoluteCapacity=1.0, usedResources=<memory:2048, vCores:1>usedCapacity=0.0625, absoluteUsedCapacity=0.0625, numApps=1, numContainers=1
2014-04-21 19:03:44,312 INFO org.apache.hadoop.yarn.server.resourcemanager.scheduler.capacity.CapacityScheduler: Application appattempt_1398103439608_0002_000001 released container container_1398103439608_0002_01_000002 on node: host: nodea:47962 #containers=0 available=8192 used=0 with event: FINISHED
2014-04-21 19:03:45,314 INFO org.apache.hadoop.yarn.server.resourcemanager.rmcontainer.RMContainerImpl: container_1398103439608_0002_01_000003 Container Transitioned from NEW to ALLOCATED
2014-04-21 19:03:49,290 INFO org.apache.hadoop.yarn.server.resourcemanager.RMAuditLogger: USER=ubuntu	OPERATION=AM Allocated Container	TARGET=SchedulerApp	RESULT=SUCCESS	APPID=application_1398103439608_0002	CONTAINERID=container_1398103439608_0002_01_000003
2014-04-21 19:03:49,290 INFO org.apache.hadoop.yarn.server.resourcemanager.scheduler.common.fica.FiCaSchedulerNode: Assigned container container_1398103439608_0002_01_000003 of capacity <memory:1024, vCores:1> on host nodea:47962, which currently has 1 containers, <memory:1024, vCores:1> used and <memory:7168, vCores:7> available
2014-04-21 19:03:49,291 INFO org.apache.hadoop.yarn.server.resourcemanager.scheduler.capacity.LeafQueue: assignedContainer application=application_1398103439608_0002 container=Container: [ContainerId: container_1398103439608_0002_01_000003, NodeId: nodea:47962, NodeHttpAddress: nodea:8042, Resource: <memory:1024, vCores:1>, Priority: 10, Token: Token { kind: ContainerToken, service: 10.0.0.54:47962 }, ] containerId=container_1398103439608_0002_01_000003 queue=default: capacity=1.0, absoluteCapacity=1.0, usedResources=<memory:2048, vCores:1>usedCapacity=0.0625, absoluteUsedCapacity=0.0625, numApps=1, numContainers=1 usedCapacity=0.0625 absoluteUsedCapacity=0.0625 used=<memory:2048, vCores:1> cluster=<memory:32768, vCores:32>
2014-04-21 19:03:49,297 INFO org.apache.hadoop.yarn.server.resourcemanager.scheduler.capacity.ParentQueue: Re-sorting assigned queue: root.default stats: default: capacity=1.0, absoluteCapacity=1.0, usedResources=<memory:3072, vCores:2>usedCapacity=0.09375, absoluteUsedCapacity=0.09375, numApps=1, numContainers=2
2014-04-21 19:03:49,297 INFO org.apache.hadoop.yarn.server.resourcemanager.scheduler.capacity.ParentQueue: assignedContainer queue=root usedCapacity=0.09375 absoluteUsedCapacity=0.09375 used=<memory:3072, vCores:2> cluster=<memory:32768, vCores:32>
2014-04-21 19:03:49,298 INFO org.apache.hadoop.yarn.server.resourcemanager.rmcontainer.RMContainerImpl: container_1398103439608_0002_01_000003 Container Transitioned from ALLOCATED to ACQUIRED
2014-04-21 19:03:49,299 INFO org.apache.hadoop.yarn.server.resourcemanager.rmcontainer.RMContainerImpl: container_1398103439608_0002_01_000004 Container Transitioned from NEW to ALLOCATED
2014-04-21 19:03:49,299 INFO org.apache.hadoop.yarn.server.resourcemanager.RMAuditLogger: USER=ubuntu	OPERATION=AM Allocated Container	TARGET=SchedulerApp	RESULT=SUCCESS	APPID=application_1398103439608_0002	CONTAINERID=container_1398103439608_0002_01_000004
2014-04-21 19:03:49,299 INFO org.apache.hadoop.yarn.server.resourcemanager.scheduler.common.fica.FiCaSchedulerNode: Assigned container container_1398103439608_0002_01_000004 of capacity <memory:1024, vCores:1> on host noded:47267, which currently has 1 containers, <memory:1024, vCores:1> used and <memory:7168, vCores:7> available
2014-04-21 19:03:49,300 INFO org.apache.hadoop.yarn.server.resourcemanager.scheduler.capacity.LeafQueue: assignedContainer application=application_1398103439608_0002 container=Container: [ContainerId: container_1398103439608_0002_01_000004, NodeId: noded:47267, NodeHttpAddress: noded:8042, Resource: <memory:1024, vCores:1>, Priority: 10, Token: Token { kind: ContainerToken, service: 10.0.0.193:47267 }, ] containerId=container_1398103439608_0002_01_000004 queue=default: capacity=1.0, absoluteCapacity=1.0, usedResources=<memory:3072, vCores:2>usedCapacity=0.09375, absoluteUsedCapacity=0.09375, numApps=1, numContainers=2 usedCapacity=0.09375 absoluteUsedCapacity=0.09375 used=<memory:3072, vCores:2> cluster=<memory:32768, vCores:32>
2014-04-21 19:03:49,300 INFO org.apache.hadoop.yarn.server.resourcemanager.scheduler.capacity.ParentQueue: Re-sorting assigned queue: root.default stats: default: capacity=1.0, absoluteCapacity=1.0, usedResources=<memory:4096, vCores:3>usedCapacity=0.125, absoluteUsedCapacity=0.125, numApps=1, numContainers=3
2014-04-21 19:03:49,300 INFO org.apache.hadoop.yarn.server.resourcemanager.scheduler.capacity.ParentQueue: assignedContainer queue=root usedCapacity=0.125 absoluteUsedCapacity=0.125 used=<memory:4096, vCores:3> cluster=<memory:32768, vCores:32>
2014-04-21 19:03:49,301 INFO org.apache.hadoop.yarn.server.resourcemanager.rmcontainer.RMContainerImpl: container_1398103439608_0002_01_000005 Container Transitioned from NEW to ALLOCATED
2014-04-21 19:03:49,301 INFO org.apache.hadoop.yarn.server.resourcemanager.RMAuditLogger: USER=ubuntu	OPERATION=AM Allocated Container	TARGET=SchedulerApp	RESULT=SUCCESS	APPID=application_1398103439608_0002	CONTAINERID=container_1398103439608_0002_01_000005
2014-04-21 19:03:49,301 INFO org.apache.hadoop.yarn.server.resourcemanager.scheduler.common.fica.FiCaSchedulerNode: Assigned container container_1398103439608_0002_01_000005 of capacity <memory:1024, vCores:1> on host nodec:34990, which currently has 1 containers, <memory:1024, vCores:1> used and <memory:7168, vCores:7> available
2014-04-21 19:03:49,301 INFO org.apache.hadoop.yarn.server.resourcemanager.scheduler.capacity.LeafQueue: assignedContainer application=application_1398103439608_0002 container=Container: [ContainerId: container_1398103439608_0002_01_000005, NodeId: nodec:34990, NodeHttpAddress: nodec:8042, Resource: <memory:1024, vCores:1>, Priority: 10, Token: Token { kind: ContainerToken, service: 10.0.0.189:34990 }, ] containerId=container_1398103439608_0002_01_000005 queue=default: capacity=1.0, absoluteCapacity=1.0, usedResources=<memory:4096, vCores:3>usedCapacity=0.125, absoluteUsedCapacity=0.125, numApps=1, numContainers=3 usedCapacity=0.125 absoluteUsedCapacity=0.125 used=<memory:4096, vCores:3> cluster=<memory:32768, vCores:32>
2014-04-21 19:03:49,301 INFO org.apache.hadoop.yarn.server.resourcemanager.scheduler.capacity.ParentQueue: Re-sorting assigned queue: root.default stats: default: capacity=1.0, absoluteCapacity=1.0, usedResources=<memory:5120, vCores:4>usedCapacity=0.15625, absoluteUsedCapacity=0.15625, numApps=1, numContainers=4
2014-04-21 19:03:49,301 INFO org.apache.hadoop.yarn.server.resourcemanager.scheduler.capacity.ParentQueue: assignedContainer queue=root usedCapacity=0.15625 absoluteUsedCapacity=0.15625 used=<memory:5120, vCores:4> cluster=<memory:32768, vCores:32>
2014-04-21 19:03:49,302 INFO org.apache.hadoop.yarn.server.resourcemanager.rmcontainer.RMContainerImpl: container_1398103439608_0002_01_000006 Container Transitioned from NEW to ALLOCATED
2014-04-21 19:03:49,302 INFO org.apache.hadoop.yarn.server.resourcemanager.RMAuditLogger: USER=ubuntu	OPERATION=AM Allocated Container	TARGET=SchedulerApp	RESULT=SUCCESS	APPID=application_1398103439608_0002	CONTAINERID=container_1398103439608_0002_01_000006
2014-04-21 19:03:49,302 INFO org.apache.hadoop.yarn.server.resourcemanager.scheduler.common.fica.FiCaSchedulerNode: Assigned container container_1398103439608_0002_01_000006 of capacity <memory:1024, vCores:1> on host nodeb:58333, which currently has 2 containers, <memory:3072, vCores:2> used and <memory:5120, vCores:6> available
2014-04-21 19:03:49,303 INFO org.apache.hadoop.yarn.server.resourcemanager.scheduler.capacity.LeafQueue: assignedContainer application=application_1398103439608_0002 container=Container: [ContainerId: container_1398103439608_0002_01_000006, NodeId: nodeb:58333, NodeHttpAddress: nodeb:8042, Resource: <memory:1024, vCores:1>, Priority: 10, Token: Token { kind: ContainerToken, service: 10.0.0.199:58333 }, ] containerId=container_1398103439608_0002_01_000006 queue=default: capacity=1.0, absoluteCapacity=1.0, usedResources=<memory:5120, vCores:4>usedCapacity=0.15625, absoluteUsedCapacity=0.15625, numApps=1, numContainers=4 usedCapacity=0.15625 absoluteUsedCapacity=0.15625 used=<memory:5120, vCores:4> cluster=<memory:32768, vCores:32>
2014-04-21 19:03:49,303 INFO org.apache.hadoop.yarn.server.resourcemanager.scheduler.capacity.ParentQueue: Re-sorting assigned queue: root.default stats: default: capacity=1.0, absoluteCapacity=1.0, usedResources=<memory:6144, vCores:5>usedCapacity=0.1875, absoluteUsedCapacity=0.1875, numApps=1, numContainers=5
2014-04-21 19:03:49,303 INFO org.apache.hadoop.yarn.server.resourcemanager.scheduler.capacity.ParentQueue: assignedContainer queue=root usedCapacity=0.1875 absoluteUsedCapacity=0.1875 used=<memory:6144, vCores:5> cluster=<memory:32768, vCores:32>
2014-04-21 19:03:49,303 INFO org.apache.hadoop.yarn.server.webproxy.WebAppProxyServlet: dr.who is accessing unchecked http://ip-10-0-0-199:42563/mapreduce/attempts/job_1398103439608_0002/r/NEW which is the app master GUI of application_1398103439608_0002 owned by ubuntu
2014-04-21 19:03:49,504 INFO org.apache.hadoop.yarn.server.webproxy.WebAppProxyServlet: dr.who is accessing unchecked http://ip-10-0-0-199:42563/static/jquery/jquery-1.8.2.min.js which is the app master GUI of application_1398103439608_0002 owned by ubuntu
2014-04-21 19:03:49,506 INFO org.apache.hadoop.yarn.server.webproxy.WebAppProxyServlet: dr.who is accessing unchecked http://ip-10-0-0-199:42563/static/dt-1.9.4/js/jquery.dataTables.min.js which is the app master GUI of application_1398103439608_0002 owned by ubuntu
2014-04-21 19:03:49,508 INFO org.apache.hadoop.yarn.server.webproxy.WebAppProxyServlet: dr.who is accessing unchecked http://ip-10-0-0-199:42563/static/jquery/themes-1.9.1/base/jquery-ui.css which is the app master GUI of application_1398103439608_0002 owned by ubuntu
2014-04-21 19:03:49,509 INFO org.apache.hadoop.yarn.server.webproxy.WebAppProxyServlet: dr.who is accessing unchecked http://ip-10-0-0-199:42563/static/dt-1.9.4/css/jui-dt.css which is the app master GUI of application_1398103439608_0002 owned by ubuntu
2014-04-21 19:03:49,510 INFO org.apache.hadoop.yarn.server.webproxy.WebAppProxyServlet: dr.who is accessing unchecked http://ip-10-0-0-199:42563/static/yarn.css which is the app master GUI of application_1398103439608_0002 owned by ubuntu
2014-04-21 19:03:49,516 INFO org.apache.hadoop.yarn.server.webproxy.WebAppProxyServlet: dr.who is accessing unchecked http://ip-10-0-0-199:42563/static/jquery/jquery-ui-1.9.1.custom.min.js which is the app master GUI of application_1398103439608_0002 owned by ubuntu
2014-04-21 19:03:49,599 INFO org.apache.hadoop.yarn.server.webproxy.WebAppProxyServlet: dr.who is accessing unchecked http://ip-10-0-0-199:42563/static/yarn.dt.plugins.js which is the app master GUI of application_1398103439608_0002 owned by ubuntu
2014-04-21 19:03:49,840 INFO org.apache.hadoop.yarn.server.webproxy.WebAppProxyServlet: dr.who is accessing unchecked http://ip-10-0-0-199:42563/static/jquery/themes-1.9.1/base/images/ui-bg_glass_95_fef1ec_1x400.png which is the app master GUI of application_1398103439608_0002 owned by ubuntu
2014-04-21 19:03:49,843 INFO org.apache.hadoop.yarn.server.webproxy.WebAppProxyServlet: dr.who is accessing unchecked http://ip-10-0-0-199:42563/static/jquery/themes-1.9.1/base/images/ui-bg_flat_75_ffffff_40x100.png which is the app master GUI of application_1398103439608_0002 owned by ubuntu
2014-04-21 19:03:49,850 INFO org.apache.hadoop.yarn.server.webproxy.WebAppProxyServlet: dr.who is accessing unchecked http://ip-10-0-0-199:42563/static/jquery/themes-1.9.1/base/images/ui-bg_glass_65_ffffff_1x400.png which is the app master GUI of application_1398103439608_0002 owned by ubuntu
2014-04-21 19:03:49,852 INFO org.apache.hadoop.yarn.server.webproxy.WebAppProxyServlet: dr.who is accessing unchecked http://ip-10-0-0-199:42563/static/jquery/themes-1.9.1/base/images/ui-icons_454545_256x240.png which is the app master GUI of application_1398103439608_0002 owned by ubuntu
2014-04-21 19:03:49,859 INFO org.apache.hadoop.yarn.server.webproxy.WebAppProxyServlet: dr.who is accessing unchecked http://ip-10-0-0-199:42563/static/jquery/themes-1.9.1/base/images/ui-icons_888888_256x240.png which is the app master GUI of application_1398103439608_0002 owned by ubuntu
2014-04-21 19:03:49,860 INFO org.apache.hadoop.yarn.server.webproxy.WebAppProxyServlet: dr.who is accessing unchecked http://ip-10-0-0-199:42563/static/jquery/themes-1.9.1/base/images/ui-bg_glass_75_e6e6e6_1x400.png which is the app master GUI of application_1398103439608_0002 owned by ubuntu
2014-04-21 19:03:49,920 INFO org.apache.hadoop.yarn.server.webproxy.WebAppProxyServlet: dr.who is accessing unchecked http://ip-10-0-0-199:42563/static/jquery/themes-1.9.1/base/images/ui-bg_highlight-soft_75_cccccc_1x100.png which is the app master GUI of application_1398103439608_0002 owned by ubuntu
2014-04-21 19:03:50,309 INFO org.apache.hadoop.yarn.server.resourcemanager.rmcontainer.RMContainerImpl: container_1398103439608_0002_01_000004 Container Transitioned from ALLOCATED to ACQUIRED
2014-04-21 19:03:50,309 INFO org.apache.hadoop.yarn.server.resourcemanager.rmcontainer.RMContainerImpl: container_1398103439608_0002_01_000005 Container Transitioned from ALLOCATED to ACQUIRED
2014-04-21 19:03:50,695 INFO org.apache.hadoop.yarn.server.resourcemanager.rmcontainer.RMContainerImpl: container_1398103439608_0002_01_000006 Container Transitioned from ALLOCATED to ACQUIRED
2014-04-21 19:03:50,700 INFO org.apache.hadoop.yarn.server.resourcemanager.rmcontainer.RMContainerImpl: container_1398103439608_0002_01_000003 Container Transitioned from ACQUIRED to RUNNING
2014-04-21 19:03:50,886 INFO org.apache.hadoop.yarn.server.resourcemanager.rmcontainer.RMContainerImpl: container_1398103439608_0002_01_000004 Container Transitioned from ACQUIRED to RUNNING
2014-04-21 19:03:50,928 INFO org.apache.hadoop.yarn.server.resourcemanager.rmcontainer.RMContainerImpl: container_1398103439608_0002_01_000005 Container Transitioned from ACQUIRED to RUNNING
2014-04-21 19:03:51,705 INFO org.apache.hadoop.yarn.server.resourcemanager.scheduler.AppSchedulingInfo: checking for deactivate... 
2014-04-21 19:03:51,851 INFO org.apache.hadoop.yarn.server.resourcemanager.rmcontainer.RMContainerImpl: container_1398103439608_0002_01_000005 Container Transitioned from RUNNING to COMPLETED
2014-04-21 19:03:51,851 INFO org.apache.hadoop.yarn.server.resourcemanager.scheduler.common.fica.FiCaSchedulerApp: Completed container: container_1398103439608_0002_01_000005 in state: COMPLETED event:FINISHED
2014-04-21 19:03:51,851 INFO org.apache.hadoop.yarn.server.resourcemanager.RMAuditLogger: USER=ubuntu	OPERATION=AM Released Container	TARGET=SchedulerApp	RESULT=SUCCESS	APPID=application_1398103439608_0002	CONTAINERID=container_1398103439608_0002_01_000005
2014-04-21 19:03:51,852 INFO org.apache.hadoop.yarn.server.resourcemanager.scheduler.common.fica.FiCaSchedulerNode: Released container container_1398103439608_0002_01_000005 of capacity <memory:1024, vCores:1> on host nodec:34990, which currently has 0 containers, <memory:0, vCores:0> used and <memory:8192, vCores:8> available, release resources=true
2014-04-21 19:03:51,852 INFO org.apache.hadoop.yarn.server.resourcemanager.scheduler.capacity.LeafQueue: default used=<memory:5120, vCores:4> numContainers=4 user=ubuntu user-resources=<memory:5120, vCores:4>
2014-04-21 19:03:51,852 INFO org.apache.hadoop.yarn.server.resourcemanager.scheduler.capacity.LeafQueue: completedContainer container=Container: [ContainerId: container_1398103439608_0002_01_000005, NodeId: nodec:34990, NodeHttpAddress: nodec:8042, Resource: <memory:1024, vCores:1>, Priority: 10, Token: Token { kind: ContainerToken, service: 10.0.0.189:34990 }, ] resource=<memory:1024, vCores:1> queue=default: capacity=1.0, absoluteCapacity=1.0, usedResources=<memory:5120, vCores:4>usedCapacity=0.15625, absoluteUsedCapacity=0.15625, numApps=1, numContainers=4 usedCapacity=0.15625 absoluteUsedCapacity=0.15625 used=<memory:5120, vCores:4> cluster=<memory:32768, vCores:32>
2014-04-21 19:03:51,852 INFO org.apache.hadoop.yarn.server.resourcemanager.scheduler.capacity.ParentQueue: completedContainer queue=root usedCapacity=0.15625 absoluteUsedCapacity=0.15625 used=<memory:5120, vCores:4> cluster=<memory:32768, vCores:32>
2014-04-21 19:03:51,852 INFO org.apache.hadoop.yarn.server.resourcemanager.scheduler.capacity.ParentQueue: Re-sorting completed queue: root.default stats: default: capacity=1.0, absoluteCapacity=1.0, usedResources=<memory:5120, vCores:4>usedCapacity=0.15625, absoluteUsedCapacity=0.15625, numApps=1, numContainers=4
2014-04-21 19:03:51,852 INFO org.apache.hadoop.yarn.server.resourcemanager.scheduler.capacity.CapacityScheduler: Application appattempt_1398103439608_0002_000001 released container container_1398103439608_0002_01_000005 on node: host: nodec:34990 #containers=0 available=8192 used=0 with event: FINISHED
2014-04-21 19:03:51,868 INFO org.apache.hadoop.yarn.server.resourcemanager.rmapp.attempt.RMAppAttemptImpl: appattempt_1398103439608_0002_000001 State change from RUNNING to FINISHING
2014-04-21 19:03:51,869 INFO org.apache.hadoop.yarn.server.resourcemanager.rmapp.RMAppImpl: Removing application with id application_1398103439608_0002
2014-04-21 19:03:51,869 INFO org.apache.hadoop.yarn.server.resourcemanager.recovery.RMStateStore: Removing info for app: application_1398103439608_0002
2014-04-21 19:03:51,869 INFO org.apache.hadoop.yarn.server.resourcemanager.rmapp.RMAppImpl: application_1398103439608_0002 State change from RUNNING to REMOVING
2014-04-21 19:03:51,869 INFO org.apache.hadoop.yarn.server.resourcemanager.rmapp.RMAppImpl: application_1398103439608_0002 State change from REMOVING to FINISHING
2014-04-21 19:03:52,842 INFO org.apache.hadoop.yarn.server.resourcemanager.rmcontainer.RMContainerImpl: container_1398103439608_0002_01_000004 Container Transitioned from RUNNING to COMPLETED
2014-04-21 19:03:52,843 INFO org.apache.hadoop.yarn.server.resourcemanager.scheduler.common.fica.FiCaSchedulerApp: Completed container: container_1398103439608_0002_01_000004 in state: COMPLETED event:FINISHED
2014-04-21 19:03:52,843 INFO org.apache.hadoop.yarn.server.resourcemanager.RMAuditLogger: USER=ubuntu	OPERATION=AM Released Container	TARGET=SchedulerApp	RESULT=SUCCESS	APPID=application_1398103439608_0002	CONTAINERID=container_1398103439608_0002_01_000004
2014-04-21 19:03:52,843 INFO org.apache.hadoop.yarn.server.resourcemanager.scheduler.common.fica.FiCaSchedulerNode: Released container container_1398103439608_0002_01_000004 of capacity <memory:1024, vCores:1> on host noded:47267, which currently has 0 containers, <memory:0, vCores:0> used and <memory:8192, vCores:8> available, release resources=true
2014-04-21 19:03:52,843 INFO org.apache.hadoop.yarn.server.resourcemanager.scheduler.capacity.LeafQueue: default used=<memory:4096, vCores:3> numContainers=3 user=ubuntu user-resources=<memory:4096, vCores:3>
2014-04-21 19:03:52,843 INFO org.apache.hadoop.yarn.server.resourcemanager.scheduler.capacity.LeafQueue: completedContainer container=Container: [ContainerId: container_1398103439608_0002_01_000004, NodeId: noded:47267, NodeHttpAddress: noded:8042, Resource: <memory:1024, vCores:1>, Priority: 10, Token: Token { kind: ContainerToken, service: 10.0.0.193:47267 }, ] resource=<memory:1024, vCores:1> queue=default: capacity=1.0, absoluteCapacity=1.0, usedResources=<memory:4096, vCores:3>usedCapacity=0.125, absoluteUsedCapacity=0.125, numApps=1, numContainers=3 usedCapacity=0.125 absoluteUsedCapacity=0.125 used=<memory:4096, vCores:3> cluster=<memory:32768, vCores:32>
2014-04-21 19:03:52,843 INFO org.apache.hadoop.yarn.server.resourcemanager.scheduler.capacity.ParentQueue: completedContainer queue=root usedCapacity=0.125 absoluteUsedCapacity=0.125 used=<memory:4096, vCores:3> cluster=<memory:32768, vCores:32>
2014-04-21 19:03:52,844 INFO org.apache.hadoop.yarn.server.resourcemanager.scheduler.capacity.ParentQueue: Re-sorting completed queue: root.default stats: default: capacity=1.0, absoluteCapacity=1.0, usedResources=<memory:4096, vCores:3>usedCapacity=0.125, absoluteUsedCapacity=0.125, numApps=1, numContainers=3
2014-04-21 19:03:52,844 INFO org.apache.hadoop.yarn.server.resourcemanager.scheduler.capacity.CapacityScheduler: Application appattempt_1398103439608_0002_000001 released container container_1398103439608_0002_01_000004 on node: host: noded:47267 #containers=0 available=8192 used=0 with event: FINISHED
2014-04-21 19:03:52,861 INFO org.apache.hadoop.yarn.server.resourcemanager.rmcontainer.RMContainerImpl: container_1398103439608_0002_01_000003 Container Transitioned from RUNNING to COMPLETED
2014-04-21 19:03:52,861 INFO org.apache.hadoop.yarn.server.resourcemanager.scheduler.common.fica.FiCaSchedulerApp: Completed container: container_1398103439608_0002_01_000003 in state: COMPLETED event:FINISHED
2014-04-21 19:03:52,862 INFO org.apache.hadoop.yarn.server.resourcemanager.RMAuditLogger: USER=ubuntu	OPERATION=AM Released Container	TARGET=SchedulerApp	RESULT=SUCCESS	APPID=application_1398103439608_0002	CONTAINERID=container_1398103439608_0002_01_000003
2014-04-21 19:03:52,862 INFO org.apache.hadoop.yarn.server.resourcemanager.scheduler.common.fica.FiCaSchedulerNode: Released container container_1398103439608_0002_01_000003 of capacity <memory:1024, vCores:1> on host nodea:47962, which currently has 0 containers, <memory:0, vCores:0> used and <memory:8192, vCores:8> available, release resources=true
2014-04-21 19:03:52,862 INFO org.apache.hadoop.yarn.server.resourcemanager.scheduler.capacity.LeafQueue: default used=<memory:3072, vCores:2> numContainers=2 user=ubuntu user-resources=<memory:3072, vCores:2>
2014-04-21 19:03:52,862 INFO org.apache.hadoop.yarn.server.resourcemanager.scheduler.capacity.LeafQueue: completedContainer container=Container: [ContainerId: container_1398103439608_0002_01_000003, NodeId: nodea:47962, NodeHttpAddress: nodea:8042, Resource: <memory:1024, vCores:1>, Priority: 10, Token: Token { kind: ContainerToken, service: 10.0.0.54:47962 }, ] resource=<memory:1024, vCores:1> queue=default: capacity=1.0, absoluteCapacity=1.0, usedResources=<memory:3072, vCores:2>usedCapacity=0.09375, absoluteUsedCapacity=0.09375, numApps=1, numContainers=2 usedCapacity=0.09375 absoluteUsedCapacity=0.09375 used=<memory:3072, vCores:2> cluster=<memory:32768, vCores:32>
2014-04-21 19:03:52,862 INFO org.apache.hadoop.yarn.server.resourcemanager.scheduler.capacity.ParentQueue: completedContainer queue=root usedCapacity=0.09375 absoluteUsedCapacity=0.09375 used=<memory:3072, vCores:2> cluster=<memory:32768, vCores:32>
2014-04-21 19:03:52,862 INFO org.apache.hadoop.yarn.server.resourcemanager.scheduler.capacity.ParentQueue: Re-sorting completed queue: root.default stats: default: capacity=1.0, absoluteCapacity=1.0, usedResources=<memory:3072, vCores:2>usedCapacity=0.09375, absoluteUsedCapacity=0.09375, numApps=1, numContainers=2
2014-04-21 19:03:52,862 INFO org.apache.hadoop.yarn.server.resourcemanager.scheduler.capacity.CapacityScheduler: Application appattempt_1398103439608_0002_000001 released container container_1398103439608_0002_01_000003 on node: host: nodea:47962 #containers=0 available=8192 used=0 with event: FINISHED
2014-04-21 19:03:58,417 INFO org.apache.hadoop.yarn.server.resourcemanager.rmcontainer.RMContainerImpl: container_1398103439608_0002_01_000001 Container Transitioned from RUNNING to COMPLETED
2014-04-21 19:03:58,417 INFO org.apache.hadoop.yarn.server.resourcemanager.ApplicationMasterService: Unregistering app attempt : appattempt_1398103439608_0002_000001
2014-04-21 19:03:58,417 INFO org.apache.hadoop.yarn.server.resourcemanager.scheduler.common.fica.FiCaSchedulerApp: Completed container: container_1398103439608_0002_01_000001 in state: COMPLETED event:FINISHED
2014-04-21 19:03:58,417 INFO org.apache.hadoop.yarn.server.resourcemanager.rmapp.attempt.RMAppAttemptImpl: appattempt_1398103439608_0002_000001 State change from FINISHING to FINISHED
2014-04-21 19:03:58,418 INFO org.apache.hadoop.yarn.server.resourcemanager.RMAuditLogger: USER=ubuntu	OPERATION=AM Released Container	TARGET=SchedulerApp	RESULT=SUCCESS	APPID=application_1398103439608_0002	CONTAINERID=container_1398103439608_0002_01_000001
2014-04-21 19:03:58,418 INFO org.apache.hadoop.yarn.server.resourcemanager.rmapp.RMAppImpl: application_1398103439608_0002 State change from FINISHING to FINISHED
2014-04-21 19:03:58,418 INFO org.apache.hadoop.yarn.server.resourcemanager.scheduler.common.fica.FiCaSchedulerNode: Released container container_1398103439608_0002_01_000001 of capacity <memory:2048, vCores:1> on host nodeb:58333, which currently has 1 containers, <memory:1024, vCores:1> used and <memory:7168, vCores:7> available, release resources=true
2014-04-21 19:03:58,418 INFO org.apache.hadoop.yarn.server.resourcemanager.RMAuditLogger: USER=ubuntu	OPERATION=Application Finished - Succeeded	TARGET=RMAppManager	RESULT=SUCCESS	APPID=application_1398103439608_0002
2014-04-21 19:03:58,418 INFO org.apache.hadoop.yarn.server.resourcemanager.scheduler.capacity.LeafQueue: default used=<memory:1024, vCores:1> numContainers=1 user=ubuntu user-resources=<memory:1024, vCores:1>
2014-04-21 19:03:58,418 INFO org.apache.hadoop.yarn.server.resourcemanager.RMAppManager$ApplicationSummary: appId=application_1398103439608_0002,name=partitioner||path:/dict||num reduce:4,user=ubuntu,queue=default,state=FINISHED,trackingUrl=ec2-54-187-121-79.us-west-2.compute.amazonaws.com:8088/proxy/application_1398103439608_0002/jobhistory/job/job_1398103439608_0002,appMasterHost=ip-10-0-0-199,startTime=1398106998955,finishTime=1398107031869,finalStatus=FAILED
2014-04-21 19:03:58,419 INFO org.apache.hadoop.yarn.server.resourcemanager.scheduler.capacity.LeafQueue: completedContainer container=Container: [ContainerId: container_1398103439608_0002_01_000001, NodeId: nodeb:58333, NodeHttpAddress: nodeb:8042, Resource: <memory:2048, vCores:1>, Priority: 0, Token: Token { kind: ContainerToken, service: 10.0.0.199:58333 }, ] resource=<memory:2048, vCores:1> queue=default: capacity=1.0, absoluteCapacity=1.0, usedResources=<memory:1024, vCores:1>usedCapacity=0.03125, absoluteUsedCapacity=0.03125, numApps=1, numContainers=1 usedCapacity=0.03125 absoluteUsedCapacity=0.03125 used=<memory:1024, vCores:1> cluster=<memory:32768, vCores:32>
2014-04-21 19:03:58,419 INFO org.apache.hadoop.yarn.server.resourcemanager.scheduler.capacity.ParentQueue: completedContainer queue=root usedCapacity=0.03125 absoluteUsedCapacity=0.03125 used=<memory:1024, vCores:1> cluster=<memory:32768, vCores:32>
2014-04-21 19:03:58,419 INFO org.apache.hadoop.yarn.server.resourcemanager.amlauncher.AMLauncher: Cleaning master appattempt_1398103439608_0002_000001
2014-04-21 19:03:58,420 INFO org.apache.hadoop.yarn.server.resourcemanager.scheduler.capacity.ParentQueue: Re-sorting completed queue: root.default stats: default: capacity=1.0, absoluteCapacity=1.0, usedResources=<memory:1024, vCores:1>usedCapacity=0.03125, absoluteUsedCapacity=0.03125, numApps=1, numContainers=1
2014-04-21 19:03:58,420 INFO org.apache.hadoop.yarn.server.resourcemanager.scheduler.capacity.CapacityScheduler: Application appattempt_1398103439608_0002_000001 released container container_1398103439608_0002_01_000001 on node: host: nodeb:58333 #containers=1 available=7168 used=1024 with event: FINISHED
2014-04-21 19:03:58,420 INFO org.apache.hadoop.yarn.server.resourcemanager.scheduler.capacity.CapacityScheduler: Application appattempt_1398103439608_0002_000001 is done. finalState=FINISHED
2014-04-21 19:03:58,421 INFO org.apache.hadoop.yarn.server.resourcemanager.rmcontainer.RMContainerImpl: container_1398103439608_0002_01_000006 Container Transitioned from ACQUIRED to KILLED
2014-04-21 19:03:58,421 INFO org.apache.hadoop.yarn.server.resourcemanager.scheduler.common.fica.FiCaSchedulerApp: Completed container: container_1398103439608_0002_01_000006 in state: KILLED event:KILL
2014-04-21 19:03:58,421 INFO org.apache.hadoop.yarn.server.resourcemanager.RMAuditLogger: USER=ubuntu	OPERATION=AM Released Container	TARGET=SchedulerApp	RESULT=SUCCESS	APPID=application_1398103439608_0002	CONTAINERID=container_1398103439608_0002_01_000006
2014-04-21 19:03:58,421 INFO org.apache.hadoop.yarn.server.resourcemanager.scheduler.common.fica.FiCaSchedulerNode: Released container container_1398103439608_0002_01_000006 of capacity <memory:1024, vCores:1> on host nodeb:58333, which currently has 0 containers, <memory:0, vCores:0> used and <memory:8192, vCores:8> available, release resources=true
2014-04-21 19:03:58,421 INFO org.apache.hadoop.yarn.server.resourcemanager.scheduler.capacity.LeafQueue: default used=<memory:0, vCores:0> numContainers=0 user=ubuntu user-resources=<memory:0, vCores:0>
2014-04-21 19:03:58,421 INFO org.apache.hadoop.yarn.server.resourcemanager.scheduler.capacity.LeafQueue: completedContainer container=Container: [ContainerId: container_1398103439608_0002_01_000006, NodeId: nodeb:58333, NodeHttpAddress: nodeb:8042, Resource: <memory:1024, vCores:1>, Priority: 10, Token: Token { kind: ContainerToken, service: 10.0.0.199:58333 }, ] resource=<memory:1024, vCores:1> queue=default: capacity=1.0, absoluteCapacity=1.0, usedResources=<memory:0, vCores:0>usedCapacity=0.0, absoluteUsedCapacity=0.0, numApps=1, numContainers=0 usedCapacity=0.0 absoluteUsedCapacity=0.0 used=<memory:0, vCores:0> cluster=<memory:32768, vCores:32>
2014-04-21 19:03:58,422 INFO org.apache.hadoop.yarn.server.resourcemanager.scheduler.capacity.ParentQueue: completedContainer queue=root usedCapacity=0.0 absoluteUsedCapacity=0.0 used=<memory:0, vCores:0> cluster=<memory:32768, vCores:32>
2014-04-21 19:03:58,422 INFO org.apache.hadoop.yarn.server.resourcemanager.scheduler.capacity.ParentQueue: Re-sorting completed queue: root.default stats: default: capacity=1.0, absoluteCapacity=1.0, usedResources=<memory:0, vCores:0>usedCapacity=0.0, absoluteUsedCapacity=0.0, numApps=1, numContainers=0
2014-04-21 19:03:58,422 INFO org.apache.hadoop.yarn.server.resourcemanager.scheduler.capacity.CapacityScheduler: Application appattempt_1398103439608_0002_000001 released container container_1398103439608_0002_01_000006 on node: host: nodeb:58333 #containers=0 available=8192 used=0 with event: KILL
2014-04-21 19:03:58,422 INFO org.apache.hadoop.yarn.server.resourcemanager.scheduler.AppSchedulingInfo: Application application_1398103439608_0002 requests cleared
2014-04-21 19:03:58,422 INFO org.apache.hadoop.yarn.server.resourcemanager.scheduler.capacity.LeafQueue: Application removed - appId: application_1398103439608_0002 user: ubuntu queue: default #user-pending-applications: 0 #user-active-applications: 0 #queue-pending-applications: 0 #queue-active-applications: 0
2014-04-21 19:03:58,422 INFO org.apache.hadoop.yarn.server.resourcemanager.scheduler.capacity.ParentQueue: Application removed - appId: application_1398103439608_0002 user: ubuntu leaf-queue of parent: root #applications: 0
2014-04-21 19:04:20,187 INFO org.apache.hadoop.yarn.server.webproxy.WebAppProxyServlet: dr.who is accessing unchecked http://nodeb:19888/jobhistory/job/job_1398103439608_0002/mapreduce/attempts/job_1398103439608_0002/r/NEW which is the app master GUI of application_1398103439608_0002 owned by ubuntu
2014-04-21 19:41:58,156 ERROR org.apache.hadoop.yarn.server.resourcemanager.ResourceManager: RECEIVED SIGNAL 15: SIGTERM
2014-04-21 19:41:58,168 INFO org.mortbay.log: Stopped SelectChannelConnector@ec2-54-187-121-79.us-west-2.compute.amazonaws.com:8088
2014-04-21 19:41:58,276 ERROR org.apache.hadoop.security.token.delegation.AbstractDelegationTokenSecretManager: InterruptedExcpetion recieved for ExpiredTokenRemover thread java.lang.InterruptedException: sleep interrupted
2014-04-21 19:41:58,277 INFO org.apache.hadoop.metrics2.impl.MetricsSystemImpl: Stopping ResourceManager metrics system...
2014-04-21 19:41:58,280 INFO org.apache.hadoop.metrics2.impl.MetricsSystemImpl: ResourceManager metrics system stopped.
2014-04-21 19:41:58,280 INFO org.apache.hadoop.metrics2.impl.MetricsSystemImpl: ResourceManager metrics system shutdown complete.
2014-04-21 19:41:58,283 WARN org.apache.hadoop.yarn.server.resourcemanager.amlauncher.ApplicationMasterLauncher: org.apache.hadoop.yarn.server.resourcemanager.amlauncher.ApplicationMasterLauncher$LauncherThread interrupted. Returning.
2014-04-21 19:41:58,284 INFO org.apache.hadoop.ipc.Server: Stopping server on 8033
2014-04-21 19:41:58,287 INFO org.apache.hadoop.ipc.Server: Stopping IPC Server listener on 8033
2014-04-21 19:41:58,287 INFO org.apache.hadoop.ipc.Server: Stopping IPC Server Responder
2014-04-21 19:41:58,288 INFO org.apache.hadoop.ipc.Server: Stopping server on 8032
2014-04-21 19:41:58,305 INFO org.apache.hadoop.ipc.Server: Stopping IPC Server listener on 8032
2014-04-21 19:41:58,306 INFO org.apache.hadoop.ipc.Server: Stopping IPC Server Responder
2014-04-21 19:41:58,307 INFO org.apache.hadoop.ipc.Server: Stopping server on 8030
2014-04-21 19:41:58,316 INFO org.apache.hadoop.ipc.Server: Stopping IPC Server listener on 8030
2014-04-21 19:41:58,317 INFO org.apache.hadoop.ipc.Server: Stopping IPC Server Responder
2014-04-21 19:41:58,318 INFO org.apache.hadoop.ipc.Server: Stopping server on 8031
2014-04-21 19:41:58,323 INFO org.apache.hadoop.ipc.Server: Stopping IPC Server listener on 8031
2014-04-21 19:41:58,326 INFO org.apache.hadoop.ipc.Server: Stopping IPC Server Responder
2014-04-21 19:41:58,326 ERROR org.apache.hadoop.yarn.server.resourcemanager.ResourceManager: Returning, interrupted : java.lang.InterruptedException
2014-04-21 19:41:58,327 INFO org.apache.hadoop.yarn.util.AbstractLivelinessMonitor: AMLivelinessMonitor thread interrupted
2014-04-21 19:41:58,327 INFO org.apache.hadoop.yarn.util.AbstractLivelinessMonitor: AMLivelinessMonitor thread interrupted
2014-04-21 19:41:58,327 INFO org.apache.hadoop.yarn.util.AbstractLivelinessMonitor: org.apache.hadoop.yarn.server.resourcemanager.rmcontainer.ContainerAllocationExpirer thread interrupted
2014-04-21 19:41:58,327 INFO org.apache.hadoop.yarn.util.AbstractLivelinessMonitor: NMLivelinessMonitor thread interrupted
2014-04-21 19:41:58,329 INFO org.apache.hadoop.yarn.server.resourcemanager.ResourceManager: SHUTDOWN_MSG: 
/************************************************************
SHUTDOWN_MSG: Shutting down ResourceManager at ip-10-0-0-54/10.0.0.54
************************************************************/
