2014-04-01 01:35:19,832 INFO org.apache.hadoop.yarn.server.resourcemanager.ResourceManager: STARTUP_MSG: 
/************************************************************
STARTUP_MSG: Starting ResourceManager
STARTUP_MSG:   host = ubuntu/127.0.1.1
STARTUP_MSG:   args = []
STARTUP_MSG:   version = 2.2.0
STARTUP_MSG:   build = Unknown -r Unknown; compiled by 'root' on 2014-04-01T16:41Z
STARTUP_MSG:   java = 1.7.0_51
************************************************************/
2014-04-01 01:35:19,836 INFO org.apache.hadoop.yarn.server.resourcemanager.ResourceManager: registered UNIX signal handlers for [TERM, HUP, INT]
2014-04-01 01:35:20,000 INFO org.apache.hadoop.yarn.server.resourcemanager.security.AMRMTokenSecretManager: Rolling master-key for amrm-tokens
2014-04-01 01:35:20,008 INFO org.apache.hadoop.yarn.server.resourcemanager.security.RMContainerTokenSecretManager: ContainerTokenKeyRollingInterval: 86400000ms and ContainerTokenKeyActivationDelay: 900000ms
2014-04-01 01:35:20,011 INFO org.apache.hadoop.yarn.server.resourcemanager.security.NMTokenSecretManagerInRM: NMTokenKeyRollingInterval: 86400000ms and NMTokenKeyActivationDelay: 900000ms
2014-04-01 01:35:20,015 INFO org.apache.hadoop.yarn.event.AsyncDispatcher: Registering class org.apache.hadoop.yarn.server.resourcemanager.recovery.RMStateStoreEventType for class org.apache.hadoop.yarn.server.resourcemanager.recovery.RMStateStore$ForwardingEventHandler
2014-04-01 01:35:20,144 WARN org.apache.hadoop.util.NativeCodeLoader: Unable to load native-hadoop library for your platform... using builtin-java classes where applicable
2014-04-01 01:35:20,192 INFO org.apache.hadoop.yarn.event.AsyncDispatcher: Registering class org.apache.hadoop.yarn.server.resourcemanager.NodesListManagerEventType for class org.apache.hadoop.yarn.server.resourcemanager.NodesListManager
2014-04-01 01:35:20,211 INFO org.apache.hadoop.yarn.server.resourcemanager.ResourceManager: Using Scheduler: org.apache.hadoop.yarn.server.resourcemanager.scheduler.capacity.CapacityScheduler
2014-04-01 01:35:20,259 INFO org.apache.hadoop.yarn.event.AsyncDispatcher: Registering class org.apache.hadoop.yarn.server.resourcemanager.scheduler.event.SchedulerEventType for class org.apache.hadoop.yarn.server.resourcemanager.ResourceManager$SchedulerEventDispatcher
2014-04-01 01:35:20,259 INFO org.apache.hadoop.yarn.event.AsyncDispatcher: Registering class org.apache.hadoop.yarn.server.resourcemanager.rmapp.RMAppEventType for class org.apache.hadoop.yarn.server.resourcemanager.ResourceManager$ApplicationEventDispatcher
2014-04-01 01:35:20,260 INFO org.apache.hadoop.yarn.event.AsyncDispatcher: Registering class org.apache.hadoop.yarn.server.resourcemanager.rmapp.attempt.RMAppAttemptEventType for class org.apache.hadoop.yarn.server.resourcemanager.ResourceManager$ApplicationAttemptEventDispatcher
2014-04-01 01:35:20,261 INFO org.apache.hadoop.yarn.event.AsyncDispatcher: Registering class org.apache.hadoop.yarn.server.resourcemanager.rmnode.RMNodeEventType for class org.apache.hadoop.yarn.server.resourcemanager.ResourceManager$NodeEventDispatcher
2014-04-01 01:35:20,324 INFO org.apache.hadoop.metrics2.impl.MetricsConfig: loaded properties from hadoop-metrics2.properties
2014-04-01 01:35:20,385 INFO org.apache.hadoop.metrics2.impl.MetricsSystemImpl: Scheduled snapshot period at 10 second(s).
2014-04-01 01:35:20,385 INFO org.apache.hadoop.metrics2.impl.MetricsSystemImpl: ResourceManager metrics system started
2014-04-01 01:35:20,449 INFO org.apache.hadoop.yarn.server.resourcemanager.scheduler.capacity.ParentQueue: root, capacity=1.0, asboluteCapacity=1.0, maxCapacity=1.0, asboluteMaxCapacity=1.0, state=RUNNING, acls=ADMINISTER_QUEUE:*SUBMIT_APPLICATIONS:*
2014-04-01 01:35:20,449 INFO org.apache.hadoop.yarn.server.resourcemanager.scheduler.capacity.ParentQueue: Initialized parent-queue root name=root, fullname=root
2014-04-01 01:35:20,459 INFO org.apache.hadoop.yarn.server.resourcemanager.scheduler.capacity.LeafQueue: Initializing default
capacity = 1.0 [= (float) configuredCapacity / 100 ]
asboluteCapacity = 1.0 [= parentAbsoluteCapacity * capacity ]
maxCapacity = 1.0 [= configuredMaxCapacity ]
absoluteMaxCapacity = 1.0 [= 1.0 maximumCapacity undefined, (parentAbsoluteMaxCapacity * maximumCapacity) / 100 otherwise ]
userLimit = 100 [= configuredUserLimit ]
userLimitFactor = 1.0 [= configuredUserLimitFactor ]
maxApplications = 10000 [= configuredMaximumSystemApplicationsPerQueue or (int)(configuredMaximumSystemApplications * absoluteCapacity)]
maxApplicationsPerUser = 10000 [= (int)(maxApplications * (userLimit / 100.0f) * userLimitFactor) ]
maxActiveApplications = 1 [= max((int)ceil((clusterResourceMemory / minimumAllocation) * maxAMResourcePerQueuePercent * absoluteMaxCapacity),1) ]
maxActiveAppsUsingAbsCap = 1 [= max((int)ceil((clusterResourceMemory / minimumAllocation) *maxAMResourcePercent * absoluteCapacity),1) ]
maxActiveApplicationsPerUser = 1 [= max((int)(maxActiveApplications * (userLimit / 100.0f) * userLimitFactor),1) ]
usedCapacity = 0.0 [= usedResourcesMemory / (clusterResourceMemory * absoluteCapacity)]
absoluteUsedCapacity = 0.0 [= usedResourcesMemory / clusterResourceMemory]
maxAMResourcePerQueuePercent = 0.1 [= configuredMaximumAMResourcePercent ]
minimumAllocationFactor = 0.875 [= (float)(maximumAllocationMemory - minimumAllocationMemory) / maximumAllocationMemory ]
numContainers = 0 [= currentNumContainers ]
state = RUNNING [= configuredState ]
acls = ADMINISTER_QUEUE:*SUBMIT_APPLICATIONS:* [= configuredAcls ]
nodeLocalityDelay = 0

2014-04-01 01:35:20,460 INFO org.apache.hadoop.yarn.server.resourcemanager.scheduler.capacity.CapacityScheduler: Initialized queue: default: capacity=1.0, absoluteCapacity=1.0, usedResources=<memory:0, vCores:0>usedCapacity=0.0, absoluteUsedCapacity=0.0, numApps=0, numContainers=0
2014-04-01 01:35:20,460 INFO org.apache.hadoop.yarn.server.resourcemanager.scheduler.capacity.CapacityScheduler: Initialized queue: root: numChildQueue= 1, capacity=1.0, absoluteCapacity=1.0, usedResources=<memory:0, vCores:0>usedCapacity=0.0, numApps=0, numContainers=0
2014-04-01 01:35:20,460 INFO org.apache.hadoop.yarn.server.resourcemanager.scheduler.capacity.CapacityScheduler: Initialized root queue root: numChildQueue= 1, capacity=1.0, absoluteCapacity=1.0, usedResources=<memory:0, vCores:0>usedCapacity=0.0, numApps=0, numContainers=0
2014-04-01 01:35:20,460 INFO org.apache.hadoop.yarn.server.resourcemanager.scheduler.capacity.CapacityScheduler: Initialized CapacityScheduler with calculator=class org.apache.hadoop.yarn.util.resource.DefaultResourceCalculator, minimumAllocation=<<memory:1024, vCores:1>>, maximumAllocation=<<memory:8192, vCores:32>>
2014-04-01 01:35:20,500 INFO org.apache.hadoop.yarn.event.AsyncDispatcher: Registering class org.apache.hadoop.yarn.server.resourcemanager.RMAppManagerEventType for class org.apache.hadoop.yarn.server.resourcemanager.RMAppManager
2014-04-01 01:35:20,519 INFO org.apache.hadoop.yarn.event.AsyncDispatcher: Registering class org.apache.hadoop.yarn.server.resourcemanager.amlauncher.AMLauncherEventType for class org.apache.hadoop.yarn.server.resourcemanager.amlauncher.ApplicationMasterLauncher
2014-04-01 01:35:20,523 INFO org.apache.hadoop.yarn.server.resourcemanager.RMNMInfo: Registered RMNMInfo MBean
2014-04-01 01:35:20,524 INFO org.apache.hadoop.util.HostsFileReader: Refreshing hosts (include/exclude) list
2014-04-01 01:35:20,527 INFO org.apache.hadoop.yarn.server.resourcemanager.security.RMContainerTokenSecretManager: Rolling master-key for container-tokens
2014-04-01 01:35:20,527 INFO org.apache.hadoop.yarn.server.resourcemanager.security.AMRMTokenSecretManager: Rolling master-key for amrm-tokens
2014-04-01 01:35:20,529 INFO org.apache.hadoop.yarn.server.resourcemanager.security.NMTokenSecretManagerInRM: Rolling master-key for nm-tokens
2014-04-01 01:35:20,564 INFO org.mortbay.log: Logging to org.slf4j.impl.Log4jLoggerAdapter(org.mortbay.log) via org.mortbay.log.Slf4jLog
2014-04-01 01:35:20,611 INFO org.apache.hadoop.http.HttpServer: Added global filter 'safety' (class=org.apache.hadoop.http.HttpServer$QuotingInputFilter)
2014-04-01 01:35:20,613 INFO org.apache.hadoop.http.HttpServer: Added filter static_user_filter (class=org.apache.hadoop.http.lib.StaticUserWebFilter$StaticUserFilter) to context cluster
2014-04-01 01:35:20,613 INFO org.apache.hadoop.http.HttpServer: Added filter static_user_filter (class=org.apache.hadoop.http.lib.StaticUserWebFilter$StaticUserFilter) to context logs
2014-04-01 01:35:20,613 INFO org.apache.hadoop.http.HttpServer: Added filter static_user_filter (class=org.apache.hadoop.http.lib.StaticUserWebFilter$StaticUserFilter) to context static
2014-04-01 01:35:20,615 INFO org.apache.hadoop.http.HttpServer: adding path spec: /cluster/*
2014-04-01 01:35:20,615 INFO org.apache.hadoop.http.HttpServer: adding path spec: /ws/*
2014-04-01 01:35:20,621 INFO org.apache.hadoop.http.HttpServer: Jetty bound to port 8088
2014-04-01 01:35:20,621 INFO org.mortbay.log: jetty-6.1.26
2014-04-01 01:35:20,639 INFO org.mortbay.log: Extract jar:file:/home/hduser/PatchedDistro/patched_hadoop/share/hadoop/yarn/hadoop-yarn-common-2.2.0.jar!/webapps/cluster to /tmp/Jetty_0_0_0_0_8088_cluster____u0rgz3/webapp
2014-04-01 01:35:20,776 INFO org.mortbay.log: Started SelectChannelConnector@0.0.0.0:8088
2014-04-01 01:35:20,776 INFO org.apache.hadoop.yarn.webapp.WebApps: Web app /cluster started at 8088
2014-04-01 01:35:21,072 INFO org.apache.hadoop.yarn.webapp.WebApps: Registered webapp guice modules
2014-04-01 01:35:21,073 INFO org.apache.hadoop.security.token.delegation.AbstractDelegationTokenSecretManager: Updating the current master key for generating delegation tokens
2014-04-01 01:35:21,073 INFO org.apache.hadoop.yarn.server.resourcemanager.security.RMDelegationTokenSecretManager: storing master key with keyID 1
2014-04-01 01:35:21,074 INFO org.apache.hadoop.security.token.delegation.AbstractDelegationTokenSecretManager: Starting expired delegation token remover thread, tokenRemoverScanInterval=60 min(s)
2014-04-01 01:35:21,074 INFO org.apache.hadoop.security.token.delegation.AbstractDelegationTokenSecretManager: Updating the current master key for generating delegation tokens
2014-04-01 01:35:21,074 INFO org.apache.hadoop.yarn.server.resourcemanager.security.RMDelegationTokenSecretManager: storing master key with keyID 2
2014-04-01 01:35:26,123 INFO org.apache.hadoop.ipc.Server: Starting Socket Reader #1 for port 8031
2014-04-01 01:35:26,137 INFO org.apache.hadoop.yarn.factories.impl.pb.RpcServerFactoryPBImpl: Adding protocol org.apache.hadoop.yarn.server.api.ResourceTrackerPB to the server
2014-04-01 01:35:26,137 INFO org.apache.hadoop.ipc.Server: IPC Server Responder: starting
2014-04-01 01:35:26,138 INFO org.apache.hadoop.ipc.Server: IPC Server listener on 8031: starting
2014-04-01 01:35:31,187 INFO org.apache.hadoop.ipc.Server: Starting Socket Reader #1 for port 8030
2014-04-01 01:35:31,251 INFO org.apache.hadoop.yarn.factories.impl.pb.RpcServerFactoryPBImpl: Adding protocol org.apache.hadoop.yarn.api.ApplicationMasterProtocolPB to the server
2014-04-01 01:35:31,252 INFO org.apache.hadoop.ipc.Server: IPC Server Responder: starting
2014-04-01 01:35:31,252 INFO org.apache.hadoop.ipc.Server: IPC Server listener on 8030: starting
2014-04-01 01:35:36,348 INFO org.apache.hadoop.ipc.Server: Starting Socket Reader #1 for port 8032
2014-04-01 01:35:36,351 INFO org.apache.hadoop.yarn.factories.impl.pb.RpcServerFactoryPBImpl: Adding protocol org.apache.hadoop.yarn.api.ApplicationClientProtocolPB to the server
2014-04-01 01:35:36,352 INFO org.apache.hadoop.ipc.Server: IPC Server Responder: starting
2014-04-01 01:35:36,355 INFO org.apache.hadoop.ipc.Server: IPC Server listener on 8032: starting
2014-04-01 01:35:41,417 INFO org.apache.hadoop.ipc.Server: Starting Socket Reader #1 for port 8033
2014-04-01 01:35:41,420 INFO org.apache.hadoop.yarn.factories.impl.pb.RpcServerFactoryPBImpl: Adding protocol org.apache.hadoop.yarn.server.api.ResourceManagerAdministrationProtocolPB to the server
2014-04-01 01:35:41,420 INFO org.apache.hadoop.ipc.Server: IPC Server Responder: starting
2014-04-01 01:35:41,421 INFO org.apache.hadoop.ipc.Server: IPC Server listener on 8033: starting
2014-04-01 01:37:29,440 INFO org.apache.hadoop.yarn.util.RackResolver: Resolved ubuntu to /default-rack
2014-04-01 01:37:29,444 INFO org.apache.hadoop.yarn.server.resourcemanager.rmnode.RMNodeImpl: ubuntu:49640 Node Transitioned from NEW to RUNNING
2014-04-01 01:37:29,446 INFO org.apache.hadoop.yarn.server.resourcemanager.scheduler.capacity.CapacityScheduler: Added node ubuntu:49640 clusterResource: <memory:8192, vCores:8>
2014-04-01 01:37:29,446 INFO org.apache.hadoop.yarn.server.resourcemanager.ResourceTrackerService: NodeManager from node ubuntu(cmPort: 49640 httpPort: 8042) registered with capability: <memory:8192, vCores:8>, assigned nodeId ubuntu:49640
2014-04-01 01:39:34,736 INFO org.apache.hadoop.yarn.server.resourcemanager.ClientRMService: Allocated new applicationId: 1
2014-04-01 01:40:27,911 INFO org.apache.hadoop.yarn.server.resourcemanager.ClientRMService: Allocated new applicationId: 2
2014-04-01 01:42:55,049 ERROR org.apache.hadoop.yarn.server.resourcemanager.ResourceManager: RECEIVED SIGNAL 15: SIGTERM
2014-04-01 01:42:55,053 INFO org.mortbay.log: Stopped SelectChannelConnector@0.0.0.0:8088
2014-04-01 01:42:55,154 ERROR org.apache.hadoop.security.token.delegation.AbstractDelegationTokenSecretManager: InterruptedExcpetion recieved for ExpiredTokenRemover thread java.lang.InterruptedException: sleep interrupted
2014-04-01 01:42:55,155 INFO org.apache.hadoop.metrics2.impl.MetricsSystemImpl: Stopping ResourceManager metrics system...
2014-04-01 01:42:55,160 INFO org.apache.hadoop.metrics2.impl.MetricsSystemImpl: ResourceManager metrics system stopped.
2014-04-01 01:42:55,160 INFO org.apache.hadoop.metrics2.impl.MetricsSystemImpl: ResourceManager metrics system shutdown complete.
2014-04-01 01:42:55,160 WARN org.apache.hadoop.yarn.server.resourcemanager.amlauncher.ApplicationMasterLauncher: org.apache.hadoop.yarn.server.resourcemanager.amlauncher.ApplicationMasterLauncher$LauncherThread interrupted. Returning.
2014-04-01 01:42:55,161 INFO org.apache.hadoop.ipc.Server: Stopping server on 8033
2014-04-01 01:42:55,163 INFO org.apache.hadoop.ipc.Server: Stopping IPC Server Responder
2014-04-01 01:42:55,163 INFO org.apache.hadoop.ipc.Server: Stopping IPC Server listener on 8033
2014-04-01 01:42:55,163 INFO org.apache.hadoop.ipc.Server: Stopping server on 8032
2014-04-01 01:42:55,168 INFO org.apache.hadoop.ipc.Server: Stopping IPC Server listener on 8032
2014-04-01 01:42:55,168 INFO org.apache.hadoop.ipc.Server: Stopping server on 8030
2014-04-01 01:42:55,169 INFO org.apache.hadoop.ipc.Server: Stopping IPC Server Responder
2014-04-01 01:42:55,171 INFO org.apache.hadoop.ipc.Server: Stopping IPC Server listener on 8030
2014-04-01 01:42:55,172 INFO org.apache.hadoop.ipc.Server: Stopping IPC Server Responder
2014-04-01 01:42:55,172 INFO org.apache.hadoop.ipc.Server: Stopping server on 8031
2014-04-01 01:42:55,176 INFO org.apache.hadoop.ipc.Server: Stopping IPC Server listener on 8031
2014-04-01 01:42:55,176 ERROR org.apache.hadoop.yarn.server.resourcemanager.ResourceManager: Returning, interrupted : java.lang.InterruptedException
2014-04-01 01:42:55,176 INFO org.apache.hadoop.yarn.util.AbstractLivelinessMonitor: AMLivelinessMonitor thread interrupted
2014-04-01 01:42:55,177 INFO org.apache.hadoop.yarn.util.AbstractLivelinessMonitor: NMLivelinessMonitor thread interrupted
2014-04-01 01:42:55,177 INFO org.apache.hadoop.yarn.util.AbstractLivelinessMonitor: org.apache.hadoop.yarn.server.resourcemanager.rmcontainer.ContainerAllocationExpirer thread interrupted
2014-04-01 01:42:55,177 INFO org.apache.hadoop.yarn.util.AbstractLivelinessMonitor: AMLivelinessMonitor thread interrupted
2014-04-01 01:42:55,177 INFO org.apache.hadoop.ipc.Server: Stopping IPC Server Responder
2014-04-01 01:42:55,178 INFO org.apache.hadoop.yarn.server.resourcemanager.ResourceManager: SHUTDOWN_MSG: 
/************************************************************
SHUTDOWN_MSG: Shutting down ResourceManager at ubuntu/127.0.1.1
************************************************************/
2014-04-01 01:46:45,717 INFO org.apache.hadoop.yarn.server.resourcemanager.ResourceManager: STARTUP_MSG: 
/************************************************************
STARTUP_MSG: Starting ResourceManager
STARTUP_MSG:   host = ubuntu/127.0.1.1
STARTUP_MSG:   args = []
STARTUP_MSG:   version = 2.2.0
STARTUP_MSG:   build = Unknown -r Unknown; compiled by 'root' on 2014-04-01T16:41Z
STARTUP_MSG:   java = 1.7.0_51
************************************************************/
2014-04-01 01:46:45,725 INFO org.apache.hadoop.yarn.server.resourcemanager.ResourceManager: registered UNIX signal handlers for [TERM, HUP, INT]
2014-04-01 01:46:45,956 INFO org.apache.hadoop.yarn.server.resourcemanager.security.AMRMTokenSecretManager: Rolling master-key for amrm-tokens
2014-04-01 01:46:45,963 INFO org.apache.hadoop.yarn.server.resourcemanager.security.RMContainerTokenSecretManager: ContainerTokenKeyRollingInterval: 86400000ms and ContainerTokenKeyActivationDelay: 900000ms
2014-04-01 01:46:45,965 INFO org.apache.hadoop.yarn.server.resourcemanager.security.NMTokenSecretManagerInRM: NMTokenKeyRollingInterval: 86400000ms and NMTokenKeyActivationDelay: 900000ms
2014-04-01 01:46:45,970 INFO org.apache.hadoop.yarn.event.AsyncDispatcher: Registering class org.apache.hadoop.yarn.server.resourcemanager.recovery.RMStateStoreEventType for class org.apache.hadoop.yarn.server.resourcemanager.recovery.RMStateStore$ForwardingEventHandler
2014-04-01 01:46:46,131 WARN org.apache.hadoop.util.NativeCodeLoader: Unable to load native-hadoop library for your platform... using builtin-java classes where applicable
2014-04-01 01:46:46,186 INFO org.apache.hadoop.yarn.event.AsyncDispatcher: Registering class org.apache.hadoop.yarn.server.resourcemanager.NodesListManagerEventType for class org.apache.hadoop.yarn.server.resourcemanager.NodesListManager
2014-04-01 01:46:46,205 INFO org.apache.hadoop.yarn.server.resourcemanager.ResourceManager: Using Scheduler: org.apache.hadoop.yarn.server.resourcemanager.scheduler.capacity.CapacityScheduler
2014-04-01 01:46:46,283 INFO org.apache.hadoop.yarn.event.AsyncDispatcher: Registering class org.apache.hadoop.yarn.server.resourcemanager.scheduler.event.SchedulerEventType for class org.apache.hadoop.yarn.server.resourcemanager.ResourceManager$SchedulerEventDispatcher
2014-04-01 01:46:46,284 INFO org.apache.hadoop.yarn.event.AsyncDispatcher: Registering class org.apache.hadoop.yarn.server.resourcemanager.rmapp.RMAppEventType for class org.apache.hadoop.yarn.server.resourcemanager.ResourceManager$ApplicationEventDispatcher
2014-04-01 01:46:46,285 INFO org.apache.hadoop.yarn.event.AsyncDispatcher: Registering class org.apache.hadoop.yarn.server.resourcemanager.rmapp.attempt.RMAppAttemptEventType for class org.apache.hadoop.yarn.server.resourcemanager.ResourceManager$ApplicationAttemptEventDispatcher
2014-04-01 01:46:46,285 INFO org.apache.hadoop.yarn.event.AsyncDispatcher: Registering class org.apache.hadoop.yarn.server.resourcemanager.rmnode.RMNodeEventType for class org.apache.hadoop.yarn.server.resourcemanager.ResourceManager$NodeEventDispatcher
2014-04-01 01:46:46,355 INFO org.apache.hadoop.metrics2.impl.MetricsConfig: loaded properties from hadoop-metrics2.properties
2014-04-01 01:46:46,403 INFO org.apache.hadoop.metrics2.impl.MetricsSystemImpl: Scheduled snapshot period at 10 second(s).
2014-04-01 01:46:46,403 INFO org.apache.hadoop.metrics2.impl.MetricsSystemImpl: ResourceManager metrics system started
2014-04-01 01:46:46,450 INFO org.apache.hadoop.yarn.server.resourcemanager.scheduler.capacity.ParentQueue: root, capacity=1.0, asboluteCapacity=1.0, maxCapacity=1.0, asboluteMaxCapacity=1.0, state=RUNNING, acls=ADMINISTER_QUEUE:*SUBMIT_APPLICATIONS:*
2014-04-01 01:46:46,450 INFO org.apache.hadoop.yarn.server.resourcemanager.scheduler.capacity.ParentQueue: Initialized parent-queue root name=root, fullname=root
2014-04-01 01:46:46,464 INFO org.apache.hadoop.yarn.server.resourcemanager.scheduler.capacity.LeafQueue: Initializing default
capacity = 1.0 [= (float) configuredCapacity / 100 ]
asboluteCapacity = 1.0 [= parentAbsoluteCapacity * capacity ]
maxCapacity = 1.0 [= configuredMaxCapacity ]
absoluteMaxCapacity = 1.0 [= 1.0 maximumCapacity undefined, (parentAbsoluteMaxCapacity * maximumCapacity) / 100 otherwise ]
userLimit = 100 [= configuredUserLimit ]
userLimitFactor = 1.0 [= configuredUserLimitFactor ]
maxApplications = 10000 [= configuredMaximumSystemApplicationsPerQueue or (int)(configuredMaximumSystemApplications * absoluteCapacity)]
maxApplicationsPerUser = 10000 [= (int)(maxApplications * (userLimit / 100.0f) * userLimitFactor) ]
maxActiveApplications = 1 [= max((int)ceil((clusterResourceMemory / minimumAllocation) * maxAMResourcePerQueuePercent * absoluteMaxCapacity),1) ]
maxActiveAppsUsingAbsCap = 1 [= max((int)ceil((clusterResourceMemory / minimumAllocation) *maxAMResourcePercent * absoluteCapacity),1) ]
maxActiveApplicationsPerUser = 1 [= max((int)(maxActiveApplications * (userLimit / 100.0f) * userLimitFactor),1) ]
usedCapacity = 0.0 [= usedResourcesMemory / (clusterResourceMemory * absoluteCapacity)]
absoluteUsedCapacity = 0.0 [= usedResourcesMemory / clusterResourceMemory]
maxAMResourcePerQueuePercent = 0.1 [= configuredMaximumAMResourcePercent ]
minimumAllocationFactor = 0.875 [= (float)(maximumAllocationMemory - minimumAllocationMemory) / maximumAllocationMemory ]
numContainers = 0 [= currentNumContainers ]
state = RUNNING [= configuredState ]
acls = ADMINISTER_QUEUE:*SUBMIT_APPLICATIONS:* [= configuredAcls ]
nodeLocalityDelay = 0

2014-04-01 01:46:46,464 INFO org.apache.hadoop.yarn.server.resourcemanager.scheduler.capacity.CapacityScheduler: Initialized queue: default: capacity=1.0, absoluteCapacity=1.0, usedResources=<memory:0, vCores:0>usedCapacity=0.0, absoluteUsedCapacity=0.0, numApps=0, numContainers=0
2014-04-01 01:46:46,464 INFO org.apache.hadoop.yarn.server.resourcemanager.scheduler.capacity.CapacityScheduler: Initialized queue: root: numChildQueue= 1, capacity=1.0, absoluteCapacity=1.0, usedResources=<memory:0, vCores:0>usedCapacity=0.0, numApps=0, numContainers=0
2014-04-01 01:46:46,464 INFO org.apache.hadoop.yarn.server.resourcemanager.scheduler.capacity.CapacityScheduler: Initialized root queue root: numChildQueue= 1, capacity=1.0, absoluteCapacity=1.0, usedResources=<memory:0, vCores:0>usedCapacity=0.0, numApps=0, numContainers=0
2014-04-01 01:46:46,464 INFO org.apache.hadoop.yarn.server.resourcemanager.scheduler.capacity.CapacityScheduler: Initialized CapacityScheduler with calculator=class org.apache.hadoop.yarn.util.resource.DefaultResourceCalculator, minimumAllocation=<<memory:1024, vCores:1>>, maximumAllocation=<<memory:8192, vCores:32>>
2014-04-01 01:46:46,502 INFO org.apache.hadoop.yarn.event.AsyncDispatcher: Registering class org.apache.hadoop.yarn.server.resourcemanager.RMAppManagerEventType for class org.apache.hadoop.yarn.server.resourcemanager.RMAppManager
2014-04-01 01:46:46,509 INFO org.apache.hadoop.yarn.event.AsyncDispatcher: Registering class org.apache.hadoop.yarn.server.resourcemanager.amlauncher.AMLauncherEventType for class org.apache.hadoop.yarn.server.resourcemanager.amlauncher.ApplicationMasterLauncher
2014-04-01 01:46:46,510 INFO org.apache.hadoop.yarn.server.resourcemanager.RMNMInfo: Registered RMNMInfo MBean
2014-04-01 01:46:46,511 INFO org.apache.hadoop.util.HostsFileReader: Refreshing hosts (include/exclude) list
2014-04-01 01:46:46,514 INFO org.apache.hadoop.yarn.server.resourcemanager.security.RMContainerTokenSecretManager: Rolling master-key for container-tokens
2014-04-01 01:46:46,514 INFO org.apache.hadoop.yarn.server.resourcemanager.security.AMRMTokenSecretManager: Rolling master-key for amrm-tokens
2014-04-01 01:46:46,516 INFO org.apache.hadoop.yarn.server.resourcemanager.security.NMTokenSecretManagerInRM: Rolling master-key for nm-tokens
2014-04-01 01:46:46,550 INFO org.mortbay.log: Logging to org.slf4j.impl.Log4jLoggerAdapter(org.mortbay.log) via org.mortbay.log.Slf4jLog
2014-04-01 01:46:46,589 INFO org.apache.hadoop.http.HttpServer: Added global filter 'safety' (class=org.apache.hadoop.http.HttpServer$QuotingInputFilter)
2014-04-01 01:46:46,591 INFO org.apache.hadoop.http.HttpServer: Added filter static_user_filter (class=org.apache.hadoop.http.lib.StaticUserWebFilter$StaticUserFilter) to context cluster
2014-04-01 01:46:46,591 INFO org.apache.hadoop.http.HttpServer: Added filter static_user_filter (class=org.apache.hadoop.http.lib.StaticUserWebFilter$StaticUserFilter) to context static
2014-04-01 01:46:46,591 INFO org.apache.hadoop.http.HttpServer: Added filter static_user_filter (class=org.apache.hadoop.http.lib.StaticUserWebFilter$StaticUserFilter) to context logs
2014-04-01 01:46:46,594 INFO org.apache.hadoop.http.HttpServer: adding path spec: /cluster/*
2014-04-01 01:46:46,594 INFO org.apache.hadoop.http.HttpServer: adding path spec: /ws/*
2014-04-01 01:46:46,600 INFO org.apache.hadoop.http.HttpServer: Jetty bound to port 8088
2014-04-01 01:46:46,600 INFO org.mortbay.log: jetty-6.1.26
2014-04-01 01:46:46,619 INFO org.mortbay.log: Extract jar:file:/home/hduser/PatchedDistro/patched_hadoop/share/hadoop/yarn/hadoop-yarn-common-2.2.0.jar!/webapps/cluster to /tmp/Jetty_0_0_0_0_8088_cluster____u0rgz3/webapp
2014-04-01 01:46:46,763 INFO org.mortbay.log: Started SelectChannelConnector@0.0.0.0:8088
2014-04-01 01:46:46,764 INFO org.apache.hadoop.yarn.webapp.WebApps: Web app /cluster started at 8088
2014-04-01 01:46:47,050 INFO org.apache.hadoop.yarn.webapp.WebApps: Registered webapp guice modules
2014-04-01 01:46:47,051 INFO org.apache.hadoop.security.token.delegation.AbstractDelegationTokenSecretManager: Updating the current master key for generating delegation tokens
2014-04-01 01:46:47,052 INFO org.apache.hadoop.yarn.server.resourcemanager.security.RMDelegationTokenSecretManager: storing master key with keyID 1
2014-04-01 01:46:47,052 INFO org.apache.hadoop.security.token.delegation.AbstractDelegationTokenSecretManager: Starting expired delegation token remover thread, tokenRemoverScanInterval=60 min(s)
2014-04-01 01:46:47,053 INFO org.apache.hadoop.security.token.delegation.AbstractDelegationTokenSecretManager: Updating the current master key for generating delegation tokens
2014-04-01 01:46:47,053 INFO org.apache.hadoop.yarn.server.resourcemanager.security.RMDelegationTokenSecretManager: storing master key with keyID 2
2014-04-01 01:46:52,107 INFO org.apache.hadoop.ipc.Server: Starting Socket Reader #1 for port 8031
2014-04-01 01:46:52,118 INFO org.apache.hadoop.yarn.factories.impl.pb.RpcServerFactoryPBImpl: Adding protocol org.apache.hadoop.yarn.server.api.ResourceTrackerPB to the server
2014-04-01 01:46:52,118 INFO org.apache.hadoop.ipc.Server: IPC Server Responder: starting
2014-04-01 01:46:52,123 INFO org.apache.hadoop.ipc.Server: IPC Server listener on 8031: starting
2014-04-01 01:46:57,171 INFO org.apache.hadoop.ipc.Server: Starting Socket Reader #1 for port 8030
2014-04-01 01:46:57,196 INFO org.apache.hadoop.yarn.factories.impl.pb.RpcServerFactoryPBImpl: Adding protocol org.apache.hadoop.yarn.api.ApplicationMasterProtocolPB to the server
2014-04-01 01:46:57,196 INFO org.apache.hadoop.ipc.Server: IPC Server Responder: starting
2014-04-01 01:46:57,197 INFO org.apache.hadoop.ipc.Server: IPC Server listener on 8030: starting
2014-04-01 01:46:58,577 INFO org.apache.hadoop.yarn.util.RackResolver: Resolved ubuntu to /default-rack
2014-04-01 01:46:58,579 INFO org.apache.hadoop.yarn.server.resourcemanager.ResourceTrackerService: NodeManager from node ubuntu(cmPort: 38688 httpPort: 8042) registered with capability: <memory:8192, vCores:8>, assigned nodeId ubuntu:38688
2014-04-01 01:46:58,582 INFO org.apache.hadoop.yarn.server.resourcemanager.rmnode.RMNodeImpl: ubuntu:38688 Node Transitioned from NEW to RUNNING
2014-04-01 01:46:58,583 INFO org.apache.hadoop.yarn.server.resourcemanager.scheduler.capacity.CapacityScheduler: Added node ubuntu:38688 clusterResource: <memory:8192, vCores:8>
2014-04-01 01:47:02,264 INFO org.apache.hadoop.yarn.factories.impl.pb.RpcServerFactoryPBImpl: Adding protocol org.apache.hadoop.yarn.api.ApplicationClientProtocolPB to the server
2014-04-01 01:47:02,264 INFO org.apache.hadoop.ipc.Server: IPC Server Responder: starting
2014-04-01 01:47:02,265 INFO org.apache.hadoop.ipc.Server: IPC Server listener on 8032: starting
2014-04-01 01:47:02,280 INFO org.apache.hadoop.ipc.Server: Starting Socket Reader #1 for port 8032
2014-04-01 01:47:07,323 INFO org.apache.hadoop.ipc.Server: Starting Socket Reader #1 for port 8033
2014-04-01 01:47:07,327 INFO org.apache.hadoop.yarn.factories.impl.pb.RpcServerFactoryPBImpl: Adding protocol org.apache.hadoop.yarn.server.api.ResourceManagerAdministrationProtocolPB to the server
2014-04-01 01:47:07,327 INFO org.apache.hadoop.ipc.Server: IPC Server Responder: starting
2014-04-01 01:47:07,328 INFO org.apache.hadoop.ipc.Server: IPC Server listener on 8033: starting
2014-04-01 01:47:08,164 INFO org.apache.hadoop.yarn.server.resourcemanager.ClientRMService: Allocated new applicationId: 1
2014-04-01 01:49:38,290 INFO org.apache.hadoop.yarn.server.resourcemanager.ClientRMService: Allocated new applicationId: 2
2014-04-01 01:49:39,376 INFO org.apache.hadoop.yarn.server.resourcemanager.ClientRMService: Application with id 2 submitted by user hduser
2014-04-01 01:49:39,377 INFO org.apache.hadoop.yarn.server.resourcemanager.rmapp.RMAppImpl: Storing application with id application_1396342005689_0002
2014-04-01 01:49:39,377 INFO org.apache.hadoop.yarn.server.resourcemanager.RMAuditLogger: USER=hduser	IP=127.0.0.1	OPERATION=Submit Application Request	TARGET=ClientRMService	RESULT=SUCCESS	APPID=application_1396342005689_0002
2014-04-01 01:49:39,378 INFO org.apache.hadoop.yarn.server.resourcemanager.rmapp.RMAppImpl: application_1396342005689_0002 State change from NEW to NEW_SAVING
2014-04-01 01:49:39,382 INFO org.apache.hadoop.yarn.server.resourcemanager.recovery.RMStateStore: Storing info for app: application_1396342005689_0002
2014-04-01 01:49:39,387 INFO org.apache.hadoop.yarn.server.resourcemanager.rmapp.RMAppImpl: application_1396342005689_0002 State change from NEW_SAVING to SUBMITTED
2014-04-01 01:49:39,387 INFO org.apache.hadoop.yarn.server.resourcemanager.ApplicationMasterService: Registering app attempt : appattempt_1396342005689_0002_000001
2014-04-01 01:49:39,391 INFO org.apache.hadoop.yarn.server.resourcemanager.rmapp.attempt.RMAppAttemptImpl: appattempt_1396342005689_0002_000001 State change from NEW to SUBMITTED
2014-04-01 01:49:39,401 INFO org.apache.hadoop.yarn.server.resourcemanager.scheduler.capacity.LeafQueue: Application application_1396342005689_0002 from user: hduser activated in queue: default
2014-04-01 01:49:39,401 INFO org.apache.hadoop.yarn.server.resourcemanager.scheduler.capacity.LeafQueue: Application added - appId: application_1396342005689_0002 user: org.apache.hadoop.yarn.server.resourcemanager.scheduler.capacity.LeafQueue$User@556b3d, leaf-queue: default #user-pending-applications: 0 #user-active-applications: 1 #queue-pending-applications: 0 #queue-active-applications: 1
2014-04-01 01:49:39,401 INFO org.apache.hadoop.yarn.server.resourcemanager.scheduler.capacity.ParentQueue: Application added - appId: application_1396342005689_0002 user: hduser leaf-queue of parent: root #applications: 1
2014-04-01 01:49:39,401 INFO org.apache.hadoop.yarn.server.resourcemanager.scheduler.capacity.CapacityScheduler: Application Submission: appattempt_1396342005689_0002_000001, user: hduser queue: default: capacity=1.0, absoluteCapacity=1.0, usedResources=<memory:0, vCores:0>usedCapacity=0.0, absoluteUsedCapacity=0.0, numApps=1, numContainers=0, currently active: 1
2014-04-01 01:49:39,402 INFO org.apache.hadoop.yarn.server.resourcemanager.rmapp.attempt.RMAppAttemptImpl: appattempt_1396342005689_0002_000001 State change from SUBMITTED to SCHEDULED
2014-04-01 01:49:39,402 INFO org.apache.hadoop.yarn.server.resourcemanager.rmapp.RMAppImpl: application_1396342005689_0002 State change from SUBMITTED to ACCEPTED
2014-04-01 01:49:40,089 INFO org.apache.hadoop.yarn.server.resourcemanager.rmcontainer.RMContainerImpl: container_1396342005689_0002_01_000001 Container Transitioned from NEW to ALLOCATED
2014-04-01 01:49:40,089 INFO org.apache.hadoop.yarn.server.resourcemanager.RMAuditLogger: USER=hduser	OPERATION=AM Allocated Container	TARGET=SchedulerApp	RESULT=SUCCESS	APPID=application_1396342005689_0002	CONTAINERID=container_1396342005689_0002_01_000001
2014-04-01 01:49:40,090 INFO org.apache.hadoop.yarn.server.resourcemanager.scheduler.common.fica.FiCaSchedulerNode: Assigned container container_1396342005689_0002_01_000001 of capacity <memory:2048, vCores:1> on host ubuntu:38688, which currently has 1 containers, <memory:2048, vCores:1> used and <memory:6144, vCores:7> available
2014-04-01 01:49:40,090 INFO org.apache.hadoop.yarn.server.resourcemanager.scheduler.capacity.LeafQueue: assignedContainer application=application_1396342005689_0002 container=Container: [ContainerId: container_1396342005689_0002_01_000001, NodeId: ubuntu:38688, NodeHttpAddress: ubuntu:8042, Resource: <memory:2048, vCores:1>, Priority: 0, Token: Token { kind: ContainerToken, service: 127.0.1.1:38688 }, ] containerId=container_1396342005689_0002_01_000001 queue=default: capacity=1.0, absoluteCapacity=1.0, usedResources=<memory:0, vCores:0>usedCapacity=0.0, absoluteUsedCapacity=0.0, numApps=1, numContainers=0 usedCapacity=0.0 absoluteUsedCapacity=0.0 used=<memory:0, vCores:0> cluster=<memory:8192, vCores:8>
2014-04-01 01:49:40,090 INFO org.apache.hadoop.yarn.server.resourcemanager.scheduler.capacity.ParentQueue: Re-sorting assigned queue: root.default stats: default: capacity=1.0, absoluteCapacity=1.0, usedResources=<memory:2048, vCores:1>usedCapacity=0.25, absoluteUsedCapacity=0.25, numApps=1, numContainers=1
2014-04-01 01:49:40,090 INFO org.apache.hadoop.yarn.server.resourcemanager.scheduler.capacity.ParentQueue: assignedContainer queue=root usedCapacity=0.25 absoluteUsedCapacity=0.25 used=<memory:2048, vCores:1> cluster=<memory:8192, vCores:8>
2014-04-01 01:49:40,092 INFO org.apache.hadoop.yarn.server.resourcemanager.rmcontainer.RMContainerImpl: container_1396342005689_0002_01_000001 Container Transitioned from ALLOCATED to ACQUIRED
2014-04-01 01:49:40,095 INFO org.apache.hadoop.yarn.server.resourcemanager.rmapp.attempt.RMAppAttemptImpl: Storing attempt: AppId: application_1396342005689_0002 AttemptId: appattempt_1396342005689_0002_000001 MasterContainer: Container: [ContainerId: container_1396342005689_0002_01_000001, NodeId: ubuntu:38688, NodeHttpAddress: ubuntu:8042, Resource: <memory:2048, vCores:1>, Priority: 0, Token: Token { kind: ContainerToken, service: 127.0.1.1:38688 }, ]
2014-04-01 01:49:40,099 INFO org.apache.hadoop.yarn.server.resourcemanager.rmapp.attempt.RMAppAttemptImpl: appattempt_1396342005689_0002_000001 State change from SCHEDULED to ALLOCATED_SAVING
2014-04-01 01:49:40,104 INFO org.apache.hadoop.yarn.server.resourcemanager.recovery.RMStateStore: Storing info for attempt: appattempt_1396342005689_0002_000001
2014-04-01 01:49:40,105 INFO org.apache.hadoop.yarn.server.resourcemanager.rmapp.attempt.RMAppAttemptImpl: appattempt_1396342005689_0002_000001 State change from ALLOCATED_SAVING to ALLOCATED
2014-04-01 01:49:40,107 INFO org.apache.hadoop.yarn.server.resourcemanager.amlauncher.AMLauncher: Launching masterappattempt_1396342005689_0002_000001
2014-04-01 01:49:40,131 INFO org.apache.hadoop.yarn.server.resourcemanager.amlauncher.AMLauncher: Setting up container Container: [ContainerId: container_1396342005689_0002_01_000001, NodeId: ubuntu:38688, NodeHttpAddress: ubuntu:8042, Resource: <memory:2048, vCores:1>, Priority: 0, Token: Token { kind: ContainerToken, service: 127.0.1.1:38688 }, ] for AM appattempt_1396342005689_0002_000001
2014-04-01 01:49:40,131 INFO org.apache.hadoop.yarn.server.resourcemanager.amlauncher.AMLauncher: Command to launch container container_1396342005689_0002_01_000001 : $JAVA_HOME/bin/java -Dlog4j.configuration=container-log4j.properties -Dyarn.app.container.log.dir=<LOG_DIR> -Dyarn.app.container.log.filesize=0 -Dhadoop.root.logger=INFO,CLA  -Xmx1024m org.apache.hadoop.mapreduce.v2.app.MRAppMaster 1><LOG_DIR>/stdout 2><LOG_DIR>/stderr 
2014-04-01 01:49:40,366 INFO org.apache.hadoop.yarn.server.resourcemanager.amlauncher.AMLauncher: Done launching container Container: [ContainerId: container_1396342005689_0002_01_000001, NodeId: ubuntu:38688, NodeHttpAddress: ubuntu:8042, Resource: <memory:2048, vCores:1>, Priority: 0, Token: Token { kind: ContainerToken, service: 127.0.1.1:38688 }, ] for AM appattempt_1396342005689_0002_000001
2014-04-01 01:49:40,366 INFO org.apache.hadoop.yarn.server.resourcemanager.rmapp.attempt.RMAppAttemptImpl: appattempt_1396342005689_0002_000001 State change from ALLOCATED to LAUNCHED
2014-04-01 01:49:41,086 INFO org.apache.hadoop.yarn.server.resourcemanager.rmcontainer.RMContainerImpl: container_1396342005689_0002_01_000001 Container Transitioned from ACQUIRED to RUNNING
2014-04-01 01:49:43,886 INFO SecurityLogger.org.apache.hadoop.ipc.Server: Auth successful for appattempt_1396342005689_0002_000001 (auth:SIMPLE)
2014-04-01 01:49:43,890 INFO org.apache.hadoop.yarn.server.resourcemanager.ApplicationMasterService: AM registration appattempt_1396342005689_0002_000001
2014-04-01 01:49:43,891 INFO org.apache.hadoop.yarn.server.resourcemanager.RMAuditLogger: USER=hduser	IP=127.0.0.1	OPERATION=Register App Master	TARGET=ApplicationMasterService	RESULT=SUCCESS	APPID=application_1396342005689_0002	APPATTEMPTID=appattempt_1396342005689_0002_000001
2014-04-01 01:49:43,891 INFO org.apache.hadoop.yarn.server.resourcemanager.rmapp.attempt.RMAppAttemptImpl: appattempt_1396342005689_0002_000001 State change from LAUNCHED to RUNNING
2014-04-01 01:49:43,891 INFO org.apache.hadoop.yarn.server.resourcemanager.rmapp.RMAppImpl: application_1396342005689_0002 State change from ACCEPTED to RUNNING
2014-04-01 01:49:45,096 INFO org.apache.hadoop.yarn.server.resourcemanager.rmcontainer.RMContainerImpl: container_1396342005689_0002_01_000002 Container Transitioned from NEW to ALLOCATED
2014-04-01 01:49:45,096 INFO org.apache.hadoop.yarn.server.resourcemanager.RMAuditLogger: USER=hduser	OPERATION=AM Allocated Container	TARGET=SchedulerApp	RESULT=SUCCESS	APPID=application_1396342005689_0002	CONTAINERID=container_1396342005689_0002_01_000002
2014-04-01 01:49:45,096 INFO org.apache.hadoop.yarn.server.resourcemanager.scheduler.common.fica.FiCaSchedulerNode: Assigned container container_1396342005689_0002_01_000002 of capacity <memory:1024, vCores:1> on host ubuntu:38688, which currently has 2 containers, <memory:3072, vCores:2> used and <memory:5120, vCores:6> available
2014-04-01 01:49:45,096 INFO org.apache.hadoop.yarn.server.resourcemanager.scheduler.capacity.LeafQueue: assignedContainer application=application_1396342005689_0002 container=Container: [ContainerId: container_1396342005689_0002_01_000002, NodeId: ubuntu:38688, NodeHttpAddress: ubuntu:8042, Resource: <memory:1024, vCores:1>, Priority: 20, Token: Token { kind: ContainerToken, service: 127.0.1.1:38688 }, ] containerId=container_1396342005689_0002_01_000002 queue=default: capacity=1.0, absoluteCapacity=1.0, usedResources=<memory:2048, vCores:1>usedCapacity=0.25, absoluteUsedCapacity=0.25, numApps=1, numContainers=1 usedCapacity=0.25 absoluteUsedCapacity=0.25 used=<memory:2048, vCores:1> cluster=<memory:8192, vCores:8>
2014-04-01 01:49:45,096 INFO org.apache.hadoop.yarn.server.resourcemanager.scheduler.capacity.ParentQueue: Re-sorting assigned queue: root.default stats: default: capacity=1.0, absoluteCapacity=1.0, usedResources=<memory:3072, vCores:2>usedCapacity=0.375, absoluteUsedCapacity=0.375, numApps=1, numContainers=2
2014-04-01 01:49:45,096 INFO org.apache.hadoop.yarn.server.resourcemanager.scheduler.capacity.ParentQueue: assignedContainer queue=root usedCapacity=0.375 absoluteUsedCapacity=0.375 used=<memory:3072, vCores:2> cluster=<memory:8192, vCores:8>
2014-04-01 01:49:45,936 INFO org.apache.hadoop.yarn.server.resourcemanager.rmcontainer.RMContainerImpl: container_1396342005689_0002_01_000002 Container Transitioned from ALLOCATED to ACQUIRED
2014-04-01 01:49:46,097 INFO org.apache.hadoop.yarn.server.resourcemanager.rmcontainer.RMContainerImpl: container_1396342005689_0002_01_000002 Container Transitioned from ACQUIRED to RUNNING
2014-04-01 01:49:46,950 INFO org.apache.hadoop.yarn.server.resourcemanager.scheduler.AppSchedulingInfo: checking for deactivate... 
2014-04-01 01:49:50,193 INFO org.apache.hadoop.yarn.server.resourcemanager.rmcontainer.RMContainerImpl: container_1396342005689_0002_01_000002 Container Transitioned from RUNNING to COMPLETED
2014-04-01 01:49:50,194 INFO org.apache.hadoop.yarn.server.resourcemanager.scheduler.common.fica.FiCaSchedulerApp: Completed container: container_1396342005689_0002_01_000002 in state: COMPLETED event:FINISHED
2014-04-01 01:49:50,194 INFO org.apache.hadoop.yarn.server.resourcemanager.RMAuditLogger: USER=hduser	OPERATION=AM Released Container	TARGET=SchedulerApp	RESULT=SUCCESS	APPID=application_1396342005689_0002	CONTAINERID=container_1396342005689_0002_01_000002
2014-04-01 01:49:50,194 INFO org.apache.hadoop.yarn.server.resourcemanager.scheduler.common.fica.FiCaSchedulerNode: Released container container_1396342005689_0002_01_000002 of capacity <memory:1024, vCores:1> on host ubuntu:38688, which currently has 1 containers, <memory:2048, vCores:1> used and <memory:6144, vCores:7> available, release resources=true
2014-04-01 01:49:50,194 INFO org.apache.hadoop.yarn.server.resourcemanager.scheduler.capacity.LeafQueue: default used=<memory:2048, vCores:1> numContainers=1 user=hduser user-resources=<memory:2048, vCores:1>
2014-04-01 01:49:50,194 INFO org.apache.hadoop.yarn.server.resourcemanager.scheduler.capacity.LeafQueue: completedContainer container=Container: [ContainerId: container_1396342005689_0002_01_000002, NodeId: ubuntu:38688, NodeHttpAddress: ubuntu:8042, Resource: <memory:1024, vCores:1>, Priority: 20, Token: Token { kind: ContainerToken, service: 127.0.1.1:38688 }, ] resource=<memory:1024, vCores:1> queue=default: capacity=1.0, absoluteCapacity=1.0, usedResources=<memory:2048, vCores:1>usedCapacity=0.25, absoluteUsedCapacity=0.25, numApps=1, numContainers=1 usedCapacity=0.25 absoluteUsedCapacity=0.25 used=<memory:2048, vCores:1> cluster=<memory:8192, vCores:8>
2014-04-01 01:49:50,194 INFO org.apache.hadoop.yarn.server.resourcemanager.scheduler.capacity.ParentQueue: completedContainer queue=root usedCapacity=0.25 absoluteUsedCapacity=0.25 used=<memory:2048, vCores:1> cluster=<memory:8192, vCores:8>
2014-04-01 01:49:50,194 INFO org.apache.hadoop.yarn.server.resourcemanager.scheduler.capacity.ParentQueue: Re-sorting completed queue: root.default stats: default: capacity=1.0, absoluteCapacity=1.0, usedResources=<memory:2048, vCores:1>usedCapacity=0.25, absoluteUsedCapacity=0.25, numApps=1, numContainers=1
2014-04-01 01:49:50,194 INFO org.apache.hadoop.yarn.server.resourcemanager.scheduler.capacity.CapacityScheduler: Application appattempt_1396342005689_0002_000001 released container container_1396342005689_0002_01_000002 on node: host: ubuntu:38688 #containers=1 available=6144 used=2048 with event: FINISHED
2014-04-01 01:49:51,196 INFO org.apache.hadoop.yarn.server.resourcemanager.rmcontainer.RMContainerImpl: container_1396342005689_0002_01_000003 Container Transitioned from NEW to ALLOCATED
2014-04-01 01:49:51,196 INFO org.apache.hadoop.yarn.server.resourcemanager.RMAuditLogger: USER=hduser	OPERATION=AM Allocated Container	TARGET=SchedulerApp	RESULT=SUCCESS	APPID=application_1396342005689_0002	CONTAINERID=container_1396342005689_0002_01_000003
2014-04-01 01:49:51,197 INFO org.apache.hadoop.yarn.server.resourcemanager.scheduler.common.fica.FiCaSchedulerNode: Assigned container container_1396342005689_0002_01_000003 of capacity <memory:1024, vCores:1> on host ubuntu:38688, which currently has 2 containers, <memory:3072, vCores:2> used and <memory:5120, vCores:6> available
2014-04-01 01:49:51,197 INFO org.apache.hadoop.yarn.server.resourcemanager.scheduler.capacity.LeafQueue: assignedContainer application=application_1396342005689_0002 container=Container: [ContainerId: container_1396342005689_0002_01_000003, NodeId: ubuntu:38688, NodeHttpAddress: ubuntu:8042, Resource: <memory:1024, vCores:1>, Priority: 10, Token: Token { kind: ContainerToken, service: 127.0.1.1:38688 }, ] containerId=container_1396342005689_0002_01_000003 queue=default: capacity=1.0, absoluteCapacity=1.0, usedResources=<memory:2048, vCores:1>usedCapacity=0.25, absoluteUsedCapacity=0.25, numApps=1, numContainers=1 usedCapacity=0.25 absoluteUsedCapacity=0.25 used=<memory:2048, vCores:1> cluster=<memory:8192, vCores:8>
2014-04-01 01:49:51,197 INFO org.apache.hadoop.yarn.server.resourcemanager.scheduler.capacity.ParentQueue: Re-sorting assigned queue: root.default stats: default: capacity=1.0, absoluteCapacity=1.0, usedResources=<memory:3072, vCores:2>usedCapacity=0.375, absoluteUsedCapacity=0.375, numApps=1, numContainers=2
2014-04-01 01:49:51,197 INFO org.apache.hadoop.yarn.server.resourcemanager.scheduler.capacity.ParentQueue: assignedContainer queue=root usedCapacity=0.375 absoluteUsedCapacity=0.375 used=<memory:3072, vCores:2> cluster=<memory:8192, vCores:8>
2014-04-01 01:49:51,971 INFO org.apache.hadoop.yarn.server.resourcemanager.rmcontainer.RMContainerImpl: container_1396342005689_0002_01_000003 Container Transitioned from ALLOCATED to ACQUIRED
2014-04-01 01:49:52,198 INFO org.apache.hadoop.yarn.server.resourcemanager.rmcontainer.RMContainerImpl: container_1396342005689_0002_01_000003 Container Transitioned from ACQUIRED to RUNNING
2014-04-01 01:49:52,975 INFO org.apache.hadoop.yarn.server.resourcemanager.scheduler.AppSchedulingInfo: checking for deactivate... 
2014-04-01 01:49:54,054 INFO org.apache.hadoop.yarn.server.resourcemanager.rmapp.attempt.RMAppAttemptImpl: appattempt_1396342005689_0002_000001 State change from RUNNING to FINISHING
2014-04-01 01:49:54,054 INFO org.apache.hadoop.yarn.server.resourcemanager.rmapp.RMAppImpl: Removing application with id application_1396342005689_0002
2014-04-01 01:49:54,055 INFO org.apache.hadoop.yarn.server.resourcemanager.rmapp.RMAppImpl: application_1396342005689_0002 State change from RUNNING to REMOVING
2014-04-01 01:49:54,055 INFO org.apache.hadoop.yarn.server.resourcemanager.recovery.RMStateStore: Removing info for app: application_1396342005689_0002
2014-04-01 01:49:54,055 INFO org.apache.hadoop.yarn.server.resourcemanager.rmapp.RMAppImpl: application_1396342005689_0002 State change from REMOVING to FINISHING
2014-04-01 01:49:54,954 INFO org.apache.hadoop.yarn.server.resourcemanager.rmcontainer.RMContainerImpl: container_1396342005689_0002_01_000003 Container Transitioned from RUNNING to COMPLETED
2014-04-01 01:49:54,954 INFO org.apache.hadoop.yarn.server.resourcemanager.scheduler.common.fica.FiCaSchedulerApp: Completed container: container_1396342005689_0002_01_000003 in state: COMPLETED event:FINISHED
2014-04-01 01:49:54,954 INFO org.apache.hadoop.yarn.server.resourcemanager.RMAuditLogger: USER=hduser	OPERATION=AM Released Container	TARGET=SchedulerApp	RESULT=SUCCESS	APPID=application_1396342005689_0002	CONTAINERID=container_1396342005689_0002_01_000003
2014-04-01 01:49:54,954 INFO org.apache.hadoop.yarn.server.resourcemanager.scheduler.common.fica.FiCaSchedulerNode: Released container container_1396342005689_0002_01_000003 of capacity <memory:1024, vCores:1> on host ubuntu:38688, which currently has 1 containers, <memory:2048, vCores:1> used and <memory:6144, vCores:7> available, release resources=true
2014-04-01 01:49:54,954 INFO org.apache.hadoop.yarn.server.resourcemanager.scheduler.capacity.LeafQueue: default used=<memory:2048, vCores:1> numContainers=1 user=hduser user-resources=<memory:2048, vCores:1>
2014-04-01 01:49:54,955 INFO org.apache.hadoop.yarn.server.resourcemanager.scheduler.capacity.LeafQueue: completedContainer container=Container: [ContainerId: container_1396342005689_0002_01_000003, NodeId: ubuntu:38688, NodeHttpAddress: ubuntu:8042, Resource: <memory:1024, vCores:1>, Priority: 10, Token: Token { kind: ContainerToken, service: 127.0.1.1:38688 }, ] resource=<memory:1024, vCores:1> queue=default: capacity=1.0, absoluteCapacity=1.0, usedResources=<memory:2048, vCores:1>usedCapacity=0.25, absoluteUsedCapacity=0.25, numApps=1, numContainers=1 usedCapacity=0.25 absoluteUsedCapacity=0.25 used=<memory:2048, vCores:1> cluster=<memory:8192, vCores:8>
2014-04-01 01:49:54,955 INFO org.apache.hadoop.yarn.server.resourcemanager.scheduler.capacity.ParentQueue: completedContainer queue=root usedCapacity=0.25 absoluteUsedCapacity=0.25 used=<memory:2048, vCores:1> cluster=<memory:8192, vCores:8>
2014-04-01 01:49:54,955 INFO org.apache.hadoop.yarn.server.resourcemanager.scheduler.capacity.ParentQueue: Re-sorting completed queue: root.default stats: default: capacity=1.0, absoluteCapacity=1.0, usedResources=<memory:2048, vCores:1>usedCapacity=0.25, absoluteUsedCapacity=0.25, numApps=1, numContainers=1
2014-04-01 01:49:54,955 INFO org.apache.hadoop.yarn.server.resourcemanager.scheduler.capacity.CapacityScheduler: Application appattempt_1396342005689_0002_000001 released container container_1396342005689_0002_01_000003 on node: host: ubuntu:38688 #containers=1 available=6144 used=2048 with event: FINISHED
2014-04-01 01:50:00,972 INFO org.apache.hadoop.yarn.server.resourcemanager.rmcontainer.RMContainerImpl: container_1396342005689_0002_01_000001 Container Transitioned from RUNNING to COMPLETED
2014-04-01 01:50:00,972 INFO org.apache.hadoop.yarn.server.resourcemanager.scheduler.common.fica.FiCaSchedulerApp: Completed container: container_1396342005689_0002_01_000001 in state: COMPLETED event:FINISHED
2014-04-01 01:50:00,972 INFO org.apache.hadoop.yarn.server.resourcemanager.RMAuditLogger: USER=hduser	OPERATION=AM Released Container	TARGET=SchedulerApp	RESULT=SUCCESS	APPID=application_1396342005689_0002	CONTAINERID=container_1396342005689_0002_01_000001
2014-04-01 01:50:00,972 INFO org.apache.hadoop.yarn.server.resourcemanager.scheduler.common.fica.FiCaSchedulerNode: Released container container_1396342005689_0002_01_000001 of capacity <memory:2048, vCores:1> on host ubuntu:38688, which currently has 0 containers, <memory:0, vCores:0> used and <memory:8192, vCores:8> available, release resources=true
2014-04-01 01:50:00,972 INFO org.apache.hadoop.yarn.server.resourcemanager.scheduler.capacity.LeafQueue: default used=<memory:0, vCores:0> numContainers=0 user=hduser user-resources=<memory:0, vCores:0>
2014-04-01 01:50:00,972 INFO org.apache.hadoop.yarn.server.resourcemanager.scheduler.capacity.LeafQueue: completedContainer container=Container: [ContainerId: container_1396342005689_0002_01_000001, NodeId: ubuntu:38688, NodeHttpAddress: ubuntu:8042, Resource: <memory:2048, vCores:1>, Priority: 0, Token: Token { kind: ContainerToken, service: 127.0.1.1:38688 }, ] resource=<memory:2048, vCores:1> queue=default: capacity=1.0, absoluteCapacity=1.0, usedResources=<memory:0, vCores:0>usedCapacity=0.0, absoluteUsedCapacity=0.0, numApps=1, numContainers=0 usedCapacity=0.0 absoluteUsedCapacity=0.0 used=<memory:0, vCores:0> cluster=<memory:8192, vCores:8>
2014-04-01 01:50:00,972 INFO org.apache.hadoop.yarn.server.resourcemanager.scheduler.capacity.ParentQueue: completedContainer queue=root usedCapacity=0.0 absoluteUsedCapacity=0.0 used=<memory:0, vCores:0> cluster=<memory:8192, vCores:8>
2014-04-01 01:50:00,972 INFO org.apache.hadoop.yarn.server.resourcemanager.scheduler.capacity.ParentQueue: Re-sorting completed queue: root.default stats: default: capacity=1.0, absoluteCapacity=1.0, usedResources=<memory:0, vCores:0>usedCapacity=0.0, absoluteUsedCapacity=0.0, numApps=1, numContainers=0
2014-04-01 01:50:00,973 INFO org.apache.hadoop.yarn.server.resourcemanager.scheduler.capacity.CapacityScheduler: Application appattempt_1396342005689_0002_000001 released container container_1396342005689_0002_01_000001 on node: host: ubuntu:38688 #containers=0 available=8192 used=0 with event: FINISHED
2014-04-01 01:50:00,973 INFO org.apache.hadoop.yarn.server.resourcemanager.ApplicationMasterService: Unregistering app attempt : appattempt_1396342005689_0002_000001
2014-04-01 01:50:00,974 INFO org.apache.hadoop.yarn.server.resourcemanager.rmapp.attempt.RMAppAttemptImpl: appattempt_1396342005689_0002_000001 State change from FINISHING to FINISHED
2014-04-01 01:50:00,975 INFO org.apache.hadoop.yarn.server.resourcemanager.rmapp.RMAppImpl: application_1396342005689_0002 State change from FINISHING to FINISHED
2014-04-01 01:50:00,976 INFO org.apache.hadoop.yarn.server.resourcemanager.scheduler.capacity.CapacityScheduler: Application appattempt_1396342005689_0002_000001 is done. finalState=FINISHED
2014-04-01 01:50:00,976 INFO org.apache.hadoop.yarn.server.resourcemanager.RMAuditLogger: USER=hduser	OPERATION=Application Finished - Succeeded	TARGET=RMAppManager	RESULT=SUCCESS	APPID=application_1396342005689_0002
2014-04-01 01:50:00,976 INFO org.apache.hadoop.yarn.server.resourcemanager.scheduler.AppSchedulingInfo: Application application_1396342005689_0002 requests cleared
2014-04-01 01:50:00,976 INFO org.apache.hadoop.yarn.server.resourcemanager.scheduler.capacity.LeafQueue: Application removed - appId: application_1396342005689_0002 user: hduser queue: default #user-pending-applications: 0 #user-active-applications: 0 #queue-pending-applications: 0 #queue-active-applications: 0
2014-04-01 01:50:00,976 INFO org.apache.hadoop.yarn.server.resourcemanager.scheduler.capacity.ParentQueue: Application removed - appId: application_1396342005689_0002 user: hduser leaf-queue of parent: root #applications: 0
2014-04-01 01:50:00,977 INFO org.apache.hadoop.yarn.server.resourcemanager.amlauncher.AMLauncher: Cleaning master appattempt_1396342005689_0002_000001
2014-04-01 01:50:00,977 INFO org.apache.hadoop.yarn.server.resourcemanager.RMAppManager$ApplicationSummary: appId=application_1396342005689_0002,name=base||path:/in||num reduce:1,user=hduser,queue=default,state=FINISHED,trackingUrl=ubuntu:8088/proxy/application_1396342005689_0002/jobhistory/job/job_1396342005689_0002,appMasterHost=ubuntu,startTime=1396342179375,finishTime=1396342194055,finalStatus=SUCCEEDED
2014-04-01 01:50:39,457 INFO org.apache.hadoop.yarn.server.resourcemanager.ClientRMService: Allocated new applicationId: 3
2014-04-01 01:50:40,086 INFO org.apache.hadoop.yarn.server.resourcemanager.ClientRMService: Application with id 3 submitted by user hduser
2014-04-01 01:50:40,087 INFO org.apache.hadoop.yarn.server.resourcemanager.rmapp.RMAppImpl: Storing application with id application_1396342005689_0003
2014-04-01 01:50:40,087 INFO org.apache.hadoop.yarn.server.resourcemanager.RMAuditLogger: USER=hduser	IP=127.0.0.1	OPERATION=Submit Application Request	TARGET=ClientRMService	RESULT=SUCCESS	APPID=application_1396342005689_0003
2014-04-01 01:50:40,087 INFO org.apache.hadoop.yarn.server.resourcemanager.rmapp.RMAppImpl: application_1396342005689_0003 State change from NEW to NEW_SAVING
2014-04-01 01:50:40,087 INFO org.apache.hadoop.yarn.server.resourcemanager.recovery.RMStateStore: Storing info for app: application_1396342005689_0003
2014-04-01 01:50:40,088 INFO org.apache.hadoop.yarn.server.resourcemanager.rmapp.RMAppImpl: application_1396342005689_0003 State change from NEW_SAVING to SUBMITTED
2014-04-01 01:50:40,088 INFO org.apache.hadoop.yarn.server.resourcemanager.ApplicationMasterService: Registering app attempt : appattempt_1396342005689_0003_000001
2014-04-01 01:50:40,089 INFO org.apache.hadoop.yarn.server.resourcemanager.rmapp.attempt.RMAppAttemptImpl: appattempt_1396342005689_0003_000001 State change from NEW to SUBMITTED
2014-04-01 01:50:40,089 INFO org.apache.hadoop.yarn.server.resourcemanager.scheduler.capacity.LeafQueue: Application application_1396342005689_0003 from user: hduser activated in queue: default
2014-04-01 01:50:40,089 INFO org.apache.hadoop.yarn.server.resourcemanager.scheduler.capacity.LeafQueue: Application added - appId: application_1396342005689_0003 user: org.apache.hadoop.yarn.server.resourcemanager.scheduler.capacity.LeafQueue$User@f27734, leaf-queue: default #user-pending-applications: 0 #user-active-applications: 1 #queue-pending-applications: 0 #queue-active-applications: 1
2014-04-01 01:50:40,089 INFO org.apache.hadoop.yarn.server.resourcemanager.scheduler.capacity.ParentQueue: Application added - appId: application_1396342005689_0003 user: hduser leaf-queue of parent: root #applications: 1
2014-04-01 01:50:40,089 INFO org.apache.hadoop.yarn.server.resourcemanager.scheduler.capacity.CapacityScheduler: Application Submission: appattempt_1396342005689_0003_000001, user: hduser queue: default: capacity=1.0, absoluteCapacity=1.0, usedResources=<memory:0, vCores:0>usedCapacity=0.0, absoluteUsedCapacity=0.0, numApps=1, numContainers=0, currently active: 1
2014-04-01 01:50:40,090 INFO org.apache.hadoop.yarn.server.resourcemanager.rmapp.attempt.RMAppAttemptImpl: appattempt_1396342005689_0003_000001 State change from SUBMITTED to SCHEDULED
2014-04-01 01:50:40,090 INFO org.apache.hadoop.yarn.server.resourcemanager.rmapp.RMAppImpl: application_1396342005689_0003 State change from SUBMITTED to ACCEPTED
2014-04-01 01:50:41,064 INFO org.apache.hadoop.yarn.server.resourcemanager.rmcontainer.RMContainerImpl: container_1396342005689_0003_01_000001 Container Transitioned from NEW to ALLOCATED
2014-04-01 01:50:41,064 INFO org.apache.hadoop.yarn.server.resourcemanager.RMAuditLogger: USER=hduser	OPERATION=AM Allocated Container	TARGET=SchedulerApp	RESULT=SUCCESS	APPID=application_1396342005689_0003	CONTAINERID=container_1396342005689_0003_01_000001
2014-04-01 01:50:41,064 INFO org.apache.hadoop.yarn.server.resourcemanager.scheduler.common.fica.FiCaSchedulerNode: Assigned container container_1396342005689_0003_01_000001 of capacity <memory:2048, vCores:1> on host ubuntu:38688, which currently has 1 containers, <memory:2048, vCores:1> used and <memory:6144, vCores:7> available
2014-04-01 01:50:41,065 INFO org.apache.hadoop.yarn.server.resourcemanager.scheduler.capacity.LeafQueue: assignedContainer application=application_1396342005689_0003 container=Container: [ContainerId: container_1396342005689_0003_01_000001, NodeId: ubuntu:38688, NodeHttpAddress: ubuntu:8042, Resource: <memory:2048, vCores:1>, Priority: 0, Token: Token { kind: ContainerToken, service: 127.0.1.1:38688 }, ] containerId=container_1396342005689_0003_01_000001 queue=default: capacity=1.0, absoluteCapacity=1.0, usedResources=<memory:0, vCores:0>usedCapacity=0.0, absoluteUsedCapacity=0.0, numApps=1, numContainers=0 usedCapacity=0.0 absoluteUsedCapacity=0.0 used=<memory:0, vCores:0> cluster=<memory:8192, vCores:8>
2014-04-01 01:50:41,065 INFO org.apache.hadoop.yarn.server.resourcemanager.scheduler.capacity.ParentQueue: Re-sorting assigned queue: root.default stats: default: capacity=1.0, absoluteCapacity=1.0, usedResources=<memory:2048, vCores:1>usedCapacity=0.25, absoluteUsedCapacity=0.25, numApps=1, numContainers=1
2014-04-01 01:50:41,065 INFO org.apache.hadoop.yarn.server.resourcemanager.scheduler.capacity.ParentQueue: assignedContainer queue=root usedCapacity=0.25 absoluteUsedCapacity=0.25 used=<memory:2048, vCores:1> cluster=<memory:8192, vCores:8>
2014-04-01 01:50:41,065 INFO org.apache.hadoop.yarn.server.resourcemanager.rmcontainer.RMContainerImpl: container_1396342005689_0003_01_000001 Container Transitioned from ALLOCATED to ACQUIRED
2014-04-01 01:50:41,066 INFO org.apache.hadoop.yarn.server.resourcemanager.rmapp.attempt.RMAppAttemptImpl: Storing attempt: AppId: application_1396342005689_0003 AttemptId: appattempt_1396342005689_0003_000001 MasterContainer: Container: [ContainerId: container_1396342005689_0003_01_000001, NodeId: ubuntu:38688, NodeHttpAddress: ubuntu:8042, Resource: <memory:2048, vCores:1>, Priority: 0, Token: Token { kind: ContainerToken, service: 127.0.1.1:38688 }, ]
2014-04-01 01:50:41,066 INFO org.apache.hadoop.yarn.server.resourcemanager.rmapp.attempt.RMAppAttemptImpl: appattempt_1396342005689_0003_000001 State change from SCHEDULED to ALLOCATED_SAVING
2014-04-01 01:50:41,066 INFO org.apache.hadoop.yarn.server.resourcemanager.recovery.RMStateStore: Storing info for attempt: appattempt_1396342005689_0003_000001
2014-04-01 01:50:41,066 INFO org.apache.hadoop.yarn.server.resourcemanager.rmapp.attempt.RMAppAttemptImpl: appattempt_1396342005689_0003_000001 State change from ALLOCATED_SAVING to ALLOCATED
2014-04-01 01:50:41,067 INFO org.apache.hadoop.yarn.server.resourcemanager.amlauncher.AMLauncher: Launching masterappattempt_1396342005689_0003_000001
2014-04-01 01:50:41,068 INFO org.apache.hadoop.yarn.server.resourcemanager.amlauncher.AMLauncher: Setting up container Container: [ContainerId: container_1396342005689_0003_01_000001, NodeId: ubuntu:38688, NodeHttpAddress: ubuntu:8042, Resource: <memory:2048, vCores:1>, Priority: 0, Token: Token { kind: ContainerToken, service: 127.0.1.1:38688 }, ] for AM appattempt_1396342005689_0003_000001
2014-04-01 01:50:41,068 INFO org.apache.hadoop.yarn.server.resourcemanager.amlauncher.AMLauncher: Command to launch container container_1396342005689_0003_01_000001 : $JAVA_HOME/bin/java -Dlog4j.configuration=container-log4j.properties -Dyarn.app.container.log.dir=<LOG_DIR> -Dyarn.app.container.log.filesize=0 -Dhadoop.root.logger=INFO,CLA  -Xmx1024m org.apache.hadoop.mapreduce.v2.app.MRAppMaster 1><LOG_DIR>/stdout 2><LOG_DIR>/stderr 
2014-04-01 01:50:41,076 INFO org.apache.hadoop.yarn.server.resourcemanager.amlauncher.AMLauncher: Done launching container Container: [ContainerId: container_1396342005689_0003_01_000001, NodeId: ubuntu:38688, NodeHttpAddress: ubuntu:8042, Resource: <memory:2048, vCores:1>, Priority: 0, Token: Token { kind: ContainerToken, service: 127.0.1.1:38688 }, ] for AM appattempt_1396342005689_0003_000001
2014-04-01 01:50:41,077 INFO org.apache.hadoop.yarn.server.resourcemanager.rmapp.attempt.RMAppAttemptImpl: appattempt_1396342005689_0003_000001 State change from ALLOCATED to LAUNCHED
2014-04-01 01:50:42,067 INFO org.apache.hadoop.yarn.server.resourcemanager.rmcontainer.RMContainerImpl: container_1396342005689_0003_01_000001 Container Transitioned from ACQUIRED to RUNNING
2014-04-01 01:50:43,701 INFO SecurityLogger.org.apache.hadoop.ipc.Server: Auth successful for appattempt_1396342005689_0003_000001 (auth:SIMPLE)
2014-04-01 01:50:43,704 INFO org.apache.hadoop.yarn.server.resourcemanager.ApplicationMasterService: AM registration appattempt_1396342005689_0003_000001
2014-04-01 01:50:43,704 INFO org.apache.hadoop.yarn.server.resourcemanager.RMAuditLogger: USER=hduser	IP=127.0.0.1	OPERATION=Register App Master	TARGET=ApplicationMasterService	RESULT=SUCCESS	APPID=application_1396342005689_0003	APPATTEMPTID=appattempt_1396342005689_0003_000001
2014-04-01 01:50:43,705 INFO org.apache.hadoop.yarn.server.resourcemanager.rmapp.attempt.RMAppAttemptImpl: appattempt_1396342005689_0003_000001 State change from LAUNCHED to RUNNING
2014-04-01 01:50:43,705 INFO org.apache.hadoop.yarn.server.resourcemanager.rmapp.RMAppImpl: application_1396342005689_0003 State change from ACCEPTED to RUNNING
2014-04-01 01:50:45,075 INFO org.apache.hadoop.yarn.server.resourcemanager.rmcontainer.RMContainerImpl: container_1396342005689_0003_01_000002 Container Transitioned from NEW to ALLOCATED
2014-04-01 01:50:45,075 INFO org.apache.hadoop.yarn.server.resourcemanager.RMAuditLogger: USER=hduser	OPERATION=AM Allocated Container	TARGET=SchedulerApp	RESULT=SUCCESS	APPID=application_1396342005689_0003	CONTAINERID=container_1396342005689_0003_01_000002
2014-04-01 01:50:45,075 INFO org.apache.hadoop.yarn.server.resourcemanager.scheduler.common.fica.FiCaSchedulerNode: Assigned container container_1396342005689_0003_01_000002 of capacity <memory:1024, vCores:1> on host ubuntu:38688, which currently has 2 containers, <memory:3072, vCores:2> used and <memory:5120, vCores:6> available
2014-04-01 01:50:45,075 INFO org.apache.hadoop.yarn.server.resourcemanager.scheduler.capacity.LeafQueue: assignedContainer application=application_1396342005689_0003 container=Container: [ContainerId: container_1396342005689_0003_01_000002, NodeId: ubuntu:38688, NodeHttpAddress: ubuntu:8042, Resource: <memory:1024, vCores:1>, Priority: 20, Token: Token { kind: ContainerToken, service: 127.0.1.1:38688 }, ] containerId=container_1396342005689_0003_01_000002 queue=default: capacity=1.0, absoluteCapacity=1.0, usedResources=<memory:2048, vCores:1>usedCapacity=0.25, absoluteUsedCapacity=0.25, numApps=1, numContainers=1 usedCapacity=0.25 absoluteUsedCapacity=0.25 used=<memory:2048, vCores:1> cluster=<memory:8192, vCores:8>
2014-04-01 01:50:45,075 INFO org.apache.hadoop.yarn.server.resourcemanager.scheduler.capacity.ParentQueue: Re-sorting assigned queue: root.default stats: default: capacity=1.0, absoluteCapacity=1.0, usedResources=<memory:3072, vCores:2>usedCapacity=0.375, absoluteUsedCapacity=0.375, numApps=1, numContainers=2
2014-04-01 01:50:45,075 INFO org.apache.hadoop.yarn.server.resourcemanager.scheduler.capacity.ParentQueue: assignedContainer queue=root usedCapacity=0.375 absoluteUsedCapacity=0.375 used=<memory:3072, vCores:2> cluster=<memory:8192, vCores:8>
2014-04-01 01:50:45,737 INFO org.apache.hadoop.yarn.server.resourcemanager.rmcontainer.RMContainerImpl: container_1396342005689_0003_01_000002 Container Transitioned from ALLOCATED to ACQUIRED
2014-04-01 01:50:46,077 INFO org.apache.hadoop.yarn.server.resourcemanager.rmcontainer.RMContainerImpl: container_1396342005689_0003_01_000002 Container Transitioned from ACQUIRED to RUNNING
2014-04-01 01:50:46,753 INFO org.apache.hadoop.yarn.server.resourcemanager.scheduler.AppSchedulingInfo: checking for deactivate... 
2014-04-01 01:50:49,257 INFO org.apache.hadoop.yarn.server.resourcemanager.rmcontainer.RMContainerImpl: container_1396342005689_0003_01_000002 Container Transitioned from RUNNING to COMPLETED
2014-04-01 01:50:49,257 INFO org.apache.hadoop.yarn.server.resourcemanager.scheduler.common.fica.FiCaSchedulerApp: Completed container: container_1396342005689_0003_01_000002 in state: COMPLETED event:FINISHED
2014-04-01 01:50:49,257 INFO org.apache.hadoop.yarn.server.resourcemanager.RMAuditLogger: USER=hduser	OPERATION=AM Released Container	TARGET=SchedulerApp	RESULT=SUCCESS	APPID=application_1396342005689_0003	CONTAINERID=container_1396342005689_0003_01_000002
2014-04-01 01:50:49,257 INFO org.apache.hadoop.yarn.server.resourcemanager.scheduler.common.fica.FiCaSchedulerNode: Released container container_1396342005689_0003_01_000002 of capacity <memory:1024, vCores:1> on host ubuntu:38688, which currently has 1 containers, <memory:2048, vCores:1> used and <memory:6144, vCores:7> available, release resources=true
2014-04-01 01:50:49,257 INFO org.apache.hadoop.yarn.server.resourcemanager.scheduler.capacity.LeafQueue: default used=<memory:2048, vCores:1> numContainers=1 user=hduser user-resources=<memory:2048, vCores:1>
2014-04-01 01:50:49,257 INFO org.apache.hadoop.yarn.server.resourcemanager.scheduler.capacity.LeafQueue: completedContainer container=Container: [ContainerId: container_1396342005689_0003_01_000002, NodeId: ubuntu:38688, NodeHttpAddress: ubuntu:8042, Resource: <memory:1024, vCores:1>, Priority: 20, Token: Token { kind: ContainerToken, service: 127.0.1.1:38688 }, ] resource=<memory:1024, vCores:1> queue=default: capacity=1.0, absoluteCapacity=1.0, usedResources=<memory:2048, vCores:1>usedCapacity=0.25, absoluteUsedCapacity=0.25, numApps=1, numContainers=1 usedCapacity=0.25 absoluteUsedCapacity=0.25 used=<memory:2048, vCores:1> cluster=<memory:8192, vCores:8>
2014-04-01 01:50:49,257 INFO org.apache.hadoop.yarn.server.resourcemanager.scheduler.capacity.ParentQueue: completedContainer queue=root usedCapacity=0.25 absoluteUsedCapacity=0.25 used=<memory:2048, vCores:1> cluster=<memory:8192, vCores:8>
2014-04-01 01:50:49,257 INFO org.apache.hadoop.yarn.server.resourcemanager.scheduler.capacity.ParentQueue: Re-sorting completed queue: root.default stats: default: capacity=1.0, absoluteCapacity=1.0, usedResources=<memory:2048, vCores:1>usedCapacity=0.25, absoluteUsedCapacity=0.25, numApps=1, numContainers=1
2014-04-01 01:50:49,257 INFO org.apache.hadoop.yarn.server.resourcemanager.scheduler.capacity.CapacityScheduler: Application appattempt_1396342005689_0003_000001 released container container_1396342005689_0003_01_000002 on node: host: ubuntu:38688 #containers=1 available=6144 used=2048 with event: FINISHED
2014-04-01 01:50:50,259 INFO org.apache.hadoop.yarn.server.resourcemanager.rmcontainer.RMContainerImpl: container_1396342005689_0003_01_000003 Container Transitioned from NEW to ALLOCATED
2014-04-01 01:50:50,259 INFO org.apache.hadoop.yarn.server.resourcemanager.RMAuditLogger: USER=hduser	OPERATION=AM Allocated Container	TARGET=SchedulerApp	RESULT=SUCCESS	APPID=application_1396342005689_0003	CONTAINERID=container_1396342005689_0003_01_000003
2014-04-01 01:50:50,259 INFO org.apache.hadoop.yarn.server.resourcemanager.scheduler.common.fica.FiCaSchedulerNode: Assigned container container_1396342005689_0003_01_000003 of capacity <memory:1024, vCores:1> on host ubuntu:38688, which currently has 2 containers, <memory:3072, vCores:2> used and <memory:5120, vCores:6> available
2014-04-01 01:50:50,260 INFO org.apache.hadoop.yarn.server.resourcemanager.scheduler.capacity.LeafQueue: assignedContainer application=application_1396342005689_0003 container=Container: [ContainerId: container_1396342005689_0003_01_000003, NodeId: ubuntu:38688, NodeHttpAddress: ubuntu:8042, Resource: <memory:1024, vCores:1>, Priority: 10, Token: Token { kind: ContainerToken, service: 127.0.1.1:38688 }, ] containerId=container_1396342005689_0003_01_000003 queue=default: capacity=1.0, absoluteCapacity=1.0, usedResources=<memory:2048, vCores:1>usedCapacity=0.25, absoluteUsedCapacity=0.25, numApps=1, numContainers=1 usedCapacity=0.25 absoluteUsedCapacity=0.25 used=<memory:2048, vCores:1> cluster=<memory:8192, vCores:8>
2014-04-01 01:50:50,260 INFO org.apache.hadoop.yarn.server.resourcemanager.scheduler.capacity.ParentQueue: Re-sorting assigned queue: root.default stats: default: capacity=1.0, absoluteCapacity=1.0, usedResources=<memory:3072, vCores:2>usedCapacity=0.375, absoluteUsedCapacity=0.375, numApps=1, numContainers=2
2014-04-01 01:50:50,260 INFO org.apache.hadoop.yarn.server.resourcemanager.scheduler.capacity.ParentQueue: assignedContainer queue=root usedCapacity=0.375 absoluteUsedCapacity=0.375 used=<memory:3072, vCores:2> cluster=<memory:8192, vCores:8>
2014-04-01 01:50:50,770 INFO org.apache.hadoop.yarn.server.resourcemanager.rmcontainer.RMContainerImpl: container_1396342005689_0003_01_000003 Container Transitioned from ALLOCATED to ACQUIRED
2014-04-01 01:50:51,262 INFO org.apache.hadoop.yarn.server.resourcemanager.rmcontainer.RMContainerImpl: container_1396342005689_0003_01_000003 Container Transitioned from ACQUIRED to RUNNING
2014-04-01 01:50:51,779 INFO org.apache.hadoop.yarn.server.resourcemanager.scheduler.AppSchedulingInfo: checking for deactivate... 
2014-04-01 01:50:52,735 INFO org.apache.hadoop.yarn.server.resourcemanager.rmapp.attempt.RMAppAttemptImpl: appattempt_1396342005689_0003_000001 State change from RUNNING to FINISHING
2014-04-01 01:50:52,735 INFO org.apache.hadoop.yarn.server.resourcemanager.rmapp.RMAppImpl: Removing application with id application_1396342005689_0003
2014-04-01 01:50:52,735 INFO org.apache.hadoop.yarn.server.resourcemanager.recovery.RMStateStore: Removing info for app: application_1396342005689_0003
2014-04-01 01:50:52,735 INFO org.apache.hadoop.yarn.server.resourcemanager.rmapp.RMAppImpl: application_1396342005689_0003 State change from RUNNING to REMOVING
2014-04-01 01:50:52,735 INFO org.apache.hadoop.yarn.server.resourcemanager.rmapp.RMAppImpl: application_1396342005689_0003 State change from REMOVING to FINISHING
2014-04-01 01:50:53,632 INFO org.apache.hadoop.yarn.server.resourcemanager.rmcontainer.RMContainerImpl: container_1396342005689_0003_01_000003 Container Transitioned from RUNNING to COMPLETED
2014-04-01 01:50:53,632 INFO org.apache.hadoop.yarn.server.resourcemanager.scheduler.common.fica.FiCaSchedulerApp: Completed container: container_1396342005689_0003_01_000003 in state: COMPLETED event:FINISHED
2014-04-01 01:50:53,632 INFO org.apache.hadoop.yarn.server.resourcemanager.RMAuditLogger: USER=hduser	OPERATION=AM Released Container	TARGET=SchedulerApp	RESULT=SUCCESS	APPID=application_1396342005689_0003	CONTAINERID=container_1396342005689_0003_01_000003
2014-04-01 01:50:53,632 INFO org.apache.hadoop.yarn.server.resourcemanager.scheduler.common.fica.FiCaSchedulerNode: Released container container_1396342005689_0003_01_000003 of capacity <memory:1024, vCores:1> on host ubuntu:38688, which currently has 1 containers, <memory:2048, vCores:1> used and <memory:6144, vCores:7> available, release resources=true
2014-04-01 01:50:53,632 INFO org.apache.hadoop.yarn.server.resourcemanager.scheduler.capacity.LeafQueue: default used=<memory:2048, vCores:1> numContainers=1 user=hduser user-resources=<memory:2048, vCores:1>
2014-04-01 01:50:53,632 INFO org.apache.hadoop.yarn.server.resourcemanager.scheduler.capacity.LeafQueue: completedContainer container=Container: [ContainerId: container_1396342005689_0003_01_000003, NodeId: ubuntu:38688, NodeHttpAddress: ubuntu:8042, Resource: <memory:1024, vCores:1>, Priority: 10, Token: Token { kind: ContainerToken, service: 127.0.1.1:38688 }, ] resource=<memory:1024, vCores:1> queue=default: capacity=1.0, absoluteCapacity=1.0, usedResources=<memory:2048, vCores:1>usedCapacity=0.25, absoluteUsedCapacity=0.25, numApps=1, numContainers=1 usedCapacity=0.25 absoluteUsedCapacity=0.25 used=<memory:2048, vCores:1> cluster=<memory:8192, vCores:8>
2014-04-01 01:50:53,632 INFO org.apache.hadoop.yarn.server.resourcemanager.scheduler.capacity.ParentQueue: completedContainer queue=root usedCapacity=0.25 absoluteUsedCapacity=0.25 used=<memory:2048, vCores:1> cluster=<memory:8192, vCores:8>
2014-04-01 01:50:53,633 INFO org.apache.hadoop.yarn.server.resourcemanager.scheduler.capacity.ParentQueue: Re-sorting completed queue: root.default stats: default: capacity=1.0, absoluteCapacity=1.0, usedResources=<memory:2048, vCores:1>usedCapacity=0.25, absoluteUsedCapacity=0.25, numApps=1, numContainers=1
2014-04-01 01:50:53,633 INFO org.apache.hadoop.yarn.server.resourcemanager.scheduler.capacity.CapacityScheduler: Application appattempt_1396342005689_0003_000001 released container container_1396342005689_0003_01_000003 on node: host: ubuntu:38688 #containers=1 available=6144 used=2048 with event: FINISHED
2014-04-01 01:50:59,648 INFO org.apache.hadoop.yarn.server.resourcemanager.rmcontainer.RMContainerImpl: container_1396342005689_0003_01_000001 Container Transitioned from RUNNING to COMPLETED
2014-04-01 01:50:59,648 INFO org.apache.hadoop.yarn.server.resourcemanager.scheduler.common.fica.FiCaSchedulerApp: Completed container: container_1396342005689_0003_01_000001 in state: COMPLETED event:FINISHED
2014-04-01 01:50:59,648 INFO org.apache.hadoop.yarn.server.resourcemanager.RMAuditLogger: USER=hduser	OPERATION=AM Released Container	TARGET=SchedulerApp	RESULT=SUCCESS	APPID=application_1396342005689_0003	CONTAINERID=container_1396342005689_0003_01_000001
2014-04-01 01:50:59,648 INFO org.apache.hadoop.yarn.server.resourcemanager.scheduler.common.fica.FiCaSchedulerNode: Released container container_1396342005689_0003_01_000001 of capacity <memory:2048, vCores:1> on host ubuntu:38688, which currently has 0 containers, <memory:0, vCores:0> used and <memory:8192, vCores:8> available, release resources=true
2014-04-01 01:50:59,649 INFO org.apache.hadoop.yarn.server.resourcemanager.scheduler.capacity.LeafQueue: default used=<memory:0, vCores:0> numContainers=0 user=hduser user-resources=<memory:0, vCores:0>
2014-04-01 01:50:59,649 INFO org.apache.hadoop.yarn.server.resourcemanager.scheduler.capacity.LeafQueue: completedContainer container=Container: [ContainerId: container_1396342005689_0003_01_000001, NodeId: ubuntu:38688, NodeHttpAddress: ubuntu:8042, Resource: <memory:2048, vCores:1>, Priority: 0, Token: Token { kind: ContainerToken, service: 127.0.1.1:38688 }, ] resource=<memory:2048, vCores:1> queue=default: capacity=1.0, absoluteCapacity=1.0, usedResources=<memory:0, vCores:0>usedCapacity=0.0, absoluteUsedCapacity=0.0, numApps=1, numContainers=0 usedCapacity=0.0 absoluteUsedCapacity=0.0 used=<memory:0, vCores:0> cluster=<memory:8192, vCores:8>
2014-04-01 01:50:59,649 INFO org.apache.hadoop.yarn.server.resourcemanager.scheduler.capacity.ParentQueue: completedContainer queue=root usedCapacity=0.0 absoluteUsedCapacity=0.0 used=<memory:0, vCores:0> cluster=<memory:8192, vCores:8>
2014-04-01 01:50:59,649 INFO org.apache.hadoop.yarn.server.resourcemanager.scheduler.capacity.ParentQueue: Re-sorting completed queue: root.default stats: default: capacity=1.0, absoluteCapacity=1.0, usedResources=<memory:0, vCores:0>usedCapacity=0.0, absoluteUsedCapacity=0.0, numApps=1, numContainers=0
2014-04-01 01:50:59,649 INFO org.apache.hadoop.yarn.server.resourcemanager.scheduler.capacity.CapacityScheduler: Application appattempt_1396342005689_0003_000001 released container container_1396342005689_0003_01_000001 on node: host: ubuntu:38688 #containers=0 available=8192 used=0 with event: FINISHED
2014-04-01 01:50:59,649 INFO org.apache.hadoop.yarn.server.resourcemanager.ApplicationMasterService: Unregistering app attempt : appattempt_1396342005689_0003_000001
2014-04-01 01:50:59,650 INFO org.apache.hadoop.yarn.server.resourcemanager.rmapp.attempt.RMAppAttemptImpl: appattempt_1396342005689_0003_000001 State change from FINISHING to FINISHED
2014-04-01 01:50:59,650 INFO org.apache.hadoop.yarn.server.resourcemanager.rmapp.RMAppImpl: application_1396342005689_0003 State change from FINISHING to FINISHED
2014-04-01 01:50:59,650 INFO org.apache.hadoop.yarn.server.resourcemanager.RMAuditLogger: USER=hduser	OPERATION=Application Finished - Succeeded	TARGET=RMAppManager	RESULT=SUCCESS	APPID=application_1396342005689_0003
2014-04-01 01:50:59,650 INFO org.apache.hadoop.yarn.server.resourcemanager.RMAppManager$ApplicationSummary: appId=application_1396342005689_0003,name=base||path:/in||num reduce:1,user=hduser,queue=default,state=FINISHED,trackingUrl=ubuntu:8088/proxy/application_1396342005689_0003/jobhistory/job/job_1396342005689_0003,appMasterHost=ubuntu,startTime=1396342240086,finishTime=1396342252735,finalStatus=SUCCEEDED
2014-04-01 01:50:59,650 INFO org.apache.hadoop.yarn.server.resourcemanager.scheduler.capacity.CapacityScheduler: Application appattempt_1396342005689_0003_000001 is done. finalState=FINISHED
2014-04-01 01:50:59,650 INFO org.apache.hadoop.yarn.server.resourcemanager.scheduler.AppSchedulingInfo: Application application_1396342005689_0003 requests cleared
2014-04-01 01:50:59,650 INFO org.apache.hadoop.yarn.server.resourcemanager.scheduler.capacity.LeafQueue: Application removed - appId: application_1396342005689_0003 user: hduser queue: default #user-pending-applications: 0 #user-active-applications: 0 #queue-pending-applications: 0 #queue-active-applications: 0
2014-04-01 01:50:59,650 INFO org.apache.hadoop.yarn.server.resourcemanager.scheduler.capacity.ParentQueue: Application removed - appId: application_1396342005689_0003 user: hduser leaf-queue of parent: root #applications: 0
2014-04-01 01:50:59,651 INFO org.apache.hadoop.yarn.server.resourcemanager.amlauncher.AMLauncher: Cleaning master appattempt_1396342005689_0003_000001
2014-04-01 02:03:36,636 INFO org.apache.hadoop.yarn.server.resourcemanager.ClientRMService: Allocated new applicationId: 4
2014-04-01 02:03:37,219 INFO org.apache.hadoop.yarn.server.resourcemanager.ClientRMService: Application with id 4 submitted by user hduser
2014-04-01 02:03:37,219 INFO org.apache.hadoop.yarn.server.resourcemanager.RMAuditLogger: USER=hduser	IP=127.0.0.1	OPERATION=Submit Application Request	TARGET=ClientRMService	RESULT=SUCCESS	APPID=application_1396342005689_0004
2014-04-01 02:03:37,219 INFO org.apache.hadoop.yarn.server.resourcemanager.rmapp.RMAppImpl: Storing application with id application_1396342005689_0004
2014-04-01 02:03:37,220 INFO org.apache.hadoop.yarn.server.resourcemanager.rmapp.RMAppImpl: application_1396342005689_0004 State change from NEW to NEW_SAVING
2014-04-01 02:03:37,220 INFO org.apache.hadoop.yarn.server.resourcemanager.recovery.RMStateStore: Storing info for app: application_1396342005689_0004
2014-04-01 02:03:37,220 INFO org.apache.hadoop.yarn.server.resourcemanager.rmapp.RMAppImpl: application_1396342005689_0004 State change from NEW_SAVING to SUBMITTED
2014-04-01 02:03:37,220 INFO org.apache.hadoop.yarn.server.resourcemanager.ApplicationMasterService: Registering app attempt : appattempt_1396342005689_0004_000001
2014-04-01 02:03:37,221 INFO org.apache.hadoop.yarn.server.resourcemanager.rmapp.attempt.RMAppAttemptImpl: appattempt_1396342005689_0004_000001 State change from NEW to SUBMITTED
2014-04-01 02:03:37,221 INFO org.apache.hadoop.yarn.server.resourcemanager.scheduler.capacity.LeafQueue: Application application_1396342005689_0004 from user: hduser activated in queue: default
2014-04-01 02:03:37,221 INFO org.apache.hadoop.yarn.server.resourcemanager.scheduler.capacity.LeafQueue: Application added - appId: application_1396342005689_0004 user: org.apache.hadoop.yarn.server.resourcemanager.scheduler.capacity.LeafQueue$User@134918e, leaf-queue: default #user-pending-applications: 0 #user-active-applications: 1 #queue-pending-applications: 0 #queue-active-applications: 1
2014-04-01 02:03:37,221 INFO org.apache.hadoop.yarn.server.resourcemanager.scheduler.capacity.ParentQueue: Application added - appId: application_1396342005689_0004 user: hduser leaf-queue of parent: root #applications: 1
2014-04-01 02:03:37,221 INFO org.apache.hadoop.yarn.server.resourcemanager.scheduler.capacity.CapacityScheduler: Application Submission: appattempt_1396342005689_0004_000001, user: hduser queue: default: capacity=1.0, absoluteCapacity=1.0, usedResources=<memory:0, vCores:0>usedCapacity=0.0, absoluteUsedCapacity=0.0, numApps=1, numContainers=0, currently active: 1
2014-04-01 02:03:37,225 INFO org.apache.hadoop.yarn.server.resourcemanager.rmapp.attempt.RMAppAttemptImpl: appattempt_1396342005689_0004_000001 State change from SUBMITTED to SCHEDULED
2014-04-01 02:03:37,225 INFO org.apache.hadoop.yarn.server.resourcemanager.rmapp.RMAppImpl: application_1396342005689_0004 State change from SUBMITTED to ACCEPTED
2014-04-01 02:03:37,570 INFO org.apache.hadoop.yarn.server.resourcemanager.rmcontainer.RMContainerImpl: container_1396342005689_0004_01_000001 Container Transitioned from NEW to ALLOCATED
2014-04-01 02:03:37,571 INFO org.apache.hadoop.yarn.server.resourcemanager.RMAuditLogger: USER=hduser	OPERATION=AM Allocated Container	TARGET=SchedulerApp	RESULT=SUCCESS	APPID=application_1396342005689_0004	CONTAINERID=container_1396342005689_0004_01_000001
2014-04-01 02:03:37,571 INFO org.apache.hadoop.yarn.server.resourcemanager.scheduler.common.fica.FiCaSchedulerNode: Assigned container container_1396342005689_0004_01_000001 of capacity <memory:2048, vCores:1> on host ubuntu:38688, which currently has 1 containers, <memory:2048, vCores:1> used and <memory:6144, vCores:7> available
2014-04-01 02:03:37,571 INFO org.apache.hadoop.yarn.server.resourcemanager.scheduler.capacity.LeafQueue: assignedContainer application=application_1396342005689_0004 container=Container: [ContainerId: container_1396342005689_0004_01_000001, NodeId: ubuntu:38688, NodeHttpAddress: ubuntu:8042, Resource: <memory:2048, vCores:1>, Priority: 0, Token: Token { kind: ContainerToken, service: 127.0.1.1:38688 }, ] containerId=container_1396342005689_0004_01_000001 queue=default: capacity=1.0, absoluteCapacity=1.0, usedResources=<memory:0, vCores:0>usedCapacity=0.0, absoluteUsedCapacity=0.0, numApps=1, numContainers=0 usedCapacity=0.0 absoluteUsedCapacity=0.0 used=<memory:0, vCores:0> cluster=<memory:8192, vCores:8>
2014-04-01 02:03:37,571 INFO org.apache.hadoop.yarn.server.resourcemanager.scheduler.capacity.ParentQueue: Re-sorting assigned queue: root.default stats: default: capacity=1.0, absoluteCapacity=1.0, usedResources=<memory:2048, vCores:1>usedCapacity=0.25, absoluteUsedCapacity=0.25, numApps=1, numContainers=1
2014-04-01 02:03:37,571 INFO org.apache.hadoop.yarn.server.resourcemanager.scheduler.capacity.ParentQueue: assignedContainer queue=root usedCapacity=0.25 absoluteUsedCapacity=0.25 used=<memory:2048, vCores:1> cluster=<memory:8192, vCores:8>
2014-04-01 02:03:37,571 INFO org.apache.hadoop.yarn.server.resourcemanager.rmcontainer.RMContainerImpl: container_1396342005689_0004_01_000001 Container Transitioned from ALLOCATED to ACQUIRED
2014-04-01 02:03:37,572 INFO org.apache.hadoop.yarn.server.resourcemanager.rmapp.attempt.RMAppAttemptImpl: Storing attempt: AppId: application_1396342005689_0004 AttemptId: appattempt_1396342005689_0004_000001 MasterContainer: Container: [ContainerId: container_1396342005689_0004_01_000001, NodeId: ubuntu:38688, NodeHttpAddress: ubuntu:8042, Resource: <memory:2048, vCores:1>, Priority: 0, Token: Token { kind: ContainerToken, service: 127.0.1.1:38688 }, ]
2014-04-01 02:03:37,572 INFO org.apache.hadoop.yarn.server.resourcemanager.rmapp.attempt.RMAppAttemptImpl: appattempt_1396342005689_0004_000001 State change from SCHEDULED to ALLOCATED_SAVING
2014-04-01 02:03:37,572 INFO org.apache.hadoop.yarn.server.resourcemanager.recovery.RMStateStore: Storing info for attempt: appattempt_1396342005689_0004_000001
2014-04-01 02:03:37,572 INFO org.apache.hadoop.yarn.server.resourcemanager.rmapp.attempt.RMAppAttemptImpl: appattempt_1396342005689_0004_000001 State change from ALLOCATED_SAVING to ALLOCATED
2014-04-01 02:03:37,573 INFO org.apache.hadoop.yarn.server.resourcemanager.amlauncher.AMLauncher: Launching masterappattempt_1396342005689_0004_000001
2014-04-01 02:03:37,573 INFO org.apache.hadoop.yarn.server.resourcemanager.amlauncher.AMLauncher: Setting up container Container: [ContainerId: container_1396342005689_0004_01_000001, NodeId: ubuntu:38688, NodeHttpAddress: ubuntu:8042, Resource: <memory:2048, vCores:1>, Priority: 0, Token: Token { kind: ContainerToken, service: 127.0.1.1:38688 }, ] for AM appattempt_1396342005689_0004_000001
2014-04-01 02:03:37,574 INFO org.apache.hadoop.yarn.server.resourcemanager.amlauncher.AMLauncher: Command to launch container container_1396342005689_0004_01_000001 : $JAVA_HOME/bin/java -Dlog4j.configuration=container-log4j.properties -Dyarn.app.container.log.dir=<LOG_DIR> -Dyarn.app.container.log.filesize=0 -Dhadoop.root.logger=INFO,CLA  -Xmx1024m org.apache.hadoop.mapreduce.v2.app.MRAppMaster 1><LOG_DIR>/stdout 2><LOG_DIR>/stderr 
2014-04-01 02:03:37,584 INFO org.apache.hadoop.yarn.server.resourcemanager.amlauncher.AMLauncher: Done launching container Container: [ContainerId: container_1396342005689_0004_01_000001, NodeId: ubuntu:38688, NodeHttpAddress: ubuntu:8042, Resource: <memory:2048, vCores:1>, Priority: 0, Token: Token { kind: ContainerToken, service: 127.0.1.1:38688 }, ] for AM appattempt_1396342005689_0004_000001
2014-04-01 02:03:37,584 INFO org.apache.hadoop.yarn.server.resourcemanager.rmapp.attempt.RMAppAttemptImpl: appattempt_1396342005689_0004_000001 State change from ALLOCATED to LAUNCHED
2014-04-01 02:03:38,572 INFO org.apache.hadoop.yarn.server.resourcemanager.rmcontainer.RMContainerImpl: container_1396342005689_0004_01_000001 Container Transitioned from ACQUIRED to RUNNING
2014-04-01 02:03:40,188 INFO SecurityLogger.org.apache.hadoop.ipc.Server: Auth successful for appattempt_1396342005689_0004_000001 (auth:SIMPLE)
2014-04-01 02:03:40,190 INFO org.apache.hadoop.yarn.server.resourcemanager.ApplicationMasterService: AM registration appattempt_1396342005689_0004_000001
2014-04-01 02:03:40,190 INFO org.apache.hadoop.yarn.server.resourcemanager.RMAuditLogger: USER=hduser	IP=127.0.0.1	OPERATION=Register App Master	TARGET=ApplicationMasterService	RESULT=SUCCESS	APPID=application_1396342005689_0004	APPATTEMPTID=appattempt_1396342005689_0004_000001
2014-04-01 02:03:40,191 INFO org.apache.hadoop.yarn.server.resourcemanager.rmapp.attempt.RMAppAttemptImpl: appattempt_1396342005689_0004_000001 State change from LAUNCHED to RUNNING
2014-04-01 02:03:40,191 INFO org.apache.hadoop.yarn.server.resourcemanager.rmapp.RMAppImpl: application_1396342005689_0004 State change from ACCEPTED to RUNNING
2014-04-01 02:03:41,580 INFO org.apache.hadoop.yarn.server.resourcemanager.rmcontainer.RMContainerImpl: container_1396342005689_0004_01_000002 Container Transitioned from NEW to ALLOCATED
2014-04-01 02:03:41,580 INFO org.apache.hadoop.yarn.server.resourcemanager.RMAuditLogger: USER=hduser	OPERATION=AM Allocated Container	TARGET=SchedulerApp	RESULT=SUCCESS	APPID=application_1396342005689_0004	CONTAINERID=container_1396342005689_0004_01_000002
2014-04-01 02:03:41,580 INFO org.apache.hadoop.yarn.server.resourcemanager.scheduler.common.fica.FiCaSchedulerNode: Assigned container container_1396342005689_0004_01_000002 of capacity <memory:1024, vCores:1> on host ubuntu:38688, which currently has 2 containers, <memory:3072, vCores:2> used and <memory:5120, vCores:6> available
2014-04-01 02:03:41,580 INFO org.apache.hadoop.yarn.server.resourcemanager.scheduler.capacity.LeafQueue: assignedContainer application=application_1396342005689_0004 container=Container: [ContainerId: container_1396342005689_0004_01_000002, NodeId: ubuntu:38688, NodeHttpAddress: ubuntu:8042, Resource: <memory:1024, vCores:1>, Priority: 20, Token: Token { kind: ContainerToken, service: 127.0.1.1:38688 }, ] containerId=container_1396342005689_0004_01_000002 queue=default: capacity=1.0, absoluteCapacity=1.0, usedResources=<memory:2048, vCores:1>usedCapacity=0.25, absoluteUsedCapacity=0.25, numApps=1, numContainers=1 usedCapacity=0.25 absoluteUsedCapacity=0.25 used=<memory:2048, vCores:1> cluster=<memory:8192, vCores:8>
2014-04-01 02:03:41,580 INFO org.apache.hadoop.yarn.server.resourcemanager.scheduler.capacity.ParentQueue: Re-sorting assigned queue: root.default stats: default: capacity=1.0, absoluteCapacity=1.0, usedResources=<memory:3072, vCores:2>usedCapacity=0.375, absoluteUsedCapacity=0.375, numApps=1, numContainers=2
2014-04-01 02:03:41,581 INFO org.apache.hadoop.yarn.server.resourcemanager.scheduler.capacity.ParentQueue: assignedContainer queue=root usedCapacity=0.375 absoluteUsedCapacity=0.375 used=<memory:3072, vCores:2> cluster=<memory:8192, vCores:8>
2014-04-01 02:03:42,223 INFO org.apache.hadoop.yarn.server.resourcemanager.rmcontainer.RMContainerImpl: container_1396342005689_0004_01_000002 Container Transitioned from ALLOCATED to ACQUIRED
2014-04-01 02:03:42,583 INFO org.apache.hadoop.yarn.server.resourcemanager.rmcontainer.RMContainerImpl: container_1396342005689_0004_01_000002 Container Transitioned from ACQUIRED to RUNNING
2014-04-01 02:03:43,236 INFO org.apache.hadoop.yarn.server.resourcemanager.scheduler.AppSchedulingInfo: checking for deactivate... 
2014-04-01 02:03:46,624 INFO org.apache.hadoop.yarn.server.resourcemanager.rmcontainer.RMContainerImpl: container_1396342005689_0004_01_000002 Container Transitioned from RUNNING to COMPLETED
2014-04-01 02:03:46,624 INFO org.apache.hadoop.yarn.server.resourcemanager.scheduler.common.fica.FiCaSchedulerApp: Completed container: container_1396342005689_0004_01_000002 in state: COMPLETED event:FINISHED
2014-04-01 02:03:46,624 INFO org.apache.hadoop.yarn.server.resourcemanager.RMAuditLogger: USER=hduser	OPERATION=AM Released Container	TARGET=SchedulerApp	RESULT=SUCCESS	APPID=application_1396342005689_0004	CONTAINERID=container_1396342005689_0004_01_000002
2014-04-01 02:03:46,624 INFO org.apache.hadoop.yarn.server.resourcemanager.scheduler.common.fica.FiCaSchedulerNode: Released container container_1396342005689_0004_01_000002 of capacity <memory:1024, vCores:1> on host ubuntu:38688, which currently has 1 containers, <memory:2048, vCores:1> used and <memory:6144, vCores:7> available, release resources=true
2014-04-01 02:03:46,624 INFO org.apache.hadoop.yarn.server.resourcemanager.scheduler.capacity.LeafQueue: default used=<memory:2048, vCores:1> numContainers=1 user=hduser user-resources=<memory:2048, vCores:1>
2014-04-01 02:03:46,624 INFO org.apache.hadoop.yarn.server.resourcemanager.scheduler.capacity.LeafQueue: completedContainer container=Container: [ContainerId: container_1396342005689_0004_01_000002, NodeId: ubuntu:38688, NodeHttpAddress: ubuntu:8042, Resource: <memory:1024, vCores:1>, Priority: 20, Token: Token { kind: ContainerToken, service: 127.0.1.1:38688 }, ] resource=<memory:1024, vCores:1> queue=default: capacity=1.0, absoluteCapacity=1.0, usedResources=<memory:2048, vCores:1>usedCapacity=0.25, absoluteUsedCapacity=0.25, numApps=1, numContainers=1 usedCapacity=0.25 absoluteUsedCapacity=0.25 used=<memory:2048, vCores:1> cluster=<memory:8192, vCores:8>
2014-04-01 02:03:46,624 INFO org.apache.hadoop.yarn.server.resourcemanager.scheduler.capacity.ParentQueue: completedContainer queue=root usedCapacity=0.25 absoluteUsedCapacity=0.25 used=<memory:2048, vCores:1> cluster=<memory:8192, vCores:8>
2014-04-01 02:03:46,624 INFO org.apache.hadoop.yarn.server.resourcemanager.scheduler.capacity.ParentQueue: Re-sorting completed queue: root.default stats: default: capacity=1.0, absoluteCapacity=1.0, usedResources=<memory:2048, vCores:1>usedCapacity=0.25, absoluteUsedCapacity=0.25, numApps=1, numContainers=1
2014-04-01 02:03:46,624 INFO org.apache.hadoop.yarn.server.resourcemanager.scheduler.capacity.CapacityScheduler: Application appattempt_1396342005689_0004_000001 released container container_1396342005689_0004_01_000002 on node: host: ubuntu:38688 #containers=1 available=6144 used=2048 with event: FINISHED
2014-04-01 02:03:46,625 INFO org.apache.hadoop.yarn.server.resourcemanager.rmcontainer.RMContainerImpl: container_1396342005689_0004_01_000003 Container Transitioned from NEW to ALLOCATED
2014-04-01 02:03:46,625 INFO org.apache.hadoop.yarn.server.resourcemanager.RMAuditLogger: USER=hduser	OPERATION=AM Allocated Container	TARGET=SchedulerApp	RESULT=SUCCESS	APPID=application_1396342005689_0004	CONTAINERID=container_1396342005689_0004_01_000003
2014-04-01 02:03:46,625 INFO org.apache.hadoop.yarn.server.resourcemanager.scheduler.common.fica.FiCaSchedulerNode: Assigned container container_1396342005689_0004_01_000003 of capacity <memory:1024, vCores:1> on host ubuntu:38688, which currently has 2 containers, <memory:3072, vCores:2> used and <memory:5120, vCores:6> available
2014-04-01 02:03:46,625 INFO org.apache.hadoop.yarn.server.resourcemanager.scheduler.capacity.LeafQueue: assignedContainer application=application_1396342005689_0004 container=Container: [ContainerId: container_1396342005689_0004_01_000003, NodeId: ubuntu:38688, NodeHttpAddress: ubuntu:8042, Resource: <memory:1024, vCores:1>, Priority: 5, Token: Token { kind: ContainerToken, service: 127.0.1.1:38688 }, ] containerId=container_1396342005689_0004_01_000003 queue=default: capacity=1.0, absoluteCapacity=1.0, usedResources=<memory:2048, vCores:1>usedCapacity=0.25, absoluteUsedCapacity=0.25, numApps=1, numContainers=1 usedCapacity=0.25 absoluteUsedCapacity=0.25 used=<memory:2048, vCores:1> cluster=<memory:8192, vCores:8>
2014-04-01 02:03:46,625 INFO org.apache.hadoop.yarn.server.resourcemanager.scheduler.capacity.ParentQueue: Re-sorting assigned queue: root.default stats: default: capacity=1.0, absoluteCapacity=1.0, usedResources=<memory:3072, vCores:2>usedCapacity=0.375, absoluteUsedCapacity=0.375, numApps=1, numContainers=2
2014-04-01 02:03:46,625 INFO org.apache.hadoop.yarn.server.resourcemanager.scheduler.capacity.ParentQueue: assignedContainer queue=root usedCapacity=0.375 absoluteUsedCapacity=0.375 used=<memory:3072, vCores:2> cluster=<memory:8192, vCores:8>
2014-04-01 02:03:47,248 INFO org.apache.hadoop.yarn.server.resourcemanager.rmcontainer.RMContainerImpl: container_1396342005689_0004_01_000003 Container Transitioned from ALLOCATED to ACQUIRED
2014-04-01 02:03:47,626 INFO org.apache.hadoop.yarn.server.resourcemanager.rmcontainer.RMContainerImpl: container_1396342005689_0004_01_000003 Container Transitioned from ACQUIRED to RUNNING
2014-04-01 02:03:48,254 INFO org.apache.hadoop.yarn.server.resourcemanager.scheduler.AppSchedulingInfo: checking for deactivate... 
2014-04-01 02:03:49,934 INFO org.apache.hadoop.yarn.server.resourcemanager.rmcontainer.RMContainerImpl: container_1396342005689_0004_01_000003 Container Transitioned from RUNNING to COMPLETED
2014-04-01 02:03:49,934 INFO org.apache.hadoop.yarn.server.resourcemanager.scheduler.common.fica.FiCaSchedulerApp: Completed container: container_1396342005689_0004_01_000003 in state: COMPLETED event:FINISHED
2014-04-01 02:03:49,934 INFO org.apache.hadoop.yarn.server.resourcemanager.RMAuditLogger: USER=hduser	OPERATION=AM Released Container	TARGET=SchedulerApp	RESULT=SUCCESS	APPID=application_1396342005689_0004	CONTAINERID=container_1396342005689_0004_01_000003
2014-04-01 02:03:49,934 INFO org.apache.hadoop.yarn.server.resourcemanager.scheduler.common.fica.FiCaSchedulerNode: Released container container_1396342005689_0004_01_000003 of capacity <memory:1024, vCores:1> on host ubuntu:38688, which currently has 1 containers, <memory:2048, vCores:1> used and <memory:6144, vCores:7> available, release resources=true
2014-04-01 02:03:49,934 INFO org.apache.hadoop.yarn.server.resourcemanager.scheduler.capacity.LeafQueue: default used=<memory:2048, vCores:1> numContainers=1 user=hduser user-resources=<memory:2048, vCores:1>
2014-04-01 02:03:49,934 INFO org.apache.hadoop.yarn.server.resourcemanager.scheduler.capacity.LeafQueue: completedContainer container=Container: [ContainerId: container_1396342005689_0004_01_000003, NodeId: ubuntu:38688, NodeHttpAddress: ubuntu:8042, Resource: <memory:1024, vCores:1>, Priority: 5, Token: Token { kind: ContainerToken, service: 127.0.1.1:38688 }, ] resource=<memory:1024, vCores:1> queue=default: capacity=1.0, absoluteCapacity=1.0, usedResources=<memory:2048, vCores:1>usedCapacity=0.25, absoluteUsedCapacity=0.25, numApps=1, numContainers=1 usedCapacity=0.25 absoluteUsedCapacity=0.25 used=<memory:2048, vCores:1> cluster=<memory:8192, vCores:8>
2014-04-01 02:03:49,935 INFO org.apache.hadoop.yarn.server.resourcemanager.scheduler.capacity.ParentQueue: completedContainer queue=root usedCapacity=0.25 absoluteUsedCapacity=0.25 used=<memory:2048, vCores:1> cluster=<memory:8192, vCores:8>
2014-04-01 02:03:49,935 INFO org.apache.hadoop.yarn.server.resourcemanager.scheduler.capacity.ParentQueue: Re-sorting completed queue: root.default stats: default: capacity=1.0, absoluteCapacity=1.0, usedResources=<memory:2048, vCores:1>usedCapacity=0.25, absoluteUsedCapacity=0.25, numApps=1, numContainers=1
2014-04-01 02:03:49,935 INFO org.apache.hadoop.yarn.server.resourcemanager.scheduler.capacity.CapacityScheduler: Application appattempt_1396342005689_0004_000001 released container container_1396342005689_0004_01_000003 on node: host: ubuntu:38688 #containers=1 available=6144 used=2048 with event: FINISHED
2014-04-01 02:03:49,935 INFO org.apache.hadoop.yarn.server.resourcemanager.rmcontainer.RMContainerImpl: container_1396342005689_0004_01_000004 Container Transitioned from NEW to ALLOCATED
2014-04-01 02:03:49,935 INFO org.apache.hadoop.yarn.server.resourcemanager.RMAuditLogger: USER=hduser	OPERATION=AM Allocated Container	TARGET=SchedulerApp	RESULT=SUCCESS	APPID=application_1396342005689_0004	CONTAINERID=container_1396342005689_0004_01_000004
2014-04-01 02:03:49,935 INFO org.apache.hadoop.yarn.server.resourcemanager.scheduler.common.fica.FiCaSchedulerNode: Assigned container container_1396342005689_0004_01_000004 of capacity <memory:1024, vCores:1> on host ubuntu:38688, which currently has 2 containers, <memory:3072, vCores:2> used and <memory:5120, vCores:6> available
2014-04-01 02:03:49,936 INFO org.apache.hadoop.yarn.server.resourcemanager.scheduler.capacity.LeafQueue: assignedContainer application=application_1396342005689_0004 container=Container: [ContainerId: container_1396342005689_0004_01_000004, NodeId: ubuntu:38688, NodeHttpAddress: ubuntu:8042, Resource: <memory:1024, vCores:1>, Priority: 5, Token: Token { kind: ContainerToken, service: 127.0.1.1:38688 }, ] containerId=container_1396342005689_0004_01_000004 queue=default: capacity=1.0, absoluteCapacity=1.0, usedResources=<memory:2048, vCores:1>usedCapacity=0.25, absoluteUsedCapacity=0.25, numApps=1, numContainers=1 usedCapacity=0.25 absoluteUsedCapacity=0.25 used=<memory:2048, vCores:1> cluster=<memory:8192, vCores:8>
2014-04-01 02:03:49,936 INFO org.apache.hadoop.yarn.server.resourcemanager.scheduler.capacity.ParentQueue: Re-sorting assigned queue: root.default stats: default: capacity=1.0, absoluteCapacity=1.0, usedResources=<memory:3072, vCores:2>usedCapacity=0.375, absoluteUsedCapacity=0.375, numApps=1, numContainers=2
2014-04-01 02:03:49,936 INFO org.apache.hadoop.yarn.server.resourcemanager.scheduler.capacity.ParentQueue: assignedContainer queue=root usedCapacity=0.375 absoluteUsedCapacity=0.375 used=<memory:3072, vCores:2> cluster=<memory:8192, vCores:8>
2014-04-01 02:03:50,264 INFO org.apache.hadoop.yarn.server.resourcemanager.rmcontainer.RMContainerImpl: container_1396342005689_0004_01_000004 Container Transitioned from ALLOCATED to ACQUIRED
2014-04-01 02:03:50,936 INFO org.apache.hadoop.yarn.server.resourcemanager.rmcontainer.RMContainerImpl: container_1396342005689_0004_01_000004 Container Transitioned from ACQUIRED to RUNNING
2014-04-01 02:03:51,271 INFO org.apache.hadoop.yarn.server.resourcemanager.scheduler.AppSchedulingInfo: checking for deactivate... 
2014-04-01 02:03:52,936 INFO org.apache.hadoop.yarn.server.resourcemanager.rmcontainer.RMContainerImpl: container_1396342005689_0004_01_000004 Container Transitioned from RUNNING to COMPLETED
2014-04-01 02:03:52,937 INFO org.apache.hadoop.yarn.server.resourcemanager.scheduler.common.fica.FiCaSchedulerApp: Completed container: container_1396342005689_0004_01_000004 in state: COMPLETED event:FINISHED
2014-04-01 02:03:52,937 INFO org.apache.hadoop.yarn.server.resourcemanager.RMAuditLogger: USER=hduser	OPERATION=AM Released Container	TARGET=SchedulerApp	RESULT=SUCCESS	APPID=application_1396342005689_0004	CONTAINERID=container_1396342005689_0004_01_000004
2014-04-01 02:03:52,937 INFO org.apache.hadoop.yarn.server.resourcemanager.scheduler.common.fica.FiCaSchedulerNode: Released container container_1396342005689_0004_01_000004 of capacity <memory:1024, vCores:1> on host ubuntu:38688, which currently has 1 containers, <memory:2048, vCores:1> used and <memory:6144, vCores:7> available, release resources=true
2014-04-01 02:03:52,937 INFO org.apache.hadoop.yarn.server.resourcemanager.scheduler.capacity.LeafQueue: default used=<memory:2048, vCores:1> numContainers=1 user=hduser user-resources=<memory:2048, vCores:1>
2014-04-01 02:03:52,937 INFO org.apache.hadoop.yarn.server.resourcemanager.scheduler.capacity.LeafQueue: completedContainer container=Container: [ContainerId: container_1396342005689_0004_01_000004, NodeId: ubuntu:38688, NodeHttpAddress: ubuntu:8042, Resource: <memory:1024, vCores:1>, Priority: 5, Token: Token { kind: ContainerToken, service: 127.0.1.1:38688 }, ] resource=<memory:1024, vCores:1> queue=default: capacity=1.0, absoluteCapacity=1.0, usedResources=<memory:2048, vCores:1>usedCapacity=0.25, absoluteUsedCapacity=0.25, numApps=1, numContainers=1 usedCapacity=0.25 absoluteUsedCapacity=0.25 used=<memory:2048, vCores:1> cluster=<memory:8192, vCores:8>
2014-04-01 02:03:52,937 INFO org.apache.hadoop.yarn.server.resourcemanager.scheduler.capacity.ParentQueue: completedContainer queue=root usedCapacity=0.25 absoluteUsedCapacity=0.25 used=<memory:2048, vCores:1> cluster=<memory:8192, vCores:8>
2014-04-01 02:03:52,937 INFO org.apache.hadoop.yarn.server.resourcemanager.scheduler.capacity.ParentQueue: Re-sorting completed queue: root.default stats: default: capacity=1.0, absoluteCapacity=1.0, usedResources=<memory:2048, vCores:1>usedCapacity=0.25, absoluteUsedCapacity=0.25, numApps=1, numContainers=1
2014-04-01 02:03:52,937 INFO org.apache.hadoop.yarn.server.resourcemanager.scheduler.capacity.CapacityScheduler: Application appattempt_1396342005689_0004_000001 released container container_1396342005689_0004_01_000004 on node: host: ubuntu:38688 #containers=1 available=6144 used=2048 with event: FINISHED
2014-04-01 02:03:53,940 INFO org.apache.hadoop.yarn.server.resourcemanager.rmcontainer.RMContainerImpl: container_1396342005689_0004_01_000005 Container Transitioned from NEW to ALLOCATED
2014-04-01 02:03:53,940 INFO org.apache.hadoop.yarn.server.resourcemanager.RMAuditLogger: USER=hduser	OPERATION=AM Allocated Container	TARGET=SchedulerApp	RESULT=SUCCESS	APPID=application_1396342005689_0004	CONTAINERID=container_1396342005689_0004_01_000005
2014-04-01 02:03:53,940 INFO org.apache.hadoop.yarn.server.resourcemanager.scheduler.common.fica.FiCaSchedulerNode: Assigned container container_1396342005689_0004_01_000005 of capacity <memory:1024, vCores:1> on host ubuntu:38688, which currently has 2 containers, <memory:3072, vCores:2> used and <memory:5120, vCores:6> available
2014-04-01 02:03:53,940 INFO org.apache.hadoop.yarn.server.resourcemanager.scheduler.capacity.LeafQueue: assignedContainer application=application_1396342005689_0004 container=Container: [ContainerId: container_1396342005689_0004_01_000005, NodeId: ubuntu:38688, NodeHttpAddress: ubuntu:8042, Resource: <memory:1024, vCores:1>, Priority: 5, Token: Token { kind: ContainerToken, service: 127.0.1.1:38688 }, ] containerId=container_1396342005689_0004_01_000005 queue=default: capacity=1.0, absoluteCapacity=1.0, usedResources=<memory:2048, vCores:1>usedCapacity=0.25, absoluteUsedCapacity=0.25, numApps=1, numContainers=1 usedCapacity=0.25 absoluteUsedCapacity=0.25 used=<memory:2048, vCores:1> cluster=<memory:8192, vCores:8>
2014-04-01 02:03:53,940 INFO org.apache.hadoop.yarn.server.resourcemanager.scheduler.capacity.ParentQueue: Re-sorting assigned queue: root.default stats: default: capacity=1.0, absoluteCapacity=1.0, usedResources=<memory:3072, vCores:2>usedCapacity=0.375, absoluteUsedCapacity=0.375, numApps=1, numContainers=2
2014-04-01 02:03:53,940 INFO org.apache.hadoop.yarn.server.resourcemanager.scheduler.capacity.ParentQueue: assignedContainer queue=root usedCapacity=0.375 absoluteUsedCapacity=0.375 used=<memory:3072, vCores:2> cluster=<memory:8192, vCores:8>
2014-04-01 02:03:54,284 INFO org.apache.hadoop.yarn.server.resourcemanager.rmcontainer.RMContainerImpl: container_1396342005689_0004_01_000005 Container Transitioned from ALLOCATED to ACQUIRED
2014-04-01 02:03:54,941 INFO org.apache.hadoop.yarn.server.resourcemanager.rmcontainer.RMContainerImpl: container_1396342005689_0004_01_000005 Container Transitioned from ACQUIRED to RUNNING
2014-04-01 02:03:55,290 INFO org.apache.hadoop.yarn.server.resourcemanager.scheduler.AppSchedulingInfo: checking for deactivate... 
2014-04-01 02:03:55,960 INFO org.apache.hadoop.yarn.server.resourcemanager.rmapp.attempt.RMAppAttemptImpl: appattempt_1396342005689_0004_000001 State change from RUNNING to FINISHING
2014-04-01 02:03:55,960 INFO org.apache.hadoop.yarn.server.resourcemanager.rmapp.RMAppImpl: Removing application with id application_1396342005689_0004
2014-04-01 02:03:55,960 INFO org.apache.hadoop.yarn.server.resourcemanager.rmapp.RMAppImpl: application_1396342005689_0004 State change from RUNNING to REMOVING
2014-04-01 02:03:55,960 INFO org.apache.hadoop.yarn.server.resourcemanager.recovery.RMStateStore: Removing info for app: application_1396342005689_0004
2014-04-01 02:03:55,960 INFO org.apache.hadoop.yarn.server.resourcemanager.rmapp.RMAppImpl: application_1396342005689_0004 State change from REMOVING to FINISHING
2014-04-01 02:03:56,945 INFO org.apache.hadoop.yarn.server.resourcemanager.rmcontainer.RMContainerImpl: container_1396342005689_0004_01_000005 Container Transitioned from RUNNING to COMPLETED
2014-04-01 02:03:56,945 INFO org.apache.hadoop.yarn.server.resourcemanager.scheduler.common.fica.FiCaSchedulerApp: Completed container: container_1396342005689_0004_01_000005 in state: COMPLETED event:FINISHED
2014-04-01 02:03:56,945 INFO org.apache.hadoop.yarn.server.resourcemanager.RMAuditLogger: USER=hduser	OPERATION=AM Released Container	TARGET=SchedulerApp	RESULT=SUCCESS	APPID=application_1396342005689_0004	CONTAINERID=container_1396342005689_0004_01_000005
2014-04-01 02:03:56,945 INFO org.apache.hadoop.yarn.server.resourcemanager.scheduler.common.fica.FiCaSchedulerNode: Released container container_1396342005689_0004_01_000005 of capacity <memory:1024, vCores:1> on host ubuntu:38688, which currently has 1 containers, <memory:2048, vCores:1> used and <memory:6144, vCores:7> available, release resources=true
2014-04-01 02:03:56,945 INFO org.apache.hadoop.yarn.server.resourcemanager.scheduler.capacity.LeafQueue: default used=<memory:2048, vCores:1> numContainers=1 user=hduser user-resources=<memory:2048, vCores:1>
2014-04-01 02:03:56,945 INFO org.apache.hadoop.yarn.server.resourcemanager.scheduler.capacity.LeafQueue: completedContainer container=Container: [ContainerId: container_1396342005689_0004_01_000005, NodeId: ubuntu:38688, NodeHttpAddress: ubuntu:8042, Resource: <memory:1024, vCores:1>, Priority: 5, Token: Token { kind: ContainerToken, service: 127.0.1.1:38688 }, ] resource=<memory:1024, vCores:1> queue=default: capacity=1.0, absoluteCapacity=1.0, usedResources=<memory:2048, vCores:1>usedCapacity=0.25, absoluteUsedCapacity=0.25, numApps=1, numContainers=1 usedCapacity=0.25 absoluteUsedCapacity=0.25 used=<memory:2048, vCores:1> cluster=<memory:8192, vCores:8>
2014-04-01 02:03:56,945 INFO org.apache.hadoop.yarn.server.resourcemanager.scheduler.capacity.ParentQueue: completedContainer queue=root usedCapacity=0.25 absoluteUsedCapacity=0.25 used=<memory:2048, vCores:1> cluster=<memory:8192, vCores:8>
2014-04-01 02:03:56,946 INFO org.apache.hadoop.yarn.server.resourcemanager.scheduler.capacity.ParentQueue: Re-sorting completed queue: root.default stats: default: capacity=1.0, absoluteCapacity=1.0, usedResources=<memory:2048, vCores:1>usedCapacity=0.25, absoluteUsedCapacity=0.25, numApps=1, numContainers=1
2014-04-01 02:03:56,946 INFO org.apache.hadoop.yarn.server.resourcemanager.scheduler.capacity.CapacityScheduler: Application appattempt_1396342005689_0004_000001 released container container_1396342005689_0004_01_000005 on node: host: ubuntu:38688 #containers=1 available=6144 used=2048 with event: FINISHED
2014-04-01 02:03:57,947 INFO org.apache.hadoop.yarn.server.resourcemanager.rmcontainer.RMContainerImpl: container_1396342005689_0004_01_000001 Container Transitioned from RUNNING to COMPLETED
2014-04-01 02:03:57,948 INFO org.apache.hadoop.yarn.server.resourcemanager.scheduler.common.fica.FiCaSchedulerApp: Completed container: container_1396342005689_0004_01_000001 in state: COMPLETED event:FINISHED
2014-04-01 02:03:57,948 INFO org.apache.hadoop.yarn.server.resourcemanager.RMAuditLogger: USER=hduser	OPERATION=AM Released Container	TARGET=SchedulerApp	RESULT=SUCCESS	APPID=application_1396342005689_0004	CONTAINERID=container_1396342005689_0004_01_000001
2014-04-01 02:03:57,948 INFO org.apache.hadoop.yarn.server.resourcemanager.scheduler.common.fica.FiCaSchedulerNode: Released container container_1396342005689_0004_01_000001 of capacity <memory:2048, vCores:1> on host ubuntu:38688, which currently has 0 containers, <memory:0, vCores:0> used and <memory:8192, vCores:8> available, release resources=true
2014-04-01 02:03:57,948 INFO org.apache.hadoop.yarn.server.resourcemanager.scheduler.capacity.LeafQueue: default used=<memory:0, vCores:0> numContainers=0 user=hduser user-resources=<memory:0, vCores:0>
2014-04-01 02:03:57,948 INFO org.apache.hadoop.yarn.server.resourcemanager.scheduler.capacity.LeafQueue: completedContainer container=Container: [ContainerId: container_1396342005689_0004_01_000001, NodeId: ubuntu:38688, NodeHttpAddress: ubuntu:8042, Resource: <memory:2048, vCores:1>, Priority: 0, Token: Token { kind: ContainerToken, service: 127.0.1.1:38688 }, ] resource=<memory:2048, vCores:1> queue=default: capacity=1.0, absoluteCapacity=1.0, usedResources=<memory:0, vCores:0>usedCapacity=0.0, absoluteUsedCapacity=0.0, numApps=1, numContainers=0 usedCapacity=0.0 absoluteUsedCapacity=0.0 used=<memory:0, vCores:0> cluster=<memory:8192, vCores:8>
2014-04-01 02:03:57,949 INFO org.apache.hadoop.yarn.server.resourcemanager.scheduler.capacity.ParentQueue: completedContainer queue=root usedCapacity=0.0 absoluteUsedCapacity=0.0 used=<memory:0, vCores:0> cluster=<memory:8192, vCores:8>
2014-04-01 02:03:57,949 INFO org.apache.hadoop.yarn.server.resourcemanager.scheduler.capacity.ParentQueue: Re-sorting completed queue: root.default stats: default: capacity=1.0, absoluteCapacity=1.0, usedResources=<memory:0, vCores:0>usedCapacity=0.0, absoluteUsedCapacity=0.0, numApps=1, numContainers=0
2014-04-01 02:03:57,949 INFO org.apache.hadoop.yarn.server.resourcemanager.scheduler.capacity.CapacityScheduler: Application appattempt_1396342005689_0004_000001 released container container_1396342005689_0004_01_000001 on node: host: ubuntu:38688 #containers=0 available=8192 used=0 with event: FINISHED
2014-04-01 02:03:57,948 INFO org.apache.hadoop.yarn.server.resourcemanager.ApplicationMasterService: Unregistering app attempt : appattempt_1396342005689_0004_000001
2014-04-01 02:03:57,949 INFO org.apache.hadoop.yarn.server.resourcemanager.rmapp.attempt.RMAppAttemptImpl: appattempt_1396342005689_0004_000001 State change from FINISHING to FINISHED
2014-04-01 02:03:57,949 INFO org.apache.hadoop.yarn.server.resourcemanager.rmapp.RMAppImpl: application_1396342005689_0004 State change from FINISHING to FINISHED
2014-04-01 02:03:57,950 INFO org.apache.hadoop.yarn.server.resourcemanager.RMAuditLogger: USER=hduser	OPERATION=Application Finished - Succeeded	TARGET=RMAppManager	RESULT=SUCCESS	APPID=application_1396342005689_0004
2014-04-01 02:03:57,950 INFO org.apache.hadoop.yarn.server.resourcemanager.RMAppManager$ApplicationSummary: appId=application_1396342005689_0004,name=base||path:/in||num reduce:8,user=hduser,queue=default,state=FINISHED,trackingUrl=ubuntu:8088/proxy/application_1396342005689_0004/jobhistory/job/job_1396342005689_0004,appMasterHost=ubuntu,startTime=1396343017219,finishTime=1396343035960,finalStatus=FAILED
2014-04-01 02:03:57,950 INFO org.apache.hadoop.yarn.server.resourcemanager.scheduler.capacity.CapacityScheduler: Application appattempt_1396342005689_0004_000001 is done. finalState=FINISHED
2014-04-01 02:03:57,950 INFO org.apache.hadoop.yarn.server.resourcemanager.scheduler.AppSchedulingInfo: Application application_1396342005689_0004 requests cleared
2014-04-01 02:03:57,950 INFO org.apache.hadoop.yarn.server.resourcemanager.scheduler.capacity.LeafQueue: Application removed - appId: application_1396342005689_0004 user: hduser queue: default #user-pending-applications: 0 #user-active-applications: 0 #queue-pending-applications: 0 #queue-active-applications: 0
2014-04-01 02:03:57,950 INFO org.apache.hadoop.yarn.server.resourcemanager.amlauncher.AMLauncher: Cleaning master appattempt_1396342005689_0004_000001
2014-04-01 02:03:57,950 INFO org.apache.hadoop.yarn.server.resourcemanager.scheduler.capacity.ParentQueue: Application removed - appId: application_1396342005689_0004 user: hduser leaf-queue of parent: root #applications: 0
2014-04-01 02:06:02,123 INFO org.apache.hadoop.yarn.server.resourcemanager.ClientRMService: Allocated new applicationId: 5
2014-04-01 02:06:02,722 INFO org.apache.hadoop.yarn.server.resourcemanager.ClientRMService: Application with id 5 submitted by user hduser
2014-04-01 02:06:02,722 INFO org.apache.hadoop.yarn.server.resourcemanager.rmapp.RMAppImpl: Storing application with id application_1396342005689_0005
2014-04-01 02:06:02,722 INFO org.apache.hadoop.yarn.server.resourcemanager.RMAuditLogger: USER=hduser	IP=127.0.0.1	OPERATION=Submit Application Request	TARGET=ClientRMService	RESULT=SUCCESS	APPID=application_1396342005689_0005
2014-04-01 02:06:02,722 INFO org.apache.hadoop.yarn.server.resourcemanager.rmapp.RMAppImpl: application_1396342005689_0005 State change from NEW to NEW_SAVING
2014-04-01 02:06:02,723 INFO org.apache.hadoop.yarn.server.resourcemanager.recovery.RMStateStore: Storing info for app: application_1396342005689_0005
2014-04-01 02:06:02,723 INFO org.apache.hadoop.yarn.server.resourcemanager.rmapp.RMAppImpl: application_1396342005689_0005 State change from NEW_SAVING to SUBMITTED
2014-04-01 02:06:02,723 INFO org.apache.hadoop.yarn.server.resourcemanager.ApplicationMasterService: Registering app attempt : appattempt_1396342005689_0005_000001
2014-04-01 02:06:02,723 INFO org.apache.hadoop.yarn.server.resourcemanager.rmapp.attempt.RMAppAttemptImpl: appattempt_1396342005689_0005_000001 State change from NEW to SUBMITTED
2014-04-01 02:06:02,724 INFO org.apache.hadoop.yarn.server.resourcemanager.scheduler.capacity.LeafQueue: Application application_1396342005689_0005 from user: hduser activated in queue: default
2014-04-01 02:06:02,724 INFO org.apache.hadoop.yarn.server.resourcemanager.scheduler.capacity.LeafQueue: Application added - appId: application_1396342005689_0005 user: org.apache.hadoop.yarn.server.resourcemanager.scheduler.capacity.LeafQueue$User@18b2918, leaf-queue: default #user-pending-applications: 0 #user-active-applications: 1 #queue-pending-applications: 0 #queue-active-applications: 1
2014-04-01 02:06:02,724 INFO org.apache.hadoop.yarn.server.resourcemanager.scheduler.capacity.ParentQueue: Application added - appId: application_1396342005689_0005 user: hduser leaf-queue of parent: root #applications: 1
2014-04-01 02:06:02,724 INFO org.apache.hadoop.yarn.server.resourcemanager.scheduler.capacity.CapacityScheduler: Application Submission: appattempt_1396342005689_0005_000001, user: hduser queue: default: capacity=1.0, absoluteCapacity=1.0, usedResources=<memory:0, vCores:0>usedCapacity=0.0, absoluteUsedCapacity=0.0, numApps=1, numContainers=0, currently active: 1
2014-04-01 02:06:02,724 INFO org.apache.hadoop.yarn.server.resourcemanager.rmapp.attempt.RMAppAttemptImpl: appattempt_1396342005689_0005_000001 State change from SUBMITTED to SCHEDULED
2014-04-01 02:06:02,724 INFO org.apache.hadoop.yarn.server.resourcemanager.rmapp.RMAppImpl: application_1396342005689_0005 State change from SUBMITTED to ACCEPTED
2014-04-01 02:06:03,253 INFO org.apache.hadoop.yarn.server.resourcemanager.rmcontainer.RMContainerImpl: container_1396342005689_0005_01_000001 Container Transitioned from NEW to ALLOCATED
2014-04-01 02:06:03,282 INFO org.apache.hadoop.yarn.server.resourcemanager.RMAuditLogger: USER=hduser	OPERATION=AM Allocated Container	TARGET=SchedulerApp	RESULT=SUCCESS	APPID=application_1396342005689_0005	CONTAINERID=container_1396342005689_0005_01_000001
2014-04-01 02:06:03,282 INFO org.apache.hadoop.yarn.server.resourcemanager.scheduler.common.fica.FiCaSchedulerNode: Assigned container container_1396342005689_0005_01_000001 of capacity <memory:2048, vCores:1> on host ubuntu:38688, which currently has 1 containers, <memory:2048, vCores:1> used and <memory:6144, vCores:7> available
2014-04-01 02:06:03,282 INFO org.apache.hadoop.yarn.server.resourcemanager.scheduler.capacity.LeafQueue: assignedContainer application=application_1396342005689_0005 container=Container: [ContainerId: container_1396342005689_0005_01_000001, NodeId: ubuntu:38688, NodeHttpAddress: ubuntu:8042, Resource: <memory:2048, vCores:1>, Priority: 0, Token: Token { kind: ContainerToken, service: 127.0.1.1:38688 }, ] containerId=container_1396342005689_0005_01_000001 queue=default: capacity=1.0, absoluteCapacity=1.0, usedResources=<memory:0, vCores:0>usedCapacity=0.0, absoluteUsedCapacity=0.0, numApps=1, numContainers=0 usedCapacity=0.0 absoluteUsedCapacity=0.0 used=<memory:0, vCores:0> cluster=<memory:8192, vCores:8>
2014-04-01 02:06:03,282 INFO org.apache.hadoop.yarn.server.resourcemanager.scheduler.capacity.ParentQueue: Re-sorting assigned queue: root.default stats: default: capacity=1.0, absoluteCapacity=1.0, usedResources=<memory:2048, vCores:1>usedCapacity=0.25, absoluteUsedCapacity=0.25, numApps=1, numContainers=1
2014-04-01 02:06:03,282 INFO org.apache.hadoop.yarn.server.resourcemanager.scheduler.capacity.ParentQueue: assignedContainer queue=root usedCapacity=0.25 absoluteUsedCapacity=0.25 used=<memory:2048, vCores:1> cluster=<memory:8192, vCores:8>
2014-04-01 02:06:03,283 INFO org.apache.hadoop.yarn.server.resourcemanager.rmcontainer.RMContainerImpl: container_1396342005689_0005_01_000001 Container Transitioned from ALLOCATED to ACQUIRED
2014-04-01 02:06:03,284 INFO org.apache.hadoop.yarn.server.resourcemanager.rmapp.attempt.RMAppAttemptImpl: Storing attempt: AppId: application_1396342005689_0005 AttemptId: appattempt_1396342005689_0005_000001 MasterContainer: Container: [ContainerId: container_1396342005689_0005_01_000001, NodeId: ubuntu:38688, NodeHttpAddress: ubuntu:8042, Resource: <memory:2048, vCores:1>, Priority: 0, Token: Token { kind: ContainerToken, service: 127.0.1.1:38688 }, ]
2014-04-01 02:06:03,284 INFO org.apache.hadoop.yarn.server.resourcemanager.rmapp.attempt.RMAppAttemptImpl: appattempt_1396342005689_0005_000001 State change from SCHEDULED to ALLOCATED_SAVING
2014-04-01 02:06:03,284 INFO org.apache.hadoop.yarn.server.resourcemanager.recovery.RMStateStore: Storing info for attempt: appattempt_1396342005689_0005_000001
2014-04-01 02:06:03,284 INFO org.apache.hadoop.yarn.server.resourcemanager.rmapp.attempt.RMAppAttemptImpl: appattempt_1396342005689_0005_000001 State change from ALLOCATED_SAVING to ALLOCATED
2014-04-01 02:06:03,285 INFO org.apache.hadoop.yarn.server.resourcemanager.amlauncher.AMLauncher: Launching masterappattempt_1396342005689_0005_000001
2014-04-01 02:06:03,286 INFO org.apache.hadoop.yarn.server.resourcemanager.amlauncher.AMLauncher: Setting up container Container: [ContainerId: container_1396342005689_0005_01_000001, NodeId: ubuntu:38688, NodeHttpAddress: ubuntu:8042, Resource: <memory:2048, vCores:1>, Priority: 0, Token: Token { kind: ContainerToken, service: 127.0.1.1:38688 }, ] for AM appattempt_1396342005689_0005_000001
2014-04-01 02:06:03,286 INFO org.apache.hadoop.yarn.server.resourcemanager.amlauncher.AMLauncher: Command to launch container container_1396342005689_0005_01_000001 : $JAVA_HOME/bin/java -Dlog4j.configuration=container-log4j.properties -Dyarn.app.container.log.dir=<LOG_DIR> -Dyarn.app.container.log.filesize=0 -Dhadoop.root.logger=INFO,CLA  -Xmx1024m org.apache.hadoop.mapreduce.v2.app.MRAppMaster 1><LOG_DIR>/stdout 2><LOG_DIR>/stderr 
2014-04-01 02:06:03,301 INFO org.apache.hadoop.yarn.server.resourcemanager.amlauncher.AMLauncher: Done launching container Container: [ContainerId: container_1396342005689_0005_01_000001, NodeId: ubuntu:38688, NodeHttpAddress: ubuntu:8042, Resource: <memory:2048, vCores:1>, Priority: 0, Token: Token { kind: ContainerToken, service: 127.0.1.1:38688 }, ] for AM appattempt_1396342005689_0005_000001
2014-04-01 02:06:03,301 INFO org.apache.hadoop.yarn.server.resourcemanager.rmapp.attempt.RMAppAttemptImpl: appattempt_1396342005689_0005_000001 State change from ALLOCATED to LAUNCHED
2014-04-01 02:06:04,255 INFO org.apache.hadoop.yarn.server.resourcemanager.rmcontainer.RMContainerImpl: container_1396342005689_0005_01_000001 Container Transitioned from ACQUIRED to RUNNING
2014-04-01 02:06:05,848 INFO SecurityLogger.org.apache.hadoop.ipc.Server: Auth successful for appattempt_1396342005689_0005_000001 (auth:SIMPLE)
2014-04-01 02:06:05,851 INFO org.apache.hadoop.yarn.server.resourcemanager.ApplicationMasterService: AM registration appattempt_1396342005689_0005_000001
2014-04-01 02:06:05,851 INFO org.apache.hadoop.yarn.server.resourcemanager.RMAuditLogger: USER=hduser	IP=127.0.0.1	OPERATION=Register App Master	TARGET=ApplicationMasterService	RESULT=SUCCESS	APPID=application_1396342005689_0005	APPATTEMPTID=appattempt_1396342005689_0005_000001
2014-04-01 02:06:05,852 INFO org.apache.hadoop.yarn.server.resourcemanager.rmapp.attempt.RMAppAttemptImpl: appattempt_1396342005689_0005_000001 State change from LAUNCHED to RUNNING
2014-04-01 02:06:05,852 INFO org.apache.hadoop.yarn.server.resourcemanager.rmapp.RMAppImpl: application_1396342005689_0005 State change from ACCEPTED to RUNNING
2014-04-01 02:06:07,263 INFO org.apache.hadoop.yarn.server.resourcemanager.rmcontainer.RMContainerImpl: container_1396342005689_0005_01_000002 Container Transitioned from NEW to ALLOCATED
2014-04-01 02:06:07,263 INFO org.apache.hadoop.yarn.server.resourcemanager.RMAuditLogger: USER=hduser	OPERATION=AM Allocated Container	TARGET=SchedulerApp	RESULT=SUCCESS	APPID=application_1396342005689_0005	CONTAINERID=container_1396342005689_0005_01_000002
2014-04-01 02:06:07,263 INFO org.apache.hadoop.yarn.server.resourcemanager.scheduler.common.fica.FiCaSchedulerNode: Assigned container container_1396342005689_0005_01_000002 of capacity <memory:1024, vCores:1> on host ubuntu:38688, which currently has 2 containers, <memory:3072, vCores:2> used and <memory:5120, vCores:6> available
2014-04-01 02:06:07,263 INFO org.apache.hadoop.yarn.server.resourcemanager.scheduler.capacity.LeafQueue: assignedContainer application=application_1396342005689_0005 container=Container: [ContainerId: container_1396342005689_0005_01_000002, NodeId: ubuntu:38688, NodeHttpAddress: ubuntu:8042, Resource: <memory:1024, vCores:1>, Priority: 20, Token: Token { kind: ContainerToken, service: 127.0.1.1:38688 }, ] containerId=container_1396342005689_0005_01_000002 queue=default: capacity=1.0, absoluteCapacity=1.0, usedResources=<memory:2048, vCores:1>usedCapacity=0.25, absoluteUsedCapacity=0.25, numApps=1, numContainers=1 usedCapacity=0.25 absoluteUsedCapacity=0.25 used=<memory:2048, vCores:1> cluster=<memory:8192, vCores:8>
2014-04-01 02:06:07,264 INFO org.apache.hadoop.yarn.server.resourcemanager.scheduler.capacity.ParentQueue: Re-sorting assigned queue: root.default stats: default: capacity=1.0, absoluteCapacity=1.0, usedResources=<memory:3072, vCores:2>usedCapacity=0.375, absoluteUsedCapacity=0.375, numApps=1, numContainers=2
2014-04-01 02:06:07,264 INFO org.apache.hadoop.yarn.server.resourcemanager.scheduler.capacity.ParentQueue: assignedContainer queue=root usedCapacity=0.375 absoluteUsedCapacity=0.375 used=<memory:3072, vCores:2> cluster=<memory:8192, vCores:8>
2014-04-01 02:06:07,882 INFO org.apache.hadoop.yarn.server.resourcemanager.rmcontainer.RMContainerImpl: container_1396342005689_0005_01_000002 Container Transitioned from ALLOCATED to ACQUIRED
2014-04-01 02:06:08,265 INFO org.apache.hadoop.yarn.server.resourcemanager.rmcontainer.RMContainerImpl: container_1396342005689_0005_01_000002 Container Transitioned from ACQUIRED to RUNNING
2014-04-01 02:06:08,898 INFO org.apache.hadoop.yarn.server.resourcemanager.scheduler.AppSchedulingInfo: checking for deactivate... 
2014-04-01 02:06:10,635 INFO org.apache.hadoop.yarn.server.resourcemanager.rmcontainer.RMContainerImpl: container_1396342005689_0005_01_000002 Container Transitioned from RUNNING to COMPLETED
2014-04-01 02:06:10,636 INFO org.apache.hadoop.yarn.server.resourcemanager.scheduler.common.fica.FiCaSchedulerApp: Completed container: container_1396342005689_0005_01_000002 in state: COMPLETED event:FINISHED
2014-04-01 02:06:10,636 INFO org.apache.hadoop.yarn.server.resourcemanager.RMAuditLogger: USER=hduser	OPERATION=AM Released Container	TARGET=SchedulerApp	RESULT=SUCCESS	APPID=application_1396342005689_0005	CONTAINERID=container_1396342005689_0005_01_000002
2014-04-01 02:06:10,636 INFO org.apache.hadoop.yarn.server.resourcemanager.scheduler.common.fica.FiCaSchedulerNode: Released container container_1396342005689_0005_01_000002 of capacity <memory:1024, vCores:1> on host ubuntu:38688, which currently has 1 containers, <memory:2048, vCores:1> used and <memory:6144, vCores:7> available, release resources=true
2014-04-01 02:06:10,636 INFO org.apache.hadoop.yarn.server.resourcemanager.scheduler.capacity.LeafQueue: default used=<memory:2048, vCores:1> numContainers=1 user=hduser user-resources=<memory:2048, vCores:1>
2014-04-01 02:06:10,636 INFO org.apache.hadoop.yarn.server.resourcemanager.scheduler.capacity.LeafQueue: completedContainer container=Container: [ContainerId: container_1396342005689_0005_01_000002, NodeId: ubuntu:38688, NodeHttpAddress: ubuntu:8042, Resource: <memory:1024, vCores:1>, Priority: 20, Token: Token { kind: ContainerToken, service: 127.0.1.1:38688 }, ] resource=<memory:1024, vCores:1> queue=default: capacity=1.0, absoluteCapacity=1.0, usedResources=<memory:2048, vCores:1>usedCapacity=0.25, absoluteUsedCapacity=0.25, numApps=1, numContainers=1 usedCapacity=0.25 absoluteUsedCapacity=0.25 used=<memory:2048, vCores:1> cluster=<memory:8192, vCores:8>
2014-04-01 02:06:10,636 INFO org.apache.hadoop.yarn.server.resourcemanager.scheduler.capacity.ParentQueue: completedContainer queue=root usedCapacity=0.25 absoluteUsedCapacity=0.25 used=<memory:2048, vCores:1> cluster=<memory:8192, vCores:8>
2014-04-01 02:06:10,636 INFO org.apache.hadoop.yarn.server.resourcemanager.scheduler.capacity.ParentQueue: Re-sorting completed queue: root.default stats: default: capacity=1.0, absoluteCapacity=1.0, usedResources=<memory:2048, vCores:1>usedCapacity=0.25, absoluteUsedCapacity=0.25, numApps=1, numContainers=1
2014-04-01 02:06:10,636 INFO org.apache.hadoop.yarn.server.resourcemanager.scheduler.capacity.CapacityScheduler: Application appattempt_1396342005689_0005_000001 released container container_1396342005689_0005_01_000002 on node: host: ubuntu:38688 #containers=1 available=6144 used=2048 with event: FINISHED
2014-04-01 02:06:10,637 INFO org.apache.hadoop.yarn.server.resourcemanager.rmcontainer.RMContainerImpl: container_1396342005689_0005_01_000003 Container Transitioned from NEW to ALLOCATED
2014-04-01 02:06:10,637 INFO org.apache.hadoop.yarn.server.resourcemanager.RMAuditLogger: USER=hduser	OPERATION=AM Allocated Container	TARGET=SchedulerApp	RESULT=SUCCESS	APPID=application_1396342005689_0005	CONTAINERID=container_1396342005689_0005_01_000003
2014-04-01 02:06:10,637 INFO org.apache.hadoop.yarn.server.resourcemanager.scheduler.common.fica.FiCaSchedulerNode: Assigned container container_1396342005689_0005_01_000003 of capacity <memory:1024, vCores:1> on host ubuntu:38688, which currently has 2 containers, <memory:3072, vCores:2> used and <memory:5120, vCores:6> available
2014-04-01 02:06:10,637 INFO org.apache.hadoop.yarn.server.resourcemanager.scheduler.capacity.LeafQueue: assignedContainer application=application_1396342005689_0005 container=Container: [ContainerId: container_1396342005689_0005_01_000003, NodeId: ubuntu:38688, NodeHttpAddress: ubuntu:8042, Resource: <memory:1024, vCores:1>, Priority: 5, Token: Token { kind: ContainerToken, service: 127.0.1.1:38688 }, ] containerId=container_1396342005689_0005_01_000003 queue=default: capacity=1.0, absoluteCapacity=1.0, usedResources=<memory:2048, vCores:1>usedCapacity=0.25, absoluteUsedCapacity=0.25, numApps=1, numContainers=1 usedCapacity=0.25 absoluteUsedCapacity=0.25 used=<memory:2048, vCores:1> cluster=<memory:8192, vCores:8>
2014-04-01 02:06:10,637 INFO org.apache.hadoop.yarn.server.resourcemanager.scheduler.capacity.ParentQueue: Re-sorting assigned queue: root.default stats: default: capacity=1.0, absoluteCapacity=1.0, usedResources=<memory:3072, vCores:2>usedCapacity=0.375, absoluteUsedCapacity=0.375, numApps=1, numContainers=2
2014-04-01 02:06:10,637 INFO org.apache.hadoop.yarn.server.resourcemanager.scheduler.capacity.ParentQueue: assignedContainer queue=root usedCapacity=0.375 absoluteUsedCapacity=0.375 used=<memory:3072, vCores:2> cluster=<memory:8192, vCores:8>
2014-04-01 02:06:10,907 INFO org.apache.hadoop.yarn.server.resourcemanager.rmcontainer.RMContainerImpl: container_1396342005689_0005_01_000003 Container Transitioned from ALLOCATED to ACQUIRED
2014-04-01 02:06:11,637 INFO org.apache.hadoop.yarn.server.resourcemanager.rmcontainer.RMContainerImpl: container_1396342005689_0005_01_000003 Container Transitioned from ACQUIRED to RUNNING
2014-04-01 02:06:11,916 INFO org.apache.hadoop.yarn.server.resourcemanager.scheduler.AppSchedulingInfo: checking for deactivate... 
2014-04-01 02:06:13,576 INFO org.apache.hadoop.yarn.server.resourcemanager.rmcontainer.RMContainerImpl: container_1396342005689_0005_01_000003 Container Transitioned from RUNNING to COMPLETED
2014-04-01 02:06:13,577 INFO org.apache.hadoop.yarn.server.resourcemanager.scheduler.common.fica.FiCaSchedulerApp: Completed container: container_1396342005689_0005_01_000003 in state: COMPLETED event:FINISHED
2014-04-01 02:06:13,577 INFO org.apache.hadoop.yarn.server.resourcemanager.RMAuditLogger: USER=hduser	OPERATION=AM Released Container	TARGET=SchedulerApp	RESULT=SUCCESS	APPID=application_1396342005689_0005	CONTAINERID=container_1396342005689_0005_01_000003
2014-04-01 02:06:13,577 INFO org.apache.hadoop.yarn.server.resourcemanager.scheduler.common.fica.FiCaSchedulerNode: Released container container_1396342005689_0005_01_000003 of capacity <memory:1024, vCores:1> on host ubuntu:38688, which currently has 1 containers, <memory:2048, vCores:1> used and <memory:6144, vCores:7> available, release resources=true
2014-04-01 02:06:13,577 INFO org.apache.hadoop.yarn.server.resourcemanager.scheduler.capacity.LeafQueue: default used=<memory:2048, vCores:1> numContainers=1 user=hduser user-resources=<memory:2048, vCores:1>
2014-04-01 02:06:13,577 INFO org.apache.hadoop.yarn.server.resourcemanager.scheduler.capacity.LeafQueue: completedContainer container=Container: [ContainerId: container_1396342005689_0005_01_000003, NodeId: ubuntu:38688, NodeHttpAddress: ubuntu:8042, Resource: <memory:1024, vCores:1>, Priority: 5, Token: Token { kind: ContainerToken, service: 127.0.1.1:38688 }, ] resource=<memory:1024, vCores:1> queue=default: capacity=1.0, absoluteCapacity=1.0, usedResources=<memory:2048, vCores:1>usedCapacity=0.25, absoluteUsedCapacity=0.25, numApps=1, numContainers=1 usedCapacity=0.25 absoluteUsedCapacity=0.25 used=<memory:2048, vCores:1> cluster=<memory:8192, vCores:8>
2014-04-01 02:06:13,577 INFO org.apache.hadoop.yarn.server.resourcemanager.scheduler.capacity.ParentQueue: completedContainer queue=root usedCapacity=0.25 absoluteUsedCapacity=0.25 used=<memory:2048, vCores:1> cluster=<memory:8192, vCores:8>
2014-04-01 02:06:13,577 INFO org.apache.hadoop.yarn.server.resourcemanager.scheduler.capacity.ParentQueue: Re-sorting completed queue: root.default stats: default: capacity=1.0, absoluteCapacity=1.0, usedResources=<memory:2048, vCores:1>usedCapacity=0.25, absoluteUsedCapacity=0.25, numApps=1, numContainers=1
2014-04-01 02:06:13,577 INFO org.apache.hadoop.yarn.server.resourcemanager.scheduler.capacity.CapacityScheduler: Application appattempt_1396342005689_0005_000001 released container container_1396342005689_0005_01_000003 on node: host: ubuntu:38688 #containers=1 available=6144 used=2048 with event: FINISHED
2014-04-01 02:06:13,578 INFO org.apache.hadoop.yarn.server.resourcemanager.rmcontainer.RMContainerImpl: container_1396342005689_0005_01_000004 Container Transitioned from NEW to ALLOCATED
2014-04-01 02:06:13,578 INFO org.apache.hadoop.yarn.server.resourcemanager.RMAuditLogger: USER=hduser	OPERATION=AM Allocated Container	TARGET=SchedulerApp	RESULT=SUCCESS	APPID=application_1396342005689_0005	CONTAINERID=container_1396342005689_0005_01_000004
2014-04-01 02:06:13,578 INFO org.apache.hadoop.yarn.server.resourcemanager.scheduler.common.fica.FiCaSchedulerNode: Assigned container container_1396342005689_0005_01_000004 of capacity <memory:1024, vCores:1> on host ubuntu:38688, which currently has 2 containers, <memory:3072, vCores:2> used and <memory:5120, vCores:6> available
2014-04-01 02:06:13,578 INFO org.apache.hadoop.yarn.server.resourcemanager.scheduler.capacity.LeafQueue: assignedContainer application=application_1396342005689_0005 container=Container: [ContainerId: container_1396342005689_0005_01_000004, NodeId: ubuntu:38688, NodeHttpAddress: ubuntu:8042, Resource: <memory:1024, vCores:1>, Priority: 5, Token: Token { kind: ContainerToken, service: 127.0.1.1:38688 }, ] containerId=container_1396342005689_0005_01_000004 queue=default: capacity=1.0, absoluteCapacity=1.0, usedResources=<memory:2048, vCores:1>usedCapacity=0.25, absoluteUsedCapacity=0.25, numApps=1, numContainers=1 usedCapacity=0.25 absoluteUsedCapacity=0.25 used=<memory:2048, vCores:1> cluster=<memory:8192, vCores:8>
2014-04-01 02:06:13,578 INFO org.apache.hadoop.yarn.server.resourcemanager.scheduler.capacity.ParentQueue: Re-sorting assigned queue: root.default stats: default: capacity=1.0, absoluteCapacity=1.0, usedResources=<memory:3072, vCores:2>usedCapacity=0.375, absoluteUsedCapacity=0.375, numApps=1, numContainers=2
2014-04-01 02:06:13,578 INFO org.apache.hadoop.yarn.server.resourcemanager.scheduler.capacity.ParentQueue: assignedContainer queue=root usedCapacity=0.375 absoluteUsedCapacity=0.375 used=<memory:3072, vCores:2> cluster=<memory:8192, vCores:8>
2014-04-01 02:06:13,923 INFO org.apache.hadoop.yarn.server.resourcemanager.rmcontainer.RMContainerImpl: container_1396342005689_0005_01_000004 Container Transitioned from ALLOCATED to ACQUIRED
2014-04-01 02:06:14,578 INFO org.apache.hadoop.yarn.server.resourcemanager.rmcontainer.RMContainerImpl: container_1396342005689_0005_01_000004 Container Transitioned from ACQUIRED to RUNNING
2014-04-01 02:06:14,928 INFO org.apache.hadoop.yarn.server.resourcemanager.scheduler.AppSchedulingInfo: checking for deactivate... 
2014-04-01 02:06:16,583 INFO org.apache.hadoop.yarn.server.resourcemanager.rmcontainer.RMContainerImpl: container_1396342005689_0005_01_000004 Container Transitioned from RUNNING to COMPLETED
2014-04-01 02:06:16,583 INFO org.apache.hadoop.yarn.server.resourcemanager.scheduler.common.fica.FiCaSchedulerApp: Completed container: container_1396342005689_0005_01_000004 in state: COMPLETED event:FINISHED
2014-04-01 02:06:16,584 INFO org.apache.hadoop.yarn.server.resourcemanager.RMAuditLogger: USER=hduser	OPERATION=AM Released Container	TARGET=SchedulerApp	RESULT=SUCCESS	APPID=application_1396342005689_0005	CONTAINERID=container_1396342005689_0005_01_000004
2014-04-01 02:06:16,584 INFO org.apache.hadoop.yarn.server.resourcemanager.scheduler.common.fica.FiCaSchedulerNode: Released container container_1396342005689_0005_01_000004 of capacity <memory:1024, vCores:1> on host ubuntu:38688, which currently has 1 containers, <memory:2048, vCores:1> used and <memory:6144, vCores:7> available, release resources=true
2014-04-01 02:06:16,584 INFO org.apache.hadoop.yarn.server.resourcemanager.scheduler.capacity.LeafQueue: default used=<memory:2048, vCores:1> numContainers=1 user=hduser user-resources=<memory:2048, vCores:1>
2014-04-01 02:06:16,584 INFO org.apache.hadoop.yarn.server.resourcemanager.scheduler.capacity.LeafQueue: completedContainer container=Container: [ContainerId: container_1396342005689_0005_01_000004, NodeId: ubuntu:38688, NodeHttpAddress: ubuntu:8042, Resource: <memory:1024, vCores:1>, Priority: 5, Token: Token { kind: ContainerToken, service: 127.0.1.1:38688 }, ] resource=<memory:1024, vCores:1> queue=default: capacity=1.0, absoluteCapacity=1.0, usedResources=<memory:2048, vCores:1>usedCapacity=0.25, absoluteUsedCapacity=0.25, numApps=1, numContainers=1 usedCapacity=0.25 absoluteUsedCapacity=0.25 used=<memory:2048, vCores:1> cluster=<memory:8192, vCores:8>
2014-04-01 02:06:16,584 INFO org.apache.hadoop.yarn.server.resourcemanager.scheduler.capacity.ParentQueue: completedContainer queue=root usedCapacity=0.25 absoluteUsedCapacity=0.25 used=<memory:2048, vCores:1> cluster=<memory:8192, vCores:8>
2014-04-01 02:06:16,584 INFO org.apache.hadoop.yarn.server.resourcemanager.scheduler.capacity.ParentQueue: Re-sorting completed queue: root.default stats: default: capacity=1.0, absoluteCapacity=1.0, usedResources=<memory:2048, vCores:1>usedCapacity=0.25, absoluteUsedCapacity=0.25, numApps=1, numContainers=1
2014-04-01 02:06:16,584 INFO org.apache.hadoop.yarn.server.resourcemanager.scheduler.capacity.CapacityScheduler: Application appattempt_1396342005689_0005_000001 released container container_1396342005689_0005_01_000004 on node: host: ubuntu:38688 #containers=1 available=6144 used=2048 with event: FINISHED
2014-04-01 02:06:17,588 INFO org.apache.hadoop.yarn.server.resourcemanager.rmcontainer.RMContainerImpl: container_1396342005689_0005_01_000005 Container Transitioned from NEW to ALLOCATED
2014-04-01 02:06:17,588 INFO org.apache.hadoop.yarn.server.resourcemanager.RMAuditLogger: USER=hduser	OPERATION=AM Allocated Container	TARGET=SchedulerApp	RESULT=SUCCESS	APPID=application_1396342005689_0005	CONTAINERID=container_1396342005689_0005_01_000005
2014-04-01 02:06:17,588 INFO org.apache.hadoop.yarn.server.resourcemanager.scheduler.common.fica.FiCaSchedulerNode: Assigned container container_1396342005689_0005_01_000005 of capacity <memory:1024, vCores:1> on host ubuntu:38688, which currently has 2 containers, <memory:3072, vCores:2> used and <memory:5120, vCores:6> available
2014-04-01 02:06:17,588 INFO org.apache.hadoop.yarn.server.resourcemanager.scheduler.capacity.LeafQueue: assignedContainer application=application_1396342005689_0005 container=Container: [ContainerId: container_1396342005689_0005_01_000005, NodeId: ubuntu:38688, NodeHttpAddress: ubuntu:8042, Resource: <memory:1024, vCores:1>, Priority: 5, Token: Token { kind: ContainerToken, service: 127.0.1.1:38688 }, ] containerId=container_1396342005689_0005_01_000005 queue=default: capacity=1.0, absoluteCapacity=1.0, usedResources=<memory:2048, vCores:1>usedCapacity=0.25, absoluteUsedCapacity=0.25, numApps=1, numContainers=1 usedCapacity=0.25 absoluteUsedCapacity=0.25 used=<memory:2048, vCores:1> cluster=<memory:8192, vCores:8>
2014-04-01 02:06:17,588 INFO org.apache.hadoop.yarn.server.resourcemanager.scheduler.capacity.ParentQueue: Re-sorting assigned queue: root.default stats: default: capacity=1.0, absoluteCapacity=1.0, usedResources=<memory:3072, vCores:2>usedCapacity=0.375, absoluteUsedCapacity=0.375, numApps=1, numContainers=2
2014-04-01 02:06:17,588 INFO org.apache.hadoop.yarn.server.resourcemanager.scheduler.capacity.ParentQueue: assignedContainer queue=root usedCapacity=0.375 absoluteUsedCapacity=0.375 used=<memory:3072, vCores:2> cluster=<memory:8192, vCores:8>
2014-04-01 02:06:17,941 INFO org.apache.hadoop.yarn.server.resourcemanager.rmcontainer.RMContainerImpl: container_1396342005689_0005_01_000005 Container Transitioned from ALLOCATED to ACQUIRED
2014-04-01 02:06:18,589 INFO org.apache.hadoop.yarn.server.resourcemanager.rmcontainer.RMContainerImpl: container_1396342005689_0005_01_000005 Container Transitioned from ACQUIRED to RUNNING
2014-04-01 02:06:18,945 INFO org.apache.hadoop.yarn.server.resourcemanager.scheduler.AppSchedulingInfo: checking for deactivate... 
2014-04-01 02:06:19,605 INFO org.apache.hadoop.yarn.server.resourcemanager.rmapp.attempt.RMAppAttemptImpl: appattempt_1396342005689_0005_000001 State change from RUNNING to FINISHING
2014-04-01 02:06:19,605 INFO org.apache.hadoop.yarn.server.resourcemanager.rmapp.RMAppImpl: Removing application with id application_1396342005689_0005
2014-04-01 02:06:19,606 INFO org.apache.hadoop.yarn.server.resourcemanager.recovery.RMStateStore: Removing info for app: application_1396342005689_0005
2014-04-01 02:06:19,606 INFO org.apache.hadoop.yarn.server.resourcemanager.rmapp.RMAppImpl: application_1396342005689_0005 State change from RUNNING to REMOVING
2014-04-01 02:06:19,606 INFO org.apache.hadoop.yarn.server.resourcemanager.rmapp.RMAppImpl: application_1396342005689_0005 State change from REMOVING to FINISHING
2014-04-01 02:06:20,580 INFO org.apache.hadoop.yarn.server.resourcemanager.rmcontainer.RMContainerImpl: container_1396342005689_0005_01_000005 Container Transitioned from RUNNING to COMPLETED
2014-04-01 02:06:20,580 INFO org.apache.hadoop.yarn.server.resourcemanager.scheduler.common.fica.FiCaSchedulerApp: Completed container: container_1396342005689_0005_01_000005 in state: COMPLETED event:FINISHED
2014-04-01 02:06:20,580 INFO org.apache.hadoop.yarn.server.resourcemanager.RMAuditLogger: USER=hduser	OPERATION=AM Released Container	TARGET=SchedulerApp	RESULT=SUCCESS	APPID=application_1396342005689_0005	CONTAINERID=container_1396342005689_0005_01_000005
2014-04-01 02:06:20,580 INFO org.apache.hadoop.yarn.server.resourcemanager.scheduler.common.fica.FiCaSchedulerNode: Released container container_1396342005689_0005_01_000005 of capacity <memory:1024, vCores:1> on host ubuntu:38688, which currently has 1 containers, <memory:2048, vCores:1> used and <memory:6144, vCores:7> available, release resources=true
2014-04-01 02:06:20,580 INFO org.apache.hadoop.yarn.server.resourcemanager.scheduler.capacity.LeafQueue: default used=<memory:2048, vCores:1> numContainers=1 user=hduser user-resources=<memory:2048, vCores:1>
2014-04-01 02:06:20,580 INFO org.apache.hadoop.yarn.server.resourcemanager.scheduler.capacity.LeafQueue: completedContainer container=Container: [ContainerId: container_1396342005689_0005_01_000005, NodeId: ubuntu:38688, NodeHttpAddress: ubuntu:8042, Resource: <memory:1024, vCores:1>, Priority: 5, Token: Token { kind: ContainerToken, service: 127.0.1.1:38688 }, ] resource=<memory:1024, vCores:1> queue=default: capacity=1.0, absoluteCapacity=1.0, usedResources=<memory:2048, vCores:1>usedCapacity=0.25, absoluteUsedCapacity=0.25, numApps=1, numContainers=1 usedCapacity=0.25 absoluteUsedCapacity=0.25 used=<memory:2048, vCores:1> cluster=<memory:8192, vCores:8>
2014-04-01 02:06:20,580 INFO org.apache.hadoop.yarn.server.resourcemanager.scheduler.capacity.ParentQueue: completedContainer queue=root usedCapacity=0.25 absoluteUsedCapacity=0.25 used=<memory:2048, vCores:1> cluster=<memory:8192, vCores:8>
2014-04-01 02:06:20,581 INFO org.apache.hadoop.yarn.server.resourcemanager.scheduler.capacity.ParentQueue: Re-sorting completed queue: root.default stats: default: capacity=1.0, absoluteCapacity=1.0, usedResources=<memory:2048, vCores:1>usedCapacity=0.25, absoluteUsedCapacity=0.25, numApps=1, numContainers=1
2014-04-01 02:06:20,581 INFO org.apache.hadoop.yarn.server.resourcemanager.scheduler.capacity.CapacityScheduler: Application appattempt_1396342005689_0005_000001 released container container_1396342005689_0005_01_000005 on node: host: ubuntu:38688 #containers=1 available=6144 used=2048 with event: FINISHED
2014-04-01 02:06:21,582 INFO org.apache.hadoop.yarn.server.resourcemanager.ApplicationMasterService: Unregistering app attempt : appattempt_1396342005689_0005_000001
2014-04-01 02:06:21,583 INFO org.apache.hadoop.yarn.server.resourcemanager.rmapp.attempt.RMAppAttemptImpl: appattempt_1396342005689_0005_000001 State change from FINISHING to FINISHED
2014-04-01 02:06:21,583 INFO org.apache.hadoop.yarn.server.resourcemanager.rmapp.RMAppImpl: application_1396342005689_0005 State change from FINISHING to FINISHED
2014-04-01 02:06:21,583 INFO org.apache.hadoop.yarn.server.resourcemanager.RMAuditLogger: USER=hduser	OPERATION=Application Finished - Succeeded	TARGET=RMAppManager	RESULT=SUCCESS	APPID=application_1396342005689_0005
2014-04-01 02:06:21,583 INFO org.apache.hadoop.yarn.server.resourcemanager.RMAppManager$ApplicationSummary: appId=application_1396342005689_0005,name=base||path:/in||num reduce:8,user=hduser,queue=default,state=FINISHED,trackingUrl=ubuntu:8088/proxy/application_1396342005689_0005/jobhistory/job/job_1396342005689_0005,appMasterHost=ubuntu,startTime=1396343162721,finishTime=1396343179606,finalStatus=FAILED
2014-04-01 02:06:21,582 INFO org.apache.hadoop.yarn.server.resourcemanager.rmcontainer.RMContainerImpl: container_1396342005689_0005_01_000001 Container Transitioned from RUNNING to COMPLETED
2014-04-01 02:06:21,589 INFO org.apache.hadoop.yarn.server.resourcemanager.amlauncher.AMLauncher: Cleaning master appattempt_1396342005689_0005_000001
2014-04-01 02:06:21,589 INFO org.apache.hadoop.yarn.server.resourcemanager.scheduler.common.fica.FiCaSchedulerApp: Completed container: container_1396342005689_0005_01_000001 in state: COMPLETED event:FINISHED
2014-04-01 02:06:21,590 INFO org.apache.hadoop.yarn.server.resourcemanager.RMAuditLogger: USER=hduser	OPERATION=AM Released Container	TARGET=SchedulerApp	RESULT=SUCCESS	APPID=application_1396342005689_0005	CONTAINERID=container_1396342005689_0005_01_000001
2014-04-01 02:06:21,590 INFO org.apache.hadoop.yarn.server.resourcemanager.scheduler.common.fica.FiCaSchedulerNode: Released container container_1396342005689_0005_01_000001 of capacity <memory:2048, vCores:1> on host ubuntu:38688, which currently has 0 containers, <memory:0, vCores:0> used and <memory:8192, vCores:8> available, release resources=true
2014-04-01 02:06:21,590 INFO org.apache.hadoop.yarn.server.resourcemanager.scheduler.capacity.LeafQueue: default used=<memory:0, vCores:0> numContainers=0 user=hduser user-resources=<memory:0, vCores:0>
2014-04-01 02:06:21,590 INFO org.apache.hadoop.yarn.server.resourcemanager.scheduler.capacity.LeafQueue: completedContainer container=Container: [ContainerId: container_1396342005689_0005_01_000001, NodeId: ubuntu:38688, NodeHttpAddress: ubuntu:8042, Resource: <memory:2048, vCores:1>, Priority: 0, Token: Token { kind: ContainerToken, service: 127.0.1.1:38688 }, ] resource=<memory:2048, vCores:1> queue=default: capacity=1.0, absoluteCapacity=1.0, usedResources=<memory:0, vCores:0>usedCapacity=0.0, absoluteUsedCapacity=0.0, numApps=1, numContainers=0 usedCapacity=0.0 absoluteUsedCapacity=0.0 used=<memory:0, vCores:0> cluster=<memory:8192, vCores:8>
2014-04-01 02:06:21,590 INFO org.apache.hadoop.yarn.server.resourcemanager.scheduler.capacity.ParentQueue: completedContainer queue=root usedCapacity=0.0 absoluteUsedCapacity=0.0 used=<memory:0, vCores:0> cluster=<memory:8192, vCores:8>
2014-04-01 02:06:21,590 INFO org.apache.hadoop.yarn.server.resourcemanager.scheduler.capacity.ParentQueue: Re-sorting completed queue: root.default stats: default: capacity=1.0, absoluteCapacity=1.0, usedResources=<memory:0, vCores:0>usedCapacity=0.0, absoluteUsedCapacity=0.0, numApps=1, numContainers=0
2014-04-01 02:06:21,590 INFO org.apache.hadoop.yarn.server.resourcemanager.scheduler.capacity.CapacityScheduler: Application appattempt_1396342005689_0005_000001 released container container_1396342005689_0005_01_000001 on node: host: ubuntu:38688 #containers=0 available=8192 used=0 with event: FINISHED
2014-04-01 02:06:21,590 INFO org.apache.hadoop.yarn.server.resourcemanager.scheduler.capacity.CapacityScheduler: Application appattempt_1396342005689_0005_000001 is done. finalState=FINISHED
2014-04-01 02:06:21,590 INFO org.apache.hadoop.yarn.server.resourcemanager.scheduler.AppSchedulingInfo: Application application_1396342005689_0005 requests cleared
2014-04-01 02:06:21,590 INFO org.apache.hadoop.yarn.server.resourcemanager.scheduler.capacity.LeafQueue: Application removed - appId: application_1396342005689_0005 user: hduser queue: default #user-pending-applications: 0 #user-active-applications: 0 #queue-pending-applications: 0 #queue-active-applications: 0
2014-04-01 02:06:21,590 INFO org.apache.hadoop.yarn.server.resourcemanager.scheduler.capacity.ParentQueue: Application removed - appId: application_1396342005689_0005 user: hduser leaf-queue of parent: root #applications: 0
2014-04-01 02:12:21,337 INFO org.apache.hadoop.yarn.server.resourcemanager.ClientRMService: Allocated new applicationId: 6
2014-04-01 02:12:21,969 INFO org.apache.hadoop.yarn.server.resourcemanager.ClientRMService: Application with id 6 submitted by user hduser
2014-04-01 02:12:21,969 INFO org.apache.hadoop.yarn.server.resourcemanager.RMAuditLogger: USER=hduser	IP=127.0.0.1	OPERATION=Submit Application Request	TARGET=ClientRMService	RESULT=SUCCESS	APPID=application_1396342005689_0006
2014-04-01 02:12:21,969 INFO org.apache.hadoop.yarn.server.resourcemanager.rmapp.RMAppImpl: Storing application with id application_1396342005689_0006
2014-04-01 02:12:21,969 INFO org.apache.hadoop.yarn.server.resourcemanager.rmapp.RMAppImpl: application_1396342005689_0006 State change from NEW to NEW_SAVING
2014-04-01 02:12:21,969 INFO org.apache.hadoop.yarn.server.resourcemanager.recovery.RMStateStore: Storing info for app: application_1396342005689_0006
2014-04-01 02:12:21,970 INFO org.apache.hadoop.yarn.server.resourcemanager.rmapp.RMAppImpl: application_1396342005689_0006 State change from NEW_SAVING to SUBMITTED
2014-04-01 02:12:21,970 INFO org.apache.hadoop.yarn.server.resourcemanager.ApplicationMasterService: Registering app attempt : appattempt_1396342005689_0006_000001
2014-04-01 02:12:21,970 INFO org.apache.hadoop.yarn.server.resourcemanager.rmapp.attempt.RMAppAttemptImpl: appattempt_1396342005689_0006_000001 State change from NEW to SUBMITTED
2014-04-01 02:12:21,970 INFO org.apache.hadoop.yarn.server.resourcemanager.scheduler.capacity.LeafQueue: Application application_1396342005689_0006 from user: hduser activated in queue: default
2014-04-01 02:12:21,970 INFO org.apache.hadoop.yarn.server.resourcemanager.scheduler.capacity.LeafQueue: Application added - appId: application_1396342005689_0006 user: org.apache.hadoop.yarn.server.resourcemanager.scheduler.capacity.LeafQueue$User@e8518c, leaf-queue: default #user-pending-applications: 0 #user-active-applications: 1 #queue-pending-applications: 0 #queue-active-applications: 1
2014-04-01 02:12:21,970 INFO org.apache.hadoop.yarn.server.resourcemanager.scheduler.capacity.ParentQueue: Application added - appId: application_1396342005689_0006 user: hduser leaf-queue of parent: root #applications: 1
2014-04-01 02:12:21,971 INFO org.apache.hadoop.yarn.server.resourcemanager.scheduler.capacity.CapacityScheduler: Application Submission: appattempt_1396342005689_0006_000001, user: hduser queue: default: capacity=1.0, absoluteCapacity=1.0, usedResources=<memory:0, vCores:0>usedCapacity=0.0, absoluteUsedCapacity=0.0, numApps=1, numContainers=0, currently active: 1
2014-04-01 02:12:21,971 INFO org.apache.hadoop.yarn.server.resourcemanager.rmapp.attempt.RMAppAttemptImpl: appattempt_1396342005689_0006_000001 State change from SUBMITTED to SCHEDULED
2014-04-01 02:12:21,971 INFO org.apache.hadoop.yarn.server.resourcemanager.rmapp.RMAppImpl: application_1396342005689_0006 State change from SUBMITTED to ACCEPTED
2014-04-01 02:12:22,497 INFO org.apache.hadoop.yarn.server.resourcemanager.rmcontainer.RMContainerImpl: container_1396342005689_0006_01_000001 Container Transitioned from NEW to ALLOCATED
2014-04-01 02:12:22,498 INFO org.apache.hadoop.yarn.server.resourcemanager.RMAuditLogger: USER=hduser	OPERATION=AM Allocated Container	TARGET=SchedulerApp	RESULT=SUCCESS	APPID=application_1396342005689_0006	CONTAINERID=container_1396342005689_0006_01_000001
2014-04-01 02:12:22,498 INFO org.apache.hadoop.yarn.server.resourcemanager.scheduler.common.fica.FiCaSchedulerNode: Assigned container container_1396342005689_0006_01_000001 of capacity <memory:2048, vCores:1> on host ubuntu:38688, which currently has 1 containers, <memory:2048, vCores:1> used and <memory:6144, vCores:7> available
2014-04-01 02:12:22,498 INFO org.apache.hadoop.yarn.server.resourcemanager.scheduler.capacity.LeafQueue: assignedContainer application=application_1396342005689_0006 container=Container: [ContainerId: container_1396342005689_0006_01_000001, NodeId: ubuntu:38688, NodeHttpAddress: ubuntu:8042, Resource: <memory:2048, vCores:1>, Priority: 0, Token: Token { kind: ContainerToken, service: 127.0.1.1:38688 }, ] containerId=container_1396342005689_0006_01_000001 queue=default: capacity=1.0, absoluteCapacity=1.0, usedResources=<memory:0, vCores:0>usedCapacity=0.0, absoluteUsedCapacity=0.0, numApps=1, numContainers=0 usedCapacity=0.0 absoluteUsedCapacity=0.0 used=<memory:0, vCores:0> cluster=<memory:8192, vCores:8>
2014-04-01 02:12:22,498 INFO org.apache.hadoop.yarn.server.resourcemanager.scheduler.capacity.ParentQueue: Re-sorting assigned queue: root.default stats: default: capacity=1.0, absoluteCapacity=1.0, usedResources=<memory:2048, vCores:1>usedCapacity=0.25, absoluteUsedCapacity=0.25, numApps=1, numContainers=1
2014-04-01 02:12:22,498 INFO org.apache.hadoop.yarn.server.resourcemanager.scheduler.capacity.ParentQueue: assignedContainer queue=root usedCapacity=0.25 absoluteUsedCapacity=0.25 used=<memory:2048, vCores:1> cluster=<memory:8192, vCores:8>
2014-04-01 02:12:22,499 INFO org.apache.hadoop.yarn.server.resourcemanager.rmcontainer.RMContainerImpl: container_1396342005689_0006_01_000001 Container Transitioned from ALLOCATED to ACQUIRED
2014-04-01 02:12:22,499 INFO org.apache.hadoop.yarn.server.resourcemanager.rmapp.attempt.RMAppAttemptImpl: Storing attempt: AppId: application_1396342005689_0006 AttemptId: appattempt_1396342005689_0006_000001 MasterContainer: Container: [ContainerId: container_1396342005689_0006_01_000001, NodeId: ubuntu:38688, NodeHttpAddress: ubuntu:8042, Resource: <memory:2048, vCores:1>, Priority: 0, Token: Token { kind: ContainerToken, service: 127.0.1.1:38688 }, ]
2014-04-01 02:12:22,499 INFO org.apache.hadoop.yarn.server.resourcemanager.rmapp.attempt.RMAppAttemptImpl: appattempt_1396342005689_0006_000001 State change from SCHEDULED to ALLOCATED_SAVING
2014-04-01 02:12:22,500 INFO org.apache.hadoop.yarn.server.resourcemanager.recovery.RMStateStore: Storing info for attempt: appattempt_1396342005689_0006_000001
2014-04-01 02:12:22,500 INFO org.apache.hadoop.yarn.server.resourcemanager.rmapp.attempt.RMAppAttemptImpl: appattempt_1396342005689_0006_000001 State change from ALLOCATED_SAVING to ALLOCATED
2014-04-01 02:12:22,500 INFO org.apache.hadoop.yarn.server.resourcemanager.amlauncher.AMLauncher: Launching masterappattempt_1396342005689_0006_000001
2014-04-01 02:12:22,501 INFO org.apache.hadoop.yarn.server.resourcemanager.amlauncher.AMLauncher: Setting up container Container: [ContainerId: container_1396342005689_0006_01_000001, NodeId: ubuntu:38688, NodeHttpAddress: ubuntu:8042, Resource: <memory:2048, vCores:1>, Priority: 0, Token: Token { kind: ContainerToken, service: 127.0.1.1:38688 }, ] for AM appattempt_1396342005689_0006_000001
2014-04-01 02:12:22,502 INFO org.apache.hadoop.yarn.server.resourcemanager.amlauncher.AMLauncher: Command to launch container container_1396342005689_0006_01_000001 : $JAVA_HOME/bin/java -Dlog4j.configuration=container-log4j.properties -Dyarn.app.container.log.dir=<LOG_DIR> -Dyarn.app.container.log.filesize=0 -Dhadoop.root.logger=INFO,CLA  -Xmx1024m org.apache.hadoop.mapreduce.v2.app.MRAppMaster 1><LOG_DIR>/stdout 2><LOG_DIR>/stderr 
2014-04-01 02:12:22,510 INFO org.apache.hadoop.yarn.server.resourcemanager.amlauncher.AMLauncher: Done launching container Container: [ContainerId: container_1396342005689_0006_01_000001, NodeId: ubuntu:38688, NodeHttpAddress: ubuntu:8042, Resource: <memory:2048, vCores:1>, Priority: 0, Token: Token { kind: ContainerToken, service: 127.0.1.1:38688 }, ] for AM appattempt_1396342005689_0006_000001
2014-04-01 02:12:22,510 INFO org.apache.hadoop.yarn.server.resourcemanager.rmapp.attempt.RMAppAttemptImpl: appattempt_1396342005689_0006_000001 State change from ALLOCATED to LAUNCHED
2014-04-01 02:12:23,499 INFO org.apache.hadoop.yarn.server.resourcemanager.rmcontainer.RMContainerImpl: container_1396342005689_0006_01_000001 Container Transitioned from ACQUIRED to RUNNING
2014-04-01 02:12:25,028 INFO SecurityLogger.org.apache.hadoop.ipc.Server: Auth successful for appattempt_1396342005689_0006_000001 (auth:SIMPLE)
2014-04-01 02:12:25,031 INFO org.apache.hadoop.yarn.server.resourcemanager.ApplicationMasterService: AM registration appattempt_1396342005689_0006_000001
2014-04-01 02:12:25,031 INFO org.apache.hadoop.yarn.server.resourcemanager.RMAuditLogger: USER=hduser	IP=127.0.0.1	OPERATION=Register App Master	TARGET=ApplicationMasterService	RESULT=SUCCESS	APPID=application_1396342005689_0006	APPATTEMPTID=appattempt_1396342005689_0006_000001
2014-04-01 02:12:25,032 INFO org.apache.hadoop.yarn.server.resourcemanager.rmapp.attempt.RMAppAttemptImpl: appattempt_1396342005689_0006_000001 State change from LAUNCHED to RUNNING
2014-04-01 02:12:25,032 INFO org.apache.hadoop.yarn.server.resourcemanager.rmapp.RMAppImpl: application_1396342005689_0006 State change from ACCEPTED to RUNNING
2014-04-01 02:12:26,508 INFO org.apache.hadoop.yarn.server.resourcemanager.rmcontainer.RMContainerImpl: container_1396342005689_0006_01_000002 Container Transitioned from NEW to ALLOCATED
2014-04-01 02:12:26,508 INFO org.apache.hadoop.yarn.server.resourcemanager.RMAuditLogger: USER=hduser	OPERATION=AM Allocated Container	TARGET=SchedulerApp	RESULT=SUCCESS	APPID=application_1396342005689_0006	CONTAINERID=container_1396342005689_0006_01_000002
2014-04-01 02:12:26,508 INFO org.apache.hadoop.yarn.server.resourcemanager.scheduler.common.fica.FiCaSchedulerNode: Assigned container container_1396342005689_0006_01_000002 of capacity <memory:1024, vCores:1> on host ubuntu:38688, which currently has 2 containers, <memory:3072, vCores:2> used and <memory:5120, vCores:6> available
2014-04-01 02:12:26,508 INFO org.apache.hadoop.yarn.server.resourcemanager.scheduler.capacity.LeafQueue: assignedContainer application=application_1396342005689_0006 container=Container: [ContainerId: container_1396342005689_0006_01_000002, NodeId: ubuntu:38688, NodeHttpAddress: ubuntu:8042, Resource: <memory:1024, vCores:1>, Priority: 20, Token: Token { kind: ContainerToken, service: 127.0.1.1:38688 }, ] containerId=container_1396342005689_0006_01_000002 queue=default: capacity=1.0, absoluteCapacity=1.0, usedResources=<memory:2048, vCores:1>usedCapacity=0.25, absoluteUsedCapacity=0.25, numApps=1, numContainers=1 usedCapacity=0.25 absoluteUsedCapacity=0.25 used=<memory:2048, vCores:1> cluster=<memory:8192, vCores:8>
2014-04-01 02:12:26,508 INFO org.apache.hadoop.yarn.server.resourcemanager.scheduler.capacity.ParentQueue: Re-sorting assigned queue: root.default stats: default: capacity=1.0, absoluteCapacity=1.0, usedResources=<memory:3072, vCores:2>usedCapacity=0.375, absoluteUsedCapacity=0.375, numApps=1, numContainers=2
2014-04-01 02:12:26,508 INFO org.apache.hadoop.yarn.server.resourcemanager.scheduler.capacity.ParentQueue: assignedContainer queue=root usedCapacity=0.375 absoluteUsedCapacity=0.375 used=<memory:3072, vCores:2> cluster=<memory:8192, vCores:8>
2014-04-01 02:12:27,066 INFO org.apache.hadoop.yarn.server.resourcemanager.rmcontainer.RMContainerImpl: container_1396342005689_0006_01_000002 Container Transitioned from ALLOCATED to ACQUIRED
2014-04-01 02:12:27,509 INFO org.apache.hadoop.yarn.server.resourcemanager.rmcontainer.RMContainerImpl: container_1396342005689_0006_01_000002 Container Transitioned from ACQUIRED to RUNNING
2014-04-01 02:12:28,076 INFO org.apache.hadoop.yarn.server.resourcemanager.scheduler.AppSchedulingInfo: checking for deactivate... 
2014-04-01 02:12:29,938 INFO org.apache.hadoop.yarn.server.resourcemanager.rmcontainer.RMContainerImpl: container_1396342005689_0006_01_000002 Container Transitioned from RUNNING to COMPLETED
2014-04-01 02:12:29,939 INFO org.apache.hadoop.yarn.server.resourcemanager.scheduler.common.fica.FiCaSchedulerApp: Completed container: container_1396342005689_0006_01_000002 in state: COMPLETED event:FINISHED
2014-04-01 02:12:29,939 INFO org.apache.hadoop.yarn.server.resourcemanager.RMAuditLogger: USER=hduser	OPERATION=AM Released Container	TARGET=SchedulerApp	RESULT=SUCCESS	APPID=application_1396342005689_0006	CONTAINERID=container_1396342005689_0006_01_000002
2014-04-01 02:12:29,939 INFO org.apache.hadoop.yarn.server.resourcemanager.scheduler.common.fica.FiCaSchedulerNode: Released container container_1396342005689_0006_01_000002 of capacity <memory:1024, vCores:1> on host ubuntu:38688, which currently has 1 containers, <memory:2048, vCores:1> used and <memory:6144, vCores:7> available, release resources=true
2014-04-01 02:12:29,939 INFO org.apache.hadoop.yarn.server.resourcemanager.scheduler.capacity.LeafQueue: default used=<memory:2048, vCores:1> numContainers=1 user=hduser user-resources=<memory:2048, vCores:1>
2014-04-01 02:12:29,939 INFO org.apache.hadoop.yarn.server.resourcemanager.scheduler.capacity.LeafQueue: completedContainer container=Container: [ContainerId: container_1396342005689_0006_01_000002, NodeId: ubuntu:38688, NodeHttpAddress: ubuntu:8042, Resource: <memory:1024, vCores:1>, Priority: 20, Token: Token { kind: ContainerToken, service: 127.0.1.1:38688 }, ] resource=<memory:1024, vCores:1> queue=default: capacity=1.0, absoluteCapacity=1.0, usedResources=<memory:2048, vCores:1>usedCapacity=0.25, absoluteUsedCapacity=0.25, numApps=1, numContainers=1 usedCapacity=0.25 absoluteUsedCapacity=0.25 used=<memory:2048, vCores:1> cluster=<memory:8192, vCores:8>
2014-04-01 02:12:29,939 INFO org.apache.hadoop.yarn.server.resourcemanager.scheduler.capacity.ParentQueue: completedContainer queue=root usedCapacity=0.25 absoluteUsedCapacity=0.25 used=<memory:2048, vCores:1> cluster=<memory:8192, vCores:8>
2014-04-01 02:12:29,939 INFO org.apache.hadoop.yarn.server.resourcemanager.scheduler.capacity.ParentQueue: Re-sorting completed queue: root.default stats: default: capacity=1.0, absoluteCapacity=1.0, usedResources=<memory:2048, vCores:1>usedCapacity=0.25, absoluteUsedCapacity=0.25, numApps=1, numContainers=1
2014-04-01 02:12:29,939 INFO org.apache.hadoop.yarn.server.resourcemanager.scheduler.capacity.CapacityScheduler: Application appattempt_1396342005689_0006_000001 released container container_1396342005689_0006_01_000002 on node: host: ubuntu:38688 #containers=1 available=6144 used=2048 with event: FINISHED
2014-04-01 02:12:29,940 INFO org.apache.hadoop.yarn.server.resourcemanager.rmcontainer.RMContainerImpl: container_1396342005689_0006_01_000003 Container Transitioned from NEW to ALLOCATED
2014-04-01 02:12:29,940 INFO org.apache.hadoop.yarn.server.resourcemanager.RMAuditLogger: USER=hduser	OPERATION=AM Allocated Container	TARGET=SchedulerApp	RESULT=SUCCESS	APPID=application_1396342005689_0006	CONTAINERID=container_1396342005689_0006_01_000003
2014-04-01 02:12:29,940 INFO org.apache.hadoop.yarn.server.resourcemanager.scheduler.common.fica.FiCaSchedulerNode: Assigned container container_1396342005689_0006_01_000003 of capacity <memory:1024, vCores:1> on host ubuntu:38688, which currently has 2 containers, <memory:3072, vCores:2> used and <memory:5120, vCores:6> available
2014-04-01 02:12:29,940 INFO org.apache.hadoop.yarn.server.resourcemanager.scheduler.capacity.LeafQueue: assignedContainer application=application_1396342005689_0006 container=Container: [ContainerId: container_1396342005689_0006_01_000003, NodeId: ubuntu:38688, NodeHttpAddress: ubuntu:8042, Resource: <memory:1024, vCores:1>, Priority: 5, Token: Token { kind: ContainerToken, service: 127.0.1.1:38688 }, ] containerId=container_1396342005689_0006_01_000003 queue=default: capacity=1.0, absoluteCapacity=1.0, usedResources=<memory:2048, vCores:1>usedCapacity=0.25, absoluteUsedCapacity=0.25, numApps=1, numContainers=1 usedCapacity=0.25 absoluteUsedCapacity=0.25 used=<memory:2048, vCores:1> cluster=<memory:8192, vCores:8>
2014-04-01 02:12:29,940 INFO org.apache.hadoop.yarn.server.resourcemanager.scheduler.capacity.ParentQueue: Re-sorting assigned queue: root.default stats: default: capacity=1.0, absoluteCapacity=1.0, usedResources=<memory:3072, vCores:2>usedCapacity=0.375, absoluteUsedCapacity=0.375, numApps=1, numContainers=2
2014-04-01 02:12:29,940 INFO org.apache.hadoop.yarn.server.resourcemanager.scheduler.capacity.ParentQueue: assignedContainer queue=root usedCapacity=0.375 absoluteUsedCapacity=0.375 used=<memory:3072, vCores:2> cluster=<memory:8192, vCores:8>
2014-04-01 02:12:30,085 INFO org.apache.hadoop.yarn.server.resourcemanager.rmcontainer.RMContainerImpl: container_1396342005689_0006_01_000003 Container Transitioned from ALLOCATED to ACQUIRED
2014-04-01 02:12:30,940 INFO org.apache.hadoop.yarn.server.resourcemanager.rmcontainer.RMContainerImpl: container_1396342005689_0006_01_000003 Container Transitioned from ACQUIRED to RUNNING
2014-04-01 02:12:31,094 INFO org.apache.hadoop.yarn.server.resourcemanager.scheduler.AppSchedulingInfo: checking for deactivate... 
2014-04-01 02:12:32,742 INFO org.apache.hadoop.yarn.server.resourcemanager.rmcontainer.RMContainerImpl: container_1396342005689_0006_01_000003 Container Transitioned from RUNNING to COMPLETED
2014-04-01 02:12:32,742 INFO org.apache.hadoop.yarn.server.resourcemanager.scheduler.common.fica.FiCaSchedulerApp: Completed container: container_1396342005689_0006_01_000003 in state: COMPLETED event:FINISHED
2014-04-01 02:12:32,742 INFO org.apache.hadoop.yarn.server.resourcemanager.RMAuditLogger: USER=hduser	OPERATION=AM Released Container	TARGET=SchedulerApp	RESULT=SUCCESS	APPID=application_1396342005689_0006	CONTAINERID=container_1396342005689_0006_01_000003
2014-04-01 02:12:32,742 INFO org.apache.hadoop.yarn.server.resourcemanager.scheduler.common.fica.FiCaSchedulerNode: Released container container_1396342005689_0006_01_000003 of capacity <memory:1024, vCores:1> on host ubuntu:38688, which currently has 1 containers, <memory:2048, vCores:1> used and <memory:6144, vCores:7> available, release resources=true
2014-04-01 02:12:32,742 INFO org.apache.hadoop.yarn.server.resourcemanager.scheduler.capacity.LeafQueue: default used=<memory:2048, vCores:1> numContainers=1 user=hduser user-resources=<memory:2048, vCores:1>
2014-04-01 02:12:32,743 INFO org.apache.hadoop.yarn.server.resourcemanager.scheduler.capacity.LeafQueue: completedContainer container=Container: [ContainerId: container_1396342005689_0006_01_000003, NodeId: ubuntu:38688, NodeHttpAddress: ubuntu:8042, Resource: <memory:1024, vCores:1>, Priority: 5, Token: Token { kind: ContainerToken, service: 127.0.1.1:38688 }, ] resource=<memory:1024, vCores:1> queue=default: capacity=1.0, absoluteCapacity=1.0, usedResources=<memory:2048, vCores:1>usedCapacity=0.25, absoluteUsedCapacity=0.25, numApps=1, numContainers=1 usedCapacity=0.25 absoluteUsedCapacity=0.25 used=<memory:2048, vCores:1> cluster=<memory:8192, vCores:8>
2014-04-01 02:12:32,743 INFO org.apache.hadoop.yarn.server.resourcemanager.scheduler.capacity.ParentQueue: completedContainer queue=root usedCapacity=0.25 absoluteUsedCapacity=0.25 used=<memory:2048, vCores:1> cluster=<memory:8192, vCores:8>
2014-04-01 02:12:32,743 INFO org.apache.hadoop.yarn.server.resourcemanager.scheduler.capacity.ParentQueue: Re-sorting completed queue: root.default stats: default: capacity=1.0, absoluteCapacity=1.0, usedResources=<memory:2048, vCores:1>usedCapacity=0.25, absoluteUsedCapacity=0.25, numApps=1, numContainers=1
2014-04-01 02:12:32,743 INFO org.apache.hadoop.yarn.server.resourcemanager.scheduler.capacity.CapacityScheduler: Application appattempt_1396342005689_0006_000001 released container container_1396342005689_0006_01_000003 on node: host: ubuntu:38688 #containers=1 available=6144 used=2048 with event: FINISHED
2014-04-01 02:12:32,743 INFO org.apache.hadoop.yarn.server.resourcemanager.rmcontainer.RMContainerImpl: container_1396342005689_0006_01_000004 Container Transitioned from NEW to ALLOCATED
2014-04-01 02:12:32,743 INFO org.apache.hadoop.yarn.server.resourcemanager.RMAuditLogger: USER=hduser	OPERATION=AM Allocated Container	TARGET=SchedulerApp	RESULT=SUCCESS	APPID=application_1396342005689_0006	CONTAINERID=container_1396342005689_0006_01_000004
2014-04-01 02:12:32,744 INFO org.apache.hadoop.yarn.server.resourcemanager.scheduler.common.fica.FiCaSchedulerNode: Assigned container container_1396342005689_0006_01_000004 of capacity <memory:1024, vCores:1> on host ubuntu:38688, which currently has 2 containers, <memory:3072, vCores:2> used and <memory:5120, vCores:6> available
2014-04-01 02:12:32,744 INFO org.apache.hadoop.yarn.server.resourcemanager.scheduler.capacity.LeafQueue: assignedContainer application=application_1396342005689_0006 container=Container: [ContainerId: container_1396342005689_0006_01_000004, NodeId: ubuntu:38688, NodeHttpAddress: ubuntu:8042, Resource: <memory:1024, vCores:1>, Priority: 5, Token: Token { kind: ContainerToken, service: 127.0.1.1:38688 }, ] containerId=container_1396342005689_0006_01_000004 queue=default: capacity=1.0, absoluteCapacity=1.0, usedResources=<memory:2048, vCores:1>usedCapacity=0.25, absoluteUsedCapacity=0.25, numApps=1, numContainers=1 usedCapacity=0.25 absoluteUsedCapacity=0.25 used=<memory:2048, vCores:1> cluster=<memory:8192, vCores:8>
2014-04-01 02:12:32,744 INFO org.apache.hadoop.yarn.server.resourcemanager.scheduler.capacity.ParentQueue: Re-sorting assigned queue: root.default stats: default: capacity=1.0, absoluteCapacity=1.0, usedResources=<memory:3072, vCores:2>usedCapacity=0.375, absoluteUsedCapacity=0.375, numApps=1, numContainers=2
2014-04-01 02:12:32,744 INFO org.apache.hadoop.yarn.server.resourcemanager.scheduler.capacity.ParentQueue: assignedContainer queue=root usedCapacity=0.375 absoluteUsedCapacity=0.375 used=<memory:3072, vCores:2> cluster=<memory:8192, vCores:8>
2014-04-01 02:12:33,103 INFO org.apache.hadoop.yarn.server.resourcemanager.rmcontainer.RMContainerImpl: container_1396342005689_0006_01_000004 Container Transitioned from ALLOCATED to ACQUIRED
2014-04-01 02:12:33,744 INFO org.apache.hadoop.yarn.server.resourcemanager.rmcontainer.RMContainerImpl: container_1396342005689_0006_01_000004 Container Transitioned from ACQUIRED to RUNNING
2014-04-01 02:12:34,110 INFO org.apache.hadoop.yarn.server.resourcemanager.scheduler.AppSchedulingInfo: checking for deactivate... 
2014-04-01 02:12:35,819 INFO org.apache.hadoop.yarn.server.resourcemanager.rmcontainer.RMContainerImpl: container_1396342005689_0006_01_000004 Container Transitioned from RUNNING to COMPLETED
2014-04-01 02:12:35,819 INFO org.apache.hadoop.yarn.server.resourcemanager.scheduler.common.fica.FiCaSchedulerApp: Completed container: container_1396342005689_0006_01_000004 in state: COMPLETED event:FINISHED
2014-04-01 02:12:35,819 INFO org.apache.hadoop.yarn.server.resourcemanager.RMAuditLogger: USER=hduser	OPERATION=AM Released Container	TARGET=SchedulerApp	RESULT=SUCCESS	APPID=application_1396342005689_0006	CONTAINERID=container_1396342005689_0006_01_000004
2014-04-01 02:12:35,819 INFO org.apache.hadoop.yarn.server.resourcemanager.scheduler.common.fica.FiCaSchedulerNode: Released container container_1396342005689_0006_01_000004 of capacity <memory:1024, vCores:1> on host ubuntu:38688, which currently has 1 containers, <memory:2048, vCores:1> used and <memory:6144, vCores:7> available, release resources=true
2014-04-01 02:12:35,819 INFO org.apache.hadoop.yarn.server.resourcemanager.scheduler.capacity.LeafQueue: default used=<memory:2048, vCores:1> numContainers=1 user=hduser user-resources=<memory:2048, vCores:1>
2014-04-01 02:12:35,820 INFO org.apache.hadoop.yarn.server.resourcemanager.scheduler.capacity.LeafQueue: completedContainer container=Container: [ContainerId: container_1396342005689_0006_01_000004, NodeId: ubuntu:38688, NodeHttpAddress: ubuntu:8042, Resource: <memory:1024, vCores:1>, Priority: 5, Token: Token { kind: ContainerToken, service: 127.0.1.1:38688 }, ] resource=<memory:1024, vCores:1> queue=default: capacity=1.0, absoluteCapacity=1.0, usedResources=<memory:2048, vCores:1>usedCapacity=0.25, absoluteUsedCapacity=0.25, numApps=1, numContainers=1 usedCapacity=0.25 absoluteUsedCapacity=0.25 used=<memory:2048, vCores:1> cluster=<memory:8192, vCores:8>
2014-04-01 02:12:35,820 INFO org.apache.hadoop.yarn.server.resourcemanager.scheduler.capacity.ParentQueue: completedContainer queue=root usedCapacity=0.25 absoluteUsedCapacity=0.25 used=<memory:2048, vCores:1> cluster=<memory:8192, vCores:8>
2014-04-01 02:12:35,820 INFO org.apache.hadoop.yarn.server.resourcemanager.scheduler.capacity.ParentQueue: Re-sorting completed queue: root.default stats: default: capacity=1.0, absoluteCapacity=1.0, usedResources=<memory:2048, vCores:1>usedCapacity=0.25, absoluteUsedCapacity=0.25, numApps=1, numContainers=1
2014-04-01 02:12:35,820 INFO org.apache.hadoop.yarn.server.resourcemanager.scheduler.capacity.CapacityScheduler: Application appattempt_1396342005689_0006_000001 released container container_1396342005689_0006_01_000004 on node: host: ubuntu:38688 #containers=1 available=6144 used=2048 with event: FINISHED
2014-04-01 02:12:36,822 INFO org.apache.hadoop.yarn.server.resourcemanager.rmcontainer.RMContainerImpl: container_1396342005689_0006_01_000005 Container Transitioned from NEW to ALLOCATED
2014-04-01 02:12:36,823 INFO org.apache.hadoop.yarn.server.resourcemanager.RMAuditLogger: USER=hduser	OPERATION=AM Allocated Container	TARGET=SchedulerApp	RESULT=SUCCESS	APPID=application_1396342005689_0006	CONTAINERID=container_1396342005689_0006_01_000005
2014-04-01 02:12:36,823 INFO org.apache.hadoop.yarn.server.resourcemanager.scheduler.common.fica.FiCaSchedulerNode: Assigned container container_1396342005689_0006_01_000005 of capacity <memory:1024, vCores:1> on host ubuntu:38688, which currently has 2 containers, <memory:3072, vCores:2> used and <memory:5120, vCores:6> available
2014-04-01 02:12:36,823 INFO org.apache.hadoop.yarn.server.resourcemanager.scheduler.capacity.LeafQueue: assignedContainer application=application_1396342005689_0006 container=Container: [ContainerId: container_1396342005689_0006_01_000005, NodeId: ubuntu:38688, NodeHttpAddress: ubuntu:8042, Resource: <memory:1024, vCores:1>, Priority: 5, Token: Token { kind: ContainerToken, service: 127.0.1.1:38688 }, ] containerId=container_1396342005689_0006_01_000005 queue=default: capacity=1.0, absoluteCapacity=1.0, usedResources=<memory:2048, vCores:1>usedCapacity=0.25, absoluteUsedCapacity=0.25, numApps=1, numContainers=1 usedCapacity=0.25 absoluteUsedCapacity=0.25 used=<memory:2048, vCores:1> cluster=<memory:8192, vCores:8>
2014-04-01 02:12:36,823 INFO org.apache.hadoop.yarn.server.resourcemanager.scheduler.capacity.ParentQueue: Re-sorting assigned queue: root.default stats: default: capacity=1.0, absoluteCapacity=1.0, usedResources=<memory:3072, vCores:2>usedCapacity=0.375, absoluteUsedCapacity=0.375, numApps=1, numContainers=2
2014-04-01 02:12:36,823 INFO org.apache.hadoop.yarn.server.resourcemanager.scheduler.capacity.ParentQueue: assignedContainer queue=root usedCapacity=0.375 absoluteUsedCapacity=0.375 used=<memory:3072, vCores:2> cluster=<memory:8192, vCores:8>
2014-04-01 02:12:37,124 INFO org.apache.hadoop.yarn.server.resourcemanager.rmcontainer.RMContainerImpl: container_1396342005689_0006_01_000005 Container Transitioned from ALLOCATED to ACQUIRED
2014-04-01 02:12:37,824 INFO org.apache.hadoop.yarn.server.resourcemanager.rmcontainer.RMContainerImpl: container_1396342005689_0006_01_000005 Container Transitioned from ACQUIRED to RUNNING
2014-04-01 02:12:38,128 INFO org.apache.hadoop.yarn.server.resourcemanager.scheduler.AppSchedulingInfo: checking for deactivate... 
2014-04-01 02:12:38,830 INFO org.apache.hadoop.yarn.server.resourcemanager.rmapp.attempt.RMAppAttemptImpl: appattempt_1396342005689_0006_000001 State change from RUNNING to FINISHING
2014-04-01 02:12:38,830 INFO org.apache.hadoop.yarn.server.resourcemanager.rmapp.RMAppImpl: Removing application with id application_1396342005689_0006
2014-04-01 02:12:38,831 INFO org.apache.hadoop.yarn.server.resourcemanager.rmapp.RMAppImpl: application_1396342005689_0006 State change from RUNNING to REMOVING
2014-04-01 02:12:38,831 INFO org.apache.hadoop.yarn.server.resourcemanager.recovery.RMStateStore: Removing info for app: application_1396342005689_0006
2014-04-01 02:12:38,831 INFO org.apache.hadoop.yarn.server.resourcemanager.rmapp.RMAppImpl: application_1396342005689_0006 State change from REMOVING to FINISHING
2014-04-01 02:12:39,818 INFO org.apache.hadoop.yarn.server.resourcemanager.rmcontainer.RMContainerImpl: container_1396342005689_0006_01_000005 Container Transitioned from RUNNING to COMPLETED
2014-04-01 02:12:39,818 INFO org.apache.hadoop.yarn.server.resourcemanager.scheduler.common.fica.FiCaSchedulerApp: Completed container: container_1396342005689_0006_01_000005 in state: COMPLETED event:FINISHED
2014-04-01 02:12:39,818 INFO org.apache.hadoop.yarn.server.resourcemanager.RMAuditLogger: USER=hduser	OPERATION=AM Released Container	TARGET=SchedulerApp	RESULT=SUCCESS	APPID=application_1396342005689_0006	CONTAINERID=container_1396342005689_0006_01_000005
2014-04-01 02:12:39,818 INFO org.apache.hadoop.yarn.server.resourcemanager.scheduler.common.fica.FiCaSchedulerNode: Released container container_1396342005689_0006_01_000005 of capacity <memory:1024, vCores:1> on host ubuntu:38688, which currently has 1 containers, <memory:2048, vCores:1> used and <memory:6144, vCores:7> available, release resources=true
2014-04-01 02:12:39,818 INFO org.apache.hadoop.yarn.server.resourcemanager.scheduler.capacity.LeafQueue: default used=<memory:2048, vCores:1> numContainers=1 user=hduser user-resources=<memory:2048, vCores:1>
2014-04-01 02:12:39,818 INFO org.apache.hadoop.yarn.server.resourcemanager.scheduler.capacity.LeafQueue: completedContainer container=Container: [ContainerId: container_1396342005689_0006_01_000005, NodeId: ubuntu:38688, NodeHttpAddress: ubuntu:8042, Resource: <memory:1024, vCores:1>, Priority: 5, Token: Token { kind: ContainerToken, service: 127.0.1.1:38688 }, ] resource=<memory:1024, vCores:1> queue=default: capacity=1.0, absoluteCapacity=1.0, usedResources=<memory:2048, vCores:1>usedCapacity=0.25, absoluteUsedCapacity=0.25, numApps=1, numContainers=1 usedCapacity=0.25 absoluteUsedCapacity=0.25 used=<memory:2048, vCores:1> cluster=<memory:8192, vCores:8>
2014-04-01 02:12:39,818 INFO org.apache.hadoop.yarn.server.resourcemanager.scheduler.capacity.ParentQueue: completedContainer queue=root usedCapacity=0.25 absoluteUsedCapacity=0.25 used=<memory:2048, vCores:1> cluster=<memory:8192, vCores:8>
2014-04-01 02:12:39,818 INFO org.apache.hadoop.yarn.server.resourcemanager.scheduler.capacity.ParentQueue: Re-sorting completed queue: root.default stats: default: capacity=1.0, absoluteCapacity=1.0, usedResources=<memory:2048, vCores:1>usedCapacity=0.25, absoluteUsedCapacity=0.25, numApps=1, numContainers=1
2014-04-01 02:12:39,819 INFO org.apache.hadoop.yarn.server.resourcemanager.scheduler.capacity.CapacityScheduler: Application appattempt_1396342005689_0006_000001 released container container_1396342005689_0006_01_000005 on node: host: ubuntu:38688 #containers=1 available=6144 used=2048 with event: FINISHED
2014-04-01 02:12:40,820 INFO org.apache.hadoop.yarn.server.resourcemanager.rmcontainer.RMContainerImpl: container_1396342005689_0006_01_000001 Container Transitioned from RUNNING to COMPLETED
2014-04-01 02:12:40,820 INFO org.apache.hadoop.yarn.server.resourcemanager.scheduler.common.fica.FiCaSchedulerApp: Completed container: container_1396342005689_0006_01_000001 in state: COMPLETED event:FINISHED
2014-04-01 02:12:40,820 INFO org.apache.hadoop.yarn.server.resourcemanager.RMAuditLogger: USER=hduser	OPERATION=AM Released Container	TARGET=SchedulerApp	RESULT=SUCCESS	APPID=application_1396342005689_0006	CONTAINERID=container_1396342005689_0006_01_000001
2014-04-01 02:12:40,821 INFO org.apache.hadoop.yarn.server.resourcemanager.scheduler.common.fica.FiCaSchedulerNode: Released container container_1396342005689_0006_01_000001 of capacity <memory:2048, vCores:1> on host ubuntu:38688, which currently has 0 containers, <memory:0, vCores:0> used and <memory:8192, vCores:8> available, release resources=true
2014-04-01 02:12:40,821 INFO org.apache.hadoop.yarn.server.resourcemanager.scheduler.capacity.LeafQueue: default used=<memory:0, vCores:0> numContainers=0 user=hduser user-resources=<memory:0, vCores:0>
2014-04-01 02:12:40,821 INFO org.apache.hadoop.yarn.server.resourcemanager.scheduler.capacity.LeafQueue: completedContainer container=Container: [ContainerId: container_1396342005689_0006_01_000001, NodeId: ubuntu:38688, NodeHttpAddress: ubuntu:8042, Resource: <memory:2048, vCores:1>, Priority: 0, Token: Token { kind: ContainerToken, service: 127.0.1.1:38688 }, ] resource=<memory:2048, vCores:1> queue=default: capacity=1.0, absoluteCapacity=1.0, usedResources=<memory:0, vCores:0>usedCapacity=0.0, absoluteUsedCapacity=0.0, numApps=1, numContainers=0 usedCapacity=0.0 absoluteUsedCapacity=0.0 used=<memory:0, vCores:0> cluster=<memory:8192, vCores:8>
2014-04-01 02:12:40,821 INFO org.apache.hadoop.yarn.server.resourcemanager.scheduler.capacity.ParentQueue: completedContainer queue=root usedCapacity=0.0 absoluteUsedCapacity=0.0 used=<memory:0, vCores:0> cluster=<memory:8192, vCores:8>
2014-04-01 02:12:40,821 INFO org.apache.hadoop.yarn.server.resourcemanager.scheduler.capacity.ParentQueue: Re-sorting completed queue: root.default stats: default: capacity=1.0, absoluteCapacity=1.0, usedResources=<memory:0, vCores:0>usedCapacity=0.0, absoluteUsedCapacity=0.0, numApps=1, numContainers=0
2014-04-01 02:12:40,821 INFO org.apache.hadoop.yarn.server.resourcemanager.scheduler.capacity.CapacityScheduler: Application appattempt_1396342005689_0006_000001 released container container_1396342005689_0006_01_000001 on node: host: ubuntu:38688 #containers=0 available=8192 used=0 with event: FINISHED
2014-04-01 02:12:40,821 INFO org.apache.hadoop.yarn.server.resourcemanager.ApplicationMasterService: Unregistering app attempt : appattempt_1396342005689_0006_000001
2014-04-01 02:12:40,822 INFO org.apache.hadoop.yarn.server.resourcemanager.rmapp.attempt.RMAppAttemptImpl: appattempt_1396342005689_0006_000001 State change from FINISHING to FINISHED
2014-04-01 02:12:40,822 INFO org.apache.hadoop.yarn.server.resourcemanager.rmapp.RMAppImpl: application_1396342005689_0006 State change from FINISHING to FINISHED
2014-04-01 02:12:40,822 INFO org.apache.hadoop.yarn.server.resourcemanager.RMAuditLogger: USER=hduser	OPERATION=Application Finished - Succeeded	TARGET=RMAppManager	RESULT=SUCCESS	APPID=application_1396342005689_0006
2014-04-01 02:12:40,822 INFO org.apache.hadoop.yarn.server.resourcemanager.RMAppManager$ApplicationSummary: appId=application_1396342005689_0006,name=base||path:/in||num reduce:8,user=hduser,queue=default,state=FINISHED,trackingUrl=ubuntu:8088/proxy/application_1396342005689_0006/jobhistory/job/job_1396342005689_0006,appMasterHost=ubuntu,startTime=1396343541968,finishTime=1396343558831,finalStatus=FAILED
2014-04-01 02:12:40,822 INFO org.apache.hadoop.yarn.server.resourcemanager.scheduler.capacity.CapacityScheduler: Application appattempt_1396342005689_0006_000001 is done. finalState=FINISHED
2014-04-01 02:12:40,822 INFO org.apache.hadoop.yarn.server.resourcemanager.scheduler.AppSchedulingInfo: Application application_1396342005689_0006 requests cleared
2014-04-01 02:12:40,822 INFO org.apache.hadoop.yarn.server.resourcemanager.scheduler.capacity.LeafQueue: Application removed - appId: application_1396342005689_0006 user: hduser queue: default #user-pending-applications: 0 #user-active-applications: 0 #queue-pending-applications: 0 #queue-active-applications: 0
2014-04-01 02:12:40,822 INFO org.apache.hadoop.yarn.server.resourcemanager.scheduler.capacity.ParentQueue: Application removed - appId: application_1396342005689_0006 user: hduser leaf-queue of parent: root #applications: 0
2014-04-01 02:12:40,823 INFO org.apache.hadoop.yarn.server.resourcemanager.amlauncher.AMLauncher: Cleaning master appattempt_1396342005689_0006_000001
2014-04-01 02:13:30,992 INFO org.apache.hadoop.yarn.server.resourcemanager.ClientRMService: Allocated new applicationId: 7
2014-04-01 02:13:31,633 INFO org.apache.hadoop.yarn.server.resourcemanager.ClientRMService: Application with id 7 submitted by user hduser
2014-04-01 02:13:31,633 INFO org.apache.hadoop.yarn.server.resourcemanager.rmapp.RMAppImpl: Storing application with id application_1396342005689_0007
2014-04-01 02:13:31,633 INFO org.apache.hadoop.yarn.server.resourcemanager.rmapp.RMAppImpl: application_1396342005689_0007 State change from NEW to NEW_SAVING
2014-04-01 02:13:31,633 INFO org.apache.hadoop.yarn.server.resourcemanager.RMAuditLogger: USER=hduser	IP=127.0.0.1	OPERATION=Submit Application Request	TARGET=ClientRMService	RESULT=SUCCESS	APPID=application_1396342005689_0007
2014-04-01 02:13:31,633 INFO org.apache.hadoop.yarn.server.resourcemanager.recovery.RMStateStore: Storing info for app: application_1396342005689_0007
2014-04-01 02:13:31,634 INFO org.apache.hadoop.yarn.server.resourcemanager.rmapp.RMAppImpl: application_1396342005689_0007 State change from NEW_SAVING to SUBMITTED
2014-04-01 02:13:31,634 INFO org.apache.hadoop.yarn.server.resourcemanager.ApplicationMasterService: Registering app attempt : appattempt_1396342005689_0007_000001
2014-04-01 02:13:31,634 INFO org.apache.hadoop.yarn.server.resourcemanager.rmapp.attempt.RMAppAttemptImpl: appattempt_1396342005689_0007_000001 State change from NEW to SUBMITTED
2014-04-01 02:13:31,634 INFO org.apache.hadoop.yarn.server.resourcemanager.scheduler.capacity.LeafQueue: Application application_1396342005689_0007 from user: hduser activated in queue: default
2014-04-01 02:13:31,634 INFO org.apache.hadoop.yarn.server.resourcemanager.scheduler.capacity.LeafQueue: Application added - appId: application_1396342005689_0007 user: org.apache.hadoop.yarn.server.resourcemanager.scheduler.capacity.LeafQueue$User@6b058b, leaf-queue: default #user-pending-applications: 0 #user-active-applications: 1 #queue-pending-applications: 0 #queue-active-applications: 1
2014-04-01 02:13:31,634 INFO org.apache.hadoop.yarn.server.resourcemanager.scheduler.capacity.ParentQueue: Application added - appId: application_1396342005689_0007 user: hduser leaf-queue of parent: root #applications: 1
2014-04-01 02:13:31,634 INFO org.apache.hadoop.yarn.server.resourcemanager.scheduler.capacity.CapacityScheduler: Application Submission: appattempt_1396342005689_0007_000001, user: hduser queue: default: capacity=1.0, absoluteCapacity=1.0, usedResources=<memory:0, vCores:0>usedCapacity=0.0, absoluteUsedCapacity=0.0, numApps=1, numContainers=0, currently active: 1
2014-04-01 02:13:31,635 INFO org.apache.hadoop.yarn.server.resourcemanager.rmapp.attempt.RMAppAttemptImpl: appattempt_1396342005689_0007_000001 State change from SUBMITTED to SCHEDULED
2014-04-01 02:13:31,635 INFO org.apache.hadoop.yarn.server.resourcemanager.rmapp.RMAppImpl: application_1396342005689_0007 State change from SUBMITTED to ACCEPTED
2014-04-01 02:13:31,935 INFO org.apache.hadoop.yarn.server.resourcemanager.rmcontainer.RMContainerImpl: container_1396342005689_0007_01_000001 Container Transitioned from NEW to ALLOCATED
2014-04-01 02:13:31,935 INFO org.apache.hadoop.yarn.server.resourcemanager.RMAuditLogger: USER=hduser	OPERATION=AM Allocated Container	TARGET=SchedulerApp	RESULT=SUCCESS	APPID=application_1396342005689_0007	CONTAINERID=container_1396342005689_0007_01_000001
2014-04-01 02:13:31,935 INFO org.apache.hadoop.yarn.server.resourcemanager.scheduler.common.fica.FiCaSchedulerNode: Assigned container container_1396342005689_0007_01_000001 of capacity <memory:2048, vCores:1> on host ubuntu:38688, which currently has 1 containers, <memory:2048, vCores:1> used and <memory:6144, vCores:7> available
2014-04-01 02:13:31,935 INFO org.apache.hadoop.yarn.server.resourcemanager.scheduler.capacity.LeafQueue: assignedContainer application=application_1396342005689_0007 container=Container: [ContainerId: container_1396342005689_0007_01_000001, NodeId: ubuntu:38688, NodeHttpAddress: ubuntu:8042, Resource: <memory:2048, vCores:1>, Priority: 0, Token: Token { kind: ContainerToken, service: 127.0.1.1:38688 }, ] containerId=container_1396342005689_0007_01_000001 queue=default: capacity=1.0, absoluteCapacity=1.0, usedResources=<memory:0, vCores:0>usedCapacity=0.0, absoluteUsedCapacity=0.0, numApps=1, numContainers=0 usedCapacity=0.0 absoluteUsedCapacity=0.0 used=<memory:0, vCores:0> cluster=<memory:8192, vCores:8>
2014-04-01 02:13:31,935 INFO org.apache.hadoop.yarn.server.resourcemanager.scheduler.capacity.ParentQueue: Re-sorting assigned queue: root.default stats: default: capacity=1.0, absoluteCapacity=1.0, usedResources=<memory:2048, vCores:1>usedCapacity=0.25, absoluteUsedCapacity=0.25, numApps=1, numContainers=1
2014-04-01 02:13:31,935 INFO org.apache.hadoop.yarn.server.resourcemanager.scheduler.capacity.ParentQueue: assignedContainer queue=root usedCapacity=0.25 absoluteUsedCapacity=0.25 used=<memory:2048, vCores:1> cluster=<memory:8192, vCores:8>
2014-04-01 02:13:31,936 INFO org.apache.hadoop.yarn.server.resourcemanager.rmcontainer.RMContainerImpl: container_1396342005689_0007_01_000001 Container Transitioned from ALLOCATED to ACQUIRED
2014-04-01 02:13:31,936 INFO org.apache.hadoop.yarn.server.resourcemanager.rmapp.attempt.RMAppAttemptImpl: Storing attempt: AppId: application_1396342005689_0007 AttemptId: appattempt_1396342005689_0007_000001 MasterContainer: Container: [ContainerId: container_1396342005689_0007_01_000001, NodeId: ubuntu:38688, NodeHttpAddress: ubuntu:8042, Resource: <memory:2048, vCores:1>, Priority: 0, Token: Token { kind: ContainerToken, service: 127.0.1.1:38688 }, ]
2014-04-01 02:13:31,936 INFO org.apache.hadoop.yarn.server.resourcemanager.rmapp.attempt.RMAppAttemptImpl: appattempt_1396342005689_0007_000001 State change from SCHEDULED to ALLOCATED_SAVING
2014-04-01 02:13:31,936 INFO org.apache.hadoop.yarn.server.resourcemanager.recovery.RMStateStore: Storing info for attempt: appattempt_1396342005689_0007_000001
2014-04-01 02:13:31,936 INFO org.apache.hadoop.yarn.server.resourcemanager.rmapp.attempt.RMAppAttemptImpl: appattempt_1396342005689_0007_000001 State change from ALLOCATED_SAVING to ALLOCATED
2014-04-01 02:13:31,937 INFO org.apache.hadoop.yarn.server.resourcemanager.amlauncher.AMLauncher: Launching masterappattempt_1396342005689_0007_000001
2014-04-01 02:13:31,937 INFO org.apache.hadoop.yarn.server.resourcemanager.amlauncher.AMLauncher: Setting up container Container: [ContainerId: container_1396342005689_0007_01_000001, NodeId: ubuntu:38688, NodeHttpAddress: ubuntu:8042, Resource: <memory:2048, vCores:1>, Priority: 0, Token: Token { kind: ContainerToken, service: 127.0.1.1:38688 }, ] for AM appattempt_1396342005689_0007_000001
2014-04-01 02:13:31,937 INFO org.apache.hadoop.yarn.server.resourcemanager.amlauncher.AMLauncher: Command to launch container container_1396342005689_0007_01_000001 : $JAVA_HOME/bin/java -Dlog4j.configuration=container-log4j.properties -Dyarn.app.container.log.dir=<LOG_DIR> -Dyarn.app.container.log.filesize=0 -Dhadoop.root.logger=INFO,CLA  -Xmx1024m org.apache.hadoop.mapreduce.v2.app.MRAppMaster 1><LOG_DIR>/stdout 2><LOG_DIR>/stderr 
2014-04-01 02:13:31,950 INFO org.apache.hadoop.yarn.server.resourcemanager.amlauncher.AMLauncher: Done launching container Container: [ContainerId: container_1396342005689_0007_01_000001, NodeId: ubuntu:38688, NodeHttpAddress: ubuntu:8042, Resource: <memory:2048, vCores:1>, Priority: 0, Token: Token { kind: ContainerToken, service: 127.0.1.1:38688 }, ] for AM appattempt_1396342005689_0007_000001
2014-04-01 02:13:31,951 INFO org.apache.hadoop.yarn.server.resourcemanager.rmapp.attempt.RMAppAttemptImpl: appattempt_1396342005689_0007_000001 State change from ALLOCATED to LAUNCHED
2014-04-01 02:13:32,936 INFO org.apache.hadoop.yarn.server.resourcemanager.rmcontainer.RMContainerImpl: container_1396342005689_0007_01_000001 Container Transitioned from ACQUIRED to RUNNING
2014-04-01 02:13:34,429 INFO SecurityLogger.org.apache.hadoop.ipc.Server: Auth successful for appattempt_1396342005689_0007_000001 (auth:SIMPLE)
2014-04-01 02:13:34,432 INFO org.apache.hadoop.yarn.server.resourcemanager.ApplicationMasterService: AM registration appattempt_1396342005689_0007_000001
2014-04-01 02:13:34,432 INFO org.apache.hadoop.yarn.server.resourcemanager.RMAuditLogger: USER=hduser	IP=127.0.0.1	OPERATION=Register App Master	TARGET=ApplicationMasterService	RESULT=SUCCESS	APPID=application_1396342005689_0007	APPATTEMPTID=appattempt_1396342005689_0007_000001
2014-04-01 02:13:34,432 INFO org.apache.hadoop.yarn.server.resourcemanager.rmapp.attempt.RMAppAttemptImpl: appattempt_1396342005689_0007_000001 State change from LAUNCHED to RUNNING
2014-04-01 02:13:34,433 INFO org.apache.hadoop.yarn.server.resourcemanager.rmapp.RMAppImpl: application_1396342005689_0007 State change from ACCEPTED to RUNNING
2014-04-01 02:13:35,951 INFO org.apache.hadoop.yarn.server.resourcemanager.rmcontainer.RMContainerImpl: container_1396342005689_0007_01_000002 Container Transitioned from NEW to ALLOCATED
2014-04-01 02:13:35,951 INFO org.apache.hadoop.yarn.server.resourcemanager.RMAuditLogger: USER=hduser	OPERATION=AM Allocated Container	TARGET=SchedulerApp	RESULT=SUCCESS	APPID=application_1396342005689_0007	CONTAINERID=container_1396342005689_0007_01_000002
2014-04-01 02:13:35,951 INFO org.apache.hadoop.yarn.server.resourcemanager.scheduler.common.fica.FiCaSchedulerNode: Assigned container container_1396342005689_0007_01_000002 of capacity <memory:1024, vCores:1> on host ubuntu:38688, which currently has 2 containers, <memory:3072, vCores:2> used and <memory:5120, vCores:6> available
2014-04-01 02:13:35,952 INFO org.apache.hadoop.yarn.server.resourcemanager.scheduler.capacity.LeafQueue: assignedContainer application=application_1396342005689_0007 container=Container: [ContainerId: container_1396342005689_0007_01_000002, NodeId: ubuntu:38688, NodeHttpAddress: ubuntu:8042, Resource: <memory:1024, vCores:1>, Priority: 20, Token: Token { kind: ContainerToken, service: 127.0.1.1:38688 }, ] containerId=container_1396342005689_0007_01_000002 queue=default: capacity=1.0, absoluteCapacity=1.0, usedResources=<memory:2048, vCores:1>usedCapacity=0.25, absoluteUsedCapacity=0.25, numApps=1, numContainers=1 usedCapacity=0.25 absoluteUsedCapacity=0.25 used=<memory:2048, vCores:1> cluster=<memory:8192, vCores:8>
2014-04-01 02:13:35,952 INFO org.apache.hadoop.yarn.server.resourcemanager.scheduler.capacity.ParentQueue: Re-sorting assigned queue: root.default stats: default: capacity=1.0, absoluteCapacity=1.0, usedResources=<memory:3072, vCores:2>usedCapacity=0.375, absoluteUsedCapacity=0.375, numApps=1, numContainers=2
2014-04-01 02:13:35,952 INFO org.apache.hadoop.yarn.server.resourcemanager.scheduler.capacity.ParentQueue: assignedContainer queue=root usedCapacity=0.375 absoluteUsedCapacity=0.375 used=<memory:3072, vCores:2> cluster=<memory:8192, vCores:8>
2014-04-01 02:13:36,465 INFO org.apache.hadoop.yarn.server.resourcemanager.rmcontainer.RMContainerImpl: container_1396342005689_0007_01_000002 Container Transitioned from ALLOCATED to ACQUIRED
2014-04-01 02:13:36,952 INFO org.apache.hadoop.yarn.server.resourcemanager.rmcontainer.RMContainerImpl: container_1396342005689_0007_01_000002 Container Transitioned from ACQUIRED to RUNNING
2014-04-01 02:13:37,494 INFO org.apache.hadoop.yarn.server.resourcemanager.scheduler.AppSchedulingInfo: checking for deactivate... 
2014-04-01 02:13:39,812 INFO org.apache.hadoop.yarn.server.resourcemanager.rmcontainer.RMContainerImpl: container_1396342005689_0007_01_000002 Container Transitioned from RUNNING to COMPLETED
2014-04-01 02:13:39,812 INFO org.apache.hadoop.yarn.server.resourcemanager.scheduler.common.fica.FiCaSchedulerApp: Completed container: container_1396342005689_0007_01_000002 in state: COMPLETED event:FINISHED
2014-04-01 02:13:39,812 INFO org.apache.hadoop.yarn.server.resourcemanager.RMAuditLogger: USER=hduser	OPERATION=AM Released Container	TARGET=SchedulerApp	RESULT=SUCCESS	APPID=application_1396342005689_0007	CONTAINERID=container_1396342005689_0007_01_000002
2014-04-01 02:13:39,812 INFO org.apache.hadoop.yarn.server.resourcemanager.scheduler.common.fica.FiCaSchedulerNode: Released container container_1396342005689_0007_01_000002 of capacity <memory:1024, vCores:1> on host ubuntu:38688, which currently has 1 containers, <memory:2048, vCores:1> used and <memory:6144, vCores:7> available, release resources=true
2014-04-01 02:13:39,812 INFO org.apache.hadoop.yarn.server.resourcemanager.scheduler.capacity.LeafQueue: default used=<memory:2048, vCores:1> numContainers=1 user=hduser user-resources=<memory:2048, vCores:1>
2014-04-01 02:13:39,812 INFO org.apache.hadoop.yarn.server.resourcemanager.scheduler.capacity.LeafQueue: completedContainer container=Container: [ContainerId: container_1396342005689_0007_01_000002, NodeId: ubuntu:38688, NodeHttpAddress: ubuntu:8042, Resource: <memory:1024, vCores:1>, Priority: 20, Token: Token { kind: ContainerToken, service: 127.0.1.1:38688 }, ] resource=<memory:1024, vCores:1> queue=default: capacity=1.0, absoluteCapacity=1.0, usedResources=<memory:2048, vCores:1>usedCapacity=0.25, absoluteUsedCapacity=0.25, numApps=1, numContainers=1 usedCapacity=0.25 absoluteUsedCapacity=0.25 used=<memory:2048, vCores:1> cluster=<memory:8192, vCores:8>
2014-04-01 02:13:39,812 INFO org.apache.hadoop.yarn.server.resourcemanager.scheduler.capacity.ParentQueue: completedContainer queue=root usedCapacity=0.25 absoluteUsedCapacity=0.25 used=<memory:2048, vCores:1> cluster=<memory:8192, vCores:8>
2014-04-01 02:13:39,812 INFO org.apache.hadoop.yarn.server.resourcemanager.scheduler.capacity.ParentQueue: Re-sorting completed queue: root.default stats: default: capacity=1.0, absoluteCapacity=1.0, usedResources=<memory:2048, vCores:1>usedCapacity=0.25, absoluteUsedCapacity=0.25, numApps=1, numContainers=1
2014-04-01 02:13:39,812 INFO org.apache.hadoop.yarn.server.resourcemanager.scheduler.capacity.CapacityScheduler: Application appattempt_1396342005689_0007_000001 released container container_1396342005689_0007_01_000002 on node: host: ubuntu:38688 #containers=1 available=6144 used=2048 with event: FINISHED
2014-04-01 02:13:40,816 INFO org.apache.hadoop.yarn.server.resourcemanager.rmcontainer.RMContainerImpl: container_1396342005689_0007_01_000003 Container Transitioned from NEW to ALLOCATED
2014-04-01 02:13:40,816 INFO org.apache.hadoop.yarn.server.resourcemanager.RMAuditLogger: USER=hduser	OPERATION=AM Allocated Container	TARGET=SchedulerApp	RESULT=SUCCESS	APPID=application_1396342005689_0007	CONTAINERID=container_1396342005689_0007_01_000003
2014-04-01 02:13:40,816 INFO org.apache.hadoop.yarn.server.resourcemanager.scheduler.common.fica.FiCaSchedulerNode: Assigned container container_1396342005689_0007_01_000003 of capacity <memory:1024, vCores:1> on host ubuntu:38688, which currently has 2 containers, <memory:3072, vCores:2> used and <memory:5120, vCores:6> available
2014-04-01 02:13:40,816 INFO org.apache.hadoop.yarn.server.resourcemanager.scheduler.capacity.LeafQueue: assignedContainer application=application_1396342005689_0007 container=Container: [ContainerId: container_1396342005689_0007_01_000003, NodeId: ubuntu:38688, NodeHttpAddress: ubuntu:8042, Resource: <memory:1024, vCores:1>, Priority: 10, Token: Token { kind: ContainerToken, service: 127.0.1.1:38688 }, ] containerId=container_1396342005689_0007_01_000003 queue=default: capacity=1.0, absoluteCapacity=1.0, usedResources=<memory:2048, vCores:1>usedCapacity=0.25, absoluteUsedCapacity=0.25, numApps=1, numContainers=1 usedCapacity=0.25 absoluteUsedCapacity=0.25 used=<memory:2048, vCores:1> cluster=<memory:8192, vCores:8>
2014-04-01 02:13:40,816 INFO org.apache.hadoop.yarn.server.resourcemanager.scheduler.capacity.ParentQueue: Re-sorting assigned queue: root.default stats: default: capacity=1.0, absoluteCapacity=1.0, usedResources=<memory:3072, vCores:2>usedCapacity=0.375, absoluteUsedCapacity=0.375, numApps=1, numContainers=2
2014-04-01 02:13:40,816 INFO org.apache.hadoop.yarn.server.resourcemanager.scheduler.capacity.ParentQueue: assignedContainer queue=root usedCapacity=0.375 absoluteUsedCapacity=0.375 used=<memory:3072, vCores:2> cluster=<memory:8192, vCores:8>
2014-04-01 02:13:41,514 INFO org.apache.hadoop.yarn.server.resourcemanager.rmcontainer.RMContainerImpl: container_1396342005689_0007_01_000003 Container Transitioned from ALLOCATED to ACQUIRED
2014-04-01 02:13:41,817 INFO org.apache.hadoop.yarn.server.resourcemanager.rmcontainer.RMContainerImpl: container_1396342005689_0007_01_000003 Container Transitioned from ACQUIRED to RUNNING
2014-04-01 02:13:41,818 INFO org.apache.hadoop.yarn.server.resourcemanager.rmcontainer.RMContainerImpl: container_1396342005689_0007_01_000004 Container Transitioned from NEW to ALLOCATED
2014-04-01 02:13:41,818 INFO org.apache.hadoop.yarn.server.resourcemanager.RMAuditLogger: USER=hduser	OPERATION=AM Allocated Container	TARGET=SchedulerApp	RESULT=SUCCESS	APPID=application_1396342005689_0007	CONTAINERID=container_1396342005689_0007_01_000004
2014-04-01 02:13:41,818 INFO org.apache.hadoop.yarn.server.resourcemanager.scheduler.common.fica.FiCaSchedulerNode: Assigned container container_1396342005689_0007_01_000004 of capacity <memory:1024, vCores:1> on host ubuntu:38688, which currently has 3 containers, <memory:4096, vCores:3> used and <memory:4096, vCores:5> available
2014-04-01 02:13:41,818 INFO org.apache.hadoop.yarn.server.resourcemanager.scheduler.capacity.LeafQueue: assignedContainer application=application_1396342005689_0007 container=Container: [ContainerId: container_1396342005689_0007_01_000004, NodeId: ubuntu:38688, NodeHttpAddress: ubuntu:8042, Resource: <memory:1024, vCores:1>, Priority: 10, Token: Token { kind: ContainerToken, service: 127.0.1.1:38688 }, ] containerId=container_1396342005689_0007_01_000004 queue=default: capacity=1.0, absoluteCapacity=1.0, usedResources=<memory:3072, vCores:2>usedCapacity=0.375, absoluteUsedCapacity=0.375, numApps=1, numContainers=2 usedCapacity=0.375 absoluteUsedCapacity=0.375 used=<memory:3072, vCores:2> cluster=<memory:8192, vCores:8>
2014-04-01 02:13:41,818 INFO org.apache.hadoop.yarn.server.resourcemanager.scheduler.capacity.ParentQueue: Re-sorting assigned queue: root.default stats: default: capacity=1.0, absoluteCapacity=1.0, usedResources=<memory:4096, vCores:3>usedCapacity=0.5, absoluteUsedCapacity=0.5, numApps=1, numContainers=3
2014-04-01 02:13:41,818 INFO org.apache.hadoop.yarn.server.resourcemanager.scheduler.capacity.ParentQueue: assignedContainer queue=root usedCapacity=0.5 absoluteUsedCapacity=0.5 used=<memory:4096, vCores:3> cluster=<memory:8192, vCores:8>
2014-04-01 02:13:42,518 INFO org.apache.hadoop.yarn.server.resourcemanager.rmcontainer.RMContainerImpl: container_1396342005689_0007_01_000004 Container Transitioned from ALLOCATED to ACQUIRED
2014-04-01 02:13:42,820 INFO org.apache.hadoop.yarn.server.resourcemanager.rmcontainer.RMContainerImpl: container_1396342005689_0007_01_000004 Container Transitioned from ACQUIRED to RUNNING
2014-04-01 02:13:42,820 INFO org.apache.hadoop.yarn.server.resourcemanager.rmcontainer.RMContainerImpl: container_1396342005689_0007_01_000005 Container Transitioned from NEW to ALLOCATED
2014-04-01 02:13:42,820 INFO org.apache.hadoop.yarn.server.resourcemanager.RMAuditLogger: USER=hduser	OPERATION=AM Allocated Container	TARGET=SchedulerApp	RESULT=SUCCESS	APPID=application_1396342005689_0007	CONTAINERID=container_1396342005689_0007_01_000005
2014-04-01 02:13:42,820 INFO org.apache.hadoop.yarn.server.resourcemanager.scheduler.common.fica.FiCaSchedulerNode: Assigned container container_1396342005689_0007_01_000005 of capacity <memory:1024, vCores:1> on host ubuntu:38688, which currently has 4 containers, <memory:5120, vCores:4> used and <memory:3072, vCores:4> available
2014-04-01 02:13:42,821 INFO org.apache.hadoop.yarn.server.resourcemanager.scheduler.capacity.LeafQueue: assignedContainer application=application_1396342005689_0007 container=Container: [ContainerId: container_1396342005689_0007_01_000005, NodeId: ubuntu:38688, NodeHttpAddress: ubuntu:8042, Resource: <memory:1024, vCores:1>, Priority: 10, Token: Token { kind: ContainerToken, service: 127.0.1.1:38688 }, ] containerId=container_1396342005689_0007_01_000005 queue=default: capacity=1.0, absoluteCapacity=1.0, usedResources=<memory:4096, vCores:3>usedCapacity=0.5, absoluteUsedCapacity=0.5, numApps=1, numContainers=3 usedCapacity=0.5 absoluteUsedCapacity=0.5 used=<memory:4096, vCores:3> cluster=<memory:8192, vCores:8>
2014-04-01 02:13:42,821 INFO org.apache.hadoop.yarn.server.resourcemanager.scheduler.capacity.ParentQueue: Re-sorting assigned queue: root.default stats: default: capacity=1.0, absoluteCapacity=1.0, usedResources=<memory:5120, vCores:4>usedCapacity=0.625, absoluteUsedCapacity=0.625, numApps=1, numContainers=4
2014-04-01 02:13:42,823 INFO org.apache.hadoop.yarn.server.resourcemanager.scheduler.capacity.ParentQueue: assignedContainer queue=root usedCapacity=0.625 absoluteUsedCapacity=0.625 used=<memory:5120, vCores:4> cluster=<memory:8192, vCores:8>
2014-04-01 02:13:43,527 INFO org.apache.hadoop.yarn.server.resourcemanager.rmcontainer.RMContainerImpl: container_1396342005689_0007_01_000005 Container Transitioned from ALLOCATED to ACQUIRED
2014-04-01 02:13:43,668 INFO org.apache.hadoop.yarn.server.resourcemanager.rmcontainer.RMContainerImpl: container_1396342005689_0007_01_000005 Container Transitioned from ACQUIRED to RUNNING
2014-04-01 02:13:43,668 INFO org.apache.hadoop.yarn.server.resourcemanager.rmcontainer.RMContainerImpl: container_1396342005689_0007_01_000006 Container Transitioned from NEW to ALLOCATED
2014-04-01 02:13:43,668 INFO org.apache.hadoop.yarn.server.resourcemanager.RMAuditLogger: USER=hduser	OPERATION=AM Allocated Container	TARGET=SchedulerApp	RESULT=SUCCESS	APPID=application_1396342005689_0007	CONTAINERID=container_1396342005689_0007_01_000006
2014-04-01 02:13:43,669 INFO org.apache.hadoop.yarn.server.resourcemanager.scheduler.common.fica.FiCaSchedulerNode: Assigned container container_1396342005689_0007_01_000006 of capacity <memory:1024, vCores:1> on host ubuntu:38688, which currently has 5 containers, <memory:6144, vCores:5> used and <memory:2048, vCores:3> available
2014-04-01 02:13:43,669 INFO org.apache.hadoop.yarn.server.resourcemanager.scheduler.capacity.LeafQueue: assignedContainer application=application_1396342005689_0007 container=Container: [ContainerId: container_1396342005689_0007_01_000006, NodeId: ubuntu:38688, NodeHttpAddress: ubuntu:8042, Resource: <memory:1024, vCores:1>, Priority: 10, Token: Token { kind: ContainerToken, service: 127.0.1.1:38688 }, ] containerId=container_1396342005689_0007_01_000006 queue=default: capacity=1.0, absoluteCapacity=1.0, usedResources=<memory:5120, vCores:4>usedCapacity=0.625, absoluteUsedCapacity=0.625, numApps=1, numContainers=4 usedCapacity=0.625 absoluteUsedCapacity=0.625 used=<memory:5120, vCores:4> cluster=<memory:8192, vCores:8>
2014-04-01 02:13:43,669 INFO org.apache.hadoop.yarn.server.resourcemanager.scheduler.capacity.ParentQueue: Re-sorting assigned queue: root.default stats: default: capacity=1.0, absoluteCapacity=1.0, usedResources=<memory:6144, vCores:5>usedCapacity=0.75, absoluteUsedCapacity=0.75, numApps=1, numContainers=5
2014-04-01 02:13:43,669 INFO org.apache.hadoop.yarn.server.resourcemanager.scheduler.capacity.ParentQueue: assignedContainer queue=root usedCapacity=0.75 absoluteUsedCapacity=0.75 used=<memory:6144, vCores:5> cluster=<memory:8192, vCores:8>
2014-04-01 02:13:44,537 INFO org.apache.hadoop.yarn.server.resourcemanager.rmcontainer.RMContainerImpl: container_1396342005689_0007_01_000006 Container Transitioned from ALLOCATED to ACQUIRED
2014-04-01 02:13:44,672 INFO org.apache.hadoop.yarn.server.resourcemanager.rmcontainer.RMContainerImpl: container_1396342005689_0007_01_000006 Container Transitioned from ACQUIRED to RUNNING
2014-04-01 02:13:44,672 INFO org.apache.hadoop.yarn.server.resourcemanager.rmcontainer.RMContainerImpl: container_1396342005689_0007_01_000003 Container Transitioned from RUNNING to COMPLETED
2014-04-01 02:13:44,672 INFO org.apache.hadoop.yarn.server.resourcemanager.scheduler.common.fica.FiCaSchedulerApp: Completed container: container_1396342005689_0007_01_000003 in state: COMPLETED event:FINISHED
2014-04-01 02:13:44,672 INFO org.apache.hadoop.yarn.server.resourcemanager.RMAuditLogger: USER=hduser	OPERATION=AM Released Container	TARGET=SchedulerApp	RESULT=SUCCESS	APPID=application_1396342005689_0007	CONTAINERID=container_1396342005689_0007_01_000003
2014-04-01 02:13:44,672 INFO org.apache.hadoop.yarn.server.resourcemanager.scheduler.common.fica.FiCaSchedulerNode: Released container container_1396342005689_0007_01_000003 of capacity <memory:1024, vCores:1> on host ubuntu:38688, which currently has 4 containers, <memory:5120, vCores:4> used and <memory:3072, vCores:4> available, release resources=true
2014-04-01 02:13:44,672 INFO org.apache.hadoop.yarn.server.resourcemanager.scheduler.capacity.LeafQueue: default used=<memory:5120, vCores:4> numContainers=4 user=hduser user-resources=<memory:5120, vCores:4>
2014-04-01 02:13:44,672 INFO org.apache.hadoop.yarn.server.resourcemanager.scheduler.capacity.LeafQueue: completedContainer container=Container: [ContainerId: container_1396342005689_0007_01_000003, NodeId: ubuntu:38688, NodeHttpAddress: ubuntu:8042, Resource: <memory:1024, vCores:1>, Priority: 10, Token: Token { kind: ContainerToken, service: 127.0.1.1:38688 }, ] resource=<memory:1024, vCores:1> queue=default: capacity=1.0, absoluteCapacity=1.0, usedResources=<memory:5120, vCores:4>usedCapacity=0.625, absoluteUsedCapacity=0.625, numApps=1, numContainers=4 usedCapacity=0.625 absoluteUsedCapacity=0.625 used=<memory:5120, vCores:4> cluster=<memory:8192, vCores:8>
2014-04-01 02:13:44,672 INFO org.apache.hadoop.yarn.server.resourcemanager.scheduler.capacity.ParentQueue: completedContainer queue=root usedCapacity=0.625 absoluteUsedCapacity=0.625 used=<memory:5120, vCores:4> cluster=<memory:8192, vCores:8>
2014-04-01 02:13:44,672 INFO org.apache.hadoop.yarn.server.resourcemanager.scheduler.capacity.ParentQueue: Re-sorting completed queue: root.default stats: default: capacity=1.0, absoluteCapacity=1.0, usedResources=<memory:5120, vCores:4>usedCapacity=0.625, absoluteUsedCapacity=0.625, numApps=1, numContainers=4
2014-04-01 02:13:44,672 INFO org.apache.hadoop.yarn.server.resourcemanager.scheduler.capacity.CapacityScheduler: Application appattempt_1396342005689_0007_000001 released container container_1396342005689_0007_01_000003 on node: host: ubuntu:38688 #containers=4 available=3072 used=5120 with event: FINISHED
2014-04-01 02:13:44,676 INFO org.apache.hadoop.yarn.server.resourcemanager.rmcontainer.RMContainerImpl: container_1396342005689_0007_01_000007 Container Transitioned from NEW to ALLOCATED
2014-04-01 02:13:44,676 INFO org.apache.hadoop.yarn.server.resourcemanager.RMAuditLogger: USER=hduser	OPERATION=AM Allocated Container	TARGET=SchedulerApp	RESULT=SUCCESS	APPID=application_1396342005689_0007	CONTAINERID=container_1396342005689_0007_01_000007
2014-04-01 02:13:44,676 INFO org.apache.hadoop.yarn.server.resourcemanager.scheduler.common.fica.FiCaSchedulerNode: Assigned container container_1396342005689_0007_01_000007 of capacity <memory:1024, vCores:1> on host ubuntu:38688, which currently has 5 containers, <memory:6144, vCores:5> used and <memory:2048, vCores:3> available
2014-04-01 02:13:44,676 INFO org.apache.hadoop.yarn.server.resourcemanager.scheduler.capacity.LeafQueue: assignedContainer application=application_1396342005689_0007 container=Container: [ContainerId: container_1396342005689_0007_01_000007, NodeId: ubuntu:38688, NodeHttpAddress: ubuntu:8042, Resource: <memory:1024, vCores:1>, Priority: 10, Token: Token { kind: ContainerToken, service: 127.0.1.1:38688 }, ] containerId=container_1396342005689_0007_01_000007 queue=default: capacity=1.0, absoluteCapacity=1.0, usedResources=<memory:5120, vCores:4>usedCapacity=0.625, absoluteUsedCapacity=0.625, numApps=1, numContainers=4 usedCapacity=0.625 absoluteUsedCapacity=0.625 used=<memory:5120, vCores:4> cluster=<memory:8192, vCores:8>
2014-04-01 02:13:44,676 INFO org.apache.hadoop.yarn.server.resourcemanager.scheduler.capacity.ParentQueue: Re-sorting assigned queue: root.default stats: default: capacity=1.0, absoluteCapacity=1.0, usedResources=<memory:6144, vCores:5>usedCapacity=0.75, absoluteUsedCapacity=0.75, numApps=1, numContainers=5
2014-04-01 02:13:44,677 INFO org.apache.hadoop.yarn.server.resourcemanager.scheduler.capacity.ParentQueue: assignedContainer queue=root usedCapacity=0.75 absoluteUsedCapacity=0.75 used=<memory:6144, vCores:5> cluster=<memory:8192, vCores:8>
2014-04-01 02:13:45,032 INFO org.apache.hadoop.yarn.server.resourcemanager.rmcontainer.RMContainerImpl: container_1396342005689_0007_01_000008 Container Transitioned from NEW to ALLOCATED
2014-04-01 02:13:45,032 INFO org.apache.hadoop.yarn.server.resourcemanager.RMAuditLogger: USER=hduser	OPERATION=AM Allocated Container	TARGET=SchedulerApp	RESULT=SUCCESS	APPID=application_1396342005689_0007	CONTAINERID=container_1396342005689_0007_01_000008
2014-04-01 02:13:45,032 INFO org.apache.hadoop.yarn.server.resourcemanager.scheduler.common.fica.FiCaSchedulerNode: Assigned container container_1396342005689_0007_01_000008 of capacity <memory:1024, vCores:1> on host ubuntu:38688, which currently has 6 containers, <memory:7168, vCores:6> used and <memory:1024, vCores:2> available
2014-04-01 02:13:45,032 INFO org.apache.hadoop.yarn.server.resourcemanager.scheduler.capacity.LeafQueue: assignedContainer application=application_1396342005689_0007 container=Container: [ContainerId: container_1396342005689_0007_01_000008, NodeId: ubuntu:38688, NodeHttpAddress: ubuntu:8042, Resource: <memory:1024, vCores:1>, Priority: 10, Token: Token { kind: ContainerToken, service: 127.0.1.1:38688 }, ] containerId=container_1396342005689_0007_01_000008 queue=default: capacity=1.0, absoluteCapacity=1.0, usedResources=<memory:6144, vCores:5>usedCapacity=0.75, absoluteUsedCapacity=0.75, numApps=1, numContainers=5 usedCapacity=0.75 absoluteUsedCapacity=0.75 used=<memory:6144, vCores:5> cluster=<memory:8192, vCores:8>
2014-04-01 02:13:45,032 INFO org.apache.hadoop.yarn.server.resourcemanager.scheduler.capacity.ParentQueue: Re-sorting assigned queue: root.default stats: default: capacity=1.0, absoluteCapacity=1.0, usedResources=<memory:7168, vCores:6>usedCapacity=0.875, absoluteUsedCapacity=0.875, numApps=1, numContainers=6
2014-04-01 02:13:45,032 INFO org.apache.hadoop.yarn.server.resourcemanager.scheduler.capacity.ParentQueue: assignedContainer queue=root usedCapacity=0.875 absoluteUsedCapacity=0.875 used=<memory:7168, vCores:6> cluster=<memory:8192, vCores:8>
2014-04-01 02:13:45,543 INFO org.apache.hadoop.yarn.server.resourcemanager.rmcontainer.RMContainerImpl: container_1396342005689_0007_01_000007 Container Transitioned from ALLOCATED to ACQUIRED
2014-04-01 02:13:45,543 INFO org.apache.hadoop.yarn.server.resourcemanager.rmcontainer.RMContainerImpl: container_1396342005689_0007_01_000008 Container Transitioned from ALLOCATED to ACQUIRED
2014-04-01 02:13:46,037 INFO org.apache.hadoop.yarn.server.resourcemanager.rmcontainer.RMContainerImpl: container_1396342005689_0007_01_000007 Container Transitioned from ACQUIRED to RUNNING
2014-04-01 02:13:46,037 INFO org.apache.hadoop.yarn.server.resourcemanager.rmcontainer.RMContainerImpl: container_1396342005689_0007_01_000008 Container Transitioned from ACQUIRED to RUNNING
2014-04-01 02:13:46,037 INFO org.apache.hadoop.yarn.server.resourcemanager.rmcontainer.RMContainerImpl: container_1396342005689_0007_01_000004 Container Transitioned from RUNNING to COMPLETED
2014-04-01 02:13:46,037 INFO org.apache.hadoop.yarn.server.resourcemanager.scheduler.common.fica.FiCaSchedulerApp: Completed container: container_1396342005689_0007_01_000004 in state: COMPLETED event:FINISHED
2014-04-01 02:13:46,037 INFO org.apache.hadoop.yarn.server.resourcemanager.RMAuditLogger: USER=hduser	OPERATION=AM Released Container	TARGET=SchedulerApp	RESULT=SUCCESS	APPID=application_1396342005689_0007	CONTAINERID=container_1396342005689_0007_01_000004
2014-04-01 02:13:46,037 INFO org.apache.hadoop.yarn.server.resourcemanager.scheduler.common.fica.FiCaSchedulerNode: Released container container_1396342005689_0007_01_000004 of capacity <memory:1024, vCores:1> on host ubuntu:38688, which currently has 5 containers, <memory:6144, vCores:5> used and <memory:2048, vCores:3> available, release resources=true
2014-04-01 02:13:46,037 INFO org.apache.hadoop.yarn.server.resourcemanager.scheduler.capacity.LeafQueue: default used=<memory:6144, vCores:5> numContainers=5 user=hduser user-resources=<memory:6144, vCores:5>
2014-04-01 02:13:46,037 INFO org.apache.hadoop.yarn.server.resourcemanager.scheduler.capacity.LeafQueue: completedContainer container=Container: [ContainerId: container_1396342005689_0007_01_000004, NodeId: ubuntu:38688, NodeHttpAddress: ubuntu:8042, Resource: <memory:1024, vCores:1>, Priority: 10, Token: Token { kind: ContainerToken, service: 127.0.1.1:38688 }, ] resource=<memory:1024, vCores:1> queue=default: capacity=1.0, absoluteCapacity=1.0, usedResources=<memory:6144, vCores:5>usedCapacity=0.75, absoluteUsedCapacity=0.75, numApps=1, numContainers=5 usedCapacity=0.75 absoluteUsedCapacity=0.75 used=<memory:6144, vCores:5> cluster=<memory:8192, vCores:8>
2014-04-01 02:13:46,037 INFO org.apache.hadoop.yarn.server.resourcemanager.scheduler.capacity.ParentQueue: completedContainer queue=root usedCapacity=0.75 absoluteUsedCapacity=0.75 used=<memory:6144, vCores:5> cluster=<memory:8192, vCores:8>
2014-04-01 02:13:46,037 INFO org.apache.hadoop.yarn.server.resourcemanager.scheduler.capacity.ParentQueue: Re-sorting completed queue: root.default stats: default: capacity=1.0, absoluteCapacity=1.0, usedResources=<memory:6144, vCores:5>usedCapacity=0.75, absoluteUsedCapacity=0.75, numApps=1, numContainers=5
2014-04-01 02:13:46,037 INFO org.apache.hadoop.yarn.server.resourcemanager.scheduler.capacity.CapacityScheduler: Application appattempt_1396342005689_0007_000001 released container container_1396342005689_0007_01_000004 on node: host: ubuntu:38688 #containers=5 available=2048 used=6144 with event: FINISHED
2014-04-01 02:13:46,037 INFO org.apache.hadoop.yarn.server.resourcemanager.rmcontainer.RMContainerImpl: container_1396342005689_0007_01_000009 Container Transitioned from NEW to ALLOCATED
2014-04-01 02:13:46,037 INFO org.apache.hadoop.yarn.server.resourcemanager.RMAuditLogger: USER=hduser	OPERATION=AM Allocated Container	TARGET=SchedulerApp	RESULT=SUCCESS	APPID=application_1396342005689_0007	CONTAINERID=container_1396342005689_0007_01_000009
2014-04-01 02:13:46,038 INFO org.apache.hadoop.yarn.server.resourcemanager.scheduler.common.fica.FiCaSchedulerNode: Assigned container container_1396342005689_0007_01_000009 of capacity <memory:1024, vCores:1> on host ubuntu:38688, which currently has 6 containers, <memory:7168, vCores:6> used and <memory:1024, vCores:2> available
2014-04-01 02:13:46,038 INFO org.apache.hadoop.yarn.server.resourcemanager.scheduler.capacity.LeafQueue: assignedContainer application=application_1396342005689_0007 container=Container: [ContainerId: container_1396342005689_0007_01_000009, NodeId: ubuntu:38688, NodeHttpAddress: ubuntu:8042, Resource: <memory:1024, vCores:1>, Priority: 10, Token: Token { kind: ContainerToken, service: 127.0.1.1:38688 }, ] containerId=container_1396342005689_0007_01_000009 queue=default: capacity=1.0, absoluteCapacity=1.0, usedResources=<memory:6144, vCores:5>usedCapacity=0.75, absoluteUsedCapacity=0.75, numApps=1, numContainers=5 usedCapacity=0.75 absoluteUsedCapacity=0.75 used=<memory:6144, vCores:5> cluster=<memory:8192, vCores:8>
2014-04-01 02:13:46,038 INFO org.apache.hadoop.yarn.server.resourcemanager.scheduler.capacity.ParentQueue: Re-sorting assigned queue: root.default stats: default: capacity=1.0, absoluteCapacity=1.0, usedResources=<memory:7168, vCores:6>usedCapacity=0.875, absoluteUsedCapacity=0.875, numApps=1, numContainers=6
2014-04-01 02:13:46,038 INFO org.apache.hadoop.yarn.server.resourcemanager.scheduler.capacity.ParentQueue: assignedContainer queue=root usedCapacity=0.875 absoluteUsedCapacity=0.875 used=<memory:7168, vCores:6> cluster=<memory:8192, vCores:8>
2014-04-01 02:13:46,062 INFO org.apache.hadoop.yarn.server.resourcemanager.rmcontainer.RMContainerImpl: container_1396342005689_0007_01_000010 Container Transitioned from NEW to ALLOCATED
2014-04-01 02:13:46,062 INFO org.apache.hadoop.yarn.server.resourcemanager.RMAuditLogger: USER=hduser	OPERATION=AM Allocated Container	TARGET=SchedulerApp	RESULT=SUCCESS	APPID=application_1396342005689_0007	CONTAINERID=container_1396342005689_0007_01_000010
2014-04-01 02:13:46,063 INFO org.apache.hadoop.yarn.server.resourcemanager.scheduler.common.fica.FiCaSchedulerNode: Assigned container container_1396342005689_0007_01_000010 of capacity <memory:1024, vCores:1> on host ubuntu:38688, which currently has 7 containers, <memory:8192, vCores:7> used and <memory:0, vCores:1> available
2014-04-01 02:13:46,063 INFO org.apache.hadoop.yarn.server.resourcemanager.scheduler.capacity.LeafQueue: assignedContainer application=application_1396342005689_0007 container=Container: [ContainerId: container_1396342005689_0007_01_000010, NodeId: ubuntu:38688, NodeHttpAddress: ubuntu:8042, Resource: <memory:1024, vCores:1>, Priority: 10, Token: Token { kind: ContainerToken, service: 127.0.1.1:38688 }, ] containerId=container_1396342005689_0007_01_000010 queue=default: capacity=1.0, absoluteCapacity=1.0, usedResources=<memory:7168, vCores:6>usedCapacity=0.875, absoluteUsedCapacity=0.875, numApps=1, numContainers=6 usedCapacity=0.875 absoluteUsedCapacity=0.875 used=<memory:7168, vCores:6> cluster=<memory:8192, vCores:8>
2014-04-01 02:13:46,063 INFO org.apache.hadoop.yarn.server.resourcemanager.scheduler.capacity.ParentQueue: Re-sorting assigned queue: root.default stats: default: capacity=1.0, absoluteCapacity=1.0, usedResources=<memory:8192, vCores:7>usedCapacity=1.0, absoluteUsedCapacity=1.0, numApps=1, numContainers=7
2014-04-01 02:13:46,063 INFO org.apache.hadoop.yarn.server.resourcemanager.scheduler.capacity.ParentQueue: assignedContainer queue=root usedCapacity=1.0 absoluteUsedCapacity=1.0 used=<memory:8192, vCores:7> cluster=<memory:8192, vCores:8>
2014-04-01 02:13:46,547 INFO org.apache.hadoop.yarn.server.resourcemanager.rmcontainer.RMContainerImpl: container_1396342005689_0007_01_000009 Container Transitioned from ALLOCATED to ACQUIRED
2014-04-01 02:13:46,547 INFO org.apache.hadoop.yarn.server.resourcemanager.rmcontainer.RMContainerImpl: container_1396342005689_0007_01_000010 Container Transitioned from ALLOCATED to ACQUIRED
2014-04-01 02:13:47,067 INFO org.apache.hadoop.yarn.server.resourcemanager.rmcontainer.RMContainerImpl: container_1396342005689_0007_01_000009 Container Transitioned from ACQUIRED to RUNNING
2014-04-01 02:13:47,067 INFO org.apache.hadoop.yarn.server.resourcemanager.rmcontainer.RMContainerImpl: container_1396342005689_0007_01_000010 Container Transitioned from ACQUIRED to RUNNING
2014-04-01 02:13:47,067 INFO org.apache.hadoop.yarn.server.resourcemanager.rmcontainer.RMContainerImpl: container_1396342005689_0007_01_000005 Container Transitioned from RUNNING to COMPLETED
2014-04-01 02:13:47,067 INFO org.apache.hadoop.yarn.server.resourcemanager.scheduler.common.fica.FiCaSchedulerApp: Completed container: container_1396342005689_0007_01_000005 in state: COMPLETED event:FINISHED
2014-04-01 02:13:47,067 INFO org.apache.hadoop.yarn.server.resourcemanager.RMAuditLogger: USER=hduser	OPERATION=AM Released Container	TARGET=SchedulerApp	RESULT=SUCCESS	APPID=application_1396342005689_0007	CONTAINERID=container_1396342005689_0007_01_000005
2014-04-01 02:13:47,067 INFO org.apache.hadoop.yarn.server.resourcemanager.scheduler.common.fica.FiCaSchedulerNode: Released container container_1396342005689_0007_01_000005 of capacity <memory:1024, vCores:1> on host ubuntu:38688, which currently has 6 containers, <memory:7168, vCores:6> used and <memory:1024, vCores:2> available, release resources=true
2014-04-01 02:13:47,067 INFO org.apache.hadoop.yarn.server.resourcemanager.scheduler.capacity.LeafQueue: default used=<memory:7168, vCores:6> numContainers=6 user=hduser user-resources=<memory:7168, vCores:6>
2014-04-01 02:13:47,067 INFO org.apache.hadoop.yarn.server.resourcemanager.scheduler.capacity.LeafQueue: completedContainer container=Container: [ContainerId: container_1396342005689_0007_01_000005, NodeId: ubuntu:38688, NodeHttpAddress: ubuntu:8042, Resource: <memory:1024, vCores:1>, Priority: 10, Token: Token { kind: ContainerToken, service: 127.0.1.1:38688 }, ] resource=<memory:1024, vCores:1> queue=default: capacity=1.0, absoluteCapacity=1.0, usedResources=<memory:7168, vCores:6>usedCapacity=0.875, absoluteUsedCapacity=0.875, numApps=1, numContainers=6 usedCapacity=0.875 absoluteUsedCapacity=0.875 used=<memory:7168, vCores:6> cluster=<memory:8192, vCores:8>
2014-04-01 02:13:47,067 INFO org.apache.hadoop.yarn.server.resourcemanager.scheduler.capacity.ParentQueue: completedContainer queue=root usedCapacity=0.875 absoluteUsedCapacity=0.875 used=<memory:7168, vCores:6> cluster=<memory:8192, vCores:8>
2014-04-01 02:13:47,067 INFO org.apache.hadoop.yarn.server.resourcemanager.scheduler.capacity.ParentQueue: Re-sorting completed queue: root.default stats: default: capacity=1.0, absoluteCapacity=1.0, usedResources=<memory:7168, vCores:6>usedCapacity=0.875, absoluteUsedCapacity=0.875, numApps=1, numContainers=6
2014-04-01 02:13:47,067 INFO org.apache.hadoop.yarn.server.resourcemanager.scheduler.capacity.CapacityScheduler: Application appattempt_1396342005689_0007_000001 released container container_1396342005689_0007_01_000005 on node: host: ubuntu:38688 #containers=6 available=1024 used=7168 with event: FINISHED
2014-04-01 02:13:47,068 INFO org.apache.hadoop.yarn.server.resourcemanager.rmcontainer.RMContainerImpl: container_1396342005689_0007_01_000011 Container Transitioned from NEW to ALLOCATED
2014-04-01 02:13:47,068 INFO org.apache.hadoop.yarn.server.resourcemanager.RMAuditLogger: USER=hduser	OPERATION=AM Allocated Container	TARGET=SchedulerApp	RESULT=SUCCESS	APPID=application_1396342005689_0007	CONTAINERID=container_1396342005689_0007_01_000011
2014-04-01 02:13:47,068 INFO org.apache.hadoop.yarn.server.resourcemanager.scheduler.common.fica.FiCaSchedulerNode: Assigned container container_1396342005689_0007_01_000011 of capacity <memory:1024, vCores:1> on host ubuntu:38688, which currently has 7 containers, <memory:8192, vCores:7> used and <memory:0, vCores:1> available
2014-04-01 02:13:47,068 INFO org.apache.hadoop.yarn.server.resourcemanager.scheduler.capacity.LeafQueue: assignedContainer application=application_1396342005689_0007 container=Container: [ContainerId: container_1396342005689_0007_01_000011, NodeId: ubuntu:38688, NodeHttpAddress: ubuntu:8042, Resource: <memory:1024, vCores:1>, Priority: 10, Token: Token { kind: ContainerToken, service: 127.0.1.1:38688 }, ] containerId=container_1396342005689_0007_01_000011 queue=default: capacity=1.0, absoluteCapacity=1.0, usedResources=<memory:7168, vCores:6>usedCapacity=0.875, absoluteUsedCapacity=0.875, numApps=1, numContainers=6 usedCapacity=0.875 absoluteUsedCapacity=0.875 used=<memory:7168, vCores:6> cluster=<memory:8192, vCores:8>
2014-04-01 02:13:47,068 INFO org.apache.hadoop.yarn.server.resourcemanager.scheduler.capacity.ParentQueue: Re-sorting assigned queue: root.default stats: default: capacity=1.0, absoluteCapacity=1.0, usedResources=<memory:8192, vCores:7>usedCapacity=1.0, absoluteUsedCapacity=1.0, numApps=1, numContainers=7
2014-04-01 02:13:47,068 INFO org.apache.hadoop.yarn.server.resourcemanager.scheduler.capacity.ParentQueue: assignedContainer queue=root usedCapacity=1.0 absoluteUsedCapacity=1.0 used=<memory:8192, vCores:7> cluster=<memory:8192, vCores:8>
2014-04-01 02:13:47,551 INFO org.apache.hadoop.yarn.server.resourcemanager.scheduler.AppSchedulingInfo: checking for deactivate... 
2014-04-01 02:13:47,552 INFO org.apache.hadoop.yarn.server.resourcemanager.rmcontainer.RMContainerImpl: container_1396342005689_0007_01_000011 Container Transitioned from ALLOCATED to ACQUIRED
2014-04-01 02:13:48,558 INFO org.apache.hadoop.yarn.server.resourcemanager.rmcontainer.RMContainerImpl: container_1396342005689_0007_01_000011 Container Transitioned from ACQUIRED to RELEASED
2014-04-01 02:13:48,558 INFO org.apache.hadoop.yarn.server.resourcemanager.scheduler.common.fica.FiCaSchedulerApp: Completed container: container_1396342005689_0007_01_000011 in state: RELEASED event:RELEASED
2014-04-01 02:13:48,559 INFO org.apache.hadoop.yarn.server.resourcemanager.RMAuditLogger: USER=hduser	IP=127.0.0.1	OPERATION=AM Released Container	TARGET=SchedulerApp	RESULT=SUCCESS	APPID=application_1396342005689_0007	CONTAINERID=container_1396342005689_0007_01_000011
2014-04-01 02:13:48,559 INFO org.apache.hadoop.yarn.server.resourcemanager.scheduler.common.fica.FiCaSchedulerNode: Released container container_1396342005689_0007_01_000011 of capacity <memory:1024, vCores:1> on host ubuntu:38688, which currently has 6 containers, <memory:7168, vCores:6> used and <memory:1024, vCores:2> available, release resources=true
2014-04-01 02:13:48,559 INFO org.apache.hadoop.yarn.server.resourcemanager.scheduler.capacity.LeafQueue: default used=<memory:7168, vCores:6> numContainers=6 user=hduser user-resources=<memory:7168, vCores:6>
2014-04-01 02:13:48,559 INFO org.apache.hadoop.yarn.server.resourcemanager.scheduler.capacity.LeafQueue: completedContainer container=Container: [ContainerId: container_1396342005689_0007_01_000011, NodeId: ubuntu:38688, NodeHttpAddress: ubuntu:8042, Resource: <memory:1024, vCores:1>, Priority: 10, Token: Token { kind: ContainerToken, service: 127.0.1.1:38688 }, ] resource=<memory:1024, vCores:1> queue=default: capacity=1.0, absoluteCapacity=1.0, usedResources=<memory:7168, vCores:6>usedCapacity=0.875, absoluteUsedCapacity=0.875, numApps=1, numContainers=6 usedCapacity=0.875 absoluteUsedCapacity=0.875 used=<memory:7168, vCores:6> cluster=<memory:8192, vCores:8>
2014-04-01 02:13:48,559 INFO org.apache.hadoop.yarn.server.resourcemanager.scheduler.capacity.ParentQueue: completedContainer queue=root usedCapacity=0.875 absoluteUsedCapacity=0.875 used=<memory:7168, vCores:6> cluster=<memory:8192, vCores:8>
2014-04-01 02:13:48,559 INFO org.apache.hadoop.yarn.server.resourcemanager.scheduler.capacity.ParentQueue: Re-sorting completed queue: root.default stats: default: capacity=1.0, absoluteCapacity=1.0, usedResources=<memory:7168, vCores:6>usedCapacity=0.875, absoluteUsedCapacity=0.875, numApps=1, numContainers=6
2014-04-01 02:13:48,559 INFO org.apache.hadoop.yarn.server.resourcemanager.scheduler.capacity.CapacityScheduler: Application appattempt_1396342005689_0007_000001 released container container_1396342005689_0007_01_000011 on node: host: ubuntu:38688 #containers=6 available=1024 used=7168 with event: RELEASED
2014-04-01 02:13:48,559 INFO org.apache.hadoop.yarn.server.resourcemanager.scheduler.AppSchedulingInfo: checking for deactivate... 
2014-04-01 02:13:49,224 INFO org.apache.hadoop.yarn.server.resourcemanager.rmcontainer.RMContainerImpl: container_1396342005689_0007_01_000006 Container Transitioned from RUNNING to COMPLETED
2014-04-01 02:13:49,225 INFO org.apache.hadoop.yarn.server.resourcemanager.scheduler.common.fica.FiCaSchedulerApp: Completed container: container_1396342005689_0007_01_000006 in state: COMPLETED event:FINISHED
2014-04-01 02:13:49,225 INFO org.apache.hadoop.yarn.server.resourcemanager.RMAuditLogger: USER=hduser	OPERATION=AM Released Container	TARGET=SchedulerApp	RESULT=SUCCESS	APPID=application_1396342005689_0007	CONTAINERID=container_1396342005689_0007_01_000006
2014-04-01 02:13:49,225 INFO org.apache.hadoop.yarn.server.resourcemanager.scheduler.common.fica.FiCaSchedulerNode: Released container container_1396342005689_0007_01_000006 of capacity <memory:1024, vCores:1> on host ubuntu:38688, which currently has 5 containers, <memory:6144, vCores:5> used and <memory:2048, vCores:3> available, release resources=true
2014-04-01 02:13:49,225 INFO org.apache.hadoop.yarn.server.resourcemanager.scheduler.capacity.LeafQueue: default used=<memory:6144, vCores:5> numContainers=5 user=hduser user-resources=<memory:6144, vCores:5>
2014-04-01 02:13:49,225 INFO org.apache.hadoop.yarn.server.resourcemanager.scheduler.capacity.LeafQueue: completedContainer container=Container: [ContainerId: container_1396342005689_0007_01_000006, NodeId: ubuntu:38688, NodeHttpAddress: ubuntu:8042, Resource: <memory:1024, vCores:1>, Priority: 10, Token: Token { kind: ContainerToken, service: 127.0.1.1:38688 }, ] resource=<memory:1024, vCores:1> queue=default: capacity=1.0, absoluteCapacity=1.0, usedResources=<memory:6144, vCores:5>usedCapacity=0.75, absoluteUsedCapacity=0.75, numApps=1, numContainers=5 usedCapacity=0.75 absoluteUsedCapacity=0.75 used=<memory:6144, vCores:5> cluster=<memory:8192, vCores:8>
2014-04-01 02:13:49,225 INFO org.apache.hadoop.yarn.server.resourcemanager.scheduler.capacity.ParentQueue: completedContainer queue=root usedCapacity=0.75 absoluteUsedCapacity=0.75 used=<memory:6144, vCores:5> cluster=<memory:8192, vCores:8>
2014-04-01 02:13:49,225 INFO org.apache.hadoop.yarn.server.resourcemanager.scheduler.capacity.ParentQueue: Re-sorting completed queue: root.default stats: default: capacity=1.0, absoluteCapacity=1.0, usedResources=<memory:6144, vCores:5>usedCapacity=0.75, absoluteUsedCapacity=0.75, numApps=1, numContainers=5
2014-04-01 02:13:49,225 INFO org.apache.hadoop.yarn.server.resourcemanager.scheduler.capacity.CapacityScheduler: Application appattempt_1396342005689_0007_000001 released container container_1396342005689_0007_01_000006 on node: host: ubuntu:38688 #containers=5 available=2048 used=6144 with event: FINISHED
2014-04-01 02:13:50,291 INFO org.apache.hadoop.yarn.server.resourcemanager.rmcontainer.RMContainerImpl: container_1396342005689_0007_01_000007 Container Transitioned from RUNNING to COMPLETED
2014-04-01 02:13:50,291 INFO org.apache.hadoop.yarn.server.resourcemanager.scheduler.common.fica.FiCaSchedulerApp: Completed container: container_1396342005689_0007_01_000007 in state: COMPLETED event:FINISHED
2014-04-01 02:13:50,291 INFO org.apache.hadoop.yarn.server.resourcemanager.RMAuditLogger: USER=hduser	OPERATION=AM Released Container	TARGET=SchedulerApp	RESULT=SUCCESS	APPID=application_1396342005689_0007	CONTAINERID=container_1396342005689_0007_01_000007
2014-04-01 02:13:50,291 INFO org.apache.hadoop.yarn.server.resourcemanager.scheduler.common.fica.FiCaSchedulerNode: Released container container_1396342005689_0007_01_000007 of capacity <memory:1024, vCores:1> on host ubuntu:38688, which currently has 4 containers, <memory:5120, vCores:4> used and <memory:3072, vCores:4> available, release resources=true
2014-04-01 02:13:50,291 INFO org.apache.hadoop.yarn.server.resourcemanager.scheduler.capacity.LeafQueue: default used=<memory:5120, vCores:4> numContainers=4 user=hduser user-resources=<memory:5120, vCores:4>
2014-04-01 02:13:50,291 INFO org.apache.hadoop.yarn.server.resourcemanager.scheduler.capacity.LeafQueue: completedContainer container=Container: [ContainerId: container_1396342005689_0007_01_000007, NodeId: ubuntu:38688, NodeHttpAddress: ubuntu:8042, Resource: <memory:1024, vCores:1>, Priority: 10, Token: Token { kind: ContainerToken, service: 127.0.1.1:38688 }, ] resource=<memory:1024, vCores:1> queue=default: capacity=1.0, absoluteCapacity=1.0, usedResources=<memory:5120, vCores:4>usedCapacity=0.625, absoluteUsedCapacity=0.625, numApps=1, numContainers=4 usedCapacity=0.625 absoluteUsedCapacity=0.625 used=<memory:5120, vCores:4> cluster=<memory:8192, vCores:8>
2014-04-01 02:13:50,291 INFO org.apache.hadoop.yarn.server.resourcemanager.scheduler.capacity.ParentQueue: completedContainer queue=root usedCapacity=0.625 absoluteUsedCapacity=0.625 used=<memory:5120, vCores:4> cluster=<memory:8192, vCores:8>
2014-04-01 02:13:50,291 INFO org.apache.hadoop.yarn.server.resourcemanager.scheduler.capacity.ParentQueue: Re-sorting completed queue: root.default stats: default: capacity=1.0, absoluteCapacity=1.0, usedResources=<memory:5120, vCores:4>usedCapacity=0.625, absoluteUsedCapacity=0.625, numApps=1, numContainers=4
2014-04-01 02:13:50,291 INFO org.apache.hadoop.yarn.server.resourcemanager.scheduler.capacity.CapacityScheduler: Application appattempt_1396342005689_0007_000001 released container container_1396342005689_0007_01_000007 on node: host: ubuntu:38688 #containers=4 available=3072 used=5120 with event: FINISHED
2014-04-01 02:13:50,969 INFO org.apache.hadoop.yarn.server.resourcemanager.rmcontainer.RMContainerImpl: container_1396342005689_0007_01_000008 Container Transitioned from RUNNING to COMPLETED
2014-04-01 02:13:50,969 INFO org.apache.hadoop.yarn.server.resourcemanager.scheduler.common.fica.FiCaSchedulerApp: Completed container: container_1396342005689_0007_01_000008 in state: COMPLETED event:FINISHED
2014-04-01 02:13:50,969 INFO org.apache.hadoop.yarn.server.resourcemanager.RMAuditLogger: USER=hduser	OPERATION=AM Released Container	TARGET=SchedulerApp	RESULT=SUCCESS	APPID=application_1396342005689_0007	CONTAINERID=container_1396342005689_0007_01_000008
2014-04-01 02:13:50,969 INFO org.apache.hadoop.yarn.server.resourcemanager.scheduler.common.fica.FiCaSchedulerNode: Released container container_1396342005689_0007_01_000008 of capacity <memory:1024, vCores:1> on host ubuntu:38688, which currently has 3 containers, <memory:4096, vCores:3> used and <memory:4096, vCores:5> available, release resources=true
2014-04-01 02:13:50,969 INFO org.apache.hadoop.yarn.server.resourcemanager.scheduler.capacity.LeafQueue: default used=<memory:4096, vCores:3> numContainers=3 user=hduser user-resources=<memory:4096, vCores:3>
2014-04-01 02:13:50,969 INFO org.apache.hadoop.yarn.server.resourcemanager.scheduler.capacity.LeafQueue: completedContainer container=Container: [ContainerId: container_1396342005689_0007_01_000008, NodeId: ubuntu:38688, NodeHttpAddress: ubuntu:8042, Resource: <memory:1024, vCores:1>, Priority: 10, Token: Token { kind: ContainerToken, service: 127.0.1.1:38688 }, ] resource=<memory:1024, vCores:1> queue=default: capacity=1.0, absoluteCapacity=1.0, usedResources=<memory:4096, vCores:3>usedCapacity=0.5, absoluteUsedCapacity=0.5, numApps=1, numContainers=3 usedCapacity=0.5 absoluteUsedCapacity=0.5 used=<memory:4096, vCores:3> cluster=<memory:8192, vCores:8>
2014-04-01 02:13:50,969 INFO org.apache.hadoop.yarn.server.resourcemanager.scheduler.capacity.ParentQueue: completedContainer queue=root usedCapacity=0.5 absoluteUsedCapacity=0.5 used=<memory:4096, vCores:3> cluster=<memory:8192, vCores:8>
2014-04-01 02:13:50,969 INFO org.apache.hadoop.yarn.server.resourcemanager.scheduler.capacity.ParentQueue: Re-sorting completed queue: root.default stats: default: capacity=1.0, absoluteCapacity=1.0, usedResources=<memory:4096, vCores:3>usedCapacity=0.5, absoluteUsedCapacity=0.5, numApps=1, numContainers=3
2014-04-01 02:13:50,969 INFO org.apache.hadoop.yarn.server.resourcemanager.scheduler.capacity.CapacityScheduler: Application appattempt_1396342005689_0007_000001 released container container_1396342005689_0007_01_000008 on node: host: ubuntu:38688 #containers=3 available=4096 used=4096 with event: FINISHED
2014-04-01 02:13:51,072 INFO org.apache.hadoop.yarn.server.resourcemanager.rmcontainer.RMContainerImpl: container_1396342005689_0007_01_000010 Container Transitioned from RUNNING to COMPLETED
2014-04-01 02:13:51,072 INFO org.apache.hadoop.yarn.server.resourcemanager.scheduler.common.fica.FiCaSchedulerApp: Completed container: container_1396342005689_0007_01_000010 in state: COMPLETED event:FINISHED
2014-04-01 02:13:51,072 INFO org.apache.hadoop.yarn.server.resourcemanager.RMAuditLogger: USER=hduser	OPERATION=AM Released Container	TARGET=SchedulerApp	RESULT=SUCCESS	APPID=application_1396342005689_0007	CONTAINERID=container_1396342005689_0007_01_000010
2014-04-01 02:13:51,072 INFO org.apache.hadoop.yarn.server.resourcemanager.scheduler.common.fica.FiCaSchedulerNode: Released container container_1396342005689_0007_01_000010 of capacity <memory:1024, vCores:1> on host ubuntu:38688, which currently has 2 containers, <memory:3072, vCores:2> used and <memory:5120, vCores:6> available, release resources=true
2014-04-01 02:13:51,072 INFO org.apache.hadoop.yarn.server.resourcemanager.scheduler.capacity.LeafQueue: default used=<memory:3072, vCores:2> numContainers=2 user=hduser user-resources=<memory:3072, vCores:2>
2014-04-01 02:13:51,072 INFO org.apache.hadoop.yarn.server.resourcemanager.scheduler.capacity.LeafQueue: completedContainer container=Container: [ContainerId: container_1396342005689_0007_01_000010, NodeId: ubuntu:38688, NodeHttpAddress: ubuntu:8042, Resource: <memory:1024, vCores:1>, Priority: 10, Token: Token { kind: ContainerToken, service: 127.0.1.1:38688 }, ] resource=<memory:1024, vCores:1> queue=default: capacity=1.0, absoluteCapacity=1.0, usedResources=<memory:3072, vCores:2>usedCapacity=0.375, absoluteUsedCapacity=0.375, numApps=1, numContainers=2 usedCapacity=0.375 absoluteUsedCapacity=0.375 used=<memory:3072, vCores:2> cluster=<memory:8192, vCores:8>
2014-04-01 02:13:51,072 INFO org.apache.hadoop.yarn.server.resourcemanager.scheduler.capacity.ParentQueue: completedContainer queue=root usedCapacity=0.375 absoluteUsedCapacity=0.375 used=<memory:3072, vCores:2> cluster=<memory:8192, vCores:8>
2014-04-01 02:13:51,072 INFO org.apache.hadoop.yarn.server.resourcemanager.scheduler.capacity.ParentQueue: Re-sorting completed queue: root.default stats: default: capacity=1.0, absoluteCapacity=1.0, usedResources=<memory:3072, vCores:2>usedCapacity=0.375, absoluteUsedCapacity=0.375, numApps=1, numContainers=2
2014-04-01 02:13:51,072 INFO org.apache.hadoop.yarn.server.resourcemanager.scheduler.capacity.CapacityScheduler: Application appattempt_1396342005689_0007_000001 released container container_1396342005689_0007_01_000010 on node: host: ubuntu:38688 #containers=2 available=5120 used=3072 with event: FINISHED
2014-04-01 02:13:51,134 INFO org.apache.hadoop.yarn.server.resourcemanager.rmapp.attempt.RMAppAttemptImpl: appattempt_1396342005689_0007_000001 State change from RUNNING to FINISHING
2014-04-01 02:13:51,134 INFO org.apache.hadoop.yarn.server.resourcemanager.rmapp.RMAppImpl: Removing application with id application_1396342005689_0007
2014-04-01 02:13:51,134 INFO org.apache.hadoop.yarn.server.resourcemanager.rmapp.RMAppImpl: application_1396342005689_0007 State change from RUNNING to REMOVING
2014-04-01 02:13:51,134 INFO org.apache.hadoop.yarn.server.resourcemanager.recovery.RMStateStore: Removing info for app: application_1396342005689_0007
2014-04-01 02:13:51,135 INFO org.apache.hadoop.yarn.server.resourcemanager.rmapp.RMAppImpl: application_1396342005689_0007 State change from REMOVING to FINISHING
2014-04-01 02:13:52,076 INFO org.apache.hadoop.yarn.server.resourcemanager.rmcontainer.RMContainerImpl: container_1396342005689_0007_01_000009 Container Transitioned from RUNNING to COMPLETED
2014-04-01 02:13:52,076 INFO org.apache.hadoop.yarn.server.resourcemanager.scheduler.common.fica.FiCaSchedulerApp: Completed container: container_1396342005689_0007_01_000009 in state: COMPLETED event:FINISHED
2014-04-01 02:13:52,076 INFO org.apache.hadoop.yarn.server.resourcemanager.RMAuditLogger: USER=hduser	OPERATION=AM Released Container	TARGET=SchedulerApp	RESULT=SUCCESS	APPID=application_1396342005689_0007	CONTAINERID=container_1396342005689_0007_01_000009
2014-04-01 02:13:52,076 INFO org.apache.hadoop.yarn.server.resourcemanager.scheduler.common.fica.FiCaSchedulerNode: Released container container_1396342005689_0007_01_000009 of capacity <memory:1024, vCores:1> on host ubuntu:38688, which currently has 1 containers, <memory:2048, vCores:1> used and <memory:6144, vCores:7> available, release resources=true
2014-04-01 02:13:52,076 INFO org.apache.hadoop.yarn.server.resourcemanager.scheduler.capacity.LeafQueue: default used=<memory:2048, vCores:1> numContainers=1 user=hduser user-resources=<memory:2048, vCores:1>
2014-04-01 02:13:52,076 INFO org.apache.hadoop.yarn.server.resourcemanager.scheduler.capacity.LeafQueue: completedContainer container=Container: [ContainerId: container_1396342005689_0007_01_000009, NodeId: ubuntu:38688, NodeHttpAddress: ubuntu:8042, Resource: <memory:1024, vCores:1>, Priority: 10, Token: Token { kind: ContainerToken, service: 127.0.1.1:38688 }, ] resource=<memory:1024, vCores:1> queue=default: capacity=1.0, absoluteCapacity=1.0, usedResources=<memory:2048, vCores:1>usedCapacity=0.25, absoluteUsedCapacity=0.25, numApps=1, numContainers=1 usedCapacity=0.25 absoluteUsedCapacity=0.25 used=<memory:2048, vCores:1> cluster=<memory:8192, vCores:8>
2014-04-01 02:13:52,076 INFO org.apache.hadoop.yarn.server.resourcemanager.scheduler.capacity.ParentQueue: completedContainer queue=root usedCapacity=0.25 absoluteUsedCapacity=0.25 used=<memory:2048, vCores:1> cluster=<memory:8192, vCores:8>
2014-04-01 02:13:52,076 INFO org.apache.hadoop.yarn.server.resourcemanager.scheduler.capacity.ParentQueue: Re-sorting completed queue: root.default stats: default: capacity=1.0, absoluteCapacity=1.0, usedResources=<memory:2048, vCores:1>usedCapacity=0.25, absoluteUsedCapacity=0.25, numApps=1, numContainers=1
2014-04-01 02:13:52,076 INFO org.apache.hadoop.yarn.server.resourcemanager.scheduler.capacity.CapacityScheduler: Application appattempt_1396342005689_0007_000001 released container container_1396342005689_0007_01_000009 on node: host: ubuntu:38688 #containers=1 available=6144 used=2048 with event: FINISHED
2014-04-01 02:13:53,079 INFO org.apache.hadoop.yarn.server.resourcemanager.rmcontainer.RMContainerImpl: container_1396342005689_0007_01_000001 Container Transitioned from RUNNING to COMPLETED
2014-04-01 02:13:53,079 INFO org.apache.hadoop.yarn.server.resourcemanager.ApplicationMasterService: Unregistering app attempt : appattempt_1396342005689_0007_000001
2014-04-01 02:13:53,079 INFO org.apache.hadoop.yarn.server.resourcemanager.scheduler.common.fica.FiCaSchedulerApp: Completed container: container_1396342005689_0007_01_000001 in state: COMPLETED event:FINISHED
2014-04-01 02:13:53,079 INFO org.apache.hadoop.yarn.server.resourcemanager.RMAuditLogger: USER=hduser	OPERATION=AM Released Container	TARGET=SchedulerApp	RESULT=SUCCESS	APPID=application_1396342005689_0007	CONTAINERID=container_1396342005689_0007_01_000001
2014-04-01 02:13:53,079 INFO org.apache.hadoop.yarn.server.resourcemanager.rmapp.attempt.RMAppAttemptImpl: appattempt_1396342005689_0007_000001 State change from FINISHING to FINISHED
2014-04-01 02:13:53,080 INFO org.apache.hadoop.yarn.server.resourcemanager.scheduler.common.fica.FiCaSchedulerNode: Released container container_1396342005689_0007_01_000001 of capacity <memory:2048, vCores:1> on host ubuntu:38688, which currently has 0 containers, <memory:0, vCores:0> used and <memory:8192, vCores:8> available, release resources=true
2014-04-01 02:13:53,080 INFO org.apache.hadoop.yarn.server.resourcemanager.rmapp.RMAppImpl: application_1396342005689_0007 State change from FINISHING to FINISHED
2014-04-01 02:13:53,080 INFO org.apache.hadoop.yarn.server.resourcemanager.scheduler.capacity.LeafQueue: default used=<memory:0, vCores:0> numContainers=0 user=hduser user-resources=<memory:0, vCores:0>
2014-04-01 02:13:53,080 INFO org.apache.hadoop.yarn.server.resourcemanager.RMAuditLogger: USER=hduser	OPERATION=Application Finished - Succeeded	TARGET=RMAppManager	RESULT=SUCCESS	APPID=application_1396342005689_0007
2014-04-01 02:13:53,080 INFO org.apache.hadoop.yarn.server.resourcemanager.amlauncher.AMLauncher: Cleaning master appattempt_1396342005689_0007_000001
2014-04-01 02:13:53,080 INFO org.apache.hadoop.yarn.server.resourcemanager.RMAppManager$ApplicationSummary: appId=application_1396342005689_0007,name=base||path:/in||num reduce:8,user=hduser,queue=default,state=FINISHED,trackingUrl=ubuntu:8088/proxy/application_1396342005689_0007/jobhistory/job/job_1396342005689_0007,appMasterHost=ubuntu,startTime=1396343611633,finishTime=1396343631135,finalStatus=SUCCEEDED
2014-04-01 02:13:53,080 INFO org.apache.hadoop.yarn.server.resourcemanager.scheduler.capacity.LeafQueue: completedContainer container=Container: [ContainerId: container_1396342005689_0007_01_000001, NodeId: ubuntu:38688, NodeHttpAddress: ubuntu:8042, Resource: <memory:2048, vCores:1>, Priority: 0, Token: Token { kind: ContainerToken, service: 127.0.1.1:38688 }, ] resource=<memory:2048, vCores:1> queue=default: capacity=1.0, absoluteCapacity=1.0, usedResources=<memory:0, vCores:0>usedCapacity=0.0, absoluteUsedCapacity=0.0, numApps=1, numContainers=0 usedCapacity=0.0 absoluteUsedCapacity=0.0 used=<memory:0, vCores:0> cluster=<memory:8192, vCores:8>
2014-04-01 02:13:53,080 INFO org.apache.hadoop.yarn.server.resourcemanager.scheduler.capacity.ParentQueue: completedContainer queue=root usedCapacity=0.0 absoluteUsedCapacity=0.0 used=<memory:0, vCores:0> cluster=<memory:8192, vCores:8>
2014-04-01 02:13:53,081 INFO org.apache.hadoop.yarn.server.resourcemanager.scheduler.capacity.ParentQueue: Re-sorting completed queue: root.default stats: default: capacity=1.0, absoluteCapacity=1.0, usedResources=<memory:0, vCores:0>usedCapacity=0.0, absoluteUsedCapacity=0.0, numApps=1, numContainers=0
2014-04-01 02:13:53,081 INFO org.apache.hadoop.yarn.server.resourcemanager.scheduler.capacity.CapacityScheduler: Application appattempt_1396342005689_0007_000001 released container container_1396342005689_0007_01_000001 on node: host: ubuntu:38688 #containers=0 available=8192 used=0 with event: FINISHED
2014-04-01 02:13:53,081 INFO org.apache.hadoop.yarn.server.resourcemanager.scheduler.capacity.CapacityScheduler: Application appattempt_1396342005689_0007_000001 is done. finalState=FINISHED
2014-04-01 02:13:53,081 INFO org.apache.hadoop.yarn.server.resourcemanager.scheduler.AppSchedulingInfo: Application application_1396342005689_0007 requests cleared
2014-04-01 02:13:53,081 INFO org.apache.hadoop.yarn.server.resourcemanager.scheduler.capacity.LeafQueue: Application removed - appId: application_1396342005689_0007 user: hduser queue: default #user-pending-applications: 0 #user-active-applications: 0 #queue-pending-applications: 0 #queue-active-applications: 0
2014-04-01 02:13:53,081 INFO org.apache.hadoop.yarn.server.resourcemanager.scheduler.capacity.ParentQueue: Application removed - appId: application_1396342005689_0007 user: hduser leaf-queue of parent: root #applications: 0
