2014-03-31 17:25:01,294 INFO org.apache.hadoop.yarn.server.resourcemanager.ResourceManager: STARTUP_MSG: 
/************************************************************
STARTUP_MSG: Starting ResourceManager
STARTUP_MSG:   host = ubuntu/127.0.1.1
STARTUP_MSG:   args = []
STARTUP_MSG:   version = 2.2.0
STARTUP_MSG:   build = Unknown -r Unknown; compiled by 'root' on 2014-03-31T23:45Z
STARTUP_MSG:   java = 1.7.0_51
************************************************************/
2014-03-31 17:25:01,298 INFO org.apache.hadoop.yarn.server.resourcemanager.ResourceManager: registered UNIX signal handlers for [TERM, HUP, INT]
2014-03-31 17:25:01,478 INFO org.apache.hadoop.yarn.server.resourcemanager.security.AMRMTokenSecretManager: Rolling master-key for amrm-tokens
2014-03-31 17:25:01,487 INFO org.apache.hadoop.yarn.server.resourcemanager.security.RMContainerTokenSecretManager: ContainerTokenKeyRollingInterval: 86400000ms and ContainerTokenKeyActivationDelay: 900000ms
2014-03-31 17:25:01,490 INFO org.apache.hadoop.yarn.server.resourcemanager.security.NMTokenSecretManagerInRM: NMTokenKeyRollingInterval: 86400000ms and NMTokenKeyActivationDelay: 900000ms
2014-03-31 17:25:01,495 INFO org.apache.hadoop.yarn.event.AsyncDispatcher: Registering class org.apache.hadoop.yarn.server.resourcemanager.recovery.RMStateStoreEventType for class org.apache.hadoop.yarn.server.resourcemanager.recovery.RMStateStore$ForwardingEventHandler
2014-03-31 17:25:02,829 WARN org.apache.hadoop.util.NativeCodeLoader: Unable to load native-hadoop library for your platform... using builtin-java classes where applicable
2014-03-31 17:25:02,886 INFO org.apache.hadoop.yarn.event.AsyncDispatcher: Registering class org.apache.hadoop.yarn.server.resourcemanager.NodesListManagerEventType for class org.apache.hadoop.yarn.server.resourcemanager.NodesListManager
2014-03-31 17:25:02,915 INFO org.apache.hadoop.yarn.server.resourcemanager.ResourceManager: Using Scheduler: org.apache.hadoop.yarn.server.resourcemanager.scheduler.capacity.CapacityScheduler
2014-03-31 17:25:02,974 INFO org.apache.hadoop.yarn.event.AsyncDispatcher: Registering class org.apache.hadoop.yarn.server.resourcemanager.scheduler.event.SchedulerEventType for class org.apache.hadoop.yarn.server.resourcemanager.ResourceManager$SchedulerEventDispatcher
2014-03-31 17:25:02,975 INFO org.apache.hadoop.yarn.event.AsyncDispatcher: Registering class org.apache.hadoop.yarn.server.resourcemanager.rmapp.RMAppEventType for class org.apache.hadoop.yarn.server.resourcemanager.ResourceManager$ApplicationEventDispatcher
2014-03-31 17:25:02,976 INFO org.apache.hadoop.yarn.event.AsyncDispatcher: Registering class org.apache.hadoop.yarn.server.resourcemanager.rmapp.attempt.RMAppAttemptEventType for class org.apache.hadoop.yarn.server.resourcemanager.ResourceManager$ApplicationAttemptEventDispatcher
2014-03-31 17:25:02,977 INFO org.apache.hadoop.yarn.event.AsyncDispatcher: Registering class org.apache.hadoop.yarn.server.resourcemanager.rmnode.RMNodeEventType for class org.apache.hadoop.yarn.server.resourcemanager.ResourceManager$NodeEventDispatcher
2014-03-31 17:25:03,039 INFO org.apache.hadoop.metrics2.impl.MetricsConfig: loaded properties from hadoop-metrics2.properties
2014-03-31 17:25:03,095 INFO org.apache.hadoop.metrics2.impl.MetricsSystemImpl: Scheduled snapshot period at 10 second(s).
2014-03-31 17:25:03,095 INFO org.apache.hadoop.metrics2.impl.MetricsSystemImpl: ResourceManager metrics system started
2014-03-31 17:25:03,144 INFO org.apache.hadoop.yarn.server.resourcemanager.scheduler.capacity.ParentQueue: root, capacity=1.0, asboluteCapacity=1.0, maxCapacity=1.0, asboluteMaxCapacity=1.0, state=RUNNING, acls=SUBMIT_APPLICATIONS:*ADMINISTER_QUEUE:*
2014-03-31 17:25:03,144 INFO org.apache.hadoop.yarn.server.resourcemanager.scheduler.capacity.ParentQueue: Initialized parent-queue root name=root, fullname=root
2014-03-31 17:25:03,152 INFO org.apache.hadoop.yarn.server.resourcemanager.scheduler.capacity.LeafQueue: Initializing default
capacity = 1.0 [= (float) configuredCapacity / 100 ]
asboluteCapacity = 1.0 [= parentAbsoluteCapacity * capacity ]
maxCapacity = 1.0 [= configuredMaxCapacity ]
absoluteMaxCapacity = 1.0 [= 1.0 maximumCapacity undefined, (parentAbsoluteMaxCapacity * maximumCapacity) / 100 otherwise ]
userLimit = 100 [= configuredUserLimit ]
userLimitFactor = 1.0 [= configuredUserLimitFactor ]
maxApplications = 10000 [= configuredMaximumSystemApplicationsPerQueue or (int)(configuredMaximumSystemApplications * absoluteCapacity)]
maxApplicationsPerUser = 10000 [= (int)(maxApplications * (userLimit / 100.0f) * userLimitFactor) ]
maxActiveApplications = 1 [= max((int)ceil((clusterResourceMemory / minimumAllocation) * maxAMResourcePerQueuePercent * absoluteMaxCapacity),1) ]
maxActiveAppsUsingAbsCap = 1 [= max((int)ceil((clusterResourceMemory / minimumAllocation) *maxAMResourcePercent * absoluteCapacity),1) ]
maxActiveApplicationsPerUser = 1 [= max((int)(maxActiveApplications * (userLimit / 100.0f) * userLimitFactor),1) ]
usedCapacity = 0.0 [= usedResourcesMemory / (clusterResourceMemory * absoluteCapacity)]
absoluteUsedCapacity = 0.0 [= usedResourcesMemory / clusterResourceMemory]
maxAMResourcePerQueuePercent = 0.1 [= configuredMaximumAMResourcePercent ]
minimumAllocationFactor = 0.875 [= (float)(maximumAllocationMemory - minimumAllocationMemory) / maximumAllocationMemory ]
numContainers = 0 [= currentNumContainers ]
state = RUNNING [= configuredState ]
acls = SUBMIT_APPLICATIONS:*ADMINISTER_QUEUE:* [= configuredAcls ]
nodeLocalityDelay = 0

2014-03-31 17:25:03,152 INFO org.apache.hadoop.yarn.server.resourcemanager.scheduler.capacity.CapacityScheduler: Initialized queue: default: capacity=1.0, absoluteCapacity=1.0, usedResources=<memory:0, vCores:0>usedCapacity=0.0, absoluteUsedCapacity=0.0, numApps=0, numContainers=0
2014-03-31 17:25:03,152 INFO org.apache.hadoop.yarn.server.resourcemanager.scheduler.capacity.CapacityScheduler: Initialized queue: root: numChildQueue= 1, capacity=1.0, absoluteCapacity=1.0, usedResources=<memory:0, vCores:0>usedCapacity=0.0, numApps=0, numContainers=0
2014-03-31 17:25:03,152 INFO org.apache.hadoop.yarn.server.resourcemanager.scheduler.capacity.CapacityScheduler: Initialized root queue root: numChildQueue= 1, capacity=1.0, absoluteCapacity=1.0, usedResources=<memory:0, vCores:0>usedCapacity=0.0, numApps=0, numContainers=0
2014-03-31 17:25:03,152 INFO org.apache.hadoop.yarn.server.resourcemanager.scheduler.capacity.CapacityScheduler: Initialized CapacityScheduler with calculator=class org.apache.hadoop.yarn.util.resource.DefaultResourceCalculator, minimumAllocation=<<memory:1024, vCores:1>>, maximumAllocation=<<memory:8192, vCores:32>>
2014-03-31 17:25:03,188 INFO org.apache.hadoop.yarn.event.AsyncDispatcher: Registering class org.apache.hadoop.yarn.server.resourcemanager.RMAppManagerEventType for class org.apache.hadoop.yarn.server.resourcemanager.RMAppManager
2014-03-31 17:25:03,196 INFO org.apache.hadoop.yarn.event.AsyncDispatcher: Registering class org.apache.hadoop.yarn.server.resourcemanager.amlauncher.AMLauncherEventType for class org.apache.hadoop.yarn.server.resourcemanager.amlauncher.ApplicationMasterLauncher
2014-03-31 17:25:03,198 INFO org.apache.hadoop.yarn.server.resourcemanager.RMNMInfo: Registered RMNMInfo MBean
2014-03-31 17:25:03,199 INFO org.apache.hadoop.util.HostsFileReader: Refreshing hosts (include/exclude) list
2014-03-31 17:25:03,204 INFO org.apache.hadoop.yarn.server.resourcemanager.security.RMContainerTokenSecretManager: Rolling master-key for container-tokens
2014-03-31 17:25:03,204 INFO org.apache.hadoop.yarn.server.resourcemanager.security.AMRMTokenSecretManager: Rolling master-key for amrm-tokens
2014-03-31 17:25:03,206 INFO org.apache.hadoop.yarn.server.resourcemanager.security.NMTokenSecretManagerInRM: Rolling master-key for nm-tokens
2014-03-31 17:25:03,241 INFO org.mortbay.log: Logging to org.slf4j.impl.Log4jLoggerAdapter(org.mortbay.log) via org.mortbay.log.Slf4jLog
2014-03-31 17:25:03,288 INFO org.apache.hadoop.http.HttpServer: Added global filter 'safety' (class=org.apache.hadoop.http.HttpServer$QuotingInputFilter)
2014-03-31 17:25:03,289 INFO org.apache.hadoop.http.HttpServer: Added filter static_user_filter (class=org.apache.hadoop.http.lib.StaticUserWebFilter$StaticUserFilter) to context cluster
2014-03-31 17:25:03,289 INFO org.apache.hadoop.http.HttpServer: Added filter static_user_filter (class=org.apache.hadoop.http.lib.StaticUserWebFilter$StaticUserFilter) to context logs
2014-03-31 17:25:03,289 INFO org.apache.hadoop.http.HttpServer: Added filter static_user_filter (class=org.apache.hadoop.http.lib.StaticUserWebFilter$StaticUserFilter) to context static
2014-03-31 17:25:03,292 INFO org.apache.hadoop.http.HttpServer: adding path spec: /cluster/*
2014-03-31 17:25:03,292 INFO org.apache.hadoop.http.HttpServer: adding path spec: /ws/*
2014-03-31 17:25:03,297 INFO org.apache.hadoop.http.HttpServer: Jetty bound to port 8088
2014-03-31 17:25:03,297 INFO org.mortbay.log: jetty-6.1.26
2014-03-31 17:25:03,319 INFO org.mortbay.log: Extract jar:file:/home/hduser/PatchedDistro/patched_hadoop/share/hadoop/yarn/hadoop-yarn-common-2.2.0.jar!/webapps/cluster to /tmp/Jetty_0_0_0_0_8088_cluster____u0rgz3/webapp
2014-03-31 17:25:03,481 INFO org.mortbay.log: Started SelectChannelConnector@0.0.0.0:8088
2014-03-31 17:25:03,481 INFO org.apache.hadoop.yarn.webapp.WebApps: Web app /cluster started at 8088
2014-03-31 17:25:03,762 INFO org.apache.hadoop.yarn.webapp.WebApps: Registered webapp guice modules
2014-03-31 17:25:03,763 INFO org.apache.hadoop.security.token.delegation.AbstractDelegationTokenSecretManager: Updating the current master key for generating delegation tokens
2014-03-31 17:25:03,763 INFO org.apache.hadoop.yarn.server.resourcemanager.security.RMDelegationTokenSecretManager: storing master key with keyID 1
2014-03-31 17:25:03,764 INFO org.apache.hadoop.security.token.delegation.AbstractDelegationTokenSecretManager: Starting expired delegation token remover thread, tokenRemoverScanInterval=60 min(s)
2014-03-31 17:25:03,764 INFO org.apache.hadoop.security.token.delegation.AbstractDelegationTokenSecretManager: Updating the current master key for generating delegation tokens
2014-03-31 17:25:03,764 INFO org.apache.hadoop.yarn.server.resourcemanager.security.RMDelegationTokenSecretManager: storing master key with keyID 2
2014-03-31 17:25:10,134 INFO org.apache.hadoop.ipc.Server: Starting Socket Reader #1 for port 8031
2014-03-31 17:25:10,146 INFO org.apache.hadoop.yarn.factories.impl.pb.RpcServerFactoryPBImpl: Adding protocol org.apache.hadoop.yarn.server.api.ResourceTrackerPB to the server
2014-03-31 17:25:10,146 INFO org.apache.hadoop.ipc.Server: IPC Server Responder: starting
2014-03-31 17:25:10,149 INFO org.apache.hadoop.ipc.Server: IPC Server listener on 8031: starting
2014-03-31 17:25:10,595 INFO org.apache.hadoop.yarn.server.resourcemanager.ResourceTrackerService: Node not found resyncing ubuntu:55559
2014-03-31 17:25:11,622 INFO org.apache.hadoop.yarn.util.RackResolver: Resolved ubuntu to /default-rack
2014-03-31 17:25:11,626 INFO org.apache.hadoop.yarn.server.resourcemanager.ResourceTrackerService: NodeManager from node ubuntu(cmPort: 55559 httpPort: 8042) registered with capability: <memory:8192, vCores:8>, assigned nodeId ubuntu:55559
2014-03-31 17:25:11,635 INFO org.apache.hadoop.yarn.server.resourcemanager.rmnode.RMNodeImpl: ubuntu:55559 Node Transitioned from NEW to RUNNING
2014-03-31 17:25:11,637 INFO org.apache.hadoop.yarn.server.resourcemanager.scheduler.capacity.CapacityScheduler: Added node ubuntu:55559 clusterResource: <memory:8192, vCores:8>
2014-03-31 17:25:16,514 INFO org.apache.hadoop.ipc.Server: Starting Socket Reader #1 for port 8030
2014-03-31 17:25:16,548 INFO org.apache.hadoop.yarn.factories.impl.pb.RpcServerFactoryPBImpl: Adding protocol org.apache.hadoop.yarn.api.ApplicationMasterProtocolPB to the server
2014-03-31 17:25:16,549 INFO org.apache.hadoop.ipc.Server: IPC Server Responder: starting
2014-03-31 17:25:16,560 INFO org.apache.hadoop.ipc.Server: IPC Server listener on 8030: starting
2014-03-31 17:25:22,952 INFO org.apache.hadoop.ipc.Server: Starting Socket Reader #1 for port 8032
2014-03-31 17:25:22,954 INFO org.apache.hadoop.yarn.factories.impl.pb.RpcServerFactoryPBImpl: Adding protocol org.apache.hadoop.yarn.api.ApplicationClientProtocolPB to the server
2014-03-31 17:25:22,954 INFO org.apache.hadoop.ipc.Server: IPC Server Responder: starting
2014-03-31 17:25:22,954 INFO org.apache.hadoop.ipc.Server: IPC Server listener on 8032: starting
2014-03-31 17:25:29,329 INFO org.apache.hadoop.ipc.Server: Starting Socket Reader #1 for port 8033
2014-03-31 17:25:29,331 INFO org.apache.hadoop.yarn.factories.impl.pb.RpcServerFactoryPBImpl: Adding protocol org.apache.hadoop.yarn.server.api.ResourceManagerAdministrationProtocolPB to the server
2014-03-31 17:25:29,331 INFO org.apache.hadoop.ipc.Server: IPC Server Responder: starting
2014-03-31 17:25:29,332 INFO org.apache.hadoop.ipc.Server: IPC Server listener on 8033: starting
2014-03-31 17:26:10,196 ERROR org.apache.hadoop.yarn.server.resourcemanager.ResourceManager: RECEIVED SIGNAL 15: SIGTERM
2014-03-31 17:26:10,205 INFO org.mortbay.log: Stopped SelectChannelConnector@0.0.0.0:8088
2014-03-31 17:26:10,206 ERROR org.apache.hadoop.security.token.delegation.AbstractDelegationTokenSecretManager: InterruptedExcpetion recieved for ExpiredTokenRemover thread java.lang.InterruptedException: sleep interrupted
2014-03-31 17:26:10,206 INFO org.apache.hadoop.metrics2.impl.MetricsSystemImpl: Stopping ResourceManager metrics system...
2014-03-31 17:26:10,207 INFO org.apache.hadoop.metrics2.impl.MetricsSystemImpl: ResourceManager metrics system stopped.
2014-03-31 17:26:10,207 INFO org.apache.hadoop.metrics2.impl.MetricsSystemImpl: ResourceManager metrics system shutdown complete.
2014-03-31 17:26:10,208 WARN org.apache.hadoop.yarn.server.resourcemanager.amlauncher.ApplicationMasterLauncher: org.apache.hadoop.yarn.server.resourcemanager.amlauncher.ApplicationMasterLauncher$LauncherThread interrupted. Returning.
2014-03-31 17:26:10,208 INFO org.apache.hadoop.ipc.Server: Stopping server on 8033
2014-03-31 17:26:10,210 INFO org.apache.hadoop.ipc.Server: Stopping IPC Server listener on 8033
2014-03-31 17:26:10,210 INFO org.apache.hadoop.ipc.Server: Stopping IPC Server Responder
2014-03-31 17:26:10,211 INFO org.apache.hadoop.ipc.Server: Stopping server on 8032
2014-03-31 17:26:10,215 INFO org.apache.hadoop.ipc.Server: Stopping IPC Server listener on 8032
2014-03-31 17:26:10,218 INFO org.apache.hadoop.ipc.Server: Stopping server on 8030
2014-03-31 17:26:10,222 INFO org.apache.hadoop.ipc.Server: Stopping IPC Server Responder
2014-03-31 17:26:10,224 INFO org.apache.hadoop.ipc.Server: Stopping IPC Server listener on 8030
2014-03-31 17:26:10,226 INFO org.apache.hadoop.ipc.Server: Stopping server on 8031
2014-03-31 17:26:10,227 INFO org.apache.hadoop.ipc.Server: Stopping IPC Server Responder
2014-03-31 17:26:10,233 INFO org.apache.hadoop.ipc.Server: Stopping IPC Server listener on 8031
2014-03-31 17:26:10,235 INFO org.apache.hadoop.ipc.Server: Stopping IPC Server Responder
2014-03-31 17:26:10,235 INFO org.apache.hadoop.yarn.util.AbstractLivelinessMonitor: NMLivelinessMonitor thread interrupted
2014-03-31 17:26:10,235 ERROR org.apache.hadoop.yarn.server.resourcemanager.ResourceManager: Returning, interrupted : java.lang.InterruptedException
2014-03-31 17:26:10,235 INFO org.apache.hadoop.yarn.util.AbstractLivelinessMonitor: AMLivelinessMonitor thread interrupted
2014-03-31 17:26:10,235 INFO org.apache.hadoop.yarn.util.AbstractLivelinessMonitor: AMLivelinessMonitor thread interrupted
2014-03-31 17:26:10,236 INFO org.apache.hadoop.yarn.util.AbstractLivelinessMonitor: org.apache.hadoop.yarn.server.resourcemanager.rmcontainer.ContainerAllocationExpirer thread interrupted
2014-03-31 17:26:10,236 INFO org.apache.hadoop.yarn.server.resourcemanager.ResourceManager: SHUTDOWN_MSG: 
/************************************************************
SHUTDOWN_MSG: Shutting down ResourceManager at ubuntu/127.0.1.1
************************************************************/
2014-03-31 17:27:08,458 INFO org.apache.hadoop.yarn.server.resourcemanager.ResourceManager: STARTUP_MSG: 
/************************************************************
STARTUP_MSG: Starting ResourceManager
STARTUP_MSG:   host = ubuntu/127.0.1.1
STARTUP_MSG:   args = []
STARTUP_MSG:   version = 2.2.0
STARTUP_MSG:   build = Unknown -r Unknown; compiled by 'root' on 2014-03-31T23:45Z
STARTUP_MSG:   java = 1.7.0_51
************************************************************/
2014-03-31 17:27:08,462 INFO org.apache.hadoop.yarn.server.resourcemanager.ResourceManager: registered UNIX signal handlers for [TERM, HUP, INT]
2014-03-31 17:27:08,641 INFO org.apache.hadoop.yarn.server.resourcemanager.security.AMRMTokenSecretManager: Rolling master-key for amrm-tokens
2014-03-31 17:27:08,648 INFO org.apache.hadoop.yarn.server.resourcemanager.security.RMContainerTokenSecretManager: ContainerTokenKeyRollingInterval: 86400000ms and ContainerTokenKeyActivationDelay: 900000ms
2014-03-31 17:27:08,651 INFO org.apache.hadoop.yarn.server.resourcemanager.security.NMTokenSecretManagerInRM: NMTokenKeyRollingInterval: 86400000ms and NMTokenKeyActivationDelay: 900000ms
2014-03-31 17:27:08,656 INFO org.apache.hadoop.yarn.event.AsyncDispatcher: Registering class org.apache.hadoop.yarn.server.resourcemanager.recovery.RMStateStoreEventType for class org.apache.hadoop.yarn.server.resourcemanager.recovery.RMStateStore$ForwardingEventHandler
2014-03-31 17:27:09,945 WARN org.apache.hadoop.util.NativeCodeLoader: Unable to load native-hadoop library for your platform... using builtin-java classes where applicable
2014-03-31 17:27:10,010 INFO org.apache.hadoop.yarn.event.AsyncDispatcher: Registering class org.apache.hadoop.yarn.server.resourcemanager.NodesListManagerEventType for class org.apache.hadoop.yarn.server.resourcemanager.NodesListManager
2014-03-31 17:27:10,031 INFO org.apache.hadoop.yarn.server.resourcemanager.ResourceManager: Using Scheduler: org.apache.hadoop.yarn.server.resourcemanager.scheduler.capacity.CapacityScheduler
2014-03-31 17:27:10,130 INFO org.apache.hadoop.yarn.event.AsyncDispatcher: Registering class org.apache.hadoop.yarn.server.resourcemanager.scheduler.event.SchedulerEventType for class org.apache.hadoop.yarn.server.resourcemanager.ResourceManager$SchedulerEventDispatcher
2014-03-31 17:27:10,131 INFO org.apache.hadoop.yarn.event.AsyncDispatcher: Registering class org.apache.hadoop.yarn.server.resourcemanager.rmapp.RMAppEventType for class org.apache.hadoop.yarn.server.resourcemanager.ResourceManager$ApplicationEventDispatcher
2014-03-31 17:27:10,132 INFO org.apache.hadoop.yarn.event.AsyncDispatcher: Registering class org.apache.hadoop.yarn.server.resourcemanager.rmapp.attempt.RMAppAttemptEventType for class org.apache.hadoop.yarn.server.resourcemanager.ResourceManager$ApplicationAttemptEventDispatcher
2014-03-31 17:27:10,133 INFO org.apache.hadoop.yarn.event.AsyncDispatcher: Registering class org.apache.hadoop.yarn.server.resourcemanager.rmnode.RMNodeEventType for class org.apache.hadoop.yarn.server.resourcemanager.ResourceManager$NodeEventDispatcher
2014-03-31 17:27:10,263 INFO org.apache.hadoop.metrics2.impl.MetricsConfig: loaded properties from hadoop-metrics2.properties
2014-03-31 17:27:10,334 INFO org.apache.hadoop.metrics2.impl.MetricsSystemImpl: Scheduled snapshot period at 10 second(s).
2014-03-31 17:27:10,334 INFO org.apache.hadoop.metrics2.impl.MetricsSystemImpl: ResourceManager metrics system started
2014-03-31 17:27:10,429 INFO org.apache.hadoop.yarn.server.resourcemanager.scheduler.capacity.ParentQueue: root, capacity=1.0, asboluteCapacity=1.0, maxCapacity=1.0, asboluteMaxCapacity=1.0, state=RUNNING, acls=ADMINISTER_QUEUE:*SUBMIT_APPLICATIONS:*
2014-03-31 17:27:10,429 INFO org.apache.hadoop.yarn.server.resourcemanager.scheduler.capacity.ParentQueue: Initialized parent-queue root name=root, fullname=root
2014-03-31 17:27:10,435 INFO org.apache.hadoop.yarn.server.resourcemanager.scheduler.capacity.LeafQueue: Initializing default
capacity = 1.0 [= (float) configuredCapacity / 100 ]
asboluteCapacity = 1.0 [= parentAbsoluteCapacity * capacity ]
maxCapacity = 1.0 [= configuredMaxCapacity ]
absoluteMaxCapacity = 1.0 [= 1.0 maximumCapacity undefined, (parentAbsoluteMaxCapacity * maximumCapacity) / 100 otherwise ]
userLimit = 100 [= configuredUserLimit ]
userLimitFactor = 1.0 [= configuredUserLimitFactor ]
maxApplications = 10000 [= configuredMaximumSystemApplicationsPerQueue or (int)(configuredMaximumSystemApplications * absoluteCapacity)]
maxApplicationsPerUser = 10000 [= (int)(maxApplications * (userLimit / 100.0f) * userLimitFactor) ]
maxActiveApplications = 1 [= max((int)ceil((clusterResourceMemory / minimumAllocation) * maxAMResourcePerQueuePercent * absoluteMaxCapacity),1) ]
maxActiveAppsUsingAbsCap = 1 [= max((int)ceil((clusterResourceMemory / minimumAllocation) *maxAMResourcePercent * absoluteCapacity),1) ]
maxActiveApplicationsPerUser = 1 [= max((int)(maxActiveApplications * (userLimit / 100.0f) * userLimitFactor),1) ]
usedCapacity = 0.0 [= usedResourcesMemory / (clusterResourceMemory * absoluteCapacity)]
absoluteUsedCapacity = 0.0 [= usedResourcesMemory / clusterResourceMemory]
maxAMResourcePerQueuePercent = 0.1 [= configuredMaximumAMResourcePercent ]
minimumAllocationFactor = 0.875 [= (float)(maximumAllocationMemory - minimumAllocationMemory) / maximumAllocationMemory ]
numContainers = 0 [= currentNumContainers ]
state = RUNNING [= configuredState ]
acls = ADMINISTER_QUEUE:*SUBMIT_APPLICATIONS:* [= configuredAcls ]
nodeLocalityDelay = 0

2014-03-31 17:27:10,435 INFO org.apache.hadoop.yarn.server.resourcemanager.scheduler.capacity.CapacityScheduler: Initialized queue: default: capacity=1.0, absoluteCapacity=1.0, usedResources=<memory:0, vCores:0>usedCapacity=0.0, absoluteUsedCapacity=0.0, numApps=0, numContainers=0
2014-03-31 17:27:10,435 INFO org.apache.hadoop.yarn.server.resourcemanager.scheduler.capacity.CapacityScheduler: Initialized queue: root: numChildQueue= 1, capacity=1.0, absoluteCapacity=1.0, usedResources=<memory:0, vCores:0>usedCapacity=0.0, numApps=0, numContainers=0
2014-03-31 17:27:10,435 INFO org.apache.hadoop.yarn.server.resourcemanager.scheduler.capacity.CapacityScheduler: Initialized root queue root: numChildQueue= 1, capacity=1.0, absoluteCapacity=1.0, usedResources=<memory:0, vCores:0>usedCapacity=0.0, numApps=0, numContainers=0
2014-03-31 17:27:10,435 INFO org.apache.hadoop.yarn.server.resourcemanager.scheduler.capacity.CapacityScheduler: Initialized CapacityScheduler with calculator=class org.apache.hadoop.yarn.util.resource.DefaultResourceCalculator, minimumAllocation=<<memory:1024, vCores:1>>, maximumAllocation=<<memory:8192, vCores:32>>
2014-03-31 17:27:10,461 INFO org.apache.hadoop.yarn.event.AsyncDispatcher: Registering class org.apache.hadoop.yarn.server.resourcemanager.RMAppManagerEventType for class org.apache.hadoop.yarn.server.resourcemanager.RMAppManager
2014-03-31 17:27:10,470 INFO org.apache.hadoop.yarn.event.AsyncDispatcher: Registering class org.apache.hadoop.yarn.server.resourcemanager.amlauncher.AMLauncherEventType for class org.apache.hadoop.yarn.server.resourcemanager.amlauncher.ApplicationMasterLauncher
2014-03-31 17:27:10,472 INFO org.apache.hadoop.yarn.server.resourcemanager.RMNMInfo: Registered RMNMInfo MBean
2014-03-31 17:27:10,473 INFO org.apache.hadoop.util.HostsFileReader: Refreshing hosts (include/exclude) list
2014-03-31 17:27:10,477 INFO org.apache.hadoop.yarn.server.resourcemanager.security.AMRMTokenSecretManager: Rolling master-key for amrm-tokens
2014-03-31 17:27:10,478 INFO org.apache.hadoop.yarn.server.resourcemanager.security.RMContainerTokenSecretManager: Rolling master-key for container-tokens
2014-03-31 17:27:10,480 INFO org.apache.hadoop.yarn.server.resourcemanager.security.NMTokenSecretManagerInRM: Rolling master-key for nm-tokens
2014-03-31 17:27:10,521 INFO org.mortbay.log: Logging to org.slf4j.impl.Log4jLoggerAdapter(org.mortbay.log) via org.mortbay.log.Slf4jLog
2014-03-31 17:27:10,572 INFO org.apache.hadoop.http.HttpServer: Added global filter 'safety' (class=org.apache.hadoop.http.HttpServer$QuotingInputFilter)
2014-03-31 17:27:10,574 INFO org.apache.hadoop.http.HttpServer: Added filter static_user_filter (class=org.apache.hadoop.http.lib.StaticUserWebFilter$StaticUserFilter) to context cluster
2014-03-31 17:27:10,574 INFO org.apache.hadoop.http.HttpServer: Added filter static_user_filter (class=org.apache.hadoop.http.lib.StaticUserWebFilter$StaticUserFilter) to context logs
2014-03-31 17:27:10,574 INFO org.apache.hadoop.http.HttpServer: Added filter static_user_filter (class=org.apache.hadoop.http.lib.StaticUserWebFilter$StaticUserFilter) to context static
2014-03-31 17:27:10,578 INFO org.apache.hadoop.http.HttpServer: adding path spec: /cluster/*
2014-03-31 17:27:10,578 INFO org.apache.hadoop.http.HttpServer: adding path spec: /ws/*
2014-03-31 17:27:10,583 INFO org.apache.hadoop.http.HttpServer: Jetty bound to port 8088
2014-03-31 17:27:10,583 INFO org.mortbay.log: jetty-6.1.26
2014-03-31 17:27:10,605 INFO org.mortbay.log: Extract jar:file:/home/hduser/PatchedDistro/patched_hadoop/share/hadoop/yarn/hadoop-yarn-common-2.2.0.jar!/webapps/cluster to /tmp/Jetty_0_0_0_0_8088_cluster____u0rgz3/webapp
2014-03-31 17:27:10,768 INFO org.mortbay.log: Started SelectChannelConnector@0.0.0.0:8088
2014-03-31 17:27:10,768 INFO org.apache.hadoop.yarn.webapp.WebApps: Web app /cluster started at 8088
2014-03-31 17:27:11,109 INFO org.apache.hadoop.yarn.webapp.WebApps: Registered webapp guice modules
2014-03-31 17:27:11,110 INFO org.apache.hadoop.security.token.delegation.AbstractDelegationTokenSecretManager: Updating the current master key for generating delegation tokens
2014-03-31 17:27:11,111 INFO org.apache.hadoop.yarn.server.resourcemanager.security.RMDelegationTokenSecretManager: storing master key with keyID 1
2014-03-31 17:27:11,112 INFO org.apache.hadoop.security.token.delegation.AbstractDelegationTokenSecretManager: Starting expired delegation token remover thread, tokenRemoverScanInterval=60 min(s)
2014-03-31 17:27:11,112 INFO org.apache.hadoop.security.token.delegation.AbstractDelegationTokenSecretManager: Updating the current master key for generating delegation tokens
2014-03-31 17:27:11,112 INFO org.apache.hadoop.yarn.server.resourcemanager.security.RMDelegationTokenSecretManager: storing master key with keyID 2
2014-03-31 17:27:18,244 INFO org.apache.hadoop.ipc.Server: Starting Socket Reader #1 for port 8031
2014-03-31 17:27:18,256 INFO org.apache.hadoop.yarn.factories.impl.pb.RpcServerFactoryPBImpl: Adding protocol org.apache.hadoop.yarn.server.api.ResourceTrackerPB to the server
2014-03-31 17:27:18,257 INFO org.apache.hadoop.ipc.Server: IPC Server Responder: starting
2014-03-31 17:27:18,257 INFO org.apache.hadoop.ipc.Server: IPC Server listener on 8031: starting
2014-03-31 17:27:24,492 INFO org.apache.hadoop.ipc.Server: Starting Socket Reader #1 for port 8030
2014-03-31 17:27:24,518 INFO org.apache.hadoop.yarn.factories.impl.pb.RpcServerFactoryPBImpl: Adding protocol org.apache.hadoop.yarn.api.ApplicationMasterProtocolPB to the server
2014-03-31 17:27:24,519 INFO org.apache.hadoop.ipc.Server: IPC Server Responder: starting
2014-03-31 17:27:24,519 INFO org.apache.hadoop.ipc.Server: IPC Server listener on 8030: starting
2014-03-31 17:27:25,160 INFO org.apache.hadoop.yarn.util.RackResolver: Resolved ubuntu to /default-rack
2014-03-31 17:27:25,164 INFO org.apache.hadoop.yarn.server.resourcemanager.rmnode.RMNodeImpl: ubuntu:35171 Node Transitioned from NEW to RUNNING
2014-03-31 17:27:25,165 INFO org.apache.hadoop.yarn.server.resourcemanager.ResourceTrackerService: NodeManager from node ubuntu(cmPort: 35171 httpPort: 8042) registered with capability: <memory:8192, vCores:8>, assigned nodeId ubuntu:35171
2014-03-31 17:27:25,167 INFO org.apache.hadoop.yarn.server.resourcemanager.scheduler.capacity.CapacityScheduler: Added node ubuntu:35171 clusterResource: <memory:8192, vCores:8>
2014-03-31 17:27:30,885 INFO org.apache.hadoop.ipc.Server: Starting Socket Reader #1 for port 8032
2014-03-31 17:27:30,891 INFO org.apache.hadoop.yarn.factories.impl.pb.RpcServerFactoryPBImpl: Adding protocol org.apache.hadoop.yarn.api.ApplicationClientProtocolPB to the server
2014-03-31 17:27:30,891 INFO org.apache.hadoop.ipc.Server: IPC Server listener on 8032: starting
2014-03-31 17:27:30,891 INFO org.apache.hadoop.ipc.Server: IPC Server Responder: starting
2014-03-31 17:27:37,240 INFO org.apache.hadoop.ipc.Server: Starting Socket Reader #1 for port 8033
2014-03-31 17:27:37,243 INFO org.apache.hadoop.yarn.factories.impl.pb.RpcServerFactoryPBImpl: Adding protocol org.apache.hadoop.yarn.server.api.ResourceManagerAdministrationProtocolPB to the server
2014-03-31 17:27:37,243 INFO org.apache.hadoop.ipc.Server: IPC Server Responder: starting
2014-03-31 17:27:37,244 INFO org.apache.hadoop.ipc.Server: IPC Server listener on 8033: starting
2014-03-31 17:28:00,799 INFO org.apache.hadoop.yarn.server.resourcemanager.ClientRMService: Allocated new applicationId: 1
2014-03-31 17:28:01,669 INFO org.apache.hadoop.yarn.server.resourcemanager.ClientRMService: Application with id 1 submitted by user hduser
2014-03-31 17:28:01,669 INFO org.apache.hadoop.yarn.server.resourcemanager.rmapp.RMAppImpl: Storing application with id application_1396312028434_0001
2014-03-31 17:28:01,670 INFO org.apache.hadoop.yarn.server.resourcemanager.RMAuditLogger: USER=hduser	IP=127.0.0.1	OPERATION=Submit Application Request	TARGET=ClientRMService	RESULT=SUCCESS	APPID=application_1396312028434_0001
2014-03-31 17:28:01,670 INFO org.apache.hadoop.yarn.server.resourcemanager.rmapp.RMAppImpl: application_1396312028434_0001 State change from NEW to NEW_SAVING
2014-03-31 17:28:01,674 INFO org.apache.hadoop.yarn.server.resourcemanager.recovery.RMStateStore: Storing info for app: application_1396312028434_0001
2014-03-31 17:28:01,701 INFO org.apache.hadoop.yarn.server.resourcemanager.rmapp.RMAppImpl: application_1396312028434_0001 State change from NEW_SAVING to SUBMITTED
2014-03-31 17:28:01,701 INFO org.apache.hadoop.yarn.server.resourcemanager.ApplicationMasterService: Registering app attempt : appattempt_1396312028434_0001_000001
2014-03-31 17:28:01,706 INFO org.apache.hadoop.yarn.server.resourcemanager.rmapp.attempt.RMAppAttemptImpl: appattempt_1396312028434_0001_000001 State change from NEW to SUBMITTED
2014-03-31 17:28:01,715 INFO org.apache.hadoop.yarn.server.resourcemanager.scheduler.capacity.LeafQueue: Application application_1396312028434_0001 from user: hduser activated in queue: default
2014-03-31 17:28:01,715 INFO org.apache.hadoop.yarn.server.resourcemanager.scheduler.capacity.LeafQueue: Application added - appId: application_1396312028434_0001 user: org.apache.hadoop.yarn.server.resourcemanager.scheduler.capacity.LeafQueue$User@1bf48f0, leaf-queue: default #user-pending-applications: 0 #user-active-applications: 1 #queue-pending-applications: 0 #queue-active-applications: 1
2014-03-31 17:28:01,715 INFO org.apache.hadoop.yarn.server.resourcemanager.scheduler.capacity.ParentQueue: Application added - appId: application_1396312028434_0001 user: hduser leaf-queue of parent: root #applications: 1
2014-03-31 17:28:01,716 INFO org.apache.hadoop.yarn.server.resourcemanager.scheduler.capacity.CapacityScheduler: Application Submission: appattempt_1396312028434_0001_000001, user: hduser queue: default: capacity=1.0, absoluteCapacity=1.0, usedResources=<memory:0, vCores:0>usedCapacity=0.0, absoluteUsedCapacity=0.0, numApps=1, numContainers=0, currently active: 1
2014-03-31 17:28:01,716 INFO org.apache.hadoop.yarn.server.resourcemanager.rmapp.attempt.RMAppAttemptImpl: appattempt_1396312028434_0001_000001 State change from SUBMITTED to SCHEDULED
2014-03-31 17:28:01,716 INFO org.apache.hadoop.yarn.server.resourcemanager.rmapp.RMAppImpl: application_1396312028434_0001 State change from SUBMITTED to ACCEPTED
2014-03-31 17:28:02,311 INFO org.apache.hadoop.yarn.server.resourcemanager.rmcontainer.RMContainerImpl: container_1396312028434_0001_01_000001 Container Transitioned from NEW to ALLOCATED
2014-03-31 17:28:02,311 INFO org.apache.hadoop.yarn.server.resourcemanager.RMAuditLogger: USER=hduser	OPERATION=AM Allocated Container	TARGET=SchedulerApp	RESULT=SUCCESS	APPID=application_1396312028434_0001	CONTAINERID=container_1396312028434_0001_01_000001
2014-03-31 17:28:02,312 INFO org.apache.hadoop.yarn.server.resourcemanager.scheduler.common.fica.FiCaSchedulerNode: Assigned container container_1396312028434_0001_01_000001 of capacity <memory:2048, vCores:1> on host ubuntu:35171, which currently has 1 containers, <memory:2048, vCores:1> used and <memory:6144, vCores:7> available
2014-03-31 17:28:02,312 INFO org.apache.hadoop.yarn.server.resourcemanager.scheduler.capacity.LeafQueue: assignedContainer application=application_1396312028434_0001 container=Container: [ContainerId: container_1396312028434_0001_01_000001, NodeId: ubuntu:35171, NodeHttpAddress: ubuntu:8042, Resource: <memory:2048, vCores:1>, Priority: 0, Token: Token { kind: ContainerToken, service: 127.0.1.1:35171 }, ] containerId=container_1396312028434_0001_01_000001 queue=default: capacity=1.0, absoluteCapacity=1.0, usedResources=<memory:0, vCores:0>usedCapacity=0.0, absoluteUsedCapacity=0.0, numApps=1, numContainers=0 usedCapacity=0.0 absoluteUsedCapacity=0.0 used=<memory:0, vCores:0> cluster=<memory:8192, vCores:8>
2014-03-31 17:28:02,312 INFO org.apache.hadoop.yarn.server.resourcemanager.scheduler.capacity.ParentQueue: Re-sorting assigned queue: root.default stats: default: capacity=1.0, absoluteCapacity=1.0, usedResources=<memory:2048, vCores:1>usedCapacity=0.25, absoluteUsedCapacity=0.25, numApps=1, numContainers=1
2014-03-31 17:28:02,312 INFO org.apache.hadoop.yarn.server.resourcemanager.scheduler.capacity.ParentQueue: assignedContainer queue=root usedCapacity=0.25 absoluteUsedCapacity=0.25 used=<memory:2048, vCores:1> cluster=<memory:8192, vCores:8>
2014-03-31 17:28:02,314 INFO org.apache.hadoop.yarn.server.resourcemanager.rmcontainer.RMContainerImpl: container_1396312028434_0001_01_000001 Container Transitioned from ALLOCATED to ACQUIRED
2014-03-31 17:28:02,318 INFO org.apache.hadoop.yarn.server.resourcemanager.rmapp.attempt.RMAppAttemptImpl: Storing attempt: AppId: application_1396312028434_0001 AttemptId: appattempt_1396312028434_0001_000001 MasterContainer: Container: [ContainerId: container_1396312028434_0001_01_000001, NodeId: ubuntu:35171, NodeHttpAddress: ubuntu:8042, Resource: <memory:2048, vCores:1>, Priority: 0, Token: Token { kind: ContainerToken, service: 127.0.1.1:35171 }, ]
2014-03-31 17:28:02,321 INFO org.apache.hadoop.yarn.server.resourcemanager.rmapp.attempt.RMAppAttemptImpl: appattempt_1396312028434_0001_000001 State change from SCHEDULED to ALLOCATED_SAVING
2014-03-31 17:28:02,325 INFO org.apache.hadoop.yarn.server.resourcemanager.recovery.RMStateStore: Storing info for attempt: appattempt_1396312028434_0001_000001
2014-03-31 17:28:02,326 INFO org.apache.hadoop.yarn.server.resourcemanager.rmapp.attempt.RMAppAttemptImpl: appattempt_1396312028434_0001_000001 State change from ALLOCATED_SAVING to ALLOCATED
2014-03-31 17:28:02,328 INFO org.apache.hadoop.yarn.server.resourcemanager.amlauncher.AMLauncher: Launching masterappattempt_1396312028434_0001_000001
2014-03-31 17:28:02,350 INFO org.apache.hadoop.yarn.server.resourcemanager.amlauncher.AMLauncher: Setting up container Container: [ContainerId: container_1396312028434_0001_01_000001, NodeId: ubuntu:35171, NodeHttpAddress: ubuntu:8042, Resource: <memory:2048, vCores:1>, Priority: 0, Token: Token { kind: ContainerToken, service: 127.0.1.1:35171 }, ] for AM appattempt_1396312028434_0001_000001
2014-03-31 17:28:02,350 INFO org.apache.hadoop.yarn.server.resourcemanager.amlauncher.AMLauncher: Command to launch container container_1396312028434_0001_01_000001 : $JAVA_HOME/bin/java -Dlog4j.configuration=container-log4j.properties -Dyarn.app.container.log.dir=<LOG_DIR> -Dyarn.app.container.log.filesize=0 -Dhadoop.root.logger=INFO,CLA  -Xmx1024m org.apache.hadoop.mapreduce.v2.app.MRAppMaster 1><LOG_DIR>/stdout 2><LOG_DIR>/stderr 
2014-03-31 17:28:02,601 INFO org.apache.hadoop.yarn.server.resourcemanager.amlauncher.AMLauncher: Done launching container Container: [ContainerId: container_1396312028434_0001_01_000001, NodeId: ubuntu:35171, NodeHttpAddress: ubuntu:8042, Resource: <memory:2048, vCores:1>, Priority: 0, Token: Token { kind: ContainerToken, service: 127.0.1.1:35171 }, ] for AM appattempt_1396312028434_0001_000001
2014-03-31 17:28:02,602 INFO org.apache.hadoop.yarn.server.resourcemanager.rmapp.attempt.RMAppAttemptImpl: appattempt_1396312028434_0001_000001 State change from ALLOCATED to LAUNCHED
2014-03-31 17:28:03,317 INFO org.apache.hadoop.yarn.server.resourcemanager.rmcontainer.RMContainerImpl: container_1396312028434_0001_01_000001 Container Transitioned from ACQUIRED to RUNNING
2014-03-31 17:28:07,212 INFO SecurityLogger.org.apache.hadoop.ipc.Server: Auth successful for appattempt_1396312028434_0001_000001 (auth:SIMPLE)
2014-03-31 17:28:07,216 INFO org.apache.hadoop.yarn.server.resourcemanager.ApplicationMasterService: AM registration appattempt_1396312028434_0001_000001
2014-03-31 17:28:07,216 INFO org.apache.hadoop.yarn.server.resourcemanager.RMAuditLogger: USER=hduser	IP=127.0.0.1	OPERATION=Register App Master	TARGET=ApplicationMasterService	RESULT=SUCCESS	APPID=application_1396312028434_0001	APPATTEMPTID=appattempt_1396312028434_0001_000001
2014-03-31 17:28:07,218 INFO org.apache.hadoop.yarn.server.resourcemanager.rmapp.attempt.RMAppAttemptImpl: appattempt_1396312028434_0001_000001 State change from LAUNCHED to RUNNING
2014-03-31 17:28:07,218 INFO org.apache.hadoop.yarn.server.resourcemanager.rmapp.RMAppImpl: application_1396312028434_0001 State change from ACCEPTED to RUNNING
2014-03-31 17:28:08,327 INFO org.apache.hadoop.yarn.server.resourcemanager.rmcontainer.RMContainerImpl: container_1396312028434_0001_01_000002 Container Transitioned from NEW to ALLOCATED
2014-03-31 17:28:08,327 INFO org.apache.hadoop.yarn.server.resourcemanager.RMAuditLogger: USER=hduser	OPERATION=AM Allocated Container	TARGET=SchedulerApp	RESULT=SUCCESS	APPID=application_1396312028434_0001	CONTAINERID=container_1396312028434_0001_01_000002
2014-03-31 17:28:08,327 INFO org.apache.hadoop.yarn.server.resourcemanager.scheduler.common.fica.FiCaSchedulerNode: Assigned container container_1396312028434_0001_01_000002 of capacity <memory:1024, vCores:1> on host ubuntu:35171, which currently has 2 containers, <memory:3072, vCores:2> used and <memory:5120, vCores:6> available
2014-03-31 17:28:08,327 INFO org.apache.hadoop.yarn.server.resourcemanager.scheduler.capacity.LeafQueue: assignedContainer application=application_1396312028434_0001 container=Container: [ContainerId: container_1396312028434_0001_01_000002, NodeId: ubuntu:35171, NodeHttpAddress: ubuntu:8042, Resource: <memory:1024, vCores:1>, Priority: 20, Token: Token { kind: ContainerToken, service: 127.0.1.1:35171 }, ] containerId=container_1396312028434_0001_01_000002 queue=default: capacity=1.0, absoluteCapacity=1.0, usedResources=<memory:2048, vCores:1>usedCapacity=0.25, absoluteUsedCapacity=0.25, numApps=1, numContainers=1 usedCapacity=0.25 absoluteUsedCapacity=0.25 used=<memory:2048, vCores:1> cluster=<memory:8192, vCores:8>
2014-03-31 17:28:08,327 INFO org.apache.hadoop.yarn.server.resourcemanager.scheduler.capacity.ParentQueue: Re-sorting assigned queue: root.default stats: default: capacity=1.0, absoluteCapacity=1.0, usedResources=<memory:3072, vCores:2>usedCapacity=0.375, absoluteUsedCapacity=0.375, numApps=1, numContainers=2
2014-03-31 17:28:08,327 INFO org.apache.hadoop.yarn.server.resourcemanager.scheduler.capacity.ParentQueue: assignedContainer queue=root usedCapacity=0.375 absoluteUsedCapacity=0.375 used=<memory:3072, vCores:2> cluster=<memory:8192, vCores:8>
2014-03-31 17:28:08,328 INFO org.apache.hadoop.yarn.server.resourcemanager.rmcontainer.RMContainerImpl: container_1396312028434_0001_01_000003 Container Transitioned from NEW to ALLOCATED
2014-03-31 17:28:08,328 INFO org.apache.hadoop.yarn.server.resourcemanager.RMAuditLogger: USER=hduser	OPERATION=AM Allocated Container	TARGET=SchedulerApp	RESULT=SUCCESS	APPID=application_1396312028434_0001	CONTAINERID=container_1396312028434_0001_01_000003
2014-03-31 17:28:08,328 INFO org.apache.hadoop.yarn.server.resourcemanager.scheduler.common.fica.FiCaSchedulerNode: Assigned container container_1396312028434_0001_01_000003 of capacity <memory:1024, vCores:1> on host ubuntu:35171, which currently has 3 containers, <memory:4096, vCores:3> used and <memory:4096, vCores:5> available
2014-03-31 17:28:08,328 INFO org.apache.hadoop.yarn.server.resourcemanager.scheduler.capacity.LeafQueue: assignedContainer application=application_1396312028434_0001 container=Container: [ContainerId: container_1396312028434_0001_01_000003, NodeId: ubuntu:35171, NodeHttpAddress: ubuntu:8042, Resource: <memory:1024, vCores:1>, Priority: 20, Token: Token { kind: ContainerToken, service: 127.0.1.1:35171 }, ] containerId=container_1396312028434_0001_01_000003 queue=default: capacity=1.0, absoluteCapacity=1.0, usedResources=<memory:3072, vCores:2>usedCapacity=0.375, absoluteUsedCapacity=0.375, numApps=1, numContainers=2 usedCapacity=0.375 absoluteUsedCapacity=0.375 used=<memory:3072, vCores:2> cluster=<memory:8192, vCores:8>
2014-03-31 17:28:08,328 INFO org.apache.hadoop.yarn.server.resourcemanager.scheduler.capacity.ParentQueue: Re-sorting assigned queue: root.default stats: default: capacity=1.0, absoluteCapacity=1.0, usedResources=<memory:4096, vCores:3>usedCapacity=0.5, absoluteUsedCapacity=0.5, numApps=1, numContainers=3
2014-03-31 17:28:08,328 INFO org.apache.hadoop.yarn.server.resourcemanager.scheduler.capacity.ParentQueue: assignedContainer queue=root usedCapacity=0.5 absoluteUsedCapacity=0.5 used=<memory:4096, vCores:3> cluster=<memory:8192, vCores:8>
2014-03-31 17:28:09,258 INFO org.apache.hadoop.yarn.server.resourcemanager.rmcontainer.RMContainerImpl: container_1396312028434_0001_01_000002 Container Transitioned from ALLOCATED to ACQUIRED
2014-03-31 17:28:09,259 INFO org.apache.hadoop.yarn.server.resourcemanager.rmcontainer.RMContainerImpl: container_1396312028434_0001_01_000003 Container Transitioned from ALLOCATED to ACQUIRED
2014-03-31 17:28:10,274 INFO org.apache.hadoop.yarn.server.resourcemanager.scheduler.AppSchedulingInfo: checking for deactivate... 
2014-03-31 17:28:10,333 INFO org.apache.hadoop.yarn.server.resourcemanager.rmcontainer.RMContainerImpl: container_1396312028434_0001_01_000002 Container Transitioned from ACQUIRED to RUNNING
2014-03-31 17:28:10,333 INFO org.apache.hadoop.yarn.server.resourcemanager.rmcontainer.RMContainerImpl: container_1396312028434_0001_01_000003 Container Transitioned from ACQUIRED to RUNNING
2014-03-31 17:28:13,209 INFO org.apache.hadoop.yarn.server.resourcemanager.rmcontainer.RMContainerImpl: container_1396312028434_0001_01_000003 Container Transitioned from RUNNING to COMPLETED
2014-03-31 17:28:13,209 INFO org.apache.hadoop.yarn.server.resourcemanager.scheduler.common.fica.FiCaSchedulerApp: Completed container: container_1396312028434_0001_01_000003 in state: COMPLETED event:FINISHED
2014-03-31 17:28:13,209 INFO org.apache.hadoop.yarn.server.resourcemanager.RMAuditLogger: USER=hduser	OPERATION=AM Released Container	TARGET=SchedulerApp	RESULT=SUCCESS	APPID=application_1396312028434_0001	CONTAINERID=container_1396312028434_0001_01_000003
2014-03-31 17:28:13,209 INFO org.apache.hadoop.yarn.server.resourcemanager.scheduler.common.fica.FiCaSchedulerNode: Released container container_1396312028434_0001_01_000003 of capacity <memory:1024, vCores:1> on host ubuntu:35171, which currently has 2 containers, <memory:3072, vCores:2> used and <memory:5120, vCores:6> available, release resources=true
2014-03-31 17:28:13,209 INFO org.apache.hadoop.yarn.server.resourcemanager.scheduler.capacity.LeafQueue: default used=<memory:3072, vCores:2> numContainers=2 user=hduser user-resources=<memory:3072, vCores:2>
2014-03-31 17:28:13,209 INFO org.apache.hadoop.yarn.server.resourcemanager.scheduler.capacity.LeafQueue: completedContainer container=Container: [ContainerId: container_1396312028434_0001_01_000003, NodeId: ubuntu:35171, NodeHttpAddress: ubuntu:8042, Resource: <memory:1024, vCores:1>, Priority: 20, Token: Token { kind: ContainerToken, service: 127.0.1.1:35171 }, ] resource=<memory:1024, vCores:1> queue=default: capacity=1.0, absoluteCapacity=1.0, usedResources=<memory:3072, vCores:2>usedCapacity=0.375, absoluteUsedCapacity=0.375, numApps=1, numContainers=2 usedCapacity=0.375 absoluteUsedCapacity=0.375 used=<memory:3072, vCores:2> cluster=<memory:8192, vCores:8>
2014-03-31 17:28:13,209 INFO org.apache.hadoop.yarn.server.resourcemanager.scheduler.capacity.ParentQueue: completedContainer queue=root usedCapacity=0.375 absoluteUsedCapacity=0.375 used=<memory:3072, vCores:2> cluster=<memory:8192, vCores:8>
2014-03-31 17:28:13,209 INFO org.apache.hadoop.yarn.server.resourcemanager.scheduler.capacity.ParentQueue: Re-sorting completed queue: root.default stats: default: capacity=1.0, absoluteCapacity=1.0, usedResources=<memory:3072, vCores:2>usedCapacity=0.375, absoluteUsedCapacity=0.375, numApps=1, numContainers=2
2014-03-31 17:28:13,209 INFO org.apache.hadoop.yarn.server.resourcemanager.scheduler.capacity.CapacityScheduler: Application appattempt_1396312028434_0001_000001 released container container_1396312028434_0001_01_000003 on node: host: ubuntu:35171 #containers=2 available=5120 used=3072 with event: FINISHED
2014-03-31 17:28:14,211 INFO org.apache.hadoop.yarn.server.resourcemanager.rmcontainer.RMContainerImpl: container_1396312028434_0001_01_000002 Container Transitioned from RUNNING to COMPLETED
2014-03-31 17:28:14,211 INFO org.apache.hadoop.yarn.server.resourcemanager.scheduler.common.fica.FiCaSchedulerApp: Completed container: container_1396312028434_0001_01_000002 in state: COMPLETED event:FINISHED
2014-03-31 17:28:14,211 INFO org.apache.hadoop.yarn.server.resourcemanager.RMAuditLogger: USER=hduser	OPERATION=AM Released Container	TARGET=SchedulerApp	RESULT=SUCCESS	APPID=application_1396312028434_0001	CONTAINERID=container_1396312028434_0001_01_000002
2014-03-31 17:28:14,212 INFO org.apache.hadoop.yarn.server.resourcemanager.scheduler.common.fica.FiCaSchedulerNode: Released container container_1396312028434_0001_01_000002 of capacity <memory:1024, vCores:1> on host ubuntu:35171, which currently has 1 containers, <memory:2048, vCores:1> used and <memory:6144, vCores:7> available, release resources=true
2014-03-31 17:28:14,212 INFO org.apache.hadoop.yarn.server.resourcemanager.scheduler.capacity.LeafQueue: default used=<memory:2048, vCores:1> numContainers=1 user=hduser user-resources=<memory:2048, vCores:1>
2014-03-31 17:28:14,212 INFO org.apache.hadoop.yarn.server.resourcemanager.scheduler.capacity.LeafQueue: completedContainer container=Container: [ContainerId: container_1396312028434_0001_01_000002, NodeId: ubuntu:35171, NodeHttpAddress: ubuntu:8042, Resource: <memory:1024, vCores:1>, Priority: 20, Token: Token { kind: ContainerToken, service: 127.0.1.1:35171 }, ] resource=<memory:1024, vCores:1> queue=default: capacity=1.0, absoluteCapacity=1.0, usedResources=<memory:2048, vCores:1>usedCapacity=0.25, absoluteUsedCapacity=0.25, numApps=1, numContainers=1 usedCapacity=0.25 absoluteUsedCapacity=0.25 used=<memory:2048, vCores:1> cluster=<memory:8192, vCores:8>
2014-03-31 17:28:14,212 INFO org.apache.hadoop.yarn.server.resourcemanager.scheduler.capacity.ParentQueue: completedContainer queue=root usedCapacity=0.25 absoluteUsedCapacity=0.25 used=<memory:2048, vCores:1> cluster=<memory:8192, vCores:8>
2014-03-31 17:28:14,212 INFO org.apache.hadoop.yarn.server.resourcemanager.scheduler.capacity.ParentQueue: Re-sorting completed queue: root.default stats: default: capacity=1.0, absoluteCapacity=1.0, usedResources=<memory:2048, vCores:1>usedCapacity=0.25, absoluteUsedCapacity=0.25, numApps=1, numContainers=1
2014-03-31 17:28:14,212 INFO org.apache.hadoop.yarn.server.resourcemanager.scheduler.capacity.CapacityScheduler: Application appattempt_1396312028434_0001_000001 released container container_1396312028434_0001_01_000002 on node: host: ubuntu:35171 #containers=1 available=6144 used=2048 with event: FINISHED
2014-03-31 17:28:15,214 INFO org.apache.hadoop.yarn.server.resourcemanager.rmcontainer.RMContainerImpl: container_1396312028434_0001_01_000004 Container Transitioned from NEW to ALLOCATED
2014-03-31 17:28:15,214 INFO org.apache.hadoop.yarn.server.resourcemanager.RMAuditLogger: USER=hduser	OPERATION=AM Allocated Container	TARGET=SchedulerApp	RESULT=SUCCESS	APPID=application_1396312028434_0001	CONTAINERID=container_1396312028434_0001_01_000004
2014-03-31 17:28:15,214 INFO org.apache.hadoop.yarn.server.resourcemanager.scheduler.common.fica.FiCaSchedulerNode: Assigned container container_1396312028434_0001_01_000004 of capacity <memory:1024, vCores:1> on host ubuntu:35171, which currently has 2 containers, <memory:3072, vCores:2> used and <memory:5120, vCores:6> available
2014-03-31 17:28:15,214 INFO org.apache.hadoop.yarn.server.resourcemanager.scheduler.capacity.LeafQueue: assignedContainer application=application_1396312028434_0001 container=Container: [ContainerId: container_1396312028434_0001_01_000004, NodeId: ubuntu:35171, NodeHttpAddress: ubuntu:8042, Resource: <memory:1024, vCores:1>, Priority: 10, Token: Token { kind: ContainerToken, service: 127.0.1.1:35171 }, ] containerId=container_1396312028434_0001_01_000004 queue=default: capacity=1.0, absoluteCapacity=1.0, usedResources=<memory:2048, vCores:1>usedCapacity=0.25, absoluteUsedCapacity=0.25, numApps=1, numContainers=1 usedCapacity=0.25 absoluteUsedCapacity=0.25 used=<memory:2048, vCores:1> cluster=<memory:8192, vCores:8>
2014-03-31 17:28:15,214 INFO org.apache.hadoop.yarn.server.resourcemanager.scheduler.capacity.ParentQueue: Re-sorting assigned queue: root.default stats: default: capacity=1.0, absoluteCapacity=1.0, usedResources=<memory:3072, vCores:2>usedCapacity=0.375, absoluteUsedCapacity=0.375, numApps=1, numContainers=2
2014-03-31 17:28:15,214 INFO org.apache.hadoop.yarn.server.resourcemanager.scheduler.capacity.ParentQueue: assignedContainer queue=root usedCapacity=0.375 absoluteUsedCapacity=0.375 used=<memory:3072, vCores:2> cluster=<memory:8192, vCores:8>
2014-03-31 17:28:15,292 INFO org.apache.hadoop.yarn.server.resourcemanager.rmcontainer.RMContainerImpl: container_1396312028434_0001_01_000004 Container Transitioned from ALLOCATED to ACQUIRED
2014-03-31 17:28:16,216 INFO org.apache.hadoop.yarn.server.resourcemanager.rmcontainer.RMContainerImpl: container_1396312028434_0001_01_000004 Container Transitioned from ACQUIRED to RUNNING
2014-03-31 17:28:16,295 INFO org.apache.hadoop.yarn.server.resourcemanager.scheduler.AppSchedulingInfo: checking for deactivate... 
2014-03-31 17:28:18,969 INFO org.apache.hadoop.yarn.server.resourcemanager.rmapp.attempt.RMAppAttemptImpl: appattempt_1396312028434_0001_000001 State change from RUNNING to FINISHING
2014-03-31 17:28:18,969 INFO org.apache.hadoop.yarn.server.resourcemanager.rmapp.RMAppImpl: Removing application with id application_1396312028434_0001
2014-03-31 17:28:18,969 INFO org.apache.hadoop.yarn.server.resourcemanager.rmapp.RMAppImpl: application_1396312028434_0001 State change from RUNNING to REMOVING
2014-03-31 17:28:18,969 INFO org.apache.hadoop.yarn.server.resourcemanager.recovery.RMStateStore: Removing info for app: application_1396312028434_0001
2014-03-31 17:28:18,970 INFO org.apache.hadoop.yarn.server.resourcemanager.rmapp.RMAppImpl: application_1396312028434_0001 State change from REMOVING to FINISHING
2014-03-31 17:28:19,456 INFO org.apache.hadoop.yarn.server.resourcemanager.rmcontainer.RMContainerImpl: container_1396312028434_0001_01_000004 Container Transitioned from RUNNING to COMPLETED
2014-03-31 17:28:19,456 INFO org.apache.hadoop.yarn.server.resourcemanager.scheduler.common.fica.FiCaSchedulerApp: Completed container: container_1396312028434_0001_01_000004 in state: COMPLETED event:FINISHED
2014-03-31 17:28:19,456 INFO org.apache.hadoop.yarn.server.resourcemanager.RMAuditLogger: USER=hduser	OPERATION=AM Released Container	TARGET=SchedulerApp	RESULT=SUCCESS	APPID=application_1396312028434_0001	CONTAINERID=container_1396312028434_0001_01_000004
2014-03-31 17:28:19,456 INFO org.apache.hadoop.yarn.server.resourcemanager.scheduler.common.fica.FiCaSchedulerNode: Released container container_1396312028434_0001_01_000004 of capacity <memory:1024, vCores:1> on host ubuntu:35171, which currently has 1 containers, <memory:2048, vCores:1> used and <memory:6144, vCores:7> available, release resources=true
2014-03-31 17:28:19,456 INFO org.apache.hadoop.yarn.server.resourcemanager.scheduler.capacity.LeafQueue: default used=<memory:2048, vCores:1> numContainers=1 user=hduser user-resources=<memory:2048, vCores:1>
2014-03-31 17:28:19,456 INFO org.apache.hadoop.yarn.server.resourcemanager.scheduler.capacity.LeafQueue: completedContainer container=Container: [ContainerId: container_1396312028434_0001_01_000004, NodeId: ubuntu:35171, NodeHttpAddress: ubuntu:8042, Resource: <memory:1024, vCores:1>, Priority: 10, Token: Token { kind: ContainerToken, service: 127.0.1.1:35171 }, ] resource=<memory:1024, vCores:1> queue=default: capacity=1.0, absoluteCapacity=1.0, usedResources=<memory:2048, vCores:1>usedCapacity=0.25, absoluteUsedCapacity=0.25, numApps=1, numContainers=1 usedCapacity=0.25 absoluteUsedCapacity=0.25 used=<memory:2048, vCores:1> cluster=<memory:8192, vCores:8>
2014-03-31 17:28:19,456 INFO org.apache.hadoop.yarn.server.resourcemanager.scheduler.capacity.ParentQueue: completedContainer queue=root usedCapacity=0.25 absoluteUsedCapacity=0.25 used=<memory:2048, vCores:1> cluster=<memory:8192, vCores:8>
2014-03-31 17:28:19,456 INFO org.apache.hadoop.yarn.server.resourcemanager.scheduler.capacity.ParentQueue: Re-sorting completed queue: root.default stats: default: capacity=1.0, absoluteCapacity=1.0, usedResources=<memory:2048, vCores:1>usedCapacity=0.25, absoluteUsedCapacity=0.25, numApps=1, numContainers=1
2014-03-31 17:28:19,456 INFO org.apache.hadoop.yarn.server.resourcemanager.scheduler.capacity.CapacityScheduler: Application appattempt_1396312028434_0001_000001 released container container_1396312028434_0001_01_000004 on node: host: ubuntu:35171 #containers=1 available=6144 used=2048 with event: FINISHED
2014-03-31 17:28:25,470 INFO org.apache.hadoop.yarn.server.resourcemanager.rmcontainer.RMContainerImpl: container_1396312028434_0001_01_000001 Container Transitioned from RUNNING to COMPLETED
2014-03-31 17:28:25,471 INFO org.apache.hadoop.yarn.server.resourcemanager.scheduler.common.fica.FiCaSchedulerApp: Completed container: container_1396312028434_0001_01_000001 in state: COMPLETED event:FINISHED
2014-03-31 17:28:25,471 INFO org.apache.hadoop.yarn.server.resourcemanager.RMAuditLogger: USER=hduser	OPERATION=AM Released Container	TARGET=SchedulerApp	RESULT=SUCCESS	APPID=application_1396312028434_0001	CONTAINERID=container_1396312028434_0001_01_000001
2014-03-31 17:28:25,471 INFO org.apache.hadoop.yarn.server.resourcemanager.scheduler.common.fica.FiCaSchedulerNode: Released container container_1396312028434_0001_01_000001 of capacity <memory:2048, vCores:1> on host ubuntu:35171, which currently has 0 containers, <memory:0, vCores:0> used and <memory:8192, vCores:8> available, release resources=true
2014-03-31 17:28:25,471 INFO org.apache.hadoop.yarn.server.resourcemanager.scheduler.capacity.LeafQueue: default used=<memory:0, vCores:0> numContainers=0 user=hduser user-resources=<memory:0, vCores:0>
2014-03-31 17:28:25,471 INFO org.apache.hadoop.yarn.server.resourcemanager.scheduler.capacity.LeafQueue: completedContainer container=Container: [ContainerId: container_1396312028434_0001_01_000001, NodeId: ubuntu:35171, NodeHttpAddress: ubuntu:8042, Resource: <memory:2048, vCores:1>, Priority: 0, Token: Token { kind: ContainerToken, service: 127.0.1.1:35171 }, ] resource=<memory:2048, vCores:1> queue=default: capacity=1.0, absoluteCapacity=1.0, usedResources=<memory:0, vCores:0>usedCapacity=0.0, absoluteUsedCapacity=0.0, numApps=1, numContainers=0 usedCapacity=0.0 absoluteUsedCapacity=0.0 used=<memory:0, vCores:0> cluster=<memory:8192, vCores:8>
2014-03-31 17:28:25,471 INFO org.apache.hadoop.yarn.server.resourcemanager.scheduler.capacity.ParentQueue: completedContainer queue=root usedCapacity=0.0 absoluteUsedCapacity=0.0 used=<memory:0, vCores:0> cluster=<memory:8192, vCores:8>
2014-03-31 17:28:25,471 INFO org.apache.hadoop.yarn.server.resourcemanager.scheduler.capacity.ParentQueue: Re-sorting completed queue: root.default stats: default: capacity=1.0, absoluteCapacity=1.0, usedResources=<memory:0, vCores:0>usedCapacity=0.0, absoluteUsedCapacity=0.0, numApps=1, numContainers=0
2014-03-31 17:28:25,471 INFO org.apache.hadoop.yarn.server.resourcemanager.scheduler.capacity.CapacityScheduler: Application appattempt_1396312028434_0001_000001 released container container_1396312028434_0001_01_000001 on node: host: ubuntu:35171 #containers=0 available=8192 used=0 with event: FINISHED
2014-03-31 17:28:25,471 INFO org.apache.hadoop.yarn.server.resourcemanager.ApplicationMasterService: Unregistering app attempt : appattempt_1396312028434_0001_000001
2014-03-31 17:28:25,472 INFO org.apache.hadoop.yarn.server.resourcemanager.rmapp.attempt.RMAppAttemptImpl: appattempt_1396312028434_0001_000001 State change from FINISHING to FINISHED
2014-03-31 17:28:25,473 INFO org.apache.hadoop.yarn.server.resourcemanager.rmapp.RMAppImpl: application_1396312028434_0001 State change from FINISHING to FINISHED
2014-03-31 17:28:25,473 INFO org.apache.hadoop.yarn.server.resourcemanager.scheduler.capacity.CapacityScheduler: Application appattempt_1396312028434_0001_000001 is done. finalState=FINISHED
2014-03-31 17:28:25,474 INFO org.apache.hadoop.yarn.server.resourcemanager.RMAuditLogger: USER=hduser	OPERATION=Application Finished - Succeeded	TARGET=RMAppManager	RESULT=SUCCESS	APPID=application_1396312028434_0001
2014-03-31 17:28:25,474 INFO org.apache.hadoop.yarn.server.resourcemanager.scheduler.AppSchedulingInfo: Application application_1396312028434_0001 requests cleared
2014-03-31 17:28:25,474 INFO org.apache.hadoop.yarn.server.resourcemanager.scheduler.capacity.LeafQueue: Application removed - appId: application_1396312028434_0001 user: hduser queue: default #user-pending-applications: 0 #user-active-applications: 0 #queue-pending-applications: 0 #queue-active-applications: 0
2014-03-31 17:28:25,474 INFO org.apache.hadoop.yarn.server.resourcemanager.scheduler.capacity.ParentQueue: Application removed - appId: application_1396312028434_0001 user: hduser leaf-queue of parent: root #applications: 0
2014-03-31 17:28:25,474 INFO org.apache.hadoop.yarn.server.resourcemanager.amlauncher.AMLauncher: Cleaning master appattempt_1396312028434_0001_000001
2014-03-31 17:28:25,475 INFO org.apache.hadoop.yarn.server.resourcemanager.RMAppManager$ApplicationSummary: appId=application_1396312028434_0001,name=wordcount,user=hduser,queue=default,state=FINISHED,trackingUrl=ubuntu:8088/proxy/application_1396312028434_0001/jobhistory/job/job_1396312028434_0001,appMasterHost=ubuntu,startTime=1396312081668,finishTime=1396312098970,finalStatus=SUCCEEDED
2014-03-31 20:02:48,172 ERROR org.apache.hadoop.yarn.server.resourcemanager.ResourceManager: RECEIVED SIGNAL 15: SIGTERM
2014-03-31 20:02:48,189 INFO org.mortbay.log: Stopped SelectChannelConnector@0.0.0.0:8088
2014-03-31 20:02:48,189 ERROR org.apache.hadoop.security.token.delegation.AbstractDelegationTokenSecretManager: InterruptedExcpetion recieved for ExpiredTokenRemover thread java.lang.InterruptedException: sleep interrupted
2014-03-31 20:02:48,190 INFO org.apache.hadoop.metrics2.impl.MetricsSystemImpl: Stopping ResourceManager metrics system...
2014-03-31 20:02:48,194 INFO org.apache.hadoop.metrics2.impl.MetricsSystemImpl: ResourceManager metrics system stopped.
2014-03-31 20:02:48,194 INFO org.apache.hadoop.metrics2.impl.MetricsSystemImpl: ResourceManager metrics system shutdown complete.
2014-03-31 20:02:48,195 WARN org.apache.hadoop.yarn.server.resourcemanager.amlauncher.ApplicationMasterLauncher: org.apache.hadoop.yarn.server.resourcemanager.amlauncher.ApplicationMasterLauncher$LauncherThread interrupted. Returning.
2014-03-31 20:02:48,196 INFO org.apache.hadoop.ipc.Server: Stopping server on 8033
2014-03-31 20:02:48,203 INFO org.apache.hadoop.ipc.Server: Stopping IPC Server Responder
2014-03-31 20:02:48,199 INFO org.apache.hadoop.ipc.Server: Stopping IPC Server listener on 8033
2014-03-31 20:02:48,203 INFO org.apache.hadoop.ipc.Server: Stopping server on 8032
2014-03-31 20:02:48,216 INFO org.apache.hadoop.ipc.Server: Stopping IPC Server listener on 8032
2014-03-31 20:02:48,216 INFO org.apache.hadoop.ipc.Server: Stopping server on 8030
2014-03-31 20:02:48,217 INFO org.apache.hadoop.ipc.Server: Stopping IPC Server Responder
2014-03-31 20:02:48,225 INFO org.apache.hadoop.ipc.Server: Stopping IPC Server listener on 8030
2014-03-31 20:02:48,227 INFO org.apache.hadoop.ipc.Server: Stopping IPC Server Responder
2014-03-31 20:02:48,228 INFO org.apache.hadoop.ipc.Server: Stopping server on 8031
2014-03-31 20:02:48,237 INFO org.apache.hadoop.ipc.Server: Stopping IPC Server listener on 8031
2014-03-31 20:02:48,240 INFO org.apache.hadoop.ipc.Server: Stopping IPC Server Responder
2014-03-31 20:02:48,240 INFO org.apache.hadoop.yarn.util.AbstractLivelinessMonitor: NMLivelinessMonitor thread interrupted
2014-03-31 20:02:48,240 ERROR org.apache.hadoop.yarn.server.resourcemanager.ResourceManager: Returning, interrupted : java.lang.InterruptedException
2014-03-31 20:02:48,241 INFO org.apache.hadoop.yarn.util.AbstractLivelinessMonitor: AMLivelinessMonitor thread interrupted
2014-03-31 20:02:48,241 INFO org.apache.hadoop.yarn.util.AbstractLivelinessMonitor: AMLivelinessMonitor thread interrupted
2014-03-31 20:02:48,241 INFO org.apache.hadoop.yarn.util.AbstractLivelinessMonitor: org.apache.hadoop.yarn.server.resourcemanager.rmcontainer.ContainerAllocationExpirer thread interrupted
2014-03-31 20:02:48,241 INFO org.apache.hadoop.yarn.server.resourcemanager.ResourceManager: SHUTDOWN_MSG: 
/************************************************************
SHUTDOWN_MSG: Shutting down ResourceManager at ubuntu/127.0.1.1
************************************************************/
2014-03-31 20:04:25,268 INFO org.apache.hadoop.yarn.server.resourcemanager.ResourceManager: STARTUP_MSG: 
/************************************************************
STARTUP_MSG: Starting ResourceManager
STARTUP_MSG:   host = ubuntu/127.0.1.1
STARTUP_MSG:   args = []
STARTUP_MSG:   version = 2.2.0
STARTUP_MSG:   build = Unknown -r Unknown; compiled by 'root' on 2014-03-31T23:45Z
STARTUP_MSG:   java = 1.7.0_51
************************************************************/
2014-03-31 20:04:25,272 INFO org.apache.hadoop.yarn.server.resourcemanager.ResourceManager: registered UNIX signal handlers for [TERM, HUP, INT]
2014-03-31 20:04:25,468 INFO org.apache.hadoop.yarn.server.resourcemanager.security.AMRMTokenSecretManager: Rolling master-key for amrm-tokens
2014-03-31 20:04:25,483 INFO org.apache.hadoop.yarn.server.resourcemanager.security.RMContainerTokenSecretManager: ContainerTokenKeyRollingInterval: 86400000ms and ContainerTokenKeyActivationDelay: 900000ms
2014-03-31 20:04:25,486 INFO org.apache.hadoop.yarn.server.resourcemanager.security.NMTokenSecretManagerInRM: NMTokenKeyRollingInterval: 86400000ms and NMTokenKeyActivationDelay: 900000ms
2014-03-31 20:04:25,491 INFO org.apache.hadoop.yarn.event.AsyncDispatcher: Registering class org.apache.hadoop.yarn.server.resourcemanager.recovery.RMStateStoreEventType for class org.apache.hadoop.yarn.server.resourcemanager.recovery.RMStateStore$ForwardingEventHandler
2014-03-31 20:04:26,825 WARN org.apache.hadoop.util.NativeCodeLoader: Unable to load native-hadoop library for your platform... using builtin-java classes where applicable
2014-03-31 20:04:26,918 INFO org.apache.hadoop.yarn.event.AsyncDispatcher: Registering class org.apache.hadoop.yarn.server.resourcemanager.NodesListManagerEventType for class org.apache.hadoop.yarn.server.resourcemanager.NodesListManager
2014-03-31 20:04:26,949 INFO org.apache.hadoop.yarn.server.resourcemanager.ResourceManager: Using Scheduler: org.apache.hadoop.yarn.server.resourcemanager.scheduler.capacity.CapacityScheduler
2014-03-31 20:04:26,997 INFO org.apache.hadoop.yarn.event.AsyncDispatcher: Registering class org.apache.hadoop.yarn.server.resourcemanager.scheduler.event.SchedulerEventType for class org.apache.hadoop.yarn.server.resourcemanager.ResourceManager$SchedulerEventDispatcher
2014-03-31 20:04:27,003 INFO org.apache.hadoop.yarn.event.AsyncDispatcher: Registering class org.apache.hadoop.yarn.server.resourcemanager.rmapp.RMAppEventType for class org.apache.hadoop.yarn.server.resourcemanager.ResourceManager$ApplicationEventDispatcher
2014-03-31 20:04:27,004 INFO org.apache.hadoop.yarn.event.AsyncDispatcher: Registering class org.apache.hadoop.yarn.server.resourcemanager.rmapp.attempt.RMAppAttemptEventType for class org.apache.hadoop.yarn.server.resourcemanager.ResourceManager$ApplicationAttemptEventDispatcher
2014-03-31 20:04:27,005 INFO org.apache.hadoop.yarn.event.AsyncDispatcher: Registering class org.apache.hadoop.yarn.server.resourcemanager.rmnode.RMNodeEventType for class org.apache.hadoop.yarn.server.resourcemanager.ResourceManager$NodeEventDispatcher
2014-03-31 20:04:27,084 INFO org.apache.hadoop.metrics2.impl.MetricsConfig: loaded properties from hadoop-metrics2.properties
2014-03-31 20:04:27,132 INFO org.apache.hadoop.metrics2.impl.MetricsSystemImpl: Scheduled snapshot period at 10 second(s).
2014-03-31 20:04:27,132 INFO org.apache.hadoop.metrics2.impl.MetricsSystemImpl: ResourceManager metrics system started
2014-03-31 20:04:27,202 INFO org.apache.hadoop.yarn.server.resourcemanager.scheduler.capacity.ParentQueue: root, capacity=1.0, asboluteCapacity=1.0, maxCapacity=1.0, asboluteMaxCapacity=1.0, state=RUNNING, acls=SUBMIT_APPLICATIONS:*ADMINISTER_QUEUE:*
2014-03-31 20:04:27,202 INFO org.apache.hadoop.yarn.server.resourcemanager.scheduler.capacity.ParentQueue: Initialized parent-queue root name=root, fullname=root
2014-03-31 20:04:27,210 INFO org.apache.hadoop.yarn.server.resourcemanager.scheduler.capacity.LeafQueue: Initializing default
capacity = 1.0 [= (float) configuredCapacity / 100 ]
asboluteCapacity = 1.0 [= parentAbsoluteCapacity * capacity ]
maxCapacity = 1.0 [= configuredMaxCapacity ]
absoluteMaxCapacity = 1.0 [= 1.0 maximumCapacity undefined, (parentAbsoluteMaxCapacity * maximumCapacity) / 100 otherwise ]
userLimit = 100 [= configuredUserLimit ]
userLimitFactor = 1.0 [= configuredUserLimitFactor ]
maxApplications = 10000 [= configuredMaximumSystemApplicationsPerQueue or (int)(configuredMaximumSystemApplications * absoluteCapacity)]
maxApplicationsPerUser = 10000 [= (int)(maxApplications * (userLimit / 100.0f) * userLimitFactor) ]
maxActiveApplications = 1 [= max((int)ceil((clusterResourceMemory / minimumAllocation) * maxAMResourcePerQueuePercent * absoluteMaxCapacity),1) ]
maxActiveAppsUsingAbsCap = 1 [= max((int)ceil((clusterResourceMemory / minimumAllocation) *maxAMResourcePercent * absoluteCapacity),1) ]
maxActiveApplicationsPerUser = 1 [= max((int)(maxActiveApplications * (userLimit / 100.0f) * userLimitFactor),1) ]
usedCapacity = 0.0 [= usedResourcesMemory / (clusterResourceMemory * absoluteCapacity)]
absoluteUsedCapacity = 0.0 [= usedResourcesMemory / clusterResourceMemory]
maxAMResourcePerQueuePercent = 0.1 [= configuredMaximumAMResourcePercent ]
minimumAllocationFactor = 0.875 [= (float)(maximumAllocationMemory - minimumAllocationMemory) / maximumAllocationMemory ]
numContainers = 0 [= currentNumContainers ]
state = RUNNING [= configuredState ]
acls = SUBMIT_APPLICATIONS:*ADMINISTER_QUEUE:* [= configuredAcls ]
nodeLocalityDelay = 0

2014-03-31 20:04:27,210 INFO org.apache.hadoop.yarn.server.resourcemanager.scheduler.capacity.CapacityScheduler: Initialized queue: default: capacity=1.0, absoluteCapacity=1.0, usedResources=<memory:0, vCores:0>usedCapacity=0.0, absoluteUsedCapacity=0.0, numApps=0, numContainers=0
2014-03-31 20:04:27,211 INFO org.apache.hadoop.yarn.server.resourcemanager.scheduler.capacity.CapacityScheduler: Initialized queue: root: numChildQueue= 1, capacity=1.0, absoluteCapacity=1.0, usedResources=<memory:0, vCores:0>usedCapacity=0.0, numApps=0, numContainers=0
2014-03-31 20:04:27,211 INFO org.apache.hadoop.yarn.server.resourcemanager.scheduler.capacity.CapacityScheduler: Initialized root queue root: numChildQueue= 1, capacity=1.0, absoluteCapacity=1.0, usedResources=<memory:0, vCores:0>usedCapacity=0.0, numApps=0, numContainers=0
2014-03-31 20:04:27,211 INFO org.apache.hadoop.yarn.server.resourcemanager.scheduler.capacity.CapacityScheduler: Initialized CapacityScheduler with calculator=class org.apache.hadoop.yarn.util.resource.DefaultResourceCalculator, minimumAllocation=<<memory:1024, vCores:1>>, maximumAllocation=<<memory:8192, vCores:32>>
2014-03-31 20:04:27,257 INFO org.apache.hadoop.yarn.event.AsyncDispatcher: Registering class org.apache.hadoop.yarn.server.resourcemanager.RMAppManagerEventType for class org.apache.hadoop.yarn.server.resourcemanager.RMAppManager
2014-03-31 20:04:27,271 INFO org.apache.hadoop.yarn.event.AsyncDispatcher: Registering class org.apache.hadoop.yarn.server.resourcemanager.amlauncher.AMLauncherEventType for class org.apache.hadoop.yarn.server.resourcemanager.amlauncher.ApplicationMasterLauncher
2014-03-31 20:04:27,274 INFO org.apache.hadoop.yarn.server.resourcemanager.RMNMInfo: Registered RMNMInfo MBean
2014-03-31 20:04:27,276 INFO org.apache.hadoop.util.HostsFileReader: Refreshing hosts (include/exclude) list
2014-03-31 20:04:27,281 INFO org.apache.hadoop.yarn.server.resourcemanager.security.AMRMTokenSecretManager: Rolling master-key for amrm-tokens
2014-03-31 20:04:27,281 INFO org.apache.hadoop.yarn.server.resourcemanager.security.RMContainerTokenSecretManager: Rolling master-key for container-tokens
2014-03-31 20:04:27,284 INFO org.apache.hadoop.yarn.server.resourcemanager.security.NMTokenSecretManagerInRM: Rolling master-key for nm-tokens
2014-03-31 20:04:27,331 INFO org.mortbay.log: Logging to org.slf4j.impl.Log4jLoggerAdapter(org.mortbay.log) via org.mortbay.log.Slf4jLog
2014-03-31 20:04:27,384 INFO org.apache.hadoop.http.HttpServer: Added global filter 'safety' (class=org.apache.hadoop.http.HttpServer$QuotingInputFilter)
2014-03-31 20:04:27,385 INFO org.apache.hadoop.http.HttpServer: Added filter static_user_filter (class=org.apache.hadoop.http.lib.StaticUserWebFilter$StaticUserFilter) to context cluster
2014-03-31 20:04:27,385 INFO org.apache.hadoop.http.HttpServer: Added filter static_user_filter (class=org.apache.hadoop.http.lib.StaticUserWebFilter$StaticUserFilter) to context logs
2014-03-31 20:04:27,385 INFO org.apache.hadoop.http.HttpServer: Added filter static_user_filter (class=org.apache.hadoop.http.lib.StaticUserWebFilter$StaticUserFilter) to context static
2014-03-31 20:04:27,388 INFO org.apache.hadoop.http.HttpServer: adding path spec: /cluster/*
2014-03-31 20:04:27,388 INFO org.apache.hadoop.http.HttpServer: adding path spec: /ws/*
2014-03-31 20:04:27,393 INFO org.apache.hadoop.http.HttpServer: Jetty bound to port 8088
2014-03-31 20:04:27,393 INFO org.mortbay.log: jetty-6.1.26
2014-03-31 20:04:27,410 INFO org.mortbay.log: Extract jar:file:/home/hduser/PatchedDistro/patched_hadoop/share/hadoop/yarn/hadoop-yarn-common-2.2.0.jar!/webapps/cluster to /tmp/Jetty_0_0_0_0_8088_cluster____u0rgz3/webapp
2014-03-31 20:04:27,574 INFO org.mortbay.log: Started SelectChannelConnector@0.0.0.0:8088
2014-03-31 20:04:27,574 INFO org.apache.hadoop.yarn.webapp.WebApps: Web app /cluster started at 8088
2014-03-31 20:04:27,872 INFO org.apache.hadoop.yarn.webapp.WebApps: Registered webapp guice modules
2014-03-31 20:04:27,873 INFO org.apache.hadoop.security.token.delegation.AbstractDelegationTokenSecretManager: Updating the current master key for generating delegation tokens
2014-03-31 20:04:27,874 INFO org.apache.hadoop.yarn.server.resourcemanager.security.RMDelegationTokenSecretManager: storing master key with keyID 1
2014-03-31 20:04:27,875 INFO org.apache.hadoop.security.token.delegation.AbstractDelegationTokenSecretManager: Starting expired delegation token remover thread, tokenRemoverScanInterval=60 min(s)
2014-03-31 20:04:27,875 INFO org.apache.hadoop.security.token.delegation.AbstractDelegationTokenSecretManager: Updating the current master key for generating delegation tokens
2014-03-31 20:04:27,875 INFO org.apache.hadoop.yarn.server.resourcemanager.security.RMDelegationTokenSecretManager: storing master key with keyID 2
2014-03-31 20:04:34,280 INFO org.apache.hadoop.ipc.Server: Starting Socket Reader #1 for port 8031
2014-03-31 20:04:34,296 INFO org.apache.hadoop.yarn.factories.impl.pb.RpcServerFactoryPBImpl: Adding protocol org.apache.hadoop.yarn.server.api.ResourceTrackerPB to the server
2014-03-31 20:04:34,296 INFO org.apache.hadoop.ipc.Server: IPC Server Responder: starting
2014-03-31 20:04:34,297 INFO org.apache.hadoop.ipc.Server: IPC Server listener on 8031: starting
2014-03-31 20:04:40,583 INFO org.apache.hadoop.ipc.Server: Starting Socket Reader #1 for port 8030
2014-03-31 20:04:40,609 INFO org.apache.hadoop.yarn.factories.impl.pb.RpcServerFactoryPBImpl: Adding protocol org.apache.hadoop.yarn.api.ApplicationMasterProtocolPB to the server
2014-03-31 20:04:40,609 INFO org.apache.hadoop.ipc.Server: IPC Server Responder: starting
2014-03-31 20:04:40,609 INFO org.apache.hadoop.ipc.Server: IPC Server listener on 8030: starting
2014-03-31 20:04:42,569 INFO org.apache.hadoop.yarn.util.RackResolver: Resolved ubuntu to /default-rack
2014-03-31 20:04:42,574 INFO org.apache.hadoop.yarn.server.resourcemanager.rmnode.RMNodeImpl: ubuntu:60709 Node Transitioned from NEW to RUNNING
2014-03-31 20:04:42,575 INFO org.apache.hadoop.yarn.server.resourcemanager.scheduler.capacity.CapacityScheduler: Added node ubuntu:60709 clusterResource: <memory:8192, vCores:8>
2014-03-31 20:04:42,576 INFO org.apache.hadoop.yarn.server.resourcemanager.ResourceTrackerService: NodeManager from node ubuntu(cmPort: 60709 httpPort: 8042) registered with capability: <memory:8192, vCores:8>, assigned nodeId ubuntu:60709
2014-03-31 20:04:46,999 INFO org.apache.hadoop.ipc.Server: Starting Socket Reader #1 for port 8032
2014-03-31 20:04:47,002 INFO org.apache.hadoop.yarn.factories.impl.pb.RpcServerFactoryPBImpl: Adding protocol org.apache.hadoop.yarn.api.ApplicationClientProtocolPB to the server
2014-03-31 20:04:47,003 INFO org.apache.hadoop.ipc.Server: IPC Server Responder: starting
2014-03-31 20:04:47,003 INFO org.apache.hadoop.ipc.Server: IPC Server listener on 8032: starting
2014-03-31 20:04:53,357 INFO org.apache.hadoop.ipc.Server: Starting Socket Reader #1 for port 8033
2014-03-31 20:04:53,363 INFO org.apache.hadoop.yarn.factories.impl.pb.RpcServerFactoryPBImpl: Adding protocol org.apache.hadoop.yarn.server.api.ResourceManagerAdministrationProtocolPB to the server
2014-03-31 20:04:53,363 INFO org.apache.hadoop.ipc.Server: IPC Server Responder: starting
2014-03-31 20:04:53,364 INFO org.apache.hadoop.ipc.Server: IPC Server listener on 8033: starting
2014-03-31 20:05:01,017 INFO org.apache.hadoop.yarn.server.resourcemanager.ClientRMService: Allocated new applicationId: 1
2014-03-31 20:05:02,274 INFO org.apache.hadoop.yarn.server.resourcemanager.rmapp.RMAppImpl: Storing application with id application_1396321465238_0001
2014-03-31 20:05:02,275 INFO org.apache.hadoop.yarn.server.resourcemanager.rmapp.RMAppImpl: application_1396321465238_0001 State change from NEW to NEW_SAVING
2014-03-31 20:05:02,275 INFO org.apache.hadoop.yarn.server.resourcemanager.ClientRMService: Application with id 1 submitted by user hduser
2014-03-31 20:05:02,277 INFO org.apache.hadoop.yarn.server.resourcemanager.RMAuditLogger: USER=hduser	IP=127.0.0.1	OPERATION=Submit Application Request	TARGET=ClientRMService	RESULT=SUCCESS	APPID=application_1396321465238_0001
2014-03-31 20:05:02,279 INFO org.apache.hadoop.yarn.server.resourcemanager.recovery.RMStateStore: Storing info for app: application_1396321465238_0001
2014-03-31 20:05:02,285 INFO org.apache.hadoop.yarn.server.resourcemanager.rmapp.RMAppImpl: application_1396321465238_0001 State change from NEW_SAVING to SUBMITTED
2014-03-31 20:05:02,286 INFO org.apache.hadoop.yarn.server.resourcemanager.ApplicationMasterService: Registering app attempt : appattempt_1396321465238_0001_000001
2014-03-31 20:05:02,290 INFO org.apache.hadoop.yarn.server.resourcemanager.rmapp.attempt.RMAppAttemptImpl: appattempt_1396321465238_0001_000001 State change from NEW to SUBMITTED
2014-03-31 20:05:02,300 INFO org.apache.hadoop.yarn.server.resourcemanager.scheduler.capacity.LeafQueue: Application application_1396321465238_0001 from user: hduser activated in queue: default
2014-03-31 20:05:02,300 INFO org.apache.hadoop.yarn.server.resourcemanager.scheduler.capacity.LeafQueue: Application added - appId: application_1396321465238_0001 user: org.apache.hadoop.yarn.server.resourcemanager.scheduler.capacity.LeafQueue$User@fc595f, leaf-queue: default #user-pending-applications: 0 #user-active-applications: 1 #queue-pending-applications: 0 #queue-active-applications: 1
2014-03-31 20:05:02,300 INFO org.apache.hadoop.yarn.server.resourcemanager.scheduler.capacity.ParentQueue: Application added - appId: application_1396321465238_0001 user: hduser leaf-queue of parent: root #applications: 1
2014-03-31 20:05:02,300 INFO org.apache.hadoop.yarn.server.resourcemanager.scheduler.capacity.CapacityScheduler: Application Submission: appattempt_1396321465238_0001_000001, user: hduser queue: default: capacity=1.0, absoluteCapacity=1.0, usedResources=<memory:0, vCores:0>usedCapacity=0.0, absoluteUsedCapacity=0.0, numApps=1, numContainers=0, currently active: 1
2014-03-31 20:05:02,301 INFO org.apache.hadoop.yarn.server.resourcemanager.rmapp.attempt.RMAppAttemptImpl: appattempt_1396321465238_0001_000001 State change from SUBMITTED to SCHEDULED
2014-03-31 20:05:02,303 INFO org.apache.hadoop.yarn.server.resourcemanager.rmapp.RMAppImpl: application_1396321465238_0001 State change from SUBMITTED to ACCEPTED
2014-03-31 20:05:02,703 INFO org.apache.hadoop.yarn.server.resourcemanager.rmcontainer.RMContainerImpl: container_1396321465238_0001_01_000001 Container Transitioned from NEW to ALLOCATED
2014-03-31 20:05:02,703 INFO org.apache.hadoop.yarn.server.resourcemanager.RMAuditLogger: USER=hduser	OPERATION=AM Allocated Container	TARGET=SchedulerApp	RESULT=SUCCESS	APPID=application_1396321465238_0001	CONTAINERID=container_1396321465238_0001_01_000001
2014-03-31 20:05:02,703 INFO org.apache.hadoop.yarn.server.resourcemanager.scheduler.common.fica.FiCaSchedulerNode: Assigned container container_1396321465238_0001_01_000001 of capacity <memory:2048, vCores:1> on host ubuntu:60709, which currently has 1 containers, <memory:2048, vCores:1> used and <memory:6144, vCores:7> available
2014-03-31 20:05:02,704 INFO org.apache.hadoop.yarn.server.resourcemanager.scheduler.capacity.LeafQueue: assignedContainer application=application_1396321465238_0001 container=Container: [ContainerId: container_1396321465238_0001_01_000001, NodeId: ubuntu:60709, NodeHttpAddress: ubuntu:8042, Resource: <memory:2048, vCores:1>, Priority: 0, Token: Token { kind: ContainerToken, service: 127.0.1.1:60709 }, ] containerId=container_1396321465238_0001_01_000001 queue=default: capacity=1.0, absoluteCapacity=1.0, usedResources=<memory:0, vCores:0>usedCapacity=0.0, absoluteUsedCapacity=0.0, numApps=1, numContainers=0 usedCapacity=0.0 absoluteUsedCapacity=0.0 used=<memory:0, vCores:0> cluster=<memory:8192, vCores:8>
2014-03-31 20:05:02,704 INFO org.apache.hadoop.yarn.server.resourcemanager.scheduler.capacity.ParentQueue: Re-sorting assigned queue: root.default stats: default: capacity=1.0, absoluteCapacity=1.0, usedResources=<memory:2048, vCores:1>usedCapacity=0.25, absoluteUsedCapacity=0.25, numApps=1, numContainers=1
2014-03-31 20:05:02,704 INFO org.apache.hadoop.yarn.server.resourcemanager.rmcontainer.RMContainerImpl: container_1396321465238_0001_01_000001 Container Transitioned from ALLOCATED to ACQUIRED
2014-03-31 20:05:02,707 INFO org.apache.hadoop.yarn.server.resourcemanager.rmapp.attempt.RMAppAttemptImpl: Storing attempt: AppId: application_1396321465238_0001 AttemptId: appattempt_1396321465238_0001_000001 MasterContainer: Container: [ContainerId: container_1396321465238_0001_01_000001, NodeId: ubuntu:60709, NodeHttpAddress: ubuntu:8042, Resource: <memory:2048, vCores:1>, Priority: 0, Token: Token { kind: ContainerToken, service: 127.0.1.1:60709 }, ]
2014-03-31 20:05:02,710 INFO org.apache.hadoop.yarn.server.resourcemanager.scheduler.capacity.ParentQueue: assignedContainer queue=root usedCapacity=0.25 absoluteUsedCapacity=0.25 used=<memory:2048, vCores:1> cluster=<memory:8192, vCores:8>
2014-03-31 20:05:02,711 INFO org.apache.hadoop.yarn.server.resourcemanager.rmapp.attempt.RMAppAttemptImpl: appattempt_1396321465238_0001_000001 State change from SCHEDULED to ALLOCATED_SAVING
2014-03-31 20:05:02,770 INFO org.apache.hadoop.yarn.server.resourcemanager.recovery.RMStateStore: Storing info for attempt: appattempt_1396321465238_0001_000001
2014-03-31 20:05:02,772 INFO org.apache.hadoop.yarn.server.resourcemanager.rmapp.attempt.RMAppAttemptImpl: appattempt_1396321465238_0001_000001 State change from ALLOCATED_SAVING to ALLOCATED
2014-03-31 20:05:02,775 INFO org.apache.hadoop.yarn.server.resourcemanager.amlauncher.AMLauncher: Launching masterappattempt_1396321465238_0001_000001
2014-03-31 20:05:02,802 INFO org.apache.hadoop.yarn.server.resourcemanager.amlauncher.AMLauncher: Setting up container Container: [ContainerId: container_1396321465238_0001_01_000001, NodeId: ubuntu:60709, NodeHttpAddress: ubuntu:8042, Resource: <memory:2048, vCores:1>, Priority: 0, Token: Token { kind: ContainerToken, service: 127.0.1.1:60709 }, ] for AM appattempt_1396321465238_0001_000001
2014-03-31 20:05:02,802 INFO org.apache.hadoop.yarn.server.resourcemanager.amlauncher.AMLauncher: Command to launch container container_1396321465238_0001_01_000001 : $JAVA_HOME/bin/java -Dlog4j.configuration=container-log4j.properties -Dyarn.app.container.log.dir=<LOG_DIR> -Dyarn.app.container.log.filesize=0 -Dhadoop.root.logger=INFO,CLA  -Xmx1024m org.apache.hadoop.mapreduce.v2.app.MRAppMaster 1><LOG_DIR>/stdout 2><LOG_DIR>/stderr 
2014-03-31 20:05:03,032 INFO org.apache.hadoop.yarn.server.resourcemanager.amlauncher.AMLauncher: Done launching container Container: [ContainerId: container_1396321465238_0001_01_000001, NodeId: ubuntu:60709, NodeHttpAddress: ubuntu:8042, Resource: <memory:2048, vCores:1>, Priority: 0, Token: Token { kind: ContainerToken, service: 127.0.1.1:60709 }, ] for AM appattempt_1396321465238_0001_000001
2014-03-31 20:05:03,032 INFO org.apache.hadoop.yarn.server.resourcemanager.rmapp.attempt.RMAppAttemptImpl: appattempt_1396321465238_0001_000001 State change from ALLOCATED to LAUNCHED
2014-03-31 20:05:03,698 INFO org.apache.hadoop.yarn.server.resourcemanager.rmcontainer.RMContainerImpl: container_1396321465238_0001_01_000001 Container Transitioned from ACQUIRED to RUNNING
2014-03-31 20:05:07,740 INFO SecurityLogger.org.apache.hadoop.ipc.Server: Auth successful for appattempt_1396321465238_0001_000001 (auth:SIMPLE)
2014-03-31 20:05:07,746 INFO org.apache.hadoop.yarn.server.resourcemanager.ApplicationMasterService: AM registration appattempt_1396321465238_0001_000001
2014-03-31 20:05:07,746 INFO org.apache.hadoop.yarn.server.resourcemanager.RMAuditLogger: USER=hduser	IP=127.0.0.1	OPERATION=Register App Master	TARGET=ApplicationMasterService	RESULT=SUCCESS	APPID=application_1396321465238_0001	APPATTEMPTID=appattempt_1396321465238_0001_000001
2014-03-31 20:05:07,751 INFO org.apache.hadoop.yarn.server.resourcemanager.rmapp.attempt.RMAppAttemptImpl: appattempt_1396321465238_0001_000001 State change from LAUNCHED to RUNNING
2014-03-31 20:05:07,751 INFO org.apache.hadoop.yarn.server.resourcemanager.rmapp.RMAppImpl: application_1396321465238_0001 State change from ACCEPTED to RUNNING
2014-03-31 20:05:09,711 INFO org.apache.hadoop.yarn.server.resourcemanager.rmcontainer.RMContainerImpl: container_1396321465238_0001_01_000002 Container Transitioned from NEW to ALLOCATED
2014-03-31 20:05:09,711 INFO org.apache.hadoop.yarn.server.resourcemanager.RMAuditLogger: USER=hduser	OPERATION=AM Allocated Container	TARGET=SchedulerApp	RESULT=SUCCESS	APPID=application_1396321465238_0001	CONTAINERID=container_1396321465238_0001_01_000002
2014-03-31 20:05:09,711 INFO org.apache.hadoop.yarn.server.resourcemanager.scheduler.common.fica.FiCaSchedulerNode: Assigned container container_1396321465238_0001_01_000002 of capacity <memory:1024, vCores:1> on host ubuntu:60709, which currently has 2 containers, <memory:3072, vCores:2> used and <memory:5120, vCores:6> available
2014-03-31 20:05:09,711 INFO org.apache.hadoop.yarn.server.resourcemanager.scheduler.capacity.LeafQueue: assignedContainer application=application_1396321465238_0001 container=Container: [ContainerId: container_1396321465238_0001_01_000002, NodeId: ubuntu:60709, NodeHttpAddress: ubuntu:8042, Resource: <memory:1024, vCores:1>, Priority: 20, Token: Token { kind: ContainerToken, service: 127.0.1.1:60709 }, ] containerId=container_1396321465238_0001_01_000002 queue=default: capacity=1.0, absoluteCapacity=1.0, usedResources=<memory:2048, vCores:1>usedCapacity=0.25, absoluteUsedCapacity=0.25, numApps=1, numContainers=1 usedCapacity=0.25 absoluteUsedCapacity=0.25 used=<memory:2048, vCores:1> cluster=<memory:8192, vCores:8>
2014-03-31 20:05:09,712 INFO org.apache.hadoop.yarn.server.resourcemanager.scheduler.capacity.ParentQueue: Re-sorting assigned queue: root.default stats: default: capacity=1.0, absoluteCapacity=1.0, usedResources=<memory:3072, vCores:2>usedCapacity=0.375, absoluteUsedCapacity=0.375, numApps=1, numContainers=2
2014-03-31 20:05:09,712 INFO org.apache.hadoop.yarn.server.resourcemanager.scheduler.capacity.ParentQueue: assignedContainer queue=root usedCapacity=0.375 absoluteUsedCapacity=0.375 used=<memory:3072, vCores:2> cluster=<memory:8192, vCores:8>
2014-03-31 20:05:09,712 INFO org.apache.hadoop.yarn.server.resourcemanager.rmcontainer.RMContainerImpl: container_1396321465238_0001_01_000003 Container Transitioned from NEW to ALLOCATED
2014-03-31 20:05:09,712 INFO org.apache.hadoop.yarn.server.resourcemanager.RMAuditLogger: USER=hduser	OPERATION=AM Allocated Container	TARGET=SchedulerApp	RESULT=SUCCESS	APPID=application_1396321465238_0001	CONTAINERID=container_1396321465238_0001_01_000003
2014-03-31 20:05:09,712 INFO org.apache.hadoop.yarn.server.resourcemanager.scheduler.common.fica.FiCaSchedulerNode: Assigned container container_1396321465238_0001_01_000003 of capacity <memory:1024, vCores:1> on host ubuntu:60709, which currently has 3 containers, <memory:4096, vCores:3> used and <memory:4096, vCores:5> available
2014-03-31 20:05:09,712 INFO org.apache.hadoop.yarn.server.resourcemanager.scheduler.capacity.LeafQueue: assignedContainer application=application_1396321465238_0001 container=Container: [ContainerId: container_1396321465238_0001_01_000003, NodeId: ubuntu:60709, NodeHttpAddress: ubuntu:8042, Resource: <memory:1024, vCores:1>, Priority: 20, Token: Token { kind: ContainerToken, service: 127.0.1.1:60709 }, ] containerId=container_1396321465238_0001_01_000003 queue=default: capacity=1.0, absoluteCapacity=1.0, usedResources=<memory:3072, vCores:2>usedCapacity=0.375, absoluteUsedCapacity=0.375, numApps=1, numContainers=2 usedCapacity=0.375 absoluteUsedCapacity=0.375 used=<memory:3072, vCores:2> cluster=<memory:8192, vCores:8>
2014-03-31 20:05:09,712 INFO org.apache.hadoop.yarn.server.resourcemanager.scheduler.capacity.ParentQueue: Re-sorting assigned queue: root.default stats: default: capacity=1.0, absoluteCapacity=1.0, usedResources=<memory:4096, vCores:3>usedCapacity=0.5, absoluteUsedCapacity=0.5, numApps=1, numContainers=3
2014-03-31 20:05:09,713 INFO org.apache.hadoop.yarn.server.resourcemanager.scheduler.capacity.ParentQueue: assignedContainer queue=root usedCapacity=0.5 absoluteUsedCapacity=0.5 used=<memory:4096, vCores:3> cluster=<memory:8192, vCores:8>
2014-03-31 20:05:09,795 INFO org.apache.hadoop.yarn.server.resourcemanager.rmcontainer.RMContainerImpl: container_1396321465238_0001_01_000002 Container Transitioned from ALLOCATED to ACQUIRED
2014-03-31 20:05:09,796 INFO org.apache.hadoop.yarn.server.resourcemanager.rmcontainer.RMContainerImpl: container_1396321465238_0001_01_000003 Container Transitioned from ALLOCATED to ACQUIRED
2014-03-31 20:05:10,714 INFO org.apache.hadoop.yarn.server.resourcemanager.rmcontainer.RMContainerImpl: container_1396321465238_0001_01_000002 Container Transitioned from ACQUIRED to RUNNING
2014-03-31 20:05:10,715 INFO org.apache.hadoop.yarn.server.resourcemanager.rmcontainer.RMContainerImpl: container_1396321465238_0001_01_000003 Container Transitioned from ACQUIRED to RUNNING
2014-03-31 20:05:10,814 INFO org.apache.hadoop.yarn.server.resourcemanager.scheduler.AppSchedulingInfo: checking for deactivate... 
2014-03-31 20:05:13,420 INFO org.apache.hadoop.yarn.server.resourcemanager.rmcontainer.RMContainerImpl: container_1396321465238_0001_01_000003 Container Transitioned from RUNNING to COMPLETED
2014-03-31 20:05:13,420 INFO org.apache.hadoop.yarn.server.resourcemanager.scheduler.common.fica.FiCaSchedulerApp: Completed container: container_1396321465238_0001_01_000003 in state: COMPLETED event:FINISHED
2014-03-31 20:05:13,420 INFO org.apache.hadoop.yarn.server.resourcemanager.RMAuditLogger: USER=hduser	OPERATION=AM Released Container	TARGET=SchedulerApp	RESULT=SUCCESS	APPID=application_1396321465238_0001	CONTAINERID=container_1396321465238_0001_01_000003
2014-03-31 20:05:13,420 INFO org.apache.hadoop.yarn.server.resourcemanager.scheduler.common.fica.FiCaSchedulerNode: Released container container_1396321465238_0001_01_000003 of capacity <memory:1024, vCores:1> on host ubuntu:60709, which currently has 2 containers, <memory:3072, vCores:2> used and <memory:5120, vCores:6> available, release resources=true
2014-03-31 20:05:13,420 INFO org.apache.hadoop.yarn.server.resourcemanager.scheduler.capacity.LeafQueue: default used=<memory:3072, vCores:2> numContainers=2 user=hduser user-resources=<memory:3072, vCores:2>
2014-03-31 20:05:13,421 INFO org.apache.hadoop.yarn.server.resourcemanager.scheduler.capacity.LeafQueue: completedContainer container=Container: [ContainerId: container_1396321465238_0001_01_000003, NodeId: ubuntu:60709, NodeHttpAddress: ubuntu:8042, Resource: <memory:1024, vCores:1>, Priority: 20, Token: Token { kind: ContainerToken, service: 127.0.1.1:60709 }, ] resource=<memory:1024, vCores:1> queue=default: capacity=1.0, absoluteCapacity=1.0, usedResources=<memory:3072, vCores:2>usedCapacity=0.375, absoluteUsedCapacity=0.375, numApps=1, numContainers=2 usedCapacity=0.375 absoluteUsedCapacity=0.375 used=<memory:3072, vCores:2> cluster=<memory:8192, vCores:8>
2014-03-31 20:05:13,421 INFO org.apache.hadoop.yarn.server.resourcemanager.scheduler.capacity.ParentQueue: completedContainer queue=root usedCapacity=0.375 absoluteUsedCapacity=0.375 used=<memory:3072, vCores:2> cluster=<memory:8192, vCores:8>
2014-03-31 20:05:13,421 INFO org.apache.hadoop.yarn.server.resourcemanager.scheduler.capacity.ParentQueue: Re-sorting completed queue: root.default stats: default: capacity=1.0, absoluteCapacity=1.0, usedResources=<memory:3072, vCores:2>usedCapacity=0.375, absoluteUsedCapacity=0.375, numApps=1, numContainers=2
2014-03-31 20:05:13,421 INFO org.apache.hadoop.yarn.server.resourcemanager.scheduler.capacity.CapacityScheduler: Application appattempt_1396321465238_0001_000001 released container container_1396321465238_0001_01_000003 on node: host: ubuntu:60709 #containers=2 available=5120 used=3072 with event: FINISHED
2014-03-31 20:05:14,423 INFO org.apache.hadoop.yarn.server.resourcemanager.rmcontainer.RMContainerImpl: container_1396321465238_0001_01_000002 Container Transitioned from RUNNING to COMPLETED
2014-03-31 20:05:14,423 INFO org.apache.hadoop.yarn.server.resourcemanager.scheduler.common.fica.FiCaSchedulerApp: Completed container: container_1396321465238_0001_01_000002 in state: COMPLETED event:FINISHED
2014-03-31 20:05:14,423 INFO org.apache.hadoop.yarn.server.resourcemanager.RMAuditLogger: USER=hduser	OPERATION=AM Released Container	TARGET=SchedulerApp	RESULT=SUCCESS	APPID=application_1396321465238_0001	CONTAINERID=container_1396321465238_0001_01_000002
2014-03-31 20:05:14,423 INFO org.apache.hadoop.yarn.server.resourcemanager.scheduler.common.fica.FiCaSchedulerNode: Released container container_1396321465238_0001_01_000002 of capacity <memory:1024, vCores:1> on host ubuntu:60709, which currently has 1 containers, <memory:2048, vCores:1> used and <memory:6144, vCores:7> available, release resources=true
2014-03-31 20:05:14,423 INFO org.apache.hadoop.yarn.server.resourcemanager.scheduler.capacity.LeafQueue: default used=<memory:2048, vCores:1> numContainers=1 user=hduser user-resources=<memory:2048, vCores:1>
2014-03-31 20:05:14,423 INFO org.apache.hadoop.yarn.server.resourcemanager.scheduler.capacity.LeafQueue: completedContainer container=Container: [ContainerId: container_1396321465238_0001_01_000002, NodeId: ubuntu:60709, NodeHttpAddress: ubuntu:8042, Resource: <memory:1024, vCores:1>, Priority: 20, Token: Token { kind: ContainerToken, service: 127.0.1.1:60709 }, ] resource=<memory:1024, vCores:1> queue=default: capacity=1.0, absoluteCapacity=1.0, usedResources=<memory:2048, vCores:1>usedCapacity=0.25, absoluteUsedCapacity=0.25, numApps=1, numContainers=1 usedCapacity=0.25 absoluteUsedCapacity=0.25 used=<memory:2048, vCores:1> cluster=<memory:8192, vCores:8>
2014-03-31 20:05:14,423 INFO org.apache.hadoop.yarn.server.resourcemanager.scheduler.capacity.ParentQueue: completedContainer queue=root usedCapacity=0.25 absoluteUsedCapacity=0.25 used=<memory:2048, vCores:1> cluster=<memory:8192, vCores:8>
2014-03-31 20:05:14,423 INFO org.apache.hadoop.yarn.server.resourcemanager.scheduler.capacity.ParentQueue: Re-sorting completed queue: root.default stats: default: capacity=1.0, absoluteCapacity=1.0, usedResources=<memory:2048, vCores:1>usedCapacity=0.25, absoluteUsedCapacity=0.25, numApps=1, numContainers=1
2014-03-31 20:05:14,423 INFO org.apache.hadoop.yarn.server.resourcemanager.scheduler.capacity.CapacityScheduler: Application appattempt_1396321465238_0001_000001 released container container_1396321465238_0001_01_000002 on node: host: ubuntu:60709 #containers=1 available=6144 used=2048 with event: FINISHED
2014-03-31 20:05:15,427 INFO org.apache.hadoop.yarn.server.resourcemanager.rmcontainer.RMContainerImpl: container_1396321465238_0001_01_000004 Container Transitioned from NEW to ALLOCATED
2014-03-31 20:05:15,427 INFO org.apache.hadoop.yarn.server.resourcemanager.RMAuditLogger: USER=hduser	OPERATION=AM Allocated Container	TARGET=SchedulerApp	RESULT=SUCCESS	APPID=application_1396321465238_0001	CONTAINERID=container_1396321465238_0001_01_000004
2014-03-31 20:05:15,427 INFO org.apache.hadoop.yarn.server.resourcemanager.scheduler.common.fica.FiCaSchedulerNode: Assigned container container_1396321465238_0001_01_000004 of capacity <memory:1024, vCores:1> on host ubuntu:60709, which currently has 2 containers, <memory:3072, vCores:2> used and <memory:5120, vCores:6> available
2014-03-31 20:05:15,427 INFO org.apache.hadoop.yarn.server.resourcemanager.scheduler.capacity.LeafQueue: assignedContainer application=application_1396321465238_0001 container=Container: [ContainerId: container_1396321465238_0001_01_000004, NodeId: ubuntu:60709, NodeHttpAddress: ubuntu:8042, Resource: <memory:1024, vCores:1>, Priority: 10, Token: Token { kind: ContainerToken, service: 127.0.1.1:60709 }, ] containerId=container_1396321465238_0001_01_000004 queue=default: capacity=1.0, absoluteCapacity=1.0, usedResources=<memory:2048, vCores:1>usedCapacity=0.25, absoluteUsedCapacity=0.25, numApps=1, numContainers=1 usedCapacity=0.25 absoluteUsedCapacity=0.25 used=<memory:2048, vCores:1> cluster=<memory:8192, vCores:8>
2014-03-31 20:05:15,427 INFO org.apache.hadoop.yarn.server.resourcemanager.scheduler.capacity.ParentQueue: Re-sorting assigned queue: root.default stats: default: capacity=1.0, absoluteCapacity=1.0, usedResources=<memory:3072, vCores:2>usedCapacity=0.375, absoluteUsedCapacity=0.375, numApps=1, numContainers=2
2014-03-31 20:05:15,427 INFO org.apache.hadoop.yarn.server.resourcemanager.scheduler.capacity.ParentQueue: assignedContainer queue=root usedCapacity=0.375 absoluteUsedCapacity=0.375 used=<memory:3072, vCores:2> cluster=<memory:8192, vCores:8>
2014-03-31 20:05:15,840 INFO org.apache.hadoop.yarn.server.resourcemanager.rmcontainer.RMContainerImpl: container_1396321465238_0001_01_000004 Container Transitioned from ALLOCATED to ACQUIRED
2014-03-31 20:05:16,428 INFO org.apache.hadoop.yarn.server.resourcemanager.rmcontainer.RMContainerImpl: container_1396321465238_0001_01_000004 Container Transitioned from ACQUIRED to RUNNING
2014-03-31 20:05:16,851 INFO org.apache.hadoop.yarn.server.resourcemanager.scheduler.AppSchedulingInfo: checking for deactivate... 
2014-03-31 20:05:19,088 INFO org.apache.hadoop.yarn.server.resourcemanager.rmapp.attempt.RMAppAttemptImpl: appattempt_1396321465238_0001_000001 State change from RUNNING to FINISHING
2014-03-31 20:05:19,088 INFO org.apache.hadoop.yarn.server.resourcemanager.rmapp.RMAppImpl: Removing application with id application_1396321465238_0001
2014-03-31 20:05:19,088 INFO org.apache.hadoop.yarn.server.resourcemanager.rmapp.RMAppImpl: application_1396321465238_0001 State change from RUNNING to REMOVING
2014-03-31 20:05:19,089 INFO org.apache.hadoop.yarn.server.resourcemanager.recovery.RMStateStore: Removing info for app: application_1396321465238_0001
2014-03-31 20:05:19,089 INFO org.apache.hadoop.yarn.server.resourcemanager.rmapp.RMAppImpl: application_1396321465238_0001 State change from REMOVING to FINISHING
2014-03-31 20:05:19,975 INFO org.apache.hadoop.yarn.server.resourcemanager.rmcontainer.RMContainerImpl: container_1396321465238_0001_01_000004 Container Transitioned from RUNNING to COMPLETED
2014-03-31 20:05:19,975 INFO org.apache.hadoop.yarn.server.resourcemanager.scheduler.common.fica.FiCaSchedulerApp: Completed container: container_1396321465238_0001_01_000004 in state: COMPLETED event:FINISHED
2014-03-31 20:05:19,975 INFO org.apache.hadoop.yarn.server.resourcemanager.RMAuditLogger: USER=hduser	OPERATION=AM Released Container	TARGET=SchedulerApp	RESULT=SUCCESS	APPID=application_1396321465238_0001	CONTAINERID=container_1396321465238_0001_01_000004
2014-03-31 20:05:19,975 INFO org.apache.hadoop.yarn.server.resourcemanager.scheduler.common.fica.FiCaSchedulerNode: Released container container_1396321465238_0001_01_000004 of capacity <memory:1024, vCores:1> on host ubuntu:60709, which currently has 1 containers, <memory:2048, vCores:1> used and <memory:6144, vCores:7> available, release resources=true
2014-03-31 20:05:19,975 INFO org.apache.hadoop.yarn.server.resourcemanager.scheduler.capacity.LeafQueue: default used=<memory:2048, vCores:1> numContainers=1 user=hduser user-resources=<memory:2048, vCores:1>
2014-03-31 20:05:19,975 INFO org.apache.hadoop.yarn.server.resourcemanager.scheduler.capacity.LeafQueue: completedContainer container=Container: [ContainerId: container_1396321465238_0001_01_000004, NodeId: ubuntu:60709, NodeHttpAddress: ubuntu:8042, Resource: <memory:1024, vCores:1>, Priority: 10, Token: Token { kind: ContainerToken, service: 127.0.1.1:60709 }, ] resource=<memory:1024, vCores:1> queue=default: capacity=1.0, absoluteCapacity=1.0, usedResources=<memory:2048, vCores:1>usedCapacity=0.25, absoluteUsedCapacity=0.25, numApps=1, numContainers=1 usedCapacity=0.25 absoluteUsedCapacity=0.25 used=<memory:2048, vCores:1> cluster=<memory:8192, vCores:8>
2014-03-31 20:05:19,975 INFO org.apache.hadoop.yarn.server.resourcemanager.scheduler.capacity.ParentQueue: completedContainer queue=root usedCapacity=0.25 absoluteUsedCapacity=0.25 used=<memory:2048, vCores:1> cluster=<memory:8192, vCores:8>
2014-03-31 20:05:19,975 INFO org.apache.hadoop.yarn.server.resourcemanager.scheduler.capacity.ParentQueue: Re-sorting completed queue: root.default stats: default: capacity=1.0, absoluteCapacity=1.0, usedResources=<memory:2048, vCores:1>usedCapacity=0.25, absoluteUsedCapacity=0.25, numApps=1, numContainers=1
2014-03-31 20:05:19,975 INFO org.apache.hadoop.yarn.server.resourcemanager.scheduler.capacity.CapacityScheduler: Application appattempt_1396321465238_0001_000001 released container container_1396321465238_0001_01_000004 on node: host: ubuntu:60709 #containers=1 available=6144 used=2048 with event: FINISHED
2014-03-31 20:05:25,995 INFO org.apache.hadoop.yarn.server.resourcemanager.rmcontainer.RMContainerImpl: container_1396321465238_0001_01_000001 Container Transitioned from RUNNING to COMPLETED
2014-03-31 20:05:25,995 INFO org.apache.hadoop.yarn.server.resourcemanager.scheduler.common.fica.FiCaSchedulerApp: Completed container: container_1396321465238_0001_01_000001 in state: COMPLETED event:FINISHED
2014-03-31 20:05:25,995 INFO org.apache.hadoop.yarn.server.resourcemanager.RMAuditLogger: USER=hduser	OPERATION=AM Released Container	TARGET=SchedulerApp	RESULT=SUCCESS	APPID=application_1396321465238_0001	CONTAINERID=container_1396321465238_0001_01_000001
2014-03-31 20:05:25,995 INFO org.apache.hadoop.yarn.server.resourcemanager.scheduler.common.fica.FiCaSchedulerNode: Released container container_1396321465238_0001_01_000001 of capacity <memory:2048, vCores:1> on host ubuntu:60709, which currently has 0 containers, <memory:0, vCores:0> used and <memory:8192, vCores:8> available, release resources=true
2014-03-31 20:05:25,995 INFO org.apache.hadoop.yarn.server.resourcemanager.scheduler.capacity.LeafQueue: default used=<memory:0, vCores:0> numContainers=0 user=hduser user-resources=<memory:0, vCores:0>
2014-03-31 20:05:25,995 INFO org.apache.hadoop.yarn.server.resourcemanager.scheduler.capacity.LeafQueue: completedContainer container=Container: [ContainerId: container_1396321465238_0001_01_000001, NodeId: ubuntu:60709, NodeHttpAddress: ubuntu:8042, Resource: <memory:2048, vCores:1>, Priority: 0, Token: Token { kind: ContainerToken, service: 127.0.1.1:60709 }, ] resource=<memory:2048, vCores:1> queue=default: capacity=1.0, absoluteCapacity=1.0, usedResources=<memory:0, vCores:0>usedCapacity=0.0, absoluteUsedCapacity=0.0, numApps=1, numContainers=0 usedCapacity=0.0 absoluteUsedCapacity=0.0 used=<memory:0, vCores:0> cluster=<memory:8192, vCores:8>
2014-03-31 20:05:25,996 INFO org.apache.hadoop.yarn.server.resourcemanager.scheduler.capacity.ParentQueue: completedContainer queue=root usedCapacity=0.0 absoluteUsedCapacity=0.0 used=<memory:0, vCores:0> cluster=<memory:8192, vCores:8>
2014-03-31 20:05:25,996 INFO org.apache.hadoop.yarn.server.resourcemanager.scheduler.capacity.ParentQueue: Re-sorting completed queue: root.default stats: default: capacity=1.0, absoluteCapacity=1.0, usedResources=<memory:0, vCores:0>usedCapacity=0.0, absoluteUsedCapacity=0.0, numApps=1, numContainers=0
2014-03-31 20:05:25,996 INFO org.apache.hadoop.yarn.server.resourcemanager.scheduler.capacity.CapacityScheduler: Application appattempt_1396321465238_0001_000001 released container container_1396321465238_0001_01_000001 on node: host: ubuntu:60709 #containers=0 available=8192 used=0 with event: FINISHED
2014-03-31 20:05:25,996 INFO org.apache.hadoop.yarn.server.resourcemanager.ApplicationMasterService: Unregistering app attempt : appattempt_1396321465238_0001_000001
2014-03-31 20:05:25,997 INFO org.apache.hadoop.yarn.server.resourcemanager.rmapp.attempt.RMAppAttemptImpl: appattempt_1396321465238_0001_000001 State change from FINISHING to FINISHED
2014-03-31 20:05:25,998 INFO org.apache.hadoop.yarn.server.resourcemanager.rmapp.RMAppImpl: application_1396321465238_0001 State change from FINISHING to FINISHED
2014-03-31 20:05:25,998 INFO org.apache.hadoop.yarn.server.resourcemanager.scheduler.capacity.CapacityScheduler: Application appattempt_1396321465238_0001_000001 is done. finalState=FINISHED
2014-03-31 20:05:25,999 INFO org.apache.hadoop.yarn.server.resourcemanager.scheduler.AppSchedulingInfo: Application application_1396321465238_0001 requests cleared
2014-03-31 20:05:25,999 INFO org.apache.hadoop.yarn.server.resourcemanager.scheduler.capacity.LeafQueue: Application removed - appId: application_1396321465238_0001 user: hduser queue: default #user-pending-applications: 0 #user-active-applications: 0 #queue-pending-applications: 0 #queue-active-applications: 0
2014-03-31 20:05:25,999 INFO org.apache.hadoop.yarn.server.resourcemanager.scheduler.capacity.ParentQueue: Application removed - appId: application_1396321465238_0001 user: hduser leaf-queue of parent: root #applications: 0
2014-03-31 20:05:25,999 INFO org.apache.hadoop.yarn.server.resourcemanager.amlauncher.AMLauncher: Cleaning master appattempt_1396321465238_0001_000001
2014-03-31 20:05:26,000 INFO org.apache.hadoop.yarn.server.resourcemanager.RMAuditLogger: USER=hduser	OPERATION=Application Finished - Succeeded	TARGET=RMAppManager	RESULT=SUCCESS	APPID=application_1396321465238_0001
2014-03-31 20:05:26,002 INFO org.apache.hadoop.yarn.server.resourcemanager.RMAppManager$ApplicationSummary: appId=application_1396321465238_0001,name=wordcount,user=hduser,queue=default,state=FINISHED,trackingUrl=ubuntu:8088/proxy/application_1396321465238_0001/jobhistory/job/job_1396321465238_0001,appMasterHost=ubuntu,startTime=1396321502273,finishTime=1396321519089,finalStatus=SUCCEEDED
2014-03-31 20:12:06,600 INFO org.apache.hadoop.yarn.server.resourcemanager.ClientRMService: Allocated new applicationId: 2
2014-03-31 20:12:07,322 INFO org.apache.hadoop.yarn.server.resourcemanager.ClientRMService: Application with id 2 submitted by user hduser
2014-03-31 20:12:07,322 INFO org.apache.hadoop.yarn.server.resourcemanager.RMAuditLogger: USER=hduser	IP=127.0.0.1	OPERATION=Submit Application Request	TARGET=ClientRMService	RESULT=SUCCESS	APPID=application_1396321465238_0002
2014-03-31 20:12:07,322 INFO org.apache.hadoop.yarn.server.resourcemanager.rmapp.RMAppImpl: Storing application with id application_1396321465238_0002
2014-03-31 20:12:07,323 INFO org.apache.hadoop.yarn.server.resourcemanager.rmapp.RMAppImpl: application_1396321465238_0002 State change from NEW to NEW_SAVING
2014-03-31 20:12:07,323 INFO org.apache.hadoop.yarn.server.resourcemanager.recovery.RMStateStore: Storing info for app: application_1396321465238_0002
2014-03-31 20:12:07,323 INFO org.apache.hadoop.yarn.server.resourcemanager.rmapp.RMAppImpl: application_1396321465238_0002 State change from NEW_SAVING to SUBMITTED
2014-03-31 20:12:07,323 INFO org.apache.hadoop.yarn.server.resourcemanager.ApplicationMasterService: Registering app attempt : appattempt_1396321465238_0002_000001
2014-03-31 20:12:07,324 INFO org.apache.hadoop.yarn.server.resourcemanager.rmapp.attempt.RMAppAttemptImpl: appattempt_1396321465238_0002_000001 State change from NEW to SUBMITTED
2014-03-31 20:12:07,324 INFO org.apache.hadoop.yarn.server.resourcemanager.scheduler.capacity.LeafQueue: Application application_1396321465238_0002 from user: hduser activated in queue: default
2014-03-31 20:12:07,324 INFO org.apache.hadoop.yarn.server.resourcemanager.scheduler.capacity.LeafQueue: Application added - appId: application_1396321465238_0002 user: org.apache.hadoop.yarn.server.resourcemanager.scheduler.capacity.LeafQueue$User@19aa40b, leaf-queue: default #user-pending-applications: 0 #user-active-applications: 1 #queue-pending-applications: 0 #queue-active-applications: 1
2014-03-31 20:12:07,324 INFO org.apache.hadoop.yarn.server.resourcemanager.scheduler.capacity.ParentQueue: Application added - appId: application_1396321465238_0002 user: hduser leaf-queue of parent: root #applications: 1
2014-03-31 20:12:07,324 INFO org.apache.hadoop.yarn.server.resourcemanager.scheduler.capacity.CapacityScheduler: Application Submission: appattempt_1396321465238_0002_000001, user: hduser queue: default: capacity=1.0, absoluteCapacity=1.0, usedResources=<memory:0, vCores:0>usedCapacity=0.0, absoluteUsedCapacity=0.0, numApps=1, numContainers=0, currently active: 1
2014-03-31 20:12:07,324 INFO org.apache.hadoop.yarn.server.resourcemanager.rmapp.attempt.RMAppAttemptImpl: appattempt_1396321465238_0002_000001 State change from SUBMITTED to SCHEDULED
2014-03-31 20:12:07,324 INFO org.apache.hadoop.yarn.server.resourcemanager.rmapp.RMAppImpl: application_1396321465238_0002 State change from SUBMITTED to ACCEPTED
2014-03-31 20:12:08,052 INFO org.apache.hadoop.yarn.server.resourcemanager.rmcontainer.RMContainerImpl: container_1396321465238_0002_01_000001 Container Transitioned from NEW to ALLOCATED
2014-03-31 20:12:08,052 INFO org.apache.hadoop.yarn.server.resourcemanager.RMAuditLogger: USER=hduser	OPERATION=AM Allocated Container	TARGET=SchedulerApp	RESULT=SUCCESS	APPID=application_1396321465238_0002	CONTAINERID=container_1396321465238_0002_01_000001
2014-03-31 20:12:08,052 INFO org.apache.hadoop.yarn.server.resourcemanager.scheduler.common.fica.FiCaSchedulerNode: Assigned container container_1396321465238_0002_01_000001 of capacity <memory:2048, vCores:1> on host ubuntu:60709, which currently has 1 containers, <memory:2048, vCores:1> used and <memory:6144, vCores:7> available
2014-03-31 20:12:08,052 INFO org.apache.hadoop.yarn.server.resourcemanager.scheduler.capacity.LeafQueue: assignedContainer application=application_1396321465238_0002 container=Container: [ContainerId: container_1396321465238_0002_01_000001, NodeId: ubuntu:60709, NodeHttpAddress: ubuntu:8042, Resource: <memory:2048, vCores:1>, Priority: 0, Token: Token { kind: ContainerToken, service: 127.0.1.1:60709 }, ] containerId=container_1396321465238_0002_01_000001 queue=default: capacity=1.0, absoluteCapacity=1.0, usedResources=<memory:0, vCores:0>usedCapacity=0.0, absoluteUsedCapacity=0.0, numApps=1, numContainers=0 usedCapacity=0.0 absoluteUsedCapacity=0.0 used=<memory:0, vCores:0> cluster=<memory:8192, vCores:8>
2014-03-31 20:12:08,052 INFO org.apache.hadoop.yarn.server.resourcemanager.scheduler.capacity.ParentQueue: Re-sorting assigned queue: root.default stats: default: capacity=1.0, absoluteCapacity=1.0, usedResources=<memory:2048, vCores:1>usedCapacity=0.25, absoluteUsedCapacity=0.25, numApps=1, numContainers=1
2014-03-31 20:12:08,052 INFO org.apache.hadoop.yarn.server.resourcemanager.scheduler.capacity.ParentQueue: assignedContainer queue=root usedCapacity=0.25 absoluteUsedCapacity=0.25 used=<memory:2048, vCores:1> cluster=<memory:8192, vCores:8>
2014-03-31 20:12:08,053 INFO org.apache.hadoop.yarn.server.resourcemanager.rmcontainer.RMContainerImpl: container_1396321465238_0002_01_000001 Container Transitioned from ALLOCATED to ACQUIRED
2014-03-31 20:12:08,054 INFO org.apache.hadoop.yarn.server.resourcemanager.rmapp.attempt.RMAppAttemptImpl: Storing attempt: AppId: application_1396321465238_0002 AttemptId: appattempt_1396321465238_0002_000001 MasterContainer: Container: [ContainerId: container_1396321465238_0002_01_000001, NodeId: ubuntu:60709, NodeHttpAddress: ubuntu:8042, Resource: <memory:2048, vCores:1>, Priority: 0, Token: Token { kind: ContainerToken, service: 127.0.1.1:60709 }, ]
2014-03-31 20:12:08,054 INFO org.apache.hadoop.yarn.server.resourcemanager.rmapp.attempt.RMAppAttemptImpl: appattempt_1396321465238_0002_000001 State change from SCHEDULED to ALLOCATED_SAVING
2014-03-31 20:12:08,054 INFO org.apache.hadoop.yarn.server.resourcemanager.recovery.RMStateStore: Storing info for attempt: appattempt_1396321465238_0002_000001
2014-03-31 20:12:08,054 INFO org.apache.hadoop.yarn.server.resourcemanager.rmapp.attempt.RMAppAttemptImpl: appattempt_1396321465238_0002_000001 State change from ALLOCATED_SAVING to ALLOCATED
2014-03-31 20:12:08,055 INFO org.apache.hadoop.yarn.server.resourcemanager.amlauncher.AMLauncher: Launching masterappattempt_1396321465238_0002_000001
2014-03-31 20:12:08,056 INFO org.apache.hadoop.yarn.server.resourcemanager.amlauncher.AMLauncher: Setting up container Container: [ContainerId: container_1396321465238_0002_01_000001, NodeId: ubuntu:60709, NodeHttpAddress: ubuntu:8042, Resource: <memory:2048, vCores:1>, Priority: 0, Token: Token { kind: ContainerToken, service: 127.0.1.1:60709 }, ] for AM appattempt_1396321465238_0002_000001
2014-03-31 20:12:08,057 INFO org.apache.hadoop.yarn.server.resourcemanager.amlauncher.AMLauncher: Command to launch container container_1396321465238_0002_01_000001 : $JAVA_HOME/bin/java -Dlog4j.configuration=container-log4j.properties -Dyarn.app.container.log.dir=<LOG_DIR> -Dyarn.app.container.log.filesize=0 -Dhadoop.root.logger=INFO,CLA  -Xmx1024m org.apache.hadoop.mapreduce.v2.app.MRAppMaster 1><LOG_DIR>/stdout 2><LOG_DIR>/stderr 
2014-03-31 20:12:08,066 INFO org.apache.hadoop.yarn.server.resourcemanager.amlauncher.AMLauncher: Done launching container Container: [ContainerId: container_1396321465238_0002_01_000001, NodeId: ubuntu:60709, NodeHttpAddress: ubuntu:8042, Resource: <memory:2048, vCores:1>, Priority: 0, Token: Token { kind: ContainerToken, service: 127.0.1.1:60709 }, ] for AM appattempt_1396321465238_0002_000001
2014-03-31 20:12:08,067 INFO org.apache.hadoop.yarn.server.resourcemanager.rmapp.attempt.RMAppAttemptImpl: appattempt_1396321465238_0002_000001 State change from ALLOCATED to LAUNCHED
2014-03-31 20:12:09,053 INFO org.apache.hadoop.yarn.server.resourcemanager.rmcontainer.RMContainerImpl: container_1396321465238_0002_01_000001 Container Transitioned from ACQUIRED to RUNNING
2014-03-31 20:12:11,865 INFO SecurityLogger.org.apache.hadoop.ipc.Server: Auth successful for appattempt_1396321465238_0002_000001 (auth:SIMPLE)
2014-03-31 20:12:11,867 INFO org.apache.hadoop.yarn.server.resourcemanager.ApplicationMasterService: AM registration appattempt_1396321465238_0002_000001
2014-03-31 20:12:11,867 INFO org.apache.hadoop.yarn.server.resourcemanager.RMAuditLogger: USER=hduser	IP=127.0.0.1	OPERATION=Register App Master	TARGET=ApplicationMasterService	RESULT=SUCCESS	APPID=application_1396321465238_0002	APPATTEMPTID=appattempt_1396321465238_0002_000001
2014-03-31 20:12:11,869 INFO org.apache.hadoop.yarn.server.resourcemanager.rmapp.attempt.RMAppAttemptImpl: appattempt_1396321465238_0002_000001 State change from LAUNCHED to RUNNING
2014-03-31 20:12:11,869 INFO org.apache.hadoop.yarn.server.resourcemanager.rmapp.RMAppImpl: application_1396321465238_0002 State change from ACCEPTED to RUNNING
2014-03-31 20:12:13,065 INFO org.apache.hadoop.yarn.server.resourcemanager.rmcontainer.RMContainerImpl: container_1396321465238_0002_01_000002 Container Transitioned from NEW to ALLOCATED
2014-03-31 20:12:13,065 INFO org.apache.hadoop.yarn.server.resourcemanager.RMAuditLogger: USER=hduser	OPERATION=AM Allocated Container	TARGET=SchedulerApp	RESULT=SUCCESS	APPID=application_1396321465238_0002	CONTAINERID=container_1396321465238_0002_01_000002
2014-03-31 20:12:13,065 INFO org.apache.hadoop.yarn.server.resourcemanager.scheduler.common.fica.FiCaSchedulerNode: Assigned container container_1396321465238_0002_01_000002 of capacity <memory:1024, vCores:1> on host ubuntu:60709, which currently has 2 containers, <memory:3072, vCores:2> used and <memory:5120, vCores:6> available
2014-03-31 20:12:13,065 INFO org.apache.hadoop.yarn.server.resourcemanager.scheduler.capacity.LeafQueue: assignedContainer application=application_1396321465238_0002 container=Container: [ContainerId: container_1396321465238_0002_01_000002, NodeId: ubuntu:60709, NodeHttpAddress: ubuntu:8042, Resource: <memory:1024, vCores:1>, Priority: 20, Token: Token { kind: ContainerToken, service: 127.0.1.1:60709 }, ] containerId=container_1396321465238_0002_01_000002 queue=default: capacity=1.0, absoluteCapacity=1.0, usedResources=<memory:2048, vCores:1>usedCapacity=0.25, absoluteUsedCapacity=0.25, numApps=1, numContainers=1 usedCapacity=0.25 absoluteUsedCapacity=0.25 used=<memory:2048, vCores:1> cluster=<memory:8192, vCores:8>
2014-03-31 20:12:13,065 INFO org.apache.hadoop.yarn.server.resourcemanager.scheduler.capacity.ParentQueue: Re-sorting assigned queue: root.default stats: default: capacity=1.0, absoluteCapacity=1.0, usedResources=<memory:3072, vCores:2>usedCapacity=0.375, absoluteUsedCapacity=0.375, numApps=1, numContainers=2
2014-03-31 20:12:13,065 INFO org.apache.hadoop.yarn.server.resourcemanager.scheduler.capacity.ParentQueue: assignedContainer queue=root usedCapacity=0.375 absoluteUsedCapacity=0.375 used=<memory:3072, vCores:2> cluster=<memory:8192, vCores:8>
2014-03-31 20:12:13,066 INFO org.apache.hadoop.yarn.server.resourcemanager.rmcontainer.RMContainerImpl: container_1396321465238_0002_01_000003 Container Transitioned from NEW to ALLOCATED
2014-03-31 20:12:13,066 INFO org.apache.hadoop.yarn.server.resourcemanager.RMAuditLogger: USER=hduser	OPERATION=AM Allocated Container	TARGET=SchedulerApp	RESULT=SUCCESS	APPID=application_1396321465238_0002	CONTAINERID=container_1396321465238_0002_01_000003
2014-03-31 20:12:13,066 INFO org.apache.hadoop.yarn.server.resourcemanager.scheduler.common.fica.FiCaSchedulerNode: Assigned container container_1396321465238_0002_01_000003 of capacity <memory:1024, vCores:1> on host ubuntu:60709, which currently has 3 containers, <memory:4096, vCores:3> used and <memory:4096, vCores:5> available
2014-03-31 20:12:13,066 INFO org.apache.hadoop.yarn.server.resourcemanager.scheduler.capacity.LeafQueue: assignedContainer application=application_1396321465238_0002 container=Container: [ContainerId: container_1396321465238_0002_01_000003, NodeId: ubuntu:60709, NodeHttpAddress: ubuntu:8042, Resource: <memory:1024, vCores:1>, Priority: 20, Token: Token { kind: ContainerToken, service: 127.0.1.1:60709 }, ] containerId=container_1396321465238_0002_01_000003 queue=default: capacity=1.0, absoluteCapacity=1.0, usedResources=<memory:3072, vCores:2>usedCapacity=0.375, absoluteUsedCapacity=0.375, numApps=1, numContainers=2 usedCapacity=0.375 absoluteUsedCapacity=0.375 used=<memory:3072, vCores:2> cluster=<memory:8192, vCores:8>
2014-03-31 20:12:13,066 INFO org.apache.hadoop.yarn.server.resourcemanager.scheduler.capacity.ParentQueue: Re-sorting assigned queue: root.default stats: default: capacity=1.0, absoluteCapacity=1.0, usedResources=<memory:4096, vCores:3>usedCapacity=0.5, absoluteUsedCapacity=0.5, numApps=1, numContainers=3
2014-03-31 20:12:13,066 INFO org.apache.hadoop.yarn.server.resourcemanager.scheduler.capacity.ParentQueue: assignedContainer queue=root usedCapacity=0.5 absoluteUsedCapacity=0.5 used=<memory:4096, vCores:3> cluster=<memory:8192, vCores:8>
2014-03-31 20:12:13,901 INFO org.apache.hadoop.yarn.server.resourcemanager.rmcontainer.RMContainerImpl: container_1396321465238_0002_01_000002 Container Transitioned from ALLOCATED to ACQUIRED
2014-03-31 20:12:13,901 INFO org.apache.hadoop.yarn.server.resourcemanager.rmcontainer.RMContainerImpl: container_1396321465238_0002_01_000003 Container Transitioned from ALLOCATED to ACQUIRED
2014-03-31 20:12:14,066 INFO org.apache.hadoop.yarn.server.resourcemanager.rmcontainer.RMContainerImpl: container_1396321465238_0002_01_000002 Container Transitioned from ACQUIRED to RUNNING
2014-03-31 20:12:14,066 INFO org.apache.hadoop.yarn.server.resourcemanager.rmcontainer.RMContainerImpl: container_1396321465238_0002_01_000003 Container Transitioned from ACQUIRED to RUNNING
2014-03-31 20:12:14,926 INFO org.apache.hadoop.yarn.server.resourcemanager.scheduler.AppSchedulingInfo: checking for deactivate... 
2014-03-31 20:12:17,510 INFO org.apache.hadoop.yarn.server.resourcemanager.rmcontainer.RMContainerImpl: container_1396321465238_0002_01_000003 Container Transitioned from RUNNING to COMPLETED
2014-03-31 20:12:17,510 INFO org.apache.hadoop.yarn.server.resourcemanager.scheduler.common.fica.FiCaSchedulerApp: Completed container: container_1396321465238_0002_01_000003 in state: COMPLETED event:FINISHED
2014-03-31 20:12:17,510 INFO org.apache.hadoop.yarn.server.resourcemanager.RMAuditLogger: USER=hduser	OPERATION=AM Released Container	TARGET=SchedulerApp	RESULT=SUCCESS	APPID=application_1396321465238_0002	CONTAINERID=container_1396321465238_0002_01_000003
2014-03-31 20:12:17,510 INFO org.apache.hadoop.yarn.server.resourcemanager.scheduler.common.fica.FiCaSchedulerNode: Released container container_1396321465238_0002_01_000003 of capacity <memory:1024, vCores:1> on host ubuntu:60709, which currently has 2 containers, <memory:3072, vCores:2> used and <memory:5120, vCores:6> available, release resources=true
2014-03-31 20:12:17,510 INFO org.apache.hadoop.yarn.server.resourcemanager.scheduler.capacity.LeafQueue: default used=<memory:3072, vCores:2> numContainers=2 user=hduser user-resources=<memory:3072, vCores:2>
2014-03-31 20:12:17,510 INFO org.apache.hadoop.yarn.server.resourcemanager.scheduler.capacity.LeafQueue: completedContainer container=Container: [ContainerId: container_1396321465238_0002_01_000003, NodeId: ubuntu:60709, NodeHttpAddress: ubuntu:8042, Resource: <memory:1024, vCores:1>, Priority: 20, Token: Token { kind: ContainerToken, service: 127.0.1.1:60709 }, ] resource=<memory:1024, vCores:1> queue=default: capacity=1.0, absoluteCapacity=1.0, usedResources=<memory:3072, vCores:2>usedCapacity=0.375, absoluteUsedCapacity=0.375, numApps=1, numContainers=2 usedCapacity=0.375 absoluteUsedCapacity=0.375 used=<memory:3072, vCores:2> cluster=<memory:8192, vCores:8>
2014-03-31 20:12:17,510 INFO org.apache.hadoop.yarn.server.resourcemanager.scheduler.capacity.ParentQueue: completedContainer queue=root usedCapacity=0.375 absoluteUsedCapacity=0.375 used=<memory:3072, vCores:2> cluster=<memory:8192, vCores:8>
2014-03-31 20:12:17,510 INFO org.apache.hadoop.yarn.server.resourcemanager.scheduler.capacity.ParentQueue: Re-sorting completed queue: root.default stats: default: capacity=1.0, absoluteCapacity=1.0, usedResources=<memory:3072, vCores:2>usedCapacity=0.375, absoluteUsedCapacity=0.375, numApps=1, numContainers=2
2014-03-31 20:12:17,510 INFO org.apache.hadoop.yarn.server.resourcemanager.scheduler.capacity.CapacityScheduler: Application appattempt_1396321465238_0002_000001 released container container_1396321465238_0002_01_000003 on node: host: ubuntu:60709 #containers=2 available=5120 used=3072 with event: FINISHED
2014-03-31 20:12:18,512 INFO org.apache.hadoop.yarn.server.resourcemanager.rmcontainer.RMContainerImpl: container_1396321465238_0002_01_000002 Container Transitioned from RUNNING to COMPLETED
2014-03-31 20:12:18,512 INFO org.apache.hadoop.yarn.server.resourcemanager.scheduler.common.fica.FiCaSchedulerApp: Completed container: container_1396321465238_0002_01_000002 in state: COMPLETED event:FINISHED
2014-03-31 20:12:18,512 INFO org.apache.hadoop.yarn.server.resourcemanager.RMAuditLogger: USER=hduser	OPERATION=AM Released Container	TARGET=SchedulerApp	RESULT=SUCCESS	APPID=application_1396321465238_0002	CONTAINERID=container_1396321465238_0002_01_000002
2014-03-31 20:12:18,512 INFO org.apache.hadoop.yarn.server.resourcemanager.scheduler.common.fica.FiCaSchedulerNode: Released container container_1396321465238_0002_01_000002 of capacity <memory:1024, vCores:1> on host ubuntu:60709, which currently has 1 containers, <memory:2048, vCores:1> used and <memory:6144, vCores:7> available, release resources=true
2014-03-31 20:12:18,512 INFO org.apache.hadoop.yarn.server.resourcemanager.scheduler.capacity.LeafQueue: default used=<memory:2048, vCores:1> numContainers=1 user=hduser user-resources=<memory:2048, vCores:1>
2014-03-31 20:12:18,512 INFO org.apache.hadoop.yarn.server.resourcemanager.scheduler.capacity.LeafQueue: completedContainer container=Container: [ContainerId: container_1396321465238_0002_01_000002, NodeId: ubuntu:60709, NodeHttpAddress: ubuntu:8042, Resource: <memory:1024, vCores:1>, Priority: 20, Token: Token { kind: ContainerToken, service: 127.0.1.1:60709 }, ] resource=<memory:1024, vCores:1> queue=default: capacity=1.0, absoluteCapacity=1.0, usedResources=<memory:2048, vCores:1>usedCapacity=0.25, absoluteUsedCapacity=0.25, numApps=1, numContainers=1 usedCapacity=0.25 absoluteUsedCapacity=0.25 used=<memory:2048, vCores:1> cluster=<memory:8192, vCores:8>
2014-03-31 20:12:18,512 INFO org.apache.hadoop.yarn.server.resourcemanager.scheduler.capacity.ParentQueue: completedContainer queue=root usedCapacity=0.25 absoluteUsedCapacity=0.25 used=<memory:2048, vCores:1> cluster=<memory:8192, vCores:8>
2014-03-31 20:12:18,512 INFO org.apache.hadoop.yarn.server.resourcemanager.scheduler.capacity.ParentQueue: Re-sorting completed queue: root.default stats: default: capacity=1.0, absoluteCapacity=1.0, usedResources=<memory:2048, vCores:1>usedCapacity=0.25, absoluteUsedCapacity=0.25, numApps=1, numContainers=1
2014-03-31 20:12:18,512 INFO org.apache.hadoop.yarn.server.resourcemanager.scheduler.capacity.CapacityScheduler: Application appattempt_1396321465238_0002_000001 released container container_1396321465238_0002_01_000002 on node: host: ubuntu:60709 #containers=1 available=6144 used=2048 with event: FINISHED
2014-03-31 20:12:19,515 INFO org.apache.hadoop.yarn.server.resourcemanager.rmcontainer.RMContainerImpl: container_1396321465238_0002_01_000004 Container Transitioned from NEW to ALLOCATED
2014-03-31 20:12:19,515 INFO org.apache.hadoop.yarn.server.resourcemanager.RMAuditLogger: USER=hduser	OPERATION=AM Allocated Container	TARGET=SchedulerApp	RESULT=SUCCESS	APPID=application_1396321465238_0002	CONTAINERID=container_1396321465238_0002_01_000004
2014-03-31 20:12:19,515 INFO org.apache.hadoop.yarn.server.resourcemanager.scheduler.common.fica.FiCaSchedulerNode: Assigned container container_1396321465238_0002_01_000004 of capacity <memory:1024, vCores:1> on host ubuntu:60709, which currently has 2 containers, <memory:3072, vCores:2> used and <memory:5120, vCores:6> available
2014-03-31 20:12:19,515 INFO org.apache.hadoop.yarn.server.resourcemanager.scheduler.capacity.LeafQueue: assignedContainer application=application_1396321465238_0002 container=Container: [ContainerId: container_1396321465238_0002_01_000004, NodeId: ubuntu:60709, NodeHttpAddress: ubuntu:8042, Resource: <memory:1024, vCores:1>, Priority: 10, Token: Token { kind: ContainerToken, service: 127.0.1.1:60709 }, ] containerId=container_1396321465238_0002_01_000004 queue=default: capacity=1.0, absoluteCapacity=1.0, usedResources=<memory:2048, vCores:1>usedCapacity=0.25, absoluteUsedCapacity=0.25, numApps=1, numContainers=1 usedCapacity=0.25 absoluteUsedCapacity=0.25 used=<memory:2048, vCores:1> cluster=<memory:8192, vCores:8>
2014-03-31 20:12:19,516 INFO org.apache.hadoop.yarn.server.resourcemanager.scheduler.capacity.ParentQueue: Re-sorting assigned queue: root.default stats: default: capacity=1.0, absoluteCapacity=1.0, usedResources=<memory:3072, vCores:2>usedCapacity=0.375, absoluteUsedCapacity=0.375, numApps=1, numContainers=2
2014-03-31 20:12:19,516 INFO org.apache.hadoop.yarn.server.resourcemanager.scheduler.capacity.ParentQueue: assignedContainer queue=root usedCapacity=0.375 absoluteUsedCapacity=0.375 used=<memory:3072, vCores:2> cluster=<memory:8192, vCores:8>
2014-03-31 20:12:19,947 INFO org.apache.hadoop.yarn.server.resourcemanager.rmcontainer.RMContainerImpl: container_1396321465238_0002_01_000004 Container Transitioned from ALLOCATED to ACQUIRED
2014-03-31 20:12:20,518 INFO org.apache.hadoop.yarn.server.resourcemanager.rmcontainer.RMContainerImpl: container_1396321465238_0002_01_000004 Container Transitioned from ACQUIRED to RUNNING
2014-03-31 20:12:20,518 INFO org.apache.hadoop.yarn.server.resourcemanager.rmcontainer.RMContainerImpl: container_1396321465238_0002_01_000005 Container Transitioned from NEW to ALLOCATED
2014-03-31 20:12:20,518 INFO org.apache.hadoop.yarn.server.resourcemanager.RMAuditLogger: USER=hduser	OPERATION=AM Allocated Container	TARGET=SchedulerApp	RESULT=SUCCESS	APPID=application_1396321465238_0002	CONTAINERID=container_1396321465238_0002_01_000005
2014-03-31 20:12:20,518 INFO org.apache.hadoop.yarn.server.resourcemanager.scheduler.common.fica.FiCaSchedulerNode: Assigned container container_1396321465238_0002_01_000005 of capacity <memory:1024, vCores:1> on host ubuntu:60709, which currently has 3 containers, <memory:4096, vCores:3> used and <memory:4096, vCores:5> available
2014-03-31 20:12:20,518 INFO org.apache.hadoop.yarn.server.resourcemanager.scheduler.capacity.LeafQueue: assignedContainer application=application_1396321465238_0002 container=Container: [ContainerId: container_1396321465238_0002_01_000005, NodeId: ubuntu:60709, NodeHttpAddress: ubuntu:8042, Resource: <memory:1024, vCores:1>, Priority: 10, Token: Token { kind: ContainerToken, service: 127.0.1.1:60709 }, ] containerId=container_1396321465238_0002_01_000005 queue=default: capacity=1.0, absoluteCapacity=1.0, usedResources=<memory:3072, vCores:2>usedCapacity=0.375, absoluteUsedCapacity=0.375, numApps=1, numContainers=2 usedCapacity=0.375 absoluteUsedCapacity=0.375 used=<memory:3072, vCores:2> cluster=<memory:8192, vCores:8>
2014-03-31 20:12:20,518 INFO org.apache.hadoop.yarn.server.resourcemanager.scheduler.capacity.ParentQueue: Re-sorting assigned queue: root.default stats: default: capacity=1.0, absoluteCapacity=1.0, usedResources=<memory:4096, vCores:3>usedCapacity=0.5, absoluteUsedCapacity=0.5, numApps=1, numContainers=3
2014-03-31 20:12:20,518 INFO org.apache.hadoop.yarn.server.resourcemanager.scheduler.capacity.ParentQueue: assignedContainer queue=root usedCapacity=0.5 absoluteUsedCapacity=0.5 used=<memory:4096, vCores:3> cluster=<memory:8192, vCores:8>
2014-03-31 20:12:20,952 INFO org.apache.hadoop.yarn.server.resourcemanager.rmcontainer.RMContainerImpl: container_1396321465238_0002_01_000005 Container Transitioned from ALLOCATED to ACQUIRED
2014-03-31 20:12:21,520 INFO org.apache.hadoop.yarn.server.resourcemanager.rmcontainer.RMContainerImpl: container_1396321465238_0002_01_000005 Container Transitioned from ACQUIRED to RUNNING
2014-03-31 20:12:21,521 INFO org.apache.hadoop.yarn.server.resourcemanager.rmcontainer.RMContainerImpl: container_1396321465238_0002_01_000006 Container Transitioned from NEW to ALLOCATED
2014-03-31 20:12:21,521 INFO org.apache.hadoop.yarn.server.resourcemanager.RMAuditLogger: USER=hduser	OPERATION=AM Allocated Container	TARGET=SchedulerApp	RESULT=SUCCESS	APPID=application_1396321465238_0002	CONTAINERID=container_1396321465238_0002_01_000006
2014-03-31 20:12:21,521 INFO org.apache.hadoop.yarn.server.resourcemanager.scheduler.common.fica.FiCaSchedulerNode: Assigned container container_1396321465238_0002_01_000006 of capacity <memory:1024, vCores:1> on host ubuntu:60709, which currently has 4 containers, <memory:5120, vCores:4> used and <memory:3072, vCores:4> available
2014-03-31 20:12:21,521 INFO org.apache.hadoop.yarn.server.resourcemanager.scheduler.capacity.LeafQueue: assignedContainer application=application_1396321465238_0002 container=Container: [ContainerId: container_1396321465238_0002_01_000006, NodeId: ubuntu:60709, NodeHttpAddress: ubuntu:8042, Resource: <memory:1024, vCores:1>, Priority: 10, Token: Token { kind: ContainerToken, service: 127.0.1.1:60709 }, ] containerId=container_1396321465238_0002_01_000006 queue=default: capacity=1.0, absoluteCapacity=1.0, usedResources=<memory:4096, vCores:3>usedCapacity=0.5, absoluteUsedCapacity=0.5, numApps=1, numContainers=3 usedCapacity=0.5 absoluteUsedCapacity=0.5 used=<memory:4096, vCores:3> cluster=<memory:8192, vCores:8>
2014-03-31 20:12:21,521 INFO org.apache.hadoop.yarn.server.resourcemanager.scheduler.capacity.ParentQueue: Re-sorting assigned queue: root.default stats: default: capacity=1.0, absoluteCapacity=1.0, usedResources=<memory:5120, vCores:4>usedCapacity=0.625, absoluteUsedCapacity=0.625, numApps=1, numContainers=4
2014-03-31 20:12:21,521 INFO org.apache.hadoop.yarn.server.resourcemanager.scheduler.capacity.ParentQueue: assignedContainer queue=root usedCapacity=0.625 absoluteUsedCapacity=0.625 used=<memory:5120, vCores:4> cluster=<memory:8192, vCores:8>
2014-03-31 20:12:21,956 INFO org.apache.hadoop.yarn.server.resourcemanager.rmcontainer.RMContainerImpl: container_1396321465238_0002_01_000006 Container Transitioned from ALLOCATED to ACQUIRED
2014-03-31 20:12:22,523 INFO org.apache.hadoop.yarn.server.resourcemanager.rmcontainer.RMContainerImpl: container_1396321465238_0002_01_000006 Container Transitioned from ACQUIRED to RUNNING
2014-03-31 20:12:22,524 INFO org.apache.hadoop.yarn.server.resourcemanager.rmcontainer.RMContainerImpl: container_1396321465238_0002_01_000007 Container Transitioned from NEW to ALLOCATED
2014-03-31 20:12:22,524 INFO org.apache.hadoop.yarn.server.resourcemanager.RMAuditLogger: USER=hduser	OPERATION=AM Allocated Container	TARGET=SchedulerApp	RESULT=SUCCESS	APPID=application_1396321465238_0002	CONTAINERID=container_1396321465238_0002_01_000007
2014-03-31 20:12:22,524 INFO org.apache.hadoop.yarn.server.resourcemanager.scheduler.common.fica.FiCaSchedulerNode: Assigned container container_1396321465238_0002_01_000007 of capacity <memory:1024, vCores:1> on host ubuntu:60709, which currently has 5 containers, <memory:6144, vCores:5> used and <memory:2048, vCores:3> available
2014-03-31 20:12:22,524 INFO org.apache.hadoop.yarn.server.resourcemanager.scheduler.capacity.LeafQueue: assignedContainer application=application_1396321465238_0002 container=Container: [ContainerId: container_1396321465238_0002_01_000007, NodeId: ubuntu:60709, NodeHttpAddress: ubuntu:8042, Resource: <memory:1024, vCores:1>, Priority: 10, Token: Token { kind: ContainerToken, service: 127.0.1.1:60709 }, ] containerId=container_1396321465238_0002_01_000007 queue=default: capacity=1.0, absoluteCapacity=1.0, usedResources=<memory:5120, vCores:4>usedCapacity=0.625, absoluteUsedCapacity=0.625, numApps=1, numContainers=4 usedCapacity=0.625 absoluteUsedCapacity=0.625 used=<memory:5120, vCores:4> cluster=<memory:8192, vCores:8>
2014-03-31 20:12:22,524 INFO org.apache.hadoop.yarn.server.resourcemanager.scheduler.capacity.ParentQueue: Re-sorting assigned queue: root.default stats: default: capacity=1.0, absoluteCapacity=1.0, usedResources=<memory:6144, vCores:5>usedCapacity=0.75, absoluteUsedCapacity=0.75, numApps=1, numContainers=5
2014-03-31 20:12:22,524 INFO org.apache.hadoop.yarn.server.resourcemanager.scheduler.capacity.ParentQueue: assignedContainer queue=root usedCapacity=0.75 absoluteUsedCapacity=0.75 used=<memory:6144, vCores:5> cluster=<memory:8192, vCores:8>
2014-03-31 20:12:22,961 INFO org.apache.hadoop.yarn.server.resourcemanager.rmcontainer.RMContainerImpl: container_1396321465238_0002_01_000007 Container Transitioned from ALLOCATED to ACQUIRED
2014-03-31 20:12:23,263 INFO org.apache.hadoop.yarn.server.resourcemanager.rmcontainer.RMContainerImpl: container_1396321465238_0002_01_000007 Container Transitioned from ACQUIRED to RUNNING
2014-03-31 20:12:23,263 INFO org.apache.hadoop.yarn.server.resourcemanager.rmcontainer.RMContainerImpl: container_1396321465238_0002_01_000008 Container Transitioned from NEW to ALLOCATED
2014-03-31 20:12:23,263 INFO org.apache.hadoop.yarn.server.resourcemanager.RMAuditLogger: USER=hduser	OPERATION=AM Allocated Container	TARGET=SchedulerApp	RESULT=SUCCESS	APPID=application_1396321465238_0002	CONTAINERID=container_1396321465238_0002_01_000008
2014-03-31 20:12:23,263 INFO org.apache.hadoop.yarn.server.resourcemanager.scheduler.common.fica.FiCaSchedulerNode: Assigned container container_1396321465238_0002_01_000008 of capacity <memory:1024, vCores:1> on host ubuntu:60709, which currently has 6 containers, <memory:7168, vCores:6> used and <memory:1024, vCores:2> available
2014-03-31 20:12:23,263 INFO org.apache.hadoop.yarn.server.resourcemanager.scheduler.capacity.LeafQueue: assignedContainer application=application_1396321465238_0002 container=Container: [ContainerId: container_1396321465238_0002_01_000008, NodeId: ubuntu:60709, NodeHttpAddress: ubuntu:8042, Resource: <memory:1024, vCores:1>, Priority: 10, Token: Token { kind: ContainerToken, service: 127.0.1.1:60709 }, ] containerId=container_1396321465238_0002_01_000008 queue=default: capacity=1.0, absoluteCapacity=1.0, usedResources=<memory:6144, vCores:5>usedCapacity=0.75, absoluteUsedCapacity=0.75, numApps=1, numContainers=5 usedCapacity=0.75 absoluteUsedCapacity=0.75 used=<memory:6144, vCores:5> cluster=<memory:8192, vCores:8>
2014-03-31 20:12:23,263 INFO org.apache.hadoop.yarn.server.resourcemanager.scheduler.capacity.ParentQueue: Re-sorting assigned queue: root.default stats: default: capacity=1.0, absoluteCapacity=1.0, usedResources=<memory:7168, vCores:6>usedCapacity=0.875, absoluteUsedCapacity=0.875, numApps=1, numContainers=6
2014-03-31 20:12:23,263 INFO org.apache.hadoop.yarn.server.resourcemanager.scheduler.capacity.ParentQueue: assignedContainer queue=root usedCapacity=0.875 absoluteUsedCapacity=0.875 used=<memory:7168, vCores:6> cluster=<memory:8192, vCores:8>
2014-03-31 20:12:23,965 INFO org.apache.hadoop.yarn.server.resourcemanager.rmcontainer.RMContainerImpl: container_1396321465238_0002_01_000008 Container Transitioned from ALLOCATED to ACQUIRED
2014-03-31 20:12:24,203 INFO org.apache.hadoop.yarn.server.resourcemanager.rmcontainer.RMContainerImpl: container_1396321465238_0002_01_000008 Container Transitioned from ACQUIRED to RUNNING
2014-03-31 20:12:24,203 INFO org.apache.hadoop.yarn.server.resourcemanager.rmcontainer.RMContainerImpl: container_1396321465238_0002_01_000004 Container Transitioned from RUNNING to COMPLETED
2014-03-31 20:12:24,203 INFO org.apache.hadoop.yarn.server.resourcemanager.scheduler.common.fica.FiCaSchedulerApp: Completed container: container_1396321465238_0002_01_000004 in state: COMPLETED event:FINISHED
2014-03-31 20:12:24,203 INFO org.apache.hadoop.yarn.server.resourcemanager.RMAuditLogger: USER=hduser	OPERATION=AM Released Container	TARGET=SchedulerApp	RESULT=SUCCESS	APPID=application_1396321465238_0002	CONTAINERID=container_1396321465238_0002_01_000004
2014-03-31 20:12:24,203 INFO org.apache.hadoop.yarn.server.resourcemanager.scheduler.common.fica.FiCaSchedulerNode: Released container container_1396321465238_0002_01_000004 of capacity <memory:1024, vCores:1> on host ubuntu:60709, which currently has 5 containers, <memory:6144, vCores:5> used and <memory:2048, vCores:3> available, release resources=true
2014-03-31 20:12:24,203 INFO org.apache.hadoop.yarn.server.resourcemanager.scheduler.capacity.LeafQueue: default used=<memory:6144, vCores:5> numContainers=5 user=hduser user-resources=<memory:6144, vCores:5>
2014-03-31 20:12:24,204 INFO org.apache.hadoop.yarn.server.resourcemanager.scheduler.capacity.LeafQueue: completedContainer container=Container: [ContainerId: container_1396321465238_0002_01_000004, NodeId: ubuntu:60709, NodeHttpAddress: ubuntu:8042, Resource: <memory:1024, vCores:1>, Priority: 10, Token: Token { kind: ContainerToken, service: 127.0.1.1:60709 }, ] resource=<memory:1024, vCores:1> queue=default: capacity=1.0, absoluteCapacity=1.0, usedResources=<memory:6144, vCores:5>usedCapacity=0.75, absoluteUsedCapacity=0.75, numApps=1, numContainers=5 usedCapacity=0.75 absoluteUsedCapacity=0.75 used=<memory:6144, vCores:5> cluster=<memory:8192, vCores:8>
2014-03-31 20:12:24,204 INFO org.apache.hadoop.yarn.server.resourcemanager.scheduler.capacity.ParentQueue: completedContainer queue=root usedCapacity=0.75 absoluteUsedCapacity=0.75 used=<memory:6144, vCores:5> cluster=<memory:8192, vCores:8>
2014-03-31 20:12:24,204 INFO org.apache.hadoop.yarn.server.resourcemanager.scheduler.capacity.ParentQueue: Re-sorting completed queue: root.default stats: default: capacity=1.0, absoluteCapacity=1.0, usedResources=<memory:6144, vCores:5>usedCapacity=0.75, absoluteUsedCapacity=0.75, numApps=1, numContainers=5
2014-03-31 20:12:24,204 INFO org.apache.hadoop.yarn.server.resourcemanager.scheduler.capacity.CapacityScheduler: Application appattempt_1396321465238_0002_000001 released container container_1396321465238_0002_01_000004 on node: host: ubuntu:60709 #containers=5 available=2048 used=6144 with event: FINISHED
2014-03-31 20:12:24,204 INFO org.apache.hadoop.yarn.server.resourcemanager.rmcontainer.RMContainerImpl: container_1396321465238_0002_01_000009 Container Transitioned from NEW to ALLOCATED
2014-03-31 20:12:24,204 INFO org.apache.hadoop.yarn.server.resourcemanager.RMAuditLogger: USER=hduser	OPERATION=AM Allocated Container	TARGET=SchedulerApp	RESULT=SUCCESS	APPID=application_1396321465238_0002	CONTAINERID=container_1396321465238_0002_01_000009
2014-03-31 20:12:24,204 INFO org.apache.hadoop.yarn.server.resourcemanager.scheduler.common.fica.FiCaSchedulerNode: Assigned container container_1396321465238_0002_01_000009 of capacity <memory:1024, vCores:1> on host ubuntu:60709, which currently has 6 containers, <memory:7168, vCores:6> used and <memory:1024, vCores:2> available
2014-03-31 20:12:24,204 INFO org.apache.hadoop.yarn.server.resourcemanager.scheduler.capacity.LeafQueue: assignedContainer application=application_1396321465238_0002 container=Container: [ContainerId: container_1396321465238_0002_01_000009, NodeId: ubuntu:60709, NodeHttpAddress: ubuntu:8042, Resource: <memory:1024, vCores:1>, Priority: 10, Token: Token { kind: ContainerToken, service: 127.0.1.1:60709 }, ] containerId=container_1396321465238_0002_01_000009 queue=default: capacity=1.0, absoluteCapacity=1.0, usedResources=<memory:6144, vCores:5>usedCapacity=0.75, absoluteUsedCapacity=0.75, numApps=1, numContainers=5 usedCapacity=0.75 absoluteUsedCapacity=0.75 used=<memory:6144, vCores:5> cluster=<memory:8192, vCores:8>
2014-03-31 20:12:24,204 INFO org.apache.hadoop.yarn.server.resourcemanager.scheduler.capacity.ParentQueue: Re-sorting assigned queue: root.default stats: default: capacity=1.0, absoluteCapacity=1.0, usedResources=<memory:7168, vCores:6>usedCapacity=0.875, absoluteUsedCapacity=0.875, numApps=1, numContainers=6
2014-03-31 20:12:24,204 INFO org.apache.hadoop.yarn.server.resourcemanager.scheduler.capacity.ParentQueue: assignedContainer queue=root usedCapacity=0.875 absoluteUsedCapacity=0.875 used=<memory:7168, vCores:6> cluster=<memory:8192, vCores:8>
2014-03-31 20:12:24,969 INFO org.apache.hadoop.yarn.server.resourcemanager.rmcontainer.RMContainerImpl: container_1396321465238_0002_01_000009 Container Transitioned from ALLOCATED to ACQUIRED
2014-03-31 20:12:25,206 INFO org.apache.hadoop.yarn.server.resourcemanager.rmcontainer.RMContainerImpl: container_1396321465238_0002_01_000009 Container Transitioned from ACQUIRED to RUNNING
2014-03-31 20:12:25,206 INFO org.apache.hadoop.yarn.server.resourcemanager.rmcontainer.RMContainerImpl: container_1396321465238_0002_01_000005 Container Transitioned from RUNNING to COMPLETED
2014-03-31 20:12:25,206 INFO org.apache.hadoop.yarn.server.resourcemanager.scheduler.common.fica.FiCaSchedulerApp: Completed container: container_1396321465238_0002_01_000005 in state: COMPLETED event:FINISHED
2014-03-31 20:12:25,206 INFO org.apache.hadoop.yarn.server.resourcemanager.RMAuditLogger: USER=hduser	OPERATION=AM Released Container	TARGET=SchedulerApp	RESULT=SUCCESS	APPID=application_1396321465238_0002	CONTAINERID=container_1396321465238_0002_01_000005
2014-03-31 20:12:25,206 INFO org.apache.hadoop.yarn.server.resourcemanager.scheduler.common.fica.FiCaSchedulerNode: Released container container_1396321465238_0002_01_000005 of capacity <memory:1024, vCores:1> on host ubuntu:60709, which currently has 5 containers, <memory:6144, vCores:5> used and <memory:2048, vCores:3> available, release resources=true
2014-03-31 20:12:25,206 INFO org.apache.hadoop.yarn.server.resourcemanager.scheduler.capacity.LeafQueue: default used=<memory:6144, vCores:5> numContainers=5 user=hduser user-resources=<memory:6144, vCores:5>
2014-03-31 20:12:25,206 INFO org.apache.hadoop.yarn.server.resourcemanager.scheduler.capacity.LeafQueue: completedContainer container=Container: [ContainerId: container_1396321465238_0002_01_000005, NodeId: ubuntu:60709, NodeHttpAddress: ubuntu:8042, Resource: <memory:1024, vCores:1>, Priority: 10, Token: Token { kind: ContainerToken, service: 127.0.1.1:60709 }, ] resource=<memory:1024, vCores:1> queue=default: capacity=1.0, absoluteCapacity=1.0, usedResources=<memory:6144, vCores:5>usedCapacity=0.75, absoluteUsedCapacity=0.75, numApps=1, numContainers=5 usedCapacity=0.75 absoluteUsedCapacity=0.75 used=<memory:6144, vCores:5> cluster=<memory:8192, vCores:8>
2014-03-31 20:12:25,206 INFO org.apache.hadoop.yarn.server.resourcemanager.scheduler.capacity.ParentQueue: completedContainer queue=root usedCapacity=0.75 absoluteUsedCapacity=0.75 used=<memory:6144, vCores:5> cluster=<memory:8192, vCores:8>
2014-03-31 20:12:25,207 INFO org.apache.hadoop.yarn.server.resourcemanager.scheduler.capacity.ParentQueue: Re-sorting completed queue: root.default stats: default: capacity=1.0, absoluteCapacity=1.0, usedResources=<memory:6144, vCores:5>usedCapacity=0.75, absoluteUsedCapacity=0.75, numApps=1, numContainers=5
2014-03-31 20:12:25,207 INFO org.apache.hadoop.yarn.server.resourcemanager.scheduler.capacity.CapacityScheduler: Application appattempt_1396321465238_0002_000001 released container container_1396321465238_0002_01_000005 on node: host: ubuntu:60709 #containers=5 available=2048 used=6144 with event: FINISHED
2014-03-31 20:12:25,207 INFO org.apache.hadoop.yarn.server.resourcemanager.rmcontainer.RMContainerImpl: container_1396321465238_0002_01_000010 Container Transitioned from NEW to ALLOCATED
2014-03-31 20:12:25,207 INFO org.apache.hadoop.yarn.server.resourcemanager.RMAuditLogger: USER=hduser	OPERATION=AM Allocated Container	TARGET=SchedulerApp	RESULT=SUCCESS	APPID=application_1396321465238_0002	CONTAINERID=container_1396321465238_0002_01_000010
2014-03-31 20:12:25,207 INFO org.apache.hadoop.yarn.server.resourcemanager.scheduler.common.fica.FiCaSchedulerNode: Assigned container container_1396321465238_0002_01_000010 of capacity <memory:1024, vCores:1> on host ubuntu:60709, which currently has 6 containers, <memory:7168, vCores:6> used and <memory:1024, vCores:2> available
2014-03-31 20:12:25,207 INFO org.apache.hadoop.yarn.server.resourcemanager.scheduler.capacity.LeafQueue: assignedContainer application=application_1396321465238_0002 container=Container: [ContainerId: container_1396321465238_0002_01_000010, NodeId: ubuntu:60709, NodeHttpAddress: ubuntu:8042, Resource: <memory:1024, vCores:1>, Priority: 10, Token: Token { kind: ContainerToken, service: 127.0.1.1:60709 }, ] containerId=container_1396321465238_0002_01_000010 queue=default: capacity=1.0, absoluteCapacity=1.0, usedResources=<memory:6144, vCores:5>usedCapacity=0.75, absoluteUsedCapacity=0.75, numApps=1, numContainers=5 usedCapacity=0.75 absoluteUsedCapacity=0.75 used=<memory:6144, vCores:5> cluster=<memory:8192, vCores:8>
2014-03-31 20:12:25,207 INFO org.apache.hadoop.yarn.server.resourcemanager.scheduler.capacity.ParentQueue: Re-sorting assigned queue: root.default stats: default: capacity=1.0, absoluteCapacity=1.0, usedResources=<memory:7168, vCores:6>usedCapacity=0.875, absoluteUsedCapacity=0.875, numApps=1, numContainers=6
2014-03-31 20:12:25,207 INFO org.apache.hadoop.yarn.server.resourcemanager.scheduler.capacity.ParentQueue: assignedContainer queue=root usedCapacity=0.875 absoluteUsedCapacity=0.875 used=<memory:7168, vCores:6> cluster=<memory:8192, vCores:8>
2014-03-31 20:12:25,369 INFO org.apache.hadoop.yarn.server.resourcemanager.rmcontainer.RMContainerImpl: container_1396321465238_0002_01_000011 Container Transitioned from NEW to ALLOCATED
2014-03-31 20:12:25,370 INFO org.apache.hadoop.yarn.server.resourcemanager.RMAuditLogger: USER=hduser	OPERATION=AM Allocated Container	TARGET=SchedulerApp	RESULT=SUCCESS	APPID=application_1396321465238_0002	CONTAINERID=container_1396321465238_0002_01_000011
2014-03-31 20:12:25,370 INFO org.apache.hadoop.yarn.server.resourcemanager.scheduler.common.fica.FiCaSchedulerNode: Assigned container container_1396321465238_0002_01_000011 of capacity <memory:1024, vCores:1> on host ubuntu:60709, which currently has 7 containers, <memory:8192, vCores:7> used and <memory:0, vCores:1> available
2014-03-31 20:12:25,370 INFO org.apache.hadoop.yarn.server.resourcemanager.scheduler.capacity.LeafQueue: assignedContainer application=application_1396321465238_0002 container=Container: [ContainerId: container_1396321465238_0002_01_000011, NodeId: ubuntu:60709, NodeHttpAddress: ubuntu:8042, Resource: <memory:1024, vCores:1>, Priority: 10, Token: Token { kind: ContainerToken, service: 127.0.1.1:60709 }, ] containerId=container_1396321465238_0002_01_000011 queue=default: capacity=1.0, absoluteCapacity=1.0, usedResources=<memory:7168, vCores:6>usedCapacity=0.875, absoluteUsedCapacity=0.875, numApps=1, numContainers=6 usedCapacity=0.875 absoluteUsedCapacity=0.875 used=<memory:7168, vCores:6> cluster=<memory:8192, vCores:8>
2014-03-31 20:12:25,370 INFO org.apache.hadoop.yarn.server.resourcemanager.scheduler.capacity.ParentQueue: Re-sorting assigned queue: root.default stats: default: capacity=1.0, absoluteCapacity=1.0, usedResources=<memory:8192, vCores:7>usedCapacity=1.0, absoluteUsedCapacity=1.0, numApps=1, numContainers=7
2014-03-31 20:12:25,370 INFO org.apache.hadoop.yarn.server.resourcemanager.scheduler.capacity.ParentQueue: assignedContainer queue=root usedCapacity=1.0 absoluteUsedCapacity=1.0 used=<memory:8192, vCores:7> cluster=<memory:8192, vCores:8>
2014-03-31 20:12:25,986 INFO org.apache.hadoop.yarn.server.resourcemanager.rmcontainer.RMContainerImpl: container_1396321465238_0002_01_000010 Container Transitioned from ALLOCATED to ACQUIRED
2014-03-31 20:12:25,992 INFO org.apache.hadoop.yarn.server.resourcemanager.rmcontainer.RMContainerImpl: container_1396321465238_0002_01_000011 Container Transitioned from ALLOCATED to ACQUIRED
2014-03-31 20:12:26,372 INFO org.apache.hadoop.yarn.server.resourcemanager.rmcontainer.RMContainerImpl: container_1396321465238_0002_01_000010 Container Transitioned from ACQUIRED to RUNNING
2014-03-31 20:12:26,372 INFO org.apache.hadoop.yarn.server.resourcemanager.rmcontainer.RMContainerImpl: container_1396321465238_0002_01_000011 Container Transitioned from ACQUIRED to RUNNING
2014-03-31 20:12:26,372 INFO org.apache.hadoop.yarn.server.resourcemanager.rmcontainer.RMContainerImpl: container_1396321465238_0002_01_000006 Container Transitioned from RUNNING to COMPLETED
2014-03-31 20:12:26,373 INFO org.apache.hadoop.yarn.server.resourcemanager.scheduler.common.fica.FiCaSchedulerApp: Completed container: container_1396321465238_0002_01_000006 in state: COMPLETED event:FINISHED
2014-03-31 20:12:26,373 INFO org.apache.hadoop.yarn.server.resourcemanager.RMAuditLogger: USER=hduser	OPERATION=AM Released Container	TARGET=SchedulerApp	RESULT=SUCCESS	APPID=application_1396321465238_0002	CONTAINERID=container_1396321465238_0002_01_000006
2014-03-31 20:12:26,373 INFO org.apache.hadoop.yarn.server.resourcemanager.scheduler.common.fica.FiCaSchedulerNode: Released container container_1396321465238_0002_01_000006 of capacity <memory:1024, vCores:1> on host ubuntu:60709, which currently has 6 containers, <memory:7168, vCores:6> used and <memory:1024, vCores:2> available, release resources=true
2014-03-31 20:12:26,373 INFO org.apache.hadoop.yarn.server.resourcemanager.scheduler.capacity.LeafQueue: default used=<memory:7168, vCores:6> numContainers=6 user=hduser user-resources=<memory:7168, vCores:6>
2014-03-31 20:12:26,373 INFO org.apache.hadoop.yarn.server.resourcemanager.scheduler.capacity.LeafQueue: completedContainer container=Container: [ContainerId: container_1396321465238_0002_01_000006, NodeId: ubuntu:60709, NodeHttpAddress: ubuntu:8042, Resource: <memory:1024, vCores:1>, Priority: 10, Token: Token { kind: ContainerToken, service: 127.0.1.1:60709 }, ] resource=<memory:1024, vCores:1> queue=default: capacity=1.0, absoluteCapacity=1.0, usedResources=<memory:7168, vCores:6>usedCapacity=0.875, absoluteUsedCapacity=0.875, numApps=1, numContainers=6 usedCapacity=0.875 absoluteUsedCapacity=0.875 used=<memory:7168, vCores:6> cluster=<memory:8192, vCores:8>
2014-03-31 20:12:26,373 INFO org.apache.hadoop.yarn.server.resourcemanager.scheduler.capacity.ParentQueue: completedContainer queue=root usedCapacity=0.875 absoluteUsedCapacity=0.875 used=<memory:7168, vCores:6> cluster=<memory:8192, vCores:8>
2014-03-31 20:12:26,373 INFO org.apache.hadoop.yarn.server.resourcemanager.scheduler.capacity.ParentQueue: Re-sorting completed queue: root.default stats: default: capacity=1.0, absoluteCapacity=1.0, usedResources=<memory:7168, vCores:6>usedCapacity=0.875, absoluteUsedCapacity=0.875, numApps=1, numContainers=6
2014-03-31 20:12:26,373 INFO org.apache.hadoop.yarn.server.resourcemanager.scheduler.capacity.CapacityScheduler: Application appattempt_1396321465238_0002_000001 released container container_1396321465238_0002_01_000006 on node: host: ubuntu:60709 #containers=6 available=1024 used=7168 with event: FINISHED
2014-03-31 20:12:26,374 INFO org.apache.hadoop.yarn.server.resourcemanager.rmcontainer.RMContainerImpl: container_1396321465238_0002_01_000012 Container Transitioned from NEW to ALLOCATED
2014-03-31 20:12:26,374 INFO org.apache.hadoop.yarn.server.resourcemanager.RMAuditLogger: USER=hduser	OPERATION=AM Allocated Container	TARGET=SchedulerApp	RESULT=SUCCESS	APPID=application_1396321465238_0002	CONTAINERID=container_1396321465238_0002_01_000012
2014-03-31 20:12:26,374 INFO org.apache.hadoop.yarn.server.resourcemanager.scheduler.common.fica.FiCaSchedulerNode: Assigned container container_1396321465238_0002_01_000012 of capacity <memory:1024, vCores:1> on host ubuntu:60709, which currently has 7 containers, <memory:8192, vCores:7> used and <memory:0, vCores:1> available
2014-03-31 20:12:26,374 INFO org.apache.hadoop.yarn.server.resourcemanager.scheduler.capacity.LeafQueue: assignedContainer application=application_1396321465238_0002 container=Container: [ContainerId: container_1396321465238_0002_01_000012, NodeId: ubuntu:60709, NodeHttpAddress: ubuntu:8042, Resource: <memory:1024, vCores:1>, Priority: 10, Token: Token { kind: ContainerToken, service: 127.0.1.1:60709 }, ] containerId=container_1396321465238_0002_01_000012 queue=default: capacity=1.0, absoluteCapacity=1.0, usedResources=<memory:7168, vCores:6>usedCapacity=0.875, absoluteUsedCapacity=0.875, numApps=1, numContainers=6 usedCapacity=0.875 absoluteUsedCapacity=0.875 used=<memory:7168, vCores:6> cluster=<memory:8192, vCores:8>
2014-03-31 20:12:26,374 INFO org.apache.hadoop.yarn.server.resourcemanager.scheduler.capacity.ParentQueue: Re-sorting assigned queue: root.default stats: default: capacity=1.0, absoluteCapacity=1.0, usedResources=<memory:8192, vCores:7>usedCapacity=1.0, absoluteUsedCapacity=1.0, numApps=1, numContainers=7
2014-03-31 20:12:26,374 INFO org.apache.hadoop.yarn.server.resourcemanager.scheduler.capacity.ParentQueue: assignedContainer queue=root usedCapacity=1.0 absoluteUsedCapacity=1.0 used=<memory:8192, vCores:7> cluster=<memory:8192, vCores:8>
2014-03-31 20:12:27,004 INFO org.apache.hadoop.yarn.server.resourcemanager.rmcontainer.RMContainerImpl: container_1396321465238_0002_01_000012 Container Transitioned from ALLOCATED to ACQUIRED
2014-03-31 20:12:27,918 INFO org.apache.hadoop.yarn.server.resourcemanager.rmcontainer.RMContainerImpl: container_1396321465238_0002_01_000012 Container Transitioned from ACQUIRED to RUNNING
2014-03-31 20:12:27,918 INFO org.apache.hadoop.yarn.server.resourcemanager.rmcontainer.RMContainerImpl: container_1396321465238_0002_01_000007 Container Transitioned from RUNNING to COMPLETED
2014-03-31 20:12:27,918 INFO org.apache.hadoop.yarn.server.resourcemanager.scheduler.common.fica.FiCaSchedulerApp: Completed container: container_1396321465238_0002_01_000007 in state: COMPLETED event:FINISHED
2014-03-31 20:12:27,918 INFO org.apache.hadoop.yarn.server.resourcemanager.RMAuditLogger: USER=hduser	OPERATION=AM Released Container	TARGET=SchedulerApp	RESULT=SUCCESS	APPID=application_1396321465238_0002	CONTAINERID=container_1396321465238_0002_01_000007
2014-03-31 20:12:27,918 INFO org.apache.hadoop.yarn.server.resourcemanager.scheduler.common.fica.FiCaSchedulerNode: Released container container_1396321465238_0002_01_000007 of capacity <memory:1024, vCores:1> on host ubuntu:60709, which currently has 6 containers, <memory:7168, vCores:6> used and <memory:1024, vCores:2> available, release resources=true
2014-03-31 20:12:27,918 INFO org.apache.hadoop.yarn.server.resourcemanager.scheduler.capacity.LeafQueue: default used=<memory:7168, vCores:6> numContainers=6 user=hduser user-resources=<memory:7168, vCores:6>
2014-03-31 20:12:27,918 INFO org.apache.hadoop.yarn.server.resourcemanager.scheduler.capacity.LeafQueue: completedContainer container=Container: [ContainerId: container_1396321465238_0002_01_000007, NodeId: ubuntu:60709, NodeHttpAddress: ubuntu:8042, Resource: <memory:1024, vCores:1>, Priority: 10, Token: Token { kind: ContainerToken, service: 127.0.1.1:60709 }, ] resource=<memory:1024, vCores:1> queue=default: capacity=1.0, absoluteCapacity=1.0, usedResources=<memory:7168, vCores:6>usedCapacity=0.875, absoluteUsedCapacity=0.875, numApps=1, numContainers=6 usedCapacity=0.875 absoluteUsedCapacity=0.875 used=<memory:7168, vCores:6> cluster=<memory:8192, vCores:8>
2014-03-31 20:12:27,918 INFO org.apache.hadoop.yarn.server.resourcemanager.scheduler.capacity.ParentQueue: completedContainer queue=root usedCapacity=0.875 absoluteUsedCapacity=0.875 used=<memory:7168, vCores:6> cluster=<memory:8192, vCores:8>
2014-03-31 20:12:27,918 INFO org.apache.hadoop.yarn.server.resourcemanager.scheduler.capacity.ParentQueue: Re-sorting completed queue: root.default stats: default: capacity=1.0, absoluteCapacity=1.0, usedResources=<memory:7168, vCores:6>usedCapacity=0.875, absoluteUsedCapacity=0.875, numApps=1, numContainers=6
2014-03-31 20:12:27,918 INFO org.apache.hadoop.yarn.server.resourcemanager.scheduler.capacity.CapacityScheduler: Application appattempt_1396321465238_0002_000001 released container container_1396321465238_0002_01_000007 on node: host: ubuntu:60709 #containers=6 available=1024 used=7168 with event: FINISHED
2014-03-31 20:12:27,919 INFO org.apache.hadoop.yarn.server.resourcemanager.rmcontainer.RMContainerImpl: container_1396321465238_0002_01_000013 Container Transitioned from NEW to ALLOCATED
2014-03-31 20:12:27,919 INFO org.apache.hadoop.yarn.server.resourcemanager.RMAuditLogger: USER=hduser	OPERATION=AM Allocated Container	TARGET=SchedulerApp	RESULT=SUCCESS	APPID=application_1396321465238_0002	CONTAINERID=container_1396321465238_0002_01_000013
2014-03-31 20:12:27,919 INFO org.apache.hadoop.yarn.server.resourcemanager.scheduler.common.fica.FiCaSchedulerNode: Assigned container container_1396321465238_0002_01_000013 of capacity <memory:1024, vCores:1> on host ubuntu:60709, which currently has 7 containers, <memory:8192, vCores:7> used and <memory:0, vCores:1> available
2014-03-31 20:12:27,919 INFO org.apache.hadoop.yarn.server.resourcemanager.scheduler.capacity.LeafQueue: assignedContainer application=application_1396321465238_0002 container=Container: [ContainerId: container_1396321465238_0002_01_000013, NodeId: ubuntu:60709, NodeHttpAddress: ubuntu:8042, Resource: <memory:1024, vCores:1>, Priority: 10, Token: Token { kind: ContainerToken, service: 127.0.1.1:60709 }, ] containerId=container_1396321465238_0002_01_000013 queue=default: capacity=1.0, absoluteCapacity=1.0, usedResources=<memory:7168, vCores:6>usedCapacity=0.875, absoluteUsedCapacity=0.875, numApps=1, numContainers=6 usedCapacity=0.875 absoluteUsedCapacity=0.875 used=<memory:7168, vCores:6> cluster=<memory:8192, vCores:8>
2014-03-31 20:12:27,919 INFO org.apache.hadoop.yarn.server.resourcemanager.scheduler.capacity.ParentQueue: Re-sorting assigned queue: root.default stats: default: capacity=1.0, absoluteCapacity=1.0, usedResources=<memory:8192, vCores:7>usedCapacity=1.0, absoluteUsedCapacity=1.0, numApps=1, numContainers=7
2014-03-31 20:12:27,919 INFO org.apache.hadoop.yarn.server.resourcemanager.scheduler.capacity.ParentQueue: assignedContainer queue=root usedCapacity=1.0 absoluteUsedCapacity=1.0 used=<memory:8192, vCores:7> cluster=<memory:8192, vCores:8>
2014-03-31 20:12:28,034 INFO org.apache.hadoop.yarn.server.resourcemanager.rmcontainer.RMContainerImpl: container_1396321465238_0002_01_000013 Container Transitioned from ALLOCATED to ACQUIRED
2014-03-31 20:12:28,258 INFO org.apache.hadoop.yarn.server.resourcemanager.rmcontainer.RMContainerImpl: container_1396321465238_0002_01_000013 Container Transitioned from ACQUIRED to RUNNING
2014-03-31 20:12:28,970 INFO org.apache.hadoop.yarn.server.resourcemanager.rmcontainer.RMContainerImpl: container_1396321465238_0002_01_000008 Container Transitioned from RUNNING to COMPLETED
2014-03-31 20:12:28,970 INFO org.apache.hadoop.yarn.server.resourcemanager.scheduler.common.fica.FiCaSchedulerApp: Completed container: container_1396321465238_0002_01_000008 in state: COMPLETED event:FINISHED
2014-03-31 20:12:28,970 INFO org.apache.hadoop.yarn.server.resourcemanager.RMAuditLogger: USER=hduser	OPERATION=AM Released Container	TARGET=SchedulerApp	RESULT=SUCCESS	APPID=application_1396321465238_0002	CONTAINERID=container_1396321465238_0002_01_000008
2014-03-31 20:12:28,970 INFO org.apache.hadoop.yarn.server.resourcemanager.scheduler.common.fica.FiCaSchedulerNode: Released container container_1396321465238_0002_01_000008 of capacity <memory:1024, vCores:1> on host ubuntu:60709, which currently has 6 containers, <memory:7168, vCores:6> used and <memory:1024, vCores:2> available, release resources=true
2014-03-31 20:12:28,971 INFO org.apache.hadoop.yarn.server.resourcemanager.scheduler.capacity.LeafQueue: default used=<memory:7168, vCores:6> numContainers=6 user=hduser user-resources=<memory:7168, vCores:6>
2014-03-31 20:12:28,971 INFO org.apache.hadoop.yarn.server.resourcemanager.scheduler.capacity.LeafQueue: completedContainer container=Container: [ContainerId: container_1396321465238_0002_01_000008, NodeId: ubuntu:60709, NodeHttpAddress: ubuntu:8042, Resource: <memory:1024, vCores:1>, Priority: 10, Token: Token { kind: ContainerToken, service: 127.0.1.1:60709 }, ] resource=<memory:1024, vCores:1> queue=default: capacity=1.0, absoluteCapacity=1.0, usedResources=<memory:7168, vCores:6>usedCapacity=0.875, absoluteUsedCapacity=0.875, numApps=1, numContainers=6 usedCapacity=0.875 absoluteUsedCapacity=0.875 used=<memory:7168, vCores:6> cluster=<memory:8192, vCores:8>
2014-03-31 20:12:28,971 INFO org.apache.hadoop.yarn.server.resourcemanager.scheduler.capacity.ParentQueue: completedContainer queue=root usedCapacity=0.875 absoluteUsedCapacity=0.875 used=<memory:7168, vCores:6> cluster=<memory:8192, vCores:8>
2014-03-31 20:12:28,971 INFO org.apache.hadoop.yarn.server.resourcemanager.scheduler.capacity.ParentQueue: Re-sorting completed queue: root.default stats: default: capacity=1.0, absoluteCapacity=1.0, usedResources=<memory:7168, vCores:6>usedCapacity=0.875, absoluteUsedCapacity=0.875, numApps=1, numContainers=6
2014-03-31 20:12:28,971 INFO org.apache.hadoop.yarn.server.resourcemanager.scheduler.capacity.CapacityScheduler: Application appattempt_1396321465238_0002_000001 released container container_1396321465238_0002_01_000008 on node: host: ubuntu:60709 #containers=6 available=1024 used=7168 with event: FINISHED
2014-03-31 20:12:28,971 INFO org.apache.hadoop.yarn.server.resourcemanager.rmcontainer.RMContainerImpl: container_1396321465238_0002_01_000014 Container Transitioned from NEW to ALLOCATED
2014-03-31 20:12:28,971 INFO org.apache.hadoop.yarn.server.resourcemanager.RMAuditLogger: USER=hduser	OPERATION=AM Allocated Container	TARGET=SchedulerApp	RESULT=SUCCESS	APPID=application_1396321465238_0002	CONTAINERID=container_1396321465238_0002_01_000014
2014-03-31 20:12:28,971 INFO org.apache.hadoop.yarn.server.resourcemanager.scheduler.common.fica.FiCaSchedulerNode: Assigned container container_1396321465238_0002_01_000014 of capacity <memory:1024, vCores:1> on host ubuntu:60709, which currently has 7 containers, <memory:8192, vCores:7> used and <memory:0, vCores:1> available
2014-03-31 20:12:28,971 INFO org.apache.hadoop.yarn.server.resourcemanager.scheduler.capacity.LeafQueue: assignedContainer application=application_1396321465238_0002 container=Container: [ContainerId: container_1396321465238_0002_01_000014, NodeId: ubuntu:60709, NodeHttpAddress: ubuntu:8042, Resource: <memory:1024, vCores:1>, Priority: 10, Token: Token { kind: ContainerToken, service: 127.0.1.1:60709 }, ] containerId=container_1396321465238_0002_01_000014 queue=default: capacity=1.0, absoluteCapacity=1.0, usedResources=<memory:7168, vCores:6>usedCapacity=0.875, absoluteUsedCapacity=0.875, numApps=1, numContainers=6 usedCapacity=0.875 absoluteUsedCapacity=0.875 used=<memory:7168, vCores:6> cluster=<memory:8192, vCores:8>
2014-03-31 20:12:28,971 INFO org.apache.hadoop.yarn.server.resourcemanager.scheduler.capacity.ParentQueue: Re-sorting assigned queue: root.default stats: default: capacity=1.0, absoluteCapacity=1.0, usedResources=<memory:8192, vCores:7>usedCapacity=1.0, absoluteUsedCapacity=1.0, numApps=1, numContainers=7
2014-03-31 20:12:28,971 INFO org.apache.hadoop.yarn.server.resourcemanager.scheduler.capacity.ParentQueue: assignedContainer queue=root usedCapacity=1.0 absoluteUsedCapacity=1.0 used=<memory:8192, vCores:7> cluster=<memory:8192, vCores:8>
2014-03-31 20:12:29,042 INFO org.apache.hadoop.yarn.server.resourcemanager.rmcontainer.RMContainerImpl: container_1396321465238_0002_01_000014 Container Transitioned from ALLOCATED to ACQUIRED
2014-03-31 20:12:29,973 INFO org.apache.hadoop.yarn.server.resourcemanager.rmcontainer.RMContainerImpl: container_1396321465238_0002_01_000014 Container Transitioned from ACQUIRED to RUNNING
2014-03-31 20:12:29,973 INFO org.apache.hadoop.yarn.server.resourcemanager.rmcontainer.RMContainerImpl: container_1396321465238_0002_01_000009 Container Transitioned from RUNNING to COMPLETED
2014-03-31 20:12:29,973 INFO org.apache.hadoop.yarn.server.resourcemanager.scheduler.common.fica.FiCaSchedulerApp: Completed container: container_1396321465238_0002_01_000009 in state: COMPLETED event:FINISHED
2014-03-31 20:12:29,973 INFO org.apache.hadoop.yarn.server.resourcemanager.RMAuditLogger: USER=hduser	OPERATION=AM Released Container	TARGET=SchedulerApp	RESULT=SUCCESS	APPID=application_1396321465238_0002	CONTAINERID=container_1396321465238_0002_01_000009
2014-03-31 20:12:29,973 INFO org.apache.hadoop.yarn.server.resourcemanager.scheduler.common.fica.FiCaSchedulerNode: Released container container_1396321465238_0002_01_000009 of capacity <memory:1024, vCores:1> on host ubuntu:60709, which currently has 6 containers, <memory:7168, vCores:6> used and <memory:1024, vCores:2> available, release resources=true
2014-03-31 20:12:29,973 INFO org.apache.hadoop.yarn.server.resourcemanager.scheduler.capacity.LeafQueue: default used=<memory:7168, vCores:6> numContainers=6 user=hduser user-resources=<memory:7168, vCores:6>
2014-03-31 20:12:29,973 INFO org.apache.hadoop.yarn.server.resourcemanager.scheduler.capacity.LeafQueue: completedContainer container=Container: [ContainerId: container_1396321465238_0002_01_000009, NodeId: ubuntu:60709, NodeHttpAddress: ubuntu:8042, Resource: <memory:1024, vCores:1>, Priority: 10, Token: Token { kind: ContainerToken, service: 127.0.1.1:60709 }, ] resource=<memory:1024, vCores:1> queue=default: capacity=1.0, absoluteCapacity=1.0, usedResources=<memory:7168, vCores:6>usedCapacity=0.875, absoluteUsedCapacity=0.875, numApps=1, numContainers=6 usedCapacity=0.875 absoluteUsedCapacity=0.875 used=<memory:7168, vCores:6> cluster=<memory:8192, vCores:8>
2014-03-31 20:12:29,973 INFO org.apache.hadoop.yarn.server.resourcemanager.scheduler.capacity.ParentQueue: completedContainer queue=root usedCapacity=0.875 absoluteUsedCapacity=0.875 used=<memory:7168, vCores:6> cluster=<memory:8192, vCores:8>
2014-03-31 20:12:29,974 INFO org.apache.hadoop.yarn.server.resourcemanager.scheduler.capacity.ParentQueue: Re-sorting completed queue: root.default stats: default: capacity=1.0, absoluteCapacity=1.0, usedResources=<memory:7168, vCores:6>usedCapacity=0.875, absoluteUsedCapacity=0.875, numApps=1, numContainers=6
2014-03-31 20:12:29,974 INFO org.apache.hadoop.yarn.server.resourcemanager.scheduler.capacity.CapacityScheduler: Application appattempt_1396321465238_0002_000001 released container container_1396321465238_0002_01_000009 on node: host: ubuntu:60709 #containers=6 available=1024 used=7168 with event: FINISHED
2014-03-31 20:12:29,974 INFO org.apache.hadoop.yarn.server.resourcemanager.rmcontainer.RMContainerImpl: container_1396321465238_0002_01_000015 Container Transitioned from NEW to ALLOCATED
2014-03-31 20:12:29,974 INFO org.apache.hadoop.yarn.server.resourcemanager.RMAuditLogger: USER=hduser	OPERATION=AM Allocated Container	TARGET=SchedulerApp	RESULT=SUCCESS	APPID=application_1396321465238_0002	CONTAINERID=container_1396321465238_0002_01_000015
2014-03-31 20:12:29,974 INFO org.apache.hadoop.yarn.server.resourcemanager.scheduler.common.fica.FiCaSchedulerNode: Assigned container container_1396321465238_0002_01_000015 of capacity <memory:1024, vCores:1> on host ubuntu:60709, which currently has 7 containers, <memory:8192, vCores:7> used and <memory:0, vCores:1> available
2014-03-31 20:12:29,974 INFO org.apache.hadoop.yarn.server.resourcemanager.scheduler.capacity.LeafQueue: assignedContainer application=application_1396321465238_0002 container=Container: [ContainerId: container_1396321465238_0002_01_000015, NodeId: ubuntu:60709, NodeHttpAddress: ubuntu:8042, Resource: <memory:1024, vCores:1>, Priority: 10, Token: Token { kind: ContainerToken, service: 127.0.1.1:60709 }, ] containerId=container_1396321465238_0002_01_000015 queue=default: capacity=1.0, absoluteCapacity=1.0, usedResources=<memory:7168, vCores:6>usedCapacity=0.875, absoluteUsedCapacity=0.875, numApps=1, numContainers=6 usedCapacity=0.875 absoluteUsedCapacity=0.875 used=<memory:7168, vCores:6> cluster=<memory:8192, vCores:8>
2014-03-31 20:12:29,974 INFO org.apache.hadoop.yarn.server.resourcemanager.scheduler.capacity.ParentQueue: Re-sorting assigned queue: root.default stats: default: capacity=1.0, absoluteCapacity=1.0, usedResources=<memory:8192, vCores:7>usedCapacity=1.0, absoluteUsedCapacity=1.0, numApps=1, numContainers=7
2014-03-31 20:12:29,974 INFO org.apache.hadoop.yarn.server.resourcemanager.scheduler.capacity.ParentQueue: assignedContainer queue=root usedCapacity=1.0 absoluteUsedCapacity=1.0 used=<memory:8192, vCores:7> cluster=<memory:8192, vCores:8>
2014-03-31 20:12:30,052 INFO org.apache.hadoop.yarn.server.resourcemanager.rmcontainer.RMContainerImpl: container_1396321465238_0002_01_000015 Container Transitioned from ALLOCATED to ACQUIRED
2014-03-31 20:12:30,788 INFO org.apache.hadoop.yarn.server.resourcemanager.rmcontainer.RMContainerImpl: container_1396321465238_0002_01_000015 Container Transitioned from ACQUIRED to RUNNING
2014-03-31 20:12:30,889 INFO org.apache.hadoop.yarn.server.resourcemanager.rmcontainer.RMContainerImpl: container_1396321465238_0002_01_000010 Container Transitioned from RUNNING to COMPLETED
2014-03-31 20:12:30,889 INFO org.apache.hadoop.yarn.server.resourcemanager.scheduler.common.fica.FiCaSchedulerApp: Completed container: container_1396321465238_0002_01_000010 in state: COMPLETED event:FINISHED
2014-03-31 20:12:30,889 INFO org.apache.hadoop.yarn.server.resourcemanager.RMAuditLogger: USER=hduser	OPERATION=AM Released Container	TARGET=SchedulerApp	RESULT=SUCCESS	APPID=application_1396321465238_0002	CONTAINERID=container_1396321465238_0002_01_000010
2014-03-31 20:12:30,889 INFO org.apache.hadoop.yarn.server.resourcemanager.scheduler.common.fica.FiCaSchedulerNode: Released container container_1396321465238_0002_01_000010 of capacity <memory:1024, vCores:1> on host ubuntu:60709, which currently has 6 containers, <memory:7168, vCores:6> used and <memory:1024, vCores:2> available, release resources=true
2014-03-31 20:12:30,889 INFO org.apache.hadoop.yarn.server.resourcemanager.scheduler.capacity.LeafQueue: default used=<memory:7168, vCores:6> numContainers=6 user=hduser user-resources=<memory:7168, vCores:6>
2014-03-31 20:12:30,889 INFO org.apache.hadoop.yarn.server.resourcemanager.scheduler.capacity.LeafQueue: completedContainer container=Container: [ContainerId: container_1396321465238_0002_01_000010, NodeId: ubuntu:60709, NodeHttpAddress: ubuntu:8042, Resource: <memory:1024, vCores:1>, Priority: 10, Token: Token { kind: ContainerToken, service: 127.0.1.1:60709 }, ] resource=<memory:1024, vCores:1> queue=default: capacity=1.0, absoluteCapacity=1.0, usedResources=<memory:7168, vCores:6>usedCapacity=0.875, absoluteUsedCapacity=0.875, numApps=1, numContainers=6 usedCapacity=0.875 absoluteUsedCapacity=0.875 used=<memory:7168, vCores:6> cluster=<memory:8192, vCores:8>
2014-03-31 20:12:30,889 INFO org.apache.hadoop.yarn.server.resourcemanager.scheduler.capacity.ParentQueue: completedContainer queue=root usedCapacity=0.875 absoluteUsedCapacity=0.875 used=<memory:7168, vCores:6> cluster=<memory:8192, vCores:8>
2014-03-31 20:12:30,889 INFO org.apache.hadoop.yarn.server.resourcemanager.scheduler.capacity.ParentQueue: Re-sorting completed queue: root.default stats: default: capacity=1.0, absoluteCapacity=1.0, usedResources=<memory:7168, vCores:6>usedCapacity=0.875, absoluteUsedCapacity=0.875, numApps=1, numContainers=6
2014-03-31 20:12:30,889 INFO org.apache.hadoop.yarn.server.resourcemanager.scheduler.capacity.CapacityScheduler: Application appattempt_1396321465238_0002_000001 released container container_1396321465238_0002_01_000010 on node: host: ubuntu:60709 #containers=6 available=1024 used=7168 with event: FINISHED
2014-03-31 20:12:30,890 INFO org.apache.hadoop.yarn.server.resourcemanager.rmcontainer.RMContainerImpl: container_1396321465238_0002_01_000016 Container Transitioned from NEW to ALLOCATED
2014-03-31 20:12:30,890 INFO org.apache.hadoop.yarn.server.resourcemanager.RMAuditLogger: USER=hduser	OPERATION=AM Allocated Container	TARGET=SchedulerApp	RESULT=SUCCESS	APPID=application_1396321465238_0002	CONTAINERID=container_1396321465238_0002_01_000016
2014-03-31 20:12:30,890 INFO org.apache.hadoop.yarn.server.resourcemanager.scheduler.common.fica.FiCaSchedulerNode: Assigned container container_1396321465238_0002_01_000016 of capacity <memory:1024, vCores:1> on host ubuntu:60709, which currently has 7 containers, <memory:8192, vCores:7> used and <memory:0, vCores:1> available
2014-03-31 20:12:30,890 INFO org.apache.hadoop.yarn.server.resourcemanager.scheduler.capacity.LeafQueue: assignedContainer application=application_1396321465238_0002 container=Container: [ContainerId: container_1396321465238_0002_01_000016, NodeId: ubuntu:60709, NodeHttpAddress: ubuntu:8042, Resource: <memory:1024, vCores:1>, Priority: 10, Token: Token { kind: ContainerToken, service: 127.0.1.1:60709 }, ] containerId=container_1396321465238_0002_01_000016 queue=default: capacity=1.0, absoluteCapacity=1.0, usedResources=<memory:7168, vCores:6>usedCapacity=0.875, absoluteUsedCapacity=0.875, numApps=1, numContainers=6 usedCapacity=0.875 absoluteUsedCapacity=0.875 used=<memory:7168, vCores:6> cluster=<memory:8192, vCores:8>
2014-03-31 20:12:30,890 INFO org.apache.hadoop.yarn.server.resourcemanager.scheduler.capacity.ParentQueue: Re-sorting assigned queue: root.default stats: default: capacity=1.0, absoluteCapacity=1.0, usedResources=<memory:8192, vCores:7>usedCapacity=1.0, absoluteUsedCapacity=1.0, numApps=1, numContainers=7
2014-03-31 20:12:30,890 INFO org.apache.hadoop.yarn.server.resourcemanager.scheduler.capacity.ParentQueue: assignedContainer queue=root usedCapacity=1.0 absoluteUsedCapacity=1.0 used=<memory:8192, vCores:7> cluster=<memory:8192, vCores:8>
2014-03-31 20:12:31,063 INFO org.apache.hadoop.yarn.server.resourcemanager.rmcontainer.RMContainerImpl: container_1396321465238_0002_01_000016 Container Transitioned from ALLOCATED to ACQUIRED
2014-03-31 20:12:31,892 INFO org.apache.hadoop.yarn.server.resourcemanager.rmcontainer.RMContainerImpl: container_1396321465238_0002_01_000016 Container Transitioned from ACQUIRED to RUNNING
2014-03-31 20:12:31,893 INFO org.apache.hadoop.yarn.server.resourcemanager.rmcontainer.RMContainerImpl: container_1396321465238_0002_01_000011 Container Transitioned from RUNNING to COMPLETED
2014-03-31 20:12:31,893 INFO org.apache.hadoop.yarn.server.resourcemanager.scheduler.common.fica.FiCaSchedulerApp: Completed container: container_1396321465238_0002_01_000011 in state: COMPLETED event:FINISHED
2014-03-31 20:12:31,893 INFO org.apache.hadoop.yarn.server.resourcemanager.RMAuditLogger: USER=hduser	OPERATION=AM Released Container	TARGET=SchedulerApp	RESULT=SUCCESS	APPID=application_1396321465238_0002	CONTAINERID=container_1396321465238_0002_01_000011
2014-03-31 20:12:31,893 INFO org.apache.hadoop.yarn.server.resourcemanager.scheduler.common.fica.FiCaSchedulerNode: Released container container_1396321465238_0002_01_000011 of capacity <memory:1024, vCores:1> on host ubuntu:60709, which currently has 6 containers, <memory:7168, vCores:6> used and <memory:1024, vCores:2> available, release resources=true
2014-03-31 20:12:31,893 INFO org.apache.hadoop.yarn.server.resourcemanager.scheduler.capacity.LeafQueue: default used=<memory:7168, vCores:6> numContainers=6 user=hduser user-resources=<memory:7168, vCores:6>
2014-03-31 20:12:31,893 INFO org.apache.hadoop.yarn.server.resourcemanager.scheduler.capacity.LeafQueue: completedContainer container=Container: [ContainerId: container_1396321465238_0002_01_000011, NodeId: ubuntu:60709, NodeHttpAddress: ubuntu:8042, Resource: <memory:1024, vCores:1>, Priority: 10, Token: Token { kind: ContainerToken, service: 127.0.1.1:60709 }, ] resource=<memory:1024, vCores:1> queue=default: capacity=1.0, absoluteCapacity=1.0, usedResources=<memory:7168, vCores:6>usedCapacity=0.875, absoluteUsedCapacity=0.875, numApps=1, numContainers=6 usedCapacity=0.875 absoluteUsedCapacity=0.875 used=<memory:7168, vCores:6> cluster=<memory:8192, vCores:8>
2014-03-31 20:12:31,893 INFO org.apache.hadoop.yarn.server.resourcemanager.scheduler.capacity.ParentQueue: completedContainer queue=root usedCapacity=0.875 absoluteUsedCapacity=0.875 used=<memory:7168, vCores:6> cluster=<memory:8192, vCores:8>
2014-03-31 20:12:31,893 INFO org.apache.hadoop.yarn.server.resourcemanager.scheduler.capacity.ParentQueue: Re-sorting completed queue: root.default stats: default: capacity=1.0, absoluteCapacity=1.0, usedResources=<memory:7168, vCores:6>usedCapacity=0.875, absoluteUsedCapacity=0.875, numApps=1, numContainers=6
2014-03-31 20:12:31,893 INFO org.apache.hadoop.yarn.server.resourcemanager.scheduler.capacity.CapacityScheduler: Application appattempt_1396321465238_0002_000001 released container container_1396321465238_0002_01_000011 on node: host: ubuntu:60709 #containers=6 available=1024 used=7168 with event: FINISHED
2014-03-31 20:12:31,893 INFO org.apache.hadoop.yarn.server.resourcemanager.rmcontainer.RMContainerImpl: container_1396321465238_0002_01_000017 Container Transitioned from NEW to ALLOCATED
2014-03-31 20:12:31,893 INFO org.apache.hadoop.yarn.server.resourcemanager.RMAuditLogger: USER=hduser	OPERATION=AM Allocated Container	TARGET=SchedulerApp	RESULT=SUCCESS	APPID=application_1396321465238_0002	CONTAINERID=container_1396321465238_0002_01_000017
2014-03-31 20:12:31,893 INFO org.apache.hadoop.yarn.server.resourcemanager.scheduler.common.fica.FiCaSchedulerNode: Assigned container container_1396321465238_0002_01_000017 of capacity <memory:1024, vCores:1> on host ubuntu:60709, which currently has 7 containers, <memory:8192, vCores:7> used and <memory:0, vCores:1> available
2014-03-31 20:12:31,894 INFO org.apache.hadoop.yarn.server.resourcemanager.scheduler.capacity.LeafQueue: assignedContainer application=application_1396321465238_0002 container=Container: [ContainerId: container_1396321465238_0002_01_000017, NodeId: ubuntu:60709, NodeHttpAddress: ubuntu:8042, Resource: <memory:1024, vCores:1>, Priority: 10, Token: Token { kind: ContainerToken, service: 127.0.1.1:60709 }, ] containerId=container_1396321465238_0002_01_000017 queue=default: capacity=1.0, absoluteCapacity=1.0, usedResources=<memory:7168, vCores:6>usedCapacity=0.875, absoluteUsedCapacity=0.875, numApps=1, numContainers=6 usedCapacity=0.875 absoluteUsedCapacity=0.875 used=<memory:7168, vCores:6> cluster=<memory:8192, vCores:8>
2014-03-31 20:12:31,894 INFO org.apache.hadoop.yarn.server.resourcemanager.scheduler.capacity.ParentQueue: Re-sorting assigned queue: root.default stats: default: capacity=1.0, absoluteCapacity=1.0, usedResources=<memory:8192, vCores:7>usedCapacity=1.0, absoluteUsedCapacity=1.0, numApps=1, numContainers=7
2014-03-31 20:12:31,894 INFO org.apache.hadoop.yarn.server.resourcemanager.scheduler.capacity.ParentQueue: assignedContainer queue=root usedCapacity=1.0 absoluteUsedCapacity=1.0 used=<memory:8192, vCores:7> cluster=<memory:8192, vCores:8>
2014-03-31 20:12:32,080 INFO org.apache.hadoop.yarn.server.resourcemanager.rmcontainer.RMContainerImpl: container_1396321465238_0002_01_000017 Container Transitioned from ALLOCATED to ACQUIRED
2014-03-31 20:12:32,152 INFO org.apache.hadoop.yarn.server.resourcemanager.rmcontainer.RMContainerImpl: container_1396321465238_0002_01_000017 Container Transitioned from ACQUIRED to RUNNING
2014-03-31 20:12:33,157 INFO org.apache.hadoop.yarn.server.resourcemanager.rmcontainer.RMContainerImpl: container_1396321465238_0002_01_000012 Container Transitioned from RUNNING to COMPLETED
2014-03-31 20:12:33,157 INFO org.apache.hadoop.yarn.server.resourcemanager.scheduler.common.fica.FiCaSchedulerApp: Completed container: container_1396321465238_0002_01_000012 in state: COMPLETED event:FINISHED
2014-03-31 20:12:33,157 INFO org.apache.hadoop.yarn.server.resourcemanager.RMAuditLogger: USER=hduser	OPERATION=AM Released Container	TARGET=SchedulerApp	RESULT=SUCCESS	APPID=application_1396321465238_0002	CONTAINERID=container_1396321465238_0002_01_000012
2014-03-31 20:12:33,157 INFO org.apache.hadoop.yarn.server.resourcemanager.scheduler.common.fica.FiCaSchedulerNode: Released container container_1396321465238_0002_01_000012 of capacity <memory:1024, vCores:1> on host ubuntu:60709, which currently has 6 containers, <memory:7168, vCores:6> used and <memory:1024, vCores:2> available, release resources=true
2014-03-31 20:12:33,157 INFO org.apache.hadoop.yarn.server.resourcemanager.scheduler.capacity.LeafQueue: default used=<memory:7168, vCores:6> numContainers=6 user=hduser user-resources=<memory:7168, vCores:6>
2014-03-31 20:12:33,157 INFO org.apache.hadoop.yarn.server.resourcemanager.scheduler.capacity.LeafQueue: completedContainer container=Container: [ContainerId: container_1396321465238_0002_01_000012, NodeId: ubuntu:60709, NodeHttpAddress: ubuntu:8042, Resource: <memory:1024, vCores:1>, Priority: 10, Token: Token { kind: ContainerToken, service: 127.0.1.1:60709 }, ] resource=<memory:1024, vCores:1> queue=default: capacity=1.0, absoluteCapacity=1.0, usedResources=<memory:7168, vCores:6>usedCapacity=0.875, absoluteUsedCapacity=0.875, numApps=1, numContainers=6 usedCapacity=0.875 absoluteUsedCapacity=0.875 used=<memory:7168, vCores:6> cluster=<memory:8192, vCores:8>
2014-03-31 20:12:33,157 INFO org.apache.hadoop.yarn.server.resourcemanager.scheduler.capacity.ParentQueue: completedContainer queue=root usedCapacity=0.875 absoluteUsedCapacity=0.875 used=<memory:7168, vCores:6> cluster=<memory:8192, vCores:8>
2014-03-31 20:12:33,157 INFO org.apache.hadoop.yarn.server.resourcemanager.scheduler.capacity.ParentQueue: Re-sorting completed queue: root.default stats: default: capacity=1.0, absoluteCapacity=1.0, usedResources=<memory:7168, vCores:6>usedCapacity=0.875, absoluteUsedCapacity=0.875, numApps=1, numContainers=6
2014-03-31 20:12:33,158 INFO org.apache.hadoop.yarn.server.resourcemanager.scheduler.capacity.CapacityScheduler: Application appattempt_1396321465238_0002_000001 released container container_1396321465238_0002_01_000012 on node: host: ubuntu:60709 #containers=6 available=1024 used=7168 with event: FINISHED
2014-03-31 20:12:33,158 INFO org.apache.hadoop.yarn.server.resourcemanager.rmcontainer.RMContainerImpl: container_1396321465238_0002_01_000018 Container Transitioned from NEW to ALLOCATED
2014-03-31 20:12:33,158 INFO org.apache.hadoop.yarn.server.resourcemanager.RMAuditLogger: USER=hduser	OPERATION=AM Allocated Container	TARGET=SchedulerApp	RESULT=SUCCESS	APPID=application_1396321465238_0002	CONTAINERID=container_1396321465238_0002_01_000018
2014-03-31 20:12:33,158 INFO org.apache.hadoop.yarn.server.resourcemanager.scheduler.common.fica.FiCaSchedulerNode: Assigned container container_1396321465238_0002_01_000018 of capacity <memory:1024, vCores:1> on host ubuntu:60709, which currently has 7 containers, <memory:8192, vCores:7> used and <memory:0, vCores:1> available
2014-03-31 20:12:33,158 INFO org.apache.hadoop.yarn.server.resourcemanager.scheduler.capacity.LeafQueue: assignedContainer application=application_1396321465238_0002 container=Container: [ContainerId: container_1396321465238_0002_01_000018, NodeId: ubuntu:60709, NodeHttpAddress: ubuntu:8042, Resource: <memory:1024, vCores:1>, Priority: 10, Token: Token { kind: ContainerToken, service: 127.0.1.1:60709 }, ] containerId=container_1396321465238_0002_01_000018 queue=default: capacity=1.0, absoluteCapacity=1.0, usedResources=<memory:7168, vCores:6>usedCapacity=0.875, absoluteUsedCapacity=0.875, numApps=1, numContainers=6 usedCapacity=0.875 absoluteUsedCapacity=0.875 used=<memory:7168, vCores:6> cluster=<memory:8192, vCores:8>
2014-03-31 20:12:33,158 INFO org.apache.hadoop.yarn.server.resourcemanager.scheduler.capacity.ParentQueue: Re-sorting assigned queue: root.default stats: default: capacity=1.0, absoluteCapacity=1.0, usedResources=<memory:8192, vCores:7>usedCapacity=1.0, absoluteUsedCapacity=1.0, numApps=1, numContainers=7
2014-03-31 20:12:33,158 INFO org.apache.hadoop.yarn.server.resourcemanager.scheduler.capacity.ParentQueue: assignedContainer queue=root usedCapacity=1.0 absoluteUsedCapacity=1.0 used=<memory:8192, vCores:7> cluster=<memory:8192, vCores:8>
2014-03-31 20:12:33,637 INFO org.apache.hadoop.yarn.server.resourcemanager.rmcontainer.RMContainerImpl: container_1396321465238_0002_01_000013 Container Transitioned from RUNNING to COMPLETED
2014-03-31 20:12:33,637 INFO org.apache.hadoop.yarn.server.resourcemanager.scheduler.common.fica.FiCaSchedulerApp: Completed container: container_1396321465238_0002_01_000013 in state: COMPLETED event:FINISHED
2014-03-31 20:12:33,637 INFO org.apache.hadoop.yarn.server.resourcemanager.RMAuditLogger: USER=hduser	OPERATION=AM Released Container	TARGET=SchedulerApp	RESULT=SUCCESS	APPID=application_1396321465238_0002	CONTAINERID=container_1396321465238_0002_01_000013
2014-03-31 20:12:33,637 INFO org.apache.hadoop.yarn.server.resourcemanager.scheduler.common.fica.FiCaSchedulerNode: Released container container_1396321465238_0002_01_000013 of capacity <memory:1024, vCores:1> on host ubuntu:60709, which currently has 6 containers, <memory:7168, vCores:6> used and <memory:1024, vCores:2> available, release resources=true
2014-03-31 20:12:33,637 INFO org.apache.hadoop.yarn.server.resourcemanager.scheduler.capacity.LeafQueue: default used=<memory:7168, vCores:6> numContainers=6 user=hduser user-resources=<memory:7168, vCores:6>
2014-03-31 20:12:33,637 INFO org.apache.hadoop.yarn.server.resourcemanager.scheduler.capacity.LeafQueue: completedContainer container=Container: [ContainerId: container_1396321465238_0002_01_000013, NodeId: ubuntu:60709, NodeHttpAddress: ubuntu:8042, Resource: <memory:1024, vCores:1>, Priority: 10, Token: Token { kind: ContainerToken, service: 127.0.1.1:60709 }, ] resource=<memory:1024, vCores:1> queue=default: capacity=1.0, absoluteCapacity=1.0, usedResources=<memory:7168, vCores:6>usedCapacity=0.875, absoluteUsedCapacity=0.875, numApps=1, numContainers=6 usedCapacity=0.875 absoluteUsedCapacity=0.875 used=<memory:7168, vCores:6> cluster=<memory:8192, vCores:8>
2014-03-31 20:12:33,638 INFO org.apache.hadoop.yarn.server.resourcemanager.scheduler.capacity.ParentQueue: completedContainer queue=root usedCapacity=0.875 absoluteUsedCapacity=0.875 used=<memory:7168, vCores:6> cluster=<memory:8192, vCores:8>
2014-03-31 20:12:33,638 INFO org.apache.hadoop.yarn.server.resourcemanager.scheduler.capacity.ParentQueue: Re-sorting completed queue: root.default stats: default: capacity=1.0, absoluteCapacity=1.0, usedResources=<memory:7168, vCores:6>usedCapacity=0.875, absoluteUsedCapacity=0.875, numApps=1, numContainers=6
2014-03-31 20:12:33,638 INFO org.apache.hadoop.yarn.server.resourcemanager.scheduler.capacity.CapacityScheduler: Application appattempt_1396321465238_0002_000001 released container container_1396321465238_0002_01_000013 on node: host: ubuntu:60709 #containers=6 available=1024 used=7168 with event: FINISHED
2014-03-31 20:12:33,638 INFO org.apache.hadoop.yarn.server.resourcemanager.rmcontainer.RMContainerImpl: container_1396321465238_0002_01_000019 Container Transitioned from NEW to ALLOCATED
2014-03-31 20:12:33,638 INFO org.apache.hadoop.yarn.server.resourcemanager.RMAuditLogger: USER=hduser	OPERATION=AM Allocated Container	TARGET=SchedulerApp	RESULT=SUCCESS	APPID=application_1396321465238_0002	CONTAINERID=container_1396321465238_0002_01_000019
2014-03-31 20:12:33,638 INFO org.apache.hadoop.yarn.server.resourcemanager.scheduler.common.fica.FiCaSchedulerNode: Assigned container container_1396321465238_0002_01_000019 of capacity <memory:1024, vCores:1> on host ubuntu:60709, which currently has 7 containers, <memory:8192, vCores:7> used and <memory:0, vCores:1> available
2014-03-31 20:12:33,638 INFO org.apache.hadoop.yarn.server.resourcemanager.scheduler.capacity.LeafQueue: assignedContainer application=application_1396321465238_0002 container=Container: [ContainerId: container_1396321465238_0002_01_000019, NodeId: ubuntu:60709, NodeHttpAddress: ubuntu:8042, Resource: <memory:1024, vCores:1>, Priority: 10, Token: Token { kind: ContainerToken, service: 127.0.1.1:60709 }, ] containerId=container_1396321465238_0002_01_000019 queue=default: capacity=1.0, absoluteCapacity=1.0, usedResources=<memory:7168, vCores:6>usedCapacity=0.875, absoluteUsedCapacity=0.875, numApps=1, numContainers=6 usedCapacity=0.875 absoluteUsedCapacity=0.875 used=<memory:7168, vCores:6> cluster=<memory:8192, vCores:8>
2014-03-31 20:12:33,638 INFO org.apache.hadoop.yarn.server.resourcemanager.scheduler.capacity.ParentQueue: Re-sorting assigned queue: root.default stats: default: capacity=1.0, absoluteCapacity=1.0, usedResources=<memory:8192, vCores:7>usedCapacity=1.0, absoluteUsedCapacity=1.0, numApps=1, numContainers=7
2014-03-31 20:12:33,638 INFO org.apache.hadoop.yarn.server.resourcemanager.scheduler.capacity.ParentQueue: assignedContainer queue=root usedCapacity=1.0 absoluteUsedCapacity=1.0 used=<memory:8192, vCores:7> cluster=<memory:8192, vCores:8>
2014-03-31 20:12:34,088 INFO org.apache.hadoop.yarn.server.resourcemanager.rmcontainer.RMContainerImpl: container_1396321465238_0002_01_000018 Container Transitioned from ALLOCATED to ACQUIRED
2014-03-31 20:12:34,088 INFO org.apache.hadoop.yarn.server.resourcemanager.rmcontainer.RMContainerImpl: container_1396321465238_0002_01_000019 Container Transitioned from ALLOCATED to ACQUIRED
2014-03-31 20:12:34,640 INFO org.apache.hadoop.yarn.server.resourcemanager.rmcontainer.RMContainerImpl: container_1396321465238_0002_01_000018 Container Transitioned from ACQUIRED to RUNNING
2014-03-31 20:12:34,640 INFO org.apache.hadoop.yarn.server.resourcemanager.rmcontainer.RMContainerImpl: container_1396321465238_0002_01_000019 Container Transitioned from ACQUIRED to RUNNING
2014-03-31 20:12:34,640 INFO org.apache.hadoop.yarn.server.resourcemanager.rmcontainer.RMContainerImpl: container_1396321465238_0002_01_000014 Container Transitioned from RUNNING to COMPLETED
2014-03-31 20:12:34,640 INFO org.apache.hadoop.yarn.server.resourcemanager.scheduler.common.fica.FiCaSchedulerApp: Completed container: container_1396321465238_0002_01_000014 in state: COMPLETED event:FINISHED
2014-03-31 20:12:34,640 INFO org.apache.hadoop.yarn.server.resourcemanager.RMAuditLogger: USER=hduser	OPERATION=AM Released Container	TARGET=SchedulerApp	RESULT=SUCCESS	APPID=application_1396321465238_0002	CONTAINERID=container_1396321465238_0002_01_000014
2014-03-31 20:12:34,640 INFO org.apache.hadoop.yarn.server.resourcemanager.scheduler.common.fica.FiCaSchedulerNode: Released container container_1396321465238_0002_01_000014 of capacity <memory:1024, vCores:1> on host ubuntu:60709, which currently has 6 containers, <memory:7168, vCores:6> used and <memory:1024, vCores:2> available, release resources=true
2014-03-31 20:12:34,640 INFO org.apache.hadoop.yarn.server.resourcemanager.scheduler.capacity.LeafQueue: default used=<memory:7168, vCores:6> numContainers=6 user=hduser user-resources=<memory:7168, vCores:6>
2014-03-31 20:12:34,640 INFO org.apache.hadoop.yarn.server.resourcemanager.scheduler.capacity.LeafQueue: completedContainer container=Container: [ContainerId: container_1396321465238_0002_01_000014, NodeId: ubuntu:60709, NodeHttpAddress: ubuntu:8042, Resource: <memory:1024, vCores:1>, Priority: 10, Token: Token { kind: ContainerToken, service: 127.0.1.1:60709 }, ] resource=<memory:1024, vCores:1> queue=default: capacity=1.0, absoluteCapacity=1.0, usedResources=<memory:7168, vCores:6>usedCapacity=0.875, absoluteUsedCapacity=0.875, numApps=1, numContainers=6 usedCapacity=0.875 absoluteUsedCapacity=0.875 used=<memory:7168, vCores:6> cluster=<memory:8192, vCores:8>
2014-03-31 20:12:34,640 INFO org.apache.hadoop.yarn.server.resourcemanager.scheduler.capacity.ParentQueue: completedContainer queue=root usedCapacity=0.875 absoluteUsedCapacity=0.875 used=<memory:7168, vCores:6> cluster=<memory:8192, vCores:8>
2014-03-31 20:12:34,641 INFO org.apache.hadoop.yarn.server.resourcemanager.scheduler.capacity.ParentQueue: Re-sorting completed queue: root.default stats: default: capacity=1.0, absoluteCapacity=1.0, usedResources=<memory:7168, vCores:6>usedCapacity=0.875, absoluteUsedCapacity=0.875, numApps=1, numContainers=6
2014-03-31 20:12:34,641 INFO org.apache.hadoop.yarn.server.resourcemanager.scheduler.capacity.CapacityScheduler: Application appattempt_1396321465238_0002_000001 released container container_1396321465238_0002_01_000014 on node: host: ubuntu:60709 #containers=6 available=1024 used=7168 with event: FINISHED
2014-03-31 20:12:34,641 INFO org.apache.hadoop.yarn.server.resourcemanager.rmcontainer.RMContainerImpl: container_1396321465238_0002_01_000020 Container Transitioned from NEW to ALLOCATED
2014-03-31 20:12:34,641 INFO org.apache.hadoop.yarn.server.resourcemanager.RMAuditLogger: USER=hduser	OPERATION=AM Allocated Container	TARGET=SchedulerApp	RESULT=SUCCESS	APPID=application_1396321465238_0002	CONTAINERID=container_1396321465238_0002_01_000020
2014-03-31 20:12:34,641 INFO org.apache.hadoop.yarn.server.resourcemanager.scheduler.common.fica.FiCaSchedulerNode: Assigned container container_1396321465238_0002_01_000020 of capacity <memory:1024, vCores:1> on host ubuntu:60709, which currently has 7 containers, <memory:8192, vCores:7> used and <memory:0, vCores:1> available
2014-03-31 20:12:34,641 INFO org.apache.hadoop.yarn.server.resourcemanager.scheduler.capacity.LeafQueue: assignedContainer application=application_1396321465238_0002 container=Container: [ContainerId: container_1396321465238_0002_01_000020, NodeId: ubuntu:60709, NodeHttpAddress: ubuntu:8042, Resource: <memory:1024, vCores:1>, Priority: 10, Token: Token { kind: ContainerToken, service: 127.0.1.1:60709 }, ] containerId=container_1396321465238_0002_01_000020 queue=default: capacity=1.0, absoluteCapacity=1.0, usedResources=<memory:7168, vCores:6>usedCapacity=0.875, absoluteUsedCapacity=0.875, numApps=1, numContainers=6 usedCapacity=0.875 absoluteUsedCapacity=0.875 used=<memory:7168, vCores:6> cluster=<memory:8192, vCores:8>
2014-03-31 20:12:34,641 INFO org.apache.hadoop.yarn.server.resourcemanager.scheduler.capacity.ParentQueue: Re-sorting assigned queue: root.default stats: default: capacity=1.0, absoluteCapacity=1.0, usedResources=<memory:8192, vCores:7>usedCapacity=1.0, absoluteUsedCapacity=1.0, numApps=1, numContainers=7
2014-03-31 20:12:34,641 INFO org.apache.hadoop.yarn.server.resourcemanager.scheduler.capacity.ParentQueue: assignedContainer queue=root usedCapacity=1.0 absoluteUsedCapacity=1.0 used=<memory:8192, vCores:7> cluster=<memory:8192, vCores:8>
2014-03-31 20:12:35,098 INFO org.apache.hadoop.yarn.server.resourcemanager.rmcontainer.RMContainerImpl: container_1396321465238_0002_01_000020 Container Transitioned from ALLOCATED to ACQUIRED
2014-03-31 20:12:35,143 INFO org.apache.hadoop.yarn.server.resourcemanager.rmcontainer.RMContainerImpl: container_1396321465238_0002_01_000020 Container Transitioned from ACQUIRED to RUNNING
2014-03-31 20:12:35,784 INFO org.apache.hadoop.yarn.server.resourcemanager.rmcontainer.RMContainerImpl: container_1396321465238_0002_01_000015 Container Transitioned from RUNNING to COMPLETED
2014-03-31 20:12:35,785 INFO org.apache.hadoop.yarn.server.resourcemanager.scheduler.common.fica.FiCaSchedulerApp: Completed container: container_1396321465238_0002_01_000015 in state: COMPLETED event:FINISHED
2014-03-31 20:12:35,785 INFO org.apache.hadoop.yarn.server.resourcemanager.RMAuditLogger: USER=hduser	OPERATION=AM Released Container	TARGET=SchedulerApp	RESULT=SUCCESS	APPID=application_1396321465238_0002	CONTAINERID=container_1396321465238_0002_01_000015
2014-03-31 20:12:35,785 INFO org.apache.hadoop.yarn.server.resourcemanager.scheduler.common.fica.FiCaSchedulerNode: Released container container_1396321465238_0002_01_000015 of capacity <memory:1024, vCores:1> on host ubuntu:60709, which currently has 6 containers, <memory:7168, vCores:6> used and <memory:1024, vCores:2> available, release resources=true
2014-03-31 20:12:35,785 INFO org.apache.hadoop.yarn.server.resourcemanager.scheduler.capacity.LeafQueue: default used=<memory:7168, vCores:6> numContainers=6 user=hduser user-resources=<memory:7168, vCores:6>
2014-03-31 20:12:35,785 INFO org.apache.hadoop.yarn.server.resourcemanager.scheduler.capacity.LeafQueue: completedContainer container=Container: [ContainerId: container_1396321465238_0002_01_000015, NodeId: ubuntu:60709, NodeHttpAddress: ubuntu:8042, Resource: <memory:1024, vCores:1>, Priority: 10, Token: Token { kind: ContainerToken, service: 127.0.1.1:60709 }, ] resource=<memory:1024, vCores:1> queue=default: capacity=1.0, absoluteCapacity=1.0, usedResources=<memory:7168, vCores:6>usedCapacity=0.875, absoluteUsedCapacity=0.875, numApps=1, numContainers=6 usedCapacity=0.875 absoluteUsedCapacity=0.875 used=<memory:7168, vCores:6> cluster=<memory:8192, vCores:8>
2014-03-31 20:12:35,785 INFO org.apache.hadoop.yarn.server.resourcemanager.scheduler.capacity.ParentQueue: completedContainer queue=root usedCapacity=0.875 absoluteUsedCapacity=0.875 used=<memory:7168, vCores:6> cluster=<memory:8192, vCores:8>
2014-03-31 20:12:35,785 INFO org.apache.hadoop.yarn.server.resourcemanager.scheduler.capacity.ParentQueue: Re-sorting completed queue: root.default stats: default: capacity=1.0, absoluteCapacity=1.0, usedResources=<memory:7168, vCores:6>usedCapacity=0.875, absoluteUsedCapacity=0.875, numApps=1, numContainers=6
2014-03-31 20:12:35,785 INFO org.apache.hadoop.yarn.server.resourcemanager.scheduler.capacity.CapacityScheduler: Application appattempt_1396321465238_0002_000001 released container container_1396321465238_0002_01_000015 on node: host: ubuntu:60709 #containers=6 available=1024 used=7168 with event: FINISHED
2014-03-31 20:12:35,785 INFO org.apache.hadoop.yarn.server.resourcemanager.rmcontainer.RMContainerImpl: container_1396321465238_0002_01_000021 Container Transitioned from NEW to ALLOCATED
2014-03-31 20:12:35,785 INFO org.apache.hadoop.yarn.server.resourcemanager.RMAuditLogger: USER=hduser	OPERATION=AM Allocated Container	TARGET=SchedulerApp	RESULT=SUCCESS	APPID=application_1396321465238_0002	CONTAINERID=container_1396321465238_0002_01_000021
2014-03-31 20:12:35,785 INFO org.apache.hadoop.yarn.server.resourcemanager.scheduler.common.fica.FiCaSchedulerNode: Assigned container container_1396321465238_0002_01_000021 of capacity <memory:1024, vCores:1> on host ubuntu:60709, which currently has 7 containers, <memory:8192, vCores:7> used and <memory:0, vCores:1> available
2014-03-31 20:12:35,785 INFO org.apache.hadoop.yarn.server.resourcemanager.scheduler.capacity.LeafQueue: assignedContainer application=application_1396321465238_0002 container=Container: [ContainerId: container_1396321465238_0002_01_000021, NodeId: ubuntu:60709, NodeHttpAddress: ubuntu:8042, Resource: <memory:1024, vCores:1>, Priority: 10, Token: Token { kind: ContainerToken, service: 127.0.1.1:60709 }, ] containerId=container_1396321465238_0002_01_000021 queue=default: capacity=1.0, absoluteCapacity=1.0, usedResources=<memory:7168, vCores:6>usedCapacity=0.875, absoluteUsedCapacity=0.875, numApps=1, numContainers=6 usedCapacity=0.875 absoluteUsedCapacity=0.875 used=<memory:7168, vCores:6> cluster=<memory:8192, vCores:8>
2014-03-31 20:12:35,786 INFO org.apache.hadoop.yarn.server.resourcemanager.scheduler.capacity.ParentQueue: Re-sorting assigned queue: root.default stats: default: capacity=1.0, absoluteCapacity=1.0, usedResources=<memory:8192, vCores:7>usedCapacity=1.0, absoluteUsedCapacity=1.0, numApps=1, numContainers=7
2014-03-31 20:12:35,786 INFO org.apache.hadoop.yarn.server.resourcemanager.scheduler.capacity.ParentQueue: assignedContainer queue=root usedCapacity=1.0 absoluteUsedCapacity=1.0 used=<memory:8192, vCores:7> cluster=<memory:8192, vCores:8>
2014-03-31 20:12:36,106 INFO org.apache.hadoop.yarn.server.resourcemanager.rmcontainer.RMContainerImpl: container_1396321465238_0002_01_000021 Container Transitioned from ALLOCATED to ACQUIRED
2014-03-31 20:12:36,759 INFO org.apache.hadoop.yarn.server.resourcemanager.rmcontainer.RMContainerImpl: container_1396321465238_0002_01_000021 Container Transitioned from ACQUIRED to RUNNING
2014-03-31 20:12:36,759 INFO org.apache.hadoop.yarn.server.resourcemanager.rmcontainer.RMContainerImpl: container_1396321465238_0002_01_000016 Container Transitioned from RUNNING to COMPLETED
2014-03-31 20:12:36,759 INFO org.apache.hadoop.yarn.server.resourcemanager.scheduler.common.fica.FiCaSchedulerApp: Completed container: container_1396321465238_0002_01_000016 in state: COMPLETED event:FINISHED
2014-03-31 20:12:36,759 INFO org.apache.hadoop.yarn.server.resourcemanager.RMAuditLogger: USER=hduser	OPERATION=AM Released Container	TARGET=SchedulerApp	RESULT=SUCCESS	APPID=application_1396321465238_0002	CONTAINERID=container_1396321465238_0002_01_000016
2014-03-31 20:12:36,759 INFO org.apache.hadoop.yarn.server.resourcemanager.scheduler.common.fica.FiCaSchedulerNode: Released container container_1396321465238_0002_01_000016 of capacity <memory:1024, vCores:1> on host ubuntu:60709, which currently has 6 containers, <memory:7168, vCores:6> used and <memory:1024, vCores:2> available, release resources=true
2014-03-31 20:12:36,759 INFO org.apache.hadoop.yarn.server.resourcemanager.scheduler.capacity.LeafQueue: default used=<memory:7168, vCores:6> numContainers=6 user=hduser user-resources=<memory:7168, vCores:6>
2014-03-31 20:12:36,759 INFO org.apache.hadoop.yarn.server.resourcemanager.scheduler.capacity.LeafQueue: completedContainer container=Container: [ContainerId: container_1396321465238_0002_01_000016, NodeId: ubuntu:60709, NodeHttpAddress: ubuntu:8042, Resource: <memory:1024, vCores:1>, Priority: 10, Token: Token { kind: ContainerToken, service: 127.0.1.1:60709 }, ] resource=<memory:1024, vCores:1> queue=default: capacity=1.0, absoluteCapacity=1.0, usedResources=<memory:7168, vCores:6>usedCapacity=0.875, absoluteUsedCapacity=0.875, numApps=1, numContainers=6 usedCapacity=0.875 absoluteUsedCapacity=0.875 used=<memory:7168, vCores:6> cluster=<memory:8192, vCores:8>
2014-03-31 20:12:36,759 INFO org.apache.hadoop.yarn.server.resourcemanager.scheduler.capacity.ParentQueue: completedContainer queue=root usedCapacity=0.875 absoluteUsedCapacity=0.875 used=<memory:7168, vCores:6> cluster=<memory:8192, vCores:8>
2014-03-31 20:12:36,759 INFO org.apache.hadoop.yarn.server.resourcemanager.scheduler.capacity.ParentQueue: Re-sorting completed queue: root.default stats: default: capacity=1.0, absoluteCapacity=1.0, usedResources=<memory:7168, vCores:6>usedCapacity=0.875, absoluteUsedCapacity=0.875, numApps=1, numContainers=6
2014-03-31 20:12:36,759 INFO org.apache.hadoop.yarn.server.resourcemanager.scheduler.capacity.CapacityScheduler: Application appattempt_1396321465238_0002_000001 released container container_1396321465238_0002_01_000016 on node: host: ubuntu:60709 #containers=6 available=1024 used=7168 with event: FINISHED
2014-03-31 20:12:36,760 INFO org.apache.hadoop.yarn.server.resourcemanager.rmcontainer.RMContainerImpl: container_1396321465238_0002_01_000022 Container Transitioned from NEW to ALLOCATED
2014-03-31 20:12:36,760 INFO org.apache.hadoop.yarn.server.resourcemanager.RMAuditLogger: USER=hduser	OPERATION=AM Allocated Container	TARGET=SchedulerApp	RESULT=SUCCESS	APPID=application_1396321465238_0002	CONTAINERID=container_1396321465238_0002_01_000022
2014-03-31 20:12:36,760 INFO org.apache.hadoop.yarn.server.resourcemanager.scheduler.common.fica.FiCaSchedulerNode: Assigned container container_1396321465238_0002_01_000022 of capacity <memory:1024, vCores:1> on host ubuntu:60709, which currently has 7 containers, <memory:8192, vCores:7> used and <memory:0, vCores:1> available
2014-03-31 20:12:36,760 INFO org.apache.hadoop.yarn.server.resourcemanager.scheduler.capacity.LeafQueue: assignedContainer application=application_1396321465238_0002 container=Container: [ContainerId: container_1396321465238_0002_01_000022, NodeId: ubuntu:60709, NodeHttpAddress: ubuntu:8042, Resource: <memory:1024, vCores:1>, Priority: 10, Token: Token { kind: ContainerToken, service: 127.0.1.1:60709 }, ] containerId=container_1396321465238_0002_01_000022 queue=default: capacity=1.0, absoluteCapacity=1.0, usedResources=<memory:7168, vCores:6>usedCapacity=0.875, absoluteUsedCapacity=0.875, numApps=1, numContainers=6 usedCapacity=0.875 absoluteUsedCapacity=0.875 used=<memory:7168, vCores:6> cluster=<memory:8192, vCores:8>
2014-03-31 20:12:36,760 INFO org.apache.hadoop.yarn.server.resourcemanager.scheduler.capacity.ParentQueue: Re-sorting assigned queue: root.default stats: default: capacity=1.0, absoluteCapacity=1.0, usedResources=<memory:8192, vCores:7>usedCapacity=1.0, absoluteUsedCapacity=1.0, numApps=1, numContainers=7
2014-03-31 20:12:36,760 INFO org.apache.hadoop.yarn.server.resourcemanager.scheduler.capacity.ParentQueue: assignedContainer queue=root usedCapacity=1.0 absoluteUsedCapacity=1.0 used=<memory:8192, vCores:7> cluster=<memory:8192, vCores:8>
2014-03-31 20:12:37,114 INFO org.apache.hadoop.yarn.server.resourcemanager.rmcontainer.RMContainerImpl: container_1396321465238_0002_01_000022 Container Transitioned from ALLOCATED to ACQUIRED
2014-03-31 20:12:37,770 INFO org.apache.hadoop.yarn.server.resourcemanager.rmcontainer.RMContainerImpl: container_1396321465238_0002_01_000022 Container Transitioned from ACQUIRED to RUNNING
2014-03-31 20:12:37,772 INFO org.apache.hadoop.yarn.server.resourcemanager.rmcontainer.RMContainerImpl: container_1396321465238_0002_01_000017 Container Transitioned from RUNNING to COMPLETED
2014-03-31 20:12:37,772 INFO org.apache.hadoop.yarn.server.resourcemanager.scheduler.common.fica.FiCaSchedulerApp: Completed container: container_1396321465238_0002_01_000017 in state: COMPLETED event:FINISHED
2014-03-31 20:12:37,772 INFO org.apache.hadoop.yarn.server.resourcemanager.RMAuditLogger: USER=hduser	OPERATION=AM Released Container	TARGET=SchedulerApp	RESULT=SUCCESS	APPID=application_1396321465238_0002	CONTAINERID=container_1396321465238_0002_01_000017
2014-03-31 20:12:37,772 INFO org.apache.hadoop.yarn.server.resourcemanager.scheduler.common.fica.FiCaSchedulerNode: Released container container_1396321465238_0002_01_000017 of capacity <memory:1024, vCores:1> on host ubuntu:60709, which currently has 6 containers, <memory:7168, vCores:6> used and <memory:1024, vCores:2> available, release resources=true
2014-03-31 20:12:37,772 INFO org.apache.hadoop.yarn.server.resourcemanager.scheduler.capacity.LeafQueue: default used=<memory:7168, vCores:6> numContainers=6 user=hduser user-resources=<memory:7168, vCores:6>
2014-03-31 20:12:37,772 INFO org.apache.hadoop.yarn.server.resourcemanager.scheduler.capacity.LeafQueue: completedContainer container=Container: [ContainerId: container_1396321465238_0002_01_000017, NodeId: ubuntu:60709, NodeHttpAddress: ubuntu:8042, Resource: <memory:1024, vCores:1>, Priority: 10, Token: Token { kind: ContainerToken, service: 127.0.1.1:60709 }, ] resource=<memory:1024, vCores:1> queue=default: capacity=1.0, absoluteCapacity=1.0, usedResources=<memory:7168, vCores:6>usedCapacity=0.875, absoluteUsedCapacity=0.875, numApps=1, numContainers=6 usedCapacity=0.875 absoluteUsedCapacity=0.875 used=<memory:7168, vCores:6> cluster=<memory:8192, vCores:8>
2014-03-31 20:12:37,772 INFO org.apache.hadoop.yarn.server.resourcemanager.scheduler.capacity.ParentQueue: completedContainer queue=root usedCapacity=0.875 absoluteUsedCapacity=0.875 used=<memory:7168, vCores:6> cluster=<memory:8192, vCores:8>
2014-03-31 20:12:37,772 INFO org.apache.hadoop.yarn.server.resourcemanager.scheduler.capacity.ParentQueue: Re-sorting completed queue: root.default stats: default: capacity=1.0, absoluteCapacity=1.0, usedResources=<memory:7168, vCores:6>usedCapacity=0.875, absoluteUsedCapacity=0.875, numApps=1, numContainers=6
2014-03-31 20:12:37,772 INFO org.apache.hadoop.yarn.server.resourcemanager.scheduler.capacity.CapacityScheduler: Application appattempt_1396321465238_0002_000001 released container container_1396321465238_0002_01_000017 on node: host: ubuntu:60709 #containers=6 available=1024 used=7168 with event: FINISHED
2014-03-31 20:12:37,773 INFO org.apache.hadoop.yarn.server.resourcemanager.rmcontainer.RMContainerImpl: container_1396321465238_0002_01_000023 Container Transitioned from NEW to ALLOCATED
2014-03-31 20:12:37,773 INFO org.apache.hadoop.yarn.server.resourcemanager.RMAuditLogger: USER=hduser	OPERATION=AM Allocated Container	TARGET=SchedulerApp	RESULT=SUCCESS	APPID=application_1396321465238_0002	CONTAINERID=container_1396321465238_0002_01_000023
2014-03-31 20:12:37,773 INFO org.apache.hadoop.yarn.server.resourcemanager.scheduler.common.fica.FiCaSchedulerNode: Assigned container container_1396321465238_0002_01_000023 of capacity <memory:1024, vCores:1> on host ubuntu:60709, which currently has 7 containers, <memory:8192, vCores:7> used and <memory:0, vCores:1> available
2014-03-31 20:12:37,773 INFO org.apache.hadoop.yarn.server.resourcemanager.scheduler.capacity.LeafQueue: assignedContainer application=application_1396321465238_0002 container=Container: [ContainerId: container_1396321465238_0002_01_000023, NodeId: ubuntu:60709, NodeHttpAddress: ubuntu:8042, Resource: <memory:1024, vCores:1>, Priority: 10, Token: Token { kind: ContainerToken, service: 127.0.1.1:60709 }, ] containerId=container_1396321465238_0002_01_000023 queue=default: capacity=1.0, absoluteCapacity=1.0, usedResources=<memory:7168, vCores:6>usedCapacity=0.875, absoluteUsedCapacity=0.875, numApps=1, numContainers=6 usedCapacity=0.875 absoluteUsedCapacity=0.875 used=<memory:7168, vCores:6> cluster=<memory:8192, vCores:8>
2014-03-31 20:12:37,773 INFO org.apache.hadoop.yarn.server.resourcemanager.scheduler.capacity.ParentQueue: Re-sorting assigned queue: root.default stats: default: capacity=1.0, absoluteCapacity=1.0, usedResources=<memory:8192, vCores:7>usedCapacity=1.0, absoluteUsedCapacity=1.0, numApps=1, numContainers=7
2014-03-31 20:12:37,773 INFO org.apache.hadoop.yarn.server.resourcemanager.scheduler.capacity.ParentQueue: assignedContainer queue=root usedCapacity=1.0 absoluteUsedCapacity=1.0 used=<memory:8192, vCores:7> cluster=<memory:8192, vCores:8>
2014-03-31 20:12:38,122 INFO org.apache.hadoop.yarn.server.resourcemanager.rmcontainer.RMContainerImpl: container_1396321465238_0002_01_000023 Container Transitioned from ALLOCATED to ACQUIRED
2014-03-31 20:12:38,697 INFO org.apache.hadoop.yarn.server.resourcemanager.rmcontainer.RMContainerImpl: container_1396321465238_0002_01_000023 Container Transitioned from ACQUIRED to RUNNING
2014-03-31 20:12:39,457 INFO org.apache.hadoop.yarn.server.resourcemanager.rmcontainer.RMContainerImpl: container_1396321465238_0002_01_000018 Container Transitioned from RUNNING to COMPLETED
2014-03-31 20:12:39,457 INFO org.apache.hadoop.yarn.server.resourcemanager.scheduler.common.fica.FiCaSchedulerApp: Completed container: container_1396321465238_0002_01_000018 in state: COMPLETED event:FINISHED
2014-03-31 20:12:39,457 INFO org.apache.hadoop.yarn.server.resourcemanager.RMAuditLogger: USER=hduser	OPERATION=AM Released Container	TARGET=SchedulerApp	RESULT=SUCCESS	APPID=application_1396321465238_0002	CONTAINERID=container_1396321465238_0002_01_000018
2014-03-31 20:12:39,457 INFO org.apache.hadoop.yarn.server.resourcemanager.scheduler.common.fica.FiCaSchedulerNode: Released container container_1396321465238_0002_01_000018 of capacity <memory:1024, vCores:1> on host ubuntu:60709, which currently has 6 containers, <memory:7168, vCores:6> used and <memory:1024, vCores:2> available, release resources=true
2014-03-31 20:12:39,457 INFO org.apache.hadoop.yarn.server.resourcemanager.scheduler.capacity.LeafQueue: default used=<memory:7168, vCores:6> numContainers=6 user=hduser user-resources=<memory:7168, vCores:6>
2014-03-31 20:12:39,457 INFO org.apache.hadoop.yarn.server.resourcemanager.scheduler.capacity.LeafQueue: completedContainer container=Container: [ContainerId: container_1396321465238_0002_01_000018, NodeId: ubuntu:60709, NodeHttpAddress: ubuntu:8042, Resource: <memory:1024, vCores:1>, Priority: 10, Token: Token { kind: ContainerToken, service: 127.0.1.1:60709 }, ] resource=<memory:1024, vCores:1> queue=default: capacity=1.0, absoluteCapacity=1.0, usedResources=<memory:7168, vCores:6>usedCapacity=0.875, absoluteUsedCapacity=0.875, numApps=1, numContainers=6 usedCapacity=0.875 absoluteUsedCapacity=0.875 used=<memory:7168, vCores:6> cluster=<memory:8192, vCores:8>
2014-03-31 20:12:39,458 INFO org.apache.hadoop.yarn.server.resourcemanager.scheduler.capacity.ParentQueue: completedContainer queue=root usedCapacity=0.875 absoluteUsedCapacity=0.875 used=<memory:7168, vCores:6> cluster=<memory:8192, vCores:8>
2014-03-31 20:12:39,458 INFO org.apache.hadoop.yarn.server.resourcemanager.scheduler.capacity.ParentQueue: Re-sorting completed queue: root.default stats: default: capacity=1.0, absoluteCapacity=1.0, usedResources=<memory:7168, vCores:6>usedCapacity=0.875, absoluteUsedCapacity=0.875, numApps=1, numContainers=6
2014-03-31 20:12:39,458 INFO org.apache.hadoop.yarn.server.resourcemanager.scheduler.capacity.CapacityScheduler: Application appattempt_1396321465238_0002_000001 released container container_1396321465238_0002_01_000018 on node: host: ubuntu:60709 #containers=6 available=1024 used=7168 with event: FINISHED
2014-03-31 20:12:39,472 INFO org.apache.hadoop.yarn.server.resourcemanager.rmcontainer.RMContainerImpl: container_1396321465238_0002_01_000024 Container Transitioned from NEW to ALLOCATED
2014-03-31 20:12:39,472 INFO org.apache.hadoop.yarn.server.resourcemanager.RMAuditLogger: USER=hduser	OPERATION=AM Allocated Container	TARGET=SchedulerApp	RESULT=SUCCESS	APPID=application_1396321465238_0002	CONTAINERID=container_1396321465238_0002_01_000024
2014-03-31 20:12:39,472 INFO org.apache.hadoop.yarn.server.resourcemanager.scheduler.common.fica.FiCaSchedulerNode: Assigned container container_1396321465238_0002_01_000024 of capacity <memory:1024, vCores:1> on host ubuntu:60709, which currently has 7 containers, <memory:8192, vCores:7> used and <memory:0, vCores:1> available
2014-03-31 20:12:39,472 INFO org.apache.hadoop.yarn.server.resourcemanager.scheduler.capacity.LeafQueue: assignedContainer application=application_1396321465238_0002 container=Container: [ContainerId: container_1396321465238_0002_01_000024, NodeId: ubuntu:60709, NodeHttpAddress: ubuntu:8042, Resource: <memory:1024, vCores:1>, Priority: 10, Token: Token { kind: ContainerToken, service: 127.0.1.1:60709 }, ] containerId=container_1396321465238_0002_01_000024 queue=default: capacity=1.0, absoluteCapacity=1.0, usedResources=<memory:7168, vCores:6>usedCapacity=0.875, absoluteUsedCapacity=0.875, numApps=1, numContainers=6 usedCapacity=0.875 absoluteUsedCapacity=0.875 used=<memory:7168, vCores:6> cluster=<memory:8192, vCores:8>
2014-03-31 20:12:39,473 INFO org.apache.hadoop.yarn.server.resourcemanager.scheduler.capacity.ParentQueue: Re-sorting assigned queue: root.default stats: default: capacity=1.0, absoluteCapacity=1.0, usedResources=<memory:8192, vCores:7>usedCapacity=1.0, absoluteUsedCapacity=1.0, numApps=1, numContainers=7
2014-03-31 20:12:39,473 INFO org.apache.hadoop.yarn.server.resourcemanager.scheduler.capacity.ParentQueue: assignedContainer queue=root usedCapacity=1.0 absoluteUsedCapacity=1.0 used=<memory:8192, vCores:7> cluster=<memory:8192, vCores:8>
2014-03-31 20:12:39,896 INFO org.apache.hadoop.yarn.server.resourcemanager.rmcontainer.RMContainerImpl: container_1396321465238_0002_01_000019 Container Transitioned from RUNNING to COMPLETED
2014-03-31 20:12:39,896 INFO org.apache.hadoop.yarn.server.resourcemanager.scheduler.common.fica.FiCaSchedulerApp: Completed container: container_1396321465238_0002_01_000019 in state: COMPLETED event:FINISHED
2014-03-31 20:12:39,896 INFO org.apache.hadoop.yarn.server.resourcemanager.RMAuditLogger: USER=hduser	OPERATION=AM Released Container	TARGET=SchedulerApp	RESULT=SUCCESS	APPID=application_1396321465238_0002	CONTAINERID=container_1396321465238_0002_01_000019
2014-03-31 20:12:39,896 INFO org.apache.hadoop.yarn.server.resourcemanager.scheduler.common.fica.FiCaSchedulerNode: Released container container_1396321465238_0002_01_000019 of capacity <memory:1024, vCores:1> on host ubuntu:60709, which currently has 6 containers, <memory:7168, vCores:6> used and <memory:1024, vCores:2> available, release resources=true
2014-03-31 20:12:39,896 INFO org.apache.hadoop.yarn.server.resourcemanager.scheduler.capacity.LeafQueue: default used=<memory:7168, vCores:6> numContainers=6 user=hduser user-resources=<memory:7168, vCores:6>
2014-03-31 20:12:39,896 INFO org.apache.hadoop.yarn.server.resourcemanager.scheduler.capacity.LeafQueue: completedContainer container=Container: [ContainerId: container_1396321465238_0002_01_000019, NodeId: ubuntu:60709, NodeHttpAddress: ubuntu:8042, Resource: <memory:1024, vCores:1>, Priority: 10, Token: Token { kind: ContainerToken, service: 127.0.1.1:60709 }, ] resource=<memory:1024, vCores:1> queue=default: capacity=1.0, absoluteCapacity=1.0, usedResources=<memory:7168, vCores:6>usedCapacity=0.875, absoluteUsedCapacity=0.875, numApps=1, numContainers=6 usedCapacity=0.875 absoluteUsedCapacity=0.875 used=<memory:7168, vCores:6> cluster=<memory:8192, vCores:8>
2014-03-31 20:12:39,896 INFO org.apache.hadoop.yarn.server.resourcemanager.scheduler.capacity.ParentQueue: completedContainer queue=root usedCapacity=0.875 absoluteUsedCapacity=0.875 used=<memory:7168, vCores:6> cluster=<memory:8192, vCores:8>
2014-03-31 20:12:39,896 INFO org.apache.hadoop.yarn.server.resourcemanager.scheduler.capacity.ParentQueue: Re-sorting completed queue: root.default stats: default: capacity=1.0, absoluteCapacity=1.0, usedResources=<memory:7168, vCores:6>usedCapacity=0.875, absoluteUsedCapacity=0.875, numApps=1, numContainers=6
2014-03-31 20:12:39,896 INFO org.apache.hadoop.yarn.server.resourcemanager.scheduler.capacity.CapacityScheduler: Application appattempt_1396321465238_0002_000001 released container container_1396321465238_0002_01_000019 on node: host: ubuntu:60709 #containers=6 available=1024 used=7168 with event: FINISHED
2014-03-31 20:12:39,896 INFO org.apache.hadoop.yarn.server.resourcemanager.rmcontainer.RMContainerImpl: container_1396321465238_0002_01_000025 Container Transitioned from NEW to ALLOCATED
2014-03-31 20:12:39,896 INFO org.apache.hadoop.yarn.server.resourcemanager.RMAuditLogger: USER=hduser	OPERATION=AM Allocated Container	TARGET=SchedulerApp	RESULT=SUCCESS	APPID=application_1396321465238_0002	CONTAINERID=container_1396321465238_0002_01_000025
2014-03-31 20:12:39,896 INFO org.apache.hadoop.yarn.server.resourcemanager.scheduler.common.fica.FiCaSchedulerNode: Assigned container container_1396321465238_0002_01_000025 of capacity <memory:1024, vCores:1> on host ubuntu:60709, which currently has 7 containers, <memory:8192, vCores:7> used and <memory:0, vCores:1> available
2014-03-31 20:12:39,897 INFO org.apache.hadoop.yarn.server.resourcemanager.scheduler.capacity.LeafQueue: assignedContainer application=application_1396321465238_0002 container=Container: [ContainerId: container_1396321465238_0002_01_000025, NodeId: ubuntu:60709, NodeHttpAddress: ubuntu:8042, Resource: <memory:1024, vCores:1>, Priority: 10, Token: Token { kind: ContainerToken, service: 127.0.1.1:60709 }, ] containerId=container_1396321465238_0002_01_000025 queue=default: capacity=1.0, absoluteCapacity=1.0, usedResources=<memory:7168, vCores:6>usedCapacity=0.875, absoluteUsedCapacity=0.875, numApps=1, numContainers=6 usedCapacity=0.875 absoluteUsedCapacity=0.875 used=<memory:7168, vCores:6> cluster=<memory:8192, vCores:8>
2014-03-31 20:12:39,897 INFO org.apache.hadoop.yarn.server.resourcemanager.scheduler.capacity.ParentQueue: Re-sorting assigned queue: root.default stats: default: capacity=1.0, absoluteCapacity=1.0, usedResources=<memory:8192, vCores:7>usedCapacity=1.0, absoluteUsedCapacity=1.0, numApps=1, numContainers=7
2014-03-31 20:12:39,897 INFO org.apache.hadoop.yarn.server.resourcemanager.scheduler.capacity.ParentQueue: assignedContainer queue=root usedCapacity=1.0 absoluteUsedCapacity=1.0 used=<memory:8192, vCores:7> cluster=<memory:8192, vCores:8>
2014-03-31 20:12:40,129 INFO org.apache.hadoop.yarn.server.resourcemanager.rmcontainer.RMContainerImpl: container_1396321465238_0002_01_000024 Container Transitioned from ALLOCATED to ACQUIRED
2014-03-31 20:12:40,129 INFO org.apache.hadoop.yarn.server.resourcemanager.rmcontainer.RMContainerImpl: container_1396321465238_0002_01_000025 Container Transitioned from ALLOCATED to ACQUIRED
2014-03-31 20:12:40,567 INFO org.apache.hadoop.yarn.server.resourcemanager.rmcontainer.RMContainerImpl: container_1396321465238_0002_01_000024 Container Transitioned from ACQUIRED to RUNNING
2014-03-31 20:12:40,567 INFO org.apache.hadoop.yarn.server.resourcemanager.rmcontainer.RMContainerImpl: container_1396321465238_0002_01_000025 Container Transitioned from ACQUIRED to RUNNING
2014-03-31 20:12:40,567 INFO org.apache.hadoop.yarn.server.resourcemanager.rmcontainer.RMContainerImpl: container_1396321465238_0002_01_000020 Container Transitioned from RUNNING to COMPLETED
2014-03-31 20:12:40,567 INFO org.apache.hadoop.yarn.server.resourcemanager.scheduler.common.fica.FiCaSchedulerApp: Completed container: container_1396321465238_0002_01_000020 in state: COMPLETED event:FINISHED
2014-03-31 20:12:40,567 INFO org.apache.hadoop.yarn.server.resourcemanager.RMAuditLogger: USER=hduser	OPERATION=AM Released Container	TARGET=SchedulerApp	RESULT=SUCCESS	APPID=application_1396321465238_0002	CONTAINERID=container_1396321465238_0002_01_000020
2014-03-31 20:12:40,567 INFO org.apache.hadoop.yarn.server.resourcemanager.scheduler.common.fica.FiCaSchedulerNode: Released container container_1396321465238_0002_01_000020 of capacity <memory:1024, vCores:1> on host ubuntu:60709, which currently has 6 containers, <memory:7168, vCores:6> used and <memory:1024, vCores:2> available, release resources=true
2014-03-31 20:12:40,567 INFO org.apache.hadoop.yarn.server.resourcemanager.scheduler.capacity.LeafQueue: default used=<memory:7168, vCores:6> numContainers=6 user=hduser user-resources=<memory:7168, vCores:6>
2014-03-31 20:12:40,567 INFO org.apache.hadoop.yarn.server.resourcemanager.scheduler.capacity.LeafQueue: completedContainer container=Container: [ContainerId: container_1396321465238_0002_01_000020, NodeId: ubuntu:60709, NodeHttpAddress: ubuntu:8042, Resource: <memory:1024, vCores:1>, Priority: 10, Token: Token { kind: ContainerToken, service: 127.0.1.1:60709 }, ] resource=<memory:1024, vCores:1> queue=default: capacity=1.0, absoluteCapacity=1.0, usedResources=<memory:7168, vCores:6>usedCapacity=0.875, absoluteUsedCapacity=0.875, numApps=1, numContainers=6 usedCapacity=0.875 absoluteUsedCapacity=0.875 used=<memory:7168, vCores:6> cluster=<memory:8192, vCores:8>
2014-03-31 20:12:40,567 INFO org.apache.hadoop.yarn.server.resourcemanager.scheduler.capacity.ParentQueue: completedContainer queue=root usedCapacity=0.875 absoluteUsedCapacity=0.875 used=<memory:7168, vCores:6> cluster=<memory:8192, vCores:8>
2014-03-31 20:12:40,567 INFO org.apache.hadoop.yarn.server.resourcemanager.scheduler.capacity.ParentQueue: Re-sorting completed queue: root.default stats: default: capacity=1.0, absoluteCapacity=1.0, usedResources=<memory:7168, vCores:6>usedCapacity=0.875, absoluteUsedCapacity=0.875, numApps=1, numContainers=6
2014-03-31 20:12:40,567 INFO org.apache.hadoop.yarn.server.resourcemanager.scheduler.capacity.CapacityScheduler: Application appattempt_1396321465238_0002_000001 released container container_1396321465238_0002_01_000020 on node: host: ubuntu:60709 #containers=6 available=1024 used=7168 with event: FINISHED
2014-03-31 20:12:40,568 INFO org.apache.hadoop.yarn.server.resourcemanager.rmcontainer.RMContainerImpl: container_1396321465238_0002_01_000026 Container Transitioned from NEW to ALLOCATED
2014-03-31 20:12:40,568 INFO org.apache.hadoop.yarn.server.resourcemanager.RMAuditLogger: USER=hduser	OPERATION=AM Allocated Container	TARGET=SchedulerApp	RESULT=SUCCESS	APPID=application_1396321465238_0002	CONTAINERID=container_1396321465238_0002_01_000026
2014-03-31 20:12:40,568 INFO org.apache.hadoop.yarn.server.resourcemanager.scheduler.common.fica.FiCaSchedulerNode: Assigned container container_1396321465238_0002_01_000026 of capacity <memory:1024, vCores:1> on host ubuntu:60709, which currently has 7 containers, <memory:8192, vCores:7> used and <memory:0, vCores:1> available
2014-03-31 20:12:40,568 INFO org.apache.hadoop.yarn.server.resourcemanager.scheduler.capacity.LeafQueue: assignedContainer application=application_1396321465238_0002 container=Container: [ContainerId: container_1396321465238_0002_01_000026, NodeId: ubuntu:60709, NodeHttpAddress: ubuntu:8042, Resource: <memory:1024, vCores:1>, Priority: 10, Token: Token { kind: ContainerToken, service: 127.0.1.1:60709 }, ] containerId=container_1396321465238_0002_01_000026 queue=default: capacity=1.0, absoluteCapacity=1.0, usedResources=<memory:7168, vCores:6>usedCapacity=0.875, absoluteUsedCapacity=0.875, numApps=1, numContainers=6 usedCapacity=0.875 absoluteUsedCapacity=0.875 used=<memory:7168, vCores:6> cluster=<memory:8192, vCores:8>
2014-03-31 20:12:40,568 INFO org.apache.hadoop.yarn.server.resourcemanager.scheduler.capacity.ParentQueue: Re-sorting assigned queue: root.default stats: default: capacity=1.0, absoluteCapacity=1.0, usedResources=<memory:8192, vCores:7>usedCapacity=1.0, absoluteUsedCapacity=1.0, numApps=1, numContainers=7
2014-03-31 20:12:40,568 INFO org.apache.hadoop.yarn.server.resourcemanager.scheduler.capacity.ParentQueue: assignedContainer queue=root usedCapacity=1.0 absoluteUsedCapacity=1.0 used=<memory:8192, vCores:7> cluster=<memory:8192, vCores:8>
2014-03-31 20:12:41,137 INFO org.apache.hadoop.yarn.server.resourcemanager.rmcontainer.RMContainerImpl: container_1396321465238_0002_01_000026 Container Transitioned from ALLOCATED to ACQUIRED
2014-03-31 20:12:41,485 INFO org.apache.hadoop.yarn.server.resourcemanager.rmcontainer.RMContainerImpl: container_1396321465238_0002_01_000026 Container Transitioned from ACQUIRED to RUNNING
2014-03-31 20:12:41,485 INFO org.apache.hadoop.yarn.server.resourcemanager.rmcontainer.RMContainerImpl: container_1396321465238_0002_01_000021 Container Transitioned from RUNNING to COMPLETED
2014-03-31 20:12:41,485 INFO org.apache.hadoop.yarn.server.resourcemanager.scheduler.common.fica.FiCaSchedulerApp: Completed container: container_1396321465238_0002_01_000021 in state: COMPLETED event:FINISHED
2014-03-31 20:12:41,485 INFO org.apache.hadoop.yarn.server.resourcemanager.RMAuditLogger: USER=hduser	OPERATION=AM Released Container	TARGET=SchedulerApp	RESULT=SUCCESS	APPID=application_1396321465238_0002	CONTAINERID=container_1396321465238_0002_01_000021
2014-03-31 20:12:41,485 INFO org.apache.hadoop.yarn.server.resourcemanager.scheduler.common.fica.FiCaSchedulerNode: Released container container_1396321465238_0002_01_000021 of capacity <memory:1024, vCores:1> on host ubuntu:60709, which currently has 6 containers, <memory:7168, vCores:6> used and <memory:1024, vCores:2> available, release resources=true
2014-03-31 20:12:41,485 INFO org.apache.hadoop.yarn.server.resourcemanager.scheduler.capacity.LeafQueue: default used=<memory:7168, vCores:6> numContainers=6 user=hduser user-resources=<memory:7168, vCores:6>
2014-03-31 20:12:41,485 INFO org.apache.hadoop.yarn.server.resourcemanager.scheduler.capacity.LeafQueue: completedContainer container=Container: [ContainerId: container_1396321465238_0002_01_000021, NodeId: ubuntu:60709, NodeHttpAddress: ubuntu:8042, Resource: <memory:1024, vCores:1>, Priority: 10, Token: Token { kind: ContainerToken, service: 127.0.1.1:60709 }, ] resource=<memory:1024, vCores:1> queue=default: capacity=1.0, absoluteCapacity=1.0, usedResources=<memory:7168, vCores:6>usedCapacity=0.875, absoluteUsedCapacity=0.875, numApps=1, numContainers=6 usedCapacity=0.875 absoluteUsedCapacity=0.875 used=<memory:7168, vCores:6> cluster=<memory:8192, vCores:8>
2014-03-31 20:12:41,485 INFO org.apache.hadoop.yarn.server.resourcemanager.scheduler.capacity.ParentQueue: completedContainer queue=root usedCapacity=0.875 absoluteUsedCapacity=0.875 used=<memory:7168, vCores:6> cluster=<memory:8192, vCores:8>
2014-03-31 20:12:41,485 INFO org.apache.hadoop.yarn.server.resourcemanager.scheduler.capacity.ParentQueue: Re-sorting completed queue: root.default stats: default: capacity=1.0, absoluteCapacity=1.0, usedResources=<memory:7168, vCores:6>usedCapacity=0.875, absoluteUsedCapacity=0.875, numApps=1, numContainers=6
2014-03-31 20:12:41,485 INFO org.apache.hadoop.yarn.server.resourcemanager.scheduler.capacity.CapacityScheduler: Application appattempt_1396321465238_0002_000001 released container container_1396321465238_0002_01_000021 on node: host: ubuntu:60709 #containers=6 available=1024 used=7168 with event: FINISHED
2014-03-31 20:12:41,486 INFO org.apache.hadoop.yarn.server.resourcemanager.rmcontainer.RMContainerImpl: container_1396321465238_0002_01_000027 Container Transitioned from NEW to ALLOCATED
2014-03-31 20:12:41,486 INFO org.apache.hadoop.yarn.server.resourcemanager.RMAuditLogger: USER=hduser	OPERATION=AM Allocated Container	TARGET=SchedulerApp	RESULT=SUCCESS	APPID=application_1396321465238_0002	CONTAINERID=container_1396321465238_0002_01_000027
2014-03-31 20:12:41,486 INFO org.apache.hadoop.yarn.server.resourcemanager.scheduler.common.fica.FiCaSchedulerNode: Assigned container container_1396321465238_0002_01_000027 of capacity <memory:1024, vCores:1> on host ubuntu:60709, which currently has 7 containers, <memory:8192, vCores:7> used and <memory:0, vCores:1> available
2014-03-31 20:12:41,486 INFO org.apache.hadoop.yarn.server.resourcemanager.scheduler.capacity.LeafQueue: assignedContainer application=application_1396321465238_0002 container=Container: [ContainerId: container_1396321465238_0002_01_000027, NodeId: ubuntu:60709, NodeHttpAddress: ubuntu:8042, Resource: <memory:1024, vCores:1>, Priority: 10, Token: Token { kind: ContainerToken, service: 127.0.1.1:60709 }, ] containerId=container_1396321465238_0002_01_000027 queue=default: capacity=1.0, absoluteCapacity=1.0, usedResources=<memory:7168, vCores:6>usedCapacity=0.875, absoluteUsedCapacity=0.875, numApps=1, numContainers=6 usedCapacity=0.875 absoluteUsedCapacity=0.875 used=<memory:7168, vCores:6> cluster=<memory:8192, vCores:8>
2014-03-31 20:12:41,486 INFO org.apache.hadoop.yarn.server.resourcemanager.scheduler.capacity.ParentQueue: Re-sorting assigned queue: root.default stats: default: capacity=1.0, absoluteCapacity=1.0, usedResources=<memory:8192, vCores:7>usedCapacity=1.0, absoluteUsedCapacity=1.0, numApps=1, numContainers=7
2014-03-31 20:12:41,486 INFO org.apache.hadoop.yarn.server.resourcemanager.scheduler.capacity.ParentQueue: assignedContainer queue=root usedCapacity=1.0 absoluteUsedCapacity=1.0 used=<memory:8192, vCores:7> cluster=<memory:8192, vCores:8>
2014-03-31 20:12:42,151 INFO org.apache.hadoop.yarn.server.resourcemanager.rmcontainer.RMContainerImpl: container_1396321465238_0002_01_000027 Container Transitioned from ALLOCATED to ACQUIRED
2014-03-31 20:12:42,489 INFO org.apache.hadoop.yarn.server.resourcemanager.rmcontainer.RMContainerImpl: container_1396321465238_0002_01_000027 Container Transitioned from ACQUIRED to RUNNING
2014-03-31 20:12:42,490 INFO org.apache.hadoop.yarn.server.resourcemanager.rmcontainer.RMContainerImpl: container_1396321465238_0002_01_000022 Container Transitioned from RUNNING to COMPLETED
2014-03-31 20:12:42,490 INFO org.apache.hadoop.yarn.server.resourcemanager.scheduler.common.fica.FiCaSchedulerApp: Completed container: container_1396321465238_0002_01_000022 in state: COMPLETED event:FINISHED
2014-03-31 20:12:42,490 INFO org.apache.hadoop.yarn.server.resourcemanager.RMAuditLogger: USER=hduser	OPERATION=AM Released Container	TARGET=SchedulerApp	RESULT=SUCCESS	APPID=application_1396321465238_0002	CONTAINERID=container_1396321465238_0002_01_000022
2014-03-31 20:12:42,490 INFO org.apache.hadoop.yarn.server.resourcemanager.scheduler.common.fica.FiCaSchedulerNode: Released container container_1396321465238_0002_01_000022 of capacity <memory:1024, vCores:1> on host ubuntu:60709, which currently has 6 containers, <memory:7168, vCores:6> used and <memory:1024, vCores:2> available, release resources=true
2014-03-31 20:12:42,490 INFO org.apache.hadoop.yarn.server.resourcemanager.scheduler.capacity.LeafQueue: default used=<memory:7168, vCores:6> numContainers=6 user=hduser user-resources=<memory:7168, vCores:6>
2014-03-31 20:12:42,490 INFO org.apache.hadoop.yarn.server.resourcemanager.scheduler.capacity.LeafQueue: completedContainer container=Container: [ContainerId: container_1396321465238_0002_01_000022, NodeId: ubuntu:60709, NodeHttpAddress: ubuntu:8042, Resource: <memory:1024, vCores:1>, Priority: 10, Token: Token { kind: ContainerToken, service: 127.0.1.1:60709 }, ] resource=<memory:1024, vCores:1> queue=default: capacity=1.0, absoluteCapacity=1.0, usedResources=<memory:7168, vCores:6>usedCapacity=0.875, absoluteUsedCapacity=0.875, numApps=1, numContainers=6 usedCapacity=0.875 absoluteUsedCapacity=0.875 used=<memory:7168, vCores:6> cluster=<memory:8192, vCores:8>
2014-03-31 20:12:42,490 INFO org.apache.hadoop.yarn.server.resourcemanager.scheduler.capacity.ParentQueue: completedContainer queue=root usedCapacity=0.875 absoluteUsedCapacity=0.875 used=<memory:7168, vCores:6> cluster=<memory:8192, vCores:8>
2014-03-31 20:12:42,490 INFO org.apache.hadoop.yarn.server.resourcemanager.scheduler.capacity.ParentQueue: Re-sorting completed queue: root.default stats: default: capacity=1.0, absoluteCapacity=1.0, usedResources=<memory:7168, vCores:6>usedCapacity=0.875, absoluteUsedCapacity=0.875, numApps=1, numContainers=6
2014-03-31 20:12:42,490 INFO org.apache.hadoop.yarn.server.resourcemanager.scheduler.capacity.CapacityScheduler: Application appattempt_1396321465238_0002_000001 released container container_1396321465238_0002_01_000022 on node: host: ubuntu:60709 #containers=6 available=1024 used=7168 with event: FINISHED
2014-03-31 20:12:42,490 INFO org.apache.hadoop.yarn.server.resourcemanager.rmcontainer.RMContainerImpl: container_1396321465238_0002_01_000028 Container Transitioned from NEW to ALLOCATED
2014-03-31 20:12:42,490 INFO org.apache.hadoop.yarn.server.resourcemanager.RMAuditLogger: USER=hduser	OPERATION=AM Allocated Container	TARGET=SchedulerApp	RESULT=SUCCESS	APPID=application_1396321465238_0002	CONTAINERID=container_1396321465238_0002_01_000028
2014-03-31 20:12:42,490 INFO org.apache.hadoop.yarn.server.resourcemanager.scheduler.common.fica.FiCaSchedulerNode: Assigned container container_1396321465238_0002_01_000028 of capacity <memory:1024, vCores:1> on host ubuntu:60709, which currently has 7 containers, <memory:8192, vCores:7> used and <memory:0, vCores:1> available
2014-03-31 20:12:42,490 INFO org.apache.hadoop.yarn.server.resourcemanager.scheduler.capacity.LeafQueue: assignedContainer application=application_1396321465238_0002 container=Container: [ContainerId: container_1396321465238_0002_01_000028, NodeId: ubuntu:60709, NodeHttpAddress: ubuntu:8042, Resource: <memory:1024, vCores:1>, Priority: 10, Token: Token { kind: ContainerToken, service: 127.0.1.1:60709 }, ] containerId=container_1396321465238_0002_01_000028 queue=default: capacity=1.0, absoluteCapacity=1.0, usedResources=<memory:7168, vCores:6>usedCapacity=0.875, absoluteUsedCapacity=0.875, numApps=1, numContainers=6 usedCapacity=0.875 absoluteUsedCapacity=0.875 used=<memory:7168, vCores:6> cluster=<memory:8192, vCores:8>
2014-03-31 20:12:42,491 INFO org.apache.hadoop.yarn.server.resourcemanager.scheduler.capacity.ParentQueue: Re-sorting assigned queue: root.default stats: default: capacity=1.0, absoluteCapacity=1.0, usedResources=<memory:8192, vCores:7>usedCapacity=1.0, absoluteUsedCapacity=1.0, numApps=1, numContainers=7
2014-03-31 20:12:42,491 INFO org.apache.hadoop.yarn.server.resourcemanager.scheduler.capacity.ParentQueue: assignedContainer queue=root usedCapacity=1.0 absoluteUsedCapacity=1.0 used=<memory:8192, vCores:7> cluster=<memory:8192, vCores:8>
2014-03-31 20:12:43,167 INFO org.apache.hadoop.yarn.server.resourcemanager.rmcontainer.RMContainerImpl: container_1396321465238_0002_01_000028 Container Transitioned from ALLOCATED to ACQUIRED
2014-03-31 20:12:43,762 INFO org.apache.hadoop.yarn.server.resourcemanager.rmcontainer.RMContainerImpl: container_1396321465238_0002_01_000028 Container Transitioned from ACQUIRED to RUNNING
2014-03-31 20:12:43,762 INFO org.apache.hadoop.yarn.server.resourcemanager.rmcontainer.RMContainerImpl: container_1396321465238_0002_01_000023 Container Transitioned from RUNNING to COMPLETED
2014-03-31 20:12:43,762 INFO org.apache.hadoop.yarn.server.resourcemanager.scheduler.common.fica.FiCaSchedulerApp: Completed container: container_1396321465238_0002_01_000023 in state: COMPLETED event:FINISHED
2014-03-31 20:12:43,762 INFO org.apache.hadoop.yarn.server.resourcemanager.RMAuditLogger: USER=hduser	OPERATION=AM Released Container	TARGET=SchedulerApp	RESULT=SUCCESS	APPID=application_1396321465238_0002	CONTAINERID=container_1396321465238_0002_01_000023
2014-03-31 20:12:43,762 INFO org.apache.hadoop.yarn.server.resourcemanager.scheduler.common.fica.FiCaSchedulerNode: Released container container_1396321465238_0002_01_000023 of capacity <memory:1024, vCores:1> on host ubuntu:60709, which currently has 6 containers, <memory:7168, vCores:6> used and <memory:1024, vCores:2> available, release resources=true
2014-03-31 20:12:43,762 INFO org.apache.hadoop.yarn.server.resourcemanager.scheduler.capacity.LeafQueue: default used=<memory:7168, vCores:6> numContainers=6 user=hduser user-resources=<memory:7168, vCores:6>
2014-03-31 20:12:43,762 INFO org.apache.hadoop.yarn.server.resourcemanager.scheduler.capacity.LeafQueue: completedContainer container=Container: [ContainerId: container_1396321465238_0002_01_000023, NodeId: ubuntu:60709, NodeHttpAddress: ubuntu:8042, Resource: <memory:1024, vCores:1>, Priority: 10, Token: Token { kind: ContainerToken, service: 127.0.1.1:60709 }, ] resource=<memory:1024, vCores:1> queue=default: capacity=1.0, absoluteCapacity=1.0, usedResources=<memory:7168, vCores:6>usedCapacity=0.875, absoluteUsedCapacity=0.875, numApps=1, numContainers=6 usedCapacity=0.875 absoluteUsedCapacity=0.875 used=<memory:7168, vCores:6> cluster=<memory:8192, vCores:8>
2014-03-31 20:12:43,762 INFO org.apache.hadoop.yarn.server.resourcemanager.scheduler.capacity.ParentQueue: completedContainer queue=root usedCapacity=0.875 absoluteUsedCapacity=0.875 used=<memory:7168, vCores:6> cluster=<memory:8192, vCores:8>
2014-03-31 20:12:43,763 INFO org.apache.hadoop.yarn.server.resourcemanager.scheduler.capacity.ParentQueue: Re-sorting completed queue: root.default stats: default: capacity=1.0, absoluteCapacity=1.0, usedResources=<memory:7168, vCores:6>usedCapacity=0.875, absoluteUsedCapacity=0.875, numApps=1, numContainers=6
2014-03-31 20:12:43,763 INFO org.apache.hadoop.yarn.server.resourcemanager.scheduler.capacity.CapacityScheduler: Application appattempt_1396321465238_0002_000001 released container container_1396321465238_0002_01_000023 on node: host: ubuntu:60709 #containers=6 available=1024 used=7168 with event: FINISHED
2014-03-31 20:12:43,763 INFO org.apache.hadoop.yarn.server.resourcemanager.rmcontainer.RMContainerImpl: container_1396321465238_0002_01_000029 Container Transitioned from NEW to ALLOCATED
2014-03-31 20:12:43,763 INFO org.apache.hadoop.yarn.server.resourcemanager.RMAuditLogger: USER=hduser	OPERATION=AM Allocated Container	TARGET=SchedulerApp	RESULT=SUCCESS	APPID=application_1396321465238_0002	CONTAINERID=container_1396321465238_0002_01_000029
2014-03-31 20:12:43,763 INFO org.apache.hadoop.yarn.server.resourcemanager.scheduler.common.fica.FiCaSchedulerNode: Assigned container container_1396321465238_0002_01_000029 of capacity <memory:1024, vCores:1> on host ubuntu:60709, which currently has 7 containers, <memory:8192, vCores:7> used and <memory:0, vCores:1> available
2014-03-31 20:12:43,763 INFO org.apache.hadoop.yarn.server.resourcemanager.scheduler.capacity.LeafQueue: assignedContainer application=application_1396321465238_0002 container=Container: [ContainerId: container_1396321465238_0002_01_000029, NodeId: ubuntu:60709, NodeHttpAddress: ubuntu:8042, Resource: <memory:1024, vCores:1>, Priority: 10, Token: Token { kind: ContainerToken, service: 127.0.1.1:60709 }, ] containerId=container_1396321465238_0002_01_000029 queue=default: capacity=1.0, absoluteCapacity=1.0, usedResources=<memory:7168, vCores:6>usedCapacity=0.875, absoluteUsedCapacity=0.875, numApps=1, numContainers=6 usedCapacity=0.875 absoluteUsedCapacity=0.875 used=<memory:7168, vCores:6> cluster=<memory:8192, vCores:8>
2014-03-31 20:12:43,763 INFO org.apache.hadoop.yarn.server.resourcemanager.scheduler.capacity.ParentQueue: Re-sorting assigned queue: root.default stats: default: capacity=1.0, absoluteCapacity=1.0, usedResources=<memory:8192, vCores:7>usedCapacity=1.0, absoluteUsedCapacity=1.0, numApps=1, numContainers=7
2014-03-31 20:12:43,764 INFO org.apache.hadoop.yarn.server.resourcemanager.scheduler.capacity.ParentQueue: assignedContainer queue=root usedCapacity=1.0 absoluteUsedCapacity=1.0 used=<memory:8192, vCores:7> cluster=<memory:8192, vCores:8>
2014-03-31 20:12:44,177 INFO org.apache.hadoop.yarn.server.resourcemanager.rmcontainer.RMContainerImpl: container_1396321465238_0002_01_000029 Container Transitioned from ALLOCATED to ACQUIRED
2014-03-31 20:12:44,765 INFO org.apache.hadoop.yarn.server.resourcemanager.rmcontainer.RMContainerImpl: container_1396321465238_0002_01_000029 Container Transitioned from ACQUIRED to RUNNING
2014-03-31 20:12:45,413 INFO org.apache.hadoop.yarn.server.resourcemanager.rmcontainer.RMContainerImpl: container_1396321465238_0002_01_000024 Container Transitioned from RUNNING to COMPLETED
2014-03-31 20:12:45,413 INFO org.apache.hadoop.yarn.server.resourcemanager.scheduler.common.fica.FiCaSchedulerApp: Completed container: container_1396321465238_0002_01_000024 in state: COMPLETED event:FINISHED
2014-03-31 20:12:45,413 INFO org.apache.hadoop.yarn.server.resourcemanager.RMAuditLogger: USER=hduser	OPERATION=AM Released Container	TARGET=SchedulerApp	RESULT=SUCCESS	APPID=application_1396321465238_0002	CONTAINERID=container_1396321465238_0002_01_000024
2014-03-31 20:12:45,413 INFO org.apache.hadoop.yarn.server.resourcemanager.scheduler.common.fica.FiCaSchedulerNode: Released container container_1396321465238_0002_01_000024 of capacity <memory:1024, vCores:1> on host ubuntu:60709, which currently has 6 containers, <memory:7168, vCores:6> used and <memory:1024, vCores:2> available, release resources=true
2014-03-31 20:12:45,413 INFO org.apache.hadoop.yarn.server.resourcemanager.scheduler.capacity.LeafQueue: default used=<memory:7168, vCores:6> numContainers=6 user=hduser user-resources=<memory:7168, vCores:6>
2014-03-31 20:12:45,414 INFO org.apache.hadoop.yarn.server.resourcemanager.scheduler.capacity.LeafQueue: completedContainer container=Container: [ContainerId: container_1396321465238_0002_01_000024, NodeId: ubuntu:60709, NodeHttpAddress: ubuntu:8042, Resource: <memory:1024, vCores:1>, Priority: 10, Token: Token { kind: ContainerToken, service: 127.0.1.1:60709 }, ] resource=<memory:1024, vCores:1> queue=default: capacity=1.0, absoluteCapacity=1.0, usedResources=<memory:7168, vCores:6>usedCapacity=0.875, absoluteUsedCapacity=0.875, numApps=1, numContainers=6 usedCapacity=0.875 absoluteUsedCapacity=0.875 used=<memory:7168, vCores:6> cluster=<memory:8192, vCores:8>
2014-03-31 20:12:45,414 INFO org.apache.hadoop.yarn.server.resourcemanager.scheduler.capacity.ParentQueue: completedContainer queue=root usedCapacity=0.875 absoluteUsedCapacity=0.875 used=<memory:7168, vCores:6> cluster=<memory:8192, vCores:8>
2014-03-31 20:12:45,414 INFO org.apache.hadoop.yarn.server.resourcemanager.scheduler.capacity.ParentQueue: Re-sorting completed queue: root.default stats: default: capacity=1.0, absoluteCapacity=1.0, usedResources=<memory:7168, vCores:6>usedCapacity=0.875, absoluteUsedCapacity=0.875, numApps=1, numContainers=6
2014-03-31 20:12:45,414 INFO org.apache.hadoop.yarn.server.resourcemanager.scheduler.capacity.CapacityScheduler: Application appattempt_1396321465238_0002_000001 released container container_1396321465238_0002_01_000024 on node: host: ubuntu:60709 #containers=6 available=1024 used=7168 with event: FINISHED
2014-03-31 20:12:45,414 INFO org.apache.hadoop.yarn.server.resourcemanager.rmcontainer.RMContainerImpl: container_1396321465238_0002_01_000030 Container Transitioned from NEW to ALLOCATED
2014-03-31 20:12:45,414 INFO org.apache.hadoop.yarn.server.resourcemanager.RMAuditLogger: USER=hduser	OPERATION=AM Allocated Container	TARGET=SchedulerApp	RESULT=SUCCESS	APPID=application_1396321465238_0002	CONTAINERID=container_1396321465238_0002_01_000030
2014-03-31 20:12:45,414 INFO org.apache.hadoop.yarn.server.resourcemanager.scheduler.common.fica.FiCaSchedulerNode: Assigned container container_1396321465238_0002_01_000030 of capacity <memory:1024, vCores:1> on host ubuntu:60709, which currently has 7 containers, <memory:8192, vCores:7> used and <memory:0, vCores:1> available
2014-03-31 20:12:45,414 INFO org.apache.hadoop.yarn.server.resourcemanager.scheduler.capacity.LeafQueue: assignedContainer application=application_1396321465238_0002 container=Container: [ContainerId: container_1396321465238_0002_01_000030, NodeId: ubuntu:60709, NodeHttpAddress: ubuntu:8042, Resource: <memory:1024, vCores:1>, Priority: 10, Token: Token { kind: ContainerToken, service: 127.0.1.1:60709 }, ] containerId=container_1396321465238_0002_01_000030 queue=default: capacity=1.0, absoluteCapacity=1.0, usedResources=<memory:7168, vCores:6>usedCapacity=0.875, absoluteUsedCapacity=0.875, numApps=1, numContainers=6 usedCapacity=0.875 absoluteUsedCapacity=0.875 used=<memory:7168, vCores:6> cluster=<memory:8192, vCores:8>
2014-03-31 20:12:45,414 INFO org.apache.hadoop.yarn.server.resourcemanager.scheduler.capacity.ParentQueue: Re-sorting assigned queue: root.default stats: default: capacity=1.0, absoluteCapacity=1.0, usedResources=<memory:8192, vCores:7>usedCapacity=1.0, absoluteUsedCapacity=1.0, numApps=1, numContainers=7
2014-03-31 20:12:45,414 INFO org.apache.hadoop.yarn.server.resourcemanager.scheduler.capacity.ParentQueue: assignedContainer queue=root usedCapacity=1.0 absoluteUsedCapacity=1.0 used=<memory:8192, vCores:7> cluster=<memory:8192, vCores:8>
2014-03-31 20:12:46,186 INFO org.apache.hadoop.yarn.server.resourcemanager.rmcontainer.RMContainerImpl: container_1396321465238_0002_01_000030 Container Transitioned from ALLOCATED to ACQUIRED
2014-03-31 20:12:46,189 INFO org.apache.hadoop.yarn.server.resourcemanager.rmcontainer.RMContainerImpl: container_1396321465238_0002_01_000025 Container Transitioned from RUNNING to COMPLETED
2014-03-31 20:12:46,189 INFO org.apache.hadoop.yarn.server.resourcemanager.scheduler.common.fica.FiCaSchedulerApp: Completed container: container_1396321465238_0002_01_000025 in state: COMPLETED event:FINISHED
2014-03-31 20:12:46,189 INFO org.apache.hadoop.yarn.server.resourcemanager.RMAuditLogger: USER=hduser	OPERATION=AM Released Container	TARGET=SchedulerApp	RESULT=SUCCESS	APPID=application_1396321465238_0002	CONTAINERID=container_1396321465238_0002_01_000025
2014-03-31 20:12:46,189 INFO org.apache.hadoop.yarn.server.resourcemanager.scheduler.common.fica.FiCaSchedulerNode: Released container container_1396321465238_0002_01_000025 of capacity <memory:1024, vCores:1> on host ubuntu:60709, which currently has 6 containers, <memory:7168, vCores:6> used and <memory:1024, vCores:2> available, release resources=true
2014-03-31 20:12:46,189 INFO org.apache.hadoop.yarn.server.resourcemanager.scheduler.capacity.LeafQueue: default used=<memory:7168, vCores:6> numContainers=6 user=hduser user-resources=<memory:7168, vCores:6>
2014-03-31 20:12:46,189 INFO org.apache.hadoop.yarn.server.resourcemanager.scheduler.capacity.LeafQueue: completedContainer container=Container: [ContainerId: container_1396321465238_0002_01_000025, NodeId: ubuntu:60709, NodeHttpAddress: ubuntu:8042, Resource: <memory:1024, vCores:1>, Priority: 10, Token: Token { kind: ContainerToken, service: 127.0.1.1:60709 }, ] resource=<memory:1024, vCores:1> queue=default: capacity=1.0, absoluteCapacity=1.0, usedResources=<memory:7168, vCores:6>usedCapacity=0.875, absoluteUsedCapacity=0.875, numApps=1, numContainers=6 usedCapacity=0.875 absoluteUsedCapacity=0.875 used=<memory:7168, vCores:6> cluster=<memory:8192, vCores:8>
2014-03-31 20:12:46,189 INFO org.apache.hadoop.yarn.server.resourcemanager.scheduler.capacity.ParentQueue: completedContainer queue=root usedCapacity=0.875 absoluteUsedCapacity=0.875 used=<memory:7168, vCores:6> cluster=<memory:8192, vCores:8>
2014-03-31 20:12:46,189 INFO org.apache.hadoop.yarn.server.resourcemanager.scheduler.capacity.ParentQueue: Re-sorting completed queue: root.default stats: default: capacity=1.0, absoluteCapacity=1.0, usedResources=<memory:7168, vCores:6>usedCapacity=0.875, absoluteUsedCapacity=0.875, numApps=1, numContainers=6
2014-03-31 20:12:46,189 INFO org.apache.hadoop.yarn.server.resourcemanager.scheduler.capacity.CapacityScheduler: Application appattempt_1396321465238_0002_000001 released container container_1396321465238_0002_01_000025 on node: host: ubuntu:60709 #containers=6 available=1024 used=7168 with event: FINISHED
2014-03-31 20:12:46,189 INFO org.apache.hadoop.yarn.server.resourcemanager.rmcontainer.RMContainerImpl: container_1396321465238_0002_01_000031 Container Transitioned from NEW to ALLOCATED
2014-03-31 20:12:46,189 INFO org.apache.hadoop.yarn.server.resourcemanager.RMAuditLogger: USER=hduser	OPERATION=AM Allocated Container	TARGET=SchedulerApp	RESULT=SUCCESS	APPID=application_1396321465238_0002	CONTAINERID=container_1396321465238_0002_01_000031
2014-03-31 20:12:46,189 INFO org.apache.hadoop.yarn.server.resourcemanager.scheduler.common.fica.FiCaSchedulerNode: Assigned container container_1396321465238_0002_01_000031 of capacity <memory:1024, vCores:1> on host ubuntu:60709, which currently has 7 containers, <memory:8192, vCores:7> used and <memory:0, vCores:1> available
2014-03-31 20:12:46,190 INFO org.apache.hadoop.yarn.server.resourcemanager.scheduler.capacity.LeafQueue: assignedContainer application=application_1396321465238_0002 container=Container: [ContainerId: container_1396321465238_0002_01_000031, NodeId: ubuntu:60709, NodeHttpAddress: ubuntu:8042, Resource: <memory:1024, vCores:1>, Priority: 10, Token: Token { kind: ContainerToken, service: 127.0.1.1:60709 }, ] containerId=container_1396321465238_0002_01_000031 queue=default: capacity=1.0, absoluteCapacity=1.0, usedResources=<memory:7168, vCores:6>usedCapacity=0.875, absoluteUsedCapacity=0.875, numApps=1, numContainers=6 usedCapacity=0.875 absoluteUsedCapacity=0.875 used=<memory:7168, vCores:6> cluster=<memory:8192, vCores:8>
2014-03-31 20:12:46,190 INFO org.apache.hadoop.yarn.server.resourcemanager.scheduler.capacity.ParentQueue: Re-sorting assigned queue: root.default stats: default: capacity=1.0, absoluteCapacity=1.0, usedResources=<memory:8192, vCores:7>usedCapacity=1.0, absoluteUsedCapacity=1.0, numApps=1, numContainers=7
2014-03-31 20:12:46,190 INFO org.apache.hadoop.yarn.server.resourcemanager.scheduler.capacity.ParentQueue: assignedContainer queue=root usedCapacity=1.0 absoluteUsedCapacity=1.0 used=<memory:8192, vCores:7> cluster=<memory:8192, vCores:8>
2014-03-31 20:12:46,838 INFO org.apache.hadoop.yarn.server.resourcemanager.rmcontainer.RMContainerImpl: container_1396321465238_0002_01_000030 Container Transitioned from ACQUIRED to RUNNING
2014-03-31 20:12:46,838 INFO org.apache.hadoop.yarn.server.resourcemanager.rmcontainer.RMContainerImpl: container_1396321465238_0002_01_000026 Container Transitioned from RUNNING to COMPLETED
2014-03-31 20:12:46,838 INFO org.apache.hadoop.yarn.server.resourcemanager.scheduler.common.fica.FiCaSchedulerApp: Completed container: container_1396321465238_0002_01_000026 in state: COMPLETED event:FINISHED
2014-03-31 20:12:46,838 INFO org.apache.hadoop.yarn.server.resourcemanager.RMAuditLogger: USER=hduser	OPERATION=AM Released Container	TARGET=SchedulerApp	RESULT=SUCCESS	APPID=application_1396321465238_0002	CONTAINERID=container_1396321465238_0002_01_000026
2014-03-31 20:12:46,838 INFO org.apache.hadoop.yarn.server.resourcemanager.scheduler.common.fica.FiCaSchedulerNode: Released container container_1396321465238_0002_01_000026 of capacity <memory:1024, vCores:1> on host ubuntu:60709, which currently has 6 containers, <memory:7168, vCores:6> used and <memory:1024, vCores:2> available, release resources=true
2014-03-31 20:12:46,838 INFO org.apache.hadoop.yarn.server.resourcemanager.scheduler.capacity.LeafQueue: default used=<memory:7168, vCores:6> numContainers=6 user=hduser user-resources=<memory:7168, vCores:6>
2014-03-31 20:12:46,838 INFO org.apache.hadoop.yarn.server.resourcemanager.scheduler.capacity.LeafQueue: completedContainer container=Container: [ContainerId: container_1396321465238_0002_01_000026, NodeId: ubuntu:60709, NodeHttpAddress: ubuntu:8042, Resource: <memory:1024, vCores:1>, Priority: 10, Token: Token { kind: ContainerToken, service: 127.0.1.1:60709 }, ] resource=<memory:1024, vCores:1> queue=default: capacity=1.0, absoluteCapacity=1.0, usedResources=<memory:7168, vCores:6>usedCapacity=0.875, absoluteUsedCapacity=0.875, numApps=1, numContainers=6 usedCapacity=0.875 absoluteUsedCapacity=0.875 used=<memory:7168, vCores:6> cluster=<memory:8192, vCores:8>
2014-03-31 20:12:46,838 INFO org.apache.hadoop.yarn.server.resourcemanager.scheduler.capacity.ParentQueue: completedContainer queue=root usedCapacity=0.875 absoluteUsedCapacity=0.875 used=<memory:7168, vCores:6> cluster=<memory:8192, vCores:8>
2014-03-31 20:12:46,838 INFO org.apache.hadoop.yarn.server.resourcemanager.scheduler.capacity.ParentQueue: Re-sorting completed queue: root.default stats: default: capacity=1.0, absoluteCapacity=1.0, usedResources=<memory:7168, vCores:6>usedCapacity=0.875, absoluteUsedCapacity=0.875, numApps=1, numContainers=6
2014-03-31 20:12:46,839 INFO org.apache.hadoop.yarn.server.resourcemanager.scheduler.capacity.CapacityScheduler: Application appattempt_1396321465238_0002_000001 released container container_1396321465238_0002_01_000026 on node: host: ubuntu:60709 #containers=6 available=1024 used=7168 with event: FINISHED
2014-03-31 20:12:46,839 INFO org.apache.hadoop.yarn.server.resourcemanager.rmcontainer.RMContainerImpl: container_1396321465238_0002_01_000032 Container Transitioned from NEW to ALLOCATED
2014-03-31 20:12:46,839 INFO org.apache.hadoop.yarn.server.resourcemanager.RMAuditLogger: USER=hduser	OPERATION=AM Allocated Container	TARGET=SchedulerApp	RESULT=SUCCESS	APPID=application_1396321465238_0002	CONTAINERID=container_1396321465238_0002_01_000032
2014-03-31 20:12:46,839 INFO org.apache.hadoop.yarn.server.resourcemanager.scheduler.common.fica.FiCaSchedulerNode: Assigned container container_1396321465238_0002_01_000032 of capacity <memory:1024, vCores:1> on host ubuntu:60709, which currently has 7 containers, <memory:8192, vCores:7> used and <memory:0, vCores:1> available
2014-03-31 20:12:46,839 INFO org.apache.hadoop.yarn.server.resourcemanager.scheduler.capacity.LeafQueue: assignedContainer application=application_1396321465238_0002 container=Container: [ContainerId: container_1396321465238_0002_01_000032, NodeId: ubuntu:60709, NodeHttpAddress: ubuntu:8042, Resource: <memory:1024, vCores:1>, Priority: 10, Token: Token { kind: ContainerToken, service: 127.0.1.1:60709 }, ] containerId=container_1396321465238_0002_01_000032 queue=default: capacity=1.0, absoluteCapacity=1.0, usedResources=<memory:7168, vCores:6>usedCapacity=0.875, absoluteUsedCapacity=0.875, numApps=1, numContainers=6 usedCapacity=0.875 absoluteUsedCapacity=0.875 used=<memory:7168, vCores:6> cluster=<memory:8192, vCores:8>
2014-03-31 20:12:46,839 INFO org.apache.hadoop.yarn.server.resourcemanager.scheduler.capacity.ParentQueue: Re-sorting assigned queue: root.default stats: default: capacity=1.0, absoluteCapacity=1.0, usedResources=<memory:8192, vCores:7>usedCapacity=1.0, absoluteUsedCapacity=1.0, numApps=1, numContainers=7
2014-03-31 20:12:46,839 INFO org.apache.hadoop.yarn.server.resourcemanager.scheduler.capacity.ParentQueue: assignedContainer queue=root usedCapacity=1.0 absoluteUsedCapacity=1.0 used=<memory:8192, vCores:7> cluster=<memory:8192, vCores:8>
2014-03-31 20:12:47,200 INFO org.apache.hadoop.yarn.server.resourcemanager.rmcontainer.RMContainerImpl: container_1396321465238_0002_01_000031 Container Transitioned from ALLOCATED to ACQUIRED
2014-03-31 20:12:47,200 INFO org.apache.hadoop.yarn.server.resourcemanager.rmcontainer.RMContainerImpl: container_1396321465238_0002_01_000032 Container Transitioned from ALLOCATED to ACQUIRED
2014-03-31 20:12:47,485 INFO org.apache.hadoop.yarn.server.resourcemanager.rmcontainer.RMContainerImpl: container_1396321465238_0002_01_000031 Container Transitioned from ACQUIRED to RUNNING
2014-03-31 20:12:47,485 INFO org.apache.hadoop.yarn.server.resourcemanager.rmcontainer.RMContainerImpl: container_1396321465238_0002_01_000032 Container Transitioned from ACQUIRED to RUNNING
2014-03-31 20:12:47,485 INFO org.apache.hadoop.yarn.server.resourcemanager.rmcontainer.RMContainerImpl: container_1396321465238_0002_01_000027 Container Transitioned from RUNNING to COMPLETED
2014-03-31 20:12:47,485 INFO org.apache.hadoop.yarn.server.resourcemanager.scheduler.common.fica.FiCaSchedulerApp: Completed container: container_1396321465238_0002_01_000027 in state: COMPLETED event:FINISHED
2014-03-31 20:12:47,485 INFO org.apache.hadoop.yarn.server.resourcemanager.RMAuditLogger: USER=hduser	OPERATION=AM Released Container	TARGET=SchedulerApp	RESULT=SUCCESS	APPID=application_1396321465238_0002	CONTAINERID=container_1396321465238_0002_01_000027
2014-03-31 20:12:47,485 INFO org.apache.hadoop.yarn.server.resourcemanager.scheduler.common.fica.FiCaSchedulerNode: Released container container_1396321465238_0002_01_000027 of capacity <memory:1024, vCores:1> on host ubuntu:60709, which currently has 6 containers, <memory:7168, vCores:6> used and <memory:1024, vCores:2> available, release resources=true
2014-03-31 20:12:47,485 INFO org.apache.hadoop.yarn.server.resourcemanager.scheduler.capacity.LeafQueue: default used=<memory:7168, vCores:6> numContainers=6 user=hduser user-resources=<memory:7168, vCores:6>
2014-03-31 20:12:47,485 INFO org.apache.hadoop.yarn.server.resourcemanager.scheduler.capacity.LeafQueue: completedContainer container=Container: [ContainerId: container_1396321465238_0002_01_000027, NodeId: ubuntu:60709, NodeHttpAddress: ubuntu:8042, Resource: <memory:1024, vCores:1>, Priority: 10, Token: Token { kind: ContainerToken, service: 127.0.1.1:60709 }, ] resource=<memory:1024, vCores:1> queue=default: capacity=1.0, absoluteCapacity=1.0, usedResources=<memory:7168, vCores:6>usedCapacity=0.875, absoluteUsedCapacity=0.875, numApps=1, numContainers=6 usedCapacity=0.875 absoluteUsedCapacity=0.875 used=<memory:7168, vCores:6> cluster=<memory:8192, vCores:8>
2014-03-31 20:12:47,485 INFO org.apache.hadoop.yarn.server.resourcemanager.scheduler.capacity.ParentQueue: completedContainer queue=root usedCapacity=0.875 absoluteUsedCapacity=0.875 used=<memory:7168, vCores:6> cluster=<memory:8192, vCores:8>
2014-03-31 20:12:47,485 INFO org.apache.hadoop.yarn.server.resourcemanager.scheduler.capacity.ParentQueue: Re-sorting completed queue: root.default stats: default: capacity=1.0, absoluteCapacity=1.0, usedResources=<memory:7168, vCores:6>usedCapacity=0.875, absoluteUsedCapacity=0.875, numApps=1, numContainers=6
2014-03-31 20:12:47,486 INFO org.apache.hadoop.yarn.server.resourcemanager.scheduler.capacity.CapacityScheduler: Application appattempt_1396321465238_0002_000001 released container container_1396321465238_0002_01_000027 on node: host: ubuntu:60709 #containers=6 available=1024 used=7168 with event: FINISHED
2014-03-31 20:12:47,486 INFO org.apache.hadoop.yarn.server.resourcemanager.rmcontainer.RMContainerImpl: container_1396321465238_0002_01_000033 Container Transitioned from NEW to ALLOCATED
2014-03-31 20:12:47,486 INFO org.apache.hadoop.yarn.server.resourcemanager.RMAuditLogger: USER=hduser	OPERATION=AM Allocated Container	TARGET=SchedulerApp	RESULT=SUCCESS	APPID=application_1396321465238_0002	CONTAINERID=container_1396321465238_0002_01_000033
2014-03-31 20:12:47,486 INFO org.apache.hadoop.yarn.server.resourcemanager.scheduler.common.fica.FiCaSchedulerNode: Assigned container container_1396321465238_0002_01_000033 of capacity <memory:1024, vCores:1> on host ubuntu:60709, which currently has 7 containers, <memory:8192, vCores:7> used and <memory:0, vCores:1> available
2014-03-31 20:12:47,486 INFO org.apache.hadoop.yarn.server.resourcemanager.scheduler.capacity.LeafQueue: assignedContainer application=application_1396321465238_0002 container=Container: [ContainerId: container_1396321465238_0002_01_000033, NodeId: ubuntu:60709, NodeHttpAddress: ubuntu:8042, Resource: <memory:1024, vCores:1>, Priority: 10, Token: Token { kind: ContainerToken, service: 127.0.1.1:60709 }, ] containerId=container_1396321465238_0002_01_000033 queue=default: capacity=1.0, absoluteCapacity=1.0, usedResources=<memory:7168, vCores:6>usedCapacity=0.875, absoluteUsedCapacity=0.875, numApps=1, numContainers=6 usedCapacity=0.875 absoluteUsedCapacity=0.875 used=<memory:7168, vCores:6> cluster=<memory:8192, vCores:8>
2014-03-31 20:12:47,486 INFO org.apache.hadoop.yarn.server.resourcemanager.scheduler.capacity.ParentQueue: Re-sorting assigned queue: root.default stats: default: capacity=1.0, absoluteCapacity=1.0, usedResources=<memory:8192, vCores:7>usedCapacity=1.0, absoluteUsedCapacity=1.0, numApps=1, numContainers=7
2014-03-31 20:12:47,486 INFO org.apache.hadoop.yarn.server.resourcemanager.scheduler.capacity.ParentQueue: assignedContainer queue=root usedCapacity=1.0 absoluteUsedCapacity=1.0 used=<memory:8192, vCores:7> cluster=<memory:8192, vCores:8>
2014-03-31 20:12:48,204 INFO org.apache.hadoop.yarn.server.resourcemanager.rmcontainer.RMContainerImpl: container_1396321465238_0002_01_000033 Container Transitioned from ALLOCATED to ACQUIRED
2014-03-31 20:12:48,489 INFO org.apache.hadoop.yarn.server.resourcemanager.rmcontainer.RMContainerImpl: container_1396321465238_0002_01_000033 Container Transitioned from ACQUIRED to RUNNING
2014-03-31 20:12:48,489 INFO org.apache.hadoop.yarn.server.resourcemanager.rmcontainer.RMContainerImpl: container_1396321465238_0002_01_000028 Container Transitioned from RUNNING to COMPLETED
2014-03-31 20:12:48,489 INFO org.apache.hadoop.yarn.server.resourcemanager.scheduler.common.fica.FiCaSchedulerApp: Completed container: container_1396321465238_0002_01_000028 in state: COMPLETED event:FINISHED
2014-03-31 20:12:48,489 INFO org.apache.hadoop.yarn.server.resourcemanager.RMAuditLogger: USER=hduser	OPERATION=AM Released Container	TARGET=SchedulerApp	RESULT=SUCCESS	APPID=application_1396321465238_0002	CONTAINERID=container_1396321465238_0002_01_000028
2014-03-31 20:12:48,489 INFO org.apache.hadoop.yarn.server.resourcemanager.scheduler.common.fica.FiCaSchedulerNode: Released container container_1396321465238_0002_01_000028 of capacity <memory:1024, vCores:1> on host ubuntu:60709, which currently has 6 containers, <memory:7168, vCores:6> used and <memory:1024, vCores:2> available, release resources=true
2014-03-31 20:12:48,489 INFO org.apache.hadoop.yarn.server.resourcemanager.scheduler.capacity.LeafQueue: default used=<memory:7168, vCores:6> numContainers=6 user=hduser user-resources=<memory:7168, vCores:6>
2014-03-31 20:12:48,489 INFO org.apache.hadoop.yarn.server.resourcemanager.scheduler.capacity.LeafQueue: completedContainer container=Container: [ContainerId: container_1396321465238_0002_01_000028, NodeId: ubuntu:60709, NodeHttpAddress: ubuntu:8042, Resource: <memory:1024, vCores:1>, Priority: 10, Token: Token { kind: ContainerToken, service: 127.0.1.1:60709 }, ] resource=<memory:1024, vCores:1> queue=default: capacity=1.0, absoluteCapacity=1.0, usedResources=<memory:7168, vCores:6>usedCapacity=0.875, absoluteUsedCapacity=0.875, numApps=1, numContainers=6 usedCapacity=0.875 absoluteUsedCapacity=0.875 used=<memory:7168, vCores:6> cluster=<memory:8192, vCores:8>
2014-03-31 20:12:48,489 INFO org.apache.hadoop.yarn.server.resourcemanager.scheduler.capacity.ParentQueue: completedContainer queue=root usedCapacity=0.875 absoluteUsedCapacity=0.875 used=<memory:7168, vCores:6> cluster=<memory:8192, vCores:8>
2014-03-31 20:12:48,489 INFO org.apache.hadoop.yarn.server.resourcemanager.scheduler.capacity.ParentQueue: Re-sorting completed queue: root.default stats: default: capacity=1.0, absoluteCapacity=1.0, usedResources=<memory:7168, vCores:6>usedCapacity=0.875, absoluteUsedCapacity=0.875, numApps=1, numContainers=6
2014-03-31 20:12:48,489 INFO org.apache.hadoop.yarn.server.resourcemanager.scheduler.capacity.CapacityScheduler: Application appattempt_1396321465238_0002_000001 released container container_1396321465238_0002_01_000028 on node: host: ubuntu:60709 #containers=6 available=1024 used=7168 with event: FINISHED
2014-03-31 20:12:48,490 INFO org.apache.hadoop.yarn.server.resourcemanager.rmcontainer.RMContainerImpl: container_1396321465238_0002_01_000034 Container Transitioned from NEW to ALLOCATED
2014-03-31 20:12:48,490 INFO org.apache.hadoop.yarn.server.resourcemanager.RMAuditLogger: USER=hduser	OPERATION=AM Allocated Container	TARGET=SchedulerApp	RESULT=SUCCESS	APPID=application_1396321465238_0002	CONTAINERID=container_1396321465238_0002_01_000034
2014-03-31 20:12:48,490 INFO org.apache.hadoop.yarn.server.resourcemanager.scheduler.common.fica.FiCaSchedulerNode: Assigned container container_1396321465238_0002_01_000034 of capacity <memory:1024, vCores:1> on host ubuntu:60709, which currently has 7 containers, <memory:8192, vCores:7> used and <memory:0, vCores:1> available
2014-03-31 20:12:48,490 INFO org.apache.hadoop.yarn.server.resourcemanager.scheduler.capacity.LeafQueue: assignedContainer application=application_1396321465238_0002 container=Container: [ContainerId: container_1396321465238_0002_01_000034, NodeId: ubuntu:60709, NodeHttpAddress: ubuntu:8042, Resource: <memory:1024, vCores:1>, Priority: 10, Token: Token { kind: ContainerToken, service: 127.0.1.1:60709 }, ] containerId=container_1396321465238_0002_01_000034 queue=default: capacity=1.0, absoluteCapacity=1.0, usedResources=<memory:7168, vCores:6>usedCapacity=0.875, absoluteUsedCapacity=0.875, numApps=1, numContainers=6 usedCapacity=0.875 absoluteUsedCapacity=0.875 used=<memory:7168, vCores:6> cluster=<memory:8192, vCores:8>
2014-03-31 20:12:48,490 INFO org.apache.hadoop.yarn.server.resourcemanager.scheduler.capacity.ParentQueue: Re-sorting assigned queue: root.default stats: default: capacity=1.0, absoluteCapacity=1.0, usedResources=<memory:8192, vCores:7>usedCapacity=1.0, absoluteUsedCapacity=1.0, numApps=1, numContainers=7
2014-03-31 20:12:48,490 INFO org.apache.hadoop.yarn.server.resourcemanager.scheduler.capacity.ParentQueue: assignedContainer queue=root usedCapacity=1.0 absoluteUsedCapacity=1.0 used=<memory:8192, vCores:7> cluster=<memory:8192, vCores:8>
2014-03-31 20:12:49,213 INFO org.apache.hadoop.yarn.server.resourcemanager.rmcontainer.RMContainerImpl: container_1396321465238_0002_01_000034 Container Transitioned from ALLOCATED to ACQUIRED
2014-03-31 20:12:50,120 INFO org.apache.hadoop.yarn.server.resourcemanager.rmcontainer.RMContainerImpl: container_1396321465238_0002_01_000034 Container Transitioned from ACQUIRED to RUNNING
2014-03-31 20:12:50,120 INFO org.apache.hadoop.yarn.server.resourcemanager.rmcontainer.RMContainerImpl: container_1396321465238_0002_01_000029 Container Transitioned from RUNNING to COMPLETED
2014-03-31 20:12:50,120 INFO org.apache.hadoop.yarn.server.resourcemanager.scheduler.common.fica.FiCaSchedulerApp: Completed container: container_1396321465238_0002_01_000029 in state: COMPLETED event:FINISHED
2014-03-31 20:12:50,120 INFO org.apache.hadoop.yarn.server.resourcemanager.RMAuditLogger: USER=hduser	OPERATION=AM Released Container	TARGET=SchedulerApp	RESULT=SUCCESS	APPID=application_1396321465238_0002	CONTAINERID=container_1396321465238_0002_01_000029
2014-03-31 20:12:50,120 INFO org.apache.hadoop.yarn.server.resourcemanager.scheduler.common.fica.FiCaSchedulerNode: Released container container_1396321465238_0002_01_000029 of capacity <memory:1024, vCores:1> on host ubuntu:60709, which currently has 6 containers, <memory:7168, vCores:6> used and <memory:1024, vCores:2> available, release resources=true
2014-03-31 20:12:50,120 INFO org.apache.hadoop.yarn.server.resourcemanager.scheduler.capacity.LeafQueue: default used=<memory:7168, vCores:6> numContainers=6 user=hduser user-resources=<memory:7168, vCores:6>
2014-03-31 20:12:50,121 INFO org.apache.hadoop.yarn.server.resourcemanager.scheduler.capacity.LeafQueue: completedContainer container=Container: [ContainerId: container_1396321465238_0002_01_000029, NodeId: ubuntu:60709, NodeHttpAddress: ubuntu:8042, Resource: <memory:1024, vCores:1>, Priority: 10, Token: Token { kind: ContainerToken, service: 127.0.1.1:60709 }, ] resource=<memory:1024, vCores:1> queue=default: capacity=1.0, absoluteCapacity=1.0, usedResources=<memory:7168, vCores:6>usedCapacity=0.875, absoluteUsedCapacity=0.875, numApps=1, numContainers=6 usedCapacity=0.875 absoluteUsedCapacity=0.875 used=<memory:7168, vCores:6> cluster=<memory:8192, vCores:8>
2014-03-31 20:12:50,121 INFO org.apache.hadoop.yarn.server.resourcemanager.scheduler.capacity.ParentQueue: completedContainer queue=root usedCapacity=0.875 absoluteUsedCapacity=0.875 used=<memory:7168, vCores:6> cluster=<memory:8192, vCores:8>
2014-03-31 20:12:50,121 INFO org.apache.hadoop.yarn.server.resourcemanager.scheduler.capacity.ParentQueue: Re-sorting completed queue: root.default stats: default: capacity=1.0, absoluteCapacity=1.0, usedResources=<memory:7168, vCores:6>usedCapacity=0.875, absoluteUsedCapacity=0.875, numApps=1, numContainers=6
2014-03-31 20:12:50,121 INFO org.apache.hadoop.yarn.server.resourcemanager.scheduler.capacity.CapacityScheduler: Application appattempt_1396321465238_0002_000001 released container container_1396321465238_0002_01_000029 on node: host: ubuntu:60709 #containers=6 available=1024 used=7168 with event: FINISHED
2014-03-31 20:12:50,121 INFO org.apache.hadoop.yarn.server.resourcemanager.rmcontainer.RMContainerImpl: container_1396321465238_0002_01_000035 Container Transitioned from NEW to ALLOCATED
2014-03-31 20:12:50,121 INFO org.apache.hadoop.yarn.server.resourcemanager.RMAuditLogger: USER=hduser	OPERATION=AM Allocated Container	TARGET=SchedulerApp	RESULT=SUCCESS	APPID=application_1396321465238_0002	CONTAINERID=container_1396321465238_0002_01_000035
2014-03-31 20:12:50,121 INFO org.apache.hadoop.yarn.server.resourcemanager.scheduler.common.fica.FiCaSchedulerNode: Assigned container container_1396321465238_0002_01_000035 of capacity <memory:1024, vCores:1> on host ubuntu:60709, which currently has 7 containers, <memory:8192, vCores:7> used and <memory:0, vCores:1> available
2014-03-31 20:12:50,121 INFO org.apache.hadoop.yarn.server.resourcemanager.scheduler.capacity.LeafQueue: assignedContainer application=application_1396321465238_0002 container=Container: [ContainerId: container_1396321465238_0002_01_000035, NodeId: ubuntu:60709, NodeHttpAddress: ubuntu:8042, Resource: <memory:1024, vCores:1>, Priority: 10, Token: Token { kind: ContainerToken, service: 127.0.1.1:60709 }, ] containerId=container_1396321465238_0002_01_000035 queue=default: capacity=1.0, absoluteCapacity=1.0, usedResources=<memory:7168, vCores:6>usedCapacity=0.875, absoluteUsedCapacity=0.875, numApps=1, numContainers=6 usedCapacity=0.875 absoluteUsedCapacity=0.875 used=<memory:7168, vCores:6> cluster=<memory:8192, vCores:8>
2014-03-31 20:12:50,121 INFO org.apache.hadoop.yarn.server.resourcemanager.scheduler.capacity.ParentQueue: Re-sorting assigned queue: root.default stats: default: capacity=1.0, absoluteCapacity=1.0, usedResources=<memory:8192, vCores:7>usedCapacity=1.0, absoluteUsedCapacity=1.0, numApps=1, numContainers=7
2014-03-31 20:12:50,121 INFO org.apache.hadoop.yarn.server.resourcemanager.scheduler.capacity.ParentQueue: assignedContainer queue=root usedCapacity=1.0 absoluteUsedCapacity=1.0 used=<memory:8192, vCores:7> cluster=<memory:8192, vCores:8>
2014-03-31 20:12:50,215 INFO org.apache.hadoop.yarn.server.resourcemanager.rmcontainer.RMContainerImpl: container_1396321465238_0002_01_000035 Container Transitioned from ALLOCATED to ACQUIRED
2014-03-31 20:12:50,524 INFO org.apache.hadoop.yarn.server.resourcemanager.rmcontainer.RMContainerImpl: container_1396321465238_0002_01_000035 Container Transitioned from ACQUIRED to RUNNING
2014-03-31 20:12:51,226 INFO org.apache.hadoop.yarn.server.resourcemanager.scheduler.AppSchedulingInfo: checking for deactivate... 
2014-03-31 20:12:51,546 INFO org.apache.hadoop.yarn.server.resourcemanager.rmcontainer.RMContainerImpl: container_1396321465238_0002_01_000030 Container Transitioned from RUNNING to COMPLETED
2014-03-31 20:12:51,546 INFO org.apache.hadoop.yarn.server.resourcemanager.scheduler.common.fica.FiCaSchedulerApp: Completed container: container_1396321465238_0002_01_000030 in state: COMPLETED event:FINISHED
2014-03-31 20:12:51,546 INFO org.apache.hadoop.yarn.server.resourcemanager.RMAuditLogger: USER=hduser	OPERATION=AM Released Container	TARGET=SchedulerApp	RESULT=SUCCESS	APPID=application_1396321465238_0002	CONTAINERID=container_1396321465238_0002_01_000030
2014-03-31 20:12:51,546 INFO org.apache.hadoop.yarn.server.resourcemanager.scheduler.common.fica.FiCaSchedulerNode: Released container container_1396321465238_0002_01_000030 of capacity <memory:1024, vCores:1> on host ubuntu:60709, which currently has 6 containers, <memory:7168, vCores:6> used and <memory:1024, vCores:2> available, release resources=true
2014-03-31 20:12:51,546 INFO org.apache.hadoop.yarn.server.resourcemanager.scheduler.capacity.LeafQueue: default used=<memory:7168, vCores:6> numContainers=6 user=hduser user-resources=<memory:7168, vCores:6>
2014-03-31 20:12:51,546 INFO org.apache.hadoop.yarn.server.resourcemanager.scheduler.capacity.LeafQueue: completedContainer container=Container: [ContainerId: container_1396321465238_0002_01_000030, NodeId: ubuntu:60709, NodeHttpAddress: ubuntu:8042, Resource: <memory:1024, vCores:1>, Priority: 10, Token: Token { kind: ContainerToken, service: 127.0.1.1:60709 }, ] resource=<memory:1024, vCores:1> queue=default: capacity=1.0, absoluteCapacity=1.0, usedResources=<memory:7168, vCores:6>usedCapacity=0.875, absoluteUsedCapacity=0.875, numApps=1, numContainers=6 usedCapacity=0.875 absoluteUsedCapacity=0.875 used=<memory:7168, vCores:6> cluster=<memory:8192, vCores:8>
2014-03-31 20:12:51,546 INFO org.apache.hadoop.yarn.server.resourcemanager.scheduler.capacity.ParentQueue: completedContainer queue=root usedCapacity=0.875 absoluteUsedCapacity=0.875 used=<memory:7168, vCores:6> cluster=<memory:8192, vCores:8>
2014-03-31 20:12:51,546 INFO org.apache.hadoop.yarn.server.resourcemanager.scheduler.capacity.ParentQueue: Re-sorting completed queue: root.default stats: default: capacity=1.0, absoluteCapacity=1.0, usedResources=<memory:7168, vCores:6>usedCapacity=0.875, absoluteUsedCapacity=0.875, numApps=1, numContainers=6
2014-03-31 20:12:51,546 INFO org.apache.hadoop.yarn.server.resourcemanager.scheduler.capacity.CapacityScheduler: Application appattempt_1396321465238_0002_000001 released container container_1396321465238_0002_01_000030 on node: host: ubuntu:60709 #containers=6 available=1024 used=7168 with event: FINISHED
2014-03-31 20:12:52,203 INFO org.apache.hadoop.yarn.server.resourcemanager.rmcontainer.RMContainerImpl: container_1396321465238_0002_01_000032 Container Transitioned from RUNNING to COMPLETED
2014-03-31 20:12:52,203 INFO org.apache.hadoop.yarn.server.resourcemanager.scheduler.common.fica.FiCaSchedulerApp: Completed container: container_1396321465238_0002_01_000032 in state: COMPLETED event:FINISHED
2014-03-31 20:12:52,203 INFO org.apache.hadoop.yarn.server.resourcemanager.RMAuditLogger: USER=hduser	OPERATION=AM Released Container	TARGET=SchedulerApp	RESULT=SUCCESS	APPID=application_1396321465238_0002	CONTAINERID=container_1396321465238_0002_01_000032
2014-03-31 20:12:52,204 INFO org.apache.hadoop.yarn.server.resourcemanager.scheduler.common.fica.FiCaSchedulerNode: Released container container_1396321465238_0002_01_000032 of capacity <memory:1024, vCores:1> on host ubuntu:60709, which currently has 5 containers, <memory:6144, vCores:5> used and <memory:2048, vCores:3> available, release resources=true
2014-03-31 20:12:52,204 INFO org.apache.hadoop.yarn.server.resourcemanager.scheduler.capacity.LeafQueue: default used=<memory:6144, vCores:5> numContainers=5 user=hduser user-resources=<memory:6144, vCores:5>
2014-03-31 20:12:52,204 INFO org.apache.hadoop.yarn.server.resourcemanager.scheduler.capacity.LeafQueue: completedContainer container=Container: [ContainerId: container_1396321465238_0002_01_000032, NodeId: ubuntu:60709, NodeHttpAddress: ubuntu:8042, Resource: <memory:1024, vCores:1>, Priority: 10, Token: Token { kind: ContainerToken, service: 127.0.1.1:60709 }, ] resource=<memory:1024, vCores:1> queue=default: capacity=1.0, absoluteCapacity=1.0, usedResources=<memory:6144, vCores:5>usedCapacity=0.75, absoluteUsedCapacity=0.75, numApps=1, numContainers=5 usedCapacity=0.75 absoluteUsedCapacity=0.75 used=<memory:6144, vCores:5> cluster=<memory:8192, vCores:8>
2014-03-31 20:12:52,204 INFO org.apache.hadoop.yarn.server.resourcemanager.scheduler.capacity.ParentQueue: completedContainer queue=root usedCapacity=0.75 absoluteUsedCapacity=0.75 used=<memory:6144, vCores:5> cluster=<memory:8192, vCores:8>
2014-03-31 20:12:52,204 INFO org.apache.hadoop.yarn.server.resourcemanager.scheduler.capacity.ParentQueue: Re-sorting completed queue: root.default stats: default: capacity=1.0, absoluteCapacity=1.0, usedResources=<memory:6144, vCores:5>usedCapacity=0.75, absoluteUsedCapacity=0.75, numApps=1, numContainers=5
2014-03-31 20:12:52,204 INFO org.apache.hadoop.yarn.server.resourcemanager.scheduler.capacity.CapacityScheduler: Application appattempt_1396321465238_0002_000001 released container container_1396321465238_0002_01_000032 on node: host: ubuntu:60709 #containers=5 available=2048 used=6144 with event: FINISHED
2014-03-31 20:12:52,838 INFO org.apache.hadoop.yarn.server.resourcemanager.rmcontainer.RMContainerImpl: container_1396321465238_0002_01_000031 Container Transitioned from RUNNING to COMPLETED
2014-03-31 20:12:52,838 INFO org.apache.hadoop.yarn.server.resourcemanager.scheduler.common.fica.FiCaSchedulerApp: Completed container: container_1396321465238_0002_01_000031 in state: COMPLETED event:FINISHED
2014-03-31 20:12:52,838 INFO org.apache.hadoop.yarn.server.resourcemanager.RMAuditLogger: USER=hduser	OPERATION=AM Released Container	TARGET=SchedulerApp	RESULT=SUCCESS	APPID=application_1396321465238_0002	CONTAINERID=container_1396321465238_0002_01_000031
2014-03-31 20:12:52,838 INFO org.apache.hadoop.yarn.server.resourcemanager.scheduler.common.fica.FiCaSchedulerNode: Released container container_1396321465238_0002_01_000031 of capacity <memory:1024, vCores:1> on host ubuntu:60709, which currently has 4 containers, <memory:5120, vCores:4> used and <memory:3072, vCores:4> available, release resources=true
2014-03-31 20:12:52,839 INFO org.apache.hadoop.yarn.server.resourcemanager.scheduler.capacity.LeafQueue: default used=<memory:5120, vCores:4> numContainers=4 user=hduser user-resources=<memory:5120, vCores:4>
2014-03-31 20:12:52,839 INFO org.apache.hadoop.yarn.server.resourcemanager.scheduler.capacity.LeafQueue: completedContainer container=Container: [ContainerId: container_1396321465238_0002_01_000031, NodeId: ubuntu:60709, NodeHttpAddress: ubuntu:8042, Resource: <memory:1024, vCores:1>, Priority: 10, Token: Token { kind: ContainerToken, service: 127.0.1.1:60709 }, ] resource=<memory:1024, vCores:1> queue=default: capacity=1.0, absoluteCapacity=1.0, usedResources=<memory:5120, vCores:4>usedCapacity=0.625, absoluteUsedCapacity=0.625, numApps=1, numContainers=4 usedCapacity=0.625 absoluteUsedCapacity=0.625 used=<memory:5120, vCores:4> cluster=<memory:8192, vCores:8>
2014-03-31 20:12:52,839 INFO org.apache.hadoop.yarn.server.resourcemanager.scheduler.capacity.ParentQueue: completedContainer queue=root usedCapacity=0.625 absoluteUsedCapacity=0.625 used=<memory:5120, vCores:4> cluster=<memory:8192, vCores:8>
2014-03-31 20:12:52,839 INFO org.apache.hadoop.yarn.server.resourcemanager.scheduler.capacity.ParentQueue: Re-sorting completed queue: root.default stats: default: capacity=1.0, absoluteCapacity=1.0, usedResources=<memory:5120, vCores:4>usedCapacity=0.625, absoluteUsedCapacity=0.625, numApps=1, numContainers=4
2014-03-31 20:12:52,839 INFO org.apache.hadoop.yarn.server.resourcemanager.scheduler.capacity.CapacityScheduler: Application appattempt_1396321465238_0002_000001 released container container_1396321465238_0002_01_000031 on node: host: ubuntu:60709 #containers=4 available=3072 used=5120 with event: FINISHED
2014-03-31 20:12:53,853 INFO org.apache.hadoop.yarn.server.resourcemanager.rmcontainer.RMContainerImpl: container_1396321465238_0002_01_000033 Container Transitioned from RUNNING to COMPLETED
2014-03-31 20:12:53,853 INFO org.apache.hadoop.yarn.server.resourcemanager.scheduler.common.fica.FiCaSchedulerApp: Completed container: container_1396321465238_0002_01_000033 in state: COMPLETED event:FINISHED
2014-03-31 20:12:53,853 INFO org.apache.hadoop.yarn.server.resourcemanager.RMAuditLogger: USER=hduser	OPERATION=AM Released Container	TARGET=SchedulerApp	RESULT=SUCCESS	APPID=application_1396321465238_0002	CONTAINERID=container_1396321465238_0002_01_000033
2014-03-31 20:12:53,853 INFO org.apache.hadoop.yarn.server.resourcemanager.scheduler.common.fica.FiCaSchedulerNode: Released container container_1396321465238_0002_01_000033 of capacity <memory:1024, vCores:1> on host ubuntu:60709, which currently has 3 containers, <memory:4096, vCores:3> used and <memory:4096, vCores:5> available, release resources=true
2014-03-31 20:12:53,853 INFO org.apache.hadoop.yarn.server.resourcemanager.scheduler.capacity.LeafQueue: default used=<memory:4096, vCores:3> numContainers=3 user=hduser user-resources=<memory:4096, vCores:3>
2014-03-31 20:12:53,854 INFO org.apache.hadoop.yarn.server.resourcemanager.scheduler.capacity.LeafQueue: completedContainer container=Container: [ContainerId: container_1396321465238_0002_01_000033, NodeId: ubuntu:60709, NodeHttpAddress: ubuntu:8042, Resource: <memory:1024, vCores:1>, Priority: 10, Token: Token { kind: ContainerToken, service: 127.0.1.1:60709 }, ] resource=<memory:1024, vCores:1> queue=default: capacity=1.0, absoluteCapacity=1.0, usedResources=<memory:4096, vCores:3>usedCapacity=0.5, absoluteUsedCapacity=0.5, numApps=1, numContainers=3 usedCapacity=0.5 absoluteUsedCapacity=0.5 used=<memory:4096, vCores:3> cluster=<memory:8192, vCores:8>
2014-03-31 20:12:53,854 INFO org.apache.hadoop.yarn.server.resourcemanager.scheduler.capacity.ParentQueue: completedContainer queue=root usedCapacity=0.5 absoluteUsedCapacity=0.5 used=<memory:4096, vCores:3> cluster=<memory:8192, vCores:8>
2014-03-31 20:12:53,854 INFO org.apache.hadoop.yarn.server.resourcemanager.scheduler.capacity.ParentQueue: Re-sorting completed queue: root.default stats: default: capacity=1.0, absoluteCapacity=1.0, usedResources=<memory:4096, vCores:3>usedCapacity=0.5, absoluteUsedCapacity=0.5, numApps=1, numContainers=3
2014-03-31 20:12:53,854 INFO org.apache.hadoop.yarn.server.resourcemanager.scheduler.capacity.CapacityScheduler: Application appattempt_1396321465238_0002_000001 released container container_1396321465238_0002_01_000033 on node: host: ubuntu:60709 #containers=3 available=4096 used=4096 with event: FINISHED
2014-03-31 20:12:53,854 INFO org.apache.hadoop.yarn.server.resourcemanager.rmcontainer.RMContainerImpl: container_1396321465238_0002_01_000036 Container Transitioned from NEW to ALLOCATED
2014-03-31 20:12:53,854 INFO org.apache.hadoop.yarn.server.resourcemanager.RMAuditLogger: USER=hduser	OPERATION=AM Allocated Container	TARGET=SchedulerApp	RESULT=SUCCESS	APPID=application_1396321465238_0002	CONTAINERID=container_1396321465238_0002_01_000036
2014-03-31 20:12:53,854 INFO org.apache.hadoop.yarn.server.resourcemanager.scheduler.common.fica.FiCaSchedulerNode: Assigned container container_1396321465238_0002_01_000036 of capacity <memory:1024, vCores:1> on host ubuntu:60709, which currently has 4 containers, <memory:5120, vCores:4> used and <memory:3072, vCores:4> available
2014-03-31 20:12:53,854 INFO org.apache.hadoop.yarn.server.resourcemanager.scheduler.capacity.LeafQueue: assignedContainer application=application_1396321465238_0002 container=Container: [ContainerId: container_1396321465238_0002_01_000036, NodeId: ubuntu:60709, NodeHttpAddress: ubuntu:8042, Resource: <memory:1024, vCores:1>, Priority: 10, Token: Token { kind: ContainerToken, service: 127.0.1.1:60709 }, ] containerId=container_1396321465238_0002_01_000036 queue=default: capacity=1.0, absoluteCapacity=1.0, usedResources=<memory:4096, vCores:3>usedCapacity=0.5, absoluteUsedCapacity=0.5, numApps=1, numContainers=3 usedCapacity=0.5 absoluteUsedCapacity=0.5 used=<memory:4096, vCores:3> cluster=<memory:8192, vCores:8>
2014-03-31 20:12:53,854 INFO org.apache.hadoop.yarn.server.resourcemanager.scheduler.capacity.ParentQueue: Re-sorting assigned queue: root.default stats: default: capacity=1.0, absoluteCapacity=1.0, usedResources=<memory:5120, vCores:4>usedCapacity=0.625, absoluteUsedCapacity=0.625, numApps=1, numContainers=4
2014-03-31 20:12:53,855 INFO org.apache.hadoop.yarn.server.resourcemanager.scheduler.capacity.ParentQueue: assignedContainer queue=root usedCapacity=0.625 absoluteUsedCapacity=0.625 used=<memory:5120, vCores:4> cluster=<memory:8192, vCores:8>
2014-03-31 20:12:54,241 INFO org.apache.hadoop.yarn.server.resourcemanager.rmcontainer.RMContainerImpl: container_1396321465238_0002_01_000036 Container Transitioned from ALLOCATED to ACQUIRED
2014-03-31 20:12:54,335 INFO org.apache.hadoop.yarn.server.resourcemanager.rmcontainer.RMContainerImpl: container_1396321465238_0002_01_000035 Container Transitioned from RUNNING to COMPLETED
2014-03-31 20:12:54,335 INFO org.apache.hadoop.yarn.server.resourcemanager.scheduler.common.fica.FiCaSchedulerApp: Completed container: container_1396321465238_0002_01_000035 in state: COMPLETED event:FINISHED
2014-03-31 20:12:54,335 INFO org.apache.hadoop.yarn.server.resourcemanager.RMAuditLogger: USER=hduser	OPERATION=AM Released Container	TARGET=SchedulerApp	RESULT=SUCCESS	APPID=application_1396321465238_0002	CONTAINERID=container_1396321465238_0002_01_000035
2014-03-31 20:12:54,335 INFO org.apache.hadoop.yarn.server.resourcemanager.scheduler.common.fica.FiCaSchedulerNode: Released container container_1396321465238_0002_01_000035 of capacity <memory:1024, vCores:1> on host ubuntu:60709, which currently has 3 containers, <memory:4096, vCores:3> used and <memory:4096, vCores:5> available, release resources=true
2014-03-31 20:12:54,335 INFO org.apache.hadoop.yarn.server.resourcemanager.scheduler.capacity.LeafQueue: default used=<memory:4096, vCores:3> numContainers=3 user=hduser user-resources=<memory:4096, vCores:3>
2014-03-31 20:12:54,336 INFO org.apache.hadoop.yarn.server.resourcemanager.scheduler.capacity.LeafQueue: completedContainer container=Container: [ContainerId: container_1396321465238_0002_01_000035, NodeId: ubuntu:60709, NodeHttpAddress: ubuntu:8042, Resource: <memory:1024, vCores:1>, Priority: 10, Token: Token { kind: ContainerToken, service: 127.0.1.1:60709 }, ] resource=<memory:1024, vCores:1> queue=default: capacity=1.0, absoluteCapacity=1.0, usedResources=<memory:4096, vCores:3>usedCapacity=0.5, absoluteUsedCapacity=0.5, numApps=1, numContainers=3 usedCapacity=0.5 absoluteUsedCapacity=0.5 used=<memory:4096, vCores:3> cluster=<memory:8192, vCores:8>
2014-03-31 20:12:54,336 INFO org.apache.hadoop.yarn.server.resourcemanager.scheduler.capacity.ParentQueue: completedContainer queue=root usedCapacity=0.5 absoluteUsedCapacity=0.5 used=<memory:4096, vCores:3> cluster=<memory:8192, vCores:8>
2014-03-31 20:12:54,336 INFO org.apache.hadoop.yarn.server.resourcemanager.scheduler.capacity.ParentQueue: Re-sorting completed queue: root.default stats: default: capacity=1.0, absoluteCapacity=1.0, usedResources=<memory:4096, vCores:3>usedCapacity=0.5, absoluteUsedCapacity=0.5, numApps=1, numContainers=3
2014-03-31 20:12:54,336 INFO org.apache.hadoop.yarn.server.resourcemanager.scheduler.capacity.CapacityScheduler: Application appattempt_1396321465238_0002_000001 released container container_1396321465238_0002_01_000035 on node: host: ubuntu:60709 #containers=3 available=4096 used=4096 with event: FINISHED
2014-03-31 20:12:54,898 INFO org.apache.hadoop.yarn.server.resourcemanager.rmapp.attempt.RMAppAttemptImpl: appattempt_1396321465238_0002_000001 State change from RUNNING to FINISHING
2014-03-31 20:12:54,900 INFO org.apache.hadoop.yarn.server.resourcemanager.rmapp.RMAppImpl: Removing application with id application_1396321465238_0002
2014-03-31 20:12:54,900 INFO org.apache.hadoop.yarn.server.resourcemanager.rmapp.RMAppImpl: application_1396321465238_0002 State change from RUNNING to REMOVING
2014-03-31 20:12:54,900 INFO org.apache.hadoop.yarn.server.resourcemanager.recovery.RMStateStore: Removing info for app: application_1396321465238_0002
2014-03-31 20:12:54,900 INFO org.apache.hadoop.yarn.server.resourcemanager.rmapp.RMAppImpl: application_1396321465238_0002 State change from REMOVING to FINISHING
2014-03-31 20:12:55,341 INFO org.apache.hadoop.yarn.server.resourcemanager.rmcontainer.RMContainerImpl: container_1396321465238_0002_01_000034 Container Transitioned from RUNNING to COMPLETED
2014-03-31 20:12:55,341 INFO org.apache.hadoop.yarn.server.resourcemanager.scheduler.common.fica.FiCaSchedulerApp: Completed container: container_1396321465238_0002_01_000034 in state: COMPLETED event:FINISHED
2014-03-31 20:12:55,341 INFO org.apache.hadoop.yarn.server.resourcemanager.RMAuditLogger: USER=hduser	OPERATION=AM Released Container	TARGET=SchedulerApp	RESULT=SUCCESS	APPID=application_1396321465238_0002	CONTAINERID=container_1396321465238_0002_01_000034
2014-03-31 20:12:55,341 INFO org.apache.hadoop.yarn.server.resourcemanager.scheduler.common.fica.FiCaSchedulerNode: Released container container_1396321465238_0002_01_000034 of capacity <memory:1024, vCores:1> on host ubuntu:60709, which currently has 2 containers, <memory:3072, vCores:2> used and <memory:5120, vCores:6> available, release resources=true
2014-03-31 20:12:55,341 INFO org.apache.hadoop.yarn.server.resourcemanager.scheduler.capacity.LeafQueue: default used=<memory:3072, vCores:2> numContainers=2 user=hduser user-resources=<memory:3072, vCores:2>
2014-03-31 20:12:55,341 INFO org.apache.hadoop.yarn.server.resourcemanager.scheduler.capacity.LeafQueue: completedContainer container=Container: [ContainerId: container_1396321465238_0002_01_000034, NodeId: ubuntu:60709, NodeHttpAddress: ubuntu:8042, Resource: <memory:1024, vCores:1>, Priority: 10, Token: Token { kind: ContainerToken, service: 127.0.1.1:60709 }, ] resource=<memory:1024, vCores:1> queue=default: capacity=1.0, absoluteCapacity=1.0, usedResources=<memory:3072, vCores:2>usedCapacity=0.375, absoluteUsedCapacity=0.375, numApps=1, numContainers=2 usedCapacity=0.375 absoluteUsedCapacity=0.375 used=<memory:3072, vCores:2> cluster=<memory:8192, vCores:8>
2014-03-31 20:12:55,341 INFO org.apache.hadoop.yarn.server.resourcemanager.scheduler.capacity.ParentQueue: completedContainer queue=root usedCapacity=0.375 absoluteUsedCapacity=0.375 used=<memory:3072, vCores:2> cluster=<memory:8192, vCores:8>
2014-03-31 20:12:55,342 INFO org.apache.hadoop.yarn.server.resourcemanager.scheduler.capacity.ParentQueue: Re-sorting completed queue: root.default stats: default: capacity=1.0, absoluteCapacity=1.0, usedResources=<memory:3072, vCores:2>usedCapacity=0.375, absoluteUsedCapacity=0.375, numApps=1, numContainers=2
2014-03-31 20:12:55,342 INFO org.apache.hadoop.yarn.server.resourcemanager.scheduler.capacity.CapacityScheduler: Application appattempt_1396321465238_0002_000001 released container container_1396321465238_0002_01_000034 on node: host: ubuntu:60709 #containers=2 available=5120 used=3072 with event: FINISHED
2014-03-31 20:13:01,361 INFO org.apache.hadoop.yarn.server.resourcemanager.rmcontainer.RMContainerImpl: container_1396321465238_0002_01_000001 Container Transitioned from RUNNING to COMPLETED
2014-03-31 20:13:01,361 INFO org.apache.hadoop.yarn.server.resourcemanager.scheduler.common.fica.FiCaSchedulerApp: Completed container: container_1396321465238_0002_01_000001 in state: COMPLETED event:FINISHED
2014-03-31 20:13:01,361 INFO org.apache.hadoop.yarn.server.resourcemanager.ApplicationMasterService: Unregistering app attempt : appattempt_1396321465238_0002_000001
2014-03-31 20:13:01,361 INFO org.apache.hadoop.yarn.server.resourcemanager.RMAuditLogger: USER=hduser	OPERATION=AM Released Container	TARGET=SchedulerApp	RESULT=SUCCESS	APPID=application_1396321465238_0002	CONTAINERID=container_1396321465238_0002_01_000001
2014-03-31 20:13:01,362 INFO org.apache.hadoop.yarn.server.resourcemanager.rmapp.attempt.RMAppAttemptImpl: appattempt_1396321465238_0002_000001 State change from FINISHING to FINISHED
2014-03-31 20:13:01,362 INFO org.apache.hadoop.yarn.server.resourcemanager.scheduler.common.fica.FiCaSchedulerNode: Released container container_1396321465238_0002_01_000001 of capacity <memory:2048, vCores:1> on host ubuntu:60709, which currently has 1 containers, <memory:1024, vCores:1> used and <memory:7168, vCores:7> available, release resources=true
2014-03-31 20:13:01,362 INFO org.apache.hadoop.yarn.server.resourcemanager.rmapp.RMAppImpl: application_1396321465238_0002 State change from FINISHING to FINISHED
2014-03-31 20:13:01,362 INFO org.apache.hadoop.yarn.server.resourcemanager.scheduler.capacity.LeafQueue: default used=<memory:1024, vCores:1> numContainers=1 user=hduser user-resources=<memory:1024, vCores:1>
2014-03-31 20:13:01,362 INFO org.apache.hadoop.yarn.server.resourcemanager.RMAuditLogger: USER=hduser	OPERATION=Application Finished - Succeeded	TARGET=RMAppManager	RESULT=SUCCESS	APPID=application_1396321465238_0002
2014-03-31 20:13:01,362 INFO org.apache.hadoop.yarn.server.resourcemanager.scheduler.capacity.LeafQueue: completedContainer container=Container: [ContainerId: container_1396321465238_0002_01_000001, NodeId: ubuntu:60709, NodeHttpAddress: ubuntu:8042, Resource: <memory:2048, vCores:1>, Priority: 0, Token: Token { kind: ContainerToken, service: 127.0.1.1:60709 }, ] resource=<memory:2048, vCores:1> queue=default: capacity=1.0, absoluteCapacity=1.0, usedResources=<memory:1024, vCores:1>usedCapacity=0.125, absoluteUsedCapacity=0.125, numApps=1, numContainers=1 usedCapacity=0.125 absoluteUsedCapacity=0.125 used=<memory:1024, vCores:1> cluster=<memory:8192, vCores:8>
2014-03-31 20:13:01,362 INFO org.apache.hadoop.yarn.server.resourcemanager.RMAppManager$ApplicationSummary: appId=application_1396321465238_0002,name=wordcount,user=hduser,queue=default,state=FINISHED,trackingUrl=ubuntu:8088/proxy/application_1396321465238_0002/jobhistory/job/job_1396321465238_0002,appMasterHost=ubuntu,startTime=1396321927322,finishTime=1396321974900,finalStatus=SUCCEEDED
2014-03-31 20:13:01,362 INFO org.apache.hadoop.yarn.server.resourcemanager.scheduler.capacity.ParentQueue: completedContainer queue=root usedCapacity=0.125 absoluteUsedCapacity=0.125 used=<memory:1024, vCores:1> cluster=<memory:8192, vCores:8>
2014-03-31 20:13:01,363 INFO org.apache.hadoop.yarn.server.resourcemanager.scheduler.capacity.ParentQueue: Re-sorting completed queue: root.default stats: default: capacity=1.0, absoluteCapacity=1.0, usedResources=<memory:1024, vCores:1>usedCapacity=0.125, absoluteUsedCapacity=0.125, numApps=1, numContainers=1
2014-03-31 20:13:01,363 INFO org.apache.hadoop.yarn.server.resourcemanager.scheduler.capacity.CapacityScheduler: Application appattempt_1396321465238_0002_000001 released container container_1396321465238_0002_01_000001 on node: host: ubuntu:60709 #containers=1 available=7168 used=1024 with event: FINISHED
2014-03-31 20:13:01,363 INFO org.apache.hadoop.yarn.server.resourcemanager.scheduler.capacity.CapacityScheduler: Application appattempt_1396321465238_0002_000001 is done. finalState=FINISHED
2014-03-31 20:13:01,364 INFO org.apache.hadoop.yarn.server.resourcemanager.rmcontainer.RMContainerImpl: container_1396321465238_0002_01_000036 Container Transitioned from ACQUIRED to KILLED
2014-03-31 20:13:01,364 INFO org.apache.hadoop.yarn.server.resourcemanager.scheduler.common.fica.FiCaSchedulerApp: Completed container: container_1396321465238_0002_01_000036 in state: KILLED event:KILL
2014-03-31 20:13:01,364 INFO org.apache.hadoop.yarn.server.resourcemanager.RMAuditLogger: USER=hduser	OPERATION=AM Released Container	TARGET=SchedulerApp	RESULT=SUCCESS	APPID=application_1396321465238_0002	CONTAINERID=container_1396321465238_0002_01_000036
2014-03-31 20:13:01,364 INFO org.apache.hadoop.yarn.server.resourcemanager.scheduler.common.fica.FiCaSchedulerNode: Released container container_1396321465238_0002_01_000036 of capacity <memory:1024, vCores:1> on host ubuntu:60709, which currently has 0 containers, <memory:0, vCores:0> used and <memory:8192, vCores:8> available, release resources=true
2014-03-31 20:13:01,364 INFO org.apache.hadoop.yarn.server.resourcemanager.scheduler.capacity.LeafQueue: default used=<memory:0, vCores:0> numContainers=0 user=hduser user-resources=<memory:0, vCores:0>
2014-03-31 20:13:01,364 INFO org.apache.hadoop.yarn.server.resourcemanager.scheduler.capacity.LeafQueue: completedContainer container=Container: [ContainerId: container_1396321465238_0002_01_000036, NodeId: ubuntu:60709, NodeHttpAddress: ubuntu:8042, Resource: <memory:1024, vCores:1>, Priority: 10, Token: Token { kind: ContainerToken, service: 127.0.1.1:60709 }, ] resource=<memory:1024, vCores:1> queue=default: capacity=1.0, absoluteCapacity=1.0, usedResources=<memory:0, vCores:0>usedCapacity=0.0, absoluteUsedCapacity=0.0, numApps=1, numContainers=0 usedCapacity=0.0 absoluteUsedCapacity=0.0 used=<memory:0, vCores:0> cluster=<memory:8192, vCores:8>
2014-03-31 20:13:01,364 INFO org.apache.hadoop.yarn.server.resourcemanager.scheduler.capacity.ParentQueue: completedContainer queue=root usedCapacity=0.0 absoluteUsedCapacity=0.0 used=<memory:0, vCores:0> cluster=<memory:8192, vCores:8>
2014-03-31 20:13:01,364 INFO org.apache.hadoop.yarn.server.resourcemanager.scheduler.capacity.ParentQueue: Re-sorting completed queue: root.default stats: default: capacity=1.0, absoluteCapacity=1.0, usedResources=<memory:0, vCores:0>usedCapacity=0.0, absoluteUsedCapacity=0.0, numApps=1, numContainers=0
2014-03-31 20:13:01,364 INFO org.apache.hadoop.yarn.server.resourcemanager.scheduler.capacity.CapacityScheduler: Application appattempt_1396321465238_0002_000001 released container container_1396321465238_0002_01_000036 on node: host: ubuntu:60709 #containers=0 available=8192 used=0 with event: KILL
2014-03-31 20:13:01,364 INFO org.apache.hadoop.yarn.server.resourcemanager.scheduler.AppSchedulingInfo: Application application_1396321465238_0002 requests cleared
2014-03-31 20:13:01,364 INFO org.apache.hadoop.yarn.server.resourcemanager.scheduler.capacity.LeafQueue: Application removed - appId: application_1396321465238_0002 user: hduser queue: default #user-pending-applications: 0 #user-active-applications: 0 #queue-pending-applications: 0 #queue-active-applications: 0
2014-03-31 20:13:01,365 INFO org.apache.hadoop.yarn.server.resourcemanager.scheduler.capacity.ParentQueue: Application removed - appId: application_1396321465238_0002 user: hduser leaf-queue of parent: root #applications: 0
2014-03-31 20:13:01,365 INFO org.apache.hadoop.yarn.server.resourcemanager.amlauncher.AMLauncher: Cleaning master appattempt_1396321465238_0002_000001
