2014-05-03 22:41:04,945 INFO org.apache.hadoop.yarn.server.resourcemanager.ResourceManager: STARTUP_MSG: 
/************************************************************
STARTUP_MSG: Starting ResourceManager
STARTUP_MSG:   host = ip-10-0-0-182/10.0.0.182
STARTUP_MSG:   args = []
STARTUP_MSG:   version = 2.2.0
STARTUP_MSG:   build = Unknown -r Unknown; compiled by 'Joey' on 2014-03-24T00:00Z
STARTUP_MSG:   java = 1.7.0_51
************************************************************/
2014-05-03 22:41:04,954 INFO org.apache.hadoop.yarn.server.resourcemanager.ResourceManager: registered UNIX signal handlers for [TERM, HUP, INT]
2014-05-03 22:41:05,292 INFO org.apache.hadoop.yarn.server.resourcemanager.security.AMRMTokenSecretManager: Rolling master-key for amrm-tokens
2014-05-03 22:41:05,307 INFO org.apache.hadoop.yarn.server.resourcemanager.security.RMContainerTokenSecretManager: ContainerTokenKeyRollingInterval: 86400000ms and ContainerTokenKeyActivationDelay: 900000ms
2014-05-03 22:41:05,311 INFO org.apache.hadoop.yarn.server.resourcemanager.security.NMTokenSecretManagerInRM: NMTokenKeyRollingInterval: 86400000ms and NMTokenKeyActivationDelay: 900000ms
2014-05-03 22:41:05,319 INFO org.apache.hadoop.yarn.event.AsyncDispatcher: Registering class org.apache.hadoop.yarn.server.resourcemanager.recovery.RMStateStoreEventType for class org.apache.hadoop.yarn.server.resourcemanager.recovery.RMStateStore$ForwardingEventHandler
2014-05-03 22:41:06,120 INFO org.apache.hadoop.yarn.event.AsyncDispatcher: Registering class org.apache.hadoop.yarn.server.resourcemanager.NodesListManagerEventType for class org.apache.hadoop.yarn.server.resourcemanager.NodesListManager
2014-05-03 22:41:06,332 INFO org.apache.hadoop.yarn.server.resourcemanager.ResourceManager: Using Scheduler: org.apache.hadoop.yarn.server.resourcemanager.scheduler.capacity.CapacityScheduler
2014-05-03 22:41:06,628 INFO org.apache.hadoop.yarn.event.AsyncDispatcher: Registering class org.apache.hadoop.yarn.server.resourcemanager.scheduler.event.SchedulerEventType for class org.apache.hadoop.yarn.server.resourcemanager.ResourceManager$SchedulerEventDispatcher
2014-05-03 22:41:06,629 INFO org.apache.hadoop.yarn.event.AsyncDispatcher: Registering class org.apache.hadoop.yarn.server.resourcemanager.rmapp.RMAppEventType for class org.apache.hadoop.yarn.server.resourcemanager.ResourceManager$ApplicationEventDispatcher
2014-05-03 22:41:06,631 INFO org.apache.hadoop.yarn.event.AsyncDispatcher: Registering class org.apache.hadoop.yarn.server.resourcemanager.rmapp.attempt.RMAppAttemptEventType for class org.apache.hadoop.yarn.server.resourcemanager.ResourceManager$ApplicationAttemptEventDispatcher
2014-05-03 22:41:06,632 INFO org.apache.hadoop.yarn.event.AsyncDispatcher: Registering class org.apache.hadoop.yarn.server.resourcemanager.rmnode.RMNodeEventType for class org.apache.hadoop.yarn.server.resourcemanager.ResourceManager$NodeEventDispatcher
2014-05-03 22:41:06,794 INFO org.apache.hadoop.metrics2.impl.MetricsConfig: loaded properties from hadoop-metrics2.properties
2014-05-03 22:41:06,933 INFO org.apache.hadoop.metrics2.impl.MetricsSystemImpl: Scheduled snapshot period at 10 second(s).
2014-05-03 22:41:06,933 INFO org.apache.hadoop.metrics2.impl.MetricsSystemImpl: ResourceManager metrics system started
2014-05-03 22:41:07,194 INFO org.apache.hadoop.yarn.server.resourcemanager.scheduler.capacity.ParentQueue: root, capacity=1.0, asboluteCapacity=1.0, maxCapacity=1.0, asboluteMaxCapacity=1.0, state=RUNNING, acls=SUBMIT_APPLICATIONS:*ADMINISTER_QUEUE:*
2014-05-03 22:41:07,194 INFO org.apache.hadoop.yarn.server.resourcemanager.scheduler.capacity.ParentQueue: Initialized parent-queue root name=root, fullname=root
2014-05-03 22:41:07,234 INFO org.apache.hadoop.yarn.server.resourcemanager.scheduler.capacity.LeafQueue: Initializing default
capacity = 1.0 [= (float) configuredCapacity / 100 ]
asboluteCapacity = 1.0 [= parentAbsoluteCapacity * capacity ]
maxCapacity = 1.0 [= configuredMaxCapacity ]
absoluteMaxCapacity = 1.0 [= 1.0 maximumCapacity undefined, (parentAbsoluteMaxCapacity * maximumCapacity) / 100 otherwise ]
userLimit = 100 [= configuredUserLimit ]
userLimitFactor = 1.0 [= configuredUserLimitFactor ]
maxApplications = 10000 [= configuredMaximumSystemApplicationsPerQueue or (int)(configuredMaximumSystemApplications * absoluteCapacity)]
maxApplicationsPerUser = 10000 [= (int)(maxApplications * (userLimit / 100.0f) * userLimitFactor) ]
maxActiveApplications = 1 [= max((int)ceil((clusterResourceMemory / minimumAllocation) * maxAMResourcePerQueuePercent * absoluteMaxCapacity),1) ]
maxActiveAppsUsingAbsCap = 1 [= max((int)ceil((clusterResourceMemory / minimumAllocation) *maxAMResourcePercent * absoluteCapacity),1) ]
maxActiveApplicationsPerUser = 1 [= max((int)(maxActiveApplications * (userLimit / 100.0f) * userLimitFactor),1) ]
usedCapacity = 0.0 [= usedResourcesMemory / (clusterResourceMemory * absoluteCapacity)]
absoluteUsedCapacity = 0.0 [= usedResourcesMemory / clusterResourceMemory]
maxAMResourcePerQueuePercent = 0.1 [= configuredMaximumAMResourcePercent ]
minimumAllocationFactor = 0.875 [= (float)(maximumAllocationMemory - minimumAllocationMemory) / maximumAllocationMemory ]
numContainers = 0 [= currentNumContainers ]
state = RUNNING [= configuredState ]
acls = SUBMIT_APPLICATIONS:*ADMINISTER_QUEUE:* [= configuredAcls ]
nodeLocalityDelay = 0

2014-05-03 22:41:07,234 INFO org.apache.hadoop.yarn.server.resourcemanager.scheduler.capacity.CapacityScheduler: Initialized queue: default: capacity=1.0, absoluteCapacity=1.0, usedResources=<memory:0, vCores:0>usedCapacity=0.0, absoluteUsedCapacity=0.0, numApps=0, numContainers=0
2014-05-03 22:41:07,234 INFO org.apache.hadoop.yarn.server.resourcemanager.scheduler.capacity.CapacityScheduler: Initialized queue: root: numChildQueue= 1, capacity=1.0, absoluteCapacity=1.0, usedResources=<memory:0, vCores:0>usedCapacity=0.0, numApps=0, numContainers=0
2014-05-03 22:41:07,235 INFO org.apache.hadoop.yarn.server.resourcemanager.scheduler.capacity.CapacityScheduler: Initialized root queue root: numChildQueue= 1, capacity=1.0, absoluteCapacity=1.0, usedResources=<memory:0, vCores:0>usedCapacity=0.0, numApps=0, numContainers=0
2014-05-03 22:41:07,235 INFO org.apache.hadoop.yarn.server.resourcemanager.scheduler.capacity.CapacityScheduler: Initialized CapacityScheduler with calculator=class org.apache.hadoop.yarn.util.resource.DefaultResourceCalculator, minimumAllocation=<<memory:1024, vCores:1>>, maximumAllocation=<<memory:8192, vCores:32>>
2014-05-03 22:41:07,429 INFO org.apache.hadoop.yarn.event.AsyncDispatcher: Registering class org.apache.hadoop.yarn.server.resourcemanager.RMAppManagerEventType for class org.apache.hadoop.yarn.server.resourcemanager.RMAppManager
2014-05-03 22:41:07,451 INFO org.apache.hadoop.yarn.event.AsyncDispatcher: Registering class org.apache.hadoop.yarn.server.resourcemanager.amlauncher.AMLauncherEventType for class org.apache.hadoop.yarn.server.resourcemanager.amlauncher.ApplicationMasterLauncher
2014-05-03 22:41:07,455 INFO org.apache.hadoop.yarn.server.resourcemanager.RMNMInfo: Registered RMNMInfo MBean
2014-05-03 22:41:07,456 INFO org.apache.hadoop.util.HostsFileReader: Refreshing hosts (include/exclude) list
2014-05-03 22:41:07,467 INFO org.apache.hadoop.yarn.server.resourcemanager.security.AMRMTokenSecretManager: Rolling master-key for amrm-tokens
2014-05-03 22:41:07,467 INFO org.apache.hadoop.yarn.server.resourcemanager.security.RMContainerTokenSecretManager: Rolling master-key for container-tokens
2014-05-03 22:41:07,471 INFO org.apache.hadoop.yarn.server.resourcemanager.security.NMTokenSecretManagerInRM: Rolling master-key for nm-tokens
2014-05-03 22:41:07,545 INFO org.mortbay.log: Logging to org.slf4j.impl.Log4jLoggerAdapter(org.mortbay.log) via org.mortbay.log.Slf4jLog
2014-05-03 22:41:07,619 INFO org.apache.hadoop.http.HttpServer: Added global filter 'safety' (class=org.apache.hadoop.http.HttpServer$QuotingInputFilter)
2014-05-03 22:41:07,623 INFO org.apache.hadoop.http.HttpServer: Added filter static_user_filter (class=org.apache.hadoop.http.lib.StaticUserWebFilter$StaticUserFilter) to context cluster
2014-05-03 22:41:07,623 INFO org.apache.hadoop.http.HttpServer: Added filter static_user_filter (class=org.apache.hadoop.http.lib.StaticUserWebFilter$StaticUserFilter) to context logs
2014-05-03 22:41:07,623 INFO org.apache.hadoop.http.HttpServer: Added filter static_user_filter (class=org.apache.hadoop.http.lib.StaticUserWebFilter$StaticUserFilter) to context static
2014-05-03 22:41:07,628 INFO org.apache.hadoop.http.HttpServer: adding path spec: /cluster/*
2014-05-03 22:41:07,628 INFO org.apache.hadoop.http.HttpServer: adding path spec: /ws/*
2014-05-03 22:41:07,639 INFO org.apache.hadoop.http.HttpServer: Jetty bound to port 8088
2014-05-03 22:41:07,639 INFO org.mortbay.log: jetty-6.1.26
2014-05-03 22:41:07,693 INFO org.mortbay.log: Extract jar:file:/home/ubuntu/PatchedDistro/hadoop-2.2.0/share/hadoop/yarn/hadoop-yarn-common-2.2.0.jar!/webapps/cluster to /tmp/Jetty_ec2.54.186.230.200_us.west.2_compute_amazonaws_com_8088_cluster____.lsgqu1/webapp
2014-05-03 22:41:08,361 INFO org.mortbay.log: Started SelectChannelConnector@ec2-54-186-230-200.us-west-2.compute.amazonaws.com:8088
2014-05-03 22:41:08,361 INFO org.apache.hadoop.yarn.webapp.WebApps: Web app /cluster started at 8088
2014-05-03 22:41:09,528 INFO org.apache.hadoop.yarn.webapp.WebApps: Registered webapp guice modules
2014-05-03 22:41:09,530 INFO org.apache.hadoop.security.token.delegation.AbstractDelegationTokenSecretManager: Updating the current master key for generating delegation tokens
2014-05-03 22:41:09,531 INFO org.apache.hadoop.yarn.server.resourcemanager.security.RMDelegationTokenSecretManager: storing master key with keyID 1
2014-05-03 22:41:09,532 INFO org.apache.hadoop.security.token.delegation.AbstractDelegationTokenSecretManager: Starting expired delegation token remover thread, tokenRemoverScanInterval=60 min(s)
2014-05-03 22:41:09,532 INFO org.apache.hadoop.security.token.delegation.AbstractDelegationTokenSecretManager: Updating the current master key for generating delegation tokens
2014-05-03 22:41:09,532 INFO org.apache.hadoop.yarn.server.resourcemanager.security.RMDelegationTokenSecretManager: storing master key with keyID 2
2014-05-03 22:41:09,593 INFO org.apache.hadoop.ipc.Server: Starting Socket Reader #1 for port 8031
2014-05-03 22:41:09,632 INFO org.apache.hadoop.yarn.factories.impl.pb.RpcServerFactoryPBImpl: Adding protocol org.apache.hadoop.yarn.server.api.ResourceTrackerPB to the server
2014-05-03 22:41:09,636 INFO org.apache.hadoop.ipc.Server: IPC Server Responder: starting
2014-05-03 22:41:09,645 INFO org.apache.hadoop.ipc.Server: IPC Server listener on 8031: starting
2014-05-03 22:41:09,784 INFO org.apache.hadoop.ipc.Server: Starting Socket Reader #1 for port 8030
2014-05-03 22:41:09,967 INFO org.apache.hadoop.yarn.factories.impl.pb.RpcServerFactoryPBImpl: Adding protocol org.apache.hadoop.yarn.api.ApplicationMasterProtocolPB to the server
2014-05-03 22:41:09,968 INFO org.apache.hadoop.ipc.Server: IPC Server Responder: starting
2014-05-03 22:41:09,968 INFO org.apache.hadoop.ipc.Server: IPC Server listener on 8030: starting
2014-05-03 22:41:10,248 INFO org.apache.hadoop.yarn.util.RackResolver: Resolved nodeb to /default-rack
2014-05-03 22:41:10,269 INFO org.apache.hadoop.yarn.util.RackResolver: Resolved noded to /default-rack
2014-05-03 22:41:10,296 INFO org.apache.hadoop.ipc.Server: Starting Socket Reader #1 for port 8032
2014-05-03 22:41:10,304 INFO org.apache.hadoop.yarn.server.resourcemanager.ResourceTrackerService: NodeManager from node nodeb(cmPort: 55487 httpPort: 8042) registered with capability: <memory:8192, vCores:8>, assigned nodeId nodeb:55487
2014-05-03 22:41:10,305 INFO org.apache.hadoop.yarn.server.resourcemanager.ResourceTrackerService: NodeManager from node noded(cmPort: 50846 httpPort: 8042) registered with capability: <memory:8192, vCores:8>, assigned nodeId noded:50846
2014-05-03 22:41:10,307 INFO org.apache.hadoop.yarn.server.resourcemanager.rmnode.RMNodeImpl: nodeb:55487 Node Transitioned from NEW to RUNNING
2014-05-03 22:41:10,312 INFO org.apache.hadoop.yarn.server.resourcemanager.scheduler.capacity.CapacityScheduler: Added node nodeb:55487 clusterResource: <memory:8192, vCores:8>
2014-05-03 22:41:10,313 INFO org.apache.hadoop.yarn.server.resourcemanager.rmnode.RMNodeImpl: noded:50846 Node Transitioned from NEW to RUNNING
2014-05-03 22:41:10,313 INFO org.apache.hadoop.yarn.server.resourcemanager.scheduler.capacity.CapacityScheduler: Added node noded:50846 clusterResource: <memory:16384, vCores:16>
2014-05-03 22:41:10,321 INFO org.apache.hadoop.yarn.factories.impl.pb.RpcServerFactoryPBImpl: Adding protocol org.apache.hadoop.yarn.api.ApplicationClientProtocolPB to the server
2014-05-03 22:41:10,322 INFO org.apache.hadoop.ipc.Server: IPC Server Responder: starting
2014-05-03 22:41:10,323 INFO org.apache.hadoop.ipc.Server: IPC Server listener on 8032: starting
2014-05-03 22:41:10,400 INFO org.apache.hadoop.yarn.factories.impl.pb.RpcServerFactoryPBImpl: Adding protocol org.apache.hadoop.yarn.server.api.ResourceManagerAdministrationProtocolPB to the server
2014-05-03 22:41:10,400 INFO org.apache.hadoop.ipc.Server: Starting Socket Reader #1 for port 8033
2014-05-03 22:41:10,401 INFO org.apache.hadoop.ipc.Server: IPC Server Responder: starting
2014-05-03 22:41:10,413 INFO org.apache.hadoop.ipc.Server: IPC Server listener on 8033: starting
2014-05-03 22:41:10,543 INFO org.apache.hadoop.yarn.util.RackResolver: Resolved nodec to /default-rack
2014-05-03 22:41:10,544 INFO org.apache.hadoop.yarn.server.resourcemanager.ResourceTrackerService: NodeManager from node nodec(cmPort: 54860 httpPort: 8042) registered with capability: <memory:8192, vCores:8>, assigned nodeId nodec:54860
2014-05-03 22:41:10,544 INFO org.apache.hadoop.yarn.server.resourcemanager.rmnode.RMNodeImpl: nodec:54860 Node Transitioned from NEW to RUNNING
2014-05-03 22:41:10,544 INFO org.apache.hadoop.yarn.server.resourcemanager.scheduler.capacity.CapacityScheduler: Added node nodec:54860 clusterResource: <memory:24576, vCores:24>
2014-05-03 22:41:12,754 INFO org.apache.hadoop.yarn.util.RackResolver: Resolved nodea to /default-rack
2014-05-03 22:41:12,755 INFO org.apache.hadoop.yarn.server.resourcemanager.ResourceTrackerService: NodeManager from node nodea(cmPort: 56325 httpPort: 8042) registered with capability: <memory:8192, vCores:8>, assigned nodeId nodea:56325
2014-05-03 22:41:12,755 INFO org.apache.hadoop.yarn.server.resourcemanager.rmnode.RMNodeImpl: nodea:56325 Node Transitioned from NEW to RUNNING
2014-05-03 22:41:12,755 INFO org.apache.hadoop.yarn.server.resourcemanager.scheduler.capacity.CapacityScheduler: Added node nodea:56325 clusterResource: <memory:32768, vCores:32>
2014-05-03 23:05:04,570 INFO org.apache.hadoop.yarn.server.resourcemanager.ClientRMService: Allocated new applicationId: 1
2014-05-03 23:05:06,422 INFO org.apache.hadoop.yarn.server.resourcemanager.ClientRMService: Application with id 1 submitted by user ubuntu
2014-05-03 23:05:06,423 INFO org.apache.hadoop.yarn.server.resourcemanager.rmapp.RMAppImpl: Storing application with id application_1399156864902_0001
2014-05-03 23:05:06,423 INFO org.apache.hadoop.yarn.server.resourcemanager.RMAuditLogger: USER=ubuntu	IP=10.0.0.182	OPERATION=Submit Application Request	TARGET=ClientRMService	RESULT=SUCCESS	APPID=application_1399156864902_0001
2014-05-03 23:05:06,425 INFO org.apache.hadoop.yarn.server.resourcemanager.rmapp.RMAppImpl: application_1399156864902_0001 State change from NEW to NEW_SAVING
2014-05-03 23:05:06,429 INFO org.apache.hadoop.yarn.server.resourcemanager.recovery.RMStateStore: Storing info for app: application_1399156864902_0001
2014-05-03 23:05:06,441 INFO org.apache.hadoop.yarn.server.resourcemanager.rmapp.RMAppImpl: application_1399156864902_0001 State change from NEW_SAVING to SUBMITTED
2014-05-03 23:05:06,441 INFO org.apache.hadoop.yarn.server.resourcemanager.ApplicationMasterService: Registering app attempt : appattempt_1399156864902_0001_000001
2014-05-03 23:05:06,453 INFO org.apache.hadoop.yarn.server.resourcemanager.rmapp.attempt.RMAppAttemptImpl: appattempt_1399156864902_0001_000001 State change from NEW to SUBMITTED
2014-05-03 23:05:06,476 INFO org.apache.hadoop.yarn.server.resourcemanager.scheduler.capacity.LeafQueue: Application application_1399156864902_0001 from user: ubuntu activated in queue: default
2014-05-03 23:05:06,476 INFO org.apache.hadoop.yarn.server.resourcemanager.scheduler.capacity.LeafQueue: Application added - appId: application_1399156864902_0001 user: org.apache.hadoop.yarn.server.resourcemanager.scheduler.capacity.LeafQueue$User@6f578744, leaf-queue: default #user-pending-applications: 0 #user-active-applications: 1 #queue-pending-applications: 0 #queue-active-applications: 1
2014-05-03 23:05:06,476 INFO org.apache.hadoop.yarn.server.resourcemanager.scheduler.capacity.ParentQueue: Application added - appId: application_1399156864902_0001 user: ubuntu leaf-queue of parent: root #applications: 1
2014-05-03 23:05:06,476 INFO org.apache.hadoop.yarn.server.resourcemanager.scheduler.capacity.CapacityScheduler: Application Submission: appattempt_1399156864902_0001_000001, user: ubuntu queue: default: capacity=1.0, absoluteCapacity=1.0, usedResources=<memory:0, vCores:0>usedCapacity=0.0, absoluteUsedCapacity=0.0, numApps=1, numContainers=0, currently active: 1
2014-05-03 23:05:06,477 INFO org.apache.hadoop.yarn.server.resourcemanager.rmapp.attempt.RMAppAttemptImpl: appattempt_1399156864902_0001_000001 State change from SUBMITTED to SCHEDULED
2014-05-03 23:05:06,480 INFO org.apache.hadoop.yarn.server.resourcemanager.rmapp.RMAppImpl: application_1399156864902_0001 State change from SUBMITTED to ACCEPTED
2014-05-03 23:05:06,864 INFO org.apache.hadoop.yarn.server.resourcemanager.rmcontainer.RMContainerImpl: container_1399156864902_0001_01_000001 Container Transitioned from NEW to ALLOCATED
2014-05-03 23:05:06,864 INFO org.apache.hadoop.yarn.server.resourcemanager.RMAuditLogger: USER=ubuntu	OPERATION=AM Allocated Container	TARGET=SchedulerApp	RESULT=SUCCESS	APPID=application_1399156864902_0001	CONTAINERID=container_1399156864902_0001_01_000001
2014-05-03 23:05:06,865 INFO org.apache.hadoop.yarn.server.resourcemanager.scheduler.common.fica.FiCaSchedulerNode: Assigned container container_1399156864902_0001_01_000001 of capacity <memory:2048, vCores:1> on host nodeb:55487, which currently has 1 containers, <memory:2048, vCores:1> used and <memory:6144, vCores:7> available
2014-05-03 23:05:06,865 INFO org.apache.hadoop.yarn.server.resourcemanager.scheduler.capacity.LeafQueue: assignedContainer application=application_1399156864902_0001 container=Container: [ContainerId: container_1399156864902_0001_01_000001, NodeId: nodeb:55487, NodeHttpAddress: nodeb:8042, Resource: <memory:2048, vCores:1>, Priority: 0, Token: Token { kind: ContainerToken, service: 10.0.0.243:55487 }, ] containerId=container_1399156864902_0001_01_000001 queue=default: capacity=1.0, absoluteCapacity=1.0, usedResources=<memory:0, vCores:0>usedCapacity=0.0, absoluteUsedCapacity=0.0, numApps=1, numContainers=0 usedCapacity=0.0 absoluteUsedCapacity=0.0 used=<memory:0, vCores:0> cluster=<memory:32768, vCores:32>
2014-05-03 23:05:06,865 INFO org.apache.hadoop.yarn.server.resourcemanager.scheduler.capacity.ParentQueue: Re-sorting assigned queue: root.default stats: default: capacity=1.0, absoluteCapacity=1.0, usedResources=<memory:2048, vCores:1>usedCapacity=0.0625, absoluteUsedCapacity=0.0625, numApps=1, numContainers=1
2014-05-03 23:05:06,865 INFO org.apache.hadoop.yarn.server.resourcemanager.scheduler.capacity.ParentQueue: assignedContainer queue=root usedCapacity=0.0625 absoluteUsedCapacity=0.0625 used=<memory:2048, vCores:1> cluster=<memory:32768, vCores:32>
2014-05-03 23:05:06,866 INFO org.apache.hadoop.yarn.server.resourcemanager.rmcontainer.RMContainerImpl: container_1399156864902_0001_01_000001 Container Transitioned from ALLOCATED to ACQUIRED
2014-05-03 23:05:06,868 INFO org.apache.hadoop.yarn.server.resourcemanager.rmapp.attempt.RMAppAttemptImpl: Storing attempt: AppId: application_1399156864902_0001 AttemptId: appattempt_1399156864902_0001_000001 MasterContainer: Container: [ContainerId: container_1399156864902_0001_01_000001, NodeId: nodeb:55487, NodeHttpAddress: nodeb:8042, Resource: <memory:2048, vCores:1>, Priority: 0, Token: Token { kind: ContainerToken, service: 10.0.0.243:55487 }, ]
2014-05-03 23:05:06,872 INFO org.apache.hadoop.yarn.server.resourcemanager.rmapp.attempt.RMAppAttemptImpl: appattempt_1399156864902_0001_000001 State change from SCHEDULED to ALLOCATED_SAVING
2014-05-03 23:05:06,877 INFO org.apache.hadoop.yarn.server.resourcemanager.recovery.RMStateStore: Storing info for attempt: appattempt_1399156864902_0001_000001
2014-05-03 23:05:06,878 INFO org.apache.hadoop.yarn.server.resourcemanager.rmapp.attempt.RMAppAttemptImpl: appattempt_1399156864902_0001_000001 State change from ALLOCATED_SAVING to ALLOCATED
2014-05-03 23:05:06,880 INFO org.apache.hadoop.yarn.server.resourcemanager.amlauncher.AMLauncher: Launching masterappattempt_1399156864902_0001_000001
2014-05-03 23:05:06,911 INFO org.apache.hadoop.yarn.server.resourcemanager.amlauncher.AMLauncher: Setting up container Container: [ContainerId: container_1399156864902_0001_01_000001, NodeId: nodeb:55487, NodeHttpAddress: nodeb:8042, Resource: <memory:2048, vCores:1>, Priority: 0, Token: Token { kind: ContainerToken, service: 10.0.0.243:55487 }, ] for AM appattempt_1399156864902_0001_000001
2014-05-03 23:05:06,912 INFO org.apache.hadoop.yarn.server.resourcemanager.amlauncher.AMLauncher: Command to launch container container_1399156864902_0001_01_000001 : $JAVA_HOME/bin/java -Dlog4j.configuration=container-log4j.properties -Dyarn.app.container.log.dir=<LOG_DIR> -Dyarn.app.container.log.filesize=0 -Dhadoop.root.logger=INFO,CLA  -Xmx1024m org.apache.hadoop.mapreduce.v2.app.MRAppMaster 1><LOG_DIR>/stdout 2><LOG_DIR>/stderr 
2014-05-03 23:05:07,279 INFO org.apache.hadoop.yarn.server.resourcemanager.amlauncher.AMLauncher: Done launching container Container: [ContainerId: container_1399156864902_0001_01_000001, NodeId: nodeb:55487, NodeHttpAddress: nodeb:8042, Resource: <memory:2048, vCores:1>, Priority: 0, Token: Token { kind: ContainerToken, service: 10.0.0.243:55487 }, ] for AM appattempt_1399156864902_0001_000001
2014-05-03 23:05:07,279 INFO org.apache.hadoop.yarn.server.resourcemanager.rmapp.attempt.RMAppAttemptImpl: appattempt_1399156864902_0001_000001 State change from ALLOCATED to LAUNCHED
2014-05-03 23:05:07,877 INFO org.apache.hadoop.yarn.server.resourcemanager.rmcontainer.RMContainerImpl: container_1399156864902_0001_01_000001 Container Transitioned from ACQUIRED to RUNNING
2014-05-03 23:05:13,736 INFO SecurityLogger.org.apache.hadoop.ipc.Server: Auth successful for appattempt_1399156864902_0001_000001 (auth:SIMPLE)
2014-05-03 23:05:13,742 INFO org.apache.hadoop.yarn.server.resourcemanager.ApplicationMasterService: AM registration appattempt_1399156864902_0001_000001
2014-05-03 23:05:13,743 INFO org.apache.hadoop.yarn.server.resourcemanager.RMAuditLogger: USER=ubuntu	IP=10.0.0.243	OPERATION=Register App Master	TARGET=ApplicationMasterService	RESULT=SUCCESS	APPID=application_1399156864902_0001	APPATTEMPTID=appattempt_1399156864902_0001_000001
2014-05-03 23:05:13,743 INFO org.apache.hadoop.yarn.server.resourcemanager.rmapp.attempt.RMAppAttemptImpl: appattempt_1399156864902_0001_000001 State change from LAUNCHED to RUNNING
2014-05-03 23:05:13,743 INFO org.apache.hadoop.yarn.server.resourcemanager.rmapp.RMAppImpl: application_1399156864902_0001 State change from ACCEPTED to RUNNING
2014-05-03 23:05:14,865 INFO org.apache.hadoop.yarn.server.resourcemanager.rmcontainer.RMContainerImpl: container_1399156864902_0001_01_000002 Container Transitioned from NEW to ALLOCATED
2014-05-03 23:05:14,865 INFO org.apache.hadoop.yarn.server.resourcemanager.RMAuditLogger: USER=ubuntu	OPERATION=AM Allocated Container	TARGET=SchedulerApp	RESULT=SUCCESS	APPID=application_1399156864902_0001	CONTAINERID=container_1399156864902_0001_01_000002
2014-05-03 23:05:14,865 INFO org.apache.hadoop.yarn.server.resourcemanager.scheduler.common.fica.FiCaSchedulerNode: Assigned container container_1399156864902_0001_01_000002 of capacity <memory:1024, vCores:1> on host noded:50846, which currently has 1 containers, <memory:1024, vCores:1> used and <memory:7168, vCores:7> available
2014-05-03 23:05:14,865 INFO org.apache.hadoop.yarn.server.resourcemanager.scheduler.capacity.LeafQueue: assignedContainer application=application_1399156864902_0001 container=Container: [ContainerId: container_1399156864902_0001_01_000002, NodeId: noded:50846, NodeHttpAddress: noded:8042, Resource: <memory:1024, vCores:1>, Priority: 20, Token: Token { kind: ContainerToken, service: 10.0.0.244:50846 }, ] containerId=container_1399156864902_0001_01_000002 queue=default: capacity=1.0, absoluteCapacity=1.0, usedResources=<memory:2048, vCores:1>usedCapacity=0.0625, absoluteUsedCapacity=0.0625, numApps=1, numContainers=1 usedCapacity=0.0625 absoluteUsedCapacity=0.0625 used=<memory:2048, vCores:1> cluster=<memory:32768, vCores:32>
2014-05-03 23:05:14,865 INFO org.apache.hadoop.yarn.server.resourcemanager.scheduler.capacity.ParentQueue: Re-sorting assigned queue: root.default stats: default: capacity=1.0, absoluteCapacity=1.0, usedResources=<memory:3072, vCores:2>usedCapacity=0.09375, absoluteUsedCapacity=0.09375, numApps=1, numContainers=2
2014-05-03 23:05:14,865 INFO org.apache.hadoop.yarn.server.resourcemanager.scheduler.capacity.ParentQueue: assignedContainer queue=root usedCapacity=0.09375 absoluteUsedCapacity=0.09375 used=<memory:3072, vCores:2> cluster=<memory:32768, vCores:32>
2014-05-03 23:05:14,866 INFO org.apache.hadoop.yarn.server.resourcemanager.rmcontainer.RMContainerImpl: container_1399156864902_0001_01_000003 Container Transitioned from NEW to ALLOCATED
2014-05-03 23:05:14,866 INFO org.apache.hadoop.yarn.server.resourcemanager.RMAuditLogger: USER=ubuntu	OPERATION=AM Allocated Container	TARGET=SchedulerApp	RESULT=SUCCESS	APPID=application_1399156864902_0001	CONTAINERID=container_1399156864902_0001_01_000003
2014-05-03 23:05:14,866 INFO org.apache.hadoop.yarn.server.resourcemanager.scheduler.common.fica.FiCaSchedulerNode: Assigned container container_1399156864902_0001_01_000003 of capacity <memory:1024, vCores:1> on host noded:50846, which currently has 2 containers, <memory:2048, vCores:2> used and <memory:6144, vCores:6> available
2014-05-03 23:05:14,866 INFO org.apache.hadoop.yarn.server.resourcemanager.scheduler.capacity.LeafQueue: assignedContainer application=application_1399156864902_0001 container=Container: [ContainerId: container_1399156864902_0001_01_000003, NodeId: noded:50846, NodeHttpAddress: noded:8042, Resource: <memory:1024, vCores:1>, Priority: 20, Token: Token { kind: ContainerToken, service: 10.0.0.244:50846 }, ] containerId=container_1399156864902_0001_01_000003 queue=default: capacity=1.0, absoluteCapacity=1.0, usedResources=<memory:3072, vCores:2>usedCapacity=0.09375, absoluteUsedCapacity=0.09375, numApps=1, numContainers=2 usedCapacity=0.09375 absoluteUsedCapacity=0.09375 used=<memory:3072, vCores:2> cluster=<memory:32768, vCores:32>
2014-05-03 23:05:14,866 INFO org.apache.hadoop.yarn.server.resourcemanager.scheduler.capacity.ParentQueue: Re-sorting assigned queue: root.default stats: default: capacity=1.0, absoluteCapacity=1.0, usedResources=<memory:4096, vCores:3>usedCapacity=0.125, absoluteUsedCapacity=0.125, numApps=1, numContainers=3
2014-05-03 23:05:14,866 INFO org.apache.hadoop.yarn.server.resourcemanager.scheduler.capacity.ParentQueue: assignedContainer queue=root usedCapacity=0.125 absoluteUsedCapacity=0.125 used=<memory:4096, vCores:3> cluster=<memory:32768, vCores:32>
2014-05-03 23:05:14,867 INFO org.apache.hadoop.yarn.server.resourcemanager.rmcontainer.RMContainerImpl: container_1399156864902_0001_01_000004 Container Transitioned from NEW to ALLOCATED
2014-05-03 23:05:14,867 INFO org.apache.hadoop.yarn.server.resourcemanager.RMAuditLogger: USER=ubuntu	OPERATION=AM Allocated Container	TARGET=SchedulerApp	RESULT=SUCCESS	APPID=application_1399156864902_0001	CONTAINERID=container_1399156864902_0001_01_000004
2014-05-03 23:05:14,867 INFO org.apache.hadoop.yarn.server.resourcemanager.scheduler.common.fica.FiCaSchedulerNode: Assigned container container_1399156864902_0001_01_000004 of capacity <memory:1024, vCores:1> on host noded:50846, which currently has 3 containers, <memory:3072, vCores:3> used and <memory:5120, vCores:5> available
2014-05-03 23:05:14,867 INFO org.apache.hadoop.yarn.server.resourcemanager.scheduler.capacity.LeafQueue: assignedContainer application=application_1399156864902_0001 container=Container: [ContainerId: container_1399156864902_0001_01_000004, NodeId: noded:50846, NodeHttpAddress: noded:8042, Resource: <memory:1024, vCores:1>, Priority: 20, Token: Token { kind: ContainerToken, service: 10.0.0.244:50846 }, ] containerId=container_1399156864902_0001_01_000004 queue=default: capacity=1.0, absoluteCapacity=1.0, usedResources=<memory:4096, vCores:3>usedCapacity=0.125, absoluteUsedCapacity=0.125, numApps=1, numContainers=3 usedCapacity=0.125 absoluteUsedCapacity=0.125 used=<memory:4096, vCores:3> cluster=<memory:32768, vCores:32>
2014-05-03 23:05:14,867 INFO org.apache.hadoop.yarn.server.resourcemanager.scheduler.capacity.ParentQueue: Re-sorting assigned queue: root.default stats: default: capacity=1.0, absoluteCapacity=1.0, usedResources=<memory:5120, vCores:4>usedCapacity=0.15625, absoluteUsedCapacity=0.15625, numApps=1, numContainers=4
2014-05-03 23:05:14,867 INFO org.apache.hadoop.yarn.server.resourcemanager.scheduler.capacity.ParentQueue: assignedContainer queue=root usedCapacity=0.15625 absoluteUsedCapacity=0.15625 used=<memory:5120, vCores:4> cluster=<memory:32768, vCores:32>
2014-05-03 23:05:14,868 INFO org.apache.hadoop.yarn.server.resourcemanager.rmcontainer.RMContainerImpl: container_1399156864902_0001_01_000005 Container Transitioned from NEW to ALLOCATED
2014-05-03 23:05:14,868 INFO org.apache.hadoop.yarn.server.resourcemanager.RMAuditLogger: USER=ubuntu	OPERATION=AM Allocated Container	TARGET=SchedulerApp	RESULT=SUCCESS	APPID=application_1399156864902_0001	CONTAINERID=container_1399156864902_0001_01_000005
2014-05-03 23:05:14,868 INFO org.apache.hadoop.yarn.server.resourcemanager.scheduler.common.fica.FiCaSchedulerNode: Assigned container container_1399156864902_0001_01_000005 of capacity <memory:1024, vCores:1> on host noded:50846, which currently has 4 containers, <memory:4096, vCores:4> used and <memory:4096, vCores:4> available
2014-05-03 23:05:14,868 INFO org.apache.hadoop.yarn.server.resourcemanager.scheduler.capacity.LeafQueue: assignedContainer application=application_1399156864902_0001 container=Container: [ContainerId: container_1399156864902_0001_01_000005, NodeId: noded:50846, NodeHttpAddress: noded:8042, Resource: <memory:1024, vCores:1>, Priority: 20, Token: Token { kind: ContainerToken, service: 10.0.0.244:50846 }, ] containerId=container_1399156864902_0001_01_000005 queue=default: capacity=1.0, absoluteCapacity=1.0, usedResources=<memory:5120, vCores:4>usedCapacity=0.15625, absoluteUsedCapacity=0.15625, numApps=1, numContainers=4 usedCapacity=0.15625 absoluteUsedCapacity=0.15625 used=<memory:5120, vCores:4> cluster=<memory:32768, vCores:32>
2014-05-03 23:05:14,868 INFO org.apache.hadoop.yarn.server.resourcemanager.scheduler.capacity.ParentQueue: Re-sorting assigned queue: root.default stats: default: capacity=1.0, absoluteCapacity=1.0, usedResources=<memory:6144, vCores:5>usedCapacity=0.1875, absoluteUsedCapacity=0.1875, numApps=1, numContainers=5
2014-05-03 23:05:14,868 INFO org.apache.hadoop.yarn.server.resourcemanager.scheduler.capacity.ParentQueue: assignedContainer queue=root usedCapacity=0.1875 absoluteUsedCapacity=0.1875 used=<memory:6144, vCores:5> cluster=<memory:32768, vCores:32>
2014-05-03 23:05:15,851 INFO org.apache.hadoop.yarn.server.resourcemanager.rmcontainer.RMContainerImpl: container_1399156864902_0001_01_000002 Container Transitioned from ALLOCATED to ACQUIRED
2014-05-03 23:05:15,852 INFO org.apache.hadoop.yarn.server.resourcemanager.rmcontainer.RMContainerImpl: container_1399156864902_0001_01_000003 Container Transitioned from ALLOCATED to ACQUIRED
2014-05-03 23:05:15,852 INFO org.apache.hadoop.yarn.server.resourcemanager.rmcontainer.RMContainerImpl: container_1399156864902_0001_01_000004 Container Transitioned from ALLOCATED to ACQUIRED
2014-05-03 23:05:15,852 INFO org.apache.hadoop.yarn.server.resourcemanager.rmcontainer.RMContainerImpl: container_1399156864902_0001_01_000005 Container Transitioned from ALLOCATED to ACQUIRED
2014-05-03 23:05:16,896 INFO org.apache.hadoop.yarn.server.resourcemanager.scheduler.AppSchedulingInfo: checking for deactivate... 
2014-05-03 23:05:16,902 INFO org.apache.hadoop.yarn.server.resourcemanager.rmcontainer.RMContainerImpl: container_1399156864902_0001_01_000002 Container Transitioned from ACQUIRED to RUNNING
2014-05-03 23:05:16,902 INFO org.apache.hadoop.yarn.server.resourcemanager.rmcontainer.RMContainerImpl: container_1399156864902_0001_01_000003 Container Transitioned from ACQUIRED to RUNNING
2014-05-03 23:05:16,902 INFO org.apache.hadoop.yarn.server.resourcemanager.rmcontainer.RMContainerImpl: container_1399156864902_0001_01_000004 Container Transitioned from ACQUIRED to RUNNING
2014-05-03 23:05:16,902 INFO org.apache.hadoop.yarn.server.resourcemanager.rmcontainer.RMContainerImpl: container_1399156864902_0001_01_000005 Container Transitioned from ACQUIRED to RUNNING
2014-05-03 23:05:52,172 INFO org.apache.hadoop.yarn.server.resourcemanager.rmcontainer.RMContainerImpl: container_1399156864902_0001_01_000002 Container Transitioned from RUNNING to COMPLETED
2014-05-03 23:05:52,172 INFO org.apache.hadoop.yarn.server.resourcemanager.scheduler.common.fica.FiCaSchedulerApp: Completed container: container_1399156864902_0001_01_000002 in state: COMPLETED event:FINISHED
2014-05-03 23:05:52,172 INFO org.apache.hadoop.yarn.server.resourcemanager.RMAuditLogger: USER=ubuntu	OPERATION=AM Released Container	TARGET=SchedulerApp	RESULT=SUCCESS	APPID=application_1399156864902_0001	CONTAINERID=container_1399156864902_0001_01_000002
2014-05-03 23:05:52,172 INFO org.apache.hadoop.yarn.server.resourcemanager.scheduler.common.fica.FiCaSchedulerNode: Released container container_1399156864902_0001_01_000002 of capacity <memory:1024, vCores:1> on host noded:50846, which currently has 3 containers, <memory:3072, vCores:3> used and <memory:5120, vCores:5> available, release resources=true
2014-05-03 23:05:52,172 INFO org.apache.hadoop.yarn.server.resourcemanager.scheduler.capacity.LeafQueue: default used=<memory:5120, vCores:4> numContainers=4 user=ubuntu user-resources=<memory:5120, vCores:4>
2014-05-03 23:05:52,172 INFO org.apache.hadoop.yarn.server.resourcemanager.scheduler.capacity.LeafQueue: completedContainer container=Container: [ContainerId: container_1399156864902_0001_01_000002, NodeId: noded:50846, NodeHttpAddress: noded:8042, Resource: <memory:1024, vCores:1>, Priority: 20, Token: Token { kind: ContainerToken, service: 10.0.0.244:50846 }, ] resource=<memory:1024, vCores:1> queue=default: capacity=1.0, absoluteCapacity=1.0, usedResources=<memory:5120, vCores:4>usedCapacity=0.15625, absoluteUsedCapacity=0.15625, numApps=1, numContainers=4 usedCapacity=0.15625 absoluteUsedCapacity=0.15625 used=<memory:5120, vCores:4> cluster=<memory:32768, vCores:32>
2014-05-03 23:05:52,172 INFO org.apache.hadoop.yarn.server.resourcemanager.scheduler.capacity.ParentQueue: completedContainer queue=root usedCapacity=0.15625 absoluteUsedCapacity=0.15625 used=<memory:5120, vCores:4> cluster=<memory:32768, vCores:32>
2014-05-03 23:05:52,172 INFO org.apache.hadoop.yarn.server.resourcemanager.scheduler.capacity.ParentQueue: Re-sorting completed queue: root.default stats: default: capacity=1.0, absoluteCapacity=1.0, usedResources=<memory:5120, vCores:4>usedCapacity=0.15625, absoluteUsedCapacity=0.15625, numApps=1, numContainers=4
2014-05-03 23:05:52,172 INFO org.apache.hadoop.yarn.server.resourcemanager.scheduler.capacity.CapacityScheduler: Application appattempt_1399156864902_0001_000001 released container container_1399156864902_0001_01_000002 on node: host: noded:50846 #containers=3 available=5120 used=3072 with event: FINISHED
2014-05-03 23:05:52,626 INFO org.apache.hadoop.yarn.server.resourcemanager.rmcontainer.RMContainerImpl: container_1399156864902_0001_01_000003 Container Transitioned from RUNNING to COMPLETED
2014-05-03 23:05:52,626 INFO org.apache.hadoop.yarn.server.resourcemanager.scheduler.common.fica.FiCaSchedulerApp: Completed container: container_1399156864902_0001_01_000003 in state: COMPLETED event:FINISHED
2014-05-03 23:05:52,626 INFO org.apache.hadoop.yarn.server.resourcemanager.RMAuditLogger: USER=ubuntu	OPERATION=AM Released Container	TARGET=SchedulerApp	RESULT=SUCCESS	APPID=application_1399156864902_0001	CONTAINERID=container_1399156864902_0001_01_000003
2014-05-03 23:05:52,626 INFO org.apache.hadoop.yarn.server.resourcemanager.scheduler.common.fica.FiCaSchedulerNode: Released container container_1399156864902_0001_01_000003 of capacity <memory:1024, vCores:1> on host noded:50846, which currently has 2 containers, <memory:2048, vCores:2> used and <memory:6144, vCores:6> available, release resources=true
2014-05-03 23:05:52,626 INFO org.apache.hadoop.yarn.server.resourcemanager.scheduler.capacity.LeafQueue: default used=<memory:4096, vCores:3> numContainers=3 user=ubuntu user-resources=<memory:4096, vCores:3>
2014-05-03 23:05:52,626 INFO org.apache.hadoop.yarn.server.resourcemanager.scheduler.capacity.LeafQueue: completedContainer container=Container: [ContainerId: container_1399156864902_0001_01_000003, NodeId: noded:50846, NodeHttpAddress: noded:8042, Resource: <memory:1024, vCores:1>, Priority: 20, Token: Token { kind: ContainerToken, service: 10.0.0.244:50846 }, ] resource=<memory:1024, vCores:1> queue=default: capacity=1.0, absoluteCapacity=1.0, usedResources=<memory:4096, vCores:3>usedCapacity=0.125, absoluteUsedCapacity=0.125, numApps=1, numContainers=3 usedCapacity=0.125 absoluteUsedCapacity=0.125 used=<memory:4096, vCores:3> cluster=<memory:32768, vCores:32>
2014-05-03 23:05:52,626 INFO org.apache.hadoop.yarn.server.resourcemanager.scheduler.capacity.ParentQueue: completedContainer queue=root usedCapacity=0.125 absoluteUsedCapacity=0.125 used=<memory:4096, vCores:3> cluster=<memory:32768, vCores:32>
2014-05-03 23:05:52,626 INFO org.apache.hadoop.yarn.server.resourcemanager.scheduler.capacity.ParentQueue: Re-sorting completed queue: root.default stats: default: capacity=1.0, absoluteCapacity=1.0, usedResources=<memory:4096, vCores:3>usedCapacity=0.125, absoluteUsedCapacity=0.125, numApps=1, numContainers=3
2014-05-03 23:05:52,627 INFO org.apache.hadoop.yarn.server.resourcemanager.scheduler.capacity.CapacityScheduler: Application appattempt_1399156864902_0001_000001 released container container_1399156864902_0001_01_000003 on node: host: noded:50846 #containers=2 available=6144 used=2048 with event: FINISHED
2014-05-03 23:05:52,693 INFO org.apache.hadoop.yarn.server.resourcemanager.rmcontainer.RMContainerImpl: container_1399156864902_0001_01_000005 Container Transitioned from RUNNING to COMPLETED
2014-05-03 23:05:52,693 INFO org.apache.hadoop.yarn.server.resourcemanager.scheduler.common.fica.FiCaSchedulerApp: Completed container: container_1399156864902_0001_01_000005 in state: COMPLETED event:FINISHED
2014-05-03 23:05:52,693 INFO org.apache.hadoop.yarn.server.resourcemanager.RMAuditLogger: USER=ubuntu	OPERATION=AM Released Container	TARGET=SchedulerApp	RESULT=SUCCESS	APPID=application_1399156864902_0001	CONTAINERID=container_1399156864902_0001_01_000005
2014-05-03 23:05:52,693 INFO org.apache.hadoop.yarn.server.resourcemanager.scheduler.common.fica.FiCaSchedulerNode: Released container container_1399156864902_0001_01_000005 of capacity <memory:1024, vCores:1> on host noded:50846, which currently has 1 containers, <memory:1024, vCores:1> used and <memory:7168, vCores:7> available, release resources=true
2014-05-03 23:05:52,693 INFO org.apache.hadoop.yarn.server.resourcemanager.scheduler.capacity.LeafQueue: default used=<memory:3072, vCores:2> numContainers=2 user=ubuntu user-resources=<memory:3072, vCores:2>
2014-05-03 23:05:52,693 INFO org.apache.hadoop.yarn.server.resourcemanager.scheduler.capacity.LeafQueue: completedContainer container=Container: [ContainerId: container_1399156864902_0001_01_000005, NodeId: noded:50846, NodeHttpAddress: noded:8042, Resource: <memory:1024, vCores:1>, Priority: 20, Token: Token { kind: ContainerToken, service: 10.0.0.244:50846 }, ] resource=<memory:1024, vCores:1> queue=default: capacity=1.0, absoluteCapacity=1.0, usedResources=<memory:3072, vCores:2>usedCapacity=0.09375, absoluteUsedCapacity=0.09375, numApps=1, numContainers=2 usedCapacity=0.09375 absoluteUsedCapacity=0.09375 used=<memory:3072, vCores:2> cluster=<memory:32768, vCores:32>
2014-05-03 23:05:52,693 INFO org.apache.hadoop.yarn.server.resourcemanager.scheduler.capacity.ParentQueue: completedContainer queue=root usedCapacity=0.09375 absoluteUsedCapacity=0.09375 used=<memory:3072, vCores:2> cluster=<memory:32768, vCores:32>
2014-05-03 23:05:52,693 INFO org.apache.hadoop.yarn.server.resourcemanager.scheduler.capacity.ParentQueue: Re-sorting completed queue: root.default stats: default: capacity=1.0, absoluteCapacity=1.0, usedResources=<memory:3072, vCores:2>usedCapacity=0.09375, absoluteUsedCapacity=0.09375, numApps=1, numContainers=2
2014-05-03 23:05:52,693 INFO org.apache.hadoop.yarn.server.resourcemanager.scheduler.capacity.CapacityScheduler: Application appattempt_1399156864902_0001_000001 released container container_1399156864902_0001_01_000005 on node: host: noded:50846 #containers=1 available=7168 used=1024 with event: FINISHED
2014-05-03 23:05:53,757 INFO org.apache.hadoop.yarn.server.resourcemanager.rmcontainer.RMContainerImpl: container_1399156864902_0001_01_000004 Container Transitioned from RUNNING to COMPLETED
2014-05-03 23:05:53,757 INFO org.apache.hadoop.yarn.server.resourcemanager.scheduler.common.fica.FiCaSchedulerApp: Completed container: container_1399156864902_0001_01_000004 in state: COMPLETED event:FINISHED
2014-05-03 23:05:53,757 INFO org.apache.hadoop.yarn.server.resourcemanager.RMAuditLogger: USER=ubuntu	OPERATION=AM Released Container	TARGET=SchedulerApp	RESULT=SUCCESS	APPID=application_1399156864902_0001	CONTAINERID=container_1399156864902_0001_01_000004
2014-05-03 23:05:53,757 INFO org.apache.hadoop.yarn.server.resourcemanager.scheduler.common.fica.FiCaSchedulerNode: Released container container_1399156864902_0001_01_000004 of capacity <memory:1024, vCores:1> on host noded:50846, which currently has 0 containers, <memory:0, vCores:0> used and <memory:8192, vCores:8> available, release resources=true
2014-05-03 23:05:53,757 INFO org.apache.hadoop.yarn.server.resourcemanager.scheduler.capacity.LeafQueue: default used=<memory:2048, vCores:1> numContainers=1 user=ubuntu user-resources=<memory:2048, vCores:1>
2014-05-03 23:05:53,757 INFO org.apache.hadoop.yarn.server.resourcemanager.scheduler.capacity.LeafQueue: completedContainer container=Container: [ContainerId: container_1399156864902_0001_01_000004, NodeId: noded:50846, NodeHttpAddress: noded:8042, Resource: <memory:1024, vCores:1>, Priority: 20, Token: Token { kind: ContainerToken, service: 10.0.0.244:50846 }, ] resource=<memory:1024, vCores:1> queue=default: capacity=1.0, absoluteCapacity=1.0, usedResources=<memory:2048, vCores:1>usedCapacity=0.0625, absoluteUsedCapacity=0.0625, numApps=1, numContainers=1 usedCapacity=0.0625 absoluteUsedCapacity=0.0625 used=<memory:2048, vCores:1> cluster=<memory:32768, vCores:32>
2014-05-03 23:05:53,757 INFO org.apache.hadoop.yarn.server.resourcemanager.scheduler.capacity.ParentQueue: completedContainer queue=root usedCapacity=0.0625 absoluteUsedCapacity=0.0625 used=<memory:2048, vCores:1> cluster=<memory:32768, vCores:32>
2014-05-03 23:05:53,757 INFO org.apache.hadoop.yarn.server.resourcemanager.scheduler.capacity.ParentQueue: Re-sorting completed queue: root.default stats: default: capacity=1.0, absoluteCapacity=1.0, usedResources=<memory:2048, vCores:1>usedCapacity=0.0625, absoluteUsedCapacity=0.0625, numApps=1, numContainers=1
2014-05-03 23:05:53,757 INFO org.apache.hadoop.yarn.server.resourcemanager.scheduler.capacity.CapacityScheduler: Application appattempt_1399156864902_0001_000001 released container container_1399156864902_0001_01_000004 on node: host: noded:50846 #containers=0 available=8192 used=0 with event: FINISHED
2014-05-03 23:05:54,056 INFO org.apache.hadoop.yarn.server.resourcemanager.rmcontainer.RMContainerImpl: container_1399156864902_0001_01_000006 Container Transitioned from NEW to ALLOCATED
2014-05-03 23:05:54,056 INFO org.apache.hadoop.yarn.server.resourcemanager.RMAuditLogger: USER=ubuntu	OPERATION=AM Allocated Container	TARGET=SchedulerApp	RESULT=SUCCESS	APPID=application_1399156864902_0001	CONTAINERID=container_1399156864902_0001_01_000006
2014-05-03 23:05:54,056 INFO org.apache.hadoop.yarn.server.resourcemanager.scheduler.common.fica.FiCaSchedulerNode: Assigned container container_1399156864902_0001_01_000006 of capacity <memory:1024, vCores:1> on host nodea:56325, which currently has 1 containers, <memory:1024, vCores:1> used and <memory:7168, vCores:7> available
2014-05-03 23:05:54,056 INFO org.apache.hadoop.yarn.server.resourcemanager.scheduler.capacity.LeafQueue: assignedContainer application=application_1399156864902_0001 container=Container: [ContainerId: container_1399156864902_0001_01_000006, NodeId: nodea:56325, NodeHttpAddress: nodea:8042, Resource: <memory:1024, vCores:1>, Priority: 10, Token: Token { kind: ContainerToken, service: 10.0.0.182:56325 }, ] containerId=container_1399156864902_0001_01_000006 queue=default: capacity=1.0, absoluteCapacity=1.0, usedResources=<memory:2048, vCores:1>usedCapacity=0.0625, absoluteUsedCapacity=0.0625, numApps=1, numContainers=1 usedCapacity=0.0625 absoluteUsedCapacity=0.0625 used=<memory:2048, vCores:1> cluster=<memory:32768, vCores:32>
2014-05-03 23:05:54,056 INFO org.apache.hadoop.yarn.server.resourcemanager.scheduler.capacity.ParentQueue: Re-sorting assigned queue: root.default stats: default: capacity=1.0, absoluteCapacity=1.0, usedResources=<memory:3072, vCores:2>usedCapacity=0.09375, absoluteUsedCapacity=0.09375, numApps=1, numContainers=2
2014-05-03 23:05:54,056 INFO org.apache.hadoop.yarn.server.resourcemanager.scheduler.capacity.ParentQueue: assignedContainer queue=root usedCapacity=0.09375 absoluteUsedCapacity=0.09375 used=<memory:3072, vCores:2> cluster=<memory:32768, vCores:32>
2014-05-03 23:05:54,073 INFO org.apache.hadoop.yarn.server.resourcemanager.rmcontainer.RMContainerImpl: container_1399156864902_0001_01_000007 Container Transitioned from NEW to ALLOCATED
2014-05-03 23:05:54,073 INFO org.apache.hadoop.yarn.server.resourcemanager.RMAuditLogger: USER=ubuntu	OPERATION=AM Allocated Container	TARGET=SchedulerApp	RESULT=SUCCESS	APPID=application_1399156864902_0001	CONTAINERID=container_1399156864902_0001_01_000007
2014-05-03 23:05:54,073 INFO org.apache.hadoop.yarn.server.resourcemanager.scheduler.common.fica.FiCaSchedulerNode: Assigned container container_1399156864902_0001_01_000007 of capacity <memory:1024, vCores:1> on host nodec:54860, which currently has 1 containers, <memory:1024, vCores:1> used and <memory:7168, vCores:7> available
2014-05-03 23:05:54,073 INFO org.apache.hadoop.yarn.server.resourcemanager.scheduler.capacity.LeafQueue: assignedContainer application=application_1399156864902_0001 container=Container: [ContainerId: container_1399156864902_0001_01_000007, NodeId: nodec:54860, NodeHttpAddress: nodec:8042, Resource: <memory:1024, vCores:1>, Priority: 10, Token: Token { kind: ContainerToken, service: 10.0.0.245:54860 }, ] containerId=container_1399156864902_0001_01_000007 queue=default: capacity=1.0, absoluteCapacity=1.0, usedResources=<memory:3072, vCores:2>usedCapacity=0.09375, absoluteUsedCapacity=0.09375, numApps=1, numContainers=2 usedCapacity=0.09375 absoluteUsedCapacity=0.09375 used=<memory:3072, vCores:2> cluster=<memory:32768, vCores:32>
2014-05-03 23:05:54,074 INFO org.apache.hadoop.yarn.server.resourcemanager.scheduler.capacity.ParentQueue: Re-sorting assigned queue: root.default stats: default: capacity=1.0, absoluteCapacity=1.0, usedResources=<memory:4096, vCores:3>usedCapacity=0.125, absoluteUsedCapacity=0.125, numApps=1, numContainers=3
2014-05-03 23:05:54,074 INFO org.apache.hadoop.yarn.server.resourcemanager.scheduler.capacity.ParentQueue: assignedContainer queue=root usedCapacity=0.125 absoluteUsedCapacity=0.125 used=<memory:4096, vCores:3> cluster=<memory:32768, vCores:32>
2014-05-03 23:05:54,758 INFO org.apache.hadoop.yarn.server.resourcemanager.rmcontainer.RMContainerImpl: container_1399156864902_0001_01_000008 Container Transitioned from NEW to ALLOCATED
2014-05-03 23:05:54,758 INFO org.apache.hadoop.yarn.server.resourcemanager.RMAuditLogger: USER=ubuntu	OPERATION=AM Allocated Container	TARGET=SchedulerApp	RESULT=SUCCESS	APPID=application_1399156864902_0001	CONTAINERID=container_1399156864902_0001_01_000008
2014-05-03 23:05:54,758 INFO org.apache.hadoop.yarn.server.resourcemanager.scheduler.common.fica.FiCaSchedulerNode: Assigned container container_1399156864902_0001_01_000008 of capacity <memory:1024, vCores:1> on host noded:50846, which currently has 1 containers, <memory:1024, vCores:1> used and <memory:7168, vCores:7> available
2014-05-03 23:05:54,759 INFO org.apache.hadoop.yarn.server.resourcemanager.scheduler.capacity.LeafQueue: assignedContainer application=application_1399156864902_0001 container=Container: [ContainerId: container_1399156864902_0001_01_000008, NodeId: noded:50846, NodeHttpAddress: noded:8042, Resource: <memory:1024, vCores:1>, Priority: 10, Token: Token { kind: ContainerToken, service: 10.0.0.244:50846 }, ] containerId=container_1399156864902_0001_01_000008 queue=default: capacity=1.0, absoluteCapacity=1.0, usedResources=<memory:4096, vCores:3>usedCapacity=0.125, absoluteUsedCapacity=0.125, numApps=1, numContainers=3 usedCapacity=0.125 absoluteUsedCapacity=0.125 used=<memory:4096, vCores:3> cluster=<memory:32768, vCores:32>
2014-05-03 23:05:54,759 INFO org.apache.hadoop.yarn.server.resourcemanager.scheduler.capacity.ParentQueue: Re-sorting assigned queue: root.default stats: default: capacity=1.0, absoluteCapacity=1.0, usedResources=<memory:5120, vCores:4>usedCapacity=0.15625, absoluteUsedCapacity=0.15625, numApps=1, numContainers=4
2014-05-03 23:05:54,759 INFO org.apache.hadoop.yarn.server.resourcemanager.scheduler.capacity.ParentQueue: assignedContainer queue=root usedCapacity=0.15625 absoluteUsedCapacity=0.15625 used=<memory:5120, vCores:4> cluster=<memory:32768, vCores:32>
2014-05-03 23:05:54,999 INFO org.apache.hadoop.yarn.server.resourcemanager.rmcontainer.RMContainerImpl: container_1399156864902_0001_01_000009 Container Transitioned from NEW to ALLOCATED
2014-05-03 23:05:54,999 INFO org.apache.hadoop.yarn.server.resourcemanager.RMAuditLogger: USER=ubuntu	OPERATION=AM Allocated Container	TARGET=SchedulerApp	RESULT=SUCCESS	APPID=application_1399156864902_0001	CONTAINERID=container_1399156864902_0001_01_000009
2014-05-03 23:05:54,999 INFO org.apache.hadoop.yarn.server.resourcemanager.scheduler.common.fica.FiCaSchedulerNode: Assigned container container_1399156864902_0001_01_000009 of capacity <memory:1024, vCores:1> on host nodeb:55487, which currently has 2 containers, <memory:3072, vCores:2> used and <memory:5120, vCores:6> available
2014-05-03 23:05:54,999 INFO org.apache.hadoop.yarn.server.resourcemanager.scheduler.capacity.LeafQueue: assignedContainer application=application_1399156864902_0001 container=Container: [ContainerId: container_1399156864902_0001_01_000009, NodeId: nodeb:55487, NodeHttpAddress: nodeb:8042, Resource: <memory:1024, vCores:1>, Priority: 10, Token: Token { kind: ContainerToken, service: 10.0.0.243:55487 }, ] containerId=container_1399156864902_0001_01_000009 queue=default: capacity=1.0, absoluteCapacity=1.0, usedResources=<memory:5120, vCores:4>usedCapacity=0.15625, absoluteUsedCapacity=0.15625, numApps=1, numContainers=4 usedCapacity=0.15625 absoluteUsedCapacity=0.15625 used=<memory:5120, vCores:4> cluster=<memory:32768, vCores:32>
2014-05-03 23:05:54,999 INFO org.apache.hadoop.yarn.server.resourcemanager.scheduler.capacity.ParentQueue: Re-sorting assigned queue: root.default stats: default: capacity=1.0, absoluteCapacity=1.0, usedResources=<memory:6144, vCores:5>usedCapacity=0.1875, absoluteUsedCapacity=0.1875, numApps=1, numContainers=5
2014-05-03 23:05:54,999 INFO org.apache.hadoop.yarn.server.resourcemanager.scheduler.capacity.ParentQueue: assignedContainer queue=root usedCapacity=0.1875 absoluteUsedCapacity=0.1875 used=<memory:6144, vCores:5> cluster=<memory:32768, vCores:32>
2014-05-03 23:05:55,011 INFO org.apache.hadoop.yarn.server.resourcemanager.rmcontainer.RMContainerImpl: container_1399156864902_0001_01_000006 Container Transitioned from ALLOCATED to ACQUIRED
2014-05-03 23:05:55,016 INFO org.apache.hadoop.yarn.server.resourcemanager.rmcontainer.RMContainerImpl: container_1399156864902_0001_01_000007 Container Transitioned from ALLOCATED to ACQUIRED
2014-05-03 23:05:55,017 INFO org.apache.hadoop.yarn.server.resourcemanager.rmcontainer.RMContainerImpl: container_1399156864902_0001_01_000008 Container Transitioned from ALLOCATED to ACQUIRED
2014-05-03 23:05:55,017 INFO org.apache.hadoop.yarn.server.resourcemanager.rmcontainer.RMContainerImpl: container_1399156864902_0001_01_000009 Container Transitioned from ALLOCATED to ACQUIRED
2014-05-03 23:05:55,058 INFO org.apache.hadoop.yarn.server.resourcemanager.rmcontainer.RMContainerImpl: container_1399156864902_0001_01_000010 Container Transitioned from NEW to ALLOCATED
2014-05-03 23:05:55,058 INFO org.apache.hadoop.yarn.server.resourcemanager.RMAuditLogger: USER=ubuntu	OPERATION=AM Allocated Container	TARGET=SchedulerApp	RESULT=SUCCESS	APPID=application_1399156864902_0001	CONTAINERID=container_1399156864902_0001_01_000010
2014-05-03 23:05:55,058 INFO org.apache.hadoop.yarn.server.resourcemanager.scheduler.common.fica.FiCaSchedulerNode: Assigned container container_1399156864902_0001_01_000010 of capacity <memory:1024, vCores:1> on host nodea:56325, which currently has 2 containers, <memory:2048, vCores:2> used and <memory:6144, vCores:6> available
2014-05-03 23:05:55,058 INFO org.apache.hadoop.yarn.server.resourcemanager.scheduler.capacity.LeafQueue: assignedContainer application=application_1399156864902_0001 container=Container: [ContainerId: container_1399156864902_0001_01_000010, NodeId: nodea:56325, NodeHttpAddress: nodea:8042, Resource: <memory:1024, vCores:1>, Priority: 10, Token: Token { kind: ContainerToken, service: 10.0.0.182:56325 }, ] containerId=container_1399156864902_0001_01_000010 queue=default: capacity=1.0, absoluteCapacity=1.0, usedResources=<memory:6144, vCores:5>usedCapacity=0.1875, absoluteUsedCapacity=0.1875, numApps=1, numContainers=5 usedCapacity=0.1875 absoluteUsedCapacity=0.1875 used=<memory:6144, vCores:5> cluster=<memory:32768, vCores:32>
2014-05-03 23:05:55,058 INFO org.apache.hadoop.yarn.server.resourcemanager.scheduler.capacity.ParentQueue: Re-sorting assigned queue: root.default stats: default: capacity=1.0, absoluteCapacity=1.0, usedResources=<memory:7168, vCores:6>usedCapacity=0.21875, absoluteUsedCapacity=0.21875, numApps=1, numContainers=6
2014-05-03 23:05:55,059 INFO org.apache.hadoop.yarn.server.resourcemanager.scheduler.capacity.ParentQueue: assignedContainer queue=root usedCapacity=0.21875 absoluteUsedCapacity=0.21875 used=<memory:7168, vCores:6> cluster=<memory:32768, vCores:32>
2014-05-03 23:05:55,076 INFO org.apache.hadoop.yarn.server.resourcemanager.rmcontainer.RMContainerImpl: container_1399156864902_0001_01_000011 Container Transitioned from NEW to ALLOCATED
2014-05-03 23:05:55,076 INFO org.apache.hadoop.yarn.server.resourcemanager.RMAuditLogger: USER=ubuntu	OPERATION=AM Allocated Container	TARGET=SchedulerApp	RESULT=SUCCESS	APPID=application_1399156864902_0001	CONTAINERID=container_1399156864902_0001_01_000011
2014-05-03 23:05:55,076 INFO org.apache.hadoop.yarn.server.resourcemanager.scheduler.common.fica.FiCaSchedulerNode: Assigned container container_1399156864902_0001_01_000011 of capacity <memory:1024, vCores:1> on host nodec:54860, which currently has 2 containers, <memory:2048, vCores:2> used and <memory:6144, vCores:6> available
2014-05-03 23:05:55,076 INFO org.apache.hadoop.yarn.server.resourcemanager.scheduler.capacity.LeafQueue: assignedContainer application=application_1399156864902_0001 container=Container: [ContainerId: container_1399156864902_0001_01_000011, NodeId: nodec:54860, NodeHttpAddress: nodec:8042, Resource: <memory:1024, vCores:1>, Priority: 10, Token: Token { kind: ContainerToken, service: 10.0.0.245:54860 }, ] containerId=container_1399156864902_0001_01_000011 queue=default: capacity=1.0, absoluteCapacity=1.0, usedResources=<memory:7168, vCores:6>usedCapacity=0.21875, absoluteUsedCapacity=0.21875, numApps=1, numContainers=6 usedCapacity=0.21875 absoluteUsedCapacity=0.21875 used=<memory:7168, vCores:6> cluster=<memory:32768, vCores:32>
2014-05-03 23:05:55,076 INFO org.apache.hadoop.yarn.server.resourcemanager.scheduler.capacity.ParentQueue: Re-sorting assigned queue: root.default stats: default: capacity=1.0, absoluteCapacity=1.0, usedResources=<memory:8192, vCores:7>usedCapacity=0.25, absoluteUsedCapacity=0.25, numApps=1, numContainers=7
2014-05-03 23:05:55,076 INFO org.apache.hadoop.yarn.server.resourcemanager.scheduler.capacity.ParentQueue: assignedContainer queue=root usedCapacity=0.25 absoluteUsedCapacity=0.25 used=<memory:8192, vCores:7> cluster=<memory:32768, vCores:32>
2014-05-03 23:05:55,761 INFO org.apache.hadoop.yarn.server.resourcemanager.rmcontainer.RMContainerImpl: container_1399156864902_0001_01_000008 Container Transitioned from ACQUIRED to RUNNING
2014-05-03 23:05:55,761 INFO org.apache.hadoop.yarn.server.resourcemanager.rmcontainer.RMContainerImpl: container_1399156864902_0001_01_000012 Container Transitioned from NEW to ALLOCATED
2014-05-03 23:05:55,761 INFO org.apache.hadoop.yarn.server.resourcemanager.RMAuditLogger: USER=ubuntu	OPERATION=AM Allocated Container	TARGET=SchedulerApp	RESULT=SUCCESS	APPID=application_1399156864902_0001	CONTAINERID=container_1399156864902_0001_01_000012
2014-05-03 23:05:55,762 INFO org.apache.hadoop.yarn.server.resourcemanager.scheduler.common.fica.FiCaSchedulerNode: Assigned container container_1399156864902_0001_01_000012 of capacity <memory:1024, vCores:1> on host noded:50846, which currently has 2 containers, <memory:2048, vCores:2> used and <memory:6144, vCores:6> available
2014-05-03 23:05:55,762 INFO org.apache.hadoop.yarn.server.resourcemanager.scheduler.capacity.LeafQueue: assignedContainer application=application_1399156864902_0001 container=Container: [ContainerId: container_1399156864902_0001_01_000012, NodeId: noded:50846, NodeHttpAddress: noded:8042, Resource: <memory:1024, vCores:1>, Priority: 10, Token: Token { kind: ContainerToken, service: 10.0.0.244:50846 }, ] containerId=container_1399156864902_0001_01_000012 queue=default: capacity=1.0, absoluteCapacity=1.0, usedResources=<memory:8192, vCores:7>usedCapacity=0.25, absoluteUsedCapacity=0.25, numApps=1, numContainers=7 usedCapacity=0.25 absoluteUsedCapacity=0.25 used=<memory:8192, vCores:7> cluster=<memory:32768, vCores:32>
2014-05-03 23:05:55,762 INFO org.apache.hadoop.yarn.server.resourcemanager.scheduler.capacity.ParentQueue: Re-sorting assigned queue: root.default stats: default: capacity=1.0, absoluteCapacity=1.0, usedResources=<memory:9216, vCores:8>usedCapacity=0.28125, absoluteUsedCapacity=0.28125, numApps=1, numContainers=8
2014-05-03 23:05:55,762 INFO org.apache.hadoop.yarn.server.resourcemanager.scheduler.capacity.ParentQueue: assignedContainer queue=root usedCapacity=0.28125 absoluteUsedCapacity=0.28125 used=<memory:9216, vCores:8> cluster=<memory:32768, vCores:32>
2014-05-03 23:05:56,001 INFO org.apache.hadoop.yarn.server.resourcemanager.rmcontainer.RMContainerImpl: container_1399156864902_0001_01_000009 Container Transitioned from ACQUIRED to RUNNING
2014-05-03 23:05:56,002 INFO org.apache.hadoop.yarn.server.resourcemanager.rmcontainer.RMContainerImpl: container_1399156864902_0001_01_000013 Container Transitioned from NEW to ALLOCATED
2014-05-03 23:05:56,002 INFO org.apache.hadoop.yarn.server.resourcemanager.RMAuditLogger: USER=ubuntu	OPERATION=AM Allocated Container	TARGET=SchedulerApp	RESULT=SUCCESS	APPID=application_1399156864902_0001	CONTAINERID=container_1399156864902_0001_01_000013
2014-05-03 23:05:56,002 INFO org.apache.hadoop.yarn.server.resourcemanager.scheduler.common.fica.FiCaSchedulerNode: Assigned container container_1399156864902_0001_01_000013 of capacity <memory:1024, vCores:1> on host nodeb:55487, which currently has 3 containers, <memory:4096, vCores:3> used and <memory:4096, vCores:5> available
2014-05-03 23:05:56,003 INFO org.apache.hadoop.yarn.server.resourcemanager.scheduler.capacity.LeafQueue: assignedContainer application=application_1399156864902_0001 container=Container: [ContainerId: container_1399156864902_0001_01_000013, NodeId: nodeb:55487, NodeHttpAddress: nodeb:8042, Resource: <memory:1024, vCores:1>, Priority: 10, Token: Token { kind: ContainerToken, service: 10.0.0.243:55487 }, ] containerId=container_1399156864902_0001_01_000013 queue=default: capacity=1.0, absoluteCapacity=1.0, usedResources=<memory:9216, vCores:8>usedCapacity=0.28125, absoluteUsedCapacity=0.28125, numApps=1, numContainers=8 usedCapacity=0.28125 absoluteUsedCapacity=0.28125 used=<memory:9216, vCores:8> cluster=<memory:32768, vCores:32>
2014-05-03 23:05:56,003 INFO org.apache.hadoop.yarn.server.resourcemanager.scheduler.capacity.ParentQueue: Re-sorting assigned queue: root.default stats: default: capacity=1.0, absoluteCapacity=1.0, usedResources=<memory:10240, vCores:9>usedCapacity=0.3125, absoluteUsedCapacity=0.3125, numApps=1, numContainers=9
2014-05-03 23:05:56,003 INFO org.apache.hadoop.yarn.server.resourcemanager.scheduler.capacity.ParentQueue: assignedContainer queue=root usedCapacity=0.3125 absoluteUsedCapacity=0.3125 used=<memory:10240, vCores:9> cluster=<memory:32768, vCores:32>
2014-05-03 23:05:56,025 INFO org.apache.hadoop.yarn.server.resourcemanager.rmcontainer.RMContainerImpl: container_1399156864902_0001_01_000010 Container Transitioned from ALLOCATED to ACQUIRED
2014-05-03 23:05:56,026 INFO org.apache.hadoop.yarn.server.resourcemanager.rmcontainer.RMContainerImpl: container_1399156864902_0001_01_000011 Container Transitioned from ALLOCATED to ACQUIRED
2014-05-03 23:05:56,026 INFO org.apache.hadoop.yarn.server.resourcemanager.rmcontainer.RMContainerImpl: container_1399156864902_0001_01_000012 Container Transitioned from ALLOCATED to ACQUIRED
2014-05-03 23:05:56,026 INFO org.apache.hadoop.yarn.server.resourcemanager.rmcontainer.RMContainerImpl: container_1399156864902_0001_01_000013 Container Transitioned from ALLOCATED to ACQUIRED
2014-05-03 23:05:56,088 INFO org.apache.hadoop.yarn.server.resourcemanager.rmcontainer.RMContainerImpl: container_1399156864902_0001_01_000006 Container Transitioned from ACQUIRED to RUNNING
2014-05-03 23:05:56,088 INFO org.apache.hadoop.yarn.server.resourcemanager.rmcontainer.RMContainerImpl: container_1399156864902_0001_01_000010 Container Transitioned from ACQUIRED to RUNNING
2014-05-03 23:05:56,089 INFO org.apache.hadoop.yarn.server.resourcemanager.rmcontainer.RMContainerImpl: container_1399156864902_0001_01_000014 Container Transitioned from NEW to ALLOCATED
2014-05-03 23:05:56,089 INFO org.apache.hadoop.yarn.server.resourcemanager.RMAuditLogger: USER=ubuntu	OPERATION=AM Allocated Container	TARGET=SchedulerApp	RESULT=SUCCESS	APPID=application_1399156864902_0001	CONTAINERID=container_1399156864902_0001_01_000014
2014-05-03 23:05:56,089 INFO org.apache.hadoop.yarn.server.resourcemanager.scheduler.common.fica.FiCaSchedulerNode: Assigned container container_1399156864902_0001_01_000014 of capacity <memory:1024, vCores:1> on host nodea:56325, which currently has 3 containers, <memory:3072, vCores:3> used and <memory:5120, vCores:5> available
2014-05-03 23:05:56,090 INFO org.apache.hadoop.yarn.server.resourcemanager.scheduler.capacity.LeafQueue: assignedContainer application=application_1399156864902_0001 container=Container: [ContainerId: container_1399156864902_0001_01_000014, NodeId: nodea:56325, NodeHttpAddress: nodea:8042, Resource: <memory:1024, vCores:1>, Priority: 10, Token: Token { kind: ContainerToken, service: 10.0.0.182:56325 }, ] containerId=container_1399156864902_0001_01_000014 queue=default: capacity=1.0, absoluteCapacity=1.0, usedResources=<memory:10240, vCores:9>usedCapacity=0.3125, absoluteUsedCapacity=0.3125, numApps=1, numContainers=9 usedCapacity=0.3125 absoluteUsedCapacity=0.3125 used=<memory:10240, vCores:9> cluster=<memory:32768, vCores:32>
2014-05-03 23:05:56,090 INFO org.apache.hadoop.yarn.server.resourcemanager.scheduler.capacity.ParentQueue: Re-sorting assigned queue: root.default stats: default: capacity=1.0, absoluteCapacity=1.0, usedResources=<memory:11264, vCores:10>usedCapacity=0.34375, absoluteUsedCapacity=0.34375, numApps=1, numContainers=10
2014-05-03 23:05:56,090 INFO org.apache.hadoop.yarn.server.resourcemanager.scheduler.capacity.ParentQueue: assignedContainer queue=root usedCapacity=0.34375 absoluteUsedCapacity=0.34375 used=<memory:11264, vCores:10> cluster=<memory:32768, vCores:32>
2014-05-03 23:05:56,106 INFO org.apache.hadoop.yarn.server.resourcemanager.rmcontainer.RMContainerImpl: container_1399156864902_0001_01_000007 Container Transitioned from ACQUIRED to RUNNING
2014-05-03 23:05:56,106 INFO org.apache.hadoop.yarn.server.resourcemanager.rmcontainer.RMContainerImpl: container_1399156864902_0001_01_000011 Container Transitioned from ACQUIRED to RUNNING
2014-05-03 23:05:56,106 INFO org.apache.hadoop.yarn.server.resourcemanager.rmcontainer.RMContainerImpl: container_1399156864902_0001_01_000015 Container Transitioned from NEW to ALLOCATED
2014-05-03 23:05:56,106 INFO org.apache.hadoop.yarn.server.resourcemanager.RMAuditLogger: USER=ubuntu	OPERATION=AM Allocated Container	TARGET=SchedulerApp	RESULT=SUCCESS	APPID=application_1399156864902_0001	CONTAINERID=container_1399156864902_0001_01_000015
2014-05-03 23:05:56,106 INFO org.apache.hadoop.yarn.server.resourcemanager.scheduler.common.fica.FiCaSchedulerNode: Assigned container container_1399156864902_0001_01_000015 of capacity <memory:1024, vCores:1> on host nodec:54860, which currently has 3 containers, <memory:3072, vCores:3> used and <memory:5120, vCores:5> available
2014-05-03 23:05:56,107 INFO org.apache.hadoop.yarn.server.resourcemanager.scheduler.capacity.LeafQueue: assignedContainer application=application_1399156864902_0001 container=Container: [ContainerId: container_1399156864902_0001_01_000015, NodeId: nodec:54860, NodeHttpAddress: nodec:8042, Resource: <memory:1024, vCores:1>, Priority: 10, Token: Token { kind: ContainerToken, service: 10.0.0.245:54860 }, ] containerId=container_1399156864902_0001_01_000015 queue=default: capacity=1.0, absoluteCapacity=1.0, usedResources=<memory:11264, vCores:10>usedCapacity=0.34375, absoluteUsedCapacity=0.34375, numApps=1, numContainers=10 usedCapacity=0.34375 absoluteUsedCapacity=0.34375 used=<memory:11264, vCores:10> cluster=<memory:32768, vCores:32>
2014-05-03 23:05:56,107 INFO org.apache.hadoop.yarn.server.resourcemanager.scheduler.capacity.ParentQueue: Re-sorting assigned queue: root.default stats: default: capacity=1.0, absoluteCapacity=1.0, usedResources=<memory:12288, vCores:11>usedCapacity=0.375, absoluteUsedCapacity=0.375, numApps=1, numContainers=11
2014-05-03 23:05:56,107 INFO org.apache.hadoop.yarn.server.resourcemanager.scheduler.capacity.ParentQueue: assignedContainer queue=root usedCapacity=0.375 absoluteUsedCapacity=0.375 used=<memory:12288, vCores:11> cluster=<memory:32768, vCores:32>
2014-05-03 23:05:56,767 INFO org.apache.hadoop.yarn.server.resourcemanager.rmcontainer.RMContainerImpl: container_1399156864902_0001_01_000012 Container Transitioned from ACQUIRED to RUNNING
2014-05-03 23:05:56,769 INFO org.apache.hadoop.yarn.server.resourcemanager.rmcontainer.RMContainerImpl: container_1399156864902_0001_01_000016 Container Transitioned from NEW to ALLOCATED
2014-05-03 23:05:56,769 INFO org.apache.hadoop.yarn.server.resourcemanager.RMAuditLogger: USER=ubuntu	OPERATION=AM Allocated Container	TARGET=SchedulerApp	RESULT=SUCCESS	APPID=application_1399156864902_0001	CONTAINERID=container_1399156864902_0001_01_000016
2014-05-03 23:05:56,769 INFO org.apache.hadoop.yarn.server.resourcemanager.scheduler.common.fica.FiCaSchedulerNode: Assigned container container_1399156864902_0001_01_000016 of capacity <memory:1024, vCores:1> on host noded:50846, which currently has 3 containers, <memory:3072, vCores:3> used and <memory:5120, vCores:5> available
2014-05-03 23:05:56,769 INFO org.apache.hadoop.yarn.server.resourcemanager.scheduler.capacity.LeafQueue: assignedContainer application=application_1399156864902_0001 container=Container: [ContainerId: container_1399156864902_0001_01_000016, NodeId: noded:50846, NodeHttpAddress: noded:8042, Resource: <memory:1024, vCores:1>, Priority: 10, Token: Token { kind: ContainerToken, service: 10.0.0.244:50846 }, ] containerId=container_1399156864902_0001_01_000016 queue=default: capacity=1.0, absoluteCapacity=1.0, usedResources=<memory:12288, vCores:11>usedCapacity=0.375, absoluteUsedCapacity=0.375, numApps=1, numContainers=11 usedCapacity=0.375 absoluteUsedCapacity=0.375 used=<memory:12288, vCores:11> cluster=<memory:32768, vCores:32>
2014-05-03 23:05:56,769 INFO org.apache.hadoop.yarn.server.resourcemanager.scheduler.capacity.ParentQueue: Re-sorting assigned queue: root.default stats: default: capacity=1.0, absoluteCapacity=1.0, usedResources=<memory:13312, vCores:12>usedCapacity=0.40625, absoluteUsedCapacity=0.40625, numApps=1, numContainers=12
2014-05-03 23:05:56,769 INFO org.apache.hadoop.yarn.server.resourcemanager.scheduler.capacity.ParentQueue: assignedContainer queue=root usedCapacity=0.40625 absoluteUsedCapacity=0.40625 used=<memory:13312, vCores:12> cluster=<memory:32768, vCores:32>
2014-05-03 23:05:57,009 INFO org.apache.hadoop.yarn.server.resourcemanager.rmcontainer.RMContainerImpl: container_1399156864902_0001_01_000013 Container Transitioned from ACQUIRED to RUNNING
2014-05-03 23:05:57,009 INFO org.apache.hadoop.yarn.server.resourcemanager.rmcontainer.RMContainerImpl: container_1399156864902_0001_01_000017 Container Transitioned from NEW to ALLOCATED
2014-05-03 23:05:57,010 INFO org.apache.hadoop.yarn.server.resourcemanager.RMAuditLogger: USER=ubuntu	OPERATION=AM Allocated Container	TARGET=SchedulerApp	RESULT=SUCCESS	APPID=application_1399156864902_0001	CONTAINERID=container_1399156864902_0001_01_000017
2014-05-03 23:05:57,010 INFO org.apache.hadoop.yarn.server.resourcemanager.scheduler.common.fica.FiCaSchedulerNode: Assigned container container_1399156864902_0001_01_000017 of capacity <memory:1024, vCores:1> on host nodeb:55487, which currently has 4 containers, <memory:5120, vCores:4> used and <memory:3072, vCores:4> available
2014-05-03 23:05:57,010 INFO org.apache.hadoop.yarn.server.resourcemanager.scheduler.capacity.LeafQueue: assignedContainer application=application_1399156864902_0001 container=Container: [ContainerId: container_1399156864902_0001_01_000017, NodeId: nodeb:55487, NodeHttpAddress: nodeb:8042, Resource: <memory:1024, vCores:1>, Priority: 10, Token: Token { kind: ContainerToken, service: 10.0.0.243:55487 }, ] containerId=container_1399156864902_0001_01_000017 queue=default: capacity=1.0, absoluteCapacity=1.0, usedResources=<memory:13312, vCores:12>usedCapacity=0.40625, absoluteUsedCapacity=0.40625, numApps=1, numContainers=12 usedCapacity=0.40625 absoluteUsedCapacity=0.40625 used=<memory:13312, vCores:12> cluster=<memory:32768, vCores:32>
2014-05-03 23:05:57,010 INFO org.apache.hadoop.yarn.server.resourcemanager.scheduler.capacity.ParentQueue: Re-sorting assigned queue: root.default stats: default: capacity=1.0, absoluteCapacity=1.0, usedResources=<memory:14336, vCores:13>usedCapacity=0.4375, absoluteUsedCapacity=0.4375, numApps=1, numContainers=13
2014-05-03 23:05:57,010 INFO org.apache.hadoop.yarn.server.resourcemanager.scheduler.capacity.ParentQueue: assignedContainer queue=root usedCapacity=0.4375 absoluteUsedCapacity=0.4375 used=<memory:14336, vCores:13> cluster=<memory:32768, vCores:32>
2014-05-03 23:05:57,032 INFO org.apache.hadoop.yarn.server.resourcemanager.scheduler.AppSchedulingInfo: checking for deactivate... 
2014-05-03 23:05:57,033 INFO org.apache.hadoop.yarn.server.resourcemanager.rmcontainer.RMContainerImpl: container_1399156864902_0001_01_000014 Container Transitioned from ALLOCATED to ACQUIRED
2014-05-03 23:05:57,033 INFO org.apache.hadoop.yarn.server.resourcemanager.rmcontainer.RMContainerImpl: container_1399156864902_0001_01_000015 Container Transitioned from ALLOCATED to ACQUIRED
2014-05-03 23:05:57,033 INFO org.apache.hadoop.yarn.server.resourcemanager.rmcontainer.RMContainerImpl: container_1399156864902_0001_01_000016 Container Transitioned from ALLOCATED to ACQUIRED
2014-05-03 23:05:57,033 INFO org.apache.hadoop.yarn.server.resourcemanager.rmcontainer.RMContainerImpl: container_1399156864902_0001_01_000017 Container Transitioned from ALLOCATED to ACQUIRED
2014-05-03 23:05:58,040 INFO org.apache.hadoop.yarn.server.resourcemanager.rmcontainer.RMContainerImpl: container_1399156864902_0001_01_000014 Container Transitioned from ACQUIRED to RELEASED
2014-05-03 23:05:58,040 INFO org.apache.hadoop.yarn.server.resourcemanager.scheduler.common.fica.FiCaSchedulerApp: Completed container: container_1399156864902_0001_01_000014 in state: RELEASED event:RELEASED
2014-05-03 23:05:58,041 INFO org.apache.hadoop.yarn.server.resourcemanager.RMAuditLogger: USER=ubuntu	IP=10.0.0.243	OPERATION=AM Released Container	TARGET=SchedulerApp	RESULT=SUCCESS	APPID=application_1399156864902_0001	CONTAINERID=container_1399156864902_0001_01_000014
2014-05-03 23:05:58,041 INFO org.apache.hadoop.yarn.server.resourcemanager.scheduler.common.fica.FiCaSchedulerNode: Released container container_1399156864902_0001_01_000014 of capacity <memory:1024, vCores:1> on host nodea:56325, which currently has 2 containers, <memory:2048, vCores:2> used and <memory:6144, vCores:6> available, release resources=true
2014-05-03 23:05:58,041 INFO org.apache.hadoop.yarn.server.resourcemanager.scheduler.capacity.LeafQueue: default used=<memory:13312, vCores:12> numContainers=12 user=ubuntu user-resources=<memory:13312, vCores:12>
2014-05-03 23:05:58,041 INFO org.apache.hadoop.yarn.server.resourcemanager.scheduler.capacity.LeafQueue: completedContainer container=Container: [ContainerId: container_1399156864902_0001_01_000014, NodeId: nodea:56325, NodeHttpAddress: nodea:8042, Resource: <memory:1024, vCores:1>, Priority: 10, Token: Token { kind: ContainerToken, service: 10.0.0.182:56325 }, ] resource=<memory:1024, vCores:1> queue=default: capacity=1.0, absoluteCapacity=1.0, usedResources=<memory:13312, vCores:12>usedCapacity=0.40625, absoluteUsedCapacity=0.40625, numApps=1, numContainers=12 usedCapacity=0.40625 absoluteUsedCapacity=0.40625 used=<memory:13312, vCores:12> cluster=<memory:32768, vCores:32>
2014-05-03 23:05:58,042 INFO org.apache.hadoop.yarn.server.resourcemanager.scheduler.capacity.ParentQueue: completedContainer queue=root usedCapacity=0.40625 absoluteUsedCapacity=0.40625 used=<memory:13312, vCores:12> cluster=<memory:32768, vCores:32>
2014-05-03 23:05:58,042 INFO org.apache.hadoop.yarn.server.resourcemanager.scheduler.capacity.ParentQueue: Re-sorting completed queue: root.default stats: default: capacity=1.0, absoluteCapacity=1.0, usedResources=<memory:13312, vCores:12>usedCapacity=0.40625, absoluteUsedCapacity=0.40625, numApps=1, numContainers=12
2014-05-03 23:05:58,042 INFO org.apache.hadoop.yarn.server.resourcemanager.scheduler.capacity.CapacityScheduler: Application appattempt_1399156864902_0001_000001 released container container_1399156864902_0001_01_000014 on node: host: nodea:56325 #containers=2 available=6144 used=2048 with event: RELEASED
2014-05-03 23:05:58,042 INFO org.apache.hadoop.yarn.server.resourcemanager.rmcontainer.RMContainerImpl: container_1399156864902_0001_01_000015 Container Transitioned from ACQUIRED to RELEASED
2014-05-03 23:05:58,042 INFO org.apache.hadoop.yarn.server.resourcemanager.scheduler.common.fica.FiCaSchedulerApp: Completed container: container_1399156864902_0001_01_000015 in state: RELEASED event:RELEASED
2014-05-03 23:05:58,042 INFO org.apache.hadoop.yarn.server.resourcemanager.RMAuditLogger: USER=ubuntu	IP=10.0.0.243	OPERATION=AM Released Container	TARGET=SchedulerApp	RESULT=SUCCESS	APPID=application_1399156864902_0001	CONTAINERID=container_1399156864902_0001_01_000015
2014-05-03 23:05:58,043 INFO org.apache.hadoop.yarn.server.resourcemanager.scheduler.common.fica.FiCaSchedulerNode: Released container container_1399156864902_0001_01_000015 of capacity <memory:1024, vCores:1> on host nodec:54860, which currently has 2 containers, <memory:2048, vCores:2> used and <memory:6144, vCores:6> available, release resources=true
2014-05-03 23:05:58,043 INFO org.apache.hadoop.yarn.server.resourcemanager.scheduler.capacity.LeafQueue: default used=<memory:12288, vCores:11> numContainers=11 user=ubuntu user-resources=<memory:12288, vCores:11>
2014-05-03 23:05:58,043 INFO org.apache.hadoop.yarn.server.resourcemanager.scheduler.capacity.LeafQueue: completedContainer container=Container: [ContainerId: container_1399156864902_0001_01_000015, NodeId: nodec:54860, NodeHttpAddress: nodec:8042, Resource: <memory:1024, vCores:1>, Priority: 10, Token: Token { kind: ContainerToken, service: 10.0.0.245:54860 }, ] resource=<memory:1024, vCores:1> queue=default: capacity=1.0, absoluteCapacity=1.0, usedResources=<memory:12288, vCores:11>usedCapacity=0.375, absoluteUsedCapacity=0.375, numApps=1, numContainers=11 usedCapacity=0.375 absoluteUsedCapacity=0.375 used=<memory:12288, vCores:11> cluster=<memory:32768, vCores:32>
2014-05-03 23:05:58,043 INFO org.apache.hadoop.yarn.server.resourcemanager.scheduler.capacity.ParentQueue: completedContainer queue=root usedCapacity=0.375 absoluteUsedCapacity=0.375 used=<memory:12288, vCores:11> cluster=<memory:32768, vCores:32>
2014-05-03 23:05:58,043 INFO org.apache.hadoop.yarn.server.resourcemanager.scheduler.capacity.ParentQueue: Re-sorting completed queue: root.default stats: default: capacity=1.0, absoluteCapacity=1.0, usedResources=<memory:12288, vCores:11>usedCapacity=0.375, absoluteUsedCapacity=0.375, numApps=1, numContainers=11
2014-05-03 23:05:58,043 INFO org.apache.hadoop.yarn.server.resourcemanager.scheduler.capacity.CapacityScheduler: Application appattempt_1399156864902_0001_000001 released container container_1399156864902_0001_01_000015 on node: host: nodec:54860 #containers=2 available=6144 used=2048 with event: RELEASED
2014-05-03 23:05:58,044 INFO org.apache.hadoop.yarn.server.resourcemanager.rmcontainer.RMContainerImpl: container_1399156864902_0001_01_000016 Container Transitioned from ACQUIRED to RELEASED
2014-05-03 23:05:58,044 INFO org.apache.hadoop.yarn.server.resourcemanager.scheduler.common.fica.FiCaSchedulerApp: Completed container: container_1399156864902_0001_01_000016 in state: RELEASED event:RELEASED
2014-05-03 23:05:58,044 INFO org.apache.hadoop.yarn.server.resourcemanager.RMAuditLogger: USER=ubuntu	IP=10.0.0.243	OPERATION=AM Released Container	TARGET=SchedulerApp	RESULT=SUCCESS	APPID=application_1399156864902_0001	CONTAINERID=container_1399156864902_0001_01_000016
2014-05-03 23:05:58,044 INFO org.apache.hadoop.yarn.server.resourcemanager.scheduler.common.fica.FiCaSchedulerNode: Released container container_1399156864902_0001_01_000016 of capacity <memory:1024, vCores:1> on host noded:50846, which currently has 2 containers, <memory:2048, vCores:2> used and <memory:6144, vCores:6> available, release resources=true
2014-05-03 23:05:58,044 INFO org.apache.hadoop.yarn.server.resourcemanager.scheduler.capacity.LeafQueue: default used=<memory:11264, vCores:10> numContainers=10 user=ubuntu user-resources=<memory:11264, vCores:10>
2014-05-03 23:05:58,044 INFO org.apache.hadoop.yarn.server.resourcemanager.scheduler.capacity.LeafQueue: completedContainer container=Container: [ContainerId: container_1399156864902_0001_01_000016, NodeId: noded:50846, NodeHttpAddress: noded:8042, Resource: <memory:1024, vCores:1>, Priority: 10, Token: Token { kind: ContainerToken, service: 10.0.0.244:50846 }, ] resource=<memory:1024, vCores:1> queue=default: capacity=1.0, absoluteCapacity=1.0, usedResources=<memory:11264, vCores:10>usedCapacity=0.34375, absoluteUsedCapacity=0.34375, numApps=1, numContainers=10 usedCapacity=0.34375 absoluteUsedCapacity=0.34375 used=<memory:11264, vCores:10> cluster=<memory:32768, vCores:32>
2014-05-03 23:05:58,045 INFO org.apache.hadoop.yarn.server.resourcemanager.scheduler.capacity.ParentQueue: completedContainer queue=root usedCapacity=0.34375 absoluteUsedCapacity=0.34375 used=<memory:11264, vCores:10> cluster=<memory:32768, vCores:32>
2014-05-03 23:05:58,045 INFO org.apache.hadoop.yarn.server.resourcemanager.scheduler.capacity.ParentQueue: Re-sorting completed queue: root.default stats: default: capacity=1.0, absoluteCapacity=1.0, usedResources=<memory:11264, vCores:10>usedCapacity=0.34375, absoluteUsedCapacity=0.34375, numApps=1, numContainers=10
2014-05-03 23:05:58,045 INFO org.apache.hadoop.yarn.server.resourcemanager.scheduler.capacity.CapacityScheduler: Application appattempt_1399156864902_0001_000001 released container container_1399156864902_0001_01_000016 on node: host: noded:50846 #containers=2 available=6144 used=2048 with event: RELEASED
2014-05-03 23:05:58,045 INFO org.apache.hadoop.yarn.server.resourcemanager.rmcontainer.RMContainerImpl: container_1399156864902_0001_01_000017 Container Transitioned from ACQUIRED to RELEASED
2014-05-03 23:05:58,045 INFO org.apache.hadoop.yarn.server.resourcemanager.scheduler.common.fica.FiCaSchedulerApp: Completed container: container_1399156864902_0001_01_000017 in state: RELEASED event:RELEASED
2014-05-03 23:05:58,045 INFO org.apache.hadoop.yarn.server.resourcemanager.RMAuditLogger: USER=ubuntu	IP=10.0.0.243	OPERATION=AM Released Container	TARGET=SchedulerApp	RESULT=SUCCESS	APPID=application_1399156864902_0001	CONTAINERID=container_1399156864902_0001_01_000017
2014-05-03 23:05:58,046 INFO org.apache.hadoop.yarn.server.resourcemanager.scheduler.common.fica.FiCaSchedulerNode: Released container container_1399156864902_0001_01_000017 of capacity <memory:1024, vCores:1> on host nodeb:55487, which currently has 3 containers, <memory:4096, vCores:3> used and <memory:4096, vCores:5> available, release resources=true
2014-05-03 23:05:58,046 INFO org.apache.hadoop.yarn.server.resourcemanager.scheduler.capacity.LeafQueue: default used=<memory:10240, vCores:9> numContainers=9 user=ubuntu user-resources=<memory:10240, vCores:9>
2014-05-03 23:05:58,046 INFO org.apache.hadoop.yarn.server.resourcemanager.scheduler.capacity.LeafQueue: completedContainer container=Container: [ContainerId: container_1399156864902_0001_01_000017, NodeId: nodeb:55487, NodeHttpAddress: nodeb:8042, Resource: <memory:1024, vCores:1>, Priority: 10, Token: Token { kind: ContainerToken, service: 10.0.0.243:55487 }, ] resource=<memory:1024, vCores:1> queue=default: capacity=1.0, absoluteCapacity=1.0, usedResources=<memory:10240, vCores:9>usedCapacity=0.3125, absoluteUsedCapacity=0.3125, numApps=1, numContainers=9 usedCapacity=0.3125 absoluteUsedCapacity=0.3125 used=<memory:10240, vCores:9> cluster=<memory:32768, vCores:32>
2014-05-03 23:05:58,046 INFO org.apache.hadoop.yarn.server.resourcemanager.scheduler.capacity.ParentQueue: completedContainer queue=root usedCapacity=0.3125 absoluteUsedCapacity=0.3125 used=<memory:10240, vCores:9> cluster=<memory:32768, vCores:32>
2014-05-03 23:05:58,046 INFO org.apache.hadoop.yarn.server.resourcemanager.scheduler.capacity.ParentQueue: Re-sorting completed queue: root.default stats: default: capacity=1.0, absoluteCapacity=1.0, usedResources=<memory:10240, vCores:9>usedCapacity=0.3125, absoluteUsedCapacity=0.3125, numApps=1, numContainers=9
2014-05-03 23:05:58,046 INFO org.apache.hadoop.yarn.server.resourcemanager.scheduler.capacity.CapacityScheduler: Application appattempt_1399156864902_0001_000001 released container container_1399156864902_0001_01_000017 on node: host: nodeb:55487 #containers=3 available=4096 used=4096 with event: RELEASED
2014-05-03 23:07:46,344 INFO org.apache.hadoop.yarn.server.resourcemanager.rmcontainer.RMContainerImpl: container_1399156864902_0001_01_000008 Container Transitioned from RUNNING to COMPLETED
2014-05-03 23:07:46,344 INFO org.apache.hadoop.yarn.server.resourcemanager.scheduler.common.fica.FiCaSchedulerApp: Completed container: container_1399156864902_0001_01_000008 in state: COMPLETED event:FINISHED
2014-05-03 23:07:46,344 INFO org.apache.hadoop.yarn.server.resourcemanager.RMAuditLogger: USER=ubuntu	OPERATION=AM Released Container	TARGET=SchedulerApp	RESULT=SUCCESS	APPID=application_1399156864902_0001	CONTAINERID=container_1399156864902_0001_01_000008
2014-05-03 23:07:46,344 INFO org.apache.hadoop.yarn.server.resourcemanager.scheduler.common.fica.FiCaSchedulerNode: Released container container_1399156864902_0001_01_000008 of capacity <memory:1024, vCores:1> on host noded:50846, which currently has 1 containers, <memory:1024, vCores:1> used and <memory:7168, vCores:7> available, release resources=true
2014-05-03 23:07:46,345 INFO org.apache.hadoop.yarn.server.resourcemanager.scheduler.capacity.LeafQueue: default used=<memory:9216, vCores:8> numContainers=8 user=ubuntu user-resources=<memory:9216, vCores:8>
2014-05-03 23:07:46,345 INFO org.apache.hadoop.yarn.server.resourcemanager.scheduler.capacity.LeafQueue: completedContainer container=Container: [ContainerId: container_1399156864902_0001_01_000008, NodeId: noded:50846, NodeHttpAddress: noded:8042, Resource: <memory:1024, vCores:1>, Priority: 10, Token: Token { kind: ContainerToken, service: 10.0.0.244:50846 }, ] resource=<memory:1024, vCores:1> queue=default: capacity=1.0, absoluteCapacity=1.0, usedResources=<memory:9216, vCores:8>usedCapacity=0.28125, absoluteUsedCapacity=0.28125, numApps=1, numContainers=8 usedCapacity=0.28125 absoluteUsedCapacity=0.28125 used=<memory:9216, vCores:8> cluster=<memory:32768, vCores:32>
2014-05-03 23:07:46,345 INFO org.apache.hadoop.yarn.server.resourcemanager.scheduler.capacity.ParentQueue: completedContainer queue=root usedCapacity=0.28125 absoluteUsedCapacity=0.28125 used=<memory:9216, vCores:8> cluster=<memory:32768, vCores:32>
2014-05-03 23:07:46,345 INFO org.apache.hadoop.yarn.server.resourcemanager.scheduler.capacity.ParentQueue: Re-sorting completed queue: root.default stats: default: capacity=1.0, absoluteCapacity=1.0, usedResources=<memory:9216, vCores:8>usedCapacity=0.28125, absoluteUsedCapacity=0.28125, numApps=1, numContainers=8
2014-05-03 23:07:46,345 INFO org.apache.hadoop.yarn.server.resourcemanager.scheduler.capacity.CapacityScheduler: Application appattempt_1399156864902_0001_000001 released container container_1399156864902_0001_01_000008 on node: host: noded:50846 #containers=1 available=7168 used=1024 with event: FINISHED
2014-05-03 23:07:47,346 INFO org.apache.hadoop.yarn.server.resourcemanager.rmcontainer.RMContainerImpl: container_1399156864902_0001_01_000012 Container Transitioned from RUNNING to COMPLETED
2014-05-03 23:07:47,346 INFO org.apache.hadoop.yarn.server.resourcemanager.scheduler.common.fica.FiCaSchedulerApp: Completed container: container_1399156864902_0001_01_000012 in state: COMPLETED event:FINISHED
2014-05-03 23:07:47,346 INFO org.apache.hadoop.yarn.server.resourcemanager.RMAuditLogger: USER=ubuntu	OPERATION=AM Released Container	TARGET=SchedulerApp	RESULT=SUCCESS	APPID=application_1399156864902_0001	CONTAINERID=container_1399156864902_0001_01_000012
2014-05-03 23:07:47,347 INFO org.apache.hadoop.yarn.server.resourcemanager.scheduler.common.fica.FiCaSchedulerNode: Released container container_1399156864902_0001_01_000012 of capacity <memory:1024, vCores:1> on host noded:50846, which currently has 0 containers, <memory:0, vCores:0> used and <memory:8192, vCores:8> available, release resources=true
2014-05-03 23:07:47,347 INFO org.apache.hadoop.yarn.server.resourcemanager.scheduler.capacity.LeafQueue: default used=<memory:8192, vCores:7> numContainers=7 user=ubuntu user-resources=<memory:8192, vCores:7>
2014-05-03 23:07:47,347 INFO org.apache.hadoop.yarn.server.resourcemanager.scheduler.capacity.LeafQueue: completedContainer container=Container: [ContainerId: container_1399156864902_0001_01_000012, NodeId: noded:50846, NodeHttpAddress: noded:8042, Resource: <memory:1024, vCores:1>, Priority: 10, Token: Token { kind: ContainerToken, service: 10.0.0.244:50846 }, ] resource=<memory:1024, vCores:1> queue=default: capacity=1.0, absoluteCapacity=1.0, usedResources=<memory:8192, vCores:7>usedCapacity=0.25, absoluteUsedCapacity=0.25, numApps=1, numContainers=7 usedCapacity=0.25 absoluteUsedCapacity=0.25 used=<memory:8192, vCores:7> cluster=<memory:32768, vCores:32>
2014-05-03 23:07:47,347 INFO org.apache.hadoop.yarn.server.resourcemanager.scheduler.capacity.ParentQueue: completedContainer queue=root usedCapacity=0.25 absoluteUsedCapacity=0.25 used=<memory:8192, vCores:7> cluster=<memory:32768, vCores:32>
2014-05-03 23:07:47,347 INFO org.apache.hadoop.yarn.server.resourcemanager.scheduler.capacity.ParentQueue: Re-sorting completed queue: root.default stats: default: capacity=1.0, absoluteCapacity=1.0, usedResources=<memory:8192, vCores:7>usedCapacity=0.25, absoluteUsedCapacity=0.25, numApps=1, numContainers=7
2014-05-03 23:07:47,347 INFO org.apache.hadoop.yarn.server.resourcemanager.scheduler.capacity.CapacityScheduler: Application appattempt_1399156864902_0001_000001 released container container_1399156864902_0001_01_000012 on node: host: noded:50846 #containers=0 available=8192 used=0 with event: FINISHED
2014-05-03 23:08:15,291 INFO org.apache.hadoop.yarn.server.resourcemanager.rmcontainer.RMContainerImpl: container_1399156864902_0001_01_000013 Container Transitioned from RUNNING to COMPLETED
2014-05-03 23:08:15,291 INFO org.apache.hadoop.yarn.server.resourcemanager.scheduler.common.fica.FiCaSchedulerApp: Completed container: container_1399156864902_0001_01_000013 in state: COMPLETED event:FINISHED
2014-05-03 23:08:15,292 INFO org.apache.hadoop.yarn.server.resourcemanager.RMAuditLogger: USER=ubuntu	OPERATION=AM Released Container	TARGET=SchedulerApp	RESULT=SUCCESS	APPID=application_1399156864902_0001	CONTAINERID=container_1399156864902_0001_01_000013
2014-05-03 23:08:15,292 INFO org.apache.hadoop.yarn.server.resourcemanager.scheduler.common.fica.FiCaSchedulerNode: Released container container_1399156864902_0001_01_000013 of capacity <memory:1024, vCores:1> on host nodeb:55487, which currently has 2 containers, <memory:3072, vCores:2> used and <memory:5120, vCores:6> available, release resources=true
2014-05-03 23:08:15,292 INFO org.apache.hadoop.yarn.server.resourcemanager.scheduler.capacity.LeafQueue: default used=<memory:7168, vCores:6> numContainers=6 user=ubuntu user-resources=<memory:7168, vCores:6>
2014-05-03 23:08:15,292 INFO org.apache.hadoop.yarn.server.resourcemanager.scheduler.capacity.LeafQueue: completedContainer container=Container: [ContainerId: container_1399156864902_0001_01_000013, NodeId: nodeb:55487, NodeHttpAddress: nodeb:8042, Resource: <memory:1024, vCores:1>, Priority: 10, Token: Token { kind: ContainerToken, service: 10.0.0.243:55487 }, ] resource=<memory:1024, vCores:1> queue=default: capacity=1.0, absoluteCapacity=1.0, usedResources=<memory:7168, vCores:6>usedCapacity=0.21875, absoluteUsedCapacity=0.21875, numApps=1, numContainers=6 usedCapacity=0.21875 absoluteUsedCapacity=0.21875 used=<memory:7168, vCores:6> cluster=<memory:32768, vCores:32>
2014-05-03 23:08:15,292 INFO org.apache.hadoop.yarn.server.resourcemanager.scheduler.capacity.ParentQueue: completedContainer queue=root usedCapacity=0.21875 absoluteUsedCapacity=0.21875 used=<memory:7168, vCores:6> cluster=<memory:32768, vCores:32>
2014-05-03 23:08:15,292 INFO org.apache.hadoop.yarn.server.resourcemanager.scheduler.capacity.ParentQueue: Re-sorting completed queue: root.default stats: default: capacity=1.0, absoluteCapacity=1.0, usedResources=<memory:7168, vCores:6>usedCapacity=0.21875, absoluteUsedCapacity=0.21875, numApps=1, numContainers=6
2014-05-03 23:08:15,292 INFO org.apache.hadoop.yarn.server.resourcemanager.scheduler.capacity.CapacityScheduler: Application appattempt_1399156864902_0001_000001 released container container_1399156864902_0001_01_000013 on node: host: nodeb:55487 #containers=2 available=5120 used=3072 with event: FINISHED
2014-05-03 23:08:15,453 INFO org.apache.hadoop.yarn.server.resourcemanager.rmcontainer.RMContainerImpl: container_1399156864902_0001_01_000010 Container Transitioned from RUNNING to COMPLETED
2014-05-03 23:08:15,453 INFO org.apache.hadoop.yarn.server.resourcemanager.scheduler.common.fica.FiCaSchedulerApp: Completed container: container_1399156864902_0001_01_000010 in state: COMPLETED event:FINISHED
2014-05-03 23:08:15,453 INFO org.apache.hadoop.yarn.server.resourcemanager.RMAuditLogger: USER=ubuntu	OPERATION=AM Released Container	TARGET=SchedulerApp	RESULT=SUCCESS	APPID=application_1399156864902_0001	CONTAINERID=container_1399156864902_0001_01_000010
2014-05-03 23:08:15,453 INFO org.apache.hadoop.yarn.server.resourcemanager.scheduler.common.fica.FiCaSchedulerNode: Released container container_1399156864902_0001_01_000010 of capacity <memory:1024, vCores:1> on host nodea:56325, which currently has 1 containers, <memory:1024, vCores:1> used and <memory:7168, vCores:7> available, release resources=true
2014-05-03 23:08:15,453 INFO org.apache.hadoop.yarn.server.resourcemanager.scheduler.capacity.LeafQueue: default used=<memory:6144, vCores:5> numContainers=5 user=ubuntu user-resources=<memory:6144, vCores:5>
2014-05-03 23:08:15,453 INFO org.apache.hadoop.yarn.server.resourcemanager.scheduler.capacity.LeafQueue: completedContainer container=Container: [ContainerId: container_1399156864902_0001_01_000010, NodeId: nodea:56325, NodeHttpAddress: nodea:8042, Resource: <memory:1024, vCores:1>, Priority: 10, Token: Token { kind: ContainerToken, service: 10.0.0.182:56325 }, ] resource=<memory:1024, vCores:1> queue=default: capacity=1.0, absoluteCapacity=1.0, usedResources=<memory:6144, vCores:5>usedCapacity=0.1875, absoluteUsedCapacity=0.1875, numApps=1, numContainers=5 usedCapacity=0.1875 absoluteUsedCapacity=0.1875 used=<memory:6144, vCores:5> cluster=<memory:32768, vCores:32>
2014-05-03 23:08:15,453 INFO org.apache.hadoop.yarn.server.resourcemanager.scheduler.capacity.ParentQueue: completedContainer queue=root usedCapacity=0.1875 absoluteUsedCapacity=0.1875 used=<memory:6144, vCores:5> cluster=<memory:32768, vCores:32>
2014-05-03 23:08:15,453 INFO org.apache.hadoop.yarn.server.resourcemanager.scheduler.capacity.ParentQueue: Re-sorting completed queue: root.default stats: default: capacity=1.0, absoluteCapacity=1.0, usedResources=<memory:6144, vCores:5>usedCapacity=0.1875, absoluteUsedCapacity=0.1875, numApps=1, numContainers=5
2014-05-03 23:08:15,454 INFO org.apache.hadoop.yarn.server.resourcemanager.scheduler.capacity.CapacityScheduler: Application appattempt_1399156864902_0001_000001 released container container_1399156864902_0001_01_000010 on node: host: nodea:56325 #containers=1 available=7168 used=1024 with event: FINISHED
2014-05-03 23:08:15,857 INFO org.apache.hadoop.yarn.server.resourcemanager.rmapp.attempt.RMAppAttemptImpl: appattempt_1399156864902_0001_000001 State change from RUNNING to FINISHING
2014-05-03 23:08:15,866 INFO org.apache.hadoop.yarn.server.resourcemanager.rmapp.RMAppImpl: Removing application with id application_1399156864902_0001
2014-05-03 23:08:15,867 INFO org.apache.hadoop.yarn.server.resourcemanager.rmapp.RMAppImpl: application_1399156864902_0001 State change from RUNNING to REMOVING
2014-05-03 23:08:15,867 INFO org.apache.hadoop.yarn.server.resourcemanager.recovery.RMStateStore: Removing info for app: application_1399156864902_0001
2014-05-03 23:08:15,867 INFO org.apache.hadoop.yarn.server.resourcemanager.rmapp.RMAppImpl: application_1399156864902_0001 State change from REMOVING to FINISHING
2014-05-03 23:08:15,950 INFO org.apache.hadoop.yarn.server.resourcemanager.rmcontainer.RMContainerImpl: container_1399156864902_0001_01_000007 Container Transitioned from RUNNING to COMPLETED
2014-05-03 23:08:15,950 INFO org.apache.hadoop.yarn.server.resourcemanager.scheduler.common.fica.FiCaSchedulerApp: Completed container: container_1399156864902_0001_01_000007 in state: COMPLETED event:FINISHED
2014-05-03 23:08:15,951 INFO org.apache.hadoop.yarn.server.resourcemanager.RMAuditLogger: USER=ubuntu	OPERATION=AM Released Container	TARGET=SchedulerApp	RESULT=SUCCESS	APPID=application_1399156864902_0001	CONTAINERID=container_1399156864902_0001_01_000007
2014-05-03 23:08:15,951 INFO org.apache.hadoop.yarn.server.resourcemanager.scheduler.common.fica.FiCaSchedulerNode: Released container container_1399156864902_0001_01_000007 of capacity <memory:1024, vCores:1> on host nodec:54860, which currently has 1 containers, <memory:1024, vCores:1> used and <memory:7168, vCores:7> available, release resources=true
2014-05-03 23:08:15,951 INFO org.apache.hadoop.yarn.server.resourcemanager.scheduler.capacity.LeafQueue: default used=<memory:5120, vCores:4> numContainers=4 user=ubuntu user-resources=<memory:5120, vCores:4>
2014-05-03 23:08:15,951 INFO org.apache.hadoop.yarn.server.resourcemanager.scheduler.capacity.LeafQueue: completedContainer container=Container: [ContainerId: container_1399156864902_0001_01_000007, NodeId: nodec:54860, NodeHttpAddress: nodec:8042, Resource: <memory:1024, vCores:1>, Priority: 10, Token: Token { kind: ContainerToken, service: 10.0.0.245:54860 }, ] resource=<memory:1024, vCores:1> queue=default: capacity=1.0, absoluteCapacity=1.0, usedResources=<memory:5120, vCores:4>usedCapacity=0.15625, absoluteUsedCapacity=0.15625, numApps=1, numContainers=4 usedCapacity=0.15625 absoluteUsedCapacity=0.15625 used=<memory:5120, vCores:4> cluster=<memory:32768, vCores:32>
2014-05-03 23:08:15,951 INFO org.apache.hadoop.yarn.server.resourcemanager.scheduler.capacity.ParentQueue: completedContainer queue=root usedCapacity=0.15625 absoluteUsedCapacity=0.15625 used=<memory:5120, vCores:4> cluster=<memory:32768, vCores:32>
2014-05-03 23:08:15,951 INFO org.apache.hadoop.yarn.server.resourcemanager.scheduler.capacity.ParentQueue: Re-sorting completed queue: root.default stats: default: capacity=1.0, absoluteCapacity=1.0, usedResources=<memory:5120, vCores:4>usedCapacity=0.15625, absoluteUsedCapacity=0.15625, numApps=1, numContainers=4
2014-05-03 23:08:15,951 INFO org.apache.hadoop.yarn.server.resourcemanager.scheduler.capacity.CapacityScheduler: Application appattempt_1399156864902_0001_000001 released container container_1399156864902_0001_01_000007 on node: host: nodec:54860 #containers=1 available=7168 used=1024 with event: FINISHED
2014-05-03 23:08:15,951 INFO org.apache.hadoop.yarn.server.resourcemanager.rmcontainer.RMContainerImpl: container_1399156864902_0001_01_000011 Container Transitioned from RUNNING to COMPLETED
2014-05-03 23:08:15,951 INFO org.apache.hadoop.yarn.server.resourcemanager.scheduler.common.fica.FiCaSchedulerApp: Completed container: container_1399156864902_0001_01_000011 in state: COMPLETED event:FINISHED
2014-05-03 23:08:15,951 INFO org.apache.hadoop.yarn.server.resourcemanager.RMAuditLogger: USER=ubuntu	OPERATION=AM Released Container	TARGET=SchedulerApp	RESULT=SUCCESS	APPID=application_1399156864902_0001	CONTAINERID=container_1399156864902_0001_01_000011
2014-05-03 23:08:15,951 INFO org.apache.hadoop.yarn.server.resourcemanager.scheduler.common.fica.FiCaSchedulerNode: Released container container_1399156864902_0001_01_000011 of capacity <memory:1024, vCores:1> on host nodec:54860, which currently has 0 containers, <memory:0, vCores:0> used and <memory:8192, vCores:8> available, release resources=true
2014-05-03 23:08:15,951 INFO org.apache.hadoop.yarn.server.resourcemanager.scheduler.capacity.LeafQueue: default used=<memory:4096, vCores:3> numContainers=3 user=ubuntu user-resources=<memory:4096, vCores:3>
2014-05-03 23:08:15,952 INFO org.apache.hadoop.yarn.server.resourcemanager.scheduler.capacity.LeafQueue: completedContainer container=Container: [ContainerId: container_1399156864902_0001_01_000011, NodeId: nodec:54860, NodeHttpAddress: nodec:8042, Resource: <memory:1024, vCores:1>, Priority: 10, Token: Token { kind: ContainerToken, service: 10.0.0.245:54860 }, ] resource=<memory:1024, vCores:1> queue=default: capacity=1.0, absoluteCapacity=1.0, usedResources=<memory:4096, vCores:3>usedCapacity=0.125, absoluteUsedCapacity=0.125, numApps=1, numContainers=3 usedCapacity=0.125 absoluteUsedCapacity=0.125 used=<memory:4096, vCores:3> cluster=<memory:32768, vCores:32>
2014-05-03 23:08:15,952 INFO org.apache.hadoop.yarn.server.resourcemanager.scheduler.capacity.ParentQueue: completedContainer queue=root usedCapacity=0.125 absoluteUsedCapacity=0.125 used=<memory:4096, vCores:3> cluster=<memory:32768, vCores:32>
2014-05-03 23:08:15,952 INFO org.apache.hadoop.yarn.server.resourcemanager.scheduler.capacity.ParentQueue: Re-sorting completed queue: root.default stats: default: capacity=1.0, absoluteCapacity=1.0, usedResources=<memory:4096, vCores:3>usedCapacity=0.125, absoluteUsedCapacity=0.125, numApps=1, numContainers=3
2014-05-03 23:08:15,952 INFO org.apache.hadoop.yarn.server.resourcemanager.scheduler.capacity.CapacityScheduler: Application appattempt_1399156864902_0001_000001 released container container_1399156864902_0001_01_000011 on node: host: nodec:54860 #containers=0 available=8192 used=0 with event: FINISHED
2014-05-03 23:08:16,301 INFO org.apache.hadoop.yarn.server.resourcemanager.rmcontainer.RMContainerImpl: container_1399156864902_0001_01_000009 Container Transitioned from RUNNING to COMPLETED
2014-05-03 23:08:16,301 INFO org.apache.hadoop.yarn.server.resourcemanager.scheduler.common.fica.FiCaSchedulerApp: Completed container: container_1399156864902_0001_01_000009 in state: COMPLETED event:FINISHED
2014-05-03 23:08:16,301 INFO org.apache.hadoop.yarn.server.resourcemanager.RMAuditLogger: USER=ubuntu	OPERATION=AM Released Container	TARGET=SchedulerApp	RESULT=SUCCESS	APPID=application_1399156864902_0001	CONTAINERID=container_1399156864902_0001_01_000009
2014-05-03 23:08:16,301 INFO org.apache.hadoop.yarn.server.resourcemanager.scheduler.common.fica.FiCaSchedulerNode: Released container container_1399156864902_0001_01_000009 of capacity <memory:1024, vCores:1> on host nodeb:55487, which currently has 1 containers, <memory:2048, vCores:1> used and <memory:6144, vCores:7> available, release resources=true
2014-05-03 23:08:16,301 INFO org.apache.hadoop.yarn.server.resourcemanager.scheduler.capacity.LeafQueue: default used=<memory:3072, vCores:2> numContainers=2 user=ubuntu user-resources=<memory:3072, vCores:2>
2014-05-03 23:08:16,301 INFO org.apache.hadoop.yarn.server.resourcemanager.scheduler.capacity.LeafQueue: completedContainer container=Container: [ContainerId: container_1399156864902_0001_01_000009, NodeId: nodeb:55487, NodeHttpAddress: nodeb:8042, Resource: <memory:1024, vCores:1>, Priority: 10, Token: Token { kind: ContainerToken, service: 10.0.0.243:55487 }, ] resource=<memory:1024, vCores:1> queue=default: capacity=1.0, absoluteCapacity=1.0, usedResources=<memory:3072, vCores:2>usedCapacity=0.09375, absoluteUsedCapacity=0.09375, numApps=1, numContainers=2 usedCapacity=0.09375 absoluteUsedCapacity=0.09375 used=<memory:3072, vCores:2> cluster=<memory:32768, vCores:32>
2014-05-03 23:08:16,302 INFO org.apache.hadoop.yarn.server.resourcemanager.scheduler.capacity.ParentQueue: completedContainer queue=root usedCapacity=0.09375 absoluteUsedCapacity=0.09375 used=<memory:3072, vCores:2> cluster=<memory:32768, vCores:32>
2014-05-03 23:08:16,302 INFO org.apache.hadoop.yarn.server.resourcemanager.scheduler.capacity.ParentQueue: Re-sorting completed queue: root.default stats: default: capacity=1.0, absoluteCapacity=1.0, usedResources=<memory:3072, vCores:2>usedCapacity=0.09375, absoluteUsedCapacity=0.09375, numApps=1, numContainers=2
2014-05-03 23:08:16,302 INFO org.apache.hadoop.yarn.server.resourcemanager.scheduler.capacity.CapacityScheduler: Application appattempt_1399156864902_0001_000001 released container container_1399156864902_0001_01_000009 on node: host: nodeb:55487 #containers=1 available=6144 used=2048 with event: FINISHED
2014-05-03 23:08:16,696 INFO org.apache.hadoop.yarn.server.resourcemanager.rmcontainer.RMContainerImpl: container_1399156864902_0001_01_000006 Container Transitioned from RUNNING to COMPLETED
2014-05-03 23:08:16,696 INFO org.apache.hadoop.yarn.server.resourcemanager.scheduler.common.fica.FiCaSchedulerApp: Completed container: container_1399156864902_0001_01_000006 in state: COMPLETED event:FINISHED
2014-05-03 23:08:16,696 INFO org.apache.hadoop.yarn.server.resourcemanager.RMAuditLogger: USER=ubuntu	OPERATION=AM Released Container	TARGET=SchedulerApp	RESULT=SUCCESS	APPID=application_1399156864902_0001	CONTAINERID=container_1399156864902_0001_01_000006
2014-05-03 23:08:16,696 INFO org.apache.hadoop.yarn.server.resourcemanager.scheduler.common.fica.FiCaSchedulerNode: Released container container_1399156864902_0001_01_000006 of capacity <memory:1024, vCores:1> on host nodea:56325, which currently has 0 containers, <memory:0, vCores:0> used and <memory:8192, vCores:8> available, release resources=true
2014-05-03 23:08:16,696 INFO org.apache.hadoop.yarn.server.resourcemanager.scheduler.capacity.LeafQueue: default used=<memory:2048, vCores:1> numContainers=1 user=ubuntu user-resources=<memory:2048, vCores:1>
2014-05-03 23:08:16,696 INFO org.apache.hadoop.yarn.server.resourcemanager.scheduler.capacity.LeafQueue: completedContainer container=Container: [ContainerId: container_1399156864902_0001_01_000006, NodeId: nodea:56325, NodeHttpAddress: nodea:8042, Resource: <memory:1024, vCores:1>, Priority: 10, Token: Token { kind: ContainerToken, service: 10.0.0.182:56325 }, ] resource=<memory:1024, vCores:1> queue=default: capacity=1.0, absoluteCapacity=1.0, usedResources=<memory:2048, vCores:1>usedCapacity=0.0625, absoluteUsedCapacity=0.0625, numApps=1, numContainers=1 usedCapacity=0.0625 absoluteUsedCapacity=0.0625 used=<memory:2048, vCores:1> cluster=<memory:32768, vCores:32>
2014-05-03 23:08:16,696 INFO org.apache.hadoop.yarn.server.resourcemanager.scheduler.capacity.ParentQueue: completedContainer queue=root usedCapacity=0.0625 absoluteUsedCapacity=0.0625 used=<memory:2048, vCores:1> cluster=<memory:32768, vCores:32>
2014-05-03 23:08:16,696 INFO org.apache.hadoop.yarn.server.resourcemanager.scheduler.capacity.ParentQueue: Re-sorting completed queue: root.default stats: default: capacity=1.0, absoluteCapacity=1.0, usedResources=<memory:2048, vCores:1>usedCapacity=0.0625, absoluteUsedCapacity=0.0625, numApps=1, numContainers=1
2014-05-03 23:08:16,696 INFO org.apache.hadoop.yarn.server.resourcemanager.scheduler.capacity.CapacityScheduler: Application appattempt_1399156864902_0001_000001 released container container_1399156864902_0001_01_000006 on node: host: nodea:56325 #containers=0 available=8192 used=0 with event: FINISHED
2014-05-03 23:08:22,316 INFO org.apache.hadoop.yarn.server.resourcemanager.rmcontainer.RMContainerImpl: container_1399156864902_0001_01_000001 Container Transitioned from RUNNING to COMPLETED
2014-05-03 23:08:22,316 INFO org.apache.hadoop.yarn.server.resourcemanager.ApplicationMasterService: Unregistering app attempt : appattempt_1399156864902_0001_000001
2014-05-03 23:08:22,316 INFO org.apache.hadoop.yarn.server.resourcemanager.scheduler.common.fica.FiCaSchedulerApp: Completed container: container_1399156864902_0001_01_000001 in state: COMPLETED event:FINISHED
2014-05-03 23:08:22,317 INFO org.apache.hadoop.yarn.server.resourcemanager.RMAuditLogger: USER=ubuntu	OPERATION=AM Released Container	TARGET=SchedulerApp	RESULT=SUCCESS	APPID=application_1399156864902_0001	CONTAINERID=container_1399156864902_0001_01_000001
2014-05-03 23:08:22,317 INFO org.apache.hadoop.yarn.server.resourcemanager.scheduler.common.fica.FiCaSchedulerNode: Released container container_1399156864902_0001_01_000001 of capacity <memory:2048, vCores:1> on host nodeb:55487, which currently has 0 containers, <memory:0, vCores:0> used and <memory:8192, vCores:8> available, release resources=true
2014-05-03 23:08:22,317 INFO org.apache.hadoop.yarn.server.resourcemanager.scheduler.capacity.LeafQueue: default used=<memory:0, vCores:0> numContainers=0 user=ubuntu user-resources=<memory:0, vCores:0>
2014-05-03 23:08:22,317 INFO org.apache.hadoop.yarn.server.resourcemanager.scheduler.capacity.LeafQueue: completedContainer container=Container: [ContainerId: container_1399156864902_0001_01_000001, NodeId: nodeb:55487, NodeHttpAddress: nodeb:8042, Resource: <memory:2048, vCores:1>, Priority: 0, Token: Token { kind: ContainerToken, service: 10.0.0.243:55487 }, ] resource=<memory:2048, vCores:1> queue=default: capacity=1.0, absoluteCapacity=1.0, usedResources=<memory:0, vCores:0>usedCapacity=0.0, absoluteUsedCapacity=0.0, numApps=1, numContainers=0 usedCapacity=0.0 absoluteUsedCapacity=0.0 used=<memory:0, vCores:0> cluster=<memory:32768, vCores:32>
2014-05-03 23:08:22,317 INFO org.apache.hadoop.yarn.server.resourcemanager.scheduler.capacity.ParentQueue: completedContainer queue=root usedCapacity=0.0 absoluteUsedCapacity=0.0 used=<memory:0, vCores:0> cluster=<memory:32768, vCores:32>
2014-05-03 23:08:22,317 INFO org.apache.hadoop.yarn.server.resourcemanager.scheduler.capacity.ParentQueue: Re-sorting completed queue: root.default stats: default: capacity=1.0, absoluteCapacity=1.0, usedResources=<memory:0, vCores:0>usedCapacity=0.0, absoluteUsedCapacity=0.0, numApps=1, numContainers=0
2014-05-03 23:08:22,317 INFO org.apache.hadoop.yarn.server.resourcemanager.scheduler.capacity.CapacityScheduler: Application appattempt_1399156864902_0001_000001 released container container_1399156864902_0001_01_000001 on node: host: nodeb:55487 #containers=0 available=8192 used=0 with event: FINISHED
2014-05-03 23:08:22,318 INFO org.apache.hadoop.yarn.server.resourcemanager.rmapp.attempt.RMAppAttemptImpl: appattempt_1399156864902_0001_000001 State change from FINISHING to FINISHED
2014-05-03 23:08:22,319 INFO org.apache.hadoop.yarn.server.resourcemanager.rmapp.RMAppImpl: application_1399156864902_0001 State change from FINISHING to FINISHED
2014-05-03 23:08:22,320 INFO org.apache.hadoop.yarn.server.resourcemanager.scheduler.capacity.CapacityScheduler: Application appattempt_1399156864902_0001_000001 is done. finalState=FINISHED
2014-05-03 23:08:22,320 INFO org.apache.hadoop.yarn.server.resourcemanager.scheduler.AppSchedulingInfo: Application application_1399156864902_0001 requests cleared
2014-05-03 23:08:22,321 INFO org.apache.hadoop.yarn.server.resourcemanager.RMAuditLogger: USER=ubuntu	OPERATION=Application Finished - Succeeded	TARGET=RMAppManager	RESULT=SUCCESS	APPID=application_1399156864902_0001
2014-05-03 23:08:22,321 INFO org.apache.hadoop.yarn.server.resourcemanager.scheduler.capacity.LeafQueue: Application removed - appId: application_1399156864902_0001 user: ubuntu queue: default #user-pending-applications: 0 #user-active-applications: 0 #queue-pending-applications: 0 #queue-active-applications: 0
2014-05-03 23:08:22,321 INFO org.apache.hadoop.yarn.server.resourcemanager.scheduler.capacity.ParentQueue: Application removed - appId: application_1399156864902_0001 user: ubuntu leaf-queue of parent: root #applications: 0
2014-05-03 23:08:22,321 INFO org.apache.hadoop.yarn.server.resourcemanager.amlauncher.AMLauncher: Cleaning master appattempt_1399156864902_0001_000001
2014-05-03 23:08:22,323 INFO org.apache.hadoop.yarn.server.resourcemanager.RMAppManager$ApplicationSummary: appId=application_1399156864902_0001,name=base||path:/in1m||num reduce:8,user=ubuntu,queue=default,state=FINISHED,trackingUrl=ec2-54-186-230-200.us-west-2.compute.amazonaws.com:8088/proxy/application_1399156864902_0001/jobhistory/job/job_1399156864902_0001,appMasterHost=ip-10-0-0-243,startTime=1399158306421,finishTime=1399158495867,finalStatus=SUCCEEDED
2014-05-03 23:10:31,169 INFO org.apache.hadoop.yarn.server.resourcemanager.ClientRMService: Allocated new applicationId: 2
2014-05-03 23:10:32,499 INFO org.apache.hadoop.yarn.server.resourcemanager.ClientRMService: Application with id 2 submitted by user ubuntu
2014-05-03 23:10:32,499 INFO org.apache.hadoop.yarn.server.resourcemanager.rmapp.RMAppImpl: Storing application with id application_1399156864902_0002
2014-05-03 23:10:32,499 INFO org.apache.hadoop.yarn.server.resourcemanager.rmapp.RMAppImpl: application_1399156864902_0002 State change from NEW to NEW_SAVING
2014-05-03 23:10:32,499 INFO org.apache.hadoop.yarn.server.resourcemanager.recovery.RMStateStore: Storing info for app: application_1399156864902_0002
2014-05-03 23:10:32,499 INFO org.apache.hadoop.yarn.server.resourcemanager.RMAuditLogger: USER=ubuntu	IP=10.0.0.182	OPERATION=Submit Application Request	TARGET=ClientRMService	RESULT=SUCCESS	APPID=application_1399156864902_0002
2014-05-03 23:10:32,501 INFO org.apache.hadoop.yarn.server.resourcemanager.rmapp.RMAppImpl: application_1399156864902_0002 State change from NEW_SAVING to SUBMITTED
2014-05-03 23:10:32,501 INFO org.apache.hadoop.yarn.server.resourcemanager.ApplicationMasterService: Registering app attempt : appattempt_1399156864902_0002_000001
2014-05-03 23:10:32,502 INFO org.apache.hadoop.yarn.server.resourcemanager.rmapp.attempt.RMAppAttemptImpl: appattempt_1399156864902_0002_000001 State change from NEW to SUBMITTED
2014-05-03 23:10:32,502 INFO org.apache.hadoop.yarn.server.resourcemanager.scheduler.capacity.LeafQueue: Application application_1399156864902_0002 from user: ubuntu activated in queue: default
2014-05-03 23:10:32,502 INFO org.apache.hadoop.yarn.server.resourcemanager.scheduler.capacity.LeafQueue: Application added - appId: application_1399156864902_0002 user: org.apache.hadoop.yarn.server.resourcemanager.scheduler.capacity.LeafQueue$User@368a8022, leaf-queue: default #user-pending-applications: 0 #user-active-applications: 1 #queue-pending-applications: 0 #queue-active-applications: 1
2014-05-03 23:10:32,502 INFO org.apache.hadoop.yarn.server.resourcemanager.scheduler.capacity.ParentQueue: Application added - appId: application_1399156864902_0002 user: ubuntu leaf-queue of parent: root #applications: 1
2014-05-03 23:10:32,502 INFO org.apache.hadoop.yarn.server.resourcemanager.scheduler.capacity.CapacityScheduler: Application Submission: appattempt_1399156864902_0002_000001, user: ubuntu queue: default: capacity=1.0, absoluteCapacity=1.0, usedResources=<memory:0, vCores:0>usedCapacity=0.0, absoluteUsedCapacity=0.0, numApps=1, numContainers=0, currently active: 1
2014-05-03 23:10:32,503 INFO org.apache.hadoop.yarn.server.resourcemanager.rmapp.attempt.RMAppAttemptImpl: appattempt_1399156864902_0002_000001 State change from SUBMITTED to SCHEDULED
2014-05-03 23:10:32,503 INFO org.apache.hadoop.yarn.server.resourcemanager.rmapp.RMAppImpl: application_1399156864902_0002 State change from SUBMITTED to ACCEPTED
2014-05-03 23:10:32,524 INFO org.apache.hadoop.yarn.server.resourcemanager.rmcontainer.RMContainerImpl: container_1399156864902_0002_01_000001 Container Transitioned from NEW to ALLOCATED
2014-05-03 23:10:32,524 INFO org.apache.hadoop.yarn.server.resourcemanager.RMAuditLogger: USER=ubuntu	OPERATION=AM Allocated Container	TARGET=SchedulerApp	RESULT=SUCCESS	APPID=application_1399156864902_0002	CONTAINERID=container_1399156864902_0002_01_000001
2014-05-03 23:10:32,525 INFO org.apache.hadoop.yarn.server.resourcemanager.scheduler.common.fica.FiCaSchedulerNode: Assigned container container_1399156864902_0002_01_000001 of capacity <memory:2048, vCores:1> on host nodeb:55487, which currently has 1 containers, <memory:2048, vCores:1> used and <memory:6144, vCores:7> available
2014-05-03 23:10:32,525 INFO org.apache.hadoop.yarn.server.resourcemanager.scheduler.capacity.LeafQueue: assignedContainer application=application_1399156864902_0002 container=Container: [ContainerId: container_1399156864902_0002_01_000001, NodeId: nodeb:55487, NodeHttpAddress: nodeb:8042, Resource: <memory:2048, vCores:1>, Priority: 0, Token: Token { kind: ContainerToken, service: 10.0.0.243:55487 }, ] containerId=container_1399156864902_0002_01_000001 queue=default: capacity=1.0, absoluteCapacity=1.0, usedResources=<memory:0, vCores:0>usedCapacity=0.0, absoluteUsedCapacity=0.0, numApps=1, numContainers=0 usedCapacity=0.0 absoluteUsedCapacity=0.0 used=<memory:0, vCores:0> cluster=<memory:32768, vCores:32>
2014-05-03 23:10:32,525 INFO org.apache.hadoop.yarn.server.resourcemanager.scheduler.capacity.ParentQueue: Re-sorting assigned queue: root.default stats: default: capacity=1.0, absoluteCapacity=1.0, usedResources=<memory:2048, vCores:1>usedCapacity=0.0625, absoluteUsedCapacity=0.0625, numApps=1, numContainers=1
2014-05-03 23:10:32,525 INFO org.apache.hadoop.yarn.server.resourcemanager.scheduler.capacity.ParentQueue: assignedContainer queue=root usedCapacity=0.0625 absoluteUsedCapacity=0.0625 used=<memory:2048, vCores:1> cluster=<memory:32768, vCores:32>
2014-05-03 23:10:32,525 INFO org.apache.hadoop.yarn.server.resourcemanager.rmcontainer.RMContainerImpl: container_1399156864902_0002_01_000001 Container Transitioned from ALLOCATED to ACQUIRED
2014-05-03 23:10:32,526 INFO org.apache.hadoop.yarn.server.resourcemanager.rmapp.attempt.RMAppAttemptImpl: Storing attempt: AppId: application_1399156864902_0002 AttemptId: appattempt_1399156864902_0002_000001 MasterContainer: Container: [ContainerId: container_1399156864902_0002_01_000001, NodeId: nodeb:55487, NodeHttpAddress: nodeb:8042, Resource: <memory:2048, vCores:1>, Priority: 0, Token: Token { kind: ContainerToken, service: 10.0.0.243:55487 }, ]
2014-05-03 23:10:32,526 INFO org.apache.hadoop.yarn.server.resourcemanager.rmapp.attempt.RMAppAttemptImpl: appattempt_1399156864902_0002_000001 State change from SCHEDULED to ALLOCATED_SAVING
2014-05-03 23:10:32,526 INFO org.apache.hadoop.yarn.server.resourcemanager.recovery.RMStateStore: Storing info for attempt: appattempt_1399156864902_0002_000001
2014-05-03 23:10:32,526 INFO org.apache.hadoop.yarn.server.resourcemanager.rmapp.attempt.RMAppAttemptImpl: appattempt_1399156864902_0002_000001 State change from ALLOCATED_SAVING to ALLOCATED
2014-05-03 23:10:32,529 INFO org.apache.hadoop.yarn.server.resourcemanager.amlauncher.AMLauncher: Launching masterappattempt_1399156864902_0002_000001
2014-05-03 23:10:32,530 INFO org.apache.hadoop.yarn.server.resourcemanager.amlauncher.AMLauncher: Setting up container Container: [ContainerId: container_1399156864902_0002_01_000001, NodeId: nodeb:55487, NodeHttpAddress: nodeb:8042, Resource: <memory:2048, vCores:1>, Priority: 0, Token: Token { kind: ContainerToken, service: 10.0.0.243:55487 }, ] for AM appattempt_1399156864902_0002_000001
2014-05-03 23:10:32,530 INFO org.apache.hadoop.yarn.server.resourcemanager.amlauncher.AMLauncher: Command to launch container container_1399156864902_0002_01_000001 : $JAVA_HOME/bin/java -Dlog4j.configuration=container-log4j.properties -Dyarn.app.container.log.dir=<LOG_DIR> -Dyarn.app.container.log.filesize=0 -Dhadoop.root.logger=INFO,CLA  -Xmx1024m org.apache.hadoop.mapreduce.v2.app.MRAppMaster 1><LOG_DIR>/stdout 2><LOG_DIR>/stderr 
2014-05-03 23:10:32,543 INFO org.apache.hadoop.yarn.server.resourcemanager.amlauncher.AMLauncher: Done launching container Container: [ContainerId: container_1399156864902_0002_01_000001, NodeId: nodeb:55487, NodeHttpAddress: nodeb:8042, Resource: <memory:2048, vCores:1>, Priority: 0, Token: Token { kind: ContainerToken, service: 10.0.0.243:55487 }, ] for AM appattempt_1399156864902_0002_000001
2014-05-03 23:10:32,543 INFO org.apache.hadoop.yarn.server.resourcemanager.rmapp.attempt.RMAppAttemptImpl: appattempt_1399156864902_0002_000001 State change from ALLOCATED to LAUNCHED
2014-05-03 23:10:33,526 INFO org.apache.hadoop.yarn.server.resourcemanager.rmcontainer.RMContainerImpl: container_1399156864902_0002_01_000001 Container Transitioned from ACQUIRED to RUNNING
2014-05-03 23:10:37,896 INFO SecurityLogger.org.apache.hadoop.ipc.Server: Auth successful for appattempt_1399156864902_0002_000001 (auth:SIMPLE)
2014-05-03 23:10:37,900 INFO org.apache.hadoop.yarn.server.resourcemanager.ApplicationMasterService: AM registration appattempt_1399156864902_0002_000001
2014-05-03 23:10:37,900 INFO org.apache.hadoop.yarn.server.resourcemanager.RMAuditLogger: USER=ubuntu	IP=10.0.0.243	OPERATION=Register App Master	TARGET=ApplicationMasterService	RESULT=SUCCESS	APPID=application_1399156864902_0002	APPATTEMPTID=appattempt_1399156864902_0002_000001
2014-05-03 23:10:37,901 INFO org.apache.hadoop.yarn.server.resourcemanager.rmapp.attempt.RMAppAttemptImpl: appattempt_1399156864902_0002_000001 State change from LAUNCHED to RUNNING
2014-05-03 23:10:37,901 INFO org.apache.hadoop.yarn.server.resourcemanager.rmapp.RMAppImpl: application_1399156864902_0002 State change from ACCEPTED to RUNNING
2014-05-03 23:10:39,179 INFO org.apache.hadoop.yarn.server.resourcemanager.rmcontainer.RMContainerImpl: container_1399156864902_0002_01_000002 Container Transitioned from NEW to ALLOCATED
2014-05-03 23:10:39,179 INFO org.apache.hadoop.yarn.server.resourcemanager.RMAuditLogger: USER=ubuntu	OPERATION=AM Allocated Container	TARGET=SchedulerApp	RESULT=SUCCESS	APPID=application_1399156864902_0002	CONTAINERID=container_1399156864902_0002_01_000002
2014-05-03 23:10:39,179 INFO org.apache.hadoop.yarn.server.resourcemanager.scheduler.common.fica.FiCaSchedulerNode: Assigned container container_1399156864902_0002_01_000002 of capacity <memory:1024, vCores:1> on host nodec:54860, which currently has 1 containers, <memory:1024, vCores:1> used and <memory:7168, vCores:7> available
2014-05-03 23:10:39,179 INFO org.apache.hadoop.yarn.server.resourcemanager.scheduler.capacity.LeafQueue: assignedContainer application=application_1399156864902_0002 container=Container: [ContainerId: container_1399156864902_0002_01_000002, NodeId: nodec:54860, NodeHttpAddress: nodec:8042, Resource: <memory:1024, vCores:1>, Priority: 20, Token: Token { kind: ContainerToken, service: 10.0.0.245:54860 }, ] containerId=container_1399156864902_0002_01_000002 queue=default: capacity=1.0, absoluteCapacity=1.0, usedResources=<memory:2048, vCores:1>usedCapacity=0.0625, absoluteUsedCapacity=0.0625, numApps=1, numContainers=1 usedCapacity=0.0625 absoluteUsedCapacity=0.0625 used=<memory:2048, vCores:1> cluster=<memory:32768, vCores:32>
2014-05-03 23:10:39,179 INFO org.apache.hadoop.yarn.server.resourcemanager.scheduler.capacity.ParentQueue: Re-sorting assigned queue: root.default stats: default: capacity=1.0, absoluteCapacity=1.0, usedResources=<memory:3072, vCores:2>usedCapacity=0.09375, absoluteUsedCapacity=0.09375, numApps=1, numContainers=2
2014-05-03 23:10:39,179 INFO org.apache.hadoop.yarn.server.resourcemanager.scheduler.capacity.ParentQueue: assignedContainer queue=root usedCapacity=0.09375 absoluteUsedCapacity=0.09375 used=<memory:3072, vCores:2> cluster=<memory:32768, vCores:32>
2014-05-03 23:10:39,180 INFO org.apache.hadoop.yarn.server.resourcemanager.rmcontainer.RMContainerImpl: container_1399156864902_0002_01_000003 Container Transitioned from NEW to ALLOCATED
2014-05-03 23:10:39,180 INFO org.apache.hadoop.yarn.server.resourcemanager.RMAuditLogger: USER=ubuntu	OPERATION=AM Allocated Container	TARGET=SchedulerApp	RESULT=SUCCESS	APPID=application_1399156864902_0002	CONTAINERID=container_1399156864902_0002_01_000003
2014-05-03 23:10:39,180 INFO org.apache.hadoop.yarn.server.resourcemanager.scheduler.common.fica.FiCaSchedulerNode: Assigned container container_1399156864902_0002_01_000003 of capacity <memory:1024, vCores:1> on host nodec:54860, which currently has 2 containers, <memory:2048, vCores:2> used and <memory:6144, vCores:6> available
2014-05-03 23:10:39,180 INFO org.apache.hadoop.yarn.server.resourcemanager.scheduler.capacity.LeafQueue: assignedContainer application=application_1399156864902_0002 container=Container: [ContainerId: container_1399156864902_0002_01_000003, NodeId: nodec:54860, NodeHttpAddress: nodec:8042, Resource: <memory:1024, vCores:1>, Priority: 20, Token: Token { kind: ContainerToken, service: 10.0.0.245:54860 }, ] containerId=container_1399156864902_0002_01_000003 queue=default: capacity=1.0, absoluteCapacity=1.0, usedResources=<memory:3072, vCores:2>usedCapacity=0.09375, absoluteUsedCapacity=0.09375, numApps=1, numContainers=2 usedCapacity=0.09375 absoluteUsedCapacity=0.09375 used=<memory:3072, vCores:2> cluster=<memory:32768, vCores:32>
2014-05-03 23:10:39,180 INFO org.apache.hadoop.yarn.server.resourcemanager.scheduler.capacity.ParentQueue: Re-sorting assigned queue: root.default stats: default: capacity=1.0, absoluteCapacity=1.0, usedResources=<memory:4096, vCores:3>usedCapacity=0.125, absoluteUsedCapacity=0.125, numApps=1, numContainers=3
2014-05-03 23:10:39,180 INFO org.apache.hadoop.yarn.server.resourcemanager.scheduler.capacity.ParentQueue: assignedContainer queue=root usedCapacity=0.125 absoluteUsedCapacity=0.125 used=<memory:4096, vCores:3> cluster=<memory:32768, vCores:32>
2014-05-03 23:10:39,181 INFO org.apache.hadoop.yarn.server.resourcemanager.rmcontainer.RMContainerImpl: container_1399156864902_0002_01_000004 Container Transitioned from NEW to ALLOCATED
2014-05-03 23:10:39,181 INFO org.apache.hadoop.yarn.server.resourcemanager.RMAuditLogger: USER=ubuntu	OPERATION=AM Allocated Container	TARGET=SchedulerApp	RESULT=SUCCESS	APPID=application_1399156864902_0002	CONTAINERID=container_1399156864902_0002_01_000004
2014-05-03 23:10:39,181 INFO org.apache.hadoop.yarn.server.resourcemanager.scheduler.common.fica.FiCaSchedulerNode: Assigned container container_1399156864902_0002_01_000004 of capacity <memory:1024, vCores:1> on host nodec:54860, which currently has 3 containers, <memory:3072, vCores:3> used and <memory:5120, vCores:5> available
2014-05-03 23:10:39,181 INFO org.apache.hadoop.yarn.server.resourcemanager.scheduler.capacity.LeafQueue: assignedContainer application=application_1399156864902_0002 container=Container: [ContainerId: container_1399156864902_0002_01_000004, NodeId: nodec:54860, NodeHttpAddress: nodec:8042, Resource: <memory:1024, vCores:1>, Priority: 20, Token: Token { kind: ContainerToken, service: 10.0.0.245:54860 }, ] containerId=container_1399156864902_0002_01_000004 queue=default: capacity=1.0, absoluteCapacity=1.0, usedResources=<memory:4096, vCores:3>usedCapacity=0.125, absoluteUsedCapacity=0.125, numApps=1, numContainers=3 usedCapacity=0.125 absoluteUsedCapacity=0.125 used=<memory:4096, vCores:3> cluster=<memory:32768, vCores:32>
2014-05-03 23:10:39,181 INFO org.apache.hadoop.yarn.server.resourcemanager.scheduler.capacity.ParentQueue: Re-sorting assigned queue: root.default stats: default: capacity=1.0, absoluteCapacity=1.0, usedResources=<memory:5120, vCores:4>usedCapacity=0.15625, absoluteUsedCapacity=0.15625, numApps=1, numContainers=4
2014-05-03 23:10:39,181 INFO org.apache.hadoop.yarn.server.resourcemanager.scheduler.capacity.ParentQueue: assignedContainer queue=root usedCapacity=0.15625 absoluteUsedCapacity=0.15625 used=<memory:5120, vCores:4> cluster=<memory:32768, vCores:32>
2014-05-03 23:10:39,181 INFO org.apache.hadoop.yarn.server.resourcemanager.rmcontainer.RMContainerImpl: container_1399156864902_0002_01_000005 Container Transitioned from NEW to ALLOCATED
2014-05-03 23:10:39,181 INFO org.apache.hadoop.yarn.server.resourcemanager.RMAuditLogger: USER=ubuntu	OPERATION=AM Allocated Container	TARGET=SchedulerApp	RESULT=SUCCESS	APPID=application_1399156864902_0002	CONTAINERID=container_1399156864902_0002_01_000005
2014-05-03 23:10:39,181 INFO org.apache.hadoop.yarn.server.resourcemanager.scheduler.common.fica.FiCaSchedulerNode: Assigned container container_1399156864902_0002_01_000005 of capacity <memory:1024, vCores:1> on host nodec:54860, which currently has 4 containers, <memory:4096, vCores:4> used and <memory:4096, vCores:4> available
2014-05-03 23:10:39,182 INFO org.apache.hadoop.yarn.server.resourcemanager.scheduler.capacity.LeafQueue: assignedContainer application=application_1399156864902_0002 container=Container: [ContainerId: container_1399156864902_0002_01_000005, NodeId: nodec:54860, NodeHttpAddress: nodec:8042, Resource: <memory:1024, vCores:1>, Priority: 20, Token: Token { kind: ContainerToken, service: 10.0.0.245:54860 }, ] containerId=container_1399156864902_0002_01_000005 queue=default: capacity=1.0, absoluteCapacity=1.0, usedResources=<memory:5120, vCores:4>usedCapacity=0.15625, absoluteUsedCapacity=0.15625, numApps=1, numContainers=4 usedCapacity=0.15625 absoluteUsedCapacity=0.15625 used=<memory:5120, vCores:4> cluster=<memory:32768, vCores:32>
2014-05-03 23:10:39,182 INFO org.apache.hadoop.yarn.server.resourcemanager.scheduler.capacity.ParentQueue: Re-sorting assigned queue: root.default stats: default: capacity=1.0, absoluteCapacity=1.0, usedResources=<memory:6144, vCores:5>usedCapacity=0.1875, absoluteUsedCapacity=0.1875, numApps=1, numContainers=5
2014-05-03 23:10:39,182 INFO org.apache.hadoop.yarn.server.resourcemanager.scheduler.capacity.ParentQueue: assignedContainer queue=root usedCapacity=0.1875 absoluteUsedCapacity=0.1875 used=<memory:6144, vCores:5> cluster=<memory:32768, vCores:32>
2014-05-03 23:10:40,076 INFO org.apache.hadoop.yarn.server.resourcemanager.rmcontainer.RMContainerImpl: container_1399156864902_0002_01_000002 Container Transitioned from ALLOCATED to ACQUIRED
2014-05-03 23:10:40,077 INFO org.apache.hadoop.yarn.server.resourcemanager.rmcontainer.RMContainerImpl: container_1399156864902_0002_01_000003 Container Transitioned from ALLOCATED to ACQUIRED
2014-05-03 23:10:40,077 INFO org.apache.hadoop.yarn.server.resourcemanager.rmcontainer.RMContainerImpl: container_1399156864902_0002_01_000004 Container Transitioned from ALLOCATED to ACQUIRED
2014-05-03 23:10:40,078 INFO org.apache.hadoop.yarn.server.resourcemanager.rmcontainer.RMContainerImpl: container_1399156864902_0002_01_000005 Container Transitioned from ALLOCATED to ACQUIRED
2014-05-03 23:10:41,107 INFO org.apache.hadoop.yarn.server.resourcemanager.scheduler.AppSchedulingInfo: checking for deactivate... 
2014-05-03 23:10:41,184 INFO org.apache.hadoop.yarn.server.resourcemanager.rmcontainer.RMContainerImpl: container_1399156864902_0002_01_000002 Container Transitioned from ACQUIRED to RUNNING
2014-05-03 23:10:41,184 INFO org.apache.hadoop.yarn.server.resourcemanager.rmcontainer.RMContainerImpl: container_1399156864902_0002_01_000003 Container Transitioned from ACQUIRED to RUNNING
2014-05-03 23:10:41,184 INFO org.apache.hadoop.yarn.server.resourcemanager.rmcontainer.RMContainerImpl: container_1399156864902_0002_01_000004 Container Transitioned from ACQUIRED to RUNNING
2014-05-03 23:10:41,184 INFO org.apache.hadoop.yarn.server.resourcemanager.rmcontainer.RMContainerImpl: container_1399156864902_0002_01_000005 Container Transitioned from ACQUIRED to RUNNING
2014-05-03 23:11:10,642 INFO org.apache.hadoop.yarn.server.resourcemanager.rmcontainer.RMContainerImpl: container_1399156864902_0002_01_000005 Container Transitioned from RUNNING to COMPLETED
2014-05-03 23:11:10,642 INFO org.apache.hadoop.yarn.server.resourcemanager.scheduler.common.fica.FiCaSchedulerApp: Completed container: container_1399156864902_0002_01_000005 in state: COMPLETED event:FINISHED
2014-05-03 23:11:10,642 INFO org.apache.hadoop.yarn.server.resourcemanager.RMAuditLogger: USER=ubuntu	OPERATION=AM Released Container	TARGET=SchedulerApp	RESULT=SUCCESS	APPID=application_1399156864902_0002	CONTAINERID=container_1399156864902_0002_01_000005
2014-05-03 23:11:10,642 INFO org.apache.hadoop.yarn.server.resourcemanager.scheduler.common.fica.FiCaSchedulerNode: Released container container_1399156864902_0002_01_000005 of capacity <memory:1024, vCores:1> on host nodec:54860, which currently has 3 containers, <memory:3072, vCores:3> used and <memory:5120, vCores:5> available, release resources=true
2014-05-03 23:11:10,642 INFO org.apache.hadoop.yarn.server.resourcemanager.scheduler.capacity.LeafQueue: default used=<memory:5120, vCores:4> numContainers=4 user=ubuntu user-resources=<memory:5120, vCores:4>
2014-05-03 23:11:10,642 INFO org.apache.hadoop.yarn.server.resourcemanager.scheduler.capacity.LeafQueue: completedContainer container=Container: [ContainerId: container_1399156864902_0002_01_000005, NodeId: nodec:54860, NodeHttpAddress: nodec:8042, Resource: <memory:1024, vCores:1>, Priority: 20, Token: Token { kind: ContainerToken, service: 10.0.0.245:54860 }, ] resource=<memory:1024, vCores:1> queue=default: capacity=1.0, absoluteCapacity=1.0, usedResources=<memory:5120, vCores:4>usedCapacity=0.15625, absoluteUsedCapacity=0.15625, numApps=1, numContainers=4 usedCapacity=0.15625 absoluteUsedCapacity=0.15625 used=<memory:5120, vCores:4> cluster=<memory:32768, vCores:32>
2014-05-03 23:11:10,642 INFO org.apache.hadoop.yarn.server.resourcemanager.scheduler.capacity.ParentQueue: completedContainer queue=root usedCapacity=0.15625 absoluteUsedCapacity=0.15625 used=<memory:5120, vCores:4> cluster=<memory:32768, vCores:32>
2014-05-03 23:11:10,643 INFO org.apache.hadoop.yarn.server.resourcemanager.scheduler.capacity.ParentQueue: Re-sorting completed queue: root.default stats: default: capacity=1.0, absoluteCapacity=1.0, usedResources=<memory:5120, vCores:4>usedCapacity=0.15625, absoluteUsedCapacity=0.15625, numApps=1, numContainers=4
2014-05-03 23:11:10,643 INFO org.apache.hadoop.yarn.server.resourcemanager.scheduler.capacity.CapacityScheduler: Application appattempt_1399156864902_0002_000001 released container container_1399156864902_0002_01_000005 on node: host: nodec:54860 #containers=3 available=5120 used=3072 with event: FINISHED
2014-05-03 23:11:11,372 INFO org.apache.hadoop.yarn.server.resourcemanager.rmcontainer.RMContainerImpl: container_1399156864902_0002_01_000002 Container Transitioned from RUNNING to COMPLETED
2014-05-03 23:11:11,372 INFO org.apache.hadoop.yarn.server.resourcemanager.scheduler.common.fica.FiCaSchedulerApp: Completed container: container_1399156864902_0002_01_000002 in state: COMPLETED event:FINISHED
2014-05-03 23:11:11,372 INFO org.apache.hadoop.yarn.server.resourcemanager.RMAuditLogger: USER=ubuntu	OPERATION=AM Released Container	TARGET=SchedulerApp	RESULT=SUCCESS	APPID=application_1399156864902_0002	CONTAINERID=container_1399156864902_0002_01_000002
2014-05-03 23:11:11,373 INFO org.apache.hadoop.yarn.server.resourcemanager.scheduler.common.fica.FiCaSchedulerNode: Released container container_1399156864902_0002_01_000002 of capacity <memory:1024, vCores:1> on host nodec:54860, which currently has 2 containers, <memory:2048, vCores:2> used and <memory:6144, vCores:6> available, release resources=true
2014-05-03 23:11:11,373 INFO org.apache.hadoop.yarn.server.resourcemanager.scheduler.capacity.LeafQueue: default used=<memory:4096, vCores:3> numContainers=3 user=ubuntu user-resources=<memory:4096, vCores:3>
2014-05-03 23:11:11,373 INFO org.apache.hadoop.yarn.server.resourcemanager.scheduler.capacity.LeafQueue: completedContainer container=Container: [ContainerId: container_1399156864902_0002_01_000002, NodeId: nodec:54860, NodeHttpAddress: nodec:8042, Resource: <memory:1024, vCores:1>, Priority: 20, Token: Token { kind: ContainerToken, service: 10.0.0.245:54860 }, ] resource=<memory:1024, vCores:1> queue=default: capacity=1.0, absoluteCapacity=1.0, usedResources=<memory:4096, vCores:3>usedCapacity=0.125, absoluteUsedCapacity=0.125, numApps=1, numContainers=3 usedCapacity=0.125 absoluteUsedCapacity=0.125 used=<memory:4096, vCores:3> cluster=<memory:32768, vCores:32>
2014-05-03 23:11:11,373 INFO org.apache.hadoop.yarn.server.resourcemanager.scheduler.capacity.ParentQueue: completedContainer queue=root usedCapacity=0.125 absoluteUsedCapacity=0.125 used=<memory:4096, vCores:3> cluster=<memory:32768, vCores:32>
2014-05-03 23:11:11,373 INFO org.apache.hadoop.yarn.server.resourcemanager.scheduler.capacity.ParentQueue: Re-sorting completed queue: root.default stats: default: capacity=1.0, absoluteCapacity=1.0, usedResources=<memory:4096, vCores:3>usedCapacity=0.125, absoluteUsedCapacity=0.125, numApps=1, numContainers=3
2014-05-03 23:11:11,373 INFO org.apache.hadoop.yarn.server.resourcemanager.scheduler.capacity.CapacityScheduler: Application appattempt_1399156864902_0002_000001 released container container_1399156864902_0002_01_000002 on node: host: nodec:54860 #containers=2 available=6144 used=2048 with event: FINISHED
2014-05-03 23:11:11,374 INFO org.apache.hadoop.yarn.server.resourcemanager.rmcontainer.RMContainerImpl: container_1399156864902_0002_01_000006 Container Transitioned from NEW to ALLOCATED
2014-05-03 23:11:11,374 INFO org.apache.hadoop.yarn.server.resourcemanager.RMAuditLogger: USER=ubuntu	OPERATION=AM Allocated Container	TARGET=SchedulerApp	RESULT=SUCCESS	APPID=application_1399156864902_0002	CONTAINERID=container_1399156864902_0002_01_000006
2014-05-03 23:11:11,374 INFO org.apache.hadoop.yarn.server.resourcemanager.scheduler.common.fica.FiCaSchedulerNode: Assigned container container_1399156864902_0002_01_000006 of capacity <memory:1024, vCores:1> on host nodec:54860, which currently has 3 containers, <memory:3072, vCores:3> used and <memory:5120, vCores:5> available
2014-05-03 23:11:11,374 INFO org.apache.hadoop.yarn.server.resourcemanager.scheduler.capacity.LeafQueue: assignedContainer application=application_1399156864902_0002 container=Container: [ContainerId: container_1399156864902_0002_01_000006, NodeId: nodec:54860, NodeHttpAddress: nodec:8042, Resource: <memory:1024, vCores:1>, Priority: 10, Token: Token { kind: ContainerToken, service: 10.0.0.245:54860 }, ] containerId=container_1399156864902_0002_01_000006 queue=default: capacity=1.0, absoluteCapacity=1.0, usedResources=<memory:4096, vCores:3>usedCapacity=0.125, absoluteUsedCapacity=0.125, numApps=1, numContainers=3 usedCapacity=0.125 absoluteUsedCapacity=0.125 used=<memory:4096, vCores:3> cluster=<memory:32768, vCores:32>
2014-05-03 23:11:11,374 INFO org.apache.hadoop.yarn.server.resourcemanager.scheduler.capacity.ParentQueue: Re-sorting assigned queue: root.default stats: default: capacity=1.0, absoluteCapacity=1.0, usedResources=<memory:5120, vCores:4>usedCapacity=0.15625, absoluteUsedCapacity=0.15625, numApps=1, numContainers=4
2014-05-03 23:11:11,374 INFO org.apache.hadoop.yarn.server.resourcemanager.scheduler.capacity.ParentQueue: assignedContainer queue=root usedCapacity=0.15625 absoluteUsedCapacity=0.15625 used=<memory:5120, vCores:4> cluster=<memory:32768, vCores:32>
2014-05-03 23:11:11,604 INFO org.apache.hadoop.yarn.server.resourcemanager.rmcontainer.RMContainerImpl: container_1399156864902_0002_01_000007 Container Transitioned from NEW to ALLOCATED
2014-05-03 23:11:11,604 INFO org.apache.hadoop.yarn.server.resourcemanager.RMAuditLogger: USER=ubuntu	OPERATION=AM Allocated Container	TARGET=SchedulerApp	RESULT=SUCCESS	APPID=application_1399156864902_0002	CONTAINERID=container_1399156864902_0002_01_000007
2014-05-03 23:11:11,604 INFO org.apache.hadoop.yarn.server.resourcemanager.scheduler.common.fica.FiCaSchedulerNode: Assigned container container_1399156864902_0002_01_000007 of capacity <memory:1024, vCores:1> on host nodeb:55487, which currently has 2 containers, <memory:3072, vCores:2> used and <memory:5120, vCores:6> available
2014-05-03 23:11:11,604 INFO org.apache.hadoop.yarn.server.resourcemanager.scheduler.capacity.LeafQueue: assignedContainer application=application_1399156864902_0002 container=Container: [ContainerId: container_1399156864902_0002_01_000007, NodeId: nodeb:55487, NodeHttpAddress: nodeb:8042, Resource: <memory:1024, vCores:1>, Priority: 10, Token: Token { kind: ContainerToken, service: 10.0.0.243:55487 }, ] containerId=container_1399156864902_0002_01_000007 queue=default: capacity=1.0, absoluteCapacity=1.0, usedResources=<memory:5120, vCores:4>usedCapacity=0.15625, absoluteUsedCapacity=0.15625, numApps=1, numContainers=4 usedCapacity=0.15625 absoluteUsedCapacity=0.15625 used=<memory:5120, vCores:4> cluster=<memory:32768, vCores:32>
2014-05-03 23:11:11,604 INFO org.apache.hadoop.yarn.server.resourcemanager.scheduler.capacity.ParentQueue: Re-sorting assigned queue: root.default stats: default: capacity=1.0, absoluteCapacity=1.0, usedResources=<memory:6144, vCores:5>usedCapacity=0.1875, absoluteUsedCapacity=0.1875, numApps=1, numContainers=5
2014-05-03 23:11:11,604 INFO org.apache.hadoop.yarn.server.resourcemanager.scheduler.capacity.ParentQueue: assignedContainer queue=root usedCapacity=0.1875 absoluteUsedCapacity=0.1875 used=<memory:6144, vCores:5> cluster=<memory:32768, vCores:32>
2014-05-03 23:11:11,639 INFO org.apache.hadoop.yarn.server.resourcemanager.rmcontainer.RMContainerImpl: container_1399156864902_0002_01_000008 Container Transitioned from NEW to ALLOCATED
2014-05-03 23:11:11,639 INFO org.apache.hadoop.yarn.server.resourcemanager.RMAuditLogger: USER=ubuntu	OPERATION=AM Allocated Container	TARGET=SchedulerApp	RESULT=SUCCESS	APPID=application_1399156864902_0002	CONTAINERID=container_1399156864902_0002_01_000008
2014-05-03 23:11:11,639 INFO org.apache.hadoop.yarn.server.resourcemanager.scheduler.common.fica.FiCaSchedulerNode: Assigned container container_1399156864902_0002_01_000008 of capacity <memory:1024, vCores:1> on host noded:50846, which currently has 1 containers, <memory:1024, vCores:1> used and <memory:7168, vCores:7> available
2014-05-03 23:11:11,639 INFO org.apache.hadoop.yarn.server.resourcemanager.scheduler.capacity.LeafQueue: assignedContainer application=application_1399156864902_0002 container=Container: [ContainerId: container_1399156864902_0002_01_000008, NodeId: noded:50846, NodeHttpAddress: noded:8042, Resource: <memory:1024, vCores:1>, Priority: 10, Token: Token { kind: ContainerToken, service: 10.0.0.244:50846 }, ] containerId=container_1399156864902_0002_01_000008 queue=default: capacity=1.0, absoluteCapacity=1.0, usedResources=<memory:6144, vCores:5>usedCapacity=0.1875, absoluteUsedCapacity=0.1875, numApps=1, numContainers=5 usedCapacity=0.1875 absoluteUsedCapacity=0.1875 used=<memory:6144, vCores:5> cluster=<memory:32768, vCores:32>
2014-05-03 23:11:11,639 INFO org.apache.hadoop.yarn.server.resourcemanager.scheduler.capacity.ParentQueue: Re-sorting assigned queue: root.default stats: default: capacity=1.0, absoluteCapacity=1.0, usedResources=<memory:7168, vCores:6>usedCapacity=0.21875, absoluteUsedCapacity=0.21875, numApps=1, numContainers=6
2014-05-03 23:11:11,639 INFO org.apache.hadoop.yarn.server.resourcemanager.scheduler.capacity.ParentQueue: assignedContainer queue=root usedCapacity=0.21875 absoluteUsedCapacity=0.21875 used=<memory:7168, vCores:6> cluster=<memory:32768, vCores:32>
2014-05-03 23:11:11,940 INFO org.apache.hadoop.yarn.server.resourcemanager.rmcontainer.RMContainerImpl: container_1399156864902_0002_01_000009 Container Transitioned from NEW to ALLOCATED
2014-05-03 23:11:11,940 INFO org.apache.hadoop.yarn.server.resourcemanager.RMAuditLogger: USER=ubuntu	OPERATION=AM Allocated Container	TARGET=SchedulerApp	RESULT=SUCCESS	APPID=application_1399156864902_0002	CONTAINERID=container_1399156864902_0002_01_000009
2014-05-03 23:11:11,940 INFO org.apache.hadoop.yarn.server.resourcemanager.scheduler.common.fica.FiCaSchedulerNode: Assigned container container_1399156864902_0002_01_000009 of capacity <memory:1024, vCores:1> on host nodea:56325, which currently has 1 containers, <memory:1024, vCores:1> used and <memory:7168, vCores:7> available
2014-05-03 23:11:11,940 INFO org.apache.hadoop.yarn.server.resourcemanager.scheduler.capacity.LeafQueue: assignedContainer application=application_1399156864902_0002 container=Container: [ContainerId: container_1399156864902_0002_01_000009, NodeId: nodea:56325, NodeHttpAddress: nodea:8042, Resource: <memory:1024, vCores:1>, Priority: 10, Token: Token { kind: ContainerToken, service: 10.0.0.182:56325 }, ] containerId=container_1399156864902_0002_01_000009 queue=default: capacity=1.0, absoluteCapacity=1.0, usedResources=<memory:7168, vCores:6>usedCapacity=0.21875, absoluteUsedCapacity=0.21875, numApps=1, numContainers=6 usedCapacity=0.21875 absoluteUsedCapacity=0.21875 used=<memory:7168, vCores:6> cluster=<memory:32768, vCores:32>
2014-05-03 23:11:11,941 INFO org.apache.hadoop.yarn.server.resourcemanager.scheduler.capacity.ParentQueue: Re-sorting assigned queue: root.default stats: default: capacity=1.0, absoluteCapacity=1.0, usedResources=<memory:8192, vCores:7>usedCapacity=0.25, absoluteUsedCapacity=0.25, numApps=1, numContainers=7
2014-05-03 23:11:11,941 INFO org.apache.hadoop.yarn.server.resourcemanager.scheduler.capacity.ParentQueue: assignedContainer queue=root usedCapacity=0.25 absoluteUsedCapacity=0.25 used=<memory:8192, vCores:7> cluster=<memory:32768, vCores:32>
2014-05-03 23:11:12,028 INFO org.apache.hadoop.yarn.server.resourcemanager.rmcontainer.RMContainerImpl: container_1399156864902_0002_01_000004 Container Transitioned from RUNNING to COMPLETED
2014-05-03 23:11:12,028 INFO org.apache.hadoop.yarn.server.resourcemanager.scheduler.common.fica.FiCaSchedulerApp: Completed container: container_1399156864902_0002_01_000004 in state: COMPLETED event:FINISHED
2014-05-03 23:11:12,028 INFO org.apache.hadoop.yarn.server.resourcemanager.RMAuditLogger: USER=ubuntu	OPERATION=AM Released Container	TARGET=SchedulerApp	RESULT=SUCCESS	APPID=application_1399156864902_0002	CONTAINERID=container_1399156864902_0002_01_000004
2014-05-03 23:11:12,028 INFO org.apache.hadoop.yarn.server.resourcemanager.scheduler.common.fica.FiCaSchedulerNode: Released container container_1399156864902_0002_01_000004 of capacity <memory:1024, vCores:1> on host nodec:54860, which currently has 2 containers, <memory:2048, vCores:2> used and <memory:6144, vCores:6> available, release resources=true
2014-05-03 23:11:12,028 INFO org.apache.hadoop.yarn.server.resourcemanager.scheduler.capacity.LeafQueue: default used=<memory:7168, vCores:6> numContainers=6 user=ubuntu user-resources=<memory:7168, vCores:6>
2014-05-03 23:11:12,029 INFO org.apache.hadoop.yarn.server.resourcemanager.scheduler.capacity.LeafQueue: completedContainer container=Container: [ContainerId: container_1399156864902_0002_01_000004, NodeId: nodec:54860, NodeHttpAddress: nodec:8042, Resource: <memory:1024, vCores:1>, Priority: 20, Token: Token { kind: ContainerToken, service: 10.0.0.245:54860 }, ] resource=<memory:1024, vCores:1> queue=default: capacity=1.0, absoluteCapacity=1.0, usedResources=<memory:7168, vCores:6>usedCapacity=0.21875, absoluteUsedCapacity=0.21875, numApps=1, numContainers=6 usedCapacity=0.21875 absoluteUsedCapacity=0.21875 used=<memory:7168, vCores:6> cluster=<memory:32768, vCores:32>
2014-05-03 23:11:12,029 INFO org.apache.hadoop.yarn.server.resourcemanager.scheduler.capacity.ParentQueue: completedContainer queue=root usedCapacity=0.21875 absoluteUsedCapacity=0.21875 used=<memory:7168, vCores:6> cluster=<memory:32768, vCores:32>
2014-05-03 23:11:12,029 INFO org.apache.hadoop.yarn.server.resourcemanager.scheduler.capacity.ParentQueue: Re-sorting completed queue: root.default stats: default: capacity=1.0, absoluteCapacity=1.0, usedResources=<memory:7168, vCores:6>usedCapacity=0.21875, absoluteUsedCapacity=0.21875, numApps=1, numContainers=6
2014-05-03 23:11:12,029 INFO org.apache.hadoop.yarn.server.resourcemanager.scheduler.capacity.CapacityScheduler: Application appattempt_1399156864902_0002_000001 released container container_1399156864902_0002_01_000004 on node: host: nodec:54860 #containers=2 available=6144 used=2048 with event: FINISHED
2014-05-03 23:11:12,029 INFO org.apache.hadoop.yarn.server.resourcemanager.rmcontainer.RMContainerImpl: container_1399156864902_0002_01_000010 Container Transitioned from NEW to ALLOCATED
2014-05-03 23:11:12,029 INFO org.apache.hadoop.yarn.server.resourcemanager.RMAuditLogger: USER=ubuntu	OPERATION=AM Allocated Container	TARGET=SchedulerApp	RESULT=SUCCESS	APPID=application_1399156864902_0002	CONTAINERID=container_1399156864902_0002_01_000010
2014-05-03 23:11:12,029 INFO org.apache.hadoop.yarn.server.resourcemanager.scheduler.common.fica.FiCaSchedulerNode: Assigned container container_1399156864902_0002_01_000010 of capacity <memory:1024, vCores:1> on host nodec:54860, which currently has 3 containers, <memory:3072, vCores:3> used and <memory:5120, vCores:5> available
2014-05-03 23:11:12,029 INFO org.apache.hadoop.yarn.server.resourcemanager.scheduler.capacity.LeafQueue: assignedContainer application=application_1399156864902_0002 container=Container: [ContainerId: container_1399156864902_0002_01_000010, NodeId: nodec:54860, NodeHttpAddress: nodec:8042, Resource: <memory:1024, vCores:1>, Priority: 10, Token: Token { kind: ContainerToken, service: 10.0.0.245:54860 }, ] containerId=container_1399156864902_0002_01_000010 queue=default: capacity=1.0, absoluteCapacity=1.0, usedResources=<memory:7168, vCores:6>usedCapacity=0.21875, absoluteUsedCapacity=0.21875, numApps=1, numContainers=6 usedCapacity=0.21875 absoluteUsedCapacity=0.21875 used=<memory:7168, vCores:6> cluster=<memory:32768, vCores:32>
2014-05-03 23:11:12,030 INFO org.apache.hadoop.yarn.server.resourcemanager.scheduler.capacity.ParentQueue: Re-sorting assigned queue: root.default stats: default: capacity=1.0, absoluteCapacity=1.0, usedResources=<memory:8192, vCores:7>usedCapacity=0.25, absoluteUsedCapacity=0.25, numApps=1, numContainers=7
2014-05-03 23:11:12,030 INFO org.apache.hadoop.yarn.server.resourcemanager.scheduler.capacity.ParentQueue: assignedContainer queue=root usedCapacity=0.25 absoluteUsedCapacity=0.25 used=<memory:8192, vCores:7> cluster=<memory:32768, vCores:32>
2014-05-03 23:11:12,189 INFO org.apache.hadoop.yarn.server.resourcemanager.rmcontainer.RMContainerImpl: container_1399156864902_0002_01_000006 Container Transitioned from ALLOCATED to ACQUIRED
2014-05-03 23:11:12,193 INFO org.apache.hadoop.yarn.server.resourcemanager.rmcontainer.RMContainerImpl: container_1399156864902_0002_01_000007 Container Transitioned from ALLOCATED to ACQUIRED
2014-05-03 23:11:12,193 INFO org.apache.hadoop.yarn.server.resourcemanager.rmcontainer.RMContainerImpl: container_1399156864902_0002_01_000008 Container Transitioned from ALLOCATED to ACQUIRED
2014-05-03 23:11:12,194 INFO org.apache.hadoop.yarn.server.resourcemanager.rmcontainer.RMContainerImpl: container_1399156864902_0002_01_000009 Container Transitioned from ALLOCATED to ACQUIRED
2014-05-03 23:11:12,194 INFO org.apache.hadoop.yarn.server.resourcemanager.rmcontainer.RMContainerImpl: container_1399156864902_0002_01_000010 Container Transitioned from ALLOCATED to ACQUIRED
2014-05-03 23:11:12,606 INFO org.apache.hadoop.yarn.server.resourcemanager.rmcontainer.RMContainerImpl: container_1399156864902_0002_01_000007 Container Transitioned from ACQUIRED to RUNNING
2014-05-03 23:11:12,607 INFO org.apache.hadoop.yarn.server.resourcemanager.rmcontainer.RMContainerImpl: container_1399156864902_0002_01_000011 Container Transitioned from NEW to ALLOCATED
2014-05-03 23:11:12,607 INFO org.apache.hadoop.yarn.server.resourcemanager.RMAuditLogger: USER=ubuntu	OPERATION=AM Allocated Container	TARGET=SchedulerApp	RESULT=SUCCESS	APPID=application_1399156864902_0002	CONTAINERID=container_1399156864902_0002_01_000011
2014-05-03 23:11:12,607 INFO org.apache.hadoop.yarn.server.resourcemanager.scheduler.common.fica.FiCaSchedulerNode: Assigned container container_1399156864902_0002_01_000011 of capacity <memory:1024, vCores:1> on host nodeb:55487, which currently has 3 containers, <memory:4096, vCores:3> used and <memory:4096, vCores:5> available
2014-05-03 23:11:12,607 INFO org.apache.hadoop.yarn.server.resourcemanager.scheduler.capacity.LeafQueue: assignedContainer application=application_1399156864902_0002 container=Container: [ContainerId: container_1399156864902_0002_01_000011, NodeId: nodeb:55487, NodeHttpAddress: nodeb:8042, Resource: <memory:1024, vCores:1>, Priority: 10, Token: Token { kind: ContainerToken, service: 10.0.0.243:55487 }, ] containerId=container_1399156864902_0002_01_000011 queue=default: capacity=1.0, absoluteCapacity=1.0, usedResources=<memory:8192, vCores:7>usedCapacity=0.25, absoluteUsedCapacity=0.25, numApps=1, numContainers=7 usedCapacity=0.25 absoluteUsedCapacity=0.25 used=<memory:8192, vCores:7> cluster=<memory:32768, vCores:32>
2014-05-03 23:11:12,607 INFO org.apache.hadoop.yarn.server.resourcemanager.scheduler.capacity.ParentQueue: Re-sorting assigned queue: root.default stats: default: capacity=1.0, absoluteCapacity=1.0, usedResources=<memory:9216, vCores:8>usedCapacity=0.28125, absoluteUsedCapacity=0.28125, numApps=1, numContainers=8
2014-05-03 23:11:12,607 INFO org.apache.hadoop.yarn.server.resourcemanager.scheduler.capacity.ParentQueue: assignedContainer queue=root usedCapacity=0.28125 absoluteUsedCapacity=0.28125 used=<memory:9216, vCores:8> cluster=<memory:32768, vCores:32>
2014-05-03 23:11:12,641 INFO org.apache.hadoop.yarn.server.resourcemanager.rmcontainer.RMContainerImpl: container_1399156864902_0002_01_000008 Container Transitioned from ACQUIRED to RUNNING
2014-05-03 23:11:12,642 INFO org.apache.hadoop.yarn.server.resourcemanager.rmcontainer.RMContainerImpl: container_1399156864902_0002_01_000012 Container Transitioned from NEW to ALLOCATED
2014-05-03 23:11:12,642 INFO org.apache.hadoop.yarn.server.resourcemanager.RMAuditLogger: USER=ubuntu	OPERATION=AM Allocated Container	TARGET=SchedulerApp	RESULT=SUCCESS	APPID=application_1399156864902_0002	CONTAINERID=container_1399156864902_0002_01_000012
2014-05-03 23:11:12,642 INFO org.apache.hadoop.yarn.server.resourcemanager.scheduler.common.fica.FiCaSchedulerNode: Assigned container container_1399156864902_0002_01_000012 of capacity <memory:1024, vCores:1> on host noded:50846, which currently has 2 containers, <memory:2048, vCores:2> used and <memory:6144, vCores:6> available
2014-05-03 23:11:12,642 INFO org.apache.hadoop.yarn.server.resourcemanager.scheduler.capacity.LeafQueue: assignedContainer application=application_1399156864902_0002 container=Container: [ContainerId: container_1399156864902_0002_01_000012, NodeId: noded:50846, NodeHttpAddress: noded:8042, Resource: <memory:1024, vCores:1>, Priority: 10, Token: Token { kind: ContainerToken, service: 10.0.0.244:50846 }, ] containerId=container_1399156864902_0002_01_000012 queue=default: capacity=1.0, absoluteCapacity=1.0, usedResources=<memory:9216, vCores:8>usedCapacity=0.28125, absoluteUsedCapacity=0.28125, numApps=1, numContainers=8 usedCapacity=0.28125 absoluteUsedCapacity=0.28125 used=<memory:9216, vCores:8> cluster=<memory:32768, vCores:32>
2014-05-03 23:11:12,642 INFO org.apache.hadoop.yarn.server.resourcemanager.scheduler.capacity.ParentQueue: Re-sorting assigned queue: root.default stats: default: capacity=1.0, absoluteCapacity=1.0, usedResources=<memory:10240, vCores:9>usedCapacity=0.3125, absoluteUsedCapacity=0.3125, numApps=1, numContainers=9
2014-05-03 23:11:12,642 INFO org.apache.hadoop.yarn.server.resourcemanager.scheduler.capacity.ParentQueue: assignedContainer queue=root usedCapacity=0.3125 absoluteUsedCapacity=0.3125 used=<memory:10240, vCores:9> cluster=<memory:32768, vCores:32>
2014-05-03 23:11:12,942 INFO org.apache.hadoop.yarn.server.resourcemanager.rmcontainer.RMContainerImpl: container_1399156864902_0002_01_000009 Container Transitioned from ACQUIRED to RUNNING
2014-05-03 23:11:12,943 INFO org.apache.hadoop.yarn.server.resourcemanager.rmcontainer.RMContainerImpl: container_1399156864902_0002_01_000013 Container Transitioned from NEW to ALLOCATED
2014-05-03 23:11:12,943 INFO org.apache.hadoop.yarn.server.resourcemanager.RMAuditLogger: USER=ubuntu	OPERATION=AM Allocated Container	TARGET=SchedulerApp	RESULT=SUCCESS	APPID=application_1399156864902_0002	CONTAINERID=container_1399156864902_0002_01_000013
2014-05-03 23:11:12,943 INFO org.apache.hadoop.yarn.server.resourcemanager.scheduler.common.fica.FiCaSchedulerNode: Assigned container container_1399156864902_0002_01_000013 of capacity <memory:1024, vCores:1> on host nodea:56325, which currently has 2 containers, <memory:2048, vCores:2> used and <memory:6144, vCores:6> available
2014-05-03 23:11:12,943 INFO org.apache.hadoop.yarn.server.resourcemanager.scheduler.capacity.LeafQueue: assignedContainer application=application_1399156864902_0002 container=Container: [ContainerId: container_1399156864902_0002_01_000013, NodeId: nodea:56325, NodeHttpAddress: nodea:8042, Resource: <memory:1024, vCores:1>, Priority: 10, Token: Token { kind: ContainerToken, service: 10.0.0.182:56325 }, ] containerId=container_1399156864902_0002_01_000013 queue=default: capacity=1.0, absoluteCapacity=1.0, usedResources=<memory:10240, vCores:9>usedCapacity=0.3125, absoluteUsedCapacity=0.3125, numApps=1, numContainers=9 usedCapacity=0.3125 absoluteUsedCapacity=0.3125 used=<memory:10240, vCores:9> cluster=<memory:32768, vCores:32>
2014-05-03 23:11:12,943 INFO org.apache.hadoop.yarn.server.resourcemanager.scheduler.capacity.ParentQueue: Re-sorting assigned queue: root.default stats: default: capacity=1.0, absoluteCapacity=1.0, usedResources=<memory:11264, vCores:10>usedCapacity=0.34375, absoluteUsedCapacity=0.34375, numApps=1, numContainers=10
2014-05-03 23:11:12,944 INFO org.apache.hadoop.yarn.server.resourcemanager.scheduler.capacity.ParentQueue: assignedContainer queue=root usedCapacity=0.34375 absoluteUsedCapacity=0.34375 used=<memory:11264, vCores:10> cluster=<memory:32768, vCores:32>
2014-05-03 23:11:13,031 INFO org.apache.hadoop.yarn.server.resourcemanager.rmcontainer.RMContainerImpl: container_1399156864902_0002_01_000006 Container Transitioned from ACQUIRED to RUNNING
2014-05-03 23:11:13,031 INFO org.apache.hadoop.yarn.server.resourcemanager.rmcontainer.RMContainerImpl: container_1399156864902_0002_01_000010 Container Transitioned from ACQUIRED to RUNNING
2014-05-03 23:11:13,032 INFO org.apache.hadoop.yarn.server.resourcemanager.rmcontainer.RMContainerImpl: container_1399156864902_0002_01_000003 Container Transitioned from RUNNING to COMPLETED
2014-05-03 23:11:13,032 INFO org.apache.hadoop.yarn.server.resourcemanager.scheduler.common.fica.FiCaSchedulerApp: Completed container: container_1399156864902_0002_01_000003 in state: COMPLETED event:FINISHED
2014-05-03 23:11:13,032 INFO org.apache.hadoop.yarn.server.resourcemanager.RMAuditLogger: USER=ubuntu	OPERATION=AM Released Container	TARGET=SchedulerApp	RESULT=SUCCESS	APPID=application_1399156864902_0002	CONTAINERID=container_1399156864902_0002_01_000003
2014-05-03 23:11:13,032 INFO org.apache.hadoop.yarn.server.resourcemanager.scheduler.common.fica.FiCaSchedulerNode: Released container container_1399156864902_0002_01_000003 of capacity <memory:1024, vCores:1> on host nodec:54860, which currently has 2 containers, <memory:2048, vCores:2> used and <memory:6144, vCores:6> available, release resources=true
2014-05-03 23:11:13,032 INFO org.apache.hadoop.yarn.server.resourcemanager.scheduler.capacity.LeafQueue: default used=<memory:10240, vCores:9> numContainers=9 user=ubuntu user-resources=<memory:10240, vCores:9>
2014-05-03 23:11:13,033 INFO org.apache.hadoop.yarn.server.resourcemanager.scheduler.capacity.LeafQueue: completedContainer container=Container: [ContainerId: container_1399156864902_0002_01_000003, NodeId: nodec:54860, NodeHttpAddress: nodec:8042, Resource: <memory:1024, vCores:1>, Priority: 20, Token: Token { kind: ContainerToken, service: 10.0.0.245:54860 }, ] resource=<memory:1024, vCores:1> queue=default: capacity=1.0, absoluteCapacity=1.0, usedResources=<memory:10240, vCores:9>usedCapacity=0.3125, absoluteUsedCapacity=0.3125, numApps=1, numContainers=9 usedCapacity=0.3125 absoluteUsedCapacity=0.3125 used=<memory:10240, vCores:9> cluster=<memory:32768, vCores:32>
2014-05-03 23:11:13,033 INFO org.apache.hadoop.yarn.server.resourcemanager.scheduler.capacity.ParentQueue: completedContainer queue=root usedCapacity=0.3125 absoluteUsedCapacity=0.3125 used=<memory:10240, vCores:9> cluster=<memory:32768, vCores:32>
2014-05-03 23:11:13,033 INFO org.apache.hadoop.yarn.server.resourcemanager.scheduler.capacity.ParentQueue: Re-sorting completed queue: root.default stats: default: capacity=1.0, absoluteCapacity=1.0, usedResources=<memory:10240, vCores:9>usedCapacity=0.3125, absoluteUsedCapacity=0.3125, numApps=1, numContainers=9
2014-05-03 23:11:13,033 INFO org.apache.hadoop.yarn.server.resourcemanager.scheduler.capacity.CapacityScheduler: Application appattempt_1399156864902_0002_000001 released container container_1399156864902_0002_01_000003 on node: host: nodec:54860 #containers=2 available=6144 used=2048 with event: FINISHED
2014-05-03 23:11:13,201 INFO org.apache.hadoop.yarn.server.resourcemanager.rmcontainer.RMContainerImpl: container_1399156864902_0002_01_000011 Container Transitioned from ALLOCATED to ACQUIRED
2014-05-03 23:11:13,201 INFO org.apache.hadoop.yarn.server.resourcemanager.rmcontainer.RMContainerImpl: container_1399156864902_0002_01_000012 Container Transitioned from ALLOCATED to ACQUIRED
2014-05-03 23:11:13,202 INFO org.apache.hadoop.yarn.server.resourcemanager.rmcontainer.RMContainerImpl: container_1399156864902_0002_01_000013 Container Transitioned from ALLOCATED to ACQUIRED
2014-05-03 23:11:13,609 INFO org.apache.hadoop.yarn.server.resourcemanager.rmcontainer.RMContainerImpl: container_1399156864902_0002_01_000011 Container Transitioned from ACQUIRED to RUNNING
2014-05-03 23:11:13,610 INFO org.apache.hadoop.yarn.server.resourcemanager.rmcontainer.RMContainerImpl: container_1399156864902_0002_01_000014 Container Transitioned from NEW to ALLOCATED
2014-05-03 23:11:13,610 INFO org.apache.hadoop.yarn.server.resourcemanager.RMAuditLogger: USER=ubuntu	OPERATION=AM Allocated Container	TARGET=SchedulerApp	RESULT=SUCCESS	APPID=application_1399156864902_0002	CONTAINERID=container_1399156864902_0002_01_000014
2014-05-03 23:11:13,610 INFO org.apache.hadoop.yarn.server.resourcemanager.scheduler.common.fica.FiCaSchedulerNode: Assigned container container_1399156864902_0002_01_000014 of capacity <memory:1024, vCores:1> on host nodeb:55487, which currently has 4 containers, <memory:5120, vCores:4> used and <memory:3072, vCores:4> available
2014-05-03 23:11:13,610 INFO org.apache.hadoop.yarn.server.resourcemanager.scheduler.capacity.LeafQueue: assignedContainer application=application_1399156864902_0002 container=Container: [ContainerId: container_1399156864902_0002_01_000014, NodeId: nodeb:55487, NodeHttpAddress: nodeb:8042, Resource: <memory:1024, vCores:1>, Priority: 10, Token: Token { kind: ContainerToken, service: 10.0.0.243:55487 }, ] containerId=container_1399156864902_0002_01_000014 queue=default: capacity=1.0, absoluteCapacity=1.0, usedResources=<memory:10240, vCores:9>usedCapacity=0.3125, absoluteUsedCapacity=0.3125, numApps=1, numContainers=9 usedCapacity=0.3125 absoluteUsedCapacity=0.3125 used=<memory:10240, vCores:9> cluster=<memory:32768, vCores:32>
2014-05-03 23:11:13,610 INFO org.apache.hadoop.yarn.server.resourcemanager.scheduler.capacity.ParentQueue: Re-sorting assigned queue: root.default stats: default: capacity=1.0, absoluteCapacity=1.0, usedResources=<memory:11264, vCores:10>usedCapacity=0.34375, absoluteUsedCapacity=0.34375, numApps=1, numContainers=10
2014-05-03 23:11:13,610 INFO org.apache.hadoop.yarn.server.resourcemanager.scheduler.capacity.ParentQueue: assignedContainer queue=root usedCapacity=0.34375 absoluteUsedCapacity=0.34375 used=<memory:11264, vCores:10> cluster=<memory:32768, vCores:32>
2014-05-03 23:11:13,644 INFO org.apache.hadoop.yarn.server.resourcemanager.rmcontainer.RMContainerImpl: container_1399156864902_0002_01_000012 Container Transitioned from ACQUIRED to RUNNING
2014-05-03 23:11:13,645 INFO org.apache.hadoop.yarn.server.resourcemanager.rmcontainer.RMContainerImpl: container_1399156864902_0002_01_000015 Container Transitioned from NEW to ALLOCATED
2014-05-03 23:11:13,645 INFO org.apache.hadoop.yarn.server.resourcemanager.RMAuditLogger: USER=ubuntu	OPERATION=AM Allocated Container	TARGET=SchedulerApp	RESULT=SUCCESS	APPID=application_1399156864902_0002	CONTAINERID=container_1399156864902_0002_01_000015
2014-05-03 23:11:13,645 INFO org.apache.hadoop.yarn.server.resourcemanager.scheduler.common.fica.FiCaSchedulerNode: Assigned container container_1399156864902_0002_01_000015 of capacity <memory:1024, vCores:1> on host noded:50846, which currently has 3 containers, <memory:3072, vCores:3> used and <memory:5120, vCores:5> available
2014-05-03 23:11:13,645 INFO org.apache.hadoop.yarn.server.resourcemanager.scheduler.capacity.LeafQueue: assignedContainer application=application_1399156864902_0002 container=Container: [ContainerId: container_1399156864902_0002_01_000015, NodeId: noded:50846, NodeHttpAddress: noded:8042, Resource: <memory:1024, vCores:1>, Priority: 10, Token: Token { kind: ContainerToken, service: 10.0.0.244:50846 }, ] containerId=container_1399156864902_0002_01_000015 queue=default: capacity=1.0, absoluteCapacity=1.0, usedResources=<memory:11264, vCores:10>usedCapacity=0.34375, absoluteUsedCapacity=0.34375, numApps=1, numContainers=10 usedCapacity=0.34375 absoluteUsedCapacity=0.34375 used=<memory:11264, vCores:10> cluster=<memory:32768, vCores:32>
2014-05-03 23:11:13,645 INFO org.apache.hadoop.yarn.server.resourcemanager.scheduler.capacity.ParentQueue: Re-sorting assigned queue: root.default stats: default: capacity=1.0, absoluteCapacity=1.0, usedResources=<memory:12288, vCores:11>usedCapacity=0.375, absoluteUsedCapacity=0.375, numApps=1, numContainers=11
2014-05-03 23:11:13,645 INFO org.apache.hadoop.yarn.server.resourcemanager.scheduler.capacity.ParentQueue: assignedContainer queue=root usedCapacity=0.375 absoluteUsedCapacity=0.375 used=<memory:12288, vCores:11> cluster=<memory:32768, vCores:32>
2014-05-03 23:11:13,947 INFO org.apache.hadoop.yarn.server.resourcemanager.rmcontainer.RMContainerImpl: container_1399156864902_0002_01_000013 Container Transitioned from ACQUIRED to RUNNING
2014-05-03 23:11:13,947 INFO org.apache.hadoop.yarn.server.resourcemanager.rmcontainer.RMContainerImpl: container_1399156864902_0002_01_000016 Container Transitioned from NEW to ALLOCATED
2014-05-03 23:11:13,948 INFO org.apache.hadoop.yarn.server.resourcemanager.RMAuditLogger: USER=ubuntu	OPERATION=AM Allocated Container	TARGET=SchedulerApp	RESULT=SUCCESS	APPID=application_1399156864902_0002	CONTAINERID=container_1399156864902_0002_01_000016
2014-05-03 23:11:13,948 INFO org.apache.hadoop.yarn.server.resourcemanager.scheduler.common.fica.FiCaSchedulerNode: Assigned container container_1399156864902_0002_01_000016 of capacity <memory:1024, vCores:1> on host nodea:56325, which currently has 3 containers, <memory:3072, vCores:3> used and <memory:5120, vCores:5> available
2014-05-03 23:11:13,948 INFO org.apache.hadoop.yarn.server.resourcemanager.scheduler.capacity.LeafQueue: assignedContainer application=application_1399156864902_0002 container=Container: [ContainerId: container_1399156864902_0002_01_000016, NodeId: nodea:56325, NodeHttpAddress: nodea:8042, Resource: <memory:1024, vCores:1>, Priority: 10, Token: Token { kind: ContainerToken, service: 10.0.0.182:56325 }, ] containerId=container_1399156864902_0002_01_000016 queue=default: capacity=1.0, absoluteCapacity=1.0, usedResources=<memory:12288, vCores:11>usedCapacity=0.375, absoluteUsedCapacity=0.375, numApps=1, numContainers=11 usedCapacity=0.375 absoluteUsedCapacity=0.375 used=<memory:12288, vCores:11> cluster=<memory:32768, vCores:32>
2014-05-03 23:11:13,948 INFO org.apache.hadoop.yarn.server.resourcemanager.scheduler.capacity.ParentQueue: Re-sorting assigned queue: root.default stats: default: capacity=1.0, absoluteCapacity=1.0, usedResources=<memory:13312, vCores:12>usedCapacity=0.40625, absoluteUsedCapacity=0.40625, numApps=1, numContainers=12
2014-05-03 23:11:13,948 INFO org.apache.hadoop.yarn.server.resourcemanager.scheduler.capacity.ParentQueue: assignedContainer queue=root usedCapacity=0.40625 absoluteUsedCapacity=0.40625 used=<memory:13312, vCores:12> cluster=<memory:32768, vCores:32>
2014-05-03 23:11:14,207 INFO org.apache.hadoop.yarn.server.resourcemanager.scheduler.AppSchedulingInfo: checking for deactivate... 
2014-05-03 23:11:14,208 INFO org.apache.hadoop.yarn.server.resourcemanager.rmcontainer.RMContainerImpl: container_1399156864902_0002_01_000014 Container Transitioned from ALLOCATED to ACQUIRED
2014-05-03 23:11:14,208 INFO org.apache.hadoop.yarn.server.resourcemanager.rmcontainer.RMContainerImpl: container_1399156864902_0002_01_000015 Container Transitioned from ALLOCATED to ACQUIRED
2014-05-03 23:11:14,208 INFO org.apache.hadoop.yarn.server.resourcemanager.rmcontainer.RMContainerImpl: container_1399156864902_0002_01_000016 Container Transitioned from ALLOCATED to ACQUIRED
2014-05-03 23:11:15,213 INFO org.apache.hadoop.yarn.server.resourcemanager.rmcontainer.RMContainerImpl: container_1399156864902_0002_01_000014 Container Transitioned from ACQUIRED to RELEASED
2014-05-03 23:11:15,213 INFO org.apache.hadoop.yarn.server.resourcemanager.scheduler.common.fica.FiCaSchedulerApp: Completed container: container_1399156864902_0002_01_000014 in state: RELEASED event:RELEASED
2014-05-03 23:11:15,213 INFO org.apache.hadoop.yarn.server.resourcemanager.RMAuditLogger: USER=ubuntu	IP=10.0.0.243	OPERATION=AM Released Container	TARGET=SchedulerApp	RESULT=SUCCESS	APPID=application_1399156864902_0002	CONTAINERID=container_1399156864902_0002_01_000014
2014-05-03 23:11:15,214 INFO org.apache.hadoop.yarn.server.resourcemanager.scheduler.common.fica.FiCaSchedulerNode: Released container container_1399156864902_0002_01_000014 of capacity <memory:1024, vCores:1> on host nodeb:55487, which currently has 3 containers, <memory:4096, vCores:3> used and <memory:4096, vCores:5> available, release resources=true
2014-05-03 23:11:15,214 INFO org.apache.hadoop.yarn.server.resourcemanager.scheduler.capacity.LeafQueue: default used=<memory:12288, vCores:11> numContainers=11 user=ubuntu user-resources=<memory:12288, vCores:11>
2014-05-03 23:11:15,214 INFO org.apache.hadoop.yarn.server.resourcemanager.scheduler.capacity.LeafQueue: completedContainer container=Container: [ContainerId: container_1399156864902_0002_01_000014, NodeId: nodeb:55487, NodeHttpAddress: nodeb:8042, Resource: <memory:1024, vCores:1>, Priority: 10, Token: Token { kind: ContainerToken, service: 10.0.0.243:55487 }, ] resource=<memory:1024, vCores:1> queue=default: capacity=1.0, absoluteCapacity=1.0, usedResources=<memory:12288, vCores:11>usedCapacity=0.375, absoluteUsedCapacity=0.375, numApps=1, numContainers=11 usedCapacity=0.375 absoluteUsedCapacity=0.375 used=<memory:12288, vCores:11> cluster=<memory:32768, vCores:32>
2014-05-03 23:11:15,214 INFO org.apache.hadoop.yarn.server.resourcemanager.scheduler.capacity.ParentQueue: completedContainer queue=root usedCapacity=0.375 absoluteUsedCapacity=0.375 used=<memory:12288, vCores:11> cluster=<memory:32768, vCores:32>
2014-05-03 23:11:15,214 INFO org.apache.hadoop.yarn.server.resourcemanager.scheduler.capacity.ParentQueue: Re-sorting completed queue: root.default stats: default: capacity=1.0, absoluteCapacity=1.0, usedResources=<memory:12288, vCores:11>usedCapacity=0.375, absoluteUsedCapacity=0.375, numApps=1, numContainers=11
2014-05-03 23:11:15,214 INFO org.apache.hadoop.yarn.server.resourcemanager.scheduler.capacity.CapacityScheduler: Application appattempt_1399156864902_0002_000001 released container container_1399156864902_0002_01_000014 on node: host: nodeb:55487 #containers=3 available=4096 used=4096 with event: RELEASED
2014-05-03 23:11:15,214 INFO org.apache.hadoop.yarn.server.resourcemanager.rmcontainer.RMContainerImpl: container_1399156864902_0002_01_000015 Container Transitioned from ACQUIRED to RELEASED
2014-05-03 23:11:15,214 INFO org.apache.hadoop.yarn.server.resourcemanager.scheduler.common.fica.FiCaSchedulerApp: Completed container: container_1399156864902_0002_01_000015 in state: RELEASED event:RELEASED
2014-05-03 23:11:15,215 INFO org.apache.hadoop.yarn.server.resourcemanager.RMAuditLogger: USER=ubuntu	IP=10.0.0.243	OPERATION=AM Released Container	TARGET=SchedulerApp	RESULT=SUCCESS	APPID=application_1399156864902_0002	CONTAINERID=container_1399156864902_0002_01_000015
2014-05-03 23:11:15,215 INFO org.apache.hadoop.yarn.server.resourcemanager.scheduler.common.fica.FiCaSchedulerNode: Released container container_1399156864902_0002_01_000015 of capacity <memory:1024, vCores:1> on host noded:50846, which currently has 2 containers, <memory:2048, vCores:2> used and <memory:6144, vCores:6> available, release resources=true
2014-05-03 23:11:15,215 INFO org.apache.hadoop.yarn.server.resourcemanager.scheduler.capacity.LeafQueue: default used=<memory:11264, vCores:10> numContainers=10 user=ubuntu user-resources=<memory:11264, vCores:10>
2014-05-03 23:11:15,215 INFO org.apache.hadoop.yarn.server.resourcemanager.scheduler.capacity.LeafQueue: completedContainer container=Container: [ContainerId: container_1399156864902_0002_01_000015, NodeId: noded:50846, NodeHttpAddress: noded:8042, Resource: <memory:1024, vCores:1>, Priority: 10, Token: Token { kind: ContainerToken, service: 10.0.0.244:50846 }, ] resource=<memory:1024, vCores:1> queue=default: capacity=1.0, absoluteCapacity=1.0, usedResources=<memory:11264, vCores:10>usedCapacity=0.34375, absoluteUsedCapacity=0.34375, numApps=1, numContainers=10 usedCapacity=0.34375 absoluteUsedCapacity=0.34375 used=<memory:11264, vCores:10> cluster=<memory:32768, vCores:32>
2014-05-03 23:11:15,215 INFO org.apache.hadoop.yarn.server.resourcemanager.scheduler.capacity.ParentQueue: completedContainer queue=root usedCapacity=0.34375 absoluteUsedCapacity=0.34375 used=<memory:11264, vCores:10> cluster=<memory:32768, vCores:32>
2014-05-03 23:11:15,215 INFO org.apache.hadoop.yarn.server.resourcemanager.scheduler.capacity.ParentQueue: Re-sorting completed queue: root.default stats: default: capacity=1.0, absoluteCapacity=1.0, usedResources=<memory:11264, vCores:10>usedCapacity=0.34375, absoluteUsedCapacity=0.34375, numApps=1, numContainers=10
2014-05-03 23:11:15,215 INFO org.apache.hadoop.yarn.server.resourcemanager.scheduler.capacity.CapacityScheduler: Application appattempt_1399156864902_0002_000001 released container container_1399156864902_0002_01_000015 on node: host: noded:50846 #containers=2 available=6144 used=2048 with event: RELEASED
2014-05-03 23:11:15,215 INFO org.apache.hadoop.yarn.server.resourcemanager.rmcontainer.RMContainerImpl: container_1399156864902_0002_01_000016 Container Transitioned from ACQUIRED to RELEASED
2014-05-03 23:11:15,215 INFO org.apache.hadoop.yarn.server.resourcemanager.scheduler.common.fica.FiCaSchedulerApp: Completed container: container_1399156864902_0002_01_000016 in state: RELEASED event:RELEASED
2014-05-03 23:11:15,215 INFO org.apache.hadoop.yarn.server.resourcemanager.RMAuditLogger: USER=ubuntu	IP=10.0.0.243	OPERATION=AM Released Container	TARGET=SchedulerApp	RESULT=SUCCESS	APPID=application_1399156864902_0002	CONTAINERID=container_1399156864902_0002_01_000016
2014-05-03 23:11:15,216 INFO org.apache.hadoop.yarn.server.resourcemanager.scheduler.common.fica.FiCaSchedulerNode: Released container container_1399156864902_0002_01_000016 of capacity <memory:1024, vCores:1> on host nodea:56325, which currently has 2 containers, <memory:2048, vCores:2> used and <memory:6144, vCores:6> available, release resources=true
2014-05-03 23:11:15,216 INFO org.apache.hadoop.yarn.server.resourcemanager.scheduler.capacity.LeafQueue: default used=<memory:10240, vCores:9> numContainers=9 user=ubuntu user-resources=<memory:10240, vCores:9>
2014-05-03 23:11:15,216 INFO org.apache.hadoop.yarn.server.resourcemanager.scheduler.capacity.LeafQueue: completedContainer container=Container: [ContainerId: container_1399156864902_0002_01_000016, NodeId: nodea:56325, NodeHttpAddress: nodea:8042, Resource: <memory:1024, vCores:1>, Priority: 10, Token: Token { kind: ContainerToken, service: 10.0.0.182:56325 }, ] resource=<memory:1024, vCores:1> queue=default: capacity=1.0, absoluteCapacity=1.0, usedResources=<memory:10240, vCores:9>usedCapacity=0.3125, absoluteUsedCapacity=0.3125, numApps=1, numContainers=9 usedCapacity=0.3125 absoluteUsedCapacity=0.3125 used=<memory:10240, vCores:9> cluster=<memory:32768, vCores:32>
2014-05-03 23:11:15,216 INFO org.apache.hadoop.yarn.server.resourcemanager.scheduler.capacity.ParentQueue: completedContainer queue=root usedCapacity=0.3125 absoluteUsedCapacity=0.3125 used=<memory:10240, vCores:9> cluster=<memory:32768, vCores:32>
2014-05-03 23:11:15,216 INFO org.apache.hadoop.yarn.server.resourcemanager.scheduler.capacity.ParentQueue: Re-sorting completed queue: root.default stats: default: capacity=1.0, absoluteCapacity=1.0, usedResources=<memory:10240, vCores:9>usedCapacity=0.3125, absoluteUsedCapacity=0.3125, numApps=1, numContainers=9
2014-05-03 23:11:15,216 INFO org.apache.hadoop.yarn.server.resourcemanager.scheduler.capacity.CapacityScheduler: Application appattempt_1399156864902_0002_000001 released container container_1399156864902_0002_01_000016 on node: host: nodea:56325 #containers=2 available=6144 used=2048 with event: RELEASED
2014-05-03 23:12:54,976 INFO org.apache.hadoop.yarn.server.resourcemanager.rmcontainer.RMContainerImpl: container_1399156864902_0002_01_000012 Container Transitioned from RUNNING to COMPLETED
2014-05-03 23:12:54,976 INFO org.apache.hadoop.yarn.server.resourcemanager.scheduler.common.fica.FiCaSchedulerApp: Completed container: container_1399156864902_0002_01_000012 in state: COMPLETED event:FINISHED
2014-05-03 23:12:54,976 INFO org.apache.hadoop.yarn.server.resourcemanager.RMAuditLogger: USER=ubuntu	OPERATION=AM Released Container	TARGET=SchedulerApp	RESULT=SUCCESS	APPID=application_1399156864902_0002	CONTAINERID=container_1399156864902_0002_01_000012
2014-05-03 23:12:54,976 INFO org.apache.hadoop.yarn.server.resourcemanager.scheduler.common.fica.FiCaSchedulerNode: Released container container_1399156864902_0002_01_000012 of capacity <memory:1024, vCores:1> on host noded:50846, which currently has 1 containers, <memory:1024, vCores:1> used and <memory:7168, vCores:7> available, release resources=true
2014-05-03 23:12:54,976 INFO org.apache.hadoop.yarn.server.resourcemanager.scheduler.capacity.LeafQueue: default used=<memory:9216, vCores:8> numContainers=8 user=ubuntu user-resources=<memory:9216, vCores:8>
2014-05-03 23:12:54,976 INFO org.apache.hadoop.yarn.server.resourcemanager.scheduler.capacity.LeafQueue: completedContainer container=Container: [ContainerId: container_1399156864902_0002_01_000012, NodeId: noded:50846, NodeHttpAddress: noded:8042, Resource: <memory:1024, vCores:1>, Priority: 10, Token: Token { kind: ContainerToken, service: 10.0.0.244:50846 }, ] resource=<memory:1024, vCores:1> queue=default: capacity=1.0, absoluteCapacity=1.0, usedResources=<memory:9216, vCores:8>usedCapacity=0.28125, absoluteUsedCapacity=0.28125, numApps=1, numContainers=8 usedCapacity=0.28125 absoluteUsedCapacity=0.28125 used=<memory:9216, vCores:8> cluster=<memory:32768, vCores:32>
2014-05-03 23:12:54,976 INFO org.apache.hadoop.yarn.server.resourcemanager.scheduler.capacity.ParentQueue: completedContainer queue=root usedCapacity=0.28125 absoluteUsedCapacity=0.28125 used=<memory:9216, vCores:8> cluster=<memory:32768, vCores:32>
2014-05-03 23:12:54,976 INFO org.apache.hadoop.yarn.server.resourcemanager.scheduler.capacity.ParentQueue: Re-sorting completed queue: root.default stats: default: capacity=1.0, absoluteCapacity=1.0, usedResources=<memory:9216, vCores:8>usedCapacity=0.28125, absoluteUsedCapacity=0.28125, numApps=1, numContainers=8
2014-05-03 23:12:54,977 INFO org.apache.hadoop.yarn.server.resourcemanager.scheduler.capacity.CapacityScheduler: Application appattempt_1399156864902_0002_000001 released container container_1399156864902_0002_01_000012 on node: host: noded:50846 #containers=1 available=7168 used=1024 with event: FINISHED
2014-05-03 23:12:59,217 INFO org.apache.hadoop.yarn.server.resourcemanager.rmcontainer.RMContainerImpl: container_1399156864902_0002_01_000008 Container Transitioned from RUNNING to COMPLETED
2014-05-03 23:12:59,218 INFO org.apache.hadoop.yarn.server.resourcemanager.scheduler.common.fica.FiCaSchedulerApp: Completed container: container_1399156864902_0002_01_000008 in state: COMPLETED event:FINISHED
2014-05-03 23:12:59,218 INFO org.apache.hadoop.yarn.server.resourcemanager.RMAuditLogger: USER=ubuntu	OPERATION=AM Released Container	TARGET=SchedulerApp	RESULT=SUCCESS	APPID=application_1399156864902_0002	CONTAINERID=container_1399156864902_0002_01_000008
2014-05-03 23:12:59,218 INFO org.apache.hadoop.yarn.server.resourcemanager.scheduler.common.fica.FiCaSchedulerNode: Released container container_1399156864902_0002_01_000008 of capacity <memory:1024, vCores:1> on host noded:50846, which currently has 0 containers, <memory:0, vCores:0> used and <memory:8192, vCores:8> available, release resources=true
2014-05-03 23:12:59,218 INFO org.apache.hadoop.yarn.server.resourcemanager.scheduler.capacity.LeafQueue: default used=<memory:8192, vCores:7> numContainers=7 user=ubuntu user-resources=<memory:8192, vCores:7>
2014-05-03 23:12:59,218 INFO org.apache.hadoop.yarn.server.resourcemanager.scheduler.capacity.LeafQueue: completedContainer container=Container: [ContainerId: container_1399156864902_0002_01_000008, NodeId: noded:50846, NodeHttpAddress: noded:8042, Resource: <memory:1024, vCores:1>, Priority: 10, Token: Token { kind: ContainerToken, service: 10.0.0.244:50846 }, ] resource=<memory:1024, vCores:1> queue=default: capacity=1.0, absoluteCapacity=1.0, usedResources=<memory:8192, vCores:7>usedCapacity=0.25, absoluteUsedCapacity=0.25, numApps=1, numContainers=7 usedCapacity=0.25 absoluteUsedCapacity=0.25 used=<memory:8192, vCores:7> cluster=<memory:32768, vCores:32>
2014-05-03 23:12:59,218 INFO org.apache.hadoop.yarn.server.resourcemanager.scheduler.capacity.ParentQueue: completedContainer queue=root usedCapacity=0.25 absoluteUsedCapacity=0.25 used=<memory:8192, vCores:7> cluster=<memory:32768, vCores:32>
2014-05-03 23:12:59,218 INFO org.apache.hadoop.yarn.server.resourcemanager.scheduler.capacity.ParentQueue: Re-sorting completed queue: root.default stats: default: capacity=1.0, absoluteCapacity=1.0, usedResources=<memory:8192, vCores:7>usedCapacity=0.25, absoluteUsedCapacity=0.25, numApps=1, numContainers=7
2014-05-03 23:12:59,218 INFO org.apache.hadoop.yarn.server.resourcemanager.scheduler.capacity.CapacityScheduler: Application appattempt_1399156864902_0002_000001 released container container_1399156864902_0002_01_000008 on node: host: noded:50846 #containers=0 available=8192 used=0 with event: FINISHED
2014-05-03 23:13:29,187 INFO org.apache.hadoop.yarn.server.resourcemanager.rmcontainer.RMContainerImpl: container_1399156864902_0002_01_000007 Container Transitioned from RUNNING to COMPLETED
2014-05-03 23:13:29,188 INFO org.apache.hadoop.yarn.server.resourcemanager.scheduler.common.fica.FiCaSchedulerApp: Completed container: container_1399156864902_0002_01_000007 in state: COMPLETED event:FINISHED
2014-05-03 23:13:29,188 INFO org.apache.hadoop.yarn.server.resourcemanager.RMAuditLogger: USER=ubuntu	OPERATION=AM Released Container	TARGET=SchedulerApp	RESULT=SUCCESS	APPID=application_1399156864902_0002	CONTAINERID=container_1399156864902_0002_01_000007
2014-05-03 23:13:29,188 INFO org.apache.hadoop.yarn.server.resourcemanager.scheduler.common.fica.FiCaSchedulerNode: Released container container_1399156864902_0002_01_000007 of capacity <memory:1024, vCores:1> on host nodeb:55487, which currently has 2 containers, <memory:3072, vCores:2> used and <memory:5120, vCores:6> available, release resources=true
2014-05-03 23:13:29,188 INFO org.apache.hadoop.yarn.server.resourcemanager.scheduler.capacity.LeafQueue: default used=<memory:7168, vCores:6> numContainers=6 user=ubuntu user-resources=<memory:7168, vCores:6>
2014-05-03 23:13:29,188 INFO org.apache.hadoop.yarn.server.resourcemanager.scheduler.capacity.LeafQueue: completedContainer container=Container: [ContainerId: container_1399156864902_0002_01_000007, NodeId: nodeb:55487, NodeHttpAddress: nodeb:8042, Resource: <memory:1024, vCores:1>, Priority: 10, Token: Token { kind: ContainerToken, service: 10.0.0.243:55487 }, ] resource=<memory:1024, vCores:1> queue=default: capacity=1.0, absoluteCapacity=1.0, usedResources=<memory:7168, vCores:6>usedCapacity=0.21875, absoluteUsedCapacity=0.21875, numApps=1, numContainers=6 usedCapacity=0.21875 absoluteUsedCapacity=0.21875 used=<memory:7168, vCores:6> cluster=<memory:32768, vCores:32>
2014-05-03 23:13:29,188 INFO org.apache.hadoop.yarn.server.resourcemanager.scheduler.capacity.ParentQueue: completedContainer queue=root usedCapacity=0.21875 absoluteUsedCapacity=0.21875 used=<memory:7168, vCores:6> cluster=<memory:32768, vCores:32>
2014-05-03 23:13:29,188 INFO org.apache.hadoop.yarn.server.resourcemanager.scheduler.capacity.ParentQueue: Re-sorting completed queue: root.default stats: default: capacity=1.0, absoluteCapacity=1.0, usedResources=<memory:7168, vCores:6>usedCapacity=0.21875, absoluteUsedCapacity=0.21875, numApps=1, numContainers=6
2014-05-03 23:13:29,188 INFO org.apache.hadoop.yarn.server.resourcemanager.scheduler.capacity.CapacityScheduler: Application appattempt_1399156864902_0002_000001 released container container_1399156864902_0002_01_000007 on node: host: nodeb:55487 #containers=2 available=5120 used=3072 with event: FINISHED
2014-05-03 23:13:30,864 INFO org.apache.hadoop.yarn.server.resourcemanager.rmcontainer.RMContainerImpl: container_1399156864902_0002_01_000006 Container Transitioned from RUNNING to COMPLETED
2014-05-03 23:13:30,864 INFO org.apache.hadoop.yarn.server.resourcemanager.scheduler.common.fica.FiCaSchedulerApp: Completed container: container_1399156864902_0002_01_000006 in state: COMPLETED event:FINISHED
2014-05-03 23:13:30,864 INFO org.apache.hadoop.yarn.server.resourcemanager.RMAuditLogger: USER=ubuntu	OPERATION=AM Released Container	TARGET=SchedulerApp	RESULT=SUCCESS	APPID=application_1399156864902_0002	CONTAINERID=container_1399156864902_0002_01_000006
2014-05-03 23:13:30,864 INFO org.apache.hadoop.yarn.server.resourcemanager.scheduler.common.fica.FiCaSchedulerNode: Released container container_1399156864902_0002_01_000006 of capacity <memory:1024, vCores:1> on host nodec:54860, which currently has 1 containers, <memory:1024, vCores:1> used and <memory:7168, vCores:7> available, release resources=true
2014-05-03 23:13:30,864 INFO org.apache.hadoop.yarn.server.resourcemanager.scheduler.capacity.LeafQueue: default used=<memory:6144, vCores:5> numContainers=5 user=ubuntu user-resources=<memory:6144, vCores:5>
2014-05-03 23:13:30,864 INFO org.apache.hadoop.yarn.server.resourcemanager.scheduler.capacity.LeafQueue: completedContainer container=Container: [ContainerId: container_1399156864902_0002_01_000006, NodeId: nodec:54860, NodeHttpAddress: nodec:8042, Resource: <memory:1024, vCores:1>, Priority: 10, Token: Token { kind: ContainerToken, service: 10.0.0.245:54860 }, ] resource=<memory:1024, vCores:1> queue=default: capacity=1.0, absoluteCapacity=1.0, usedResources=<memory:6144, vCores:5>usedCapacity=0.1875, absoluteUsedCapacity=0.1875, numApps=1, numContainers=5 usedCapacity=0.1875 absoluteUsedCapacity=0.1875 used=<memory:6144, vCores:5> cluster=<memory:32768, vCores:32>
2014-05-03 23:13:30,864 INFO org.apache.hadoop.yarn.server.resourcemanager.scheduler.capacity.ParentQueue: completedContainer queue=root usedCapacity=0.1875 absoluteUsedCapacity=0.1875 used=<memory:6144, vCores:5> cluster=<memory:32768, vCores:32>
2014-05-03 23:13:30,864 INFO org.apache.hadoop.yarn.server.resourcemanager.scheduler.capacity.ParentQueue: Re-sorting completed queue: root.default stats: default: capacity=1.0, absoluteCapacity=1.0, usedResources=<memory:6144, vCores:5>usedCapacity=0.1875, absoluteUsedCapacity=0.1875, numApps=1, numContainers=5
2014-05-03 23:13:30,864 INFO org.apache.hadoop.yarn.server.resourcemanager.scheduler.capacity.CapacityScheduler: Application appattempt_1399156864902_0002_000001 released container container_1399156864902_0002_01_000006 on node: host: nodec:54860 #containers=1 available=7168 used=1024 with event: FINISHED
2014-05-03 23:13:31,874 INFO org.apache.hadoop.yarn.server.resourcemanager.rmcontainer.RMContainerImpl: container_1399156864902_0002_01_000010 Container Transitioned from RUNNING to COMPLETED
2014-05-03 23:13:31,875 INFO org.apache.hadoop.yarn.server.resourcemanager.scheduler.common.fica.FiCaSchedulerApp: Completed container: container_1399156864902_0002_01_000010 in state: COMPLETED event:FINISHED
2014-05-03 23:13:31,875 INFO org.apache.hadoop.yarn.server.resourcemanager.RMAuditLogger: USER=ubuntu	OPERATION=AM Released Container	TARGET=SchedulerApp	RESULT=SUCCESS	APPID=application_1399156864902_0002	CONTAINERID=container_1399156864902_0002_01_000010
2014-05-03 23:13:31,875 INFO org.apache.hadoop.yarn.server.resourcemanager.scheduler.common.fica.FiCaSchedulerNode: Released container container_1399156864902_0002_01_000010 of capacity <memory:1024, vCores:1> on host nodec:54860, which currently has 0 containers, <memory:0, vCores:0> used and <memory:8192, vCores:8> available, release resources=true
2014-05-03 23:13:31,875 INFO org.apache.hadoop.yarn.server.resourcemanager.scheduler.capacity.LeafQueue: default used=<memory:5120, vCores:4> numContainers=4 user=ubuntu user-resources=<memory:5120, vCores:4>
2014-05-03 23:13:31,875 INFO org.apache.hadoop.yarn.server.resourcemanager.scheduler.capacity.LeafQueue: completedContainer container=Container: [ContainerId: container_1399156864902_0002_01_000010, NodeId: nodec:54860, NodeHttpAddress: nodec:8042, Resource: <memory:1024, vCores:1>, Priority: 10, Token: Token { kind: ContainerToken, service: 10.0.0.245:54860 }, ] resource=<memory:1024, vCores:1> queue=default: capacity=1.0, absoluteCapacity=1.0, usedResources=<memory:5120, vCores:4>usedCapacity=0.15625, absoluteUsedCapacity=0.15625, numApps=1, numContainers=4 usedCapacity=0.15625 absoluteUsedCapacity=0.15625 used=<memory:5120, vCores:4> cluster=<memory:32768, vCores:32>
2014-05-03 23:13:31,875 INFO org.apache.hadoop.yarn.server.resourcemanager.scheduler.capacity.ParentQueue: completedContainer queue=root usedCapacity=0.15625 absoluteUsedCapacity=0.15625 used=<memory:5120, vCores:4> cluster=<memory:32768, vCores:32>
2014-05-03 23:13:31,875 INFO org.apache.hadoop.yarn.server.resourcemanager.scheduler.capacity.ParentQueue: Re-sorting completed queue: root.default stats: default: capacity=1.0, absoluteCapacity=1.0, usedResources=<memory:5120, vCores:4>usedCapacity=0.15625, absoluteUsedCapacity=0.15625, numApps=1, numContainers=4
2014-05-03 23:13:31,875 INFO org.apache.hadoop.yarn.server.resourcemanager.scheduler.capacity.CapacityScheduler: Application appattempt_1399156864902_0002_000001 released container container_1399156864902_0002_01_000010 on node: host: nodec:54860 #containers=0 available=8192 used=0 with event: FINISHED
2014-05-03 23:13:31,886 INFO org.apache.hadoop.yarn.server.resourcemanager.rmcontainer.RMContainerImpl: container_1399156864902_0002_01_000013 Container Transitioned from RUNNING to COMPLETED
2014-05-03 23:13:31,886 INFO org.apache.hadoop.yarn.server.resourcemanager.scheduler.common.fica.FiCaSchedulerApp: Completed container: container_1399156864902_0002_01_000013 in state: COMPLETED event:FINISHED
2014-05-03 23:13:31,886 INFO org.apache.hadoop.yarn.server.resourcemanager.RMAuditLogger: USER=ubuntu	OPERATION=AM Released Container	TARGET=SchedulerApp	RESULT=SUCCESS	APPID=application_1399156864902_0002	CONTAINERID=container_1399156864902_0002_01_000013
2014-05-03 23:13:31,886 INFO org.apache.hadoop.yarn.server.resourcemanager.scheduler.common.fica.FiCaSchedulerNode: Released container container_1399156864902_0002_01_000013 of capacity <memory:1024, vCores:1> on host nodea:56325, which currently has 1 containers, <memory:1024, vCores:1> used and <memory:7168, vCores:7> available, release resources=true
2014-05-03 23:13:31,886 INFO org.apache.hadoop.yarn.server.resourcemanager.scheduler.capacity.LeafQueue: default used=<memory:4096, vCores:3> numContainers=3 user=ubuntu user-resources=<memory:4096, vCores:3>
2014-05-03 23:13:31,886 INFO org.apache.hadoop.yarn.server.resourcemanager.scheduler.capacity.LeafQueue: completedContainer container=Container: [ContainerId: container_1399156864902_0002_01_000013, NodeId: nodea:56325, NodeHttpAddress: nodea:8042, Resource: <memory:1024, vCores:1>, Priority: 10, Token: Token { kind: ContainerToken, service: 10.0.0.182:56325 }, ] resource=<memory:1024, vCores:1> queue=default: capacity=1.0, absoluteCapacity=1.0, usedResources=<memory:4096, vCores:3>usedCapacity=0.125, absoluteUsedCapacity=0.125, numApps=1, numContainers=3 usedCapacity=0.125 absoluteUsedCapacity=0.125 used=<memory:4096, vCores:3> cluster=<memory:32768, vCores:32>
2014-05-03 23:13:31,886 INFO org.apache.hadoop.yarn.server.resourcemanager.scheduler.capacity.ParentQueue: completedContainer queue=root usedCapacity=0.125 absoluteUsedCapacity=0.125 used=<memory:4096, vCores:3> cluster=<memory:32768, vCores:32>
2014-05-03 23:13:31,887 INFO org.apache.hadoop.yarn.server.resourcemanager.scheduler.capacity.ParentQueue: Re-sorting completed queue: root.default stats: default: capacity=1.0, absoluteCapacity=1.0, usedResources=<memory:4096, vCores:3>usedCapacity=0.125, absoluteUsedCapacity=0.125, numApps=1, numContainers=3
2014-05-03 23:13:31,887 INFO org.apache.hadoop.yarn.server.resourcemanager.scheduler.capacity.CapacityScheduler: Application appattempt_1399156864902_0002_000001 released container container_1399156864902_0002_01_000013 on node: host: nodea:56325 #containers=1 available=7168 used=1024 with event: FINISHED
2014-05-03 23:13:32,888 INFO org.apache.hadoop.yarn.server.resourcemanager.rmcontainer.RMContainerImpl: container_1399156864902_0002_01_000009 Container Transitioned from RUNNING to COMPLETED
2014-05-03 23:13:32,888 INFO org.apache.hadoop.yarn.server.resourcemanager.scheduler.common.fica.FiCaSchedulerApp: Completed container: container_1399156864902_0002_01_000009 in state: COMPLETED event:FINISHED
2014-05-03 23:13:32,888 INFO org.apache.hadoop.yarn.server.resourcemanager.RMAuditLogger: USER=ubuntu	OPERATION=AM Released Container	TARGET=SchedulerApp	RESULT=SUCCESS	APPID=application_1399156864902_0002	CONTAINERID=container_1399156864902_0002_01_000009
2014-05-03 23:13:32,888 INFO org.apache.hadoop.yarn.server.resourcemanager.scheduler.common.fica.FiCaSchedulerNode: Released container container_1399156864902_0002_01_000009 of capacity <memory:1024, vCores:1> on host nodea:56325, which currently has 0 containers, <memory:0, vCores:0> used and <memory:8192, vCores:8> available, release resources=true
2014-05-03 23:13:32,888 INFO org.apache.hadoop.yarn.server.resourcemanager.scheduler.capacity.LeafQueue: default used=<memory:3072, vCores:2> numContainers=2 user=ubuntu user-resources=<memory:3072, vCores:2>
2014-05-03 23:13:32,888 INFO org.apache.hadoop.yarn.server.resourcemanager.scheduler.capacity.LeafQueue: completedContainer container=Container: [ContainerId: container_1399156864902_0002_01_000009, NodeId: nodea:56325, NodeHttpAddress: nodea:8042, Resource: <memory:1024, vCores:1>, Priority: 10, Token: Token { kind: ContainerToken, service: 10.0.0.182:56325 }, ] resource=<memory:1024, vCores:1> queue=default: capacity=1.0, absoluteCapacity=1.0, usedResources=<memory:3072, vCores:2>usedCapacity=0.09375, absoluteUsedCapacity=0.09375, numApps=1, numContainers=2 usedCapacity=0.09375 absoluteUsedCapacity=0.09375 used=<memory:3072, vCores:2> cluster=<memory:32768, vCores:32>
2014-05-03 23:13:32,888 INFO org.apache.hadoop.yarn.server.resourcemanager.scheduler.capacity.ParentQueue: completedContainer queue=root usedCapacity=0.09375 absoluteUsedCapacity=0.09375 used=<memory:3072, vCores:2> cluster=<memory:32768, vCores:32>
2014-05-03 23:13:32,888 INFO org.apache.hadoop.yarn.server.resourcemanager.scheduler.capacity.ParentQueue: Re-sorting completed queue: root.default stats: default: capacity=1.0, absoluteCapacity=1.0, usedResources=<memory:3072, vCores:2>usedCapacity=0.09375, absoluteUsedCapacity=0.09375, numApps=1, numContainers=2
2014-05-03 23:13:32,888 INFO org.apache.hadoop.yarn.server.resourcemanager.scheduler.capacity.CapacityScheduler: Application appattempt_1399156864902_0002_000001 released container container_1399156864902_0002_01_000009 on node: host: nodea:56325 #containers=0 available=8192 used=0 with event: FINISHED
2014-05-03 23:13:34,040 INFO org.apache.hadoop.yarn.server.resourcemanager.rmapp.attempt.RMAppAttemptImpl: appattempt_1399156864902_0002_000001 State change from RUNNING to FINISHING
2014-05-03 23:13:34,040 INFO org.apache.hadoop.yarn.server.resourcemanager.rmapp.RMAppImpl: Removing application with id application_1399156864902_0002
2014-05-03 23:13:34,041 INFO org.apache.hadoop.yarn.server.resourcemanager.rmapp.RMAppImpl: application_1399156864902_0002 State change from RUNNING to REMOVING
2014-05-03 23:13:34,041 INFO org.apache.hadoop.yarn.server.resourcemanager.recovery.RMStateStore: Removing info for app: application_1399156864902_0002
2014-05-03 23:13:34,041 INFO org.apache.hadoop.yarn.server.resourcemanager.rmapp.RMAppImpl: application_1399156864902_0002 State change from REMOVING to FINISHING
2014-05-03 23:13:34,837 INFO org.apache.hadoop.yarn.server.resourcemanager.rmcontainer.RMContainerImpl: container_1399156864902_0002_01_000011 Container Transitioned from RUNNING to COMPLETED
2014-05-03 23:13:34,837 INFO org.apache.hadoop.yarn.server.resourcemanager.scheduler.common.fica.FiCaSchedulerApp: Completed container: container_1399156864902_0002_01_000011 in state: COMPLETED event:FINISHED
2014-05-03 23:13:34,838 INFO org.apache.hadoop.yarn.server.resourcemanager.RMAuditLogger: USER=ubuntu	OPERATION=AM Released Container	TARGET=SchedulerApp	RESULT=SUCCESS	APPID=application_1399156864902_0002	CONTAINERID=container_1399156864902_0002_01_000011
2014-05-03 23:13:34,838 INFO org.apache.hadoop.yarn.server.resourcemanager.scheduler.common.fica.FiCaSchedulerNode: Released container container_1399156864902_0002_01_000011 of capacity <memory:1024, vCores:1> on host nodeb:55487, which currently has 1 containers, <memory:2048, vCores:1> used and <memory:6144, vCores:7> available, release resources=true
2014-05-03 23:13:34,838 INFO org.apache.hadoop.yarn.server.resourcemanager.scheduler.capacity.LeafQueue: default used=<memory:2048, vCores:1> numContainers=1 user=ubuntu user-resources=<memory:2048, vCores:1>
2014-05-03 23:13:34,838 INFO org.apache.hadoop.yarn.server.resourcemanager.scheduler.capacity.LeafQueue: completedContainer container=Container: [ContainerId: container_1399156864902_0002_01_000011, NodeId: nodeb:55487, NodeHttpAddress: nodeb:8042, Resource: <memory:1024, vCores:1>, Priority: 10, Token: Token { kind: ContainerToken, service: 10.0.0.243:55487 }, ] resource=<memory:1024, vCores:1> queue=default: capacity=1.0, absoluteCapacity=1.0, usedResources=<memory:2048, vCores:1>usedCapacity=0.0625, absoluteUsedCapacity=0.0625, numApps=1, numContainers=1 usedCapacity=0.0625 absoluteUsedCapacity=0.0625 used=<memory:2048, vCores:1> cluster=<memory:32768, vCores:32>
2014-05-03 23:13:34,838 INFO org.apache.hadoop.yarn.server.resourcemanager.scheduler.capacity.ParentQueue: completedContainer queue=root usedCapacity=0.0625 absoluteUsedCapacity=0.0625 used=<memory:2048, vCores:1> cluster=<memory:32768, vCores:32>
2014-05-03 23:13:34,838 INFO org.apache.hadoop.yarn.server.resourcemanager.scheduler.capacity.ParentQueue: Re-sorting completed queue: root.default stats: default: capacity=1.0, absoluteCapacity=1.0, usedResources=<memory:2048, vCores:1>usedCapacity=0.0625, absoluteUsedCapacity=0.0625, numApps=1, numContainers=1
2014-05-03 23:13:34,838 INFO org.apache.hadoop.yarn.server.resourcemanager.scheduler.capacity.CapacityScheduler: Application appattempt_1399156864902_0002_000001 released container container_1399156864902_0002_01_000011 on node: host: nodeb:55487 #containers=1 available=6144 used=2048 with event: FINISHED
2014-05-03 23:13:40,848 INFO org.apache.hadoop.yarn.server.resourcemanager.rmcontainer.RMContainerImpl: container_1399156864902_0002_01_000001 Container Transitioned from RUNNING to COMPLETED
2014-05-03 23:13:40,848 INFO org.apache.hadoop.yarn.server.resourcemanager.ApplicationMasterService: Unregistering app attempt : appattempt_1399156864902_0002_000001
2014-05-03 23:13:40,848 INFO org.apache.hadoop.yarn.server.resourcemanager.scheduler.common.fica.FiCaSchedulerApp: Completed container: container_1399156864902_0002_01_000001 in state: COMPLETED event:FINISHED
2014-05-03 23:13:40,849 INFO org.apache.hadoop.yarn.server.resourcemanager.rmapp.attempt.RMAppAttemptImpl: appattempt_1399156864902_0002_000001 State change from FINISHING to FINISHED
2014-05-03 23:13:40,849 INFO org.apache.hadoop.yarn.server.resourcemanager.RMAuditLogger: USER=ubuntu	OPERATION=AM Released Container	TARGET=SchedulerApp	RESULT=SUCCESS	APPID=application_1399156864902_0002	CONTAINERID=container_1399156864902_0002_01_000001
2014-05-03 23:13:40,849 INFO org.apache.hadoop.yarn.server.resourcemanager.rmapp.RMAppImpl: application_1399156864902_0002 State change from FINISHING to FINISHED
2014-05-03 23:13:40,849 INFO org.apache.hadoop.yarn.server.resourcemanager.scheduler.common.fica.FiCaSchedulerNode: Released container container_1399156864902_0002_01_000001 of capacity <memory:2048, vCores:1> on host nodeb:55487, which currently has 0 containers, <memory:0, vCores:0> used and <memory:8192, vCores:8> available, release resources=true
2014-05-03 23:13:40,849 INFO org.apache.hadoop.yarn.server.resourcemanager.scheduler.capacity.LeafQueue: default used=<memory:0, vCores:0> numContainers=0 user=ubuntu user-resources=<memory:0, vCores:0>
2014-05-03 23:13:40,849 INFO org.apache.hadoop.yarn.server.resourcemanager.scheduler.capacity.LeafQueue: completedContainer container=Container: [ContainerId: container_1399156864902_0002_01_000001, NodeId: nodeb:55487, NodeHttpAddress: nodeb:8042, Resource: <memory:2048, vCores:1>, Priority: 0, Token: Token { kind: ContainerToken, service: 10.0.0.243:55487 }, ] resource=<memory:2048, vCores:1> queue=default: capacity=1.0, absoluteCapacity=1.0, usedResources=<memory:0, vCores:0>usedCapacity=0.0, absoluteUsedCapacity=0.0, numApps=1, numContainers=0 usedCapacity=0.0 absoluteUsedCapacity=0.0 used=<memory:0, vCores:0> cluster=<memory:32768, vCores:32>
2014-05-03 23:13:40,849 INFO org.apache.hadoop.yarn.server.resourcemanager.RMAuditLogger: USER=ubuntu	OPERATION=Application Finished - Succeeded	TARGET=RMAppManager	RESULT=SUCCESS	APPID=application_1399156864902_0002
2014-05-03 23:13:40,849 INFO org.apache.hadoop.yarn.server.resourcemanager.scheduler.capacity.ParentQueue: completedContainer queue=root usedCapacity=0.0 absoluteUsedCapacity=0.0 used=<memory:0, vCores:0> cluster=<memory:32768, vCores:32>
2014-05-03 23:13:40,850 INFO org.apache.hadoop.yarn.server.resourcemanager.scheduler.capacity.ParentQueue: Re-sorting completed queue: root.default stats: default: capacity=1.0, absoluteCapacity=1.0, usedResources=<memory:0, vCores:0>usedCapacity=0.0, absoluteUsedCapacity=0.0, numApps=1, numContainers=0
2014-05-03 23:13:40,850 INFO org.apache.hadoop.yarn.server.resourcemanager.RMAppManager$ApplicationSummary: appId=application_1399156864902_0002,name=base||path:/in1m||num reduce:8,user=ubuntu,queue=default,state=FINISHED,trackingUrl=ec2-54-186-230-200.us-west-2.compute.amazonaws.com:8088/proxy/application_1399156864902_0002/jobhistory/job/job_1399156864902_0002,appMasterHost=ip-10-0-0-243,startTime=1399158632499,finishTime=1399158814041,finalStatus=SUCCEEDED
2014-05-03 23:13:40,850 INFO org.apache.hadoop.yarn.server.resourcemanager.scheduler.capacity.CapacityScheduler: Application appattempt_1399156864902_0002_000001 released container container_1399156864902_0002_01_000001 on node: host: nodeb:55487 #containers=0 available=8192 used=0 with event: FINISHED
2014-05-03 23:13:40,850 INFO org.apache.hadoop.yarn.server.resourcemanager.scheduler.capacity.CapacityScheduler: Application appattempt_1399156864902_0002_000001 is done. finalState=FINISHED
2014-05-03 23:13:40,850 INFO org.apache.hadoop.yarn.server.resourcemanager.scheduler.AppSchedulingInfo: Application application_1399156864902_0002 requests cleared
2014-05-03 23:13:40,850 INFO org.apache.hadoop.yarn.server.resourcemanager.amlauncher.AMLauncher: Cleaning master appattempt_1399156864902_0002_000001
2014-05-03 23:13:40,850 INFO org.apache.hadoop.yarn.server.resourcemanager.scheduler.capacity.LeafQueue: Application removed - appId: application_1399156864902_0002 user: ubuntu queue: default #user-pending-applications: 0 #user-active-applications: 0 #queue-pending-applications: 0 #queue-active-applications: 0
2014-05-03 23:13:40,850 INFO org.apache.hadoop.yarn.server.resourcemanager.scheduler.capacity.ParentQueue: Application removed - appId: application_1399156864902_0002 user: ubuntu leaf-queue of parent: root #applications: 0
2014-05-03 23:17:18,077 INFO org.apache.hadoop.yarn.server.resourcemanager.ClientRMService: Allocated new applicationId: 3
2014-05-03 23:17:19,388 INFO org.apache.hadoop.yarn.server.resourcemanager.ClientRMService: Application with id 3 submitted by user ubuntu
2014-05-03 23:17:19,388 INFO org.apache.hadoop.yarn.server.resourcemanager.rmapp.RMAppImpl: Storing application with id application_1399156864902_0003
2014-05-03 23:17:19,388 INFO org.apache.hadoop.yarn.server.resourcemanager.RMAuditLogger: USER=ubuntu	IP=10.0.0.182	OPERATION=Submit Application Request	TARGET=ClientRMService	RESULT=SUCCESS	APPID=application_1399156864902_0003
2014-05-03 23:17:19,388 INFO org.apache.hadoop.yarn.server.resourcemanager.recovery.RMStateStore: Storing info for app: application_1399156864902_0003
2014-05-03 23:17:19,388 INFO org.apache.hadoop.yarn.server.resourcemanager.rmapp.RMAppImpl: application_1399156864902_0003 State change from NEW to NEW_SAVING
2014-05-03 23:17:19,390 INFO org.apache.hadoop.yarn.server.resourcemanager.rmapp.RMAppImpl: application_1399156864902_0003 State change from NEW_SAVING to SUBMITTED
2014-05-03 23:17:19,390 INFO org.apache.hadoop.yarn.server.resourcemanager.ApplicationMasterService: Registering app attempt : appattempt_1399156864902_0003_000001
2014-05-03 23:17:19,391 INFO org.apache.hadoop.yarn.server.resourcemanager.rmapp.attempt.RMAppAttemptImpl: appattempt_1399156864902_0003_000001 State change from NEW to SUBMITTED
2014-05-03 23:17:19,391 INFO org.apache.hadoop.yarn.server.resourcemanager.scheduler.capacity.LeafQueue: Application application_1399156864902_0003 from user: ubuntu activated in queue: default
2014-05-03 23:17:19,391 INFO org.apache.hadoop.yarn.server.resourcemanager.scheduler.capacity.LeafQueue: Application added - appId: application_1399156864902_0003 user: org.apache.hadoop.yarn.server.resourcemanager.scheduler.capacity.LeafQueue$User@5ecdb1d0, leaf-queue: default #user-pending-applications: 0 #user-active-applications: 1 #queue-pending-applications: 0 #queue-active-applications: 1
2014-05-03 23:17:19,391 INFO org.apache.hadoop.yarn.server.resourcemanager.scheduler.capacity.ParentQueue: Application added - appId: application_1399156864902_0003 user: ubuntu leaf-queue of parent: root #applications: 1
2014-05-03 23:17:19,391 INFO org.apache.hadoop.yarn.server.resourcemanager.scheduler.capacity.CapacityScheduler: Application Submission: appattempt_1399156864902_0003_000001, user: ubuntu queue: default: capacity=1.0, absoluteCapacity=1.0, usedResources=<memory:0, vCores:0>usedCapacity=0.0, absoluteUsedCapacity=0.0, numApps=1, numContainers=0, currently active: 1
2014-05-03 23:17:19,391 INFO org.apache.hadoop.yarn.server.resourcemanager.rmapp.attempt.RMAppAttemptImpl: appattempt_1399156864902_0003_000001 State change from SUBMITTED to SCHEDULED
2014-05-03 23:17:19,391 INFO org.apache.hadoop.yarn.server.resourcemanager.rmapp.RMAppImpl: application_1399156864902_0003 State change from SUBMITTED to ACCEPTED
2014-05-03 23:17:19,606 INFO org.apache.hadoop.yarn.server.resourcemanager.rmcontainer.RMContainerImpl: container_1399156864902_0003_01_000001 Container Transitioned from NEW to ALLOCATED
2014-05-03 23:17:19,606 INFO org.apache.hadoop.yarn.server.resourcemanager.RMAuditLogger: USER=ubuntu	OPERATION=AM Allocated Container	TARGET=SchedulerApp	RESULT=SUCCESS	APPID=application_1399156864902_0003	CONTAINERID=container_1399156864902_0003_01_000001
2014-05-03 23:17:19,606 INFO org.apache.hadoop.yarn.server.resourcemanager.scheduler.common.fica.FiCaSchedulerNode: Assigned container container_1399156864902_0003_01_000001 of capacity <memory:2048, vCores:1> on host noded:50846, which currently has 1 containers, <memory:2048, vCores:1> used and <memory:6144, vCores:7> available
2014-05-03 23:17:19,606 INFO org.apache.hadoop.yarn.server.resourcemanager.scheduler.capacity.LeafQueue: assignedContainer application=application_1399156864902_0003 container=Container: [ContainerId: container_1399156864902_0003_01_000001, NodeId: noded:50846, NodeHttpAddress: noded:8042, Resource: <memory:2048, vCores:1>, Priority: 0, Token: Token { kind: ContainerToken, service: 10.0.0.244:50846 }, ] containerId=container_1399156864902_0003_01_000001 queue=default: capacity=1.0, absoluteCapacity=1.0, usedResources=<memory:0, vCores:0>usedCapacity=0.0, absoluteUsedCapacity=0.0, numApps=1, numContainers=0 usedCapacity=0.0 absoluteUsedCapacity=0.0 used=<memory:0, vCores:0> cluster=<memory:32768, vCores:32>
2014-05-03 23:17:19,606 INFO org.apache.hadoop.yarn.server.resourcemanager.scheduler.capacity.ParentQueue: Re-sorting assigned queue: root.default stats: default: capacity=1.0, absoluteCapacity=1.0, usedResources=<memory:2048, vCores:1>usedCapacity=0.0625, absoluteUsedCapacity=0.0625, numApps=1, numContainers=1
2014-05-03 23:17:19,607 INFO org.apache.hadoop.yarn.server.resourcemanager.rmcontainer.RMContainerImpl: container_1399156864902_0003_01_000001 Container Transitioned from ALLOCATED to ACQUIRED
2014-05-03 23:17:19,607 INFO org.apache.hadoop.yarn.server.resourcemanager.rmapp.attempt.RMAppAttemptImpl: Storing attempt: AppId: application_1399156864902_0003 AttemptId: appattempt_1399156864902_0003_000001 MasterContainer: Container: [ContainerId: container_1399156864902_0003_01_000001, NodeId: noded:50846, NodeHttpAddress: noded:8042, Resource: <memory:2048, vCores:1>, Priority: 0, Token: Token { kind: ContainerToken, service: 10.0.0.244:50846 }, ]
2014-05-03 23:17:19,607 INFO org.apache.hadoop.yarn.server.resourcemanager.rmapp.attempt.RMAppAttemptImpl: appattempt_1399156864902_0003_000001 State change from SCHEDULED to ALLOCATED_SAVING
2014-05-03 23:17:19,607 INFO org.apache.hadoop.yarn.server.resourcemanager.recovery.RMStateStore: Storing info for attempt: appattempt_1399156864902_0003_000001
2014-05-03 23:17:19,607 INFO org.apache.hadoop.yarn.server.resourcemanager.scheduler.capacity.ParentQueue: assignedContainer queue=root usedCapacity=0.0625 absoluteUsedCapacity=0.0625 used=<memory:2048, vCores:1> cluster=<memory:32768, vCores:32>
2014-05-03 23:17:19,608 INFO org.apache.hadoop.yarn.server.resourcemanager.rmapp.attempt.RMAppAttemptImpl: appattempt_1399156864902_0003_000001 State change from ALLOCATED_SAVING to ALLOCATED
2014-05-03 23:17:19,608 INFO org.apache.hadoop.yarn.server.resourcemanager.amlauncher.AMLauncher: Launching masterappattempt_1399156864902_0003_000001
2014-05-03 23:17:19,609 INFO org.apache.hadoop.yarn.server.resourcemanager.amlauncher.AMLauncher: Setting up container Container: [ContainerId: container_1399156864902_0003_01_000001, NodeId: noded:50846, NodeHttpAddress: noded:8042, Resource: <memory:2048, vCores:1>, Priority: 0, Token: Token { kind: ContainerToken, service: 10.0.0.244:50846 }, ] for AM appattempt_1399156864902_0003_000001
2014-05-03 23:17:19,609 INFO org.apache.hadoop.yarn.server.resourcemanager.amlauncher.AMLauncher: Command to launch container container_1399156864902_0003_01_000001 : $JAVA_HOME/bin/java -Dlog4j.configuration=container-log4j.properties -Dyarn.app.container.log.dir=<LOG_DIR> -Dyarn.app.container.log.filesize=0 -Dhadoop.root.logger=INFO,CLA  -Xmx1024m org.apache.hadoop.mapreduce.v2.app.MRAppMaster 1><LOG_DIR>/stdout 2><LOG_DIR>/stderr 
2014-05-03 23:17:19,621 INFO org.apache.hadoop.yarn.server.resourcemanager.amlauncher.AMLauncher: Done launching container Container: [ContainerId: container_1399156864902_0003_01_000001, NodeId: noded:50846, NodeHttpAddress: noded:8042, Resource: <memory:2048, vCores:1>, Priority: 0, Token: Token { kind: ContainerToken, service: 10.0.0.244:50846 }, ] for AM appattempt_1399156864902_0003_000001
2014-05-03 23:17:19,621 INFO org.apache.hadoop.yarn.server.resourcemanager.rmapp.attempt.RMAppAttemptImpl: appattempt_1399156864902_0003_000001 State change from ALLOCATED to LAUNCHED
2014-05-03 23:17:20,607 INFO org.apache.hadoop.yarn.server.resourcemanager.rmcontainer.RMContainerImpl: container_1399156864902_0003_01_000001 Container Transitioned from ACQUIRED to RUNNING
2014-05-03 23:17:24,704 INFO SecurityLogger.org.apache.hadoop.ipc.Server: Auth successful for appattempt_1399156864902_0003_000001 (auth:SIMPLE)
2014-05-03 23:17:25,322 INFO org.apache.hadoop.yarn.server.resourcemanager.ApplicationMasterService: AM registration appattempt_1399156864902_0003_000001
2014-05-03 23:17:25,323 INFO org.apache.hadoop.yarn.server.resourcemanager.RMAuditLogger: USER=ubuntu	IP=10.0.0.244	OPERATION=Register App Master	TARGET=ApplicationMasterService	RESULT=SUCCESS	APPID=application_1399156864902_0003	APPATTEMPTID=appattempt_1399156864902_0003_000001
2014-05-03 23:17:25,323 INFO org.apache.hadoop.yarn.server.resourcemanager.rmapp.attempt.RMAppAttemptImpl: appattempt_1399156864902_0003_000001 State change from LAUNCHED to RUNNING
2014-05-03 23:17:25,323 INFO org.apache.hadoop.yarn.server.resourcemanager.rmapp.RMAppImpl: application_1399156864902_0003 State change from ACCEPTED to RUNNING
2014-05-03 23:17:26,621 INFO org.apache.hadoop.yarn.server.resourcemanager.rmcontainer.RMContainerImpl: container_1399156864902_0003_01_000002 Container Transitioned from NEW to ALLOCATED
2014-05-03 23:17:26,622 INFO org.apache.hadoop.yarn.server.resourcemanager.RMAuditLogger: USER=ubuntu	OPERATION=AM Allocated Container	TARGET=SchedulerApp	RESULT=SUCCESS	APPID=application_1399156864902_0003	CONTAINERID=container_1399156864902_0003_01_000002
2014-05-03 23:17:26,622 INFO org.apache.hadoop.yarn.server.resourcemanager.scheduler.common.fica.FiCaSchedulerNode: Assigned container container_1399156864902_0003_01_000002 of capacity <memory:1024, vCores:1> on host noded:50846, which currently has 2 containers, <memory:3072, vCores:2> used and <memory:5120, vCores:6> available
2014-05-03 23:17:26,622 INFO org.apache.hadoop.yarn.server.resourcemanager.scheduler.capacity.LeafQueue: assignedContainer application=application_1399156864902_0003 container=Container: [ContainerId: container_1399156864902_0003_01_000002, NodeId: noded:50846, NodeHttpAddress: noded:8042, Resource: <memory:1024, vCores:1>, Priority: 20, Token: Token { kind: ContainerToken, service: 10.0.0.244:50846 }, ] containerId=container_1399156864902_0003_01_000002 queue=default: capacity=1.0, absoluteCapacity=1.0, usedResources=<memory:2048, vCores:1>usedCapacity=0.0625, absoluteUsedCapacity=0.0625, numApps=1, numContainers=1 usedCapacity=0.0625 absoluteUsedCapacity=0.0625 used=<memory:2048, vCores:1> cluster=<memory:32768, vCores:32>
2014-05-03 23:17:26,622 INFO org.apache.hadoop.yarn.server.resourcemanager.scheduler.capacity.ParentQueue: Re-sorting assigned queue: root.default stats: default: capacity=1.0, absoluteCapacity=1.0, usedResources=<memory:3072, vCores:2>usedCapacity=0.09375, absoluteUsedCapacity=0.09375, numApps=1, numContainers=2
2014-05-03 23:17:26,622 INFO org.apache.hadoop.yarn.server.resourcemanager.scheduler.capacity.ParentQueue: assignedContainer queue=root usedCapacity=0.09375 absoluteUsedCapacity=0.09375 used=<memory:3072, vCores:2> cluster=<memory:32768, vCores:32>
2014-05-03 23:17:26,622 INFO org.apache.hadoop.yarn.server.resourcemanager.rmcontainer.RMContainerImpl: container_1399156864902_0003_01_000003 Container Transitioned from NEW to ALLOCATED
2014-05-03 23:17:26,622 INFO org.apache.hadoop.yarn.server.resourcemanager.RMAuditLogger: USER=ubuntu	OPERATION=AM Allocated Container	TARGET=SchedulerApp	RESULT=SUCCESS	APPID=application_1399156864902_0003	CONTAINERID=container_1399156864902_0003_01_000003
2014-05-03 23:17:26,623 INFO org.apache.hadoop.yarn.server.resourcemanager.scheduler.common.fica.FiCaSchedulerNode: Assigned container container_1399156864902_0003_01_000003 of capacity <memory:1024, vCores:1> on host noded:50846, which currently has 3 containers, <memory:4096, vCores:3> used and <memory:4096, vCores:5> available
2014-05-03 23:17:26,623 INFO org.apache.hadoop.yarn.server.resourcemanager.scheduler.capacity.LeafQueue: assignedContainer application=application_1399156864902_0003 container=Container: [ContainerId: container_1399156864902_0003_01_000003, NodeId: noded:50846, NodeHttpAddress: noded:8042, Resource: <memory:1024, vCores:1>, Priority: 20, Token: Token { kind: ContainerToken, service: 10.0.0.244:50846 }, ] containerId=container_1399156864902_0003_01_000003 queue=default: capacity=1.0, absoluteCapacity=1.0, usedResources=<memory:3072, vCores:2>usedCapacity=0.09375, absoluteUsedCapacity=0.09375, numApps=1, numContainers=2 usedCapacity=0.09375 absoluteUsedCapacity=0.09375 used=<memory:3072, vCores:2> cluster=<memory:32768, vCores:32>
2014-05-03 23:17:26,623 INFO org.apache.hadoop.yarn.server.resourcemanager.scheduler.capacity.ParentQueue: Re-sorting assigned queue: root.default stats: default: capacity=1.0, absoluteCapacity=1.0, usedResources=<memory:4096, vCores:3>usedCapacity=0.125, absoluteUsedCapacity=0.125, numApps=1, numContainers=3
2014-05-03 23:17:26,623 INFO org.apache.hadoop.yarn.server.resourcemanager.scheduler.capacity.ParentQueue: assignedContainer queue=root usedCapacity=0.125 absoluteUsedCapacity=0.125 used=<memory:4096, vCores:3> cluster=<memory:32768, vCores:32>
2014-05-03 23:17:26,623 INFO org.apache.hadoop.yarn.server.resourcemanager.rmcontainer.RMContainerImpl: container_1399156864902_0003_01_000004 Container Transitioned from NEW to ALLOCATED
2014-05-03 23:17:26,623 INFO org.apache.hadoop.yarn.server.resourcemanager.RMAuditLogger: USER=ubuntu	OPERATION=AM Allocated Container	TARGET=SchedulerApp	RESULT=SUCCESS	APPID=application_1399156864902_0003	CONTAINERID=container_1399156864902_0003_01_000004
2014-05-03 23:17:26,623 INFO org.apache.hadoop.yarn.server.resourcemanager.scheduler.common.fica.FiCaSchedulerNode: Assigned container container_1399156864902_0003_01_000004 of capacity <memory:1024, vCores:1> on host noded:50846, which currently has 4 containers, <memory:5120, vCores:4> used and <memory:3072, vCores:4> available
2014-05-03 23:17:26,623 INFO org.apache.hadoop.yarn.server.resourcemanager.scheduler.capacity.LeafQueue: assignedContainer application=application_1399156864902_0003 container=Container: [ContainerId: container_1399156864902_0003_01_000004, NodeId: noded:50846, NodeHttpAddress: noded:8042, Resource: <memory:1024, vCores:1>, Priority: 20, Token: Token { kind: ContainerToken, service: 10.0.0.244:50846 }, ] containerId=container_1399156864902_0003_01_000004 queue=default: capacity=1.0, absoluteCapacity=1.0, usedResources=<memory:4096, vCores:3>usedCapacity=0.125, absoluteUsedCapacity=0.125, numApps=1, numContainers=3 usedCapacity=0.125 absoluteUsedCapacity=0.125 used=<memory:4096, vCores:3> cluster=<memory:32768, vCores:32>
2014-05-03 23:17:26,624 INFO org.apache.hadoop.yarn.server.resourcemanager.scheduler.capacity.ParentQueue: Re-sorting assigned queue: root.default stats: default: capacity=1.0, absoluteCapacity=1.0, usedResources=<memory:5120, vCores:4>usedCapacity=0.15625, absoluteUsedCapacity=0.15625, numApps=1, numContainers=4
2014-05-03 23:17:26,624 INFO org.apache.hadoop.yarn.server.resourcemanager.scheduler.capacity.ParentQueue: assignedContainer queue=root usedCapacity=0.15625 absoluteUsedCapacity=0.15625 used=<memory:5120, vCores:4> cluster=<memory:32768, vCores:32>
2014-05-03 23:17:26,624 INFO org.apache.hadoop.yarn.server.resourcemanager.rmcontainer.RMContainerImpl: container_1399156864902_0003_01_000005 Container Transitioned from NEW to ALLOCATED
2014-05-03 23:17:26,624 INFO org.apache.hadoop.yarn.server.resourcemanager.RMAuditLogger: USER=ubuntu	OPERATION=AM Allocated Container	TARGET=SchedulerApp	RESULT=SUCCESS	APPID=application_1399156864902_0003	CONTAINERID=container_1399156864902_0003_01_000005
2014-05-03 23:17:26,624 INFO org.apache.hadoop.yarn.server.resourcemanager.scheduler.common.fica.FiCaSchedulerNode: Assigned container container_1399156864902_0003_01_000005 of capacity <memory:1024, vCores:1> on host noded:50846, which currently has 5 containers, <memory:6144, vCores:5> used and <memory:2048, vCores:3> available
2014-05-03 23:17:26,624 INFO org.apache.hadoop.yarn.server.resourcemanager.scheduler.capacity.LeafQueue: assignedContainer application=application_1399156864902_0003 container=Container: [ContainerId: container_1399156864902_0003_01_000005, NodeId: noded:50846, NodeHttpAddress: noded:8042, Resource: <memory:1024, vCores:1>, Priority: 20, Token: Token { kind: ContainerToken, service: 10.0.0.244:50846 }, ] containerId=container_1399156864902_0003_01_000005 queue=default: capacity=1.0, absoluteCapacity=1.0, usedResources=<memory:5120, vCores:4>usedCapacity=0.15625, absoluteUsedCapacity=0.15625, numApps=1, numContainers=4 usedCapacity=0.15625 absoluteUsedCapacity=0.15625 used=<memory:5120, vCores:4> cluster=<memory:32768, vCores:32>
2014-05-03 23:17:26,624 INFO org.apache.hadoop.yarn.server.resourcemanager.scheduler.capacity.ParentQueue: Re-sorting assigned queue: root.default stats: default: capacity=1.0, absoluteCapacity=1.0, usedResources=<memory:6144, vCores:5>usedCapacity=0.1875, absoluteUsedCapacity=0.1875, numApps=1, numContainers=5
2014-05-03 23:17:26,625 INFO org.apache.hadoop.yarn.server.resourcemanager.scheduler.capacity.ParentQueue: assignedContainer queue=root usedCapacity=0.1875 absoluteUsedCapacity=0.1875 used=<memory:6144, vCores:5> cluster=<memory:32768, vCores:32>
2014-05-03 23:17:27,386 INFO org.apache.hadoop.yarn.server.resourcemanager.rmcontainer.RMContainerImpl: container_1399156864902_0003_01_000002 Container Transitioned from ALLOCATED to ACQUIRED
2014-05-03 23:17:27,387 INFO org.apache.hadoop.yarn.server.resourcemanager.rmcontainer.RMContainerImpl: container_1399156864902_0003_01_000003 Container Transitioned from ALLOCATED to ACQUIRED
2014-05-03 23:17:27,390 INFO org.apache.hadoop.yarn.server.resourcemanager.rmcontainer.RMContainerImpl: container_1399156864902_0003_01_000004 Container Transitioned from ALLOCATED to ACQUIRED
2014-05-03 23:17:27,390 INFO org.apache.hadoop.yarn.server.resourcemanager.rmcontainer.RMContainerImpl: container_1399156864902_0003_01_000005 Container Transitioned from ALLOCATED to ACQUIRED
2014-05-03 23:17:27,628 INFO org.apache.hadoop.yarn.server.resourcemanager.rmcontainer.RMContainerImpl: container_1399156864902_0003_01_000002 Container Transitioned from ACQUIRED to RUNNING
2014-05-03 23:17:27,629 INFO org.apache.hadoop.yarn.server.resourcemanager.rmcontainer.RMContainerImpl: container_1399156864902_0003_01_000003 Container Transitioned from ACQUIRED to RUNNING
2014-05-03 23:17:27,629 INFO org.apache.hadoop.yarn.server.resourcemanager.rmcontainer.RMContainerImpl: container_1399156864902_0003_01_000004 Container Transitioned from ACQUIRED to RUNNING
2014-05-03 23:17:27,629 INFO org.apache.hadoop.yarn.server.resourcemanager.rmcontainer.RMContainerImpl: container_1399156864902_0003_01_000005 Container Transitioned from ACQUIRED to RUNNING
2014-05-03 23:17:28,419 INFO org.apache.hadoop.yarn.server.resourcemanager.scheduler.AppSchedulingInfo: checking for deactivate... 
2014-05-03 23:18:00,453 INFO org.apache.hadoop.yarn.server.resourcemanager.rmcontainer.RMContainerImpl: container_1399156864902_0003_01_000003 Container Transitioned from RUNNING to COMPLETED
2014-05-03 23:18:00,453 INFO org.apache.hadoop.yarn.server.resourcemanager.scheduler.common.fica.FiCaSchedulerApp: Completed container: container_1399156864902_0003_01_000003 in state: COMPLETED event:FINISHED
2014-05-03 23:18:00,453 INFO org.apache.hadoop.yarn.server.resourcemanager.RMAuditLogger: USER=ubuntu	OPERATION=AM Released Container	TARGET=SchedulerApp	RESULT=SUCCESS	APPID=application_1399156864902_0003	CONTAINERID=container_1399156864902_0003_01_000003
2014-05-03 23:18:00,453 INFO org.apache.hadoop.yarn.server.resourcemanager.scheduler.common.fica.FiCaSchedulerNode: Released container container_1399156864902_0003_01_000003 of capacity <memory:1024, vCores:1> on host noded:50846, which currently has 4 containers, <memory:5120, vCores:4> used and <memory:3072, vCores:4> available, release resources=true
2014-05-03 23:18:00,453 INFO org.apache.hadoop.yarn.server.resourcemanager.scheduler.capacity.LeafQueue: default used=<memory:5120, vCores:4> numContainers=4 user=ubuntu user-resources=<memory:5120, vCores:4>
2014-05-03 23:18:00,454 INFO org.apache.hadoop.yarn.server.resourcemanager.scheduler.capacity.LeafQueue: completedContainer container=Container: [ContainerId: container_1399156864902_0003_01_000003, NodeId: noded:50846, NodeHttpAddress: noded:8042, Resource: <memory:1024, vCores:1>, Priority: 20, Token: Token { kind: ContainerToken, service: 10.0.0.244:50846 }, ] resource=<memory:1024, vCores:1> queue=default: capacity=1.0, absoluteCapacity=1.0, usedResources=<memory:5120, vCores:4>usedCapacity=0.15625, absoluteUsedCapacity=0.15625, numApps=1, numContainers=4 usedCapacity=0.15625 absoluteUsedCapacity=0.15625 used=<memory:5120, vCores:4> cluster=<memory:32768, vCores:32>
2014-05-03 23:18:00,454 INFO org.apache.hadoop.yarn.server.resourcemanager.scheduler.capacity.ParentQueue: completedContainer queue=root usedCapacity=0.15625 absoluteUsedCapacity=0.15625 used=<memory:5120, vCores:4> cluster=<memory:32768, vCores:32>
2014-05-03 23:18:00,454 INFO org.apache.hadoop.yarn.server.resourcemanager.scheduler.capacity.ParentQueue: Re-sorting completed queue: root.default stats: default: capacity=1.0, absoluteCapacity=1.0, usedResources=<memory:5120, vCores:4>usedCapacity=0.15625, absoluteUsedCapacity=0.15625, numApps=1, numContainers=4
2014-05-03 23:18:00,454 INFO org.apache.hadoop.yarn.server.resourcemanager.scheduler.capacity.CapacityScheduler: Application appattempt_1399156864902_0003_000001 released container container_1399156864902_0003_01_000003 on node: host: noded:50846 #containers=4 available=3072 used=5120 with event: FINISHED
2014-05-03 23:18:01,147 INFO org.apache.hadoop.yarn.server.resourcemanager.rmcontainer.RMContainerImpl: container_1399156864902_0003_01_000004 Container Transitioned from RUNNING to COMPLETED
2014-05-03 23:18:01,147 INFO org.apache.hadoop.yarn.server.resourcemanager.scheduler.common.fica.FiCaSchedulerApp: Completed container: container_1399156864902_0003_01_000004 in state: COMPLETED event:FINISHED
2014-05-03 23:18:01,148 INFO org.apache.hadoop.yarn.server.resourcemanager.RMAuditLogger: USER=ubuntu	OPERATION=AM Released Container	TARGET=SchedulerApp	RESULT=SUCCESS	APPID=application_1399156864902_0003	CONTAINERID=container_1399156864902_0003_01_000004
2014-05-03 23:18:01,148 INFO org.apache.hadoop.yarn.server.resourcemanager.scheduler.common.fica.FiCaSchedulerNode: Released container container_1399156864902_0003_01_000004 of capacity <memory:1024, vCores:1> on host noded:50846, which currently has 3 containers, <memory:4096, vCores:3> used and <memory:4096, vCores:5> available, release resources=true
2014-05-03 23:18:01,148 INFO org.apache.hadoop.yarn.server.resourcemanager.scheduler.capacity.LeafQueue: default used=<memory:4096, vCores:3> numContainers=3 user=ubuntu user-resources=<memory:4096, vCores:3>
2014-05-03 23:18:01,148 INFO org.apache.hadoop.yarn.server.resourcemanager.scheduler.capacity.LeafQueue: completedContainer container=Container: [ContainerId: container_1399156864902_0003_01_000004, NodeId: noded:50846, NodeHttpAddress: noded:8042, Resource: <memory:1024, vCores:1>, Priority: 20, Token: Token { kind: ContainerToken, service: 10.0.0.244:50846 }, ] resource=<memory:1024, vCores:1> queue=default: capacity=1.0, absoluteCapacity=1.0, usedResources=<memory:4096, vCores:3>usedCapacity=0.125, absoluteUsedCapacity=0.125, numApps=1, numContainers=3 usedCapacity=0.125 absoluteUsedCapacity=0.125 used=<memory:4096, vCores:3> cluster=<memory:32768, vCores:32>
2014-05-03 23:18:01,148 INFO org.apache.hadoop.yarn.server.resourcemanager.scheduler.capacity.ParentQueue: completedContainer queue=root usedCapacity=0.125 absoluteUsedCapacity=0.125 used=<memory:4096, vCores:3> cluster=<memory:32768, vCores:32>
2014-05-03 23:18:01,148 INFO org.apache.hadoop.yarn.server.resourcemanager.scheduler.capacity.ParentQueue: Re-sorting completed queue: root.default stats: default: capacity=1.0, absoluteCapacity=1.0, usedResources=<memory:4096, vCores:3>usedCapacity=0.125, absoluteUsedCapacity=0.125, numApps=1, numContainers=3
2014-05-03 23:18:01,148 INFO org.apache.hadoop.yarn.server.resourcemanager.scheduler.capacity.CapacityScheduler: Application appattempt_1399156864902_0003_000001 released container container_1399156864902_0003_01_000004 on node: host: noded:50846 #containers=3 available=4096 used=4096 with event: FINISHED
2014-05-03 23:18:01,148 INFO org.apache.hadoop.yarn.server.resourcemanager.rmcontainer.RMContainerImpl: container_1399156864902_0003_01_000006 Container Transitioned from NEW to ALLOCATED
2014-05-03 23:18:01,149 INFO org.apache.hadoop.yarn.server.resourcemanager.RMAuditLogger: USER=ubuntu	OPERATION=AM Allocated Container	TARGET=SchedulerApp	RESULT=SUCCESS	APPID=application_1399156864902_0003	CONTAINERID=container_1399156864902_0003_01_000006
2014-05-03 23:18:01,149 INFO org.apache.hadoop.yarn.server.resourcemanager.scheduler.common.fica.FiCaSchedulerNode: Assigned container container_1399156864902_0003_01_000006 of capacity <memory:1024, vCores:1> on host noded:50846, which currently has 4 containers, <memory:5120, vCores:4> used and <memory:3072, vCores:4> available
2014-05-03 23:18:01,149 INFO org.apache.hadoop.yarn.server.resourcemanager.scheduler.capacity.LeafQueue: assignedContainer application=application_1399156864902_0003 container=Container: [ContainerId: container_1399156864902_0003_01_000006, NodeId: noded:50846, NodeHttpAddress: noded:8042, Resource: <memory:1024, vCores:1>, Priority: 10, Token: Token { kind: ContainerToken, service: 10.0.0.244:50846 }, ] containerId=container_1399156864902_0003_01_000006 queue=default: capacity=1.0, absoluteCapacity=1.0, usedResources=<memory:4096, vCores:3>usedCapacity=0.125, absoluteUsedCapacity=0.125, numApps=1, numContainers=3 usedCapacity=0.125 absoluteUsedCapacity=0.125 used=<memory:4096, vCores:3> cluster=<memory:32768, vCores:32>
2014-05-03 23:18:01,149 INFO org.apache.hadoop.yarn.server.resourcemanager.scheduler.capacity.ParentQueue: Re-sorting assigned queue: root.default stats: default: capacity=1.0, absoluteCapacity=1.0, usedResources=<memory:5120, vCores:4>usedCapacity=0.15625, absoluteUsedCapacity=0.15625, numApps=1, numContainers=4
2014-05-03 23:18:01,149 INFO org.apache.hadoop.yarn.server.resourcemanager.scheduler.capacity.ParentQueue: assignedContainer queue=root usedCapacity=0.15625 absoluteUsedCapacity=0.15625 used=<memory:5120, vCores:4> cluster=<memory:32768, vCores:32>
2014-05-03 23:18:01,332 INFO org.apache.hadoop.yarn.server.resourcemanager.rmcontainer.RMContainerImpl: container_1399156864902_0003_01_000002 Container Transitioned from RUNNING to COMPLETED
2014-05-03 23:18:01,332 INFO org.apache.hadoop.yarn.server.resourcemanager.scheduler.common.fica.FiCaSchedulerApp: Completed container: container_1399156864902_0003_01_000002 in state: COMPLETED event:FINISHED
2014-05-03 23:18:01,332 INFO org.apache.hadoop.yarn.server.resourcemanager.RMAuditLogger: USER=ubuntu	OPERATION=AM Released Container	TARGET=SchedulerApp	RESULT=SUCCESS	APPID=application_1399156864902_0003	CONTAINERID=container_1399156864902_0003_01_000002
2014-05-03 23:18:01,332 INFO org.apache.hadoop.yarn.server.resourcemanager.scheduler.common.fica.FiCaSchedulerNode: Released container container_1399156864902_0003_01_000002 of capacity <memory:1024, vCores:1> on host noded:50846, which currently has 3 containers, <memory:4096, vCores:3> used and <memory:4096, vCores:5> available, release resources=true
2014-05-03 23:18:01,332 INFO org.apache.hadoop.yarn.server.resourcemanager.scheduler.capacity.LeafQueue: default used=<memory:4096, vCores:3> numContainers=3 user=ubuntu user-resources=<memory:4096, vCores:3>
2014-05-03 23:18:01,332 INFO org.apache.hadoop.yarn.server.resourcemanager.scheduler.capacity.LeafQueue: completedContainer container=Container: [ContainerId: container_1399156864902_0003_01_000002, NodeId: noded:50846, NodeHttpAddress: noded:8042, Resource: <memory:1024, vCores:1>, Priority: 20, Token: Token { kind: ContainerToken, service: 10.0.0.244:50846 }, ] resource=<memory:1024, vCores:1> queue=default: capacity=1.0, absoluteCapacity=1.0, usedResources=<memory:4096, vCores:3>usedCapacity=0.125, absoluteUsedCapacity=0.125, numApps=1, numContainers=3 usedCapacity=0.125 absoluteUsedCapacity=0.125 used=<memory:4096, vCores:3> cluster=<memory:32768, vCores:32>
2014-05-03 23:18:01,332 INFO org.apache.hadoop.yarn.server.resourcemanager.scheduler.capacity.ParentQueue: completedContainer queue=root usedCapacity=0.125 absoluteUsedCapacity=0.125 used=<memory:4096, vCores:3> cluster=<memory:32768, vCores:32>
2014-05-03 23:18:01,332 INFO org.apache.hadoop.yarn.server.resourcemanager.scheduler.capacity.ParentQueue: Re-sorting completed queue: root.default stats: default: capacity=1.0, absoluteCapacity=1.0, usedResources=<memory:4096, vCores:3>usedCapacity=0.125, absoluteUsedCapacity=0.125, numApps=1, numContainers=3
2014-05-03 23:18:01,333 INFO org.apache.hadoop.yarn.server.resourcemanager.scheduler.capacity.CapacityScheduler: Application appattempt_1399156864902_0003_000001 released container container_1399156864902_0003_01_000002 on node: host: noded:50846 #containers=3 available=4096 used=4096 with event: FINISHED
2014-05-03 23:18:01,333 INFO org.apache.hadoop.yarn.server.resourcemanager.rmcontainer.RMContainerImpl: container_1399156864902_0003_01_000007 Container Transitioned from NEW to ALLOCATED
2014-05-03 23:18:01,333 INFO org.apache.hadoop.yarn.server.resourcemanager.RMAuditLogger: USER=ubuntu	OPERATION=AM Allocated Container	TARGET=SchedulerApp	RESULT=SUCCESS	APPID=application_1399156864902_0003	CONTAINERID=container_1399156864902_0003_01_000007
2014-05-03 23:18:01,333 INFO org.apache.hadoop.yarn.server.resourcemanager.scheduler.common.fica.FiCaSchedulerNode: Assigned container container_1399156864902_0003_01_000007 of capacity <memory:1024, vCores:1> on host noded:50846, which currently has 4 containers, <memory:5120, vCores:4> used and <memory:3072, vCores:4> available
2014-05-03 23:18:01,333 INFO org.apache.hadoop.yarn.server.resourcemanager.scheduler.capacity.LeafQueue: assignedContainer application=application_1399156864902_0003 container=Container: [ContainerId: container_1399156864902_0003_01_000007, NodeId: noded:50846, NodeHttpAddress: noded:8042, Resource: <memory:1024, vCores:1>, Priority: 10, Token: Token { kind: ContainerToken, service: 10.0.0.244:50846 }, ] containerId=container_1399156864902_0003_01_000007 queue=default: capacity=1.0, absoluteCapacity=1.0, usedResources=<memory:4096, vCores:3>usedCapacity=0.125, absoluteUsedCapacity=0.125, numApps=1, numContainers=3 usedCapacity=0.125 absoluteUsedCapacity=0.125 used=<memory:4096, vCores:3> cluster=<memory:32768, vCores:32>
2014-05-03 23:18:01,333 INFO org.apache.hadoop.yarn.server.resourcemanager.scheduler.capacity.ParentQueue: Re-sorting assigned queue: root.default stats: default: capacity=1.0, absoluteCapacity=1.0, usedResources=<memory:5120, vCores:4>usedCapacity=0.15625, absoluteUsedCapacity=0.15625, numApps=1, numContainers=4
2014-05-03 23:18:01,333 INFO org.apache.hadoop.yarn.server.resourcemanager.scheduler.capacity.ParentQueue: assignedContainer queue=root usedCapacity=0.15625 absoluteUsedCapacity=0.15625 used=<memory:5120, vCores:4> cluster=<memory:32768, vCores:32>
2014-05-03 23:18:01,378 INFO org.apache.hadoop.yarn.server.resourcemanager.rmcontainer.RMContainerImpl: container_1399156864902_0003_01_000008 Container Transitioned from NEW to ALLOCATED
2014-05-03 23:18:01,378 INFO org.apache.hadoop.yarn.server.resourcemanager.RMAuditLogger: USER=ubuntu	OPERATION=AM Allocated Container	TARGET=SchedulerApp	RESULT=SUCCESS	APPID=application_1399156864902_0003	CONTAINERID=container_1399156864902_0003_01_000008
2014-05-03 23:18:01,378 INFO org.apache.hadoop.yarn.server.resourcemanager.scheduler.common.fica.FiCaSchedulerNode: Assigned container container_1399156864902_0003_01_000008 of capacity <memory:1024, vCores:1> on host nodec:54860, which currently has 1 containers, <memory:1024, vCores:1> used and <memory:7168, vCores:7> available
2014-05-03 23:18:01,378 INFO org.apache.hadoop.yarn.server.resourcemanager.scheduler.capacity.LeafQueue: assignedContainer application=application_1399156864902_0003 container=Container: [ContainerId: container_1399156864902_0003_01_000008, NodeId: nodec:54860, NodeHttpAddress: nodec:8042, Resource: <memory:1024, vCores:1>, Priority: 10, Token: Token { kind: ContainerToken, service: 10.0.0.245:54860 }, ] containerId=container_1399156864902_0003_01_000008 queue=default: capacity=1.0, absoluteCapacity=1.0, usedResources=<memory:5120, vCores:4>usedCapacity=0.15625, absoluteUsedCapacity=0.15625, numApps=1, numContainers=4 usedCapacity=0.15625 absoluteUsedCapacity=0.15625 used=<memory:5120, vCores:4> cluster=<memory:32768, vCores:32>
2014-05-03 23:18:01,378 INFO org.apache.hadoop.yarn.server.resourcemanager.scheduler.capacity.ParentQueue: Re-sorting assigned queue: root.default stats: default: capacity=1.0, absoluteCapacity=1.0, usedResources=<memory:6144, vCores:5>usedCapacity=0.1875, absoluteUsedCapacity=0.1875, numApps=1, numContainers=5
2014-05-03 23:18:01,378 INFO org.apache.hadoop.yarn.server.resourcemanager.scheduler.capacity.ParentQueue: assignedContainer queue=root usedCapacity=0.1875 absoluteUsedCapacity=0.1875 used=<memory:6144, vCores:5> cluster=<memory:32768, vCores:32>
2014-05-03 23:18:01,379 INFO org.apache.hadoop.yarn.server.resourcemanager.rmcontainer.RMContainerImpl: container_1399156864902_0003_01_000009 Container Transitioned from NEW to ALLOCATED
2014-05-03 23:18:01,379 INFO org.apache.hadoop.yarn.server.resourcemanager.RMAuditLogger: USER=ubuntu	OPERATION=AM Allocated Container	TARGET=SchedulerApp	RESULT=SUCCESS	APPID=application_1399156864902_0003	CONTAINERID=container_1399156864902_0003_01_000009
2014-05-03 23:18:01,379 INFO org.apache.hadoop.yarn.server.resourcemanager.scheduler.common.fica.FiCaSchedulerNode: Assigned container container_1399156864902_0003_01_000009 of capacity <memory:1024, vCores:1> on host nodea:56325, which currently has 1 containers, <memory:1024, vCores:1> used and <memory:7168, vCores:7> available
2014-05-03 23:18:01,379 INFO org.apache.hadoop.yarn.server.resourcemanager.scheduler.capacity.LeafQueue: assignedContainer application=application_1399156864902_0003 container=Container: [ContainerId: container_1399156864902_0003_01_000009, NodeId: nodea:56325, NodeHttpAddress: nodea:8042, Resource: <memory:1024, vCores:1>, Priority: 10, Token: Token { kind: ContainerToken, service: 10.0.0.182:56325 }, ] containerId=container_1399156864902_0003_01_000009 queue=default: capacity=1.0, absoluteCapacity=1.0, usedResources=<memory:6144, vCores:5>usedCapacity=0.1875, absoluteUsedCapacity=0.1875, numApps=1, numContainers=5 usedCapacity=0.1875 absoluteUsedCapacity=0.1875 used=<memory:6144, vCores:5> cluster=<memory:32768, vCores:32>
2014-05-03 23:18:01,379 INFO org.apache.hadoop.yarn.server.resourcemanager.scheduler.capacity.ParentQueue: Re-sorting assigned queue: root.default stats: default: capacity=1.0, absoluteCapacity=1.0, usedResources=<memory:7168, vCores:6>usedCapacity=0.21875, absoluteUsedCapacity=0.21875, numApps=1, numContainers=6
2014-05-03 23:18:01,379 INFO org.apache.hadoop.yarn.server.resourcemanager.scheduler.capacity.ParentQueue: assignedContainer queue=root usedCapacity=0.21875 absoluteUsedCapacity=0.21875 used=<memory:7168, vCores:6> cluster=<memory:32768, vCores:32>
2014-05-03 23:18:01,379 INFO org.apache.hadoop.yarn.server.resourcemanager.rmcontainer.RMContainerImpl: container_1399156864902_0003_01_000010 Container Transitioned from NEW to ALLOCATED
2014-05-03 23:18:01,380 INFO org.apache.hadoop.yarn.server.resourcemanager.RMAuditLogger: USER=ubuntu	OPERATION=AM Allocated Container	TARGET=SchedulerApp	RESULT=SUCCESS	APPID=application_1399156864902_0003	CONTAINERID=container_1399156864902_0003_01_000010
2014-05-03 23:18:01,380 INFO org.apache.hadoop.yarn.server.resourcemanager.scheduler.common.fica.FiCaSchedulerNode: Assigned container container_1399156864902_0003_01_000010 of capacity <memory:1024, vCores:1> on host nodeb:55487, which currently has 1 containers, <memory:1024, vCores:1> used and <memory:7168, vCores:7> available
2014-05-03 23:18:01,380 INFO org.apache.hadoop.yarn.server.resourcemanager.scheduler.capacity.LeafQueue: assignedContainer application=application_1399156864902_0003 container=Container: [ContainerId: container_1399156864902_0003_01_000010, NodeId: nodeb:55487, NodeHttpAddress: nodeb:8042, Resource: <memory:1024, vCores:1>, Priority: 10, Token: Token { kind: ContainerToken, service: 10.0.0.243:55487 }, ] containerId=container_1399156864902_0003_01_000010 queue=default: capacity=1.0, absoluteCapacity=1.0, usedResources=<memory:7168, vCores:6>usedCapacity=0.21875, absoluteUsedCapacity=0.21875, numApps=1, numContainers=6 usedCapacity=0.21875 absoluteUsedCapacity=0.21875 used=<memory:7168, vCores:6> cluster=<memory:32768, vCores:32>
2014-05-03 23:18:01,380 INFO org.apache.hadoop.yarn.server.resourcemanager.scheduler.capacity.ParentQueue: Re-sorting assigned queue: root.default stats: default: capacity=1.0, absoluteCapacity=1.0, usedResources=<memory:8192, vCores:7>usedCapacity=0.25, absoluteUsedCapacity=0.25, numApps=1, numContainers=7
2014-05-03 23:18:01,380 INFO org.apache.hadoop.yarn.server.resourcemanager.scheduler.capacity.ParentQueue: assignedContainer queue=root usedCapacity=0.25 absoluteUsedCapacity=0.25 used=<memory:8192, vCores:7> cluster=<memory:32768, vCores:32>
2014-05-03 23:18:01,773 INFO org.apache.hadoop.yarn.server.resourcemanager.rmcontainer.RMContainerImpl: container_1399156864902_0003_01_000006 Container Transitioned from ALLOCATED to ACQUIRED
2014-05-03 23:18:01,774 INFO org.apache.hadoop.yarn.server.resourcemanager.rmcontainer.RMContainerImpl: container_1399156864902_0003_01_000007 Container Transitioned from ALLOCATED to ACQUIRED
2014-05-03 23:18:01,774 INFO org.apache.hadoop.yarn.server.resourcemanager.rmcontainer.RMContainerImpl: container_1399156864902_0003_01_000008 Container Transitioned from ALLOCATED to ACQUIRED
2014-05-03 23:18:01,774 INFO org.apache.hadoop.yarn.server.resourcemanager.rmcontainer.RMContainerImpl: container_1399156864902_0003_01_000009 Container Transitioned from ALLOCATED to ACQUIRED
2014-05-03 23:18:01,774 INFO org.apache.hadoop.yarn.server.resourcemanager.rmcontainer.RMContainerImpl: container_1399156864902_0003_01_000010 Container Transitioned from ALLOCATED to ACQUIRED
2014-05-03 23:18:02,337 INFO org.apache.hadoop.yarn.server.resourcemanager.rmcontainer.RMContainerImpl: container_1399156864902_0003_01_000006 Container Transitioned from ACQUIRED to RUNNING
2014-05-03 23:18:02,338 INFO org.apache.hadoop.yarn.server.resourcemanager.rmcontainer.RMContainerImpl: container_1399156864902_0003_01_000007 Container Transitioned from ACQUIRED to RUNNING
2014-05-03 23:18:02,338 INFO org.apache.hadoop.yarn.server.resourcemanager.rmcontainer.RMContainerImpl: container_1399156864902_0003_01_000005 Container Transitioned from RUNNING to COMPLETED
2014-05-03 23:18:02,338 INFO org.apache.hadoop.yarn.server.resourcemanager.scheduler.common.fica.FiCaSchedulerApp: Completed container: container_1399156864902_0003_01_000005 in state: COMPLETED event:FINISHED
2014-05-03 23:18:02,338 INFO org.apache.hadoop.yarn.server.resourcemanager.RMAuditLogger: USER=ubuntu	OPERATION=AM Released Container	TARGET=SchedulerApp	RESULT=SUCCESS	APPID=application_1399156864902_0003	CONTAINERID=container_1399156864902_0003_01_000005
2014-05-03 23:18:02,338 INFO org.apache.hadoop.yarn.server.resourcemanager.scheduler.common.fica.FiCaSchedulerNode: Released container container_1399156864902_0003_01_000005 of capacity <memory:1024, vCores:1> on host noded:50846, which currently has 3 containers, <memory:4096, vCores:3> used and <memory:4096, vCores:5> available, release resources=true
2014-05-03 23:18:02,338 INFO org.apache.hadoop.yarn.server.resourcemanager.scheduler.capacity.LeafQueue: default used=<memory:7168, vCores:6> numContainers=6 user=ubuntu user-resources=<memory:7168, vCores:6>
2014-05-03 23:18:02,338 INFO org.apache.hadoop.yarn.server.resourcemanager.scheduler.capacity.LeafQueue: completedContainer container=Container: [ContainerId: container_1399156864902_0003_01_000005, NodeId: noded:50846, NodeHttpAddress: noded:8042, Resource: <memory:1024, vCores:1>, Priority: 20, Token: Token { kind: ContainerToken, service: 10.0.0.244:50846 }, ] resource=<memory:1024, vCores:1> queue=default: capacity=1.0, absoluteCapacity=1.0, usedResources=<memory:7168, vCores:6>usedCapacity=0.21875, absoluteUsedCapacity=0.21875, numApps=1, numContainers=6 usedCapacity=0.21875 absoluteUsedCapacity=0.21875 used=<memory:7168, vCores:6> cluster=<memory:32768, vCores:32>
2014-05-03 23:18:02,338 INFO org.apache.hadoop.yarn.server.resourcemanager.scheduler.capacity.ParentQueue: completedContainer queue=root usedCapacity=0.21875 absoluteUsedCapacity=0.21875 used=<memory:7168, vCores:6> cluster=<memory:32768, vCores:32>
2014-05-03 23:18:02,339 INFO org.apache.hadoop.yarn.server.resourcemanager.scheduler.capacity.ParentQueue: Re-sorting completed queue: root.default stats: default: capacity=1.0, absoluteCapacity=1.0, usedResources=<memory:7168, vCores:6>usedCapacity=0.21875, absoluteUsedCapacity=0.21875, numApps=1, numContainers=6
2014-05-03 23:18:02,339 INFO org.apache.hadoop.yarn.server.resourcemanager.scheduler.capacity.CapacityScheduler: Application appattempt_1399156864902_0003_000001 released container container_1399156864902_0003_01_000005 on node: host: noded:50846 #containers=3 available=4096 used=4096 with event: FINISHED
2014-05-03 23:18:02,339 INFO org.apache.hadoop.yarn.server.resourcemanager.rmcontainer.RMContainerImpl: container_1399156864902_0003_01_000011 Container Transitioned from NEW to ALLOCATED
2014-05-03 23:18:02,339 INFO org.apache.hadoop.yarn.server.resourcemanager.RMAuditLogger: USER=ubuntu	OPERATION=AM Allocated Container	TARGET=SchedulerApp	RESULT=SUCCESS	APPID=application_1399156864902_0003	CONTAINERID=container_1399156864902_0003_01_000011
2014-05-03 23:18:02,339 INFO org.apache.hadoop.yarn.server.resourcemanager.scheduler.common.fica.FiCaSchedulerNode: Assigned container container_1399156864902_0003_01_000011 of capacity <memory:1024, vCores:1> on host noded:50846, which currently has 4 containers, <memory:5120, vCores:4> used and <memory:3072, vCores:4> available
2014-05-03 23:18:02,340 INFO org.apache.hadoop.yarn.server.resourcemanager.scheduler.capacity.LeafQueue: assignedContainer application=application_1399156864902_0003 container=Container: [ContainerId: container_1399156864902_0003_01_000011, NodeId: noded:50846, NodeHttpAddress: noded:8042, Resource: <memory:1024, vCores:1>, Priority: 10, Token: Token { kind: ContainerToken, service: 10.0.0.244:50846 }, ] containerId=container_1399156864902_0003_01_000011 queue=default: capacity=1.0, absoluteCapacity=1.0, usedResources=<memory:7168, vCores:6>usedCapacity=0.21875, absoluteUsedCapacity=0.21875, numApps=1, numContainers=6 usedCapacity=0.21875 absoluteUsedCapacity=0.21875 used=<memory:7168, vCores:6> cluster=<memory:32768, vCores:32>
2014-05-03 23:18:02,340 INFO org.apache.hadoop.yarn.server.resourcemanager.scheduler.capacity.ParentQueue: Re-sorting assigned queue: root.default stats: default: capacity=1.0, absoluteCapacity=1.0, usedResources=<memory:8192, vCores:7>usedCapacity=0.25, absoluteUsedCapacity=0.25, numApps=1, numContainers=7
2014-05-03 23:18:02,340 INFO org.apache.hadoop.yarn.server.resourcemanager.scheduler.capacity.ParentQueue: assignedContainer queue=root usedCapacity=0.25 absoluteUsedCapacity=0.25 used=<memory:8192, vCores:7> cluster=<memory:32768, vCores:32>
2014-05-03 23:18:02,380 INFO org.apache.hadoop.yarn.server.resourcemanager.rmcontainer.RMContainerImpl: container_1399156864902_0003_01_000009 Container Transitioned from ACQUIRED to RUNNING
2014-05-03 23:18:02,380 INFO org.apache.hadoop.yarn.server.resourcemanager.rmcontainer.RMContainerImpl: container_1399156864902_0003_01_000012 Container Transitioned from NEW to ALLOCATED
2014-05-03 23:18:02,380 INFO org.apache.hadoop.yarn.server.resourcemanager.RMAuditLogger: USER=ubuntu	OPERATION=AM Allocated Container	TARGET=SchedulerApp	RESULT=SUCCESS	APPID=application_1399156864902_0003	CONTAINERID=container_1399156864902_0003_01_000012
2014-05-03 23:18:02,381 INFO org.apache.hadoop.yarn.server.resourcemanager.scheduler.common.fica.FiCaSchedulerNode: Assigned container container_1399156864902_0003_01_000012 of capacity <memory:1024, vCores:1> on host nodea:56325, which currently has 2 containers, <memory:2048, vCores:2> used and <memory:6144, vCores:6> available
2014-05-03 23:18:02,381 INFO org.apache.hadoop.yarn.server.resourcemanager.scheduler.capacity.LeafQueue: assignedContainer application=application_1399156864902_0003 container=Container: [ContainerId: container_1399156864902_0003_01_000012, NodeId: nodea:56325, NodeHttpAddress: nodea:8042, Resource: <memory:1024, vCores:1>, Priority: 10, Token: Token { kind: ContainerToken, service: 10.0.0.182:56325 }, ] containerId=container_1399156864902_0003_01_000012 queue=default: capacity=1.0, absoluteCapacity=1.0, usedResources=<memory:8192, vCores:7>usedCapacity=0.25, absoluteUsedCapacity=0.25, numApps=1, numContainers=7 usedCapacity=0.25 absoluteUsedCapacity=0.25 used=<memory:8192, vCores:7> cluster=<memory:32768, vCores:32>
2014-05-03 23:18:02,381 INFO org.apache.hadoop.yarn.server.resourcemanager.scheduler.capacity.ParentQueue: Re-sorting assigned queue: root.default stats: default: capacity=1.0, absoluteCapacity=1.0, usedResources=<memory:9216, vCores:8>usedCapacity=0.28125, absoluteUsedCapacity=0.28125, numApps=1, numContainers=8
2014-05-03 23:18:02,381 INFO org.apache.hadoop.yarn.server.resourcemanager.scheduler.capacity.ParentQueue: assignedContainer queue=root usedCapacity=0.28125 absoluteUsedCapacity=0.28125 used=<memory:9216, vCores:8> cluster=<memory:32768, vCores:32>
2014-05-03 23:18:02,381 INFO org.apache.hadoop.yarn.server.resourcemanager.rmcontainer.RMContainerImpl: container_1399156864902_0003_01_000010 Container Transitioned from ACQUIRED to RUNNING
2014-05-03 23:18:02,381 INFO org.apache.hadoop.yarn.server.resourcemanager.rmcontainer.RMContainerImpl: container_1399156864902_0003_01_000013 Container Transitioned from NEW to ALLOCATED
2014-05-03 23:18:02,382 INFO org.apache.hadoop.yarn.server.resourcemanager.RMAuditLogger: USER=ubuntu	OPERATION=AM Allocated Container	TARGET=SchedulerApp	RESULT=SUCCESS	APPID=application_1399156864902_0003	CONTAINERID=container_1399156864902_0003_01_000013
2014-05-03 23:18:02,382 INFO org.apache.hadoop.yarn.server.resourcemanager.scheduler.common.fica.FiCaSchedulerNode: Assigned container container_1399156864902_0003_01_000013 of capacity <memory:1024, vCores:1> on host nodeb:55487, which currently has 2 containers, <memory:2048, vCores:2> used and <memory:6144, vCores:6> available
2014-05-03 23:18:02,382 INFO org.apache.hadoop.yarn.server.resourcemanager.scheduler.capacity.LeafQueue: assignedContainer application=application_1399156864902_0003 container=Container: [ContainerId: container_1399156864902_0003_01_000013, NodeId: nodeb:55487, NodeHttpAddress: nodeb:8042, Resource: <memory:1024, vCores:1>, Priority: 10, Token: Token { kind: ContainerToken, service: 10.0.0.243:55487 }, ] containerId=container_1399156864902_0003_01_000013 queue=default: capacity=1.0, absoluteCapacity=1.0, usedResources=<memory:9216, vCores:8>usedCapacity=0.28125, absoluteUsedCapacity=0.28125, numApps=1, numContainers=8 usedCapacity=0.28125 absoluteUsedCapacity=0.28125 used=<memory:9216, vCores:8> cluster=<memory:32768, vCores:32>
2014-05-03 23:18:02,382 INFO org.apache.hadoop.yarn.server.resourcemanager.scheduler.capacity.ParentQueue: Re-sorting assigned queue: root.default stats: default: capacity=1.0, absoluteCapacity=1.0, usedResources=<memory:10240, vCores:9>usedCapacity=0.3125, absoluteUsedCapacity=0.3125, numApps=1, numContainers=9
2014-05-03 23:18:02,382 INFO org.apache.hadoop.yarn.server.resourcemanager.scheduler.capacity.ParentQueue: assignedContainer queue=root usedCapacity=0.3125 absoluteUsedCapacity=0.3125 used=<memory:10240, vCores:9> cluster=<memory:32768, vCores:32>
2014-05-03 23:18:02,382 INFO org.apache.hadoop.yarn.server.resourcemanager.rmcontainer.RMContainerImpl: container_1399156864902_0003_01_000008 Container Transitioned from ACQUIRED to RUNNING
2014-05-03 23:18:02,781 INFO org.apache.hadoop.yarn.server.resourcemanager.rmcontainer.RMContainerImpl: container_1399156864902_0003_01_000011 Container Transitioned from ALLOCATED to ACQUIRED
2014-05-03 23:18:02,781 INFO org.apache.hadoop.yarn.server.resourcemanager.rmcontainer.RMContainerImpl: container_1399156864902_0003_01_000012 Container Transitioned from ALLOCATED to ACQUIRED
2014-05-03 23:18:02,781 INFO org.apache.hadoop.yarn.server.resourcemanager.rmcontainer.RMContainerImpl: container_1399156864902_0003_01_000013 Container Transitioned from ALLOCATED to ACQUIRED
2014-05-03 23:18:03,342 INFO org.apache.hadoop.yarn.server.resourcemanager.rmcontainer.RMContainerImpl: container_1399156864902_0003_01_000011 Container Transitioned from ACQUIRED to RUNNING
2014-05-03 23:18:03,343 INFO org.apache.hadoop.yarn.server.resourcemanager.rmcontainer.RMContainerImpl: container_1399156864902_0003_01_000014 Container Transitioned from NEW to ALLOCATED
2014-05-03 23:18:03,343 INFO org.apache.hadoop.yarn.server.resourcemanager.RMAuditLogger: USER=ubuntu	OPERATION=AM Allocated Container	TARGET=SchedulerApp	RESULT=SUCCESS	APPID=application_1399156864902_0003	CONTAINERID=container_1399156864902_0003_01_000014
2014-05-03 23:18:03,343 INFO org.apache.hadoop.yarn.server.resourcemanager.scheduler.common.fica.FiCaSchedulerNode: Assigned container container_1399156864902_0003_01_000014 of capacity <memory:1024, vCores:1> on host noded:50846, which currently has 5 containers, <memory:6144, vCores:5> used and <memory:2048, vCores:3> available
2014-05-03 23:18:03,343 INFO org.apache.hadoop.yarn.server.resourcemanager.scheduler.capacity.LeafQueue: assignedContainer application=application_1399156864902_0003 container=Container: [ContainerId: container_1399156864902_0003_01_000014, NodeId: noded:50846, NodeHttpAddress: noded:8042, Resource: <memory:1024, vCores:1>, Priority: 10, Token: Token { kind: ContainerToken, service: 10.0.0.244:50846 }, ] containerId=container_1399156864902_0003_01_000014 queue=default: capacity=1.0, absoluteCapacity=1.0, usedResources=<memory:10240, vCores:9>usedCapacity=0.3125, absoluteUsedCapacity=0.3125, numApps=1, numContainers=9 usedCapacity=0.3125 absoluteUsedCapacity=0.3125 used=<memory:10240, vCores:9> cluster=<memory:32768, vCores:32>
2014-05-03 23:18:03,344 INFO org.apache.hadoop.yarn.server.resourcemanager.scheduler.capacity.ParentQueue: Re-sorting assigned queue: root.default stats: default: capacity=1.0, absoluteCapacity=1.0, usedResources=<memory:11264, vCores:10>usedCapacity=0.34375, absoluteUsedCapacity=0.34375, numApps=1, numContainers=10
2014-05-03 23:18:03,344 INFO org.apache.hadoop.yarn.server.resourcemanager.scheduler.capacity.ParentQueue: assignedContainer queue=root usedCapacity=0.34375 absoluteUsedCapacity=0.34375 used=<memory:11264, vCores:10> cluster=<memory:32768, vCores:32>
2014-05-03 23:18:03,382 INFO org.apache.hadoop.yarn.server.resourcemanager.rmcontainer.RMContainerImpl: container_1399156864902_0003_01_000013 Container Transitioned from ACQUIRED to RUNNING
2014-05-03 23:18:03,383 INFO org.apache.hadoop.yarn.server.resourcemanager.rmcontainer.RMContainerImpl: container_1399156864902_0003_01_000015 Container Transitioned from NEW to ALLOCATED
2014-05-03 23:18:03,383 INFO org.apache.hadoop.yarn.server.resourcemanager.RMAuditLogger: USER=ubuntu	OPERATION=AM Allocated Container	TARGET=SchedulerApp	RESULT=SUCCESS	APPID=application_1399156864902_0003	CONTAINERID=container_1399156864902_0003_01_000015
2014-05-03 23:18:03,383 INFO org.apache.hadoop.yarn.server.resourcemanager.scheduler.common.fica.FiCaSchedulerNode: Assigned container container_1399156864902_0003_01_000015 of capacity <memory:1024, vCores:1> on host nodeb:55487, which currently has 3 containers, <memory:3072, vCores:3> used and <memory:5120, vCores:5> available
2014-05-03 23:18:03,383 INFO org.apache.hadoop.yarn.server.resourcemanager.scheduler.capacity.LeafQueue: assignedContainer application=application_1399156864902_0003 container=Container: [ContainerId: container_1399156864902_0003_01_000015, NodeId: nodeb:55487, NodeHttpAddress: nodeb:8042, Resource: <memory:1024, vCores:1>, Priority: 10, Token: Token { kind: ContainerToken, service: 10.0.0.243:55487 }, ] containerId=container_1399156864902_0003_01_000015 queue=default: capacity=1.0, absoluteCapacity=1.0, usedResources=<memory:11264, vCores:10>usedCapacity=0.34375, absoluteUsedCapacity=0.34375, numApps=1, numContainers=10 usedCapacity=0.34375 absoluteUsedCapacity=0.34375 used=<memory:11264, vCores:10> cluster=<memory:32768, vCores:32>
2014-05-03 23:18:03,384 INFO org.apache.hadoop.yarn.server.resourcemanager.scheduler.capacity.ParentQueue: Re-sorting assigned queue: root.default stats: default: capacity=1.0, absoluteCapacity=1.0, usedResources=<memory:12288, vCores:11>usedCapacity=0.375, absoluteUsedCapacity=0.375, numApps=1, numContainers=11
2014-05-03 23:18:03,384 INFO org.apache.hadoop.yarn.server.resourcemanager.scheduler.capacity.ParentQueue: assignedContainer queue=root usedCapacity=0.375 absoluteUsedCapacity=0.375 used=<memory:12288, vCores:11> cluster=<memory:32768, vCores:32>
2014-05-03 23:18:03,384 INFO org.apache.hadoop.yarn.server.resourcemanager.rmcontainer.RMContainerImpl: container_1399156864902_0003_01_000016 Container Transitioned from NEW to ALLOCATED
2014-05-03 23:18:03,384 INFO org.apache.hadoop.yarn.server.resourcemanager.RMAuditLogger: USER=ubuntu	OPERATION=AM Allocated Container	TARGET=SchedulerApp	RESULT=SUCCESS	APPID=application_1399156864902_0003	CONTAINERID=container_1399156864902_0003_01_000016
2014-05-03 23:18:03,384 INFO org.apache.hadoop.yarn.server.resourcemanager.scheduler.common.fica.FiCaSchedulerNode: Assigned container container_1399156864902_0003_01_000016 of capacity <memory:1024, vCores:1> on host nodec:54860, which currently has 2 containers, <memory:2048, vCores:2> used and <memory:6144, vCores:6> available
2014-05-03 23:18:03,385 INFO org.apache.hadoop.yarn.server.resourcemanager.scheduler.capacity.LeafQueue: assignedContainer application=application_1399156864902_0003 container=Container: [ContainerId: container_1399156864902_0003_01_000016, NodeId: nodec:54860, NodeHttpAddress: nodec:8042, Resource: <memory:1024, vCores:1>, Priority: 10, Token: Token { kind: ContainerToken, service: 10.0.0.245:54860 }, ] containerId=container_1399156864902_0003_01_000016 queue=default: capacity=1.0, absoluteCapacity=1.0, usedResources=<memory:12288, vCores:11>usedCapacity=0.375, absoluteUsedCapacity=0.375, numApps=1, numContainers=11 usedCapacity=0.375 absoluteUsedCapacity=0.375 used=<memory:12288, vCores:11> cluster=<memory:32768, vCores:32>
2014-05-03 23:18:03,385 INFO org.apache.hadoop.yarn.server.resourcemanager.scheduler.capacity.ParentQueue: Re-sorting assigned queue: root.default stats: default: capacity=1.0, absoluteCapacity=1.0, usedResources=<memory:13312, vCores:12>usedCapacity=0.40625, absoluteUsedCapacity=0.40625, numApps=1, numContainers=12
2014-05-03 23:18:03,385 INFO org.apache.hadoop.yarn.server.resourcemanager.scheduler.capacity.ParentQueue: assignedContainer queue=root usedCapacity=0.40625 absoluteUsedCapacity=0.40625 used=<memory:13312, vCores:12> cluster=<memory:32768, vCores:32>
2014-05-03 23:18:03,385 INFO org.apache.hadoop.yarn.server.resourcemanager.rmcontainer.RMContainerImpl: container_1399156864902_0003_01_000012 Container Transitioned from ACQUIRED to RUNNING
2014-05-03 23:18:03,787 INFO org.apache.hadoop.yarn.server.resourcemanager.scheduler.AppSchedulingInfo: checking for deactivate... 
2014-05-03 23:18:03,787 INFO org.apache.hadoop.yarn.server.resourcemanager.rmcontainer.RMContainerImpl: container_1399156864902_0003_01_000014 Container Transitioned from ALLOCATED to ACQUIRED
2014-05-03 23:18:03,788 INFO org.apache.hadoop.yarn.server.resourcemanager.rmcontainer.RMContainerImpl: container_1399156864902_0003_01_000015 Container Transitioned from ALLOCATED to ACQUIRED
2014-05-03 23:18:03,788 INFO org.apache.hadoop.yarn.server.resourcemanager.rmcontainer.RMContainerImpl: container_1399156864902_0003_01_000016 Container Transitioned from ALLOCATED to ACQUIRED
2014-05-03 23:18:04,793 INFO org.apache.hadoop.yarn.server.resourcemanager.rmcontainer.RMContainerImpl: container_1399156864902_0003_01_000014 Container Transitioned from ACQUIRED to RELEASED
2014-05-03 23:18:04,793 INFO org.apache.hadoop.yarn.server.resourcemanager.scheduler.common.fica.FiCaSchedulerApp: Completed container: container_1399156864902_0003_01_000014 in state: RELEASED event:RELEASED
2014-05-03 23:18:04,793 INFO org.apache.hadoop.yarn.server.resourcemanager.RMAuditLogger: USER=ubuntu	IP=10.0.0.244	OPERATION=AM Released Container	TARGET=SchedulerApp	RESULT=SUCCESS	APPID=application_1399156864902_0003	CONTAINERID=container_1399156864902_0003_01_000014
2014-05-03 23:18:04,793 INFO org.apache.hadoop.yarn.server.resourcemanager.scheduler.common.fica.FiCaSchedulerNode: Released container container_1399156864902_0003_01_000014 of capacity <memory:1024, vCores:1> on host noded:50846, which currently has 4 containers, <memory:5120, vCores:4> used and <memory:3072, vCores:4> available, release resources=true
2014-05-03 23:18:04,793 INFO org.apache.hadoop.yarn.server.resourcemanager.scheduler.capacity.LeafQueue: default used=<memory:12288, vCores:11> numContainers=11 user=ubuntu user-resources=<memory:12288, vCores:11>
2014-05-03 23:18:04,793 INFO org.apache.hadoop.yarn.server.resourcemanager.scheduler.capacity.LeafQueue: completedContainer container=Container: [ContainerId: container_1399156864902_0003_01_000014, NodeId: noded:50846, NodeHttpAddress: noded:8042, Resource: <memory:1024, vCores:1>, Priority: 10, Token: Token { kind: ContainerToken, service: 10.0.0.244:50846 }, ] resource=<memory:1024, vCores:1> queue=default: capacity=1.0, absoluteCapacity=1.0, usedResources=<memory:12288, vCores:11>usedCapacity=0.375, absoluteUsedCapacity=0.375, numApps=1, numContainers=11 usedCapacity=0.375 absoluteUsedCapacity=0.375 used=<memory:12288, vCores:11> cluster=<memory:32768, vCores:32>
2014-05-03 23:18:04,794 INFO org.apache.hadoop.yarn.server.resourcemanager.scheduler.capacity.ParentQueue: completedContainer queue=root usedCapacity=0.375 absoluteUsedCapacity=0.375 used=<memory:12288, vCores:11> cluster=<memory:32768, vCores:32>
2014-05-03 23:18:04,794 INFO org.apache.hadoop.yarn.server.resourcemanager.scheduler.capacity.ParentQueue: Re-sorting completed queue: root.default stats: default: capacity=1.0, absoluteCapacity=1.0, usedResources=<memory:12288, vCores:11>usedCapacity=0.375, absoluteUsedCapacity=0.375, numApps=1, numContainers=11
2014-05-03 23:18:04,794 INFO org.apache.hadoop.yarn.server.resourcemanager.scheduler.capacity.CapacityScheduler: Application appattempt_1399156864902_0003_000001 released container container_1399156864902_0003_01_000014 on node: host: noded:50846 #containers=4 available=3072 used=5120 with event: RELEASED
2014-05-03 23:18:04,794 INFO org.apache.hadoop.yarn.server.resourcemanager.rmcontainer.RMContainerImpl: container_1399156864902_0003_01_000015 Container Transitioned from ACQUIRED to RELEASED
2014-05-03 23:18:04,794 INFO org.apache.hadoop.yarn.server.resourcemanager.scheduler.common.fica.FiCaSchedulerApp: Completed container: container_1399156864902_0003_01_000015 in state: RELEASED event:RELEASED
2014-05-03 23:18:04,794 INFO org.apache.hadoop.yarn.server.resourcemanager.RMAuditLogger: USER=ubuntu	IP=10.0.0.244	OPERATION=AM Released Container	TARGET=SchedulerApp	RESULT=SUCCESS	APPID=application_1399156864902_0003	CONTAINERID=container_1399156864902_0003_01_000015
2014-05-03 23:18:04,794 INFO org.apache.hadoop.yarn.server.resourcemanager.scheduler.common.fica.FiCaSchedulerNode: Released container container_1399156864902_0003_01_000015 of capacity <memory:1024, vCores:1> on host nodeb:55487, which currently has 2 containers, <memory:2048, vCores:2> used and <memory:6144, vCores:6> available, release resources=true
2014-05-03 23:18:04,794 INFO org.apache.hadoop.yarn.server.resourcemanager.scheduler.capacity.LeafQueue: default used=<memory:11264, vCores:10> numContainers=10 user=ubuntu user-resources=<memory:11264, vCores:10>
2014-05-03 23:18:04,794 INFO org.apache.hadoop.yarn.server.resourcemanager.scheduler.capacity.LeafQueue: completedContainer container=Container: [ContainerId: container_1399156864902_0003_01_000015, NodeId: nodeb:55487, NodeHttpAddress: nodeb:8042, Resource: <memory:1024, vCores:1>, Priority: 10, Token: Token { kind: ContainerToken, service: 10.0.0.243:55487 }, ] resource=<memory:1024, vCores:1> queue=default: capacity=1.0, absoluteCapacity=1.0, usedResources=<memory:11264, vCores:10>usedCapacity=0.34375, absoluteUsedCapacity=0.34375, numApps=1, numContainers=10 usedCapacity=0.34375 absoluteUsedCapacity=0.34375 used=<memory:11264, vCores:10> cluster=<memory:32768, vCores:32>
2014-05-03 23:18:04,794 INFO org.apache.hadoop.yarn.server.resourcemanager.scheduler.capacity.ParentQueue: completedContainer queue=root usedCapacity=0.34375 absoluteUsedCapacity=0.34375 used=<memory:11264, vCores:10> cluster=<memory:32768, vCores:32>
2014-05-03 23:18:04,795 INFO org.apache.hadoop.yarn.server.resourcemanager.scheduler.capacity.ParentQueue: Re-sorting completed queue: root.default stats: default: capacity=1.0, absoluteCapacity=1.0, usedResources=<memory:11264, vCores:10>usedCapacity=0.34375, absoluteUsedCapacity=0.34375, numApps=1, numContainers=10
2014-05-03 23:18:04,795 INFO org.apache.hadoop.yarn.server.resourcemanager.scheduler.capacity.CapacityScheduler: Application appattempt_1399156864902_0003_000001 released container container_1399156864902_0003_01_000015 on node: host: nodeb:55487 #containers=2 available=6144 used=2048 with event: RELEASED
2014-05-03 23:18:04,795 INFO org.apache.hadoop.yarn.server.resourcemanager.rmcontainer.RMContainerImpl: container_1399156864902_0003_01_000016 Container Transitioned from ACQUIRED to RELEASED
2014-05-03 23:18:04,795 INFO org.apache.hadoop.yarn.server.resourcemanager.scheduler.common.fica.FiCaSchedulerApp: Completed container: container_1399156864902_0003_01_000016 in state: RELEASED event:RELEASED
2014-05-03 23:18:04,795 INFO org.apache.hadoop.yarn.server.resourcemanager.RMAuditLogger: USER=ubuntu	IP=10.0.0.244	OPERATION=AM Released Container	TARGET=SchedulerApp	RESULT=SUCCESS	APPID=application_1399156864902_0003	CONTAINERID=container_1399156864902_0003_01_000016
2014-05-03 23:18:04,795 INFO org.apache.hadoop.yarn.server.resourcemanager.scheduler.common.fica.FiCaSchedulerNode: Released container container_1399156864902_0003_01_000016 of capacity <memory:1024, vCores:1> on host nodec:54860, which currently has 1 containers, <memory:1024, vCores:1> used and <memory:7168, vCores:7> available, release resources=true
2014-05-03 23:18:04,795 INFO org.apache.hadoop.yarn.server.resourcemanager.scheduler.capacity.LeafQueue: default used=<memory:10240, vCores:9> numContainers=9 user=ubuntu user-resources=<memory:10240, vCores:9>
2014-05-03 23:18:04,795 INFO org.apache.hadoop.yarn.server.resourcemanager.scheduler.capacity.LeafQueue: completedContainer container=Container: [ContainerId: container_1399156864902_0003_01_000016, NodeId: nodec:54860, NodeHttpAddress: nodec:8042, Resource: <memory:1024, vCores:1>, Priority: 10, Token: Token { kind: ContainerToken, service: 10.0.0.245:54860 }, ] resource=<memory:1024, vCores:1> queue=default: capacity=1.0, absoluteCapacity=1.0, usedResources=<memory:10240, vCores:9>usedCapacity=0.3125, absoluteUsedCapacity=0.3125, numApps=1, numContainers=9 usedCapacity=0.3125 absoluteUsedCapacity=0.3125 used=<memory:10240, vCores:9> cluster=<memory:32768, vCores:32>
2014-05-03 23:18:04,795 INFO org.apache.hadoop.yarn.server.resourcemanager.scheduler.capacity.ParentQueue: completedContainer queue=root usedCapacity=0.3125 absoluteUsedCapacity=0.3125 used=<memory:10240, vCores:9> cluster=<memory:32768, vCores:32>
2014-05-03 23:18:04,795 INFO org.apache.hadoop.yarn.server.resourcemanager.scheduler.capacity.ParentQueue: Re-sorting completed queue: root.default stats: default: capacity=1.0, absoluteCapacity=1.0, usedResources=<memory:10240, vCores:9>usedCapacity=0.3125, absoluteUsedCapacity=0.3125, numApps=1, numContainers=9
2014-05-03 23:18:04,796 INFO org.apache.hadoop.yarn.server.resourcemanager.scheduler.capacity.CapacityScheduler: Application appattempt_1399156864902_0003_000001 released container container_1399156864902_0003_01_000016 on node: host: nodec:54860 #containers=1 available=7168 used=1024 with event: RELEASED
2014-05-03 23:18:50,576 INFO org.apache.hadoop.yarn.server.resourcemanager.rmcontainer.RMContainerImpl: container_1399156864902_0003_01_000007 Container Transitioned from RUNNING to COMPLETED
2014-05-03 23:18:50,577 INFO org.apache.hadoop.yarn.server.resourcemanager.scheduler.common.fica.FiCaSchedulerApp: Completed container: container_1399156864902_0003_01_000007 in state: COMPLETED event:FINISHED
2014-05-03 23:18:50,577 INFO org.apache.hadoop.yarn.server.resourcemanager.RMAuditLogger: USER=ubuntu	OPERATION=AM Released Container	TARGET=SchedulerApp	RESULT=SUCCESS	APPID=application_1399156864902_0003	CONTAINERID=container_1399156864902_0003_01_000007
2014-05-03 23:18:50,577 INFO org.apache.hadoop.yarn.server.resourcemanager.scheduler.common.fica.FiCaSchedulerNode: Released container container_1399156864902_0003_01_000007 of capacity <memory:1024, vCores:1> on host noded:50846, which currently has 3 containers, <memory:4096, vCores:3> used and <memory:4096, vCores:5> available, release resources=true
2014-05-03 23:18:50,577 INFO org.apache.hadoop.yarn.server.resourcemanager.scheduler.capacity.LeafQueue: default used=<memory:9216, vCores:8> numContainers=8 user=ubuntu user-resources=<memory:9216, vCores:8>
2014-05-03 23:18:50,577 INFO org.apache.hadoop.yarn.server.resourcemanager.scheduler.capacity.LeafQueue: completedContainer container=Container: [ContainerId: container_1399156864902_0003_01_000007, NodeId: noded:50846, NodeHttpAddress: noded:8042, Resource: <memory:1024, vCores:1>, Priority: 10, Token: Token { kind: ContainerToken, service: 10.0.0.244:50846 }, ] resource=<memory:1024, vCores:1> queue=default: capacity=1.0, absoluteCapacity=1.0, usedResources=<memory:9216, vCores:8>usedCapacity=0.28125, absoluteUsedCapacity=0.28125, numApps=1, numContainers=8 usedCapacity=0.28125 absoluteUsedCapacity=0.28125 used=<memory:9216, vCores:8> cluster=<memory:32768, vCores:32>
2014-05-03 23:18:50,577 INFO org.apache.hadoop.yarn.server.resourcemanager.scheduler.capacity.ParentQueue: completedContainer queue=root usedCapacity=0.28125 absoluteUsedCapacity=0.28125 used=<memory:9216, vCores:8> cluster=<memory:32768, vCores:32>
2014-05-03 23:18:50,577 INFO org.apache.hadoop.yarn.server.resourcemanager.scheduler.capacity.ParentQueue: Re-sorting completed queue: root.default stats: default: capacity=1.0, absoluteCapacity=1.0, usedResources=<memory:9216, vCores:8>usedCapacity=0.28125, absoluteUsedCapacity=0.28125, numApps=1, numContainers=8
2014-05-03 23:18:50,578 INFO org.apache.hadoop.yarn.server.resourcemanager.scheduler.capacity.CapacityScheduler: Application appattempt_1399156864902_0003_000001 released container container_1399156864902_0003_01_000007 on node: host: noded:50846 #containers=3 available=4096 used=4096 with event: FINISHED
2014-05-03 23:18:50,578 INFO org.apache.hadoop.yarn.server.resourcemanager.rmcontainer.RMContainerImpl: container_1399156864902_0003_01_000011 Container Transitioned from RUNNING to COMPLETED
2014-05-03 23:18:50,578 INFO org.apache.hadoop.yarn.server.resourcemanager.scheduler.common.fica.FiCaSchedulerApp: Completed container: container_1399156864902_0003_01_000011 in state: COMPLETED event:FINISHED
2014-05-03 23:18:50,578 INFO org.apache.hadoop.yarn.server.resourcemanager.RMAuditLogger: USER=ubuntu	OPERATION=AM Released Container	TARGET=SchedulerApp	RESULT=SUCCESS	APPID=application_1399156864902_0003	CONTAINERID=container_1399156864902_0003_01_000011
2014-05-03 23:18:50,578 INFO org.apache.hadoop.yarn.server.resourcemanager.scheduler.common.fica.FiCaSchedulerNode: Released container container_1399156864902_0003_01_000011 of capacity <memory:1024, vCores:1> on host noded:50846, which currently has 2 containers, <memory:3072, vCores:2> used and <memory:5120, vCores:6> available, release resources=true
2014-05-03 23:18:50,578 INFO org.apache.hadoop.yarn.server.resourcemanager.scheduler.capacity.LeafQueue: default used=<memory:8192, vCores:7> numContainers=7 user=ubuntu user-resources=<memory:8192, vCores:7>
2014-05-03 23:18:50,578 INFO org.apache.hadoop.yarn.server.resourcemanager.scheduler.capacity.LeafQueue: completedContainer container=Container: [ContainerId: container_1399156864902_0003_01_000011, NodeId: noded:50846, NodeHttpAddress: noded:8042, Resource: <memory:1024, vCores:1>, Priority: 10, Token: Token { kind: ContainerToken, service: 10.0.0.244:50846 }, ] resource=<memory:1024, vCores:1> queue=default: capacity=1.0, absoluteCapacity=1.0, usedResources=<memory:8192, vCores:7>usedCapacity=0.25, absoluteUsedCapacity=0.25, numApps=1, numContainers=7 usedCapacity=0.25 absoluteUsedCapacity=0.25 used=<memory:8192, vCores:7> cluster=<memory:32768, vCores:32>
2014-05-03 23:18:50,578 INFO org.apache.hadoop.yarn.server.resourcemanager.scheduler.capacity.ParentQueue: completedContainer queue=root usedCapacity=0.25 absoluteUsedCapacity=0.25 used=<memory:8192, vCores:7> cluster=<memory:32768, vCores:32>
2014-05-03 23:18:50,578 INFO org.apache.hadoop.yarn.server.resourcemanager.scheduler.capacity.ParentQueue: Re-sorting completed queue: root.default stats: default: capacity=1.0, absoluteCapacity=1.0, usedResources=<memory:8192, vCores:7>usedCapacity=0.25, absoluteUsedCapacity=0.25, numApps=1, numContainers=7
2014-05-03 23:18:50,578 INFO org.apache.hadoop.yarn.server.resourcemanager.scheduler.capacity.CapacityScheduler: Application appattempt_1399156864902_0003_000001 released container container_1399156864902_0003_01_000011 on node: host: noded:50846 #containers=2 available=5120 used=3072 with event: FINISHED
2014-05-03 23:18:50,760 INFO org.apache.hadoop.yarn.server.resourcemanager.rmcontainer.RMContainerImpl: container_1399156864902_0003_01_000010 Container Transitioned from RUNNING to COMPLETED
2014-05-03 23:18:50,760 INFO org.apache.hadoop.yarn.server.resourcemanager.scheduler.common.fica.FiCaSchedulerApp: Completed container: container_1399156864902_0003_01_000010 in state: COMPLETED event:FINISHED
2014-05-03 23:18:50,760 INFO org.apache.hadoop.yarn.server.resourcemanager.RMAuditLogger: USER=ubuntu	OPERATION=AM Released Container	TARGET=SchedulerApp	RESULT=SUCCESS	APPID=application_1399156864902_0003	CONTAINERID=container_1399156864902_0003_01_000010
2014-05-03 23:18:50,760 INFO org.apache.hadoop.yarn.server.resourcemanager.scheduler.common.fica.FiCaSchedulerNode: Released container container_1399156864902_0003_01_000010 of capacity <memory:1024, vCores:1> on host nodeb:55487, which currently has 1 containers, <memory:1024, vCores:1> used and <memory:7168, vCores:7> available, release resources=true
2014-05-03 23:18:50,760 INFO org.apache.hadoop.yarn.server.resourcemanager.scheduler.capacity.LeafQueue: default used=<memory:7168, vCores:6> numContainers=6 user=ubuntu user-resources=<memory:7168, vCores:6>
2014-05-03 23:18:50,760 INFO org.apache.hadoop.yarn.server.resourcemanager.scheduler.capacity.LeafQueue: completedContainer container=Container: [ContainerId: container_1399156864902_0003_01_000010, NodeId: nodeb:55487, NodeHttpAddress: nodeb:8042, Resource: <memory:1024, vCores:1>, Priority: 10, Token: Token { kind: ContainerToken, service: 10.0.0.243:55487 }, ] resource=<memory:1024, vCores:1> queue=default: capacity=1.0, absoluteCapacity=1.0, usedResources=<memory:7168, vCores:6>usedCapacity=0.21875, absoluteUsedCapacity=0.21875, numApps=1, numContainers=6 usedCapacity=0.21875 absoluteUsedCapacity=0.21875 used=<memory:7168, vCores:6> cluster=<memory:32768, vCores:32>
2014-05-03 23:18:50,760 INFO org.apache.hadoop.yarn.server.resourcemanager.scheduler.capacity.ParentQueue: completedContainer queue=root usedCapacity=0.21875 absoluteUsedCapacity=0.21875 used=<memory:7168, vCores:6> cluster=<memory:32768, vCores:32>
2014-05-03 23:18:50,761 INFO org.apache.hadoop.yarn.server.resourcemanager.scheduler.capacity.ParentQueue: Re-sorting completed queue: root.default stats: default: capacity=1.0, absoluteCapacity=1.0, usedResources=<memory:7168, vCores:6>usedCapacity=0.21875, absoluteUsedCapacity=0.21875, numApps=1, numContainers=6
2014-05-03 23:18:50,761 INFO org.apache.hadoop.yarn.server.resourcemanager.scheduler.capacity.CapacityScheduler: Application appattempt_1399156864902_0003_000001 released container container_1399156864902_0003_01_000010 on node: host: nodeb:55487 #containers=1 available=7168 used=1024 with event: FINISHED
2014-05-03 23:18:50,761 INFO org.apache.hadoop.yarn.server.resourcemanager.rmcontainer.RMContainerImpl: container_1399156864902_0003_01_000013 Container Transitioned from RUNNING to COMPLETED
2014-05-03 23:18:50,761 INFO org.apache.hadoop.yarn.server.resourcemanager.scheduler.common.fica.FiCaSchedulerApp: Completed container: container_1399156864902_0003_01_000013 in state: COMPLETED event:FINISHED
2014-05-03 23:18:50,761 INFO org.apache.hadoop.yarn.server.resourcemanager.RMAuditLogger: USER=ubuntu	OPERATION=AM Released Container	TARGET=SchedulerApp	RESULT=SUCCESS	APPID=application_1399156864902_0003	CONTAINERID=container_1399156864902_0003_01_000013
2014-05-03 23:18:50,761 INFO org.apache.hadoop.yarn.server.resourcemanager.scheduler.common.fica.FiCaSchedulerNode: Released container container_1399156864902_0003_01_000013 of capacity <memory:1024, vCores:1> on host nodeb:55487, which currently has 0 containers, <memory:0, vCores:0> used and <memory:8192, vCores:8> available, release resources=true
2014-05-03 23:18:50,761 INFO org.apache.hadoop.yarn.server.resourcemanager.scheduler.capacity.LeafQueue: default used=<memory:6144, vCores:5> numContainers=5 user=ubuntu user-resources=<memory:6144, vCores:5>
2014-05-03 23:18:50,761 INFO org.apache.hadoop.yarn.server.resourcemanager.scheduler.capacity.LeafQueue: completedContainer container=Container: [ContainerId: container_1399156864902_0003_01_000013, NodeId: nodeb:55487, NodeHttpAddress: nodeb:8042, Resource: <memory:1024, vCores:1>, Priority: 10, Token: Token { kind: ContainerToken, service: 10.0.0.243:55487 }, ] resource=<memory:1024, vCores:1> queue=default: capacity=1.0, absoluteCapacity=1.0, usedResources=<memory:6144, vCores:5>usedCapacity=0.1875, absoluteUsedCapacity=0.1875, numApps=1, numContainers=5 usedCapacity=0.1875 absoluteUsedCapacity=0.1875 used=<memory:6144, vCores:5> cluster=<memory:32768, vCores:32>
2014-05-03 23:18:50,761 INFO org.apache.hadoop.yarn.server.resourcemanager.scheduler.capacity.ParentQueue: completedContainer queue=root usedCapacity=0.1875 absoluteUsedCapacity=0.1875 used=<memory:6144, vCores:5> cluster=<memory:32768, vCores:32>
2014-05-03 23:18:50,761 INFO org.apache.hadoop.yarn.server.resourcemanager.scheduler.capacity.ParentQueue: Re-sorting completed queue: root.default stats: default: capacity=1.0, absoluteCapacity=1.0, usedResources=<memory:6144, vCores:5>usedCapacity=0.1875, absoluteUsedCapacity=0.1875, numApps=1, numContainers=5
2014-05-03 23:18:50,761 INFO org.apache.hadoop.yarn.server.resourcemanager.scheduler.capacity.CapacityScheduler: Application appattempt_1399156864902_0003_000001 released container container_1399156864902_0003_01_000013 on node: host: nodeb:55487 #containers=0 available=8192 used=0 with event: FINISHED
2014-05-03 23:18:50,783 INFO org.apache.hadoop.yarn.server.resourcemanager.rmcontainer.RMContainerImpl: container_1399156864902_0003_01_000009 Container Transitioned from RUNNING to COMPLETED
2014-05-03 23:18:50,783 INFO org.apache.hadoop.yarn.server.resourcemanager.scheduler.common.fica.FiCaSchedulerApp: Completed container: container_1399156864902_0003_01_000009 in state: COMPLETED event:FINISHED
2014-05-03 23:18:50,783 INFO org.apache.hadoop.yarn.server.resourcemanager.RMAuditLogger: USER=ubuntu	OPERATION=AM Released Container	TARGET=SchedulerApp	RESULT=SUCCESS	APPID=application_1399156864902_0003	CONTAINERID=container_1399156864902_0003_01_000009
2014-05-03 23:18:50,783 INFO org.apache.hadoop.yarn.server.resourcemanager.scheduler.common.fica.FiCaSchedulerNode: Released container container_1399156864902_0003_01_000009 of capacity <memory:1024, vCores:1> on host nodea:56325, which currently has 1 containers, <memory:1024, vCores:1> used and <memory:7168, vCores:7> available, release resources=true
2014-05-03 23:18:50,783 INFO org.apache.hadoop.yarn.server.resourcemanager.scheduler.capacity.LeafQueue: default used=<memory:5120, vCores:4> numContainers=4 user=ubuntu user-resources=<memory:5120, vCores:4>
2014-05-03 23:18:50,783 INFO org.apache.hadoop.yarn.server.resourcemanager.scheduler.capacity.LeafQueue: completedContainer container=Container: [ContainerId: container_1399156864902_0003_01_000009, NodeId: nodea:56325, NodeHttpAddress: nodea:8042, Resource: <memory:1024, vCores:1>, Priority: 10, Token: Token { kind: ContainerToken, service: 10.0.0.182:56325 }, ] resource=<memory:1024, vCores:1> queue=default: capacity=1.0, absoluteCapacity=1.0, usedResources=<memory:5120, vCores:4>usedCapacity=0.15625, absoluteUsedCapacity=0.15625, numApps=1, numContainers=4 usedCapacity=0.15625 absoluteUsedCapacity=0.15625 used=<memory:5120, vCores:4> cluster=<memory:32768, vCores:32>
2014-05-03 23:18:50,783 INFO org.apache.hadoop.yarn.server.resourcemanager.scheduler.capacity.ParentQueue: completedContainer queue=root usedCapacity=0.15625 absoluteUsedCapacity=0.15625 used=<memory:5120, vCores:4> cluster=<memory:32768, vCores:32>
2014-05-03 23:18:50,783 INFO org.apache.hadoop.yarn.server.resourcemanager.scheduler.capacity.ParentQueue: Re-sorting completed queue: root.default stats: default: capacity=1.0, absoluteCapacity=1.0, usedResources=<memory:5120, vCores:4>usedCapacity=0.15625, absoluteUsedCapacity=0.15625, numApps=1, numContainers=4
2014-05-03 23:18:50,784 INFO org.apache.hadoop.yarn.server.resourcemanager.scheduler.capacity.CapacityScheduler: Application appattempt_1399156864902_0003_000001 released container container_1399156864902_0003_01_000009 on node: host: nodea:56325 #containers=1 available=7168 used=1024 with event: FINISHED
2014-05-03 23:18:50,784 INFO org.apache.hadoop.yarn.server.resourcemanager.rmcontainer.RMContainerImpl: container_1399156864902_0003_01_000012 Container Transitioned from RUNNING to COMPLETED
2014-05-03 23:18:50,784 INFO org.apache.hadoop.yarn.server.resourcemanager.scheduler.common.fica.FiCaSchedulerApp: Completed container: container_1399156864902_0003_01_000012 in state: COMPLETED event:FINISHED
2014-05-03 23:18:50,784 INFO org.apache.hadoop.yarn.server.resourcemanager.RMAuditLogger: USER=ubuntu	OPERATION=AM Released Container	TARGET=SchedulerApp	RESULT=SUCCESS	APPID=application_1399156864902_0003	CONTAINERID=container_1399156864902_0003_01_000012
2014-05-03 23:18:50,784 INFO org.apache.hadoop.yarn.server.resourcemanager.scheduler.common.fica.FiCaSchedulerNode: Released container container_1399156864902_0003_01_000012 of capacity <memory:1024, vCores:1> on host nodea:56325, which currently has 0 containers, <memory:0, vCores:0> used and <memory:8192, vCores:8> available, release resources=true
2014-05-03 23:18:50,784 INFO org.apache.hadoop.yarn.server.resourcemanager.scheduler.capacity.LeafQueue: default used=<memory:4096, vCores:3> numContainers=3 user=ubuntu user-resources=<memory:4096, vCores:3>
2014-05-03 23:18:50,784 INFO org.apache.hadoop.yarn.server.resourcemanager.scheduler.capacity.LeafQueue: completedContainer container=Container: [ContainerId: container_1399156864902_0003_01_000012, NodeId: nodea:56325, NodeHttpAddress: nodea:8042, Resource: <memory:1024, vCores:1>, Priority: 10, Token: Token { kind: ContainerToken, service: 10.0.0.182:56325 }, ] resource=<memory:1024, vCores:1> queue=default: capacity=1.0, absoluteCapacity=1.0, usedResources=<memory:4096, vCores:3>usedCapacity=0.125, absoluteUsedCapacity=0.125, numApps=1, numContainers=3 usedCapacity=0.125 absoluteUsedCapacity=0.125 used=<memory:4096, vCores:3> cluster=<memory:32768, vCores:32>
2014-05-03 23:18:50,784 INFO org.apache.hadoop.yarn.server.resourcemanager.scheduler.capacity.ParentQueue: completedContainer queue=root usedCapacity=0.125 absoluteUsedCapacity=0.125 used=<memory:4096, vCores:3> cluster=<memory:32768, vCores:32>
2014-05-03 23:18:50,784 INFO org.apache.hadoop.yarn.server.resourcemanager.scheduler.capacity.ParentQueue: Re-sorting completed queue: root.default stats: default: capacity=1.0, absoluteCapacity=1.0, usedResources=<memory:4096, vCores:3>usedCapacity=0.125, absoluteUsedCapacity=0.125, numApps=1, numContainers=3
2014-05-03 23:18:50,784 INFO org.apache.hadoop.yarn.server.resourcemanager.scheduler.capacity.CapacityScheduler: Application appattempt_1399156864902_0003_000001 released container container_1399156864902_0003_01_000012 on node: host: nodea:56325 #containers=0 available=8192 used=0 with event: FINISHED
2014-05-03 23:18:50,812 INFO org.apache.hadoop.yarn.server.resourcemanager.rmcontainer.RMContainerImpl: container_1399156864902_0003_01_000008 Container Transitioned from RUNNING to COMPLETED
2014-05-03 23:18:50,812 INFO org.apache.hadoop.yarn.server.resourcemanager.scheduler.common.fica.FiCaSchedulerApp: Completed container: container_1399156864902_0003_01_000008 in state: COMPLETED event:FINISHED
2014-05-03 23:18:50,812 INFO org.apache.hadoop.yarn.server.resourcemanager.RMAuditLogger: USER=ubuntu	OPERATION=AM Released Container	TARGET=SchedulerApp	RESULT=SUCCESS	APPID=application_1399156864902_0003	CONTAINERID=container_1399156864902_0003_01_000008
2014-05-03 23:18:50,812 INFO org.apache.hadoop.yarn.server.resourcemanager.scheduler.common.fica.FiCaSchedulerNode: Released container container_1399156864902_0003_01_000008 of capacity <memory:1024, vCores:1> on host nodec:54860, which currently has 0 containers, <memory:0, vCores:0> used and <memory:8192, vCores:8> available, release resources=true
2014-05-03 23:18:50,813 INFO org.apache.hadoop.yarn.server.resourcemanager.scheduler.capacity.LeafQueue: default used=<memory:3072, vCores:2> numContainers=2 user=ubuntu user-resources=<memory:3072, vCores:2>
2014-05-03 23:18:50,813 INFO org.apache.hadoop.yarn.server.resourcemanager.scheduler.capacity.LeafQueue: completedContainer container=Container: [ContainerId: container_1399156864902_0003_01_000008, NodeId: nodec:54860, NodeHttpAddress: nodec:8042, Resource: <memory:1024, vCores:1>, Priority: 10, Token: Token { kind: ContainerToken, service: 10.0.0.245:54860 }, ] resource=<memory:1024, vCores:1> queue=default: capacity=1.0, absoluteCapacity=1.0, usedResources=<memory:3072, vCores:2>usedCapacity=0.09375, absoluteUsedCapacity=0.09375, numApps=1, numContainers=2 usedCapacity=0.09375 absoluteUsedCapacity=0.09375 used=<memory:3072, vCores:2> cluster=<memory:32768, vCores:32>
2014-05-03 23:18:50,813 INFO org.apache.hadoop.yarn.server.resourcemanager.scheduler.capacity.ParentQueue: completedContainer queue=root usedCapacity=0.09375 absoluteUsedCapacity=0.09375 used=<memory:3072, vCores:2> cluster=<memory:32768, vCores:32>
2014-05-03 23:18:50,813 INFO org.apache.hadoop.yarn.server.resourcemanager.scheduler.capacity.ParentQueue: Re-sorting completed queue: root.default stats: default: capacity=1.0, absoluteCapacity=1.0, usedResources=<memory:3072, vCores:2>usedCapacity=0.09375, absoluteUsedCapacity=0.09375, numApps=1, numContainers=2
2014-05-03 23:18:50,813 INFO org.apache.hadoop.yarn.server.resourcemanager.scheduler.capacity.CapacityScheduler: Application appattempt_1399156864902_0003_000001 released container container_1399156864902_0003_01_000008 on node: host: nodec:54860 #containers=0 available=8192 used=0 with event: FINISHED
2014-05-03 23:18:51,578 INFO org.apache.hadoop.yarn.server.resourcemanager.rmcontainer.RMContainerImpl: container_1399156864902_0003_01_000006 Container Transitioned from RUNNING to COMPLETED
2014-05-03 23:18:51,578 INFO org.apache.hadoop.yarn.server.resourcemanager.scheduler.common.fica.FiCaSchedulerApp: Completed container: container_1399156864902_0003_01_000006 in state: COMPLETED event:FINISHED
2014-05-03 23:18:51,579 INFO org.apache.hadoop.yarn.server.resourcemanager.RMAuditLogger: USER=ubuntu	OPERATION=AM Released Container	TARGET=SchedulerApp	RESULT=SUCCESS	APPID=application_1399156864902_0003	CONTAINERID=container_1399156864902_0003_01_000006
2014-05-03 23:18:51,579 INFO org.apache.hadoop.yarn.server.resourcemanager.scheduler.common.fica.FiCaSchedulerNode: Released container container_1399156864902_0003_01_000006 of capacity <memory:1024, vCores:1> on host noded:50846, which currently has 1 containers, <memory:2048, vCores:1> used and <memory:6144, vCores:7> available, release resources=true
2014-05-03 23:18:51,579 INFO org.apache.hadoop.yarn.server.resourcemanager.scheduler.capacity.LeafQueue: default used=<memory:2048, vCores:1> numContainers=1 user=ubuntu user-resources=<memory:2048, vCores:1>
2014-05-03 23:18:51,579 INFO org.apache.hadoop.yarn.server.resourcemanager.scheduler.capacity.LeafQueue: completedContainer container=Container: [ContainerId: container_1399156864902_0003_01_000006, NodeId: noded:50846, NodeHttpAddress: noded:8042, Resource: <memory:1024, vCores:1>, Priority: 10, Token: Token { kind: ContainerToken, service: 10.0.0.244:50846 }, ] resource=<memory:1024, vCores:1> queue=default: capacity=1.0, absoluteCapacity=1.0, usedResources=<memory:2048, vCores:1>usedCapacity=0.0625, absoluteUsedCapacity=0.0625, numApps=1, numContainers=1 usedCapacity=0.0625 absoluteUsedCapacity=0.0625 used=<memory:2048, vCores:1> cluster=<memory:32768, vCores:32>
2014-05-03 23:18:51,579 INFO org.apache.hadoop.yarn.server.resourcemanager.scheduler.capacity.ParentQueue: completedContainer queue=root usedCapacity=0.0625 absoluteUsedCapacity=0.0625 used=<memory:2048, vCores:1> cluster=<memory:32768, vCores:32>
2014-05-03 23:18:51,579 INFO org.apache.hadoop.yarn.server.resourcemanager.scheduler.capacity.ParentQueue: Re-sorting completed queue: root.default stats: default: capacity=1.0, absoluteCapacity=1.0, usedResources=<memory:2048, vCores:1>usedCapacity=0.0625, absoluteUsedCapacity=0.0625, numApps=1, numContainers=1
2014-05-03 23:18:51,579 INFO org.apache.hadoop.yarn.server.resourcemanager.scheduler.capacity.CapacityScheduler: Application appattempt_1399156864902_0003_000001 released container container_1399156864902_0003_01_000006 on node: host: noded:50846 #containers=1 available=6144 used=2048 with event: FINISHED
2014-05-03 23:18:51,762 INFO org.apache.hadoop.yarn.server.resourcemanager.rmcontainer.RMContainerImpl: container_1399156864902_0003_01_000017 Container Transitioned from NEW to ALLOCATED
2014-05-03 23:18:51,762 INFO org.apache.hadoop.yarn.server.resourcemanager.RMAuditLogger: USER=ubuntu	OPERATION=AM Allocated Container	TARGET=SchedulerApp	RESULT=SUCCESS	APPID=application_1399156864902_0003	CONTAINERID=container_1399156864902_0003_01_000017
2014-05-03 23:18:51,762 INFO org.apache.hadoop.yarn.server.resourcemanager.scheduler.common.fica.FiCaSchedulerNode: Assigned container container_1399156864902_0003_01_000017 of capacity <memory:1024, vCores:1> on host nodeb:55487, which currently has 1 containers, <memory:1024, vCores:1> used and <memory:7168, vCores:7> available
2014-05-03 23:18:51,762 INFO org.apache.hadoop.yarn.server.resourcemanager.scheduler.capacity.LeafQueue: assignedContainer application=application_1399156864902_0003 container=Container: [ContainerId: container_1399156864902_0003_01_000017, NodeId: nodeb:55487, NodeHttpAddress: nodeb:8042, Resource: <memory:1024, vCores:1>, Priority: 10, Token: Token { kind: ContainerToken, service: 10.0.0.243:55487 }, ] containerId=container_1399156864902_0003_01_000017 queue=default: capacity=1.0, absoluteCapacity=1.0, usedResources=<memory:2048, vCores:1>usedCapacity=0.0625, absoluteUsedCapacity=0.0625, numApps=1, numContainers=1 usedCapacity=0.0625 absoluteUsedCapacity=0.0625 used=<memory:2048, vCores:1> cluster=<memory:32768, vCores:32>
2014-05-03 23:18:51,762 INFO org.apache.hadoop.yarn.server.resourcemanager.scheduler.capacity.ParentQueue: Re-sorting assigned queue: root.default stats: default: capacity=1.0, absoluteCapacity=1.0, usedResources=<memory:3072, vCores:2>usedCapacity=0.09375, absoluteUsedCapacity=0.09375, numApps=1, numContainers=2
2014-05-03 23:18:51,762 INFO org.apache.hadoop.yarn.server.resourcemanager.scheduler.capacity.ParentQueue: assignedContainer queue=root usedCapacity=0.09375 absoluteUsedCapacity=0.09375 used=<memory:3072, vCores:2> cluster=<memory:32768, vCores:32>
2014-05-03 23:18:51,784 INFO org.apache.hadoop.yarn.server.resourcemanager.rmcontainer.RMContainerImpl: container_1399156864902_0003_01_000018 Container Transitioned from NEW to ALLOCATED
2014-05-03 23:18:51,784 INFO org.apache.hadoop.yarn.server.resourcemanager.RMAuditLogger: USER=ubuntu	OPERATION=AM Allocated Container	TARGET=SchedulerApp	RESULT=SUCCESS	APPID=application_1399156864902_0003	CONTAINERID=container_1399156864902_0003_01_000018
2014-05-03 23:18:51,784 INFO org.apache.hadoop.yarn.server.resourcemanager.scheduler.common.fica.FiCaSchedulerNode: Assigned container container_1399156864902_0003_01_000018 of capacity <memory:1024, vCores:1> on host nodea:56325, which currently has 1 containers, <memory:1024, vCores:1> used and <memory:7168, vCores:7> available
2014-05-03 23:18:51,785 INFO org.apache.hadoop.yarn.server.resourcemanager.scheduler.capacity.LeafQueue: assignedContainer application=application_1399156864902_0003 container=Container: [ContainerId: container_1399156864902_0003_01_000018, NodeId: nodea:56325, NodeHttpAddress: nodea:8042, Resource: <memory:1024, vCores:1>, Priority: 10, Token: Token { kind: ContainerToken, service: 10.0.0.182:56325 }, ] containerId=container_1399156864902_0003_01_000018 queue=default: capacity=1.0, absoluteCapacity=1.0, usedResources=<memory:3072, vCores:2>usedCapacity=0.09375, absoluteUsedCapacity=0.09375, numApps=1, numContainers=2 usedCapacity=0.09375 absoluteUsedCapacity=0.09375 used=<memory:3072, vCores:2> cluster=<memory:32768, vCores:32>
2014-05-03 23:18:51,785 INFO org.apache.hadoop.yarn.server.resourcemanager.scheduler.capacity.ParentQueue: Re-sorting assigned queue: root.default stats: default: capacity=1.0, absoluteCapacity=1.0, usedResources=<memory:4096, vCores:3>usedCapacity=0.125, absoluteUsedCapacity=0.125, numApps=1, numContainers=3
2014-05-03 23:18:51,785 INFO org.apache.hadoop.yarn.server.resourcemanager.scheduler.capacity.ParentQueue: assignedContainer queue=root usedCapacity=0.125 absoluteUsedCapacity=0.125 used=<memory:4096, vCores:3> cluster=<memory:32768, vCores:32>
2014-05-03 23:18:51,814 INFO org.apache.hadoop.yarn.server.resourcemanager.rmcontainer.RMContainerImpl: container_1399156864902_0003_01_000019 Container Transitioned from NEW to ALLOCATED
2014-05-03 23:18:51,814 INFO org.apache.hadoop.yarn.server.resourcemanager.RMAuditLogger: USER=ubuntu	OPERATION=AM Allocated Container	TARGET=SchedulerApp	RESULT=SUCCESS	APPID=application_1399156864902_0003	CONTAINERID=container_1399156864902_0003_01_000019
2014-05-03 23:18:51,814 INFO org.apache.hadoop.yarn.server.resourcemanager.scheduler.common.fica.FiCaSchedulerNode: Assigned container container_1399156864902_0003_01_000019 of capacity <memory:1024, vCores:1> on host nodec:54860, which currently has 1 containers, <memory:1024, vCores:1> used and <memory:7168, vCores:7> available
2014-05-03 23:18:51,814 INFO org.apache.hadoop.yarn.server.resourcemanager.scheduler.capacity.LeafQueue: assignedContainer application=application_1399156864902_0003 container=Container: [ContainerId: container_1399156864902_0003_01_000019, NodeId: nodec:54860, NodeHttpAddress: nodec:8042, Resource: <memory:1024, vCores:1>, Priority: 10, Token: Token { kind: ContainerToken, service: 10.0.0.245:54860 }, ] containerId=container_1399156864902_0003_01_000019 queue=default: capacity=1.0, absoluteCapacity=1.0, usedResources=<memory:4096, vCores:3>usedCapacity=0.125, absoluteUsedCapacity=0.125, numApps=1, numContainers=3 usedCapacity=0.125 absoluteUsedCapacity=0.125 used=<memory:4096, vCores:3> cluster=<memory:32768, vCores:32>
2014-05-03 23:18:51,814 INFO org.apache.hadoop.yarn.server.resourcemanager.scheduler.capacity.ParentQueue: Re-sorting assigned queue: root.default stats: default: capacity=1.0, absoluteCapacity=1.0, usedResources=<memory:5120, vCores:4>usedCapacity=0.15625, absoluteUsedCapacity=0.15625, numApps=1, numContainers=4
2014-05-03 23:18:51,814 INFO org.apache.hadoop.yarn.server.resourcemanager.scheduler.capacity.ParentQueue: assignedContainer queue=root usedCapacity=0.15625 absoluteUsedCapacity=0.15625 used=<memory:5120, vCores:4> cluster=<memory:32768, vCores:32>
2014-05-03 23:18:52,066 INFO org.apache.hadoop.yarn.server.resourcemanager.rmcontainer.RMContainerImpl: container_1399156864902_0003_01_000017 Container Transitioned from ALLOCATED to ACQUIRED
2014-05-03 23:18:52,067 INFO org.apache.hadoop.yarn.server.resourcemanager.rmcontainer.RMContainerImpl: container_1399156864902_0003_01_000018 Container Transitioned from ALLOCATED to ACQUIRED
2014-05-03 23:18:52,067 INFO org.apache.hadoop.yarn.server.resourcemanager.rmcontainer.RMContainerImpl: container_1399156864902_0003_01_000019 Container Transitioned from ALLOCATED to ACQUIRED
2014-05-03 23:18:52,764 INFO org.apache.hadoop.yarn.server.resourcemanager.rmcontainer.RMContainerImpl: container_1399156864902_0003_01_000017 Container Transitioned from ACQUIRED to RUNNING
2014-05-03 23:18:52,764 INFO org.apache.hadoop.yarn.server.resourcemanager.rmcontainer.RMContainerImpl: container_1399156864902_0003_01_000020 Container Transitioned from NEW to ALLOCATED
2014-05-03 23:18:52,764 INFO org.apache.hadoop.yarn.server.resourcemanager.RMAuditLogger: USER=ubuntu	OPERATION=AM Allocated Container	TARGET=SchedulerApp	RESULT=SUCCESS	APPID=application_1399156864902_0003	CONTAINERID=container_1399156864902_0003_01_000020
2014-05-03 23:18:52,764 INFO org.apache.hadoop.yarn.server.resourcemanager.scheduler.common.fica.FiCaSchedulerNode: Assigned container container_1399156864902_0003_01_000020 of capacity <memory:1024, vCores:1> on host nodeb:55487, which currently has 2 containers, <memory:2048, vCores:2> used and <memory:6144, vCores:6> available
2014-05-03 23:18:52,765 INFO org.apache.hadoop.yarn.server.resourcemanager.scheduler.capacity.LeafQueue: assignedContainer application=application_1399156864902_0003 container=Container: [ContainerId: container_1399156864902_0003_01_000020, NodeId: nodeb:55487, NodeHttpAddress: nodeb:8042, Resource: <memory:1024, vCores:1>, Priority: 10, Token: Token { kind: ContainerToken, service: 10.0.0.243:55487 }, ] containerId=container_1399156864902_0003_01_000020 queue=default: capacity=1.0, absoluteCapacity=1.0, usedResources=<memory:5120, vCores:4>usedCapacity=0.15625, absoluteUsedCapacity=0.15625, numApps=1, numContainers=4 usedCapacity=0.15625 absoluteUsedCapacity=0.15625 used=<memory:5120, vCores:4> cluster=<memory:32768, vCores:32>
2014-05-03 23:18:52,765 INFO org.apache.hadoop.yarn.server.resourcemanager.scheduler.capacity.ParentQueue: Re-sorting assigned queue: root.default stats: default: capacity=1.0, absoluteCapacity=1.0, usedResources=<memory:6144, vCores:5>usedCapacity=0.1875, absoluteUsedCapacity=0.1875, numApps=1, numContainers=5
2014-05-03 23:18:52,765 INFO org.apache.hadoop.yarn.server.resourcemanager.scheduler.capacity.ParentQueue: assignedContainer queue=root usedCapacity=0.1875 absoluteUsedCapacity=0.1875 used=<memory:6144, vCores:5> cluster=<memory:32768, vCores:32>
2014-05-03 23:18:52,786 INFO org.apache.hadoop.yarn.server.resourcemanager.rmcontainer.RMContainerImpl: container_1399156864902_0003_01_000018 Container Transitioned from ACQUIRED to RUNNING
2014-05-03 23:18:52,786 INFO org.apache.hadoop.yarn.server.resourcemanager.rmcontainer.RMContainerImpl: container_1399156864902_0003_01_000021 Container Transitioned from NEW to ALLOCATED
2014-05-03 23:18:52,787 INFO org.apache.hadoop.yarn.server.resourcemanager.RMAuditLogger: USER=ubuntu	OPERATION=AM Allocated Container	TARGET=SchedulerApp	RESULT=SUCCESS	APPID=application_1399156864902_0003	CONTAINERID=container_1399156864902_0003_01_000021
2014-05-03 23:18:52,787 INFO org.apache.hadoop.yarn.server.resourcemanager.scheduler.common.fica.FiCaSchedulerNode: Assigned container container_1399156864902_0003_01_000021 of capacity <memory:1024, vCores:1> on host nodea:56325, which currently has 2 containers, <memory:2048, vCores:2> used and <memory:6144, vCores:6> available
2014-05-03 23:18:52,787 INFO org.apache.hadoop.yarn.server.resourcemanager.scheduler.capacity.LeafQueue: assignedContainer application=application_1399156864902_0003 container=Container: [ContainerId: container_1399156864902_0003_01_000021, NodeId: nodea:56325, NodeHttpAddress: nodea:8042, Resource: <memory:1024, vCores:1>, Priority: 10, Token: Token { kind: ContainerToken, service: 10.0.0.182:56325 }, ] containerId=container_1399156864902_0003_01_000021 queue=default: capacity=1.0, absoluteCapacity=1.0, usedResources=<memory:6144, vCores:5>usedCapacity=0.1875, absoluteUsedCapacity=0.1875, numApps=1, numContainers=5 usedCapacity=0.1875 absoluteUsedCapacity=0.1875 used=<memory:6144, vCores:5> cluster=<memory:32768, vCores:32>
2014-05-03 23:18:52,787 INFO org.apache.hadoop.yarn.server.resourcemanager.scheduler.capacity.ParentQueue: Re-sorting assigned queue: root.default stats: default: capacity=1.0, absoluteCapacity=1.0, usedResources=<memory:7168, vCores:6>usedCapacity=0.21875, absoluteUsedCapacity=0.21875, numApps=1, numContainers=6
2014-05-03 23:18:52,787 INFO org.apache.hadoop.yarn.server.resourcemanager.scheduler.capacity.ParentQueue: assignedContainer queue=root usedCapacity=0.21875 absoluteUsedCapacity=0.21875 used=<memory:7168, vCores:6> cluster=<memory:32768, vCores:32>
2014-05-03 23:18:52,816 INFO org.apache.hadoop.yarn.server.resourcemanager.rmcontainer.RMContainerImpl: container_1399156864902_0003_01_000019 Container Transitioned from ACQUIRED to RUNNING
2014-05-03 23:18:52,816 INFO org.apache.hadoop.yarn.server.resourcemanager.rmcontainer.RMContainerImpl: container_1399156864902_0003_01_000022 Container Transitioned from NEW to ALLOCATED
2014-05-03 23:18:52,816 INFO org.apache.hadoop.yarn.server.resourcemanager.RMAuditLogger: USER=ubuntu	OPERATION=AM Allocated Container	TARGET=SchedulerApp	RESULT=SUCCESS	APPID=application_1399156864902_0003	CONTAINERID=container_1399156864902_0003_01_000022
2014-05-03 23:18:52,816 INFO org.apache.hadoop.yarn.server.resourcemanager.scheduler.common.fica.FiCaSchedulerNode: Assigned container container_1399156864902_0003_01_000022 of capacity <memory:1024, vCores:1> on host nodec:54860, which currently has 2 containers, <memory:2048, vCores:2> used and <memory:6144, vCores:6> available
2014-05-03 23:18:52,817 INFO org.apache.hadoop.yarn.server.resourcemanager.scheduler.capacity.LeafQueue: assignedContainer application=application_1399156864902_0003 container=Container: [ContainerId: container_1399156864902_0003_01_000022, NodeId: nodec:54860, NodeHttpAddress: nodec:8042, Resource: <memory:1024, vCores:1>, Priority: 10, Token: Token { kind: ContainerToken, service: 10.0.0.245:54860 }, ] containerId=container_1399156864902_0003_01_000022 queue=default: capacity=1.0, absoluteCapacity=1.0, usedResources=<memory:7168, vCores:6>usedCapacity=0.21875, absoluteUsedCapacity=0.21875, numApps=1, numContainers=6 usedCapacity=0.21875 absoluteUsedCapacity=0.21875 used=<memory:7168, vCores:6> cluster=<memory:32768, vCores:32>
2014-05-03 23:18:52,817 INFO org.apache.hadoop.yarn.server.resourcemanager.scheduler.capacity.ParentQueue: Re-sorting assigned queue: root.default stats: default: capacity=1.0, absoluteCapacity=1.0, usedResources=<memory:8192, vCores:7>usedCapacity=0.25, absoluteUsedCapacity=0.25, numApps=1, numContainers=7
2014-05-03 23:18:52,817 INFO org.apache.hadoop.yarn.server.resourcemanager.scheduler.capacity.ParentQueue: assignedContainer queue=root usedCapacity=0.25 absoluteUsedCapacity=0.25 used=<memory:8192, vCores:7> cluster=<memory:32768, vCores:32>
2014-05-03 23:18:53,072 INFO org.apache.hadoop.yarn.server.resourcemanager.rmcontainer.RMContainerImpl: container_1399156864902_0003_01_000020 Container Transitioned from ALLOCATED to ACQUIRED
2014-05-03 23:18:53,072 INFO org.apache.hadoop.yarn.server.resourcemanager.rmcontainer.RMContainerImpl: container_1399156864902_0003_01_000021 Container Transitioned from ALLOCATED to ACQUIRED
2014-05-03 23:18:53,072 INFO org.apache.hadoop.yarn.server.resourcemanager.rmcontainer.RMContainerImpl: container_1399156864902_0003_01_000022 Container Transitioned from ALLOCATED to ACQUIRED
2014-05-03 23:18:53,766 INFO org.apache.hadoop.yarn.server.resourcemanager.rmcontainer.RMContainerImpl: container_1399156864902_0003_01_000020 Container Transitioned from ACQUIRED to RUNNING
2014-05-03 23:18:53,766 INFO org.apache.hadoop.yarn.server.resourcemanager.rmcontainer.RMContainerImpl: container_1399156864902_0003_01_000023 Container Transitioned from NEW to ALLOCATED
2014-05-03 23:18:53,767 INFO org.apache.hadoop.yarn.server.resourcemanager.RMAuditLogger: USER=ubuntu	OPERATION=AM Allocated Container	TARGET=SchedulerApp	RESULT=SUCCESS	APPID=application_1399156864902_0003	CONTAINERID=container_1399156864902_0003_01_000023
2014-05-03 23:18:53,767 INFO org.apache.hadoop.yarn.server.resourcemanager.scheduler.common.fica.FiCaSchedulerNode: Assigned container container_1399156864902_0003_01_000023 of capacity <memory:1024, vCores:1> on host nodeb:55487, which currently has 3 containers, <memory:3072, vCores:3> used and <memory:5120, vCores:5> available
2014-05-03 23:18:53,767 INFO org.apache.hadoop.yarn.server.resourcemanager.scheduler.capacity.LeafQueue: assignedContainer application=application_1399156864902_0003 container=Container: [ContainerId: container_1399156864902_0003_01_000023, NodeId: nodeb:55487, NodeHttpAddress: nodeb:8042, Resource: <memory:1024, vCores:1>, Priority: 10, Token: Token { kind: ContainerToken, service: 10.0.0.243:55487 }, ] containerId=container_1399156864902_0003_01_000023 queue=default: capacity=1.0, absoluteCapacity=1.0, usedResources=<memory:8192, vCores:7>usedCapacity=0.25, absoluteUsedCapacity=0.25, numApps=1, numContainers=7 usedCapacity=0.25 absoluteUsedCapacity=0.25 used=<memory:8192, vCores:7> cluster=<memory:32768, vCores:32>
2014-05-03 23:18:53,767 INFO org.apache.hadoop.yarn.server.resourcemanager.scheduler.capacity.ParentQueue: Re-sorting assigned queue: root.default stats: default: capacity=1.0, absoluteCapacity=1.0, usedResources=<memory:9216, vCores:8>usedCapacity=0.28125, absoluteUsedCapacity=0.28125, numApps=1, numContainers=8
2014-05-03 23:18:53,767 INFO org.apache.hadoop.yarn.server.resourcemanager.scheduler.capacity.ParentQueue: assignedContainer queue=root usedCapacity=0.28125 absoluteUsedCapacity=0.28125 used=<memory:9216, vCores:8> cluster=<memory:32768, vCores:32>
2014-05-03 23:18:53,788 INFO org.apache.hadoop.yarn.server.resourcemanager.rmcontainer.RMContainerImpl: container_1399156864902_0003_01_000021 Container Transitioned from ACQUIRED to RUNNING
2014-05-03 23:18:53,789 INFO org.apache.hadoop.yarn.server.resourcemanager.rmcontainer.RMContainerImpl: container_1399156864902_0003_01_000024 Container Transitioned from NEW to ALLOCATED
2014-05-03 23:18:53,789 INFO org.apache.hadoop.yarn.server.resourcemanager.RMAuditLogger: USER=ubuntu	OPERATION=AM Allocated Container	TARGET=SchedulerApp	RESULT=SUCCESS	APPID=application_1399156864902_0003	CONTAINERID=container_1399156864902_0003_01_000024
2014-05-03 23:18:53,789 INFO org.apache.hadoop.yarn.server.resourcemanager.scheduler.common.fica.FiCaSchedulerNode: Assigned container container_1399156864902_0003_01_000024 of capacity <memory:1024, vCores:1> on host nodea:56325, which currently has 3 containers, <memory:3072, vCores:3> used and <memory:5120, vCores:5> available
2014-05-03 23:18:53,789 INFO org.apache.hadoop.yarn.server.resourcemanager.scheduler.capacity.LeafQueue: assignedContainer application=application_1399156864902_0003 container=Container: [ContainerId: container_1399156864902_0003_01_000024, NodeId: nodea:56325, NodeHttpAddress: nodea:8042, Resource: <memory:1024, vCores:1>, Priority: 10, Token: Token { kind: ContainerToken, service: 10.0.0.182:56325 }, ] containerId=container_1399156864902_0003_01_000024 queue=default: capacity=1.0, absoluteCapacity=1.0, usedResources=<memory:9216, vCores:8>usedCapacity=0.28125, absoluteUsedCapacity=0.28125, numApps=1, numContainers=8 usedCapacity=0.28125 absoluteUsedCapacity=0.28125 used=<memory:9216, vCores:8> cluster=<memory:32768, vCores:32>
2014-05-03 23:18:53,790 INFO org.apache.hadoop.yarn.server.resourcemanager.scheduler.capacity.ParentQueue: Re-sorting assigned queue: root.default stats: default: capacity=1.0, absoluteCapacity=1.0, usedResources=<memory:10240, vCores:9>usedCapacity=0.3125, absoluteUsedCapacity=0.3125, numApps=1, numContainers=9
2014-05-03 23:18:53,790 INFO org.apache.hadoop.yarn.server.resourcemanager.scheduler.capacity.ParentQueue: assignedContainer queue=root usedCapacity=0.3125 absoluteUsedCapacity=0.3125 used=<memory:10240, vCores:9> cluster=<memory:32768, vCores:32>
2014-05-03 23:18:53,818 INFO org.apache.hadoop.yarn.server.resourcemanager.rmcontainer.RMContainerImpl: container_1399156864902_0003_01_000022 Container Transitioned from ACQUIRED to RUNNING
2014-05-03 23:18:53,819 INFO org.apache.hadoop.yarn.server.resourcemanager.rmcontainer.RMContainerImpl: container_1399156864902_0003_01_000025 Container Transitioned from NEW to ALLOCATED
2014-05-03 23:18:53,819 INFO org.apache.hadoop.yarn.server.resourcemanager.RMAuditLogger: USER=ubuntu	OPERATION=AM Allocated Container	TARGET=SchedulerApp	RESULT=SUCCESS	APPID=application_1399156864902_0003	CONTAINERID=container_1399156864902_0003_01_000025
2014-05-03 23:18:53,819 INFO org.apache.hadoop.yarn.server.resourcemanager.scheduler.common.fica.FiCaSchedulerNode: Assigned container container_1399156864902_0003_01_000025 of capacity <memory:1024, vCores:1> on host nodec:54860, which currently has 3 containers, <memory:3072, vCores:3> used and <memory:5120, vCores:5> available
2014-05-03 23:18:53,819 INFO org.apache.hadoop.yarn.server.resourcemanager.scheduler.capacity.LeafQueue: assignedContainer application=application_1399156864902_0003 container=Container: [ContainerId: container_1399156864902_0003_01_000025, NodeId: nodec:54860, NodeHttpAddress: nodec:8042, Resource: <memory:1024, vCores:1>, Priority: 10, Token: Token { kind: ContainerToken, service: 10.0.0.245:54860 }, ] containerId=container_1399156864902_0003_01_000025 queue=default: capacity=1.0, absoluteCapacity=1.0, usedResources=<memory:10240, vCores:9>usedCapacity=0.3125, absoluteUsedCapacity=0.3125, numApps=1, numContainers=9 usedCapacity=0.3125 absoluteUsedCapacity=0.3125 used=<memory:10240, vCores:9> cluster=<memory:32768, vCores:32>
2014-05-03 23:18:53,819 INFO org.apache.hadoop.yarn.server.resourcemanager.scheduler.capacity.ParentQueue: Re-sorting assigned queue: root.default stats: default: capacity=1.0, absoluteCapacity=1.0, usedResources=<memory:11264, vCores:10>usedCapacity=0.34375, absoluteUsedCapacity=0.34375, numApps=1, numContainers=10
2014-05-03 23:18:53,820 INFO org.apache.hadoop.yarn.server.resourcemanager.scheduler.capacity.ParentQueue: assignedContainer queue=root usedCapacity=0.34375 absoluteUsedCapacity=0.34375 used=<memory:11264, vCores:10> cluster=<memory:32768, vCores:32>
2014-05-03 23:18:54,077 INFO org.apache.hadoop.yarn.server.resourcemanager.rmcontainer.RMContainerImpl: container_1399156864902_0003_01_000023 Container Transitioned from ALLOCATED to ACQUIRED
2014-05-03 23:18:54,077 INFO org.apache.hadoop.yarn.server.resourcemanager.rmcontainer.RMContainerImpl: container_1399156864902_0003_01_000024 Container Transitioned from ALLOCATED to ACQUIRED
2014-05-03 23:18:54,078 INFO org.apache.hadoop.yarn.server.resourcemanager.rmcontainer.RMContainerImpl: container_1399156864902_0003_01_000025 Container Transitioned from ALLOCATED to ACQUIRED
2014-05-03 23:18:54,769 INFO org.apache.hadoop.yarn.server.resourcemanager.rmcontainer.RMContainerImpl: container_1399156864902_0003_01_000023 Container Transitioned from ACQUIRED to RUNNING
2014-05-03 23:18:54,769 INFO org.apache.hadoop.yarn.server.resourcemanager.rmcontainer.RMContainerImpl: container_1399156864902_0003_01_000026 Container Transitioned from NEW to ALLOCATED
2014-05-03 23:18:54,769 INFO org.apache.hadoop.yarn.server.resourcemanager.RMAuditLogger: USER=ubuntu	OPERATION=AM Allocated Container	TARGET=SchedulerApp	RESULT=SUCCESS	APPID=application_1399156864902_0003	CONTAINERID=container_1399156864902_0003_01_000026
2014-05-03 23:18:54,769 INFO org.apache.hadoop.yarn.server.resourcemanager.scheduler.common.fica.FiCaSchedulerNode: Assigned container container_1399156864902_0003_01_000026 of capacity <memory:1024, vCores:1> on host nodeb:55487, which currently has 4 containers, <memory:4096, vCores:4> used and <memory:4096, vCores:4> available
2014-05-03 23:18:54,770 INFO org.apache.hadoop.yarn.server.resourcemanager.scheduler.capacity.LeafQueue: assignedContainer application=application_1399156864902_0003 container=Container: [ContainerId: container_1399156864902_0003_01_000026, NodeId: nodeb:55487, NodeHttpAddress: nodeb:8042, Resource: <memory:1024, vCores:1>, Priority: 10, Token: Token { kind: ContainerToken, service: 10.0.0.243:55487 }, ] containerId=container_1399156864902_0003_01_000026 queue=default: capacity=1.0, absoluteCapacity=1.0, usedResources=<memory:11264, vCores:10>usedCapacity=0.34375, absoluteUsedCapacity=0.34375, numApps=1, numContainers=10 usedCapacity=0.34375 absoluteUsedCapacity=0.34375 used=<memory:11264, vCores:10> cluster=<memory:32768, vCores:32>
2014-05-03 23:18:54,770 INFO org.apache.hadoop.yarn.server.resourcemanager.scheduler.capacity.ParentQueue: Re-sorting assigned queue: root.default stats: default: capacity=1.0, absoluteCapacity=1.0, usedResources=<memory:12288, vCores:11>usedCapacity=0.375, absoluteUsedCapacity=0.375, numApps=1, numContainers=11
2014-05-03 23:18:54,770 INFO org.apache.hadoop.yarn.server.resourcemanager.scheduler.capacity.ParentQueue: assignedContainer queue=root usedCapacity=0.375 absoluteUsedCapacity=0.375 used=<memory:12288, vCores:11> cluster=<memory:32768, vCores:32>
2014-05-03 23:18:54,791 INFO org.apache.hadoop.yarn.server.resourcemanager.rmcontainer.RMContainerImpl: container_1399156864902_0003_01_000024 Container Transitioned from ACQUIRED to RUNNING
2014-05-03 23:18:54,792 INFO org.apache.hadoop.yarn.server.resourcemanager.rmcontainer.RMContainerImpl: container_1399156864902_0003_01_000027 Container Transitioned from NEW to ALLOCATED
2014-05-03 23:18:54,792 INFO org.apache.hadoop.yarn.server.resourcemanager.RMAuditLogger: USER=ubuntu	OPERATION=AM Allocated Container	TARGET=SchedulerApp	RESULT=SUCCESS	APPID=application_1399156864902_0003	CONTAINERID=container_1399156864902_0003_01_000027
2014-05-03 23:18:54,792 INFO org.apache.hadoop.yarn.server.resourcemanager.scheduler.common.fica.FiCaSchedulerNode: Assigned container container_1399156864902_0003_01_000027 of capacity <memory:1024, vCores:1> on host nodea:56325, which currently has 4 containers, <memory:4096, vCores:4> used and <memory:4096, vCores:4> available
2014-05-03 23:18:54,792 INFO org.apache.hadoop.yarn.server.resourcemanager.scheduler.capacity.LeafQueue: assignedContainer application=application_1399156864902_0003 container=Container: [ContainerId: container_1399156864902_0003_01_000027, NodeId: nodea:56325, NodeHttpAddress: nodea:8042, Resource: <memory:1024, vCores:1>, Priority: 10, Token: Token { kind: ContainerToken, service: 10.0.0.182:56325 }, ] containerId=container_1399156864902_0003_01_000027 queue=default: capacity=1.0, absoluteCapacity=1.0, usedResources=<memory:12288, vCores:11>usedCapacity=0.375, absoluteUsedCapacity=0.375, numApps=1, numContainers=11 usedCapacity=0.375 absoluteUsedCapacity=0.375 used=<memory:12288, vCores:11> cluster=<memory:32768, vCores:32>
2014-05-03 23:18:54,792 INFO org.apache.hadoop.yarn.server.resourcemanager.scheduler.capacity.ParentQueue: Re-sorting assigned queue: root.default stats: default: capacity=1.0, absoluteCapacity=1.0, usedResources=<memory:13312, vCores:12>usedCapacity=0.40625, absoluteUsedCapacity=0.40625, numApps=1, numContainers=12
2014-05-03 23:18:54,792 INFO org.apache.hadoop.yarn.server.resourcemanager.scheduler.capacity.ParentQueue: assignedContainer queue=root usedCapacity=0.40625 absoluteUsedCapacity=0.40625 used=<memory:13312, vCores:12> cluster=<memory:32768, vCores:32>
2014-05-03 23:18:55,082 INFO org.apache.hadoop.yarn.server.resourcemanager.rmcontainer.RMContainerImpl: container_1399156864902_0003_01_000025 Container Transitioned from ACQUIRED to RELEASED
2014-05-03 23:18:55,082 INFO org.apache.hadoop.yarn.server.resourcemanager.scheduler.common.fica.FiCaSchedulerApp: Completed container: container_1399156864902_0003_01_000025 in state: RELEASED event:RELEASED
2014-05-03 23:18:55,082 INFO org.apache.hadoop.yarn.server.resourcemanager.RMAuditLogger: USER=ubuntu	IP=10.0.0.244	OPERATION=AM Released Container	TARGET=SchedulerApp	RESULT=SUCCESS	APPID=application_1399156864902_0003	CONTAINERID=container_1399156864902_0003_01_000025
2014-05-03 23:18:55,082 INFO org.apache.hadoop.yarn.server.resourcemanager.scheduler.common.fica.FiCaSchedulerNode: Released container container_1399156864902_0003_01_000025 of capacity <memory:1024, vCores:1> on host nodec:54860, which currently has 2 containers, <memory:2048, vCores:2> used and <memory:6144, vCores:6> available, release resources=true
2014-05-03 23:18:55,082 INFO org.apache.hadoop.yarn.server.resourcemanager.scheduler.capacity.LeafQueue: default used=<memory:12288, vCores:11> numContainers=11 user=ubuntu user-resources=<memory:12288, vCores:11>
2014-05-03 23:18:55,083 INFO org.apache.hadoop.yarn.server.resourcemanager.scheduler.capacity.LeafQueue: completedContainer container=Container: [ContainerId: container_1399156864902_0003_01_000025, NodeId: nodec:54860, NodeHttpAddress: nodec:8042, Resource: <memory:1024, vCores:1>, Priority: 10, Token: Token { kind: ContainerToken, service: 10.0.0.245:54860 }, ] resource=<memory:1024, vCores:1> queue=default: capacity=1.0, absoluteCapacity=1.0, usedResources=<memory:12288, vCores:11>usedCapacity=0.375, absoluteUsedCapacity=0.375, numApps=1, numContainers=11 usedCapacity=0.375 absoluteUsedCapacity=0.375 used=<memory:12288, vCores:11> cluster=<memory:32768, vCores:32>
2014-05-03 23:18:55,083 INFO org.apache.hadoop.yarn.server.resourcemanager.scheduler.capacity.ParentQueue: completedContainer queue=root usedCapacity=0.375 absoluteUsedCapacity=0.375 used=<memory:12288, vCores:11> cluster=<memory:32768, vCores:32>
2014-05-03 23:18:55,083 INFO org.apache.hadoop.yarn.server.resourcemanager.scheduler.capacity.ParentQueue: Re-sorting completed queue: root.default stats: default: capacity=1.0, absoluteCapacity=1.0, usedResources=<memory:12288, vCores:11>usedCapacity=0.375, absoluteUsedCapacity=0.375, numApps=1, numContainers=11
2014-05-03 23:18:55,083 INFO org.apache.hadoop.yarn.server.resourcemanager.scheduler.capacity.CapacityScheduler: Application appattempt_1399156864902_0003_000001 released container container_1399156864902_0003_01_000025 on node: host: nodec:54860 #containers=2 available=6144 used=2048 with event: RELEASED
2014-05-03 23:18:55,083 INFO org.apache.hadoop.yarn.server.resourcemanager.scheduler.AppSchedulingInfo: checking for deactivate... 
2014-05-03 23:18:55,083 INFO org.apache.hadoop.yarn.server.resourcemanager.rmcontainer.RMContainerImpl: container_1399156864902_0003_01_000026 Container Transitioned from ALLOCATED to ACQUIRED
2014-05-03 23:18:55,084 INFO org.apache.hadoop.yarn.server.resourcemanager.rmcontainer.RMContainerImpl: container_1399156864902_0003_01_000027 Container Transitioned from ALLOCATED to ACQUIRED
2014-05-03 23:18:56,087 INFO org.apache.hadoop.yarn.server.resourcemanager.rmcontainer.RMContainerImpl: container_1399156864902_0003_01_000026 Container Transitioned from ACQUIRED to RELEASED
2014-05-03 23:18:56,088 INFO org.apache.hadoop.yarn.server.resourcemanager.scheduler.common.fica.FiCaSchedulerApp: Completed container: container_1399156864902_0003_01_000026 in state: RELEASED event:RELEASED
2014-05-03 23:18:56,088 INFO org.apache.hadoop.yarn.server.resourcemanager.RMAuditLogger: USER=ubuntu	IP=10.0.0.244	OPERATION=AM Released Container	TARGET=SchedulerApp	RESULT=SUCCESS	APPID=application_1399156864902_0003	CONTAINERID=container_1399156864902_0003_01_000026
2014-05-03 23:18:56,088 INFO org.apache.hadoop.yarn.server.resourcemanager.scheduler.common.fica.FiCaSchedulerNode: Released container container_1399156864902_0003_01_000026 of capacity <memory:1024, vCores:1> on host nodeb:55487, which currently has 3 containers, <memory:3072, vCores:3> used and <memory:5120, vCores:5> available, release resources=true
2014-05-03 23:18:56,088 INFO org.apache.hadoop.yarn.server.resourcemanager.scheduler.capacity.LeafQueue: default used=<memory:11264, vCores:10> numContainers=10 user=ubuntu user-resources=<memory:11264, vCores:10>
2014-05-03 23:18:56,088 INFO org.apache.hadoop.yarn.server.resourcemanager.scheduler.capacity.LeafQueue: completedContainer container=Container: [ContainerId: container_1399156864902_0003_01_000026, NodeId: nodeb:55487, NodeHttpAddress: nodeb:8042, Resource: <memory:1024, vCores:1>, Priority: 10, Token: Token { kind: ContainerToken, service: 10.0.0.243:55487 }, ] resource=<memory:1024, vCores:1> queue=default: capacity=1.0, absoluteCapacity=1.0, usedResources=<memory:11264, vCores:10>usedCapacity=0.34375, absoluteUsedCapacity=0.34375, numApps=1, numContainers=10 usedCapacity=0.34375 absoluteUsedCapacity=0.34375 used=<memory:11264, vCores:10> cluster=<memory:32768, vCores:32>
2014-05-03 23:18:56,088 INFO org.apache.hadoop.yarn.server.resourcemanager.scheduler.capacity.ParentQueue: completedContainer queue=root usedCapacity=0.34375 absoluteUsedCapacity=0.34375 used=<memory:11264, vCores:10> cluster=<memory:32768, vCores:32>
2014-05-03 23:18:56,088 INFO org.apache.hadoop.yarn.server.resourcemanager.scheduler.capacity.ParentQueue: Re-sorting completed queue: root.default stats: default: capacity=1.0, absoluteCapacity=1.0, usedResources=<memory:11264, vCores:10>usedCapacity=0.34375, absoluteUsedCapacity=0.34375, numApps=1, numContainers=10
2014-05-03 23:18:56,088 INFO org.apache.hadoop.yarn.server.resourcemanager.scheduler.capacity.CapacityScheduler: Application appattempt_1399156864902_0003_000001 released container container_1399156864902_0003_01_000026 on node: host: nodeb:55487 #containers=3 available=5120 used=3072 with event: RELEASED
2014-05-03 23:18:56,089 INFO org.apache.hadoop.yarn.server.resourcemanager.rmcontainer.RMContainerImpl: container_1399156864902_0003_01_000027 Container Transitioned from ACQUIRED to RELEASED
2014-05-03 23:18:56,089 INFO org.apache.hadoop.yarn.server.resourcemanager.scheduler.common.fica.FiCaSchedulerApp: Completed container: container_1399156864902_0003_01_000027 in state: RELEASED event:RELEASED
2014-05-03 23:18:56,089 INFO org.apache.hadoop.yarn.server.resourcemanager.RMAuditLogger: USER=ubuntu	IP=10.0.0.244	OPERATION=AM Released Container	TARGET=SchedulerApp	RESULT=SUCCESS	APPID=application_1399156864902_0003	CONTAINERID=container_1399156864902_0003_01_000027
2014-05-03 23:18:56,089 INFO org.apache.hadoop.yarn.server.resourcemanager.scheduler.common.fica.FiCaSchedulerNode: Released container container_1399156864902_0003_01_000027 of capacity <memory:1024, vCores:1> on host nodea:56325, which currently has 3 containers, <memory:3072, vCores:3> used and <memory:5120, vCores:5> available, release resources=true
2014-05-03 23:18:56,091 INFO org.apache.hadoop.yarn.server.resourcemanager.scheduler.capacity.LeafQueue: default used=<memory:10240, vCores:9> numContainers=9 user=ubuntu user-resources=<memory:10240, vCores:9>
2014-05-03 23:18:56,091 INFO org.apache.hadoop.yarn.server.resourcemanager.scheduler.capacity.LeafQueue: completedContainer container=Container: [ContainerId: container_1399156864902_0003_01_000027, NodeId: nodea:56325, NodeHttpAddress: nodea:8042, Resource: <memory:1024, vCores:1>, Priority: 10, Token: Token { kind: ContainerToken, service: 10.0.0.182:56325 }, ] resource=<memory:1024, vCores:1> queue=default: capacity=1.0, absoluteCapacity=1.0, usedResources=<memory:10240, vCores:9>usedCapacity=0.3125, absoluteUsedCapacity=0.3125, numApps=1, numContainers=9 usedCapacity=0.3125 absoluteUsedCapacity=0.3125 used=<memory:10240, vCores:9> cluster=<memory:32768, vCores:32>
2014-05-03 23:18:56,092 INFO org.apache.hadoop.yarn.server.resourcemanager.scheduler.capacity.ParentQueue: completedContainer queue=root usedCapacity=0.3125 absoluteUsedCapacity=0.3125 used=<memory:10240, vCores:9> cluster=<memory:32768, vCores:32>
2014-05-03 23:18:56,092 INFO org.apache.hadoop.yarn.server.resourcemanager.scheduler.capacity.ParentQueue: Re-sorting completed queue: root.default stats: default: capacity=1.0, absoluteCapacity=1.0, usedResources=<memory:10240, vCores:9>usedCapacity=0.3125, absoluteUsedCapacity=0.3125, numApps=1, numContainers=9
2014-05-03 23:18:56,092 INFO org.apache.hadoop.yarn.server.resourcemanager.scheduler.capacity.CapacityScheduler: Application appattempt_1399156864902_0003_000001 released container container_1399156864902_0003_01_000027 on node: host: nodea:56325 #containers=3 available=5120 used=3072 with event: RELEASED
2014-05-03 23:20:58,377 INFO org.apache.hadoop.yarn.server.resourcemanager.rmcontainer.RMContainerImpl: container_1399156864902_0003_01_000019 Container Transitioned from RUNNING to COMPLETED
2014-05-03 23:20:58,377 INFO org.apache.hadoop.yarn.server.resourcemanager.scheduler.common.fica.FiCaSchedulerApp: Completed container: container_1399156864902_0003_01_000019 in state: COMPLETED event:FINISHED
2014-05-03 23:20:58,377 INFO org.apache.hadoop.yarn.server.resourcemanager.RMAuditLogger: USER=ubuntu	OPERATION=AM Released Container	TARGET=SchedulerApp	RESULT=SUCCESS	APPID=application_1399156864902_0003	CONTAINERID=container_1399156864902_0003_01_000019
2014-05-03 23:20:58,377 INFO org.apache.hadoop.yarn.server.resourcemanager.scheduler.common.fica.FiCaSchedulerNode: Released container container_1399156864902_0003_01_000019 of capacity <memory:1024, vCores:1> on host nodec:54860, which currently has 1 containers, <memory:1024, vCores:1> used and <memory:7168, vCores:7> available, release resources=true
2014-05-03 23:20:58,378 INFO org.apache.hadoop.yarn.server.resourcemanager.scheduler.capacity.LeafQueue: default used=<memory:9216, vCores:8> numContainers=8 user=ubuntu user-resources=<memory:9216, vCores:8>
2014-05-03 23:20:58,378 INFO org.apache.hadoop.yarn.server.resourcemanager.scheduler.capacity.LeafQueue: completedContainer container=Container: [ContainerId: container_1399156864902_0003_01_000019, NodeId: nodec:54860, NodeHttpAddress: nodec:8042, Resource: <memory:1024, vCores:1>, Priority: 10, Token: Token { kind: ContainerToken, service: 10.0.0.245:54860 }, ] resource=<memory:1024, vCores:1> queue=default: capacity=1.0, absoluteCapacity=1.0, usedResources=<memory:9216, vCores:8>usedCapacity=0.28125, absoluteUsedCapacity=0.28125, numApps=1, numContainers=8 usedCapacity=0.28125 absoluteUsedCapacity=0.28125 used=<memory:9216, vCores:8> cluster=<memory:32768, vCores:32>
2014-05-03 23:20:58,378 INFO org.apache.hadoop.yarn.server.resourcemanager.scheduler.capacity.ParentQueue: completedContainer queue=root usedCapacity=0.28125 absoluteUsedCapacity=0.28125 used=<memory:9216, vCores:8> cluster=<memory:32768, vCores:32>
2014-05-03 23:20:58,378 INFO org.apache.hadoop.yarn.server.resourcemanager.scheduler.capacity.ParentQueue: Re-sorting completed queue: root.default stats: default: capacity=1.0, absoluteCapacity=1.0, usedResources=<memory:9216, vCores:8>usedCapacity=0.28125, absoluteUsedCapacity=0.28125, numApps=1, numContainers=8
2014-05-03 23:20:58,378 INFO org.apache.hadoop.yarn.server.resourcemanager.scheduler.capacity.CapacityScheduler: Application appattempt_1399156864902_0003_000001 released container container_1399156864902_0003_01_000019 on node: host: nodec:54860 #containers=1 available=7168 used=1024 with event: FINISHED
2014-05-03 23:21:00,280 INFO org.apache.hadoop.yarn.server.resourcemanager.rmcontainer.RMContainerImpl: container_1399156864902_0003_01_000022 Container Transitioned from RUNNING to COMPLETED
2014-05-03 23:21:00,280 INFO org.apache.hadoop.yarn.server.resourcemanager.scheduler.common.fica.FiCaSchedulerApp: Completed container: container_1399156864902_0003_01_000022 in state: COMPLETED event:FINISHED
2014-05-03 23:21:00,280 INFO org.apache.hadoop.yarn.server.resourcemanager.RMAuditLogger: USER=ubuntu	OPERATION=AM Released Container	TARGET=SchedulerApp	RESULT=SUCCESS	APPID=application_1399156864902_0003	CONTAINERID=container_1399156864902_0003_01_000022
2014-05-03 23:21:00,280 INFO org.apache.hadoop.yarn.server.resourcemanager.scheduler.common.fica.FiCaSchedulerNode: Released container container_1399156864902_0003_01_000022 of capacity <memory:1024, vCores:1> on host nodec:54860, which currently has 0 containers, <memory:0, vCores:0> used and <memory:8192, vCores:8> available, release resources=true
2014-05-03 23:21:00,280 INFO org.apache.hadoop.yarn.server.resourcemanager.scheduler.capacity.LeafQueue: default used=<memory:8192, vCores:7> numContainers=7 user=ubuntu user-resources=<memory:8192, vCores:7>
2014-05-03 23:21:00,281 INFO org.apache.hadoop.yarn.server.resourcemanager.scheduler.capacity.LeafQueue: completedContainer container=Container: [ContainerId: container_1399156864902_0003_01_000022, NodeId: nodec:54860, NodeHttpAddress: nodec:8042, Resource: <memory:1024, vCores:1>, Priority: 10, Token: Token { kind: ContainerToken, service: 10.0.0.245:54860 }, ] resource=<memory:1024, vCores:1> queue=default: capacity=1.0, absoluteCapacity=1.0, usedResources=<memory:8192, vCores:7>usedCapacity=0.25, absoluteUsedCapacity=0.25, numApps=1, numContainers=7 usedCapacity=0.25 absoluteUsedCapacity=0.25 used=<memory:8192, vCores:7> cluster=<memory:32768, vCores:32>
2014-05-03 23:21:00,281 INFO org.apache.hadoop.yarn.server.resourcemanager.scheduler.capacity.ParentQueue: completedContainer queue=root usedCapacity=0.25 absoluteUsedCapacity=0.25 used=<memory:8192, vCores:7> cluster=<memory:32768, vCores:32>
2014-05-03 23:21:00,281 INFO org.apache.hadoop.yarn.server.resourcemanager.scheduler.capacity.ParentQueue: Re-sorting completed queue: root.default stats: default: capacity=1.0, absoluteCapacity=1.0, usedResources=<memory:8192, vCores:7>usedCapacity=0.25, absoluteUsedCapacity=0.25, numApps=1, numContainers=7
2014-05-03 23:21:00,281 INFO org.apache.hadoop.yarn.server.resourcemanager.scheduler.capacity.CapacityScheduler: Application appattempt_1399156864902_0003_000001 released container container_1399156864902_0003_01_000022 on node: host: nodec:54860 #containers=0 available=8192 used=0 with event: FINISHED
2014-05-03 23:21:01,499 INFO org.apache.hadoop.yarn.server.resourcemanager.rmcontainer.RMContainerImpl: container_1399156864902_0003_01_000017 Container Transitioned from RUNNING to COMPLETED
2014-05-03 23:21:01,499 INFO org.apache.hadoop.yarn.server.resourcemanager.scheduler.common.fica.FiCaSchedulerApp: Completed container: container_1399156864902_0003_01_000017 in state: COMPLETED event:FINISHED
2014-05-03 23:21:01,500 INFO org.apache.hadoop.yarn.server.resourcemanager.RMAuditLogger: USER=ubuntu	OPERATION=AM Released Container	TARGET=SchedulerApp	RESULT=SUCCESS	APPID=application_1399156864902_0003	CONTAINERID=container_1399156864902_0003_01_000017
2014-05-03 23:21:01,500 INFO org.apache.hadoop.yarn.server.resourcemanager.scheduler.common.fica.FiCaSchedulerNode: Released container container_1399156864902_0003_01_000017 of capacity <memory:1024, vCores:1> on host nodeb:55487, which currently has 2 containers, <memory:2048, vCores:2> used and <memory:6144, vCores:6> available, release resources=true
2014-05-03 23:21:01,500 INFO org.apache.hadoop.yarn.server.resourcemanager.scheduler.capacity.LeafQueue: default used=<memory:7168, vCores:6> numContainers=6 user=ubuntu user-resources=<memory:7168, vCores:6>
2014-05-03 23:21:01,500 INFO org.apache.hadoop.yarn.server.resourcemanager.scheduler.capacity.LeafQueue: completedContainer container=Container: [ContainerId: container_1399156864902_0003_01_000017, NodeId: nodeb:55487, NodeHttpAddress: nodeb:8042, Resource: <memory:1024, vCores:1>, Priority: 10, Token: Token { kind: ContainerToken, service: 10.0.0.243:55487 }, ] resource=<memory:1024, vCores:1> queue=default: capacity=1.0, absoluteCapacity=1.0, usedResources=<memory:7168, vCores:6>usedCapacity=0.21875, absoluteUsedCapacity=0.21875, numApps=1, numContainers=6 usedCapacity=0.21875 absoluteUsedCapacity=0.21875 used=<memory:7168, vCores:6> cluster=<memory:32768, vCores:32>
2014-05-03 23:21:01,500 INFO org.apache.hadoop.yarn.server.resourcemanager.scheduler.capacity.ParentQueue: completedContainer queue=root usedCapacity=0.21875 absoluteUsedCapacity=0.21875 used=<memory:7168, vCores:6> cluster=<memory:32768, vCores:32>
2014-05-03 23:21:01,500 INFO org.apache.hadoop.yarn.server.resourcemanager.scheduler.capacity.ParentQueue: Re-sorting completed queue: root.default stats: default: capacity=1.0, absoluteCapacity=1.0, usedResources=<memory:7168, vCores:6>usedCapacity=0.21875, absoluteUsedCapacity=0.21875, numApps=1, numContainers=6
2014-05-03 23:21:01,500 INFO org.apache.hadoop.yarn.server.resourcemanager.scheduler.capacity.CapacityScheduler: Application appattempt_1399156864902_0003_000001 released container container_1399156864902_0003_01_000017 on node: host: nodeb:55487 #containers=2 available=6144 used=2048 with event: FINISHED
2014-05-03 23:21:02,162 INFO org.apache.hadoop.yarn.server.resourcemanager.rmcontainer.RMContainerImpl: container_1399156864902_0003_01_000018 Container Transitioned from RUNNING to COMPLETED
2014-05-03 23:21:02,162 INFO org.apache.hadoop.yarn.server.resourcemanager.scheduler.common.fica.FiCaSchedulerApp: Completed container: container_1399156864902_0003_01_000018 in state: COMPLETED event:FINISHED
2014-05-03 23:21:02,162 INFO org.apache.hadoop.yarn.server.resourcemanager.RMAuditLogger: USER=ubuntu	OPERATION=AM Released Container	TARGET=SchedulerApp	RESULT=SUCCESS	APPID=application_1399156864902_0003	CONTAINERID=container_1399156864902_0003_01_000018
2014-05-03 23:21:02,162 INFO org.apache.hadoop.yarn.server.resourcemanager.scheduler.common.fica.FiCaSchedulerNode: Released container container_1399156864902_0003_01_000018 of capacity <memory:1024, vCores:1> on host nodea:56325, which currently has 2 containers, <memory:2048, vCores:2> used and <memory:6144, vCores:6> available, release resources=true
2014-05-03 23:21:02,162 INFO org.apache.hadoop.yarn.server.resourcemanager.scheduler.capacity.LeafQueue: default used=<memory:6144, vCores:5> numContainers=5 user=ubuntu user-resources=<memory:6144, vCores:5>
2014-05-03 23:21:02,162 INFO org.apache.hadoop.yarn.server.resourcemanager.scheduler.capacity.LeafQueue: completedContainer container=Container: [ContainerId: container_1399156864902_0003_01_000018, NodeId: nodea:56325, NodeHttpAddress: nodea:8042, Resource: <memory:1024, vCores:1>, Priority: 10, Token: Token { kind: ContainerToken, service: 10.0.0.182:56325 }, ] resource=<memory:1024, vCores:1> queue=default: capacity=1.0, absoluteCapacity=1.0, usedResources=<memory:6144, vCores:5>usedCapacity=0.1875, absoluteUsedCapacity=0.1875, numApps=1, numContainers=5 usedCapacity=0.1875 absoluteUsedCapacity=0.1875 used=<memory:6144, vCores:5> cluster=<memory:32768, vCores:32>
2014-05-03 23:21:02,163 INFO org.apache.hadoop.yarn.server.resourcemanager.scheduler.capacity.ParentQueue: completedContainer queue=root usedCapacity=0.1875 absoluteUsedCapacity=0.1875 used=<memory:6144, vCores:5> cluster=<memory:32768, vCores:32>
2014-05-03 23:21:02,163 INFO org.apache.hadoop.yarn.server.resourcemanager.scheduler.capacity.ParentQueue: Re-sorting completed queue: root.default stats: default: capacity=1.0, absoluteCapacity=1.0, usedResources=<memory:6144, vCores:5>usedCapacity=0.1875, absoluteUsedCapacity=0.1875, numApps=1, numContainers=5
2014-05-03 23:21:02,163 INFO org.apache.hadoop.yarn.server.resourcemanager.scheduler.capacity.CapacityScheduler: Application appattempt_1399156864902_0003_000001 released container container_1399156864902_0003_01_000018 on node: host: nodea:56325 #containers=2 available=6144 used=2048 with event: FINISHED
2014-05-03 23:21:02,346 INFO org.apache.hadoop.yarn.server.resourcemanager.rmcontainer.RMContainerImpl: container_1399156864902_0003_01_000020 Container Transitioned from RUNNING to COMPLETED
2014-05-03 23:21:02,346 INFO org.apache.hadoop.yarn.server.resourcemanager.scheduler.common.fica.FiCaSchedulerApp: Completed container: container_1399156864902_0003_01_000020 in state: COMPLETED event:FINISHED
2014-05-03 23:21:02,346 INFO org.apache.hadoop.yarn.server.resourcemanager.RMAuditLogger: USER=ubuntu	OPERATION=AM Released Container	TARGET=SchedulerApp	RESULT=SUCCESS	APPID=application_1399156864902_0003	CONTAINERID=container_1399156864902_0003_01_000020
2014-05-03 23:21:02,346 INFO org.apache.hadoop.yarn.server.resourcemanager.scheduler.common.fica.FiCaSchedulerNode: Released container container_1399156864902_0003_01_000020 of capacity <memory:1024, vCores:1> on host nodeb:55487, which currently has 1 containers, <memory:1024, vCores:1> used and <memory:7168, vCores:7> available, release resources=true
2014-05-03 23:21:02,346 INFO org.apache.hadoop.yarn.server.resourcemanager.scheduler.capacity.LeafQueue: default used=<memory:5120, vCores:4> numContainers=4 user=ubuntu user-resources=<memory:5120, vCores:4>
2014-05-03 23:21:02,347 INFO org.apache.hadoop.yarn.server.resourcemanager.scheduler.capacity.LeafQueue: completedContainer container=Container: [ContainerId: container_1399156864902_0003_01_000020, NodeId: nodeb:55487, NodeHttpAddress: nodeb:8042, Resource: <memory:1024, vCores:1>, Priority: 10, Token: Token { kind: ContainerToken, service: 10.0.0.243:55487 }, ] resource=<memory:1024, vCores:1> queue=default: capacity=1.0, absoluteCapacity=1.0, usedResources=<memory:5120, vCores:4>usedCapacity=0.15625, absoluteUsedCapacity=0.15625, numApps=1, numContainers=4 usedCapacity=0.15625 absoluteUsedCapacity=0.15625 used=<memory:5120, vCores:4> cluster=<memory:32768, vCores:32>
2014-05-03 23:21:02,347 INFO org.apache.hadoop.yarn.server.resourcemanager.scheduler.capacity.ParentQueue: completedContainer queue=root usedCapacity=0.15625 absoluteUsedCapacity=0.15625 used=<memory:5120, vCores:4> cluster=<memory:32768, vCores:32>
2014-05-03 23:21:02,347 INFO org.apache.hadoop.yarn.server.resourcemanager.scheduler.capacity.ParentQueue: Re-sorting completed queue: root.default stats: default: capacity=1.0, absoluteCapacity=1.0, usedResources=<memory:5120, vCores:4>usedCapacity=0.15625, absoluteUsedCapacity=0.15625, numApps=1, numContainers=4
2014-05-03 23:21:02,347 INFO org.apache.hadoop.yarn.server.resourcemanager.scheduler.capacity.CapacityScheduler: Application appattempt_1399156864902_0003_000001 released container container_1399156864902_0003_01_000020 on node: host: nodeb:55487 #containers=1 available=7168 used=1024 with event: FINISHED
2014-05-03 23:21:03,165 INFO org.apache.hadoop.yarn.server.resourcemanager.rmcontainer.RMContainerImpl: container_1399156864902_0003_01_000021 Container Transitioned from RUNNING to COMPLETED
2014-05-03 23:21:03,165 INFO org.apache.hadoop.yarn.server.resourcemanager.scheduler.common.fica.FiCaSchedulerApp: Completed container: container_1399156864902_0003_01_000021 in state: COMPLETED event:FINISHED
2014-05-03 23:21:03,165 INFO org.apache.hadoop.yarn.server.resourcemanager.RMAuditLogger: USER=ubuntu	OPERATION=AM Released Container	TARGET=SchedulerApp	RESULT=SUCCESS	APPID=application_1399156864902_0003	CONTAINERID=container_1399156864902_0003_01_000021
2014-05-03 23:21:03,165 INFO org.apache.hadoop.yarn.server.resourcemanager.scheduler.common.fica.FiCaSchedulerNode: Released container container_1399156864902_0003_01_000021 of capacity <memory:1024, vCores:1> on host nodea:56325, which currently has 1 containers, <memory:1024, vCores:1> used and <memory:7168, vCores:7> available, release resources=true
2014-05-03 23:21:03,166 INFO org.apache.hadoop.yarn.server.resourcemanager.scheduler.capacity.LeafQueue: default used=<memory:4096, vCores:3> numContainers=3 user=ubuntu user-resources=<memory:4096, vCores:3>
2014-05-03 23:21:03,166 INFO org.apache.hadoop.yarn.server.resourcemanager.scheduler.capacity.LeafQueue: completedContainer container=Container: [ContainerId: container_1399156864902_0003_01_000021, NodeId: nodea:56325, NodeHttpAddress: nodea:8042, Resource: <memory:1024, vCores:1>, Priority: 10, Token: Token { kind: ContainerToken, service: 10.0.0.182:56325 }, ] resource=<memory:1024, vCores:1> queue=default: capacity=1.0, absoluteCapacity=1.0, usedResources=<memory:4096, vCores:3>usedCapacity=0.125, absoluteUsedCapacity=0.125, numApps=1, numContainers=3 usedCapacity=0.125 absoluteUsedCapacity=0.125 used=<memory:4096, vCores:3> cluster=<memory:32768, vCores:32>
2014-05-03 23:21:03,166 INFO org.apache.hadoop.yarn.server.resourcemanager.scheduler.capacity.ParentQueue: completedContainer queue=root usedCapacity=0.125 absoluteUsedCapacity=0.125 used=<memory:4096, vCores:3> cluster=<memory:32768, vCores:32>
2014-05-03 23:21:03,166 INFO org.apache.hadoop.yarn.server.resourcemanager.scheduler.capacity.ParentQueue: Re-sorting completed queue: root.default stats: default: capacity=1.0, absoluteCapacity=1.0, usedResources=<memory:4096, vCores:3>usedCapacity=0.125, absoluteUsedCapacity=0.125, numApps=1, numContainers=3
2014-05-03 23:21:03,166 INFO org.apache.hadoop.yarn.server.resourcemanager.scheduler.capacity.CapacityScheduler: Application appattempt_1399156864902_0003_000001 released container container_1399156864902_0003_01_000021 on node: host: nodea:56325 #containers=1 available=7168 used=1024 with event: FINISHED
2014-05-03 23:21:03,348 INFO org.apache.hadoop.yarn.server.resourcemanager.rmcontainer.RMContainerImpl: container_1399156864902_0003_01_000023 Container Transitioned from RUNNING to COMPLETED
2014-05-03 23:21:03,348 INFO org.apache.hadoop.yarn.server.resourcemanager.scheduler.common.fica.FiCaSchedulerApp: Completed container: container_1399156864902_0003_01_000023 in state: COMPLETED event:FINISHED
2014-05-03 23:21:03,348 INFO org.apache.hadoop.yarn.server.resourcemanager.RMAuditLogger: USER=ubuntu	OPERATION=AM Released Container	TARGET=SchedulerApp	RESULT=SUCCESS	APPID=application_1399156864902_0003	CONTAINERID=container_1399156864902_0003_01_000023
2014-05-03 23:21:03,348 INFO org.apache.hadoop.yarn.server.resourcemanager.scheduler.common.fica.FiCaSchedulerNode: Released container container_1399156864902_0003_01_000023 of capacity <memory:1024, vCores:1> on host nodeb:55487, which currently has 0 containers, <memory:0, vCores:0> used and <memory:8192, vCores:8> available, release resources=true
2014-05-03 23:21:03,348 INFO org.apache.hadoop.yarn.server.resourcemanager.scheduler.capacity.LeafQueue: default used=<memory:3072, vCores:2> numContainers=2 user=ubuntu user-resources=<memory:3072, vCores:2>
2014-05-03 23:21:03,349 INFO org.apache.hadoop.yarn.server.resourcemanager.scheduler.capacity.LeafQueue: completedContainer container=Container: [ContainerId: container_1399156864902_0003_01_000023, NodeId: nodeb:55487, NodeHttpAddress: nodeb:8042, Resource: <memory:1024, vCores:1>, Priority: 10, Token: Token { kind: ContainerToken, service: 10.0.0.243:55487 }, ] resource=<memory:1024, vCores:1> queue=default: capacity=1.0, absoluteCapacity=1.0, usedResources=<memory:3072, vCores:2>usedCapacity=0.09375, absoluteUsedCapacity=0.09375, numApps=1, numContainers=2 usedCapacity=0.09375 absoluteUsedCapacity=0.09375 used=<memory:3072, vCores:2> cluster=<memory:32768, vCores:32>
2014-05-03 23:21:03,349 INFO org.apache.hadoop.yarn.server.resourcemanager.scheduler.capacity.ParentQueue: completedContainer queue=root usedCapacity=0.09375 absoluteUsedCapacity=0.09375 used=<memory:3072, vCores:2> cluster=<memory:32768, vCores:32>
2014-05-03 23:21:03,349 INFO org.apache.hadoop.yarn.server.resourcemanager.scheduler.capacity.ParentQueue: Re-sorting completed queue: root.default stats: default: capacity=1.0, absoluteCapacity=1.0, usedResources=<memory:3072, vCores:2>usedCapacity=0.09375, absoluteUsedCapacity=0.09375, numApps=1, numContainers=2
2014-05-03 23:21:03,349 INFO org.apache.hadoop.yarn.server.resourcemanager.scheduler.capacity.CapacityScheduler: Application appattempt_1399156864902_0003_000001 released container container_1399156864902_0003_01_000023 on node: host: nodeb:55487 #containers=0 available=8192 used=0 with event: FINISHED
2014-05-03 23:21:03,602 INFO org.apache.hadoop.yarn.server.resourcemanager.rmapp.attempt.RMAppAttemptImpl: appattempt_1399156864902_0003_000001 State change from RUNNING to FINISHING
2014-05-03 23:21:03,602 INFO org.apache.hadoop.yarn.server.resourcemanager.rmapp.RMAppImpl: Removing application with id application_1399156864902_0003
2014-05-03 23:21:03,602 INFO org.apache.hadoop.yarn.server.resourcemanager.rmapp.RMAppImpl: application_1399156864902_0003 State change from RUNNING to REMOVING
2014-05-03 23:21:03,603 INFO org.apache.hadoop.yarn.server.resourcemanager.recovery.RMStateStore: Removing info for app: application_1399156864902_0003
2014-05-03 23:21:03,603 INFO org.apache.hadoop.yarn.server.resourcemanager.rmapp.RMAppImpl: application_1399156864902_0003 State change from REMOVING to FINISHING
2014-05-03 23:21:04,455 INFO org.apache.hadoop.yarn.server.resourcemanager.rmcontainer.RMContainerImpl: container_1399156864902_0003_01_000024 Container Transitioned from RUNNING to COMPLETED
2014-05-03 23:21:04,455 INFO org.apache.hadoop.yarn.server.resourcemanager.scheduler.common.fica.FiCaSchedulerApp: Completed container: container_1399156864902_0003_01_000024 in state: COMPLETED event:FINISHED
2014-05-03 23:21:04,455 INFO org.apache.hadoop.yarn.server.resourcemanager.RMAuditLogger: USER=ubuntu	OPERATION=AM Released Container	TARGET=SchedulerApp	RESULT=SUCCESS	APPID=application_1399156864902_0003	CONTAINERID=container_1399156864902_0003_01_000024
2014-05-03 23:21:04,455 INFO org.apache.hadoop.yarn.server.resourcemanager.scheduler.common.fica.FiCaSchedulerNode: Released container container_1399156864902_0003_01_000024 of capacity <memory:1024, vCores:1> on host nodea:56325, which currently has 0 containers, <memory:0, vCores:0> used and <memory:8192, vCores:8> available, release resources=true
2014-05-03 23:21:04,455 INFO org.apache.hadoop.yarn.server.resourcemanager.scheduler.capacity.LeafQueue: default used=<memory:2048, vCores:1> numContainers=1 user=ubuntu user-resources=<memory:2048, vCores:1>
2014-05-03 23:21:04,455 INFO org.apache.hadoop.yarn.server.resourcemanager.scheduler.capacity.LeafQueue: completedContainer container=Container: [ContainerId: container_1399156864902_0003_01_000024, NodeId: nodea:56325, NodeHttpAddress: nodea:8042, Resource: <memory:1024, vCores:1>, Priority: 10, Token: Token { kind: ContainerToken, service: 10.0.0.182:56325 }, ] resource=<memory:1024, vCores:1> queue=default: capacity=1.0, absoluteCapacity=1.0, usedResources=<memory:2048, vCores:1>usedCapacity=0.0625, absoluteUsedCapacity=0.0625, numApps=1, numContainers=1 usedCapacity=0.0625 absoluteUsedCapacity=0.0625 used=<memory:2048, vCores:1> cluster=<memory:32768, vCores:32>
2014-05-03 23:21:04,455 INFO org.apache.hadoop.yarn.server.resourcemanager.scheduler.capacity.ParentQueue: completedContainer queue=root usedCapacity=0.0625 absoluteUsedCapacity=0.0625 used=<memory:2048, vCores:1> cluster=<memory:32768, vCores:32>
2014-05-03 23:21:04,455 INFO org.apache.hadoop.yarn.server.resourcemanager.scheduler.capacity.ParentQueue: Re-sorting completed queue: root.default stats: default: capacity=1.0, absoluteCapacity=1.0, usedResources=<memory:2048, vCores:1>usedCapacity=0.0625, absoluteUsedCapacity=0.0625, numApps=1, numContainers=1
2014-05-03 23:21:04,455 INFO org.apache.hadoop.yarn.server.resourcemanager.scheduler.capacity.CapacityScheduler: Application appattempt_1399156864902_0003_000001 released container container_1399156864902_0003_01_000024 on node: host: nodea:56325 #containers=0 available=8192 used=0 with event: FINISHED
2014-05-03 23:21:10,232 INFO org.apache.hadoop.yarn.server.resourcemanager.rmcontainer.RMContainerImpl: container_1399156864902_0003_01_000001 Container Transitioned from RUNNING to COMPLETED
2014-05-03 23:21:10,232 INFO org.apache.hadoop.yarn.server.resourcemanager.ApplicationMasterService: Unregistering app attempt : appattempt_1399156864902_0003_000001
2014-05-03 23:21:10,232 INFO org.apache.hadoop.yarn.server.resourcemanager.scheduler.common.fica.FiCaSchedulerApp: Completed container: container_1399156864902_0003_01_000001 in state: COMPLETED event:FINISHED
2014-05-03 23:21:10,232 INFO org.apache.hadoop.yarn.server.resourcemanager.rmapp.attempt.RMAppAttemptImpl: appattempt_1399156864902_0003_000001 State change from FINISHING to FINISHED
2014-05-03 23:21:10,232 INFO org.apache.hadoop.yarn.server.resourcemanager.RMAuditLogger: USER=ubuntu	OPERATION=AM Released Container	TARGET=SchedulerApp	RESULT=SUCCESS	APPID=application_1399156864902_0003	CONTAINERID=container_1399156864902_0003_01_000001
2014-05-03 23:21:10,233 INFO org.apache.hadoop.yarn.server.resourcemanager.rmapp.RMAppImpl: application_1399156864902_0003 State change from FINISHING to FINISHED
2014-05-03 23:21:10,233 INFO org.apache.hadoop.yarn.server.resourcemanager.scheduler.common.fica.FiCaSchedulerNode: Released container container_1399156864902_0003_01_000001 of capacity <memory:2048, vCores:1> on host noded:50846, which currently has 0 containers, <memory:0, vCores:0> used and <memory:8192, vCores:8> available, release resources=true
2014-05-03 23:21:10,233 INFO org.apache.hadoop.yarn.server.resourcemanager.scheduler.capacity.LeafQueue: default used=<memory:0, vCores:0> numContainers=0 user=ubuntu user-resources=<memory:0, vCores:0>
2014-05-03 23:21:10,233 INFO org.apache.hadoop.yarn.server.resourcemanager.scheduler.capacity.LeafQueue: completedContainer container=Container: [ContainerId: container_1399156864902_0003_01_000001, NodeId: noded:50846, NodeHttpAddress: noded:8042, Resource: <memory:2048, vCores:1>, Priority: 0, Token: Token { kind: ContainerToken, service: 10.0.0.244:50846 }, ] resource=<memory:2048, vCores:1> queue=default: capacity=1.0, absoluteCapacity=1.0, usedResources=<memory:0, vCores:0>usedCapacity=0.0, absoluteUsedCapacity=0.0, numApps=1, numContainers=0 usedCapacity=0.0 absoluteUsedCapacity=0.0 used=<memory:0, vCores:0> cluster=<memory:32768, vCores:32>
2014-05-03 23:21:10,233 INFO org.apache.hadoop.yarn.server.resourcemanager.RMAuditLogger: USER=ubuntu	OPERATION=Application Finished - Succeeded	TARGET=RMAppManager	RESULT=SUCCESS	APPID=application_1399156864902_0003
2014-05-03 23:21:10,233 INFO org.apache.hadoop.yarn.server.resourcemanager.scheduler.capacity.ParentQueue: completedContainer queue=root usedCapacity=0.0 absoluteUsedCapacity=0.0 used=<memory:0, vCores:0> cluster=<memory:32768, vCores:32>
2014-05-03 23:21:10,239 INFO org.apache.hadoop.yarn.server.resourcemanager.scheduler.capacity.ParentQueue: Re-sorting completed queue: root.default stats: default: capacity=1.0, absoluteCapacity=1.0, usedResources=<memory:0, vCores:0>usedCapacity=0.0, absoluteUsedCapacity=0.0, numApps=1, numContainers=0
2014-05-03 23:21:10,239 INFO org.apache.hadoop.yarn.server.resourcemanager.scheduler.capacity.CapacityScheduler: Application appattempt_1399156864902_0003_000001 released container container_1399156864902_0003_01_000001 on node: host: noded:50846 #containers=0 available=8192 used=0 with event: FINISHED
2014-05-03 23:21:10,239 INFO org.apache.hadoop.yarn.server.resourcemanager.amlauncher.AMLauncher: Cleaning master appattempt_1399156864902_0003_000001
2014-05-03 23:21:10,233 INFO org.apache.hadoop.yarn.server.resourcemanager.RMAppManager$ApplicationSummary: appId=application_1399156864902_0003,name=base||path:/in1m||num reduce:8,user=ubuntu,queue=default,state=FINISHED,trackingUrl=ec2-54-186-230-200.us-west-2.compute.amazonaws.com:8088/proxy/application_1399156864902_0003/jobhistory/job/job_1399156864902_0003,appMasterHost=ip-10-0-0-244,startTime=1399159039388,finishTime=1399159263603,finalStatus=SUCCEEDED
2014-05-03 23:21:10,239 INFO org.apache.hadoop.yarn.server.resourcemanager.scheduler.capacity.CapacityScheduler: Application appattempt_1399156864902_0003_000001 is done. finalState=FINISHED
2014-05-03 23:21:10,239 INFO org.apache.hadoop.yarn.server.resourcemanager.scheduler.AppSchedulingInfo: Application application_1399156864902_0003 requests cleared
2014-05-03 23:21:10,239 INFO org.apache.hadoop.yarn.server.resourcemanager.scheduler.capacity.LeafQueue: Application removed - appId: application_1399156864902_0003 user: ubuntu queue: default #user-pending-applications: 0 #user-active-applications: 0 #queue-pending-applications: 0 #queue-active-applications: 0
2014-05-03 23:21:10,239 INFO org.apache.hadoop.yarn.server.resourcemanager.scheduler.capacity.ParentQueue: Application removed - appId: application_1399156864902_0003 user: ubuntu leaf-queue of parent: root #applications: 0
2014-05-03 23:22:52,932 ERROR org.apache.hadoop.yarn.server.resourcemanager.ResourceManager: RECEIVED SIGNAL 15: SIGTERM
2014-05-03 23:22:52,938 INFO org.mortbay.log: Stopped SelectChannelConnector@ec2-54-186-230-200.us-west-2.compute.amazonaws.com:8088
2014-05-03 23:22:53,040 ERROR org.apache.hadoop.security.token.delegation.AbstractDelegationTokenSecretManager: InterruptedExcpetion recieved for ExpiredTokenRemover thread java.lang.InterruptedException: sleep interrupted
2014-05-03 23:22:53,041 INFO org.apache.hadoop.metrics2.impl.MetricsSystemImpl: Stopping ResourceManager metrics system...
2014-05-03 23:22:53,043 INFO org.apache.hadoop.metrics2.impl.MetricsSystemImpl: ResourceManager metrics system stopped.
2014-05-03 23:22:53,043 INFO org.apache.hadoop.metrics2.impl.MetricsSystemImpl: ResourceManager metrics system shutdown complete.
2014-05-03 23:22:53,044 WARN org.apache.hadoop.yarn.server.resourcemanager.amlauncher.ApplicationMasterLauncher: org.apache.hadoop.yarn.server.resourcemanager.amlauncher.ApplicationMasterLauncher$LauncherThread interrupted. Returning.
2014-05-03 23:22:53,045 INFO org.apache.hadoop.ipc.Server: Stopping server on 8033
2014-05-03 23:22:53,046 INFO org.apache.hadoop.ipc.Server: Stopping IPC Server listener on 8033
2014-05-03 23:22:53,046 INFO org.apache.hadoop.ipc.Server: Stopping IPC Server Responder
2014-05-03 23:22:53,046 INFO org.apache.hadoop.ipc.Server: Stopping server on 8032
2014-05-03 23:22:53,049 INFO org.apache.hadoop.ipc.Server: Stopping IPC Server listener on 8032
2014-05-03 23:22:53,050 INFO org.apache.hadoop.ipc.Server: Stopping IPC Server Responder
2014-05-03 23:22:53,055 INFO org.apache.hadoop.ipc.Server: Stopping server on 8030
2014-05-03 23:22:53,062 INFO org.apache.hadoop.ipc.Server: Stopping IPC Server listener on 8030
2014-05-03 23:22:53,063 INFO org.apache.hadoop.ipc.Server: Stopping IPC Server Responder
2014-05-03 23:22:53,064 INFO org.apache.hadoop.ipc.Server: Stopping server on 8031
2014-05-03 23:22:53,070 INFO org.apache.hadoop.ipc.Server: Stopping IPC Server listener on 8031
2014-05-03 23:22:53,071 INFO org.apache.hadoop.ipc.Server: Stopping IPC Server Responder
2014-05-03 23:22:53,071 INFO org.apache.hadoop.yarn.util.AbstractLivelinessMonitor: NMLivelinessMonitor thread interrupted
2014-05-03 23:22:53,072 ERROR org.apache.hadoop.yarn.server.resourcemanager.ResourceManager: Returning, interrupted : java.lang.InterruptedException
2014-05-03 23:22:53,072 INFO org.apache.hadoop.yarn.util.AbstractLivelinessMonitor: AMLivelinessMonitor thread interrupted
2014-05-03 23:22:53,072 INFO org.apache.hadoop.yarn.util.AbstractLivelinessMonitor: AMLivelinessMonitor thread interrupted
2014-05-03 23:22:53,072 INFO org.apache.hadoop.yarn.util.AbstractLivelinessMonitor: org.apache.hadoop.yarn.server.resourcemanager.rmcontainer.ContainerAllocationExpirer thread interrupted
2014-05-03 23:22:53,073 INFO org.apache.hadoop.yarn.server.resourcemanager.ResourceManager: SHUTDOWN_MSG: 
/************************************************************
SHUTDOWN_MSG: Shutting down ResourceManager at ip-10-0-0-182/10.0.0.182
************************************************************/
2014-05-03 23:25:03,079 INFO org.apache.hadoop.yarn.server.resourcemanager.ResourceManager: STARTUP_MSG: 
/************************************************************
STARTUP_MSG: Starting ResourceManager
STARTUP_MSG:   host = ip-10-0-0-182/10.0.0.182
STARTUP_MSG:   args = []
STARTUP_MSG:   version = 2.2.0
STARTUP_MSG:   build = Unknown -r Unknown; compiled by 'Joey' on 2014-03-24T00:00Z
STARTUP_MSG:   java = 1.7.0_51
************************************************************/
2014-05-03 23:25:03,093 INFO org.apache.hadoop.yarn.server.resourcemanager.ResourceManager: registered UNIX signal handlers for [TERM, HUP, INT]
2014-05-03 23:25:03,422 INFO org.apache.hadoop.yarn.server.resourcemanager.security.AMRMTokenSecretManager: Rolling master-key for amrm-tokens
2014-05-03 23:25:03,437 INFO org.apache.hadoop.yarn.server.resourcemanager.security.RMContainerTokenSecretManager: ContainerTokenKeyRollingInterval: 86400000ms and ContainerTokenKeyActivationDelay: 900000ms
2014-05-03 23:25:03,441 INFO org.apache.hadoop.yarn.server.resourcemanager.security.NMTokenSecretManagerInRM: NMTokenKeyRollingInterval: 86400000ms and NMTokenKeyActivationDelay: 900000ms
2014-05-03 23:25:03,449 INFO org.apache.hadoop.yarn.event.AsyncDispatcher: Registering class org.apache.hadoop.yarn.server.resourcemanager.recovery.RMStateStoreEventType for class org.apache.hadoop.yarn.server.resourcemanager.recovery.RMStateStore$ForwardingEventHandler
2014-05-03 23:25:04,187 INFO org.apache.hadoop.yarn.event.AsyncDispatcher: Registering class org.apache.hadoop.yarn.server.resourcemanager.NodesListManagerEventType for class org.apache.hadoop.yarn.server.resourcemanager.NodesListManager
2014-05-03 23:25:04,358 INFO org.apache.hadoop.yarn.server.resourcemanager.ResourceManager: Using Scheduler: org.apache.hadoop.yarn.server.resourcemanager.scheduler.capacity.CapacityScheduler
2014-05-03 23:25:04,606 INFO org.apache.hadoop.yarn.event.AsyncDispatcher: Registering class org.apache.hadoop.yarn.server.resourcemanager.scheduler.event.SchedulerEventType for class org.apache.hadoop.yarn.server.resourcemanager.ResourceManager$SchedulerEventDispatcher
2014-05-03 23:25:04,607 INFO org.apache.hadoop.yarn.event.AsyncDispatcher: Registering class org.apache.hadoop.yarn.server.resourcemanager.rmapp.RMAppEventType for class org.apache.hadoop.yarn.server.resourcemanager.ResourceManager$ApplicationEventDispatcher
2014-05-03 23:25:04,609 INFO org.apache.hadoop.yarn.event.AsyncDispatcher: Registering class org.apache.hadoop.yarn.server.resourcemanager.rmapp.attempt.RMAppAttemptEventType for class org.apache.hadoop.yarn.server.resourcemanager.ResourceManager$ApplicationAttemptEventDispatcher
2014-05-03 23:25:04,613 INFO org.apache.hadoop.yarn.event.AsyncDispatcher: Registering class org.apache.hadoop.yarn.server.resourcemanager.rmnode.RMNodeEventType for class org.apache.hadoop.yarn.server.resourcemanager.ResourceManager$NodeEventDispatcher
2014-05-03 23:25:04,857 INFO org.apache.hadoop.metrics2.impl.MetricsConfig: loaded properties from hadoop-metrics2.properties
2014-05-03 23:25:04,969 INFO org.apache.hadoop.metrics2.impl.MetricsSystemImpl: Scheduled snapshot period at 10 second(s).
2014-05-03 23:25:04,969 INFO org.apache.hadoop.metrics2.impl.MetricsSystemImpl: ResourceManager metrics system started
2014-05-03 23:25:05,220 INFO org.apache.hadoop.yarn.server.resourcemanager.scheduler.capacity.ParentQueue: root, capacity=1.0, asboluteCapacity=1.0, maxCapacity=1.0, asboluteMaxCapacity=1.0, state=RUNNING, acls=ADMINISTER_QUEUE:*SUBMIT_APPLICATIONS:*
2014-05-03 23:25:05,220 INFO org.apache.hadoop.yarn.server.resourcemanager.scheduler.capacity.ParentQueue: Initialized parent-queue root name=root, fullname=root
2014-05-03 23:25:05,269 INFO org.apache.hadoop.yarn.server.resourcemanager.scheduler.capacity.LeafQueue: Initializing default
capacity = 1.0 [= (float) configuredCapacity / 100 ]
asboluteCapacity = 1.0 [= parentAbsoluteCapacity * capacity ]
maxCapacity = 1.0 [= configuredMaxCapacity ]
absoluteMaxCapacity = 1.0 [= 1.0 maximumCapacity undefined, (parentAbsoluteMaxCapacity * maximumCapacity) / 100 otherwise ]
userLimit = 100 [= configuredUserLimit ]
userLimitFactor = 1.0 [= configuredUserLimitFactor ]
maxApplications = 10000 [= configuredMaximumSystemApplicationsPerQueue or (int)(configuredMaximumSystemApplications * absoluteCapacity)]
maxApplicationsPerUser = 10000 [= (int)(maxApplications * (userLimit / 100.0f) * userLimitFactor) ]
maxActiveApplications = 1 [= max((int)ceil((clusterResourceMemory / minimumAllocation) * maxAMResourcePerQueuePercent * absoluteMaxCapacity),1) ]
maxActiveAppsUsingAbsCap = 1 [= max((int)ceil((clusterResourceMemory / minimumAllocation) *maxAMResourcePercent * absoluteCapacity),1) ]
maxActiveApplicationsPerUser = 1 [= max((int)(maxActiveApplications * (userLimit / 100.0f) * userLimitFactor),1) ]
usedCapacity = 0.0 [= usedResourcesMemory / (clusterResourceMemory * absoluteCapacity)]
absoluteUsedCapacity = 0.0 [= usedResourcesMemory / clusterResourceMemory]
maxAMResourcePerQueuePercent = 0.1 [= configuredMaximumAMResourcePercent ]
minimumAllocationFactor = 0.875 [= (float)(maximumAllocationMemory - minimumAllocationMemory) / maximumAllocationMemory ]
numContainers = 0 [= currentNumContainers ]
state = RUNNING [= configuredState ]
acls = ADMINISTER_QUEUE:*SUBMIT_APPLICATIONS:* [= configuredAcls ]
nodeLocalityDelay = 0

2014-05-03 23:25:05,270 INFO org.apache.hadoop.yarn.server.resourcemanager.scheduler.capacity.CapacityScheduler: Initialized queue: default: capacity=1.0, absoluteCapacity=1.0, usedResources=<memory:0, vCores:0>usedCapacity=0.0, absoluteUsedCapacity=0.0, numApps=0, numContainers=0
2014-05-03 23:25:05,270 INFO org.apache.hadoop.yarn.server.resourcemanager.scheduler.capacity.CapacityScheduler: Initialized queue: root: numChildQueue= 1, capacity=1.0, absoluteCapacity=1.0, usedResources=<memory:0, vCores:0>usedCapacity=0.0, numApps=0, numContainers=0
2014-05-03 23:25:05,270 INFO org.apache.hadoop.yarn.server.resourcemanager.scheduler.capacity.CapacityScheduler: Initialized root queue root: numChildQueue= 1, capacity=1.0, absoluteCapacity=1.0, usedResources=<memory:0, vCores:0>usedCapacity=0.0, numApps=0, numContainers=0
2014-05-03 23:25:05,270 INFO org.apache.hadoop.yarn.server.resourcemanager.scheduler.capacity.CapacityScheduler: Initialized CapacityScheduler with calculator=class org.apache.hadoop.yarn.util.resource.DefaultResourceCalculator, minimumAllocation=<<memory:1024, vCores:1>>, maximumAllocation=<<memory:8192, vCores:32>>
2014-05-03 23:25:05,470 INFO org.apache.hadoop.yarn.event.AsyncDispatcher: Registering class org.apache.hadoop.yarn.server.resourcemanager.RMAppManagerEventType for class org.apache.hadoop.yarn.server.resourcemanager.RMAppManager
2014-05-03 23:25:05,514 INFO org.apache.hadoop.yarn.event.AsyncDispatcher: Registering class org.apache.hadoop.yarn.server.resourcemanager.amlauncher.AMLauncherEventType for class org.apache.hadoop.yarn.server.resourcemanager.amlauncher.ApplicationMasterLauncher
2014-05-03 23:25:05,517 INFO org.apache.hadoop.yarn.server.resourcemanager.RMNMInfo: Registered RMNMInfo MBean
2014-05-03 23:25:05,518 INFO org.apache.hadoop.util.HostsFileReader: Refreshing hosts (include/exclude) list
2014-05-03 23:25:05,542 INFO org.apache.hadoop.yarn.server.resourcemanager.security.AMRMTokenSecretManager: Rolling master-key for amrm-tokens
2014-05-03 23:25:05,542 INFO org.apache.hadoop.yarn.server.resourcemanager.security.RMContainerTokenSecretManager: Rolling master-key for container-tokens
2014-05-03 23:25:05,546 INFO org.apache.hadoop.yarn.server.resourcemanager.security.NMTokenSecretManagerInRM: Rolling master-key for nm-tokens
2014-05-03 23:25:05,643 INFO org.mortbay.log: Logging to org.slf4j.impl.Log4jLoggerAdapter(org.mortbay.log) via org.mortbay.log.Slf4jLog
2014-05-03 23:25:05,725 INFO org.apache.hadoop.http.HttpServer: Added global filter 'safety' (class=org.apache.hadoop.http.HttpServer$QuotingInputFilter)
2014-05-03 23:25:05,728 INFO org.apache.hadoop.http.HttpServer: Added filter static_user_filter (class=org.apache.hadoop.http.lib.StaticUserWebFilter$StaticUserFilter) to context cluster
2014-05-03 23:25:05,728 INFO org.apache.hadoop.http.HttpServer: Added filter static_user_filter (class=org.apache.hadoop.http.lib.StaticUserWebFilter$StaticUserFilter) to context static
2014-05-03 23:25:05,728 INFO org.apache.hadoop.http.HttpServer: Added filter static_user_filter (class=org.apache.hadoop.http.lib.StaticUserWebFilter$StaticUserFilter) to context logs
2014-05-03 23:25:05,734 INFO org.apache.hadoop.http.HttpServer: adding path spec: /cluster/*
2014-05-03 23:25:05,735 INFO org.apache.hadoop.http.HttpServer: adding path spec: /ws/*
2014-05-03 23:25:05,745 INFO org.apache.hadoop.http.HttpServer: Jetty bound to port 8088
2014-05-03 23:25:05,746 INFO org.mortbay.log: jetty-6.1.26
2014-05-03 23:25:05,802 INFO org.mortbay.log: Extract jar:file:/home/ubuntu/PatchedDistro/hadoop-2.2.0/share/hadoop/yarn/hadoop-yarn-common-2.2.0.jar!/webapps/cluster to /tmp/Jetty_ec2.54.186.230.200_us.west.2_compute_amazonaws_com_8088_cluster____.lsgqu1/webapp
2014-05-03 23:25:06,462 INFO org.mortbay.log: Started SelectChannelConnector@ec2-54-186-230-200.us-west-2.compute.amazonaws.com:8088
2014-05-03 23:25:06,463 INFO org.apache.hadoop.yarn.webapp.WebApps: Web app /cluster started at 8088
2014-05-03 23:25:07,692 INFO org.apache.hadoop.yarn.webapp.WebApps: Registered webapp guice modules
2014-05-03 23:25:07,694 INFO org.apache.hadoop.security.token.delegation.AbstractDelegationTokenSecretManager: Updating the current master key for generating delegation tokens
2014-05-03 23:25:07,698 INFO org.apache.hadoop.yarn.server.resourcemanager.security.RMDelegationTokenSecretManager: storing master key with keyID 1
2014-05-03 23:25:07,702 INFO org.apache.hadoop.security.token.delegation.AbstractDelegationTokenSecretManager: Starting expired delegation token remover thread, tokenRemoverScanInterval=60 min(s)
2014-05-03 23:25:07,702 INFO org.apache.hadoop.security.token.delegation.AbstractDelegationTokenSecretManager: Updating the current master key for generating delegation tokens
2014-05-03 23:25:07,703 INFO org.apache.hadoop.yarn.server.resourcemanager.security.RMDelegationTokenSecretManager: storing master key with keyID 2
2014-05-03 23:25:07,788 INFO org.apache.hadoop.ipc.Server: Starting Socket Reader #1 for port 8031
2014-05-03 23:25:07,817 INFO org.apache.hadoop.yarn.factories.impl.pb.RpcServerFactoryPBImpl: Adding protocol org.apache.hadoop.yarn.server.api.ResourceTrackerPB to the server
2014-05-03 23:25:07,819 INFO org.apache.hadoop.ipc.Server: IPC Server listener on 8031: starting
2014-05-03 23:25:07,818 INFO org.apache.hadoop.ipc.Server: IPC Server Responder: starting
2014-05-03 23:25:07,916 INFO org.apache.hadoop.ipc.Server: Starting Socket Reader #1 for port 8030
2014-05-03 23:25:08,031 INFO org.apache.hadoop.yarn.factories.impl.pb.RpcServerFactoryPBImpl: Adding protocol org.apache.hadoop.yarn.api.ApplicationMasterProtocolPB to the server
2014-05-03 23:25:08,040 INFO org.apache.hadoop.ipc.Server: IPC Server Responder: starting
2014-05-03 23:25:08,048 INFO org.apache.hadoop.ipc.Server: IPC Server listener on 8030: starting
2014-05-03 23:25:08,215 INFO org.apache.hadoop.yarn.util.RackResolver: Resolved noded to /default-rack
2014-05-03 23:25:08,216 INFO org.apache.hadoop.yarn.util.RackResolver: Resolved nodec to /default-rack
2014-05-03 23:25:08,216 INFO org.apache.hadoop.yarn.util.RackResolver: Resolved nodeb to /default-rack
2014-05-03 23:25:08,233 INFO org.apache.hadoop.yarn.server.resourcemanager.ResourceTrackerService: NodeManager from node noded(cmPort: 38789 httpPort: 8042) registered with capability: <memory:8192, vCores:8>, assigned nodeId noded:38789
2014-05-03 23:25:08,234 INFO org.apache.hadoop.yarn.server.resourcemanager.rmnode.RMNodeImpl: noded:38789 Node Transitioned from NEW to RUNNING
2014-05-03 23:25:08,237 INFO org.apache.hadoop.yarn.server.resourcemanager.scheduler.capacity.CapacityScheduler: Added node noded:38789 clusterResource: <memory:8192, vCores:8>
2014-05-03 23:25:08,242 INFO org.apache.hadoop.yarn.server.resourcemanager.ResourceTrackerService: NodeManager from node nodec(cmPort: 38120 httpPort: 8042) registered with capability: <memory:8192, vCores:8>, assigned nodeId nodec:38120
2014-05-03 23:25:08,242 INFO org.apache.hadoop.yarn.server.resourcemanager.ResourceTrackerService: NodeManager from node nodeb(cmPort: 35002 httpPort: 8042) registered with capability: <memory:8192, vCores:8>, assigned nodeId nodeb:35002
2014-05-03 23:25:08,242 INFO org.apache.hadoop.yarn.server.resourcemanager.rmnode.RMNodeImpl: nodec:38120 Node Transitioned from NEW to RUNNING
2014-05-03 23:25:08,242 INFO org.apache.hadoop.yarn.server.resourcemanager.rmnode.RMNodeImpl: nodeb:35002 Node Transitioned from NEW to RUNNING
2014-05-03 23:25:08,242 INFO org.apache.hadoop.yarn.server.resourcemanager.scheduler.capacity.CapacityScheduler: Added node nodec:38120 clusterResource: <memory:16384, vCores:16>
2014-05-03 23:25:08,243 INFO org.apache.hadoop.yarn.server.resourcemanager.scheduler.capacity.CapacityScheduler: Added node nodeb:35002 clusterResource: <memory:24576, vCores:24>
2014-05-03 23:25:08,296 INFO org.apache.hadoop.yarn.factories.impl.pb.RpcServerFactoryPBImpl: Adding protocol org.apache.hadoop.yarn.api.ApplicationClientProtocolPB to the server
2014-05-03 23:25:08,296 INFO org.apache.hadoop.ipc.Server: Starting Socket Reader #1 for port 8032
2014-05-03 23:25:08,296 INFO org.apache.hadoop.ipc.Server: IPC Server Responder: starting
2014-05-03 23:25:08,297 INFO org.apache.hadoop.ipc.Server: IPC Server listener on 8032: starting
2014-05-03 23:25:08,397 INFO org.apache.hadoop.yarn.factories.impl.pb.RpcServerFactoryPBImpl: Adding protocol org.apache.hadoop.yarn.server.api.ResourceManagerAdministrationProtocolPB to the server
2014-05-03 23:25:08,397 INFO org.apache.hadoop.ipc.Server: Starting Socket Reader #1 for port 8033
2014-05-03 23:25:08,397 INFO org.apache.hadoop.ipc.Server: IPC Server Responder: starting
2014-05-03 23:25:08,398 INFO org.apache.hadoop.ipc.Server: IPC Server listener on 8033: starting
2014-05-03 23:25:10,026 INFO org.apache.hadoop.yarn.util.RackResolver: Resolved nodea to /default-rack
2014-05-03 23:25:10,026 INFO org.apache.hadoop.yarn.server.resourcemanager.ResourceTrackerService: NodeManager from node nodea(cmPort: 38339 httpPort: 8042) registered with capability: <memory:8192, vCores:8>, assigned nodeId nodea:38339
2014-05-03 23:25:10,026 INFO org.apache.hadoop.yarn.server.resourcemanager.rmnode.RMNodeImpl: nodea:38339 Node Transitioned from NEW to RUNNING
2014-05-03 23:25:10,027 INFO org.apache.hadoop.yarn.server.resourcemanager.scheduler.capacity.CapacityScheduler: Added node nodea:38339 clusterResource: <memory:32768, vCores:32>
2014-05-03 23:28:09,891 INFO org.apache.hadoop.yarn.server.resourcemanager.ClientRMService: Allocated new applicationId: 1
2014-05-03 23:28:11,549 INFO org.apache.hadoop.yarn.server.resourcemanager.rmapp.RMAppImpl: Storing application with id application_1399159503039_0001
2014-05-03 23:28:11,551 INFO org.apache.hadoop.yarn.server.resourcemanager.rmapp.RMAppImpl: application_1399159503039_0001 State change from NEW to NEW_SAVING
2014-05-03 23:28:11,551 INFO org.apache.hadoop.yarn.server.resourcemanager.ClientRMService: Application with id 1 submitted by user ubuntu
2014-05-03 23:28:11,553 INFO org.apache.hadoop.yarn.server.resourcemanager.RMAuditLogger: USER=ubuntu	IP=10.0.0.182	OPERATION=Submit Application Request	TARGET=ClientRMService	RESULT=SUCCESS	APPID=application_1399159503039_0001
2014-05-03 23:28:11,561 INFO org.apache.hadoop.yarn.server.resourcemanager.recovery.RMStateStore: Storing info for app: application_1399159503039_0001
2014-05-03 23:28:11,581 INFO org.apache.hadoop.yarn.server.resourcemanager.rmapp.RMAppImpl: application_1399159503039_0001 State change from NEW_SAVING to SUBMITTED
2014-05-03 23:28:11,583 INFO org.apache.hadoop.yarn.server.resourcemanager.ApplicationMasterService: Registering app attempt : appattempt_1399159503039_0001_000001
2014-05-03 23:28:11,588 INFO org.apache.hadoop.yarn.server.resourcemanager.rmapp.attempt.RMAppAttemptImpl: appattempt_1399159503039_0001_000001 State change from NEW to SUBMITTED
2014-05-03 23:28:11,606 INFO org.apache.hadoop.yarn.server.resourcemanager.scheduler.capacity.LeafQueue: Application application_1399159503039_0001 from user: ubuntu activated in queue: default
2014-05-03 23:28:11,606 INFO org.apache.hadoop.yarn.server.resourcemanager.scheduler.capacity.LeafQueue: Application added - appId: application_1399159503039_0001 user: org.apache.hadoop.yarn.server.resourcemanager.scheduler.capacity.LeafQueue$User@3ab71d5e, leaf-queue: default #user-pending-applications: 0 #user-active-applications: 1 #queue-pending-applications: 0 #queue-active-applications: 1
2014-05-03 23:28:11,606 INFO org.apache.hadoop.yarn.server.resourcemanager.scheduler.capacity.ParentQueue: Application added - appId: application_1399159503039_0001 user: ubuntu leaf-queue of parent: root #applications: 1
2014-05-03 23:28:11,606 INFO org.apache.hadoop.yarn.server.resourcemanager.scheduler.capacity.CapacityScheduler: Application Submission: appattempt_1399159503039_0001_000001, user: ubuntu queue: default: capacity=1.0, absoluteCapacity=1.0, usedResources=<memory:0, vCores:0>usedCapacity=0.0, absoluteUsedCapacity=0.0, numApps=1, numContainers=0, currently active: 1
2014-05-03 23:28:11,607 INFO org.apache.hadoop.yarn.server.resourcemanager.rmapp.attempt.RMAppAttemptImpl: appattempt_1399159503039_0001_000001 State change from SUBMITTED to SCHEDULED
2014-05-03 23:28:11,611 INFO org.apache.hadoop.yarn.server.resourcemanager.rmapp.RMAppImpl: application_1399159503039_0001 State change from SUBMITTED to ACCEPTED
2014-05-03 23:28:11,776 INFO org.apache.hadoop.yarn.server.resourcemanager.rmcontainer.RMContainerImpl: container_1399159503039_0001_01_000001 Container Transitioned from NEW to ALLOCATED
2014-05-03 23:28:11,776 INFO org.apache.hadoop.yarn.server.resourcemanager.RMAuditLogger: USER=ubuntu	OPERATION=AM Allocated Container	TARGET=SchedulerApp	RESULT=SUCCESS	APPID=application_1399159503039_0001	CONTAINERID=container_1399159503039_0001_01_000001
2014-05-03 23:28:11,776 INFO org.apache.hadoop.yarn.server.resourcemanager.scheduler.common.fica.FiCaSchedulerNode: Assigned container container_1399159503039_0001_01_000001 of capacity <memory:2048, vCores:1> on host nodeb:35002, which currently has 1 containers, <memory:2048, vCores:1> used and <memory:6144, vCores:7> available
2014-05-03 23:28:11,777 INFO org.apache.hadoop.yarn.server.resourcemanager.scheduler.capacity.LeafQueue: assignedContainer application=application_1399159503039_0001 container=Container: [ContainerId: container_1399159503039_0001_01_000001, NodeId: nodeb:35002, NodeHttpAddress: nodeb:8042, Resource: <memory:2048, vCores:1>, Priority: 0, Token: Token { kind: ContainerToken, service: 10.0.0.243:35002 }, ] containerId=container_1399159503039_0001_01_000001 queue=default: capacity=1.0, absoluteCapacity=1.0, usedResources=<memory:0, vCores:0>usedCapacity=0.0, absoluteUsedCapacity=0.0, numApps=1, numContainers=0 usedCapacity=0.0 absoluteUsedCapacity=0.0 used=<memory:0, vCores:0> cluster=<memory:32768, vCores:32>
2014-05-03 23:28:11,777 INFO org.apache.hadoop.yarn.server.resourcemanager.scheduler.capacity.ParentQueue: Re-sorting assigned queue: root.default stats: default: capacity=1.0, absoluteCapacity=1.0, usedResources=<memory:2048, vCores:1>usedCapacity=0.0625, absoluteUsedCapacity=0.0625, numApps=1, numContainers=1
2014-05-03 23:28:11,777 INFO org.apache.hadoop.yarn.server.resourcemanager.scheduler.capacity.ParentQueue: assignedContainer queue=root usedCapacity=0.0625 absoluteUsedCapacity=0.0625 used=<memory:2048, vCores:1> cluster=<memory:32768, vCores:32>
2014-05-03 23:28:11,778 INFO org.apache.hadoop.yarn.server.resourcemanager.rmcontainer.RMContainerImpl: container_1399159503039_0001_01_000001 Container Transitioned from ALLOCATED to ACQUIRED
2014-05-03 23:28:11,781 INFO org.apache.hadoop.yarn.server.resourcemanager.rmapp.attempt.RMAppAttemptImpl: Storing attempt: AppId: application_1399159503039_0001 AttemptId: appattempt_1399159503039_0001_000001 MasterContainer: Container: [ContainerId: container_1399159503039_0001_01_000001, NodeId: nodeb:35002, NodeHttpAddress: nodeb:8042, Resource: <memory:2048, vCores:1>, Priority: 0, Token: Token { kind: ContainerToken, service: 10.0.0.243:35002 }, ]
2014-05-03 23:28:11,785 INFO org.apache.hadoop.yarn.server.resourcemanager.rmapp.attempt.RMAppAttemptImpl: appattempt_1399159503039_0001_000001 State change from SCHEDULED to ALLOCATED_SAVING
2014-05-03 23:28:11,790 INFO org.apache.hadoop.yarn.server.resourcemanager.recovery.RMStateStore: Storing info for attempt: appattempt_1399159503039_0001_000001
2014-05-03 23:28:11,792 INFO org.apache.hadoop.yarn.server.resourcemanager.rmapp.attempt.RMAppAttemptImpl: appattempt_1399159503039_0001_000001 State change from ALLOCATED_SAVING to ALLOCATED
2014-05-03 23:28:11,794 INFO org.apache.hadoop.yarn.server.resourcemanager.amlauncher.AMLauncher: Launching masterappattempt_1399159503039_0001_000001
2014-05-03 23:28:11,849 INFO org.apache.hadoop.yarn.server.resourcemanager.amlauncher.AMLauncher: Setting up container Container: [ContainerId: container_1399159503039_0001_01_000001, NodeId: nodeb:35002, NodeHttpAddress: nodeb:8042, Resource: <memory:2048, vCores:1>, Priority: 0, Token: Token { kind: ContainerToken, service: 10.0.0.243:35002 }, ] for AM appattempt_1399159503039_0001_000001
2014-05-03 23:28:11,850 INFO org.apache.hadoop.yarn.server.resourcemanager.amlauncher.AMLauncher: Command to launch container container_1399159503039_0001_01_000001 : $JAVA_HOME/bin/java -Dlog4j.configuration=container-log4j.properties -Dyarn.app.container.log.dir=<LOG_DIR> -Dyarn.app.container.log.filesize=0 -Dhadoop.root.logger=INFO,CLA  -Xmx1024m org.apache.hadoop.mapreduce.v2.app.MRAppMaster 1><LOG_DIR>/stdout 2><LOG_DIR>/stderr 
2014-05-03 23:28:12,182 INFO org.apache.hadoop.yarn.server.resourcemanager.amlauncher.AMLauncher: Done launching container Container: [ContainerId: container_1399159503039_0001_01_000001, NodeId: nodeb:35002, NodeHttpAddress: nodeb:8042, Resource: <memory:2048, vCores:1>, Priority: 0, Token: Token { kind: ContainerToken, service: 10.0.0.243:35002 }, ] for AM appattempt_1399159503039_0001_000001
2014-05-03 23:28:12,182 INFO org.apache.hadoop.yarn.server.resourcemanager.rmapp.attempt.RMAppAttemptImpl: appattempt_1399159503039_0001_000001 State change from ALLOCATED to LAUNCHED
2014-05-03 23:28:12,790 INFO org.apache.hadoop.yarn.server.resourcemanager.rmcontainer.RMContainerImpl: container_1399159503039_0001_01_000001 Container Transitioned from ACQUIRED to RUNNING
2014-05-03 23:28:18,726 INFO SecurityLogger.org.apache.hadoop.ipc.Server: Auth successful for appattempt_1399159503039_0001_000001 (auth:SIMPLE)
2014-05-03 23:28:18,740 INFO org.apache.hadoop.yarn.server.resourcemanager.ApplicationMasterService: AM registration appattempt_1399159503039_0001_000001
2014-05-03 23:28:18,741 INFO org.apache.hadoop.yarn.server.resourcemanager.rmapp.attempt.RMAppAttemptImpl: appattempt_1399159503039_0001_000001 State change from LAUNCHED to RUNNING
2014-05-03 23:28:18,742 INFO org.apache.hadoop.yarn.server.resourcemanager.rmapp.RMAppImpl: application_1399159503039_0001 State change from ACCEPTED to RUNNING
2014-05-03 23:28:18,742 INFO org.apache.hadoop.yarn.server.resourcemanager.RMAuditLogger: USER=ubuntu	IP=10.0.0.243	OPERATION=Register App Master	TARGET=ApplicationMasterService	RESULT=SUCCESS	APPID=application_1399159503039_0001	APPATTEMPTID=appattempt_1399159503039_0001_000001
2014-05-03 23:28:19,808 INFO org.apache.hadoop.yarn.server.resourcemanager.rmcontainer.RMContainerImpl: container_1399159503039_0001_01_000002 Container Transitioned from NEW to ALLOCATED
2014-05-03 23:28:19,808 INFO org.apache.hadoop.yarn.server.resourcemanager.RMAuditLogger: USER=ubuntu	OPERATION=AM Allocated Container	TARGET=SchedulerApp	RESULT=SUCCESS	APPID=application_1399159503039_0001	CONTAINERID=container_1399159503039_0001_01_000002
2014-05-03 23:28:19,808 INFO org.apache.hadoop.yarn.server.resourcemanager.scheduler.common.fica.FiCaSchedulerNode: Assigned container container_1399159503039_0001_01_000002 of capacity <memory:1024, vCores:1> on host nodeb:35002, which currently has 2 containers, <memory:3072, vCores:2> used and <memory:5120, vCores:6> available
2014-05-03 23:28:19,808 INFO org.apache.hadoop.yarn.server.resourcemanager.scheduler.capacity.LeafQueue: assignedContainer application=application_1399159503039_0001 container=Container: [ContainerId: container_1399159503039_0001_01_000002, NodeId: nodeb:35002, NodeHttpAddress: nodeb:8042, Resource: <memory:1024, vCores:1>, Priority: 20, Token: Token { kind: ContainerToken, service: 10.0.0.243:35002 }, ] containerId=container_1399159503039_0001_01_000002 queue=default: capacity=1.0, absoluteCapacity=1.0, usedResources=<memory:2048, vCores:1>usedCapacity=0.0625, absoluteUsedCapacity=0.0625, numApps=1, numContainers=1 usedCapacity=0.0625 absoluteUsedCapacity=0.0625 used=<memory:2048, vCores:1> cluster=<memory:32768, vCores:32>
2014-05-03 23:28:19,809 INFO org.apache.hadoop.yarn.server.resourcemanager.scheduler.capacity.ParentQueue: Re-sorting assigned queue: root.default stats: default: capacity=1.0, absoluteCapacity=1.0, usedResources=<memory:3072, vCores:2>usedCapacity=0.09375, absoluteUsedCapacity=0.09375, numApps=1, numContainers=2
2014-05-03 23:28:19,809 INFO org.apache.hadoop.yarn.server.resourcemanager.scheduler.capacity.ParentQueue: assignedContainer queue=root usedCapacity=0.09375 absoluteUsedCapacity=0.09375 used=<memory:3072, vCores:2> cluster=<memory:32768, vCores:32>
2014-05-03 23:28:19,810 INFO org.apache.hadoop.yarn.server.resourcemanager.rmcontainer.RMContainerImpl: container_1399159503039_0001_01_000003 Container Transitioned from NEW to ALLOCATED
2014-05-03 23:28:19,810 INFO org.apache.hadoop.yarn.server.resourcemanager.RMAuditLogger: USER=ubuntu	OPERATION=AM Allocated Container	TARGET=SchedulerApp	RESULT=SUCCESS	APPID=application_1399159503039_0001	CONTAINERID=container_1399159503039_0001_01_000003
2014-05-03 23:28:19,810 INFO org.apache.hadoop.yarn.server.resourcemanager.scheduler.common.fica.FiCaSchedulerNode: Assigned container container_1399159503039_0001_01_000003 of capacity <memory:1024, vCores:1> on host nodeb:35002, which currently has 3 containers, <memory:4096, vCores:3> used and <memory:4096, vCores:5> available
2014-05-03 23:28:19,810 INFO org.apache.hadoop.yarn.server.resourcemanager.scheduler.capacity.LeafQueue: assignedContainer application=application_1399159503039_0001 container=Container: [ContainerId: container_1399159503039_0001_01_000003, NodeId: nodeb:35002, NodeHttpAddress: nodeb:8042, Resource: <memory:1024, vCores:1>, Priority: 20, Token: Token { kind: ContainerToken, service: 10.0.0.243:35002 }, ] containerId=container_1399159503039_0001_01_000003 queue=default: capacity=1.0, absoluteCapacity=1.0, usedResources=<memory:3072, vCores:2>usedCapacity=0.09375, absoluteUsedCapacity=0.09375, numApps=1, numContainers=2 usedCapacity=0.09375 absoluteUsedCapacity=0.09375 used=<memory:3072, vCores:2> cluster=<memory:32768, vCores:32>
2014-05-03 23:28:19,810 INFO org.apache.hadoop.yarn.server.resourcemanager.scheduler.capacity.ParentQueue: Re-sorting assigned queue: root.default stats: default: capacity=1.0, absoluteCapacity=1.0, usedResources=<memory:4096, vCores:3>usedCapacity=0.125, absoluteUsedCapacity=0.125, numApps=1, numContainers=3
2014-05-03 23:28:19,810 INFO org.apache.hadoop.yarn.server.resourcemanager.scheduler.capacity.ParentQueue: assignedContainer queue=root usedCapacity=0.125 absoluteUsedCapacity=0.125 used=<memory:4096, vCores:3> cluster=<memory:32768, vCores:32>
2014-05-03 23:28:19,811 INFO org.apache.hadoop.yarn.server.resourcemanager.rmcontainer.RMContainerImpl: container_1399159503039_0001_01_000004 Container Transitioned from NEW to ALLOCATED
2014-05-03 23:28:19,811 INFO org.apache.hadoop.yarn.server.resourcemanager.RMAuditLogger: USER=ubuntu	OPERATION=AM Allocated Container	TARGET=SchedulerApp	RESULT=SUCCESS	APPID=application_1399159503039_0001	CONTAINERID=container_1399159503039_0001_01_000004
2014-05-03 23:28:19,811 INFO org.apache.hadoop.yarn.server.resourcemanager.scheduler.common.fica.FiCaSchedulerNode: Assigned container container_1399159503039_0001_01_000004 of capacity <memory:1024, vCores:1> on host nodeb:35002, which currently has 4 containers, <memory:5120, vCores:4> used and <memory:3072, vCores:4> available
2014-05-03 23:28:19,811 INFO org.apache.hadoop.yarn.server.resourcemanager.scheduler.capacity.LeafQueue: assignedContainer application=application_1399159503039_0001 container=Container: [ContainerId: container_1399159503039_0001_01_000004, NodeId: nodeb:35002, NodeHttpAddress: nodeb:8042, Resource: <memory:1024, vCores:1>, Priority: 20, Token: Token { kind: ContainerToken, service: 10.0.0.243:35002 }, ] containerId=container_1399159503039_0001_01_000004 queue=default: capacity=1.0, absoluteCapacity=1.0, usedResources=<memory:4096, vCores:3>usedCapacity=0.125, absoluteUsedCapacity=0.125, numApps=1, numContainers=3 usedCapacity=0.125 absoluteUsedCapacity=0.125 used=<memory:4096, vCores:3> cluster=<memory:32768, vCores:32>
2014-05-03 23:28:19,812 INFO org.apache.hadoop.yarn.server.resourcemanager.scheduler.capacity.ParentQueue: Re-sorting assigned queue: root.default stats: default: capacity=1.0, absoluteCapacity=1.0, usedResources=<memory:5120, vCores:4>usedCapacity=0.15625, absoluteUsedCapacity=0.15625, numApps=1, numContainers=4
2014-05-03 23:28:19,812 INFO org.apache.hadoop.yarn.server.resourcemanager.scheduler.capacity.ParentQueue: assignedContainer queue=root usedCapacity=0.15625 absoluteUsedCapacity=0.15625 used=<memory:5120, vCores:4> cluster=<memory:32768, vCores:32>
2014-05-03 23:28:19,813 INFO org.apache.hadoop.yarn.server.resourcemanager.rmcontainer.RMContainerImpl: container_1399159503039_0001_01_000005 Container Transitioned from NEW to ALLOCATED
2014-05-03 23:28:19,813 INFO org.apache.hadoop.yarn.server.resourcemanager.RMAuditLogger: USER=ubuntu	OPERATION=AM Allocated Container	TARGET=SchedulerApp	RESULT=SUCCESS	APPID=application_1399159503039_0001	CONTAINERID=container_1399159503039_0001_01_000005
2014-05-03 23:28:19,813 INFO org.apache.hadoop.yarn.server.resourcemanager.scheduler.common.fica.FiCaSchedulerNode: Assigned container container_1399159503039_0001_01_000005 of capacity <memory:1024, vCores:1> on host nodeb:35002, which currently has 5 containers, <memory:6144, vCores:5> used and <memory:2048, vCores:3> available
2014-05-03 23:28:19,813 INFO org.apache.hadoop.yarn.server.resourcemanager.scheduler.capacity.LeafQueue: assignedContainer application=application_1399159503039_0001 container=Container: [ContainerId: container_1399159503039_0001_01_000005, NodeId: nodeb:35002, NodeHttpAddress: nodeb:8042, Resource: <memory:1024, vCores:1>, Priority: 20, Token: Token { kind: ContainerToken, service: 10.0.0.243:35002 }, ] containerId=container_1399159503039_0001_01_000005 queue=default: capacity=1.0, absoluteCapacity=1.0, usedResources=<memory:5120, vCores:4>usedCapacity=0.15625, absoluteUsedCapacity=0.15625, numApps=1, numContainers=4 usedCapacity=0.15625 absoluteUsedCapacity=0.15625 used=<memory:5120, vCores:4> cluster=<memory:32768, vCores:32>
2014-05-03 23:28:19,813 INFO org.apache.hadoop.yarn.server.resourcemanager.scheduler.capacity.ParentQueue: Re-sorting assigned queue: root.default stats: default: capacity=1.0, absoluteCapacity=1.0, usedResources=<memory:6144, vCores:5>usedCapacity=0.1875, absoluteUsedCapacity=0.1875, numApps=1, numContainers=5
2014-05-03 23:28:19,813 INFO org.apache.hadoop.yarn.server.resourcemanager.scheduler.capacity.ParentQueue: assignedContainer queue=root usedCapacity=0.1875 absoluteUsedCapacity=0.1875 used=<memory:6144, vCores:5> cluster=<memory:32768, vCores:32>
2014-05-03 23:28:20,822 INFO org.apache.hadoop.yarn.server.resourcemanager.rmcontainer.RMContainerImpl: container_1399159503039_0001_01_000002 Container Transitioned from ALLOCATED to ACQUIRED
2014-05-03 23:28:20,823 INFO org.apache.hadoop.yarn.server.resourcemanager.rmcontainer.RMContainerImpl: container_1399159503039_0001_01_000003 Container Transitioned from ALLOCATED to ACQUIRED
2014-05-03 23:28:20,823 INFO org.apache.hadoop.yarn.server.resourcemanager.rmcontainer.RMContainerImpl: container_1399159503039_0001_01_000004 Container Transitioned from ALLOCATED to ACQUIRED
2014-05-03 23:28:20,823 INFO org.apache.hadoop.yarn.server.resourcemanager.rmcontainer.RMContainerImpl: container_1399159503039_0001_01_000005 Container Transitioned from ALLOCATED to ACQUIRED
2014-05-03 23:28:21,815 INFO org.apache.hadoop.yarn.server.resourcemanager.rmcontainer.RMContainerImpl: container_1399159503039_0001_01_000002 Container Transitioned from ACQUIRED to RUNNING
2014-05-03 23:28:21,815 INFO org.apache.hadoop.yarn.server.resourcemanager.rmcontainer.RMContainerImpl: container_1399159503039_0001_01_000003 Container Transitioned from ACQUIRED to RUNNING
2014-05-03 23:28:21,815 INFO org.apache.hadoop.yarn.server.resourcemanager.rmcontainer.RMContainerImpl: container_1399159503039_0001_01_000004 Container Transitioned from ACQUIRED to RUNNING
2014-05-03 23:28:21,815 INFO org.apache.hadoop.yarn.server.resourcemanager.rmcontainer.RMContainerImpl: container_1399159503039_0001_01_000005 Container Transitioned from ACQUIRED to RUNNING
2014-05-03 23:28:21,851 INFO org.apache.hadoop.yarn.server.resourcemanager.scheduler.AppSchedulingInfo: checking for deactivate... 
2014-05-03 23:28:52,856 INFO org.apache.hadoop.yarn.server.resourcemanager.rmcontainer.RMContainerImpl: container_1399159503039_0001_01_000004 Container Transitioned from RUNNING to COMPLETED
2014-05-03 23:28:52,856 INFO org.apache.hadoop.yarn.server.resourcemanager.scheduler.common.fica.FiCaSchedulerApp: Completed container: container_1399159503039_0001_01_000004 in state: COMPLETED event:FINISHED
2014-05-03 23:28:52,856 INFO org.apache.hadoop.yarn.server.resourcemanager.RMAuditLogger: USER=ubuntu	OPERATION=AM Released Container	TARGET=SchedulerApp	RESULT=SUCCESS	APPID=application_1399159503039_0001	CONTAINERID=container_1399159503039_0001_01_000004
2014-05-03 23:28:52,856 INFO org.apache.hadoop.yarn.server.resourcemanager.scheduler.common.fica.FiCaSchedulerNode: Released container container_1399159503039_0001_01_000004 of capacity <memory:1024, vCores:1> on host nodeb:35002, which currently has 4 containers, <memory:5120, vCores:4> used and <memory:3072, vCores:4> available, release resources=true
2014-05-03 23:28:52,860 INFO org.apache.hadoop.yarn.server.resourcemanager.scheduler.capacity.LeafQueue: default used=<memory:5120, vCores:4> numContainers=4 user=ubuntu user-resources=<memory:5120, vCores:4>
2014-05-03 23:28:52,860 INFO org.apache.hadoop.yarn.server.resourcemanager.scheduler.capacity.LeafQueue: completedContainer container=Container: [ContainerId: container_1399159503039_0001_01_000004, NodeId: nodeb:35002, NodeHttpAddress: nodeb:8042, Resource: <memory:1024, vCores:1>, Priority: 20, Token: Token { kind: ContainerToken, service: 10.0.0.243:35002 }, ] resource=<memory:1024, vCores:1> queue=default: capacity=1.0, absoluteCapacity=1.0, usedResources=<memory:5120, vCores:4>usedCapacity=0.15625, absoluteUsedCapacity=0.15625, numApps=1, numContainers=4 usedCapacity=0.15625 absoluteUsedCapacity=0.15625 used=<memory:5120, vCores:4> cluster=<memory:32768, vCores:32>
2014-05-03 23:28:52,860 INFO org.apache.hadoop.yarn.server.resourcemanager.scheduler.capacity.ParentQueue: completedContainer queue=root usedCapacity=0.15625 absoluteUsedCapacity=0.15625 used=<memory:5120, vCores:4> cluster=<memory:32768, vCores:32>
2014-05-03 23:28:52,860 INFO org.apache.hadoop.yarn.server.resourcemanager.scheduler.capacity.ParentQueue: Re-sorting completed queue: root.default stats: default: capacity=1.0, absoluteCapacity=1.0, usedResources=<memory:5120, vCores:4>usedCapacity=0.15625, absoluteUsedCapacity=0.15625, numApps=1, numContainers=4
2014-05-03 23:28:52,860 INFO org.apache.hadoop.yarn.server.resourcemanager.scheduler.capacity.CapacityScheduler: Application appattempt_1399159503039_0001_000001 released container container_1399159503039_0001_01_000004 on node: host: nodeb:35002 #containers=4 available=3072 used=5120 with event: FINISHED
2014-05-03 23:28:53,050 INFO org.apache.hadoop.yarn.server.resourcemanager.rmcontainer.RMContainerImpl: container_1399159503039_0001_01_000002 Container Transitioned from RUNNING to COMPLETED
2014-05-03 23:28:53,050 INFO org.apache.hadoop.yarn.server.resourcemanager.scheduler.common.fica.FiCaSchedulerApp: Completed container: container_1399159503039_0001_01_000002 in state: COMPLETED event:FINISHED
2014-05-03 23:28:53,050 INFO org.apache.hadoop.yarn.server.resourcemanager.RMAuditLogger: USER=ubuntu	OPERATION=AM Released Container	TARGET=SchedulerApp	RESULT=SUCCESS	APPID=application_1399159503039_0001	CONTAINERID=container_1399159503039_0001_01_000002
2014-05-03 23:28:53,050 INFO org.apache.hadoop.yarn.server.resourcemanager.scheduler.common.fica.FiCaSchedulerNode: Released container container_1399159503039_0001_01_000002 of capacity <memory:1024, vCores:1> on host nodeb:35002, which currently has 3 containers, <memory:4096, vCores:3> used and <memory:4096, vCores:5> available, release resources=true
2014-05-03 23:28:53,050 INFO org.apache.hadoop.yarn.server.resourcemanager.scheduler.capacity.LeafQueue: default used=<memory:4096, vCores:3> numContainers=3 user=ubuntu user-resources=<memory:4096, vCores:3>
2014-05-03 23:28:53,050 INFO org.apache.hadoop.yarn.server.resourcemanager.scheduler.capacity.LeafQueue: completedContainer container=Container: [ContainerId: container_1399159503039_0001_01_000002, NodeId: nodeb:35002, NodeHttpAddress: nodeb:8042, Resource: <memory:1024, vCores:1>, Priority: 20, Token: Token { kind: ContainerToken, service: 10.0.0.243:35002 }, ] resource=<memory:1024, vCores:1> queue=default: capacity=1.0, absoluteCapacity=1.0, usedResources=<memory:4096, vCores:3>usedCapacity=0.125, absoluteUsedCapacity=0.125, numApps=1, numContainers=3 usedCapacity=0.125 absoluteUsedCapacity=0.125 used=<memory:4096, vCores:3> cluster=<memory:32768, vCores:32>
2014-05-03 23:28:53,051 INFO org.apache.hadoop.yarn.server.resourcemanager.scheduler.capacity.ParentQueue: completedContainer queue=root usedCapacity=0.125 absoluteUsedCapacity=0.125 used=<memory:4096, vCores:3> cluster=<memory:32768, vCores:32>
2014-05-03 23:28:53,051 INFO org.apache.hadoop.yarn.server.resourcemanager.scheduler.capacity.ParentQueue: Re-sorting completed queue: root.default stats: default: capacity=1.0, absoluteCapacity=1.0, usedResources=<memory:4096, vCores:3>usedCapacity=0.125, absoluteUsedCapacity=0.125, numApps=1, numContainers=3
2014-05-03 23:28:53,051 INFO org.apache.hadoop.yarn.server.resourcemanager.scheduler.capacity.CapacityScheduler: Application appattempt_1399159503039_0001_000001 released container container_1399159503039_0001_01_000002 on node: host: nodeb:35002 #containers=3 available=4096 used=4096 with event: FINISHED
2014-05-03 23:28:53,051 INFO org.apache.hadoop.yarn.server.resourcemanager.rmcontainer.RMContainerImpl: container_1399159503039_0001_01_000005 Container Transitioned from RUNNING to COMPLETED
2014-05-03 23:28:53,051 INFO org.apache.hadoop.yarn.server.resourcemanager.scheduler.common.fica.FiCaSchedulerApp: Completed container: container_1399159503039_0001_01_000005 in state: COMPLETED event:FINISHED
2014-05-03 23:28:53,051 INFO org.apache.hadoop.yarn.server.resourcemanager.RMAuditLogger: USER=ubuntu	OPERATION=AM Released Container	TARGET=SchedulerApp	RESULT=SUCCESS	APPID=application_1399159503039_0001	CONTAINERID=container_1399159503039_0001_01_000005
2014-05-03 23:28:53,051 INFO org.apache.hadoop.yarn.server.resourcemanager.scheduler.common.fica.FiCaSchedulerNode: Released container container_1399159503039_0001_01_000005 of capacity <memory:1024, vCores:1> on host nodeb:35002, which currently has 2 containers, <memory:3072, vCores:2> used and <memory:5120, vCores:6> available, release resources=true
2014-05-03 23:28:53,051 INFO org.apache.hadoop.yarn.server.resourcemanager.scheduler.capacity.LeafQueue: default used=<memory:3072, vCores:2> numContainers=2 user=ubuntu user-resources=<memory:3072, vCores:2>
2014-05-03 23:28:53,051 INFO org.apache.hadoop.yarn.server.resourcemanager.scheduler.capacity.LeafQueue: completedContainer container=Container: [ContainerId: container_1399159503039_0001_01_000005, NodeId: nodeb:35002, NodeHttpAddress: nodeb:8042, Resource: <memory:1024, vCores:1>, Priority: 20, Token: Token { kind: ContainerToken, service: 10.0.0.243:35002 }, ] resource=<memory:1024, vCores:1> queue=default: capacity=1.0, absoluteCapacity=1.0, usedResources=<memory:3072, vCores:2>usedCapacity=0.09375, absoluteUsedCapacity=0.09375, numApps=1, numContainers=2 usedCapacity=0.09375 absoluteUsedCapacity=0.09375 used=<memory:3072, vCores:2> cluster=<memory:32768, vCores:32>
