2014-05-05 12:16:09,024 INFO org.apache.hadoop.yarn.server.resourcemanager.ResourceManager: STARTUP_MSG: 
/************************************************************
STARTUP_MSG: Starting ResourceManager
STARTUP_MSG:   host = ip-10-0-0-195/10.0.0.195
STARTUP_MSG:   args = []
STARTUP_MSG:   version = 2.2.0
STARTUP_MSG:   build = Unknown -r Unknown; compiled by 'Joey' on 2014-03-24T00:00Z
STARTUP_MSG:   java = 1.7.0_51
************************************************************/
2014-05-05 12:16:09,033 INFO org.apache.hadoop.yarn.server.resourcemanager.ResourceManager: registered UNIX signal handlers for [TERM, HUP, INT]
2014-05-05 12:16:09,376 INFO org.apache.hadoop.yarn.server.resourcemanager.security.AMRMTokenSecretManager: Rolling master-key for amrm-tokens
2014-05-05 12:16:09,392 INFO org.apache.hadoop.yarn.server.resourcemanager.security.RMContainerTokenSecretManager: ContainerTokenKeyRollingInterval: 86400000ms and ContainerTokenKeyActivationDelay: 900000ms
2014-05-05 12:16:09,396 INFO org.apache.hadoop.yarn.server.resourcemanager.security.NMTokenSecretManagerInRM: NMTokenKeyRollingInterval: 86400000ms and NMTokenKeyActivationDelay: 900000ms
2014-05-05 12:16:09,404 INFO org.apache.hadoop.yarn.event.AsyncDispatcher: Registering class org.apache.hadoop.yarn.server.resourcemanager.recovery.RMStateStoreEventType for class org.apache.hadoop.yarn.server.resourcemanager.recovery.RMStateStore$ForwardingEventHandler
2014-05-05 12:16:10,265 INFO org.apache.hadoop.yarn.event.AsyncDispatcher: Registering class org.apache.hadoop.yarn.server.resourcemanager.NodesListManagerEventType for class org.apache.hadoop.yarn.server.resourcemanager.NodesListManager
2014-05-05 12:16:10,362 INFO org.apache.hadoop.yarn.server.resourcemanager.ResourceManager: Using Scheduler: org.apache.hadoop.yarn.server.resourcemanager.scheduler.capacity.CapacityScheduler
2014-05-05 12:16:10,646 INFO org.apache.hadoop.yarn.event.AsyncDispatcher: Registering class org.apache.hadoop.yarn.server.resourcemanager.scheduler.event.SchedulerEventType for class org.apache.hadoop.yarn.server.resourcemanager.ResourceManager$SchedulerEventDispatcher
2014-05-05 12:16:10,648 INFO org.apache.hadoop.yarn.event.AsyncDispatcher: Registering class org.apache.hadoop.yarn.server.resourcemanager.rmapp.RMAppEventType for class org.apache.hadoop.yarn.server.resourcemanager.ResourceManager$ApplicationEventDispatcher
2014-05-05 12:16:10,649 INFO org.apache.hadoop.yarn.event.AsyncDispatcher: Registering class org.apache.hadoop.yarn.server.resourcemanager.rmapp.attempt.RMAppAttemptEventType for class org.apache.hadoop.yarn.server.resourcemanager.ResourceManager$ApplicationAttemptEventDispatcher
2014-05-05 12:16:10,650 INFO org.apache.hadoop.yarn.event.AsyncDispatcher: Registering class org.apache.hadoop.yarn.server.resourcemanager.rmnode.RMNodeEventType for class org.apache.hadoop.yarn.server.resourcemanager.ResourceManager$NodeEventDispatcher
2014-05-05 12:16:10,908 INFO org.apache.hadoop.metrics2.impl.MetricsConfig: loaded properties from hadoop-metrics2.properties
2014-05-05 12:16:11,033 INFO org.apache.hadoop.metrics2.impl.MetricsSystemImpl: Scheduled snapshot period at 10 second(s).
2014-05-05 12:16:11,033 INFO org.apache.hadoop.metrics2.impl.MetricsSystemImpl: ResourceManager metrics system started
2014-05-05 12:16:11,312 INFO org.apache.hadoop.yarn.server.resourcemanager.scheduler.capacity.ParentQueue: root, capacity=1.0, asboluteCapacity=1.0, maxCapacity=1.0, asboluteMaxCapacity=1.0, state=RUNNING, acls=ADMINISTER_QUEUE:*SUBMIT_APPLICATIONS:*
2014-05-05 12:16:11,312 INFO org.apache.hadoop.yarn.server.resourcemanager.scheduler.capacity.ParentQueue: Initialized parent-queue root name=root, fullname=root
2014-05-05 12:16:11,335 INFO org.apache.hadoop.yarn.server.resourcemanager.scheduler.capacity.LeafQueue: Initializing default
capacity = 1.0 [= (float) configuredCapacity / 100 ]
asboluteCapacity = 1.0 [= parentAbsoluteCapacity * capacity ]
maxCapacity = 1.0 [= configuredMaxCapacity ]
absoluteMaxCapacity = 1.0 [= 1.0 maximumCapacity undefined, (parentAbsoluteMaxCapacity * maximumCapacity) / 100 otherwise ]
userLimit = 100 [= configuredUserLimit ]
userLimitFactor = 1.0 [= configuredUserLimitFactor ]
maxApplications = 10000 [= configuredMaximumSystemApplicationsPerQueue or (int)(configuredMaximumSystemApplications * absoluteCapacity)]
maxApplicationsPerUser = 10000 [= (int)(maxApplications * (userLimit / 100.0f) * userLimitFactor) ]
maxActiveApplications = 1 [= max((int)ceil((clusterResourceMemory / minimumAllocation) * maxAMResourcePerQueuePercent * absoluteMaxCapacity),1) ]
maxActiveAppsUsingAbsCap = 1 [= max((int)ceil((clusterResourceMemory / minimumAllocation) *maxAMResourcePercent * absoluteCapacity),1) ]
maxActiveApplicationsPerUser = 1 [= max((int)(maxActiveApplications * (userLimit / 100.0f) * userLimitFactor),1) ]
usedCapacity = 0.0 [= usedResourcesMemory / (clusterResourceMemory * absoluteCapacity)]
absoluteUsedCapacity = 0.0 [= usedResourcesMemory / clusterResourceMemory]
maxAMResourcePerQueuePercent = 0.1 [= configuredMaximumAMResourcePercent ]
minimumAllocationFactor = 0.875 [= (float)(maximumAllocationMemory - minimumAllocationMemory) / maximumAllocationMemory ]
numContainers = 0 [= currentNumContainers ]
state = RUNNING [= configuredState ]
acls = ADMINISTER_QUEUE:*SUBMIT_APPLICATIONS:* [= configuredAcls ]
nodeLocalityDelay = 0

2014-05-05 12:16:11,335 INFO org.apache.hadoop.yarn.server.resourcemanager.scheduler.capacity.CapacityScheduler: Initialized queue: default: capacity=1.0, absoluteCapacity=1.0, usedResources=<memory:0, vCores:0>usedCapacity=0.0, absoluteUsedCapacity=0.0, numApps=0, numContainers=0
2014-05-05 12:16:11,344 INFO org.apache.hadoop.yarn.server.resourcemanager.scheduler.capacity.CapacityScheduler: Initialized queue: root: numChildQueue= 1, capacity=1.0, absoluteCapacity=1.0, usedResources=<memory:0, vCores:0>usedCapacity=0.0, numApps=0, numContainers=0
2014-05-05 12:16:11,344 INFO org.apache.hadoop.yarn.server.resourcemanager.scheduler.capacity.CapacityScheduler: Initialized root queue root: numChildQueue= 1, capacity=1.0, absoluteCapacity=1.0, usedResources=<memory:0, vCores:0>usedCapacity=0.0, numApps=0, numContainers=0
2014-05-05 12:16:11,344 INFO org.apache.hadoop.yarn.server.resourcemanager.scheduler.capacity.CapacityScheduler: Initialized CapacityScheduler with calculator=class org.apache.hadoop.yarn.util.resource.DefaultResourceCalculator, minimumAllocation=<<memory:1024, vCores:1>>, maximumAllocation=<<memory:8192, vCores:32>>
2014-05-05 12:16:11,560 INFO org.apache.hadoop.yarn.event.AsyncDispatcher: Registering class org.apache.hadoop.yarn.server.resourcemanager.RMAppManagerEventType for class org.apache.hadoop.yarn.server.resourcemanager.RMAppManager
2014-05-05 12:16:11,576 INFO org.apache.hadoop.yarn.event.AsyncDispatcher: Registering class org.apache.hadoop.yarn.server.resourcemanager.amlauncher.AMLauncherEventType for class org.apache.hadoop.yarn.server.resourcemanager.amlauncher.ApplicationMasterLauncher
2014-05-05 12:16:11,579 INFO org.apache.hadoop.yarn.server.resourcemanager.RMNMInfo: Registered RMNMInfo MBean
2014-05-05 12:16:11,580 INFO org.apache.hadoop.util.HostsFileReader: Refreshing hosts (include/exclude) list
2014-05-05 12:16:11,588 INFO org.apache.hadoop.yarn.server.resourcemanager.security.AMRMTokenSecretManager: Rolling master-key for amrm-tokens
2014-05-05 12:16:11,588 INFO org.apache.hadoop.yarn.server.resourcemanager.security.RMContainerTokenSecretManager: Rolling master-key for container-tokens
2014-05-05 12:16:11,592 INFO org.apache.hadoop.yarn.server.resourcemanager.security.NMTokenSecretManagerInRM: Rolling master-key for nm-tokens
2014-05-05 12:16:11,690 INFO org.mortbay.log: Logging to org.slf4j.impl.Log4jLoggerAdapter(org.mortbay.log) via org.mortbay.log.Slf4jLog
2014-05-05 12:16:11,765 INFO org.apache.hadoop.http.HttpServer: Added global filter 'safety' (class=org.apache.hadoop.http.HttpServer$QuotingInputFilter)
2014-05-05 12:16:11,768 INFO org.apache.hadoop.http.HttpServer: Added filter static_user_filter (class=org.apache.hadoop.http.lib.StaticUserWebFilter$StaticUserFilter) to context cluster
2014-05-05 12:16:11,768 INFO org.apache.hadoop.http.HttpServer: Added filter static_user_filter (class=org.apache.hadoop.http.lib.StaticUserWebFilter$StaticUserFilter) to context static
2014-05-05 12:16:11,768 INFO org.apache.hadoop.http.HttpServer: Added filter static_user_filter (class=org.apache.hadoop.http.lib.StaticUserWebFilter$StaticUserFilter) to context logs
2014-05-05 12:16:11,774 INFO org.apache.hadoop.http.HttpServer: adding path spec: /cluster/*
2014-05-05 12:16:11,774 INFO org.apache.hadoop.http.HttpServer: adding path spec: /ws/*
2014-05-05 12:16:11,785 INFO org.apache.hadoop.http.HttpServer: Jetty bound to port 8088
2014-05-05 12:16:11,785 INFO org.mortbay.log: jetty-6.1.26
2014-05-05 12:16:11,848 INFO org.mortbay.log: Extract jar:file:/home/ubuntu/PatchedDistro/hadoop-2.2.0/share/hadoop/yarn/hadoop-yarn-common-2.2.0.jar!/webapps/cluster to /tmp/Jetty_ec2.54.186.230.200_us.west.2_compute_amazonaws_com_8088_cluster____.lsgqu1/webapp
2014-05-05 12:16:12,522 INFO org.mortbay.log: Started SelectChannelConnector@ec2-54-186-230-200.us-west-2.compute.amazonaws.com:8088
2014-05-05 12:16:12,522 INFO org.apache.hadoop.yarn.webapp.WebApps: Web app /cluster started at 8088
2014-05-05 12:16:13,720 INFO org.apache.hadoop.yarn.webapp.WebApps: Registered webapp guice modules
2014-05-05 12:16:13,722 INFO org.apache.hadoop.security.token.delegation.AbstractDelegationTokenSecretManager: Updating the current master key for generating delegation tokens
2014-05-05 12:16:13,736 INFO org.apache.hadoop.yarn.server.resourcemanager.security.RMDelegationTokenSecretManager: storing master key with keyID 1
2014-05-05 12:16:13,740 INFO org.apache.hadoop.security.token.delegation.AbstractDelegationTokenSecretManager: Starting expired delegation token remover thread, tokenRemoverScanInterval=60 min(s)
2014-05-05 12:16:13,740 INFO org.apache.hadoop.security.token.delegation.AbstractDelegationTokenSecretManager: Updating the current master key for generating delegation tokens
2014-05-05 12:16:13,740 INFO org.apache.hadoop.yarn.server.resourcemanager.security.RMDelegationTokenSecretManager: storing master key with keyID 2
2014-05-05 12:16:13,828 INFO org.apache.hadoop.ipc.Server: Starting Socket Reader #1 for port 8031
2014-05-05 12:16:13,862 INFO org.apache.hadoop.yarn.factories.impl.pb.RpcServerFactoryPBImpl: Adding protocol org.apache.hadoop.yarn.server.api.ResourceTrackerPB to the server
2014-05-05 12:16:13,868 INFO org.apache.hadoop.ipc.Server: IPC Server Responder: starting
2014-05-05 12:16:13,877 INFO org.apache.hadoop.ipc.Server: IPC Server listener on 8031: starting
2014-05-05 12:16:13,997 INFO org.apache.hadoop.ipc.Server: Starting Socket Reader #1 for port 8030
2014-05-05 12:16:14,115 INFO org.apache.hadoop.yarn.factories.impl.pb.RpcServerFactoryPBImpl: Adding protocol org.apache.hadoop.yarn.api.ApplicationMasterProtocolPB to the server
2014-05-05 12:16:14,115 INFO org.apache.hadoop.ipc.Server: IPC Server Responder: starting
2014-05-05 12:16:14,116 INFO org.apache.hadoop.ipc.Server: IPC Server listener on 8030: starting
2014-05-05 12:16:14,379 INFO org.apache.hadoop.yarn.factories.impl.pb.RpcServerFactoryPBImpl: Adding protocol org.apache.hadoop.yarn.api.ApplicationClientProtocolPB to the server
2014-05-05 12:16:14,380 INFO org.apache.hadoop.ipc.Server: Starting Socket Reader #1 for port 8032
2014-05-05 12:16:14,388 INFO org.apache.hadoop.ipc.Server: IPC Server listener on 8032: starting
2014-05-05 12:16:14,404 INFO org.apache.hadoop.ipc.Server: IPC Server Responder: starting
2014-05-05 12:16:14,414 INFO org.apache.hadoop.yarn.util.RackResolver: Resolved nodec to /default-rack
2014-05-05 12:16:14,418 INFO org.apache.hadoop.yarn.util.RackResolver: Resolved noded to /default-rack
2014-05-05 12:16:14,419 INFO org.apache.hadoop.yarn.server.resourcemanager.ResourceTrackerService: NodeManager from node noded(cmPort: 39201 httpPort: 8042) registered with capability: <memory:8192, vCores:8>, assigned nodeId noded:39201
2014-05-05 12:16:14,420 INFO org.apache.hadoop.yarn.util.RackResolver: Resolved nodeb to /default-rack
2014-05-05 12:16:14,420 INFO org.apache.hadoop.yarn.server.resourcemanager.ResourceTrackerService: NodeManager from node nodeb(cmPort: 58236 httpPort: 8042) registered with capability: <memory:8192, vCores:8>, assigned nodeId nodeb:58236
2014-05-05 12:16:14,432 INFO org.apache.hadoop.yarn.server.resourcemanager.rmnode.RMNodeImpl: nodec:56496 Node Transitioned from NEW to RUNNING
2014-05-05 12:16:14,433 INFO org.apache.hadoop.yarn.server.resourcemanager.rmnode.RMNodeImpl: noded:39201 Node Transitioned from NEW to RUNNING
2014-05-05 12:16:14,433 INFO org.apache.hadoop.yarn.server.resourcemanager.rmnode.RMNodeImpl: nodeb:58236 Node Transitioned from NEW to RUNNING
2014-05-05 12:16:14,435 INFO org.apache.hadoop.yarn.server.resourcemanager.scheduler.capacity.CapacityScheduler: Added node nodec:56496 clusterResource: <memory:8192, vCores:8>
2014-05-05 12:16:14,439 INFO org.apache.hadoop.yarn.server.resourcemanager.scheduler.capacity.CapacityScheduler: Added node noded:39201 clusterResource: <memory:16384, vCores:16>
2014-05-05 12:16:14,439 INFO org.apache.hadoop.yarn.server.resourcemanager.scheduler.capacity.CapacityScheduler: Added node nodeb:58236 clusterResource: <memory:24576, vCores:24>
2014-05-05 12:16:14,439 INFO org.apache.hadoop.yarn.server.resourcemanager.ResourceTrackerService: NodeManager from node nodec(cmPort: 56496 httpPort: 8042) registered with capability: <memory:8192, vCores:8>, assigned nodeId nodec:56496
2014-05-05 12:16:14,530 INFO org.apache.hadoop.yarn.factories.impl.pb.RpcServerFactoryPBImpl: Adding protocol org.apache.hadoop.yarn.server.api.ResourceManagerAdministrationProtocolPB to the server
2014-05-05 12:16:14,531 INFO org.apache.hadoop.ipc.Server: IPC Server Responder: starting
2014-05-05 12:16:14,534 INFO org.apache.hadoop.ipc.Server: IPC Server listener on 8033: starting
2014-05-05 12:16:14,536 INFO org.apache.hadoop.ipc.Server: Starting Socket Reader #1 for port 8033
2014-05-05 12:16:16,082 INFO org.apache.hadoop.yarn.util.RackResolver: Resolved nodea to /default-rack
2014-05-05 12:16:16,082 INFO org.apache.hadoop.yarn.server.resourcemanager.ResourceTrackerService: NodeManager from node nodea(cmPort: 36550 httpPort: 8042) registered with capability: <memory:8192, vCores:8>, assigned nodeId nodea:36550
2014-05-05 12:16:16,082 INFO org.apache.hadoop.yarn.server.resourcemanager.rmnode.RMNodeImpl: nodea:36550 Node Transitioned from NEW to RUNNING
2014-05-05 12:16:16,083 INFO org.apache.hadoop.yarn.server.resourcemanager.scheduler.capacity.CapacityScheduler: Added node nodea:36550 clusterResource: <memory:32768, vCores:32>
2014-05-05 12:16:35,309 ERROR org.apache.hadoop.security.UserGroupInformation: PriviledgedActionException as:ubuntu (auth:SIMPLE) cause:org.apache.hadoop.yarn.exceptions.ApplicationNotFoundException: Application with id 'application_1399290791848_0005' doesn't exist in RM.
2014-05-05 12:16:35,310 INFO org.apache.hadoop.ipc.Server: IPC Server handler 0 on 8032, call org.apache.hadoop.yarn.api.ApplicationClientProtocolPB.getApplicationReport from 10.0.0.195:38873 Call#397 Retry#0: error: org.apache.hadoop.yarn.exceptions.ApplicationNotFoundException: Application with id 'application_1399290791848_0005' doesn't exist in RM.
org.apache.hadoop.yarn.exceptions.ApplicationNotFoundException: Application with id 'application_1399290791848_0005' doesn't exist in RM.
	at org.apache.hadoop.yarn.server.resourcemanager.ClientRMService.getApplicationReport(ClientRMService.java:247)
	at org.apache.hadoop.yarn.api.impl.pb.service.ApplicationClientProtocolPBServiceImpl.getApplicationReport(ApplicationClientProtocolPBServiceImpl.java:120)
	at org.apache.hadoop.yarn.proto.ApplicationClientProtocol$ApplicationClientProtocolService$2.callBlockingMethod(ApplicationClientProtocol.java:241)
	at org.apache.hadoop.ipc.ProtobufRpcEngine$Server$ProtoBufRpcInvoker.call(ProtobufRpcEngine.java:585)
	at org.apache.hadoop.ipc.RPC$Server.call(RPC.java:928)
	at org.apache.hadoop.ipc.Server$Handler$1.run(Server.java:2048)
	at org.apache.hadoop.ipc.Server$Handler$1.run(Server.java:2044)
	at java.security.AccessController.doPrivileged(Native Method)
	at javax.security.auth.Subject.doAs(Subject.java:415)
	at org.apache.hadoop.security.UserGroupInformation.doAs(UserGroupInformation.java:1491)
	at org.apache.hadoop.ipc.Server$Handler.run(Server.java:2042)
2014-05-05 12:16:35,415 ERROR org.apache.hadoop.security.UserGroupInformation: PriviledgedActionException as:ubuntu (auth:SIMPLE) cause:org.apache.hadoop.yarn.exceptions.ApplicationNotFoundException: Application with id 'application_1399290791848_0005' doesn't exist in RM.
2014-05-05 12:16:35,415 INFO org.apache.hadoop.ipc.Server: IPC Server handler 1 on 8032, call org.apache.hadoop.yarn.api.ApplicationClientProtocolPB.getApplicationReport from 10.0.0.195:38873 Call#398 Retry#0: error: org.apache.hadoop.yarn.exceptions.ApplicationNotFoundException: Application with id 'application_1399290791848_0005' doesn't exist in RM.
org.apache.hadoop.yarn.exceptions.ApplicationNotFoundException: Application with id 'application_1399290791848_0005' doesn't exist in RM.
	at org.apache.hadoop.yarn.server.resourcemanager.ClientRMService.getApplicationReport(ClientRMService.java:247)
	at org.apache.hadoop.yarn.api.impl.pb.service.ApplicationClientProtocolPBServiceImpl.getApplicationReport(ApplicationClientProtocolPBServiceImpl.java:120)
	at org.apache.hadoop.yarn.proto.ApplicationClientProtocol$ApplicationClientProtocolService$2.callBlockingMethod(ApplicationClientProtocol.java:241)
	at org.apache.hadoop.ipc.ProtobufRpcEngine$Server$ProtoBufRpcInvoker.call(ProtobufRpcEngine.java:585)
	at org.apache.hadoop.ipc.RPC$Server.call(RPC.java:928)
	at org.apache.hadoop.ipc.Server$Handler$1.run(Server.java:2048)
	at org.apache.hadoop.ipc.Server$Handler$1.run(Server.java:2044)
	at java.security.AccessController.doPrivileged(Native Method)
	at javax.security.auth.Subject.doAs(Subject.java:415)
	at org.apache.hadoop.security.UserGroupInformation.doAs(UserGroupInformation.java:1491)
	at org.apache.hadoop.ipc.Server$Handler.run(Server.java:2042)
2014-05-05 12:16:35,517 ERROR org.apache.hadoop.security.UserGroupInformation: PriviledgedActionException as:ubuntu (auth:SIMPLE) cause:org.apache.hadoop.yarn.exceptions.ApplicationNotFoundException: Application with id 'application_1399290791848_0005' doesn't exist in RM.
2014-05-05 12:16:35,517 INFO org.apache.hadoop.ipc.Server: IPC Server handler 2 on 8032, call org.apache.hadoop.yarn.api.ApplicationClientProtocolPB.getApplicationReport from 10.0.0.195:38873 Call#399 Retry#0: error: org.apache.hadoop.yarn.exceptions.ApplicationNotFoundException: Application with id 'application_1399290791848_0005' doesn't exist in RM.
org.apache.hadoop.yarn.exceptions.ApplicationNotFoundException: Application with id 'application_1399290791848_0005' doesn't exist in RM.
	at org.apache.hadoop.yarn.server.resourcemanager.ClientRMService.getApplicationReport(ClientRMService.java:247)
	at org.apache.hadoop.yarn.api.impl.pb.service.ApplicationClientProtocolPBServiceImpl.getApplicationReport(ApplicationClientProtocolPBServiceImpl.java:120)
	at org.apache.hadoop.yarn.proto.ApplicationClientProtocol$ApplicationClientProtocolService$2.callBlockingMethod(ApplicationClientProtocol.java:241)
	at org.apache.hadoop.ipc.ProtobufRpcEngine$Server$ProtoBufRpcInvoker.call(ProtobufRpcEngine.java:585)
	at org.apache.hadoop.ipc.RPC$Server.call(RPC.java:928)
	at org.apache.hadoop.ipc.Server$Handler$1.run(Server.java:2048)
	at org.apache.hadoop.ipc.Server$Handler$1.run(Server.java:2044)
	at java.security.AccessController.doPrivileged(Native Method)
	at javax.security.auth.Subject.doAs(Subject.java:415)
	at org.apache.hadoop.security.UserGroupInformation.doAs(UserGroupInformation.java:1491)
	at org.apache.hadoop.ipc.Server$Handler.run(Server.java:2042)
2014-05-05 12:16:36,317 ERROR org.apache.hadoop.security.UserGroupInformation: PriviledgedActionException as:ubuntu (auth:SIMPLE) cause:org.apache.hadoop.yarn.exceptions.ApplicationNotFoundException: Application with id 'application_1399290791848_0006' doesn't exist in RM.
2014-05-05 12:16:36,317 INFO org.apache.hadoop.ipc.Server: IPC Server handler 3 on 8032, call org.apache.hadoop.yarn.api.ApplicationClientProtocolPB.getApplicationReport from 10.0.0.195:38874 Call#391 Retry#0: error: org.apache.hadoop.yarn.exceptions.ApplicationNotFoundException: Application with id 'application_1399290791848_0006' doesn't exist in RM.
org.apache.hadoop.yarn.exceptions.ApplicationNotFoundException: Application with id 'application_1399290791848_0006' doesn't exist in RM.
	at org.apache.hadoop.yarn.server.resourcemanager.ClientRMService.getApplicationReport(ClientRMService.java:247)
	at org.apache.hadoop.yarn.api.impl.pb.service.ApplicationClientProtocolPBServiceImpl.getApplicationReport(ApplicationClientProtocolPBServiceImpl.java:120)
	at org.apache.hadoop.yarn.proto.ApplicationClientProtocol$ApplicationClientProtocolService$2.callBlockingMethod(ApplicationClientProtocol.java:241)
	at org.apache.hadoop.ipc.ProtobufRpcEngine$Server$ProtoBufRpcInvoker.call(ProtobufRpcEngine.java:585)
	at org.apache.hadoop.ipc.RPC$Server.call(RPC.java:928)
	at org.apache.hadoop.ipc.Server$Handler$1.run(Server.java:2048)
	at org.apache.hadoop.ipc.Server$Handler$1.run(Server.java:2044)
	at java.security.AccessController.doPrivileged(Native Method)
	at javax.security.auth.Subject.doAs(Subject.java:415)
	at org.apache.hadoop.security.UserGroupInformation.doAs(UserGroupInformation.java:1491)
	at org.apache.hadoop.ipc.Server$Handler.run(Server.java:2042)
2014-05-05 12:16:36,421 ERROR org.apache.hadoop.security.UserGroupInformation: PriviledgedActionException as:ubuntu (auth:SIMPLE) cause:org.apache.hadoop.yarn.exceptions.ApplicationNotFoundException: Application with id 'application_1399290791848_0006' doesn't exist in RM.
2014-05-05 12:16:36,421 INFO org.apache.hadoop.ipc.Server: IPC Server handler 4 on 8032, call org.apache.hadoop.yarn.api.ApplicationClientProtocolPB.getApplicationReport from 10.0.0.195:38874 Call#392 Retry#0: error: org.apache.hadoop.yarn.exceptions.ApplicationNotFoundException: Application with id 'application_1399290791848_0006' doesn't exist in RM.
org.apache.hadoop.yarn.exceptions.ApplicationNotFoundException: Application with id 'application_1399290791848_0006' doesn't exist in RM.
	at org.apache.hadoop.yarn.server.resourcemanager.ClientRMService.getApplicationReport(ClientRMService.java:247)
	at org.apache.hadoop.yarn.api.impl.pb.service.ApplicationClientProtocolPBServiceImpl.getApplicationReport(ApplicationClientProtocolPBServiceImpl.java:120)
	at org.apache.hadoop.yarn.proto.ApplicationClientProtocol$ApplicationClientProtocolService$2.callBlockingMethod(ApplicationClientProtocol.java:241)
	at org.apache.hadoop.ipc.ProtobufRpcEngine$Server$ProtoBufRpcInvoker.call(ProtobufRpcEngine.java:585)
	at org.apache.hadoop.ipc.RPC$Server.call(RPC.java:928)
	at org.apache.hadoop.ipc.Server$Handler$1.run(Server.java:2048)
	at org.apache.hadoop.ipc.Server$Handler$1.run(Server.java:2044)
	at java.security.AccessController.doPrivileged(Native Method)
	at javax.security.auth.Subject.doAs(Subject.java:415)
	at org.apache.hadoop.security.UserGroupInformation.doAs(UserGroupInformation.java:1491)
	at org.apache.hadoop.ipc.Server$Handler.run(Server.java:2042)
2014-05-05 12:16:36,530 ERROR org.apache.hadoop.security.UserGroupInformation: PriviledgedActionException as:ubuntu (auth:SIMPLE) cause:org.apache.hadoop.yarn.exceptions.ApplicationNotFoundException: Application with id 'application_1399290791848_0006' doesn't exist in RM.
2014-05-05 12:16:36,530 INFO org.apache.hadoop.ipc.Server: IPC Server handler 5 on 8032, call org.apache.hadoop.yarn.api.ApplicationClientProtocolPB.getApplicationReport from 10.0.0.195:38874 Call#393 Retry#0: error: org.apache.hadoop.yarn.exceptions.ApplicationNotFoundException: Application with id 'application_1399290791848_0006' doesn't exist in RM.
org.apache.hadoop.yarn.exceptions.ApplicationNotFoundException: Application with id 'application_1399290791848_0006' doesn't exist in RM.
	at org.apache.hadoop.yarn.server.resourcemanager.ClientRMService.getApplicationReport(ClientRMService.java:247)
	at org.apache.hadoop.yarn.api.impl.pb.service.ApplicationClientProtocolPBServiceImpl.getApplicationReport(ApplicationClientProtocolPBServiceImpl.java:120)
	at org.apache.hadoop.yarn.proto.ApplicationClientProtocol$ApplicationClientProtocolService$2.callBlockingMethod(ApplicationClientProtocol.java:241)
	at org.apache.hadoop.ipc.ProtobufRpcEngine$Server$ProtoBufRpcInvoker.call(ProtobufRpcEngine.java:585)
	at org.apache.hadoop.ipc.RPC$Server.call(RPC.java:928)
	at org.apache.hadoop.ipc.Server$Handler$1.run(Server.java:2048)
	at org.apache.hadoop.ipc.Server$Handler$1.run(Server.java:2044)
	at java.security.AccessController.doPrivileged(Native Method)
	at javax.security.auth.Subject.doAs(Subject.java:415)
	at org.apache.hadoop.security.UserGroupInformation.doAs(UserGroupInformation.java:1491)
	at org.apache.hadoop.ipc.Server$Handler.run(Server.java:2042)
2014-05-05 12:16:56,627 INFO org.apache.hadoop.yarn.util.RackResolver: Resolved nodeh to /default-rack
2014-05-05 12:16:56,627 INFO org.apache.hadoop.yarn.server.resourcemanager.ResourceTrackerService: NodeManager from node nodeh(cmPort: 55180 httpPort: 8042) registered with capability: <memory:8192, vCores:8>, assigned nodeId nodeh:55180
2014-05-05 12:16:56,627 INFO org.apache.hadoop.yarn.server.resourcemanager.rmnode.RMNodeImpl: nodeh:55180 Node Transitioned from NEW to RUNNING
2014-05-05 12:16:56,627 INFO org.apache.hadoop.yarn.server.resourcemanager.scheduler.capacity.CapacityScheduler: Added node nodeh:55180 clusterResource: <memory:40960, vCores:40>
2014-05-05 12:16:56,667 INFO org.apache.hadoop.yarn.util.RackResolver: Resolved nodeg to /default-rack
2014-05-05 12:16:56,667 INFO org.apache.hadoop.yarn.server.resourcemanager.ResourceTrackerService: NodeManager from node nodeg(cmPort: 55490 httpPort: 8042) registered with capability: <memory:8192, vCores:8>, assigned nodeId nodeg:55490
2014-05-05 12:16:56,667 INFO org.apache.hadoop.yarn.server.resourcemanager.rmnode.RMNodeImpl: nodeg:55490 Node Transitioned from NEW to RUNNING
2014-05-05 12:16:56,668 INFO org.apache.hadoop.yarn.server.resourcemanager.scheduler.capacity.CapacityScheduler: Added node nodeg:55490 clusterResource: <memory:49152, vCores:48>
2014-05-05 12:16:56,691 INFO org.apache.hadoop.yarn.util.RackResolver: Resolved nodef to /default-rack
2014-05-05 12:16:56,691 INFO org.apache.hadoop.yarn.server.resourcemanager.ResourceTrackerService: NodeManager from node nodef(cmPort: 45920 httpPort: 8042) registered with capability: <memory:8192, vCores:8>, assigned nodeId nodef:45920
2014-05-05 12:16:56,691 INFO org.apache.hadoop.yarn.server.resourcemanager.rmnode.RMNodeImpl: nodef:45920 Node Transitioned from NEW to RUNNING
2014-05-05 12:16:56,692 INFO org.apache.hadoop.yarn.server.resourcemanager.scheduler.capacity.CapacityScheduler: Added node nodef:45920 clusterResource: <memory:57344, vCores:56>
2014-05-05 12:16:56,847 INFO org.apache.hadoop.yarn.util.RackResolver: Resolved nodee to /default-rack
2014-05-05 12:16:56,847 INFO org.apache.hadoop.yarn.server.resourcemanager.ResourceTrackerService: NodeManager from node nodee(cmPort: 50556 httpPort: 8042) registered with capability: <memory:8192, vCores:8>, assigned nodeId nodee:50556
2014-05-05 12:16:56,848 INFO org.apache.hadoop.yarn.server.resourcemanager.rmnode.RMNodeImpl: nodee:50556 Node Transitioned from NEW to RUNNING
2014-05-05 12:16:56,860 INFO org.apache.hadoop.yarn.server.resourcemanager.scheduler.capacity.CapacityScheduler: Added node nodee:50556 clusterResource: <memory:65536, vCores:64>
2014-05-05 12:18:07,998 ERROR org.apache.hadoop.yarn.server.resourcemanager.ResourceManager: RECEIVED SIGNAL 15: SIGTERM
2014-05-05 12:18:08,004 INFO org.mortbay.log: Stopped SelectChannelConnector@ec2-54-186-230-200.us-west-2.compute.amazonaws.com:8088
2014-05-05 12:18:08,104 ERROR org.apache.hadoop.security.token.delegation.AbstractDelegationTokenSecretManager: InterruptedExcpetion recieved for ExpiredTokenRemover thread java.lang.InterruptedException: sleep interrupted
2014-05-05 12:18:08,105 INFO org.apache.hadoop.metrics2.impl.MetricsSystemImpl: Stopping ResourceManager metrics system...
2014-05-05 12:18:08,107 INFO org.apache.hadoop.metrics2.impl.MetricsSystemImpl: ResourceManager metrics system stopped.
2014-05-05 12:18:08,107 INFO org.apache.hadoop.metrics2.impl.MetricsSystemImpl: ResourceManager metrics system shutdown complete.
2014-05-05 12:18:08,107 WARN org.apache.hadoop.yarn.server.resourcemanager.amlauncher.ApplicationMasterLauncher: org.apache.hadoop.yarn.server.resourcemanager.amlauncher.ApplicationMasterLauncher$LauncherThread interrupted. Returning.
2014-05-05 12:18:08,107 INFO org.apache.hadoop.ipc.Server: Stopping server on 8033
2014-05-05 12:18:08,108 INFO org.apache.hadoop.ipc.Server: Stopping IPC Server listener on 8033
2014-05-05 12:18:08,109 INFO org.apache.hadoop.ipc.Server: Stopping server on 8032
2014-05-05 12:18:08,109 INFO org.apache.hadoop.ipc.Server: Stopping IPC Server Responder
2014-05-05 12:18:08,116 INFO org.apache.hadoop.ipc.Server: Stopping IPC Server listener on 8032
2014-05-05 12:18:08,117 INFO org.apache.hadoop.ipc.Server: Stopping server on 8030
2014-05-05 12:18:08,118 INFO org.apache.hadoop.ipc.Server: Stopping IPC Server Responder
2014-05-05 12:18:08,122 INFO org.apache.hadoop.ipc.Server: Stopping IPC Server listener on 8030
2014-05-05 12:18:08,123 INFO org.apache.hadoop.ipc.Server: Stopping server on 8031
2014-05-05 12:18:08,126 INFO org.apache.hadoop.ipc.Server: Stopping IPC Server Responder
2014-05-05 12:18:08,135 INFO org.apache.hadoop.ipc.Server: Stopping IPC Server listener on 8031
2014-05-05 12:18:08,137 ERROR org.apache.hadoop.yarn.server.resourcemanager.ResourceManager: Returning, interrupted : java.lang.InterruptedException
2014-05-05 12:18:08,137 INFO org.apache.hadoop.yarn.util.AbstractLivelinessMonitor: NMLivelinessMonitor thread interrupted
2014-05-05 12:18:08,138 INFO org.apache.hadoop.ipc.Server: Stopping IPC Server Responder
2014-05-05 12:18:08,138 INFO org.apache.hadoop.yarn.util.AbstractLivelinessMonitor: AMLivelinessMonitor thread interrupted
2014-05-05 12:18:08,138 INFO org.apache.hadoop.yarn.util.AbstractLivelinessMonitor: org.apache.hadoop.yarn.server.resourcemanager.rmcontainer.ContainerAllocationExpirer thread interrupted
2014-05-05 12:18:08,138 INFO org.apache.hadoop.yarn.util.AbstractLivelinessMonitor: AMLivelinessMonitor thread interrupted
2014-05-05 12:18:08,139 INFO org.apache.hadoop.yarn.server.resourcemanager.ResourceManager: SHUTDOWN_MSG: 
/************************************************************
SHUTDOWN_MSG: Shutting down ResourceManager at ip-10-0-0-195/10.0.0.195
************************************************************/
2014-05-05 12:18:59,273 INFO org.apache.hadoop.yarn.server.resourcemanager.ResourceManager: STARTUP_MSG: 
/************************************************************
STARTUP_MSG: Starting ResourceManager
STARTUP_MSG:   host = ip-10-0-0-195/10.0.0.195
STARTUP_MSG:   args = []
STARTUP_MSG:   version = 2.2.0
STARTUP_MSG:   build = Unknown -r Unknown; compiled by 'Joey' on 2014-03-24T00:00Z
STARTUP_MSG:   java = 1.7.0_51
************************************************************/
2014-05-05 12:18:59,285 INFO org.apache.hadoop.yarn.server.resourcemanager.ResourceManager: registered UNIX signal handlers for [TERM, HUP, INT]
2014-05-05 12:18:59,623 INFO org.apache.hadoop.yarn.server.resourcemanager.security.AMRMTokenSecretManager: Rolling master-key for amrm-tokens
2014-05-05 12:18:59,638 INFO org.apache.hadoop.yarn.server.resourcemanager.security.RMContainerTokenSecretManager: ContainerTokenKeyRollingInterval: 86400000ms and ContainerTokenKeyActivationDelay: 900000ms
2014-05-05 12:18:59,642 INFO org.apache.hadoop.yarn.server.resourcemanager.security.NMTokenSecretManagerInRM: NMTokenKeyRollingInterval: 86400000ms and NMTokenKeyActivationDelay: 900000ms
2014-05-05 12:18:59,650 INFO org.apache.hadoop.yarn.event.AsyncDispatcher: Registering class org.apache.hadoop.yarn.server.resourcemanager.recovery.RMStateStoreEventType for class org.apache.hadoop.yarn.server.resourcemanager.recovery.RMStateStore$ForwardingEventHandler
2014-05-05 12:19:00,503 INFO org.apache.hadoop.yarn.event.AsyncDispatcher: Registering class org.apache.hadoop.yarn.server.resourcemanager.NodesListManagerEventType for class org.apache.hadoop.yarn.server.resourcemanager.NodesListManager
2014-05-05 12:19:00,699 INFO org.apache.hadoop.yarn.server.resourcemanager.ResourceManager: Using Scheduler: org.apache.hadoop.yarn.server.resourcemanager.scheduler.capacity.CapacityScheduler
2014-05-05 12:19:00,902 INFO org.apache.hadoop.yarn.event.AsyncDispatcher: Registering class org.apache.hadoop.yarn.server.resourcemanager.scheduler.event.SchedulerEventType for class org.apache.hadoop.yarn.server.resourcemanager.ResourceManager$SchedulerEventDispatcher
2014-05-05 12:19:00,908 INFO org.apache.hadoop.yarn.event.AsyncDispatcher: Registering class org.apache.hadoop.yarn.server.resourcemanager.rmapp.RMAppEventType for class org.apache.hadoop.yarn.server.resourcemanager.ResourceManager$ApplicationEventDispatcher
2014-05-05 12:19:00,910 INFO org.apache.hadoop.yarn.event.AsyncDispatcher: Registering class org.apache.hadoop.yarn.server.resourcemanager.rmapp.attempt.RMAppAttemptEventType for class org.apache.hadoop.yarn.server.resourcemanager.ResourceManager$ApplicationAttemptEventDispatcher
2014-05-05 12:19:00,911 INFO org.apache.hadoop.yarn.event.AsyncDispatcher: Registering class org.apache.hadoop.yarn.server.resourcemanager.rmnode.RMNodeEventType for class org.apache.hadoop.yarn.server.resourcemanager.ResourceManager$NodeEventDispatcher
2014-05-05 12:19:01,209 INFO org.apache.hadoop.metrics2.impl.MetricsConfig: loaded properties from hadoop-metrics2.properties
2014-05-05 12:19:01,356 INFO org.apache.hadoop.metrics2.impl.MetricsSystemImpl: Scheduled snapshot period at 10 second(s).
2014-05-05 12:19:01,357 INFO org.apache.hadoop.metrics2.impl.MetricsSystemImpl: ResourceManager metrics system started
2014-05-05 12:19:01,609 INFO org.apache.hadoop.yarn.server.resourcemanager.scheduler.capacity.ParentQueue: root, capacity=1.0, asboluteCapacity=1.0, maxCapacity=1.0, asboluteMaxCapacity=1.0, state=RUNNING, acls=SUBMIT_APPLICATIONS:*ADMINISTER_QUEUE:*
2014-05-05 12:19:01,624 INFO org.apache.hadoop.yarn.server.resourcemanager.scheduler.capacity.ParentQueue: Initialized parent-queue root name=root, fullname=root
2014-05-05 12:19:01,655 INFO org.apache.hadoop.yarn.server.resourcemanager.scheduler.capacity.LeafQueue: Initializing default
capacity = 1.0 [= (float) configuredCapacity / 100 ]
asboluteCapacity = 1.0 [= parentAbsoluteCapacity * capacity ]
maxCapacity = 1.0 [= configuredMaxCapacity ]
absoluteMaxCapacity = 1.0 [= 1.0 maximumCapacity undefined, (parentAbsoluteMaxCapacity * maximumCapacity) / 100 otherwise ]
userLimit = 100 [= configuredUserLimit ]
userLimitFactor = 1.0 [= configuredUserLimitFactor ]
maxApplications = 10000 [= configuredMaximumSystemApplicationsPerQueue or (int)(configuredMaximumSystemApplications * absoluteCapacity)]
maxApplicationsPerUser = 10000 [= (int)(maxApplications * (userLimit / 100.0f) * userLimitFactor) ]
maxActiveApplications = 1 [= max((int)ceil((clusterResourceMemory / minimumAllocation) * maxAMResourcePerQueuePercent * absoluteMaxCapacity),1) ]
maxActiveAppsUsingAbsCap = 1 [= max((int)ceil((clusterResourceMemory / minimumAllocation) *maxAMResourcePercent * absoluteCapacity),1) ]
maxActiveApplicationsPerUser = 1 [= max((int)(maxActiveApplications * (userLimit / 100.0f) * userLimitFactor),1) ]
usedCapacity = 0.0 [= usedResourcesMemory / (clusterResourceMemory * absoluteCapacity)]
absoluteUsedCapacity = 0.0 [= usedResourcesMemory / clusterResourceMemory]
maxAMResourcePerQueuePercent = 0.1 [= configuredMaximumAMResourcePercent ]
minimumAllocationFactor = 0.875 [= (float)(maximumAllocationMemory - minimumAllocationMemory) / maximumAllocationMemory ]
numContainers = 0 [= currentNumContainers ]
state = RUNNING [= configuredState ]
acls = SUBMIT_APPLICATIONS:*ADMINISTER_QUEUE:* [= configuredAcls ]
nodeLocalityDelay = 0

2014-05-05 12:19:01,664 INFO org.apache.hadoop.yarn.server.resourcemanager.scheduler.capacity.CapacityScheduler: Initialized queue: default: capacity=1.0, absoluteCapacity=1.0, usedResources=<memory:0, vCores:0>usedCapacity=0.0, absoluteUsedCapacity=0.0, numApps=0, numContainers=0
2014-05-05 12:19:01,664 INFO org.apache.hadoop.yarn.server.resourcemanager.scheduler.capacity.CapacityScheduler: Initialized queue: root: numChildQueue= 1, capacity=1.0, absoluteCapacity=1.0, usedResources=<memory:0, vCores:0>usedCapacity=0.0, numApps=0, numContainers=0
2014-05-05 12:19:01,664 INFO org.apache.hadoop.yarn.server.resourcemanager.scheduler.capacity.CapacityScheduler: Initialized root queue root: numChildQueue= 1, capacity=1.0, absoluteCapacity=1.0, usedResources=<memory:0, vCores:0>usedCapacity=0.0, numApps=0, numContainers=0
2014-05-05 12:19:01,664 INFO org.apache.hadoop.yarn.server.resourcemanager.scheduler.capacity.CapacityScheduler: Initialized CapacityScheduler with calculator=class org.apache.hadoop.yarn.util.resource.DefaultResourceCalculator, minimumAllocation=<<memory:1024, vCores:1>>, maximumAllocation=<<memory:8192, vCores:32>>
2014-05-05 12:19:01,868 INFO org.apache.hadoop.yarn.event.AsyncDispatcher: Registering class org.apache.hadoop.yarn.server.resourcemanager.RMAppManagerEventType for class org.apache.hadoop.yarn.server.resourcemanager.RMAppManager
2014-05-05 12:19:01,881 INFO org.apache.hadoop.yarn.event.AsyncDispatcher: Registering class org.apache.hadoop.yarn.server.resourcemanager.amlauncher.AMLauncherEventType for class org.apache.hadoop.yarn.server.resourcemanager.amlauncher.ApplicationMasterLauncher
2014-05-05 12:19:01,884 INFO org.apache.hadoop.yarn.server.resourcemanager.RMNMInfo: Registered RMNMInfo MBean
2014-05-05 12:19:01,886 INFO org.apache.hadoop.util.HostsFileReader: Refreshing hosts (include/exclude) list
2014-05-05 12:19:01,894 INFO org.apache.hadoop.yarn.server.resourcemanager.security.AMRMTokenSecretManager: Rolling master-key for amrm-tokens
2014-05-05 12:19:01,894 INFO org.apache.hadoop.yarn.server.resourcemanager.security.RMContainerTokenSecretManager: Rolling master-key for container-tokens
2014-05-05 12:19:01,897 INFO org.apache.hadoop.yarn.server.resourcemanager.security.NMTokenSecretManagerInRM: Rolling master-key for nm-tokens
2014-05-05 12:19:01,994 INFO org.mortbay.log: Logging to org.slf4j.impl.Log4jLoggerAdapter(org.mortbay.log) via org.mortbay.log.Slf4jLog
2014-05-05 12:19:02,067 INFO org.apache.hadoop.http.HttpServer: Added global filter 'safety' (class=org.apache.hadoop.http.HttpServer$QuotingInputFilter)
2014-05-05 12:19:02,071 INFO org.apache.hadoop.http.HttpServer: Added filter static_user_filter (class=org.apache.hadoop.http.lib.StaticUserWebFilter$StaticUserFilter) to context cluster
2014-05-05 12:19:02,071 INFO org.apache.hadoop.http.HttpServer: Added filter static_user_filter (class=org.apache.hadoop.http.lib.StaticUserWebFilter$StaticUserFilter) to context logs
2014-05-05 12:19:02,071 INFO org.apache.hadoop.http.HttpServer: Added filter static_user_filter (class=org.apache.hadoop.http.lib.StaticUserWebFilter$StaticUserFilter) to context static
2014-05-05 12:19:02,076 INFO org.apache.hadoop.http.HttpServer: adding path spec: /cluster/*
2014-05-05 12:19:02,077 INFO org.apache.hadoop.http.HttpServer: adding path spec: /ws/*
2014-05-05 12:19:02,087 INFO org.apache.hadoop.http.HttpServer: Jetty bound to port 8088
2014-05-05 12:19:02,088 INFO org.mortbay.log: jetty-6.1.26
2014-05-05 12:19:02,144 INFO org.mortbay.log: Extract jar:file:/home/ubuntu/PatchedDistro/hadoop-2.2.0/share/hadoop/yarn/hadoop-yarn-common-2.2.0.jar!/webapps/cluster to /tmp/Jetty_ec2.54.186.230.200_us.west.2_compute_amazonaws_com_8088_cluster____.lsgqu1/webapp
2014-05-05 12:19:02,815 INFO org.mortbay.log: Started SelectChannelConnector@ec2-54-186-230-200.us-west-2.compute.amazonaws.com:8088
2014-05-05 12:19:02,815 INFO org.apache.hadoop.yarn.webapp.WebApps: Web app /cluster started at 8088
2014-05-05 12:19:04,001 INFO org.apache.hadoop.yarn.webapp.WebApps: Registered webapp guice modules
2014-05-05 12:19:04,003 INFO org.apache.hadoop.security.token.delegation.AbstractDelegationTokenSecretManager: Updating the current master key for generating delegation tokens
2014-05-05 12:19:04,004 INFO org.apache.hadoop.yarn.server.resourcemanager.security.RMDelegationTokenSecretManager: storing master key with keyID 1
2014-05-05 12:19:04,005 INFO org.apache.hadoop.security.token.delegation.AbstractDelegationTokenSecretManager: Starting expired delegation token remover thread, tokenRemoverScanInterval=60 min(s)
2014-05-05 12:19:04,005 INFO org.apache.hadoop.security.token.delegation.AbstractDelegationTokenSecretManager: Updating the current master key for generating delegation tokens
2014-05-05 12:19:04,005 INFO org.apache.hadoop.yarn.server.resourcemanager.security.RMDelegationTokenSecretManager: storing master key with keyID 2
2014-05-05 12:19:04,060 INFO org.apache.hadoop.ipc.Server: Starting Socket Reader #1 for port 8031
2014-05-05 12:19:04,077 INFO org.apache.hadoop.yarn.factories.impl.pb.RpcServerFactoryPBImpl: Adding protocol org.apache.hadoop.yarn.server.api.ResourceTrackerPB to the server
2014-05-05 12:19:04,078 INFO org.apache.hadoop.ipc.Server: IPC Server Responder: starting
2014-05-05 12:19:04,079 INFO org.apache.hadoop.ipc.Server: IPC Server listener on 8031: starting
2014-05-05 12:19:04,148 INFO org.apache.hadoop.ipc.Server: Starting Socket Reader #1 for port 8030
2014-05-05 12:19:04,293 INFO org.apache.hadoop.yarn.factories.impl.pb.RpcServerFactoryPBImpl: Adding protocol org.apache.hadoop.yarn.api.ApplicationMasterProtocolPB to the server
2014-05-05 12:19:04,293 INFO org.apache.hadoop.ipc.Server: IPC Server Responder: starting
2014-05-05 12:19:04,304 INFO org.apache.hadoop.ipc.Server: IPC Server listener on 8030: starting
2014-05-05 12:19:04,548 INFO org.apache.hadoop.yarn.util.RackResolver: Resolved nodee to /default-rack
2014-05-05 12:19:04,552 INFO org.apache.hadoop.yarn.util.RackResolver: Resolved nodef to /default-rack
2014-05-05 12:19:04,576 INFO org.apache.hadoop.yarn.server.resourcemanager.ResourceTrackerService: NodeManager from node nodee(cmPort: 49598 httpPort: 8042) registered with capability: <memory:8192, vCores:8>, assigned nodeId nodee:49598
2014-05-05 12:19:04,578 INFO org.apache.hadoop.yarn.server.resourcemanager.rmnode.RMNodeImpl: nodee:49598 Node Transitioned from NEW to RUNNING
2014-05-05 12:19:04,578 INFO org.apache.hadoop.yarn.util.RackResolver: Resolved nodeg to /default-rack
2014-05-05 12:19:04,578 INFO org.apache.hadoop.yarn.server.resourcemanager.ResourceTrackerService: NodeManager from node nodeg(cmPort: 56763 httpPort: 8042) registered with capability: <memory:8192, vCores:8>, assigned nodeId nodeg:56763
2014-05-05 12:19:04,581 INFO org.apache.hadoop.yarn.server.resourcemanager.scheduler.capacity.CapacityScheduler: Added node nodee:49598 clusterResource: <memory:8192, vCores:8>
2014-05-05 12:19:04,582 INFO org.apache.hadoop.yarn.server.resourcemanager.rmnode.RMNodeImpl: nodeg:56763 Node Transitioned from NEW to RUNNING
2014-05-05 12:19:04,583 INFO org.apache.hadoop.yarn.server.resourcemanager.scheduler.capacity.CapacityScheduler: Added node nodeg:56763 clusterResource: <memory:16384, vCores:16>
2014-05-05 12:19:04,583 INFO org.apache.hadoop.yarn.server.resourcemanager.ResourceTrackerService: NodeManager from node nodef(cmPort: 54669 httpPort: 8042) registered with capability: <memory:8192, vCores:8>, assigned nodeId nodef:54669
2014-05-05 12:19:04,583 INFO org.apache.hadoop.yarn.server.resourcemanager.rmnode.RMNodeImpl: nodef:54669 Node Transitioned from NEW to RUNNING
2014-05-05 12:19:04,583 INFO org.apache.hadoop.yarn.server.resourcemanager.scheduler.capacity.CapacityScheduler: Added node nodef:54669 clusterResource: <memory:24576, vCores:24>
2014-05-05 12:19:04,615 INFO org.apache.hadoop.yarn.factories.impl.pb.RpcServerFactoryPBImpl: Adding protocol org.apache.hadoop.yarn.api.ApplicationClientProtocolPB to the server
2014-05-05 12:19:04,620 INFO org.apache.hadoop.ipc.Server: Starting Socket Reader #1 for port 8032
2014-05-05 12:19:04,620 INFO org.apache.hadoop.ipc.Server: IPC Server Responder: starting
2014-05-05 12:19:04,639 INFO org.apache.hadoop.ipc.Server: IPC Server listener on 8032: starting
2014-05-05 12:19:04,760 INFO org.apache.hadoop.ipc.Server: Starting Socket Reader #1 for port 8033
2014-05-05 12:19:04,763 INFO org.apache.hadoop.yarn.factories.impl.pb.RpcServerFactoryPBImpl: Adding protocol org.apache.hadoop.yarn.server.api.ResourceManagerAdministrationProtocolPB to the server
2014-05-05 12:19:04,768 INFO org.apache.hadoop.ipc.Server: IPC Server Responder: starting
2014-05-05 12:19:04,771 INFO org.apache.hadoop.ipc.Server: IPC Server listener on 8033: starting
2014-05-05 12:19:04,971 INFO org.apache.hadoop.yarn.util.RackResolver: Resolved noded to /default-rack
2014-05-05 12:19:04,971 INFO org.apache.hadoop.yarn.server.resourcemanager.ResourceTrackerService: NodeManager from node noded(cmPort: 39305 httpPort: 8042) registered with capability: <memory:8192, vCores:8>, assigned nodeId noded:39305
2014-05-05 12:19:04,971 INFO org.apache.hadoop.yarn.server.resourcemanager.rmnode.RMNodeImpl: noded:39305 Node Transitioned from NEW to RUNNING
2014-05-05 12:19:04,971 INFO org.apache.hadoop.yarn.server.resourcemanager.scheduler.capacity.CapacityScheduler: Added node noded:39305 clusterResource: <memory:32768, vCores:32>
2014-05-05 12:19:04,978 INFO org.apache.hadoop.yarn.util.RackResolver: Resolved nodec to /default-rack
2014-05-05 12:19:04,978 INFO org.apache.hadoop.yarn.server.resourcemanager.ResourceTrackerService: NodeManager from node nodec(cmPort: 35478 httpPort: 8042) registered with capability: <memory:8192, vCores:8>, assigned nodeId nodec:35478
2014-05-05 12:19:04,979 INFO org.apache.hadoop.yarn.server.resourcemanager.rmnode.RMNodeImpl: nodec:35478 Node Transitioned from NEW to RUNNING
2014-05-05 12:19:04,979 INFO org.apache.hadoop.yarn.server.resourcemanager.scheduler.capacity.CapacityScheduler: Added node nodec:35478 clusterResource: <memory:40960, vCores:40>
2014-05-05 12:19:05,024 INFO org.apache.hadoop.yarn.util.RackResolver: Resolved nodeb to /default-rack
2014-05-05 12:19:05,025 INFO org.apache.hadoop.yarn.server.resourcemanager.ResourceTrackerService: NodeManager from node nodeb(cmPort: 48885 httpPort: 8042) registered with capability: <memory:8192, vCores:8>, assigned nodeId nodeb:48885
2014-05-05 12:19:05,025 INFO org.apache.hadoop.yarn.server.resourcemanager.rmnode.RMNodeImpl: nodeb:48885 Node Transitioned from NEW to RUNNING
2014-05-05 12:19:05,025 INFO org.apache.hadoop.yarn.server.resourcemanager.scheduler.capacity.CapacityScheduler: Added node nodeb:48885 clusterResource: <memory:49152, vCores:48>
2014-05-05 12:19:05,055 INFO org.apache.hadoop.yarn.util.RackResolver: Resolved nodeh to /default-rack
2014-05-05 12:19:05,055 INFO org.apache.hadoop.yarn.server.resourcemanager.ResourceTrackerService: NodeManager from node nodeh(cmPort: 46599 httpPort: 8042) registered with capability: <memory:8192, vCores:8>, assigned nodeId nodeh:46599
2014-05-05 12:19:05,056 INFO org.apache.hadoop.yarn.server.resourcemanager.rmnode.RMNodeImpl: nodeh:46599 Node Transitioned from NEW to RUNNING
2014-05-05 12:19:05,056 INFO org.apache.hadoop.yarn.server.resourcemanager.scheduler.capacity.CapacityScheduler: Added node nodeh:46599 clusterResource: <memory:57344, vCores:56>
2014-05-05 12:19:06,310 INFO org.apache.hadoop.yarn.util.RackResolver: Resolved nodea to /default-rack
2014-05-05 12:19:06,310 INFO org.apache.hadoop.yarn.server.resourcemanager.ResourceTrackerService: NodeManager from node nodea(cmPort: 51924 httpPort: 8042) registered with capability: <memory:8192, vCores:8>, assigned nodeId nodea:51924
2014-05-05 12:19:06,310 INFO org.apache.hadoop.yarn.server.resourcemanager.rmnode.RMNodeImpl: nodea:51924 Node Transitioned from NEW to RUNNING
2014-05-05 12:19:06,310 INFO org.apache.hadoop.yarn.server.resourcemanager.scheduler.capacity.CapacityScheduler: Added node nodea:51924 clusterResource: <memory:65536, vCores:64>
2014-05-05 12:27:54,580 INFO org.apache.hadoop.yarn.server.resourcemanager.ClientRMService: Allocated new applicationId: 1
2014-05-05 12:27:56,225 INFO org.apache.hadoop.yarn.server.resourcemanager.ClientRMService: Application with id 1 submitted by user ubuntu
2014-05-05 12:27:56,225 INFO org.apache.hadoop.yarn.server.resourcemanager.rmapp.RMAppImpl: Storing application with id application_1399292339232_0001
2014-05-05 12:27:56,227 INFO org.apache.hadoop.yarn.server.resourcemanager.RMAuditLogger: USER=ubuntu	IP=10.0.0.195	OPERATION=Submit Application Request	TARGET=ClientRMService	RESULT=SUCCESS	APPID=application_1399292339232_0001
2014-05-05 12:27:56,231 INFO org.apache.hadoop.yarn.server.resourcemanager.rmapp.RMAppImpl: application_1399292339232_0001 State change from NEW to NEW_SAVING
2014-05-05 12:27:56,233 INFO org.apache.hadoop.yarn.server.resourcemanager.recovery.RMStateStore: Storing info for app: application_1399292339232_0001
2014-05-05 12:27:56,243 INFO org.apache.hadoop.yarn.server.resourcemanager.rmapp.RMAppImpl: application_1399292339232_0001 State change from NEW_SAVING to SUBMITTED
2014-05-05 12:27:56,243 INFO org.apache.hadoop.yarn.server.resourcemanager.ApplicationMasterService: Registering app attempt : appattempt_1399292339232_0001_000001
2014-05-05 12:27:56,248 INFO org.apache.hadoop.yarn.server.resourcemanager.rmapp.attempt.RMAppAttemptImpl: appattempt_1399292339232_0001_000001 State change from NEW to SUBMITTED
2014-05-05 12:27:56,267 INFO org.apache.hadoop.yarn.server.resourcemanager.scheduler.capacity.LeafQueue: Application application_1399292339232_0001 from user: ubuntu activated in queue: default
2014-05-05 12:27:56,267 INFO org.apache.hadoop.yarn.server.resourcemanager.scheduler.capacity.LeafQueue: Application added - appId: application_1399292339232_0001 user: org.apache.hadoop.yarn.server.resourcemanager.scheduler.capacity.LeafQueue$User@5605afe5, leaf-queue: default #user-pending-applications: 0 #user-active-applications: 1 #queue-pending-applications: 0 #queue-active-applications: 1
2014-05-05 12:27:56,267 INFO org.apache.hadoop.yarn.server.resourcemanager.scheduler.capacity.ParentQueue: Application added - appId: application_1399292339232_0001 user: ubuntu leaf-queue of parent: root #applications: 1
2014-05-05 12:27:56,267 INFO org.apache.hadoop.yarn.server.resourcemanager.scheduler.capacity.CapacityScheduler: Application Submission: appattempt_1399292339232_0001_000001, user: ubuntu queue: default: capacity=1.0, absoluteCapacity=1.0, usedResources=<memory:0, vCores:0>usedCapacity=0.0, absoluteUsedCapacity=0.0, numApps=1, numContainers=0, currently active: 1
2014-05-05 12:27:56,268 INFO org.apache.hadoop.yarn.server.resourcemanager.rmapp.attempt.RMAppAttemptImpl: appattempt_1399292339232_0001_000001 State change from SUBMITTED to SCHEDULED
2014-05-05 12:27:56,270 INFO org.apache.hadoop.yarn.server.resourcemanager.rmapp.RMAppImpl: application_1399292339232_0001 State change from SUBMITTED to ACCEPTED
2014-05-05 12:27:56,493 INFO org.apache.hadoop.yarn.server.resourcemanager.rmcontainer.RMContainerImpl: container_1399292339232_0001_01_000001 Container Transitioned from NEW to ALLOCATED
2014-05-05 12:27:56,494 INFO org.apache.hadoop.yarn.server.resourcemanager.RMAuditLogger: USER=ubuntu	OPERATION=AM Allocated Container	TARGET=SchedulerApp	RESULT=SUCCESS	APPID=application_1399292339232_0001	CONTAINERID=container_1399292339232_0001_01_000001
2014-05-05 12:27:56,494 INFO org.apache.hadoop.yarn.server.resourcemanager.scheduler.common.fica.FiCaSchedulerNode: Assigned container container_1399292339232_0001_01_000001 of capacity <memory:2048, vCores:1> on host nodef:54669, which currently has 1 containers, <memory:2048, vCores:1> used and <memory:6144, vCores:7> available
2014-05-05 12:27:56,494 INFO org.apache.hadoop.yarn.server.resourcemanager.scheduler.capacity.LeafQueue: assignedContainer application=application_1399292339232_0001 container=Container: [ContainerId: container_1399292339232_0001_01_000001, NodeId: nodef:54669, NodeHttpAddress: nodef:8042, Resource: <memory:2048, vCores:1>, Priority: 0, Token: Token { kind: ContainerToken, service: 10.0.0.199:54669 }, ] containerId=container_1399292339232_0001_01_000001 queue=default: capacity=1.0, absoluteCapacity=1.0, usedResources=<memory:0, vCores:0>usedCapacity=0.0, absoluteUsedCapacity=0.0, numApps=1, numContainers=0 usedCapacity=0.0 absoluteUsedCapacity=0.0 used=<memory:0, vCores:0> cluster=<memory:65536, vCores:64>
2014-05-05 12:27:56,494 INFO org.apache.hadoop.yarn.server.resourcemanager.scheduler.capacity.ParentQueue: Re-sorting assigned queue: root.default stats: default: capacity=1.0, absoluteCapacity=1.0, usedResources=<memory:2048, vCores:1>usedCapacity=0.03125, absoluteUsedCapacity=0.03125, numApps=1, numContainers=1
2014-05-05 12:27:56,494 INFO org.apache.hadoop.yarn.server.resourcemanager.scheduler.capacity.ParentQueue: assignedContainer queue=root usedCapacity=0.03125 absoluteUsedCapacity=0.03125 used=<memory:2048, vCores:1> cluster=<memory:65536, vCores:64>
2014-05-05 12:27:56,495 INFO org.apache.hadoop.yarn.server.resourcemanager.rmcontainer.RMContainerImpl: container_1399292339232_0001_01_000001 Container Transitioned from ALLOCATED to ACQUIRED
2014-05-05 12:27:56,497 INFO org.apache.hadoop.yarn.server.resourcemanager.rmapp.attempt.RMAppAttemptImpl: Storing attempt: AppId: application_1399292339232_0001 AttemptId: appattempt_1399292339232_0001_000001 MasterContainer: Container: [ContainerId: container_1399292339232_0001_01_000001, NodeId: nodef:54669, NodeHttpAddress: nodef:8042, Resource: <memory:2048, vCores:1>, Priority: 0, Token: Token { kind: ContainerToken, service: 10.0.0.199:54669 }, ]
2014-05-05 12:27:56,501 INFO org.apache.hadoop.yarn.server.resourcemanager.rmapp.attempt.RMAppAttemptImpl: appattempt_1399292339232_0001_000001 State change from SCHEDULED to ALLOCATED_SAVING
2014-05-05 12:27:56,506 INFO org.apache.hadoop.yarn.server.resourcemanager.recovery.RMStateStore: Storing info for attempt: appattempt_1399292339232_0001_000001
2014-05-05 12:27:56,507 INFO org.apache.hadoop.yarn.server.resourcemanager.rmapp.attempt.RMAppAttemptImpl: appattempt_1399292339232_0001_000001 State change from ALLOCATED_SAVING to ALLOCATED
2014-05-05 12:27:56,509 INFO org.apache.hadoop.yarn.server.resourcemanager.amlauncher.AMLauncher: Launching masterappattempt_1399292339232_0001_000001
2014-05-05 12:27:56,538 INFO org.apache.hadoop.yarn.server.resourcemanager.amlauncher.AMLauncher: Setting up container Container: [ContainerId: container_1399292339232_0001_01_000001, NodeId: nodef:54669, NodeHttpAddress: nodef:8042, Resource: <memory:2048, vCores:1>, Priority: 0, Token: Token { kind: ContainerToken, service: 10.0.0.199:54669 }, ] for AM appattempt_1399292339232_0001_000001
2014-05-05 12:27:56,539 INFO org.apache.hadoop.yarn.server.resourcemanager.amlauncher.AMLauncher: Command to launch container container_1399292339232_0001_01_000001 : $JAVA_HOME/bin/java -Dlog4j.configuration=container-log4j.properties -Dyarn.app.container.log.dir=<LOG_DIR> -Dyarn.app.container.log.filesize=0 -Dhadoop.root.logger=INFO,CLA  -Xmx1024m org.apache.hadoop.mapreduce.v2.app.MRAppMaster 1><LOG_DIR>/stdout 2><LOG_DIR>/stderr 
2014-05-05 12:27:56,965 INFO org.apache.hadoop.yarn.server.resourcemanager.amlauncher.AMLauncher: Done launching container Container: [ContainerId: container_1399292339232_0001_01_000001, NodeId: nodef:54669, NodeHttpAddress: nodef:8042, Resource: <memory:2048, vCores:1>, Priority: 0, Token: Token { kind: ContainerToken, service: 10.0.0.199:54669 }, ] for AM appattempt_1399292339232_0001_000001
2014-05-05 12:27:56,966 INFO org.apache.hadoop.yarn.server.resourcemanager.rmapp.attempt.RMAppAttemptImpl: appattempt_1399292339232_0001_000001 State change from ALLOCATED to LAUNCHED
2014-05-05 12:27:57,494 INFO org.apache.hadoop.yarn.server.resourcemanager.rmcontainer.RMContainerImpl: container_1399292339232_0001_01_000001 Container Transitioned from ACQUIRED to RUNNING
2014-05-05 12:28:03,852 INFO SecurityLogger.org.apache.hadoop.ipc.Server: Auth successful for appattempt_1399292339232_0001_000001 (auth:SIMPLE)
2014-05-05 12:28:03,859 INFO org.apache.hadoop.yarn.server.resourcemanager.ApplicationMasterService: AM registration appattempt_1399292339232_0001_000001
2014-05-05 12:28:03,860 INFO org.apache.hadoop.yarn.server.resourcemanager.RMAuditLogger: USER=ubuntu	IP=10.0.0.199	OPERATION=Register App Master	TARGET=ApplicationMasterService	RESULT=SUCCESS	APPID=application_1399292339232_0001	APPATTEMPTID=appattempt_1399292339232_0001_000001
2014-05-05 12:28:03,860 INFO org.apache.hadoop.yarn.server.resourcemanager.rmapp.attempt.RMAppAttemptImpl: appattempt_1399292339232_0001_000001 State change from LAUNCHED to RUNNING
2014-05-05 12:28:03,860 INFO org.apache.hadoop.yarn.server.resourcemanager.rmapp.RMAppImpl: application_1399292339232_0001 State change from ACCEPTED to RUNNING
2014-05-05 12:28:05,056 INFO org.apache.hadoop.yarn.server.resourcemanager.rmcontainer.RMContainerImpl: container_1399292339232_0001_01_000002 Container Transitioned from NEW to ALLOCATED
2014-05-05 12:28:05,056 INFO org.apache.hadoop.yarn.server.resourcemanager.RMAuditLogger: USER=ubuntu	OPERATION=AM Allocated Container	TARGET=SchedulerApp	RESULT=SUCCESS	APPID=application_1399292339232_0001	CONTAINERID=container_1399292339232_0001_01_000002
2014-05-05 12:28:05,056 INFO org.apache.hadoop.yarn.server.resourcemanager.scheduler.common.fica.FiCaSchedulerNode: Assigned container container_1399292339232_0001_01_000002 of capacity <memory:1024, vCores:1> on host nodea:51924, which currently has 1 containers, <memory:1024, vCores:1> used and <memory:7168, vCores:7> available
2014-05-05 12:28:05,056 INFO org.apache.hadoop.yarn.server.resourcemanager.scheduler.capacity.LeafQueue: assignedContainer application=application_1399292339232_0001 container=Container: [ContainerId: container_1399292339232_0001_01_000002, NodeId: nodea:51924, NodeHttpAddress: nodea:8042, Resource: <memory:1024, vCores:1>, Priority: 20, Token: Token { kind: ContainerToken, service: 10.0.0.195:51924 }, ] containerId=container_1399292339232_0001_01_000002 queue=default: capacity=1.0, absoluteCapacity=1.0, usedResources=<memory:2048, vCores:1>usedCapacity=0.03125, absoluteUsedCapacity=0.03125, numApps=1, numContainers=1 usedCapacity=0.03125 absoluteUsedCapacity=0.03125 used=<memory:2048, vCores:1> cluster=<memory:65536, vCores:64>
2014-05-05 12:28:05,056 INFO org.apache.hadoop.yarn.server.resourcemanager.scheduler.capacity.ParentQueue: Re-sorting assigned queue: root.default stats: default: capacity=1.0, absoluteCapacity=1.0, usedResources=<memory:3072, vCores:2>usedCapacity=0.046875, absoluteUsedCapacity=0.046875, numApps=1, numContainers=2
2014-05-05 12:28:05,056 INFO org.apache.hadoop.yarn.server.resourcemanager.scheduler.capacity.ParentQueue: assignedContainer queue=root usedCapacity=0.046875 absoluteUsedCapacity=0.046875 used=<memory:3072, vCores:2> cluster=<memory:65536, vCores:64>
2014-05-05 12:28:05,057 INFO org.apache.hadoop.yarn.server.resourcemanager.rmcontainer.RMContainerImpl: container_1399292339232_0001_01_000003 Container Transitioned from NEW to ALLOCATED
2014-05-05 12:28:05,057 INFO org.apache.hadoop.yarn.server.resourcemanager.RMAuditLogger: USER=ubuntu	OPERATION=AM Allocated Container	TARGET=SchedulerApp	RESULT=SUCCESS	APPID=application_1399292339232_0001	CONTAINERID=container_1399292339232_0001_01_000003
2014-05-05 12:28:05,057 INFO org.apache.hadoop.yarn.server.resourcemanager.scheduler.common.fica.FiCaSchedulerNode: Assigned container container_1399292339232_0001_01_000003 of capacity <memory:1024, vCores:1> on host nodea:51924, which currently has 2 containers, <memory:2048, vCores:2> used and <memory:6144, vCores:6> available
2014-05-05 12:28:05,057 INFO org.apache.hadoop.yarn.server.resourcemanager.scheduler.capacity.LeafQueue: assignedContainer application=application_1399292339232_0001 container=Container: [ContainerId: container_1399292339232_0001_01_000003, NodeId: nodea:51924, NodeHttpAddress: nodea:8042, Resource: <memory:1024, vCores:1>, Priority: 20, Token: Token { kind: ContainerToken, service: 10.0.0.195:51924 }, ] containerId=container_1399292339232_0001_01_000003 queue=default: capacity=1.0, absoluteCapacity=1.0, usedResources=<memory:3072, vCores:2>usedCapacity=0.046875, absoluteUsedCapacity=0.046875, numApps=1, numContainers=2 usedCapacity=0.046875 absoluteUsedCapacity=0.046875 used=<memory:3072, vCores:2> cluster=<memory:65536, vCores:64>
2014-05-05 12:28:05,057 INFO org.apache.hadoop.yarn.server.resourcemanager.scheduler.capacity.ParentQueue: Re-sorting assigned queue: root.default stats: default: capacity=1.0, absoluteCapacity=1.0, usedResources=<memory:4096, vCores:3>usedCapacity=0.0625, absoluteUsedCapacity=0.0625, numApps=1, numContainers=3
2014-05-05 12:28:05,057 INFO org.apache.hadoop.yarn.server.resourcemanager.scheduler.capacity.ParentQueue: assignedContainer queue=root usedCapacity=0.0625 absoluteUsedCapacity=0.0625 used=<memory:4096, vCores:3> cluster=<memory:65536, vCores:64>
2014-05-05 12:28:05,058 INFO org.apache.hadoop.yarn.server.resourcemanager.rmcontainer.RMContainerImpl: container_1399292339232_0001_01_000004 Container Transitioned from NEW to ALLOCATED
2014-05-05 12:28:05,058 INFO org.apache.hadoop.yarn.server.resourcemanager.RMAuditLogger: USER=ubuntu	OPERATION=AM Allocated Container	TARGET=SchedulerApp	RESULT=SUCCESS	APPID=application_1399292339232_0001	CONTAINERID=container_1399292339232_0001_01_000004
2014-05-05 12:28:05,058 INFO org.apache.hadoop.yarn.server.resourcemanager.scheduler.common.fica.FiCaSchedulerNode: Assigned container container_1399292339232_0001_01_000004 of capacity <memory:1024, vCores:1> on host nodea:51924, which currently has 3 containers, <memory:3072, vCores:3> used and <memory:5120, vCores:5> available
2014-05-05 12:28:05,058 INFO org.apache.hadoop.yarn.server.resourcemanager.scheduler.capacity.LeafQueue: assignedContainer application=application_1399292339232_0001 container=Container: [ContainerId: container_1399292339232_0001_01_000004, NodeId: nodea:51924, NodeHttpAddress: nodea:8042, Resource: <memory:1024, vCores:1>, Priority: 20, Token: Token { kind: ContainerToken, service: 10.0.0.195:51924 }, ] containerId=container_1399292339232_0001_01_000004 queue=default: capacity=1.0, absoluteCapacity=1.0, usedResources=<memory:4096, vCores:3>usedCapacity=0.0625, absoluteUsedCapacity=0.0625, numApps=1, numContainers=3 usedCapacity=0.0625 absoluteUsedCapacity=0.0625 used=<memory:4096, vCores:3> cluster=<memory:65536, vCores:64>
2014-05-05 12:28:05,058 INFO org.apache.hadoop.yarn.server.resourcemanager.scheduler.capacity.ParentQueue: Re-sorting assigned queue: root.default stats: default: capacity=1.0, absoluteCapacity=1.0, usedResources=<memory:5120, vCores:4>usedCapacity=0.078125, absoluteUsedCapacity=0.078125, numApps=1, numContainers=4
2014-05-05 12:28:05,058 INFO org.apache.hadoop.yarn.server.resourcemanager.scheduler.capacity.ParentQueue: assignedContainer queue=root usedCapacity=0.078125 absoluteUsedCapacity=0.078125 used=<memory:5120, vCores:4> cluster=<memory:65536, vCores:64>
2014-05-05 12:28:05,059 INFO org.apache.hadoop.yarn.server.resourcemanager.rmcontainer.RMContainerImpl: container_1399292339232_0001_01_000005 Container Transitioned from NEW to ALLOCATED
2014-05-05 12:28:05,059 INFO org.apache.hadoop.yarn.server.resourcemanager.RMAuditLogger: USER=ubuntu	OPERATION=AM Allocated Container	TARGET=SchedulerApp	RESULT=SUCCESS	APPID=application_1399292339232_0001	CONTAINERID=container_1399292339232_0001_01_000005
2014-05-05 12:28:05,059 INFO org.apache.hadoop.yarn.server.resourcemanager.scheduler.common.fica.FiCaSchedulerNode: Assigned container container_1399292339232_0001_01_000005 of capacity <memory:1024, vCores:1> on host nodea:51924, which currently has 4 containers, <memory:4096, vCores:4> used and <memory:4096, vCores:4> available
2014-05-05 12:28:05,059 INFO org.apache.hadoop.yarn.server.resourcemanager.scheduler.capacity.LeafQueue: assignedContainer application=application_1399292339232_0001 container=Container: [ContainerId: container_1399292339232_0001_01_000005, NodeId: nodea:51924, NodeHttpAddress: nodea:8042, Resource: <memory:1024, vCores:1>, Priority: 20, Token: Token { kind: ContainerToken, service: 10.0.0.195:51924 }, ] containerId=container_1399292339232_0001_01_000005 queue=default: capacity=1.0, absoluteCapacity=1.0, usedResources=<memory:5120, vCores:4>usedCapacity=0.078125, absoluteUsedCapacity=0.078125, numApps=1, numContainers=4 usedCapacity=0.078125 absoluteUsedCapacity=0.078125 used=<memory:5120, vCores:4> cluster=<memory:65536, vCores:64>
2014-05-05 12:28:05,059 INFO org.apache.hadoop.yarn.server.resourcemanager.scheduler.capacity.ParentQueue: Re-sorting assigned queue: root.default stats: default: capacity=1.0, absoluteCapacity=1.0, usedResources=<memory:6144, vCores:5>usedCapacity=0.09375, absoluteUsedCapacity=0.09375, numApps=1, numContainers=5
2014-05-05 12:28:05,059 INFO org.apache.hadoop.yarn.server.resourcemanager.scheduler.capacity.ParentQueue: assignedContainer queue=root usedCapacity=0.09375 absoluteUsedCapacity=0.09375 used=<memory:6144, vCores:5> cluster=<memory:65536, vCores:64>
2014-05-05 12:28:05,987 INFO org.apache.hadoop.yarn.server.resourcemanager.rmcontainer.RMContainerImpl: container_1399292339232_0001_01_000002 Container Transitioned from ALLOCATED to ACQUIRED
2014-05-05 12:28:05,987 INFO org.apache.hadoop.yarn.server.resourcemanager.rmcontainer.RMContainerImpl: container_1399292339232_0001_01_000003 Container Transitioned from ALLOCATED to ACQUIRED
2014-05-05 12:28:05,987 INFO org.apache.hadoop.yarn.server.resourcemanager.rmcontainer.RMContainerImpl: container_1399292339232_0001_01_000004 Container Transitioned from ALLOCATED to ACQUIRED
2014-05-05 12:28:05,988 INFO org.apache.hadoop.yarn.server.resourcemanager.rmcontainer.RMContainerImpl: container_1399292339232_0001_01_000005 Container Transitioned from ALLOCATED to ACQUIRED
2014-05-05 12:28:07,008 INFO org.apache.hadoop.yarn.server.resourcemanager.scheduler.AppSchedulingInfo: checking for deactivate... 
2014-05-05 12:28:07,101 INFO org.apache.hadoop.yarn.server.resourcemanager.rmcontainer.RMContainerImpl: container_1399292339232_0001_01_000002 Container Transitioned from ACQUIRED to RUNNING
2014-05-05 12:28:07,102 INFO org.apache.hadoop.yarn.server.resourcemanager.rmcontainer.RMContainerImpl: container_1399292339232_0001_01_000003 Container Transitioned from ACQUIRED to RUNNING
2014-05-05 12:28:07,102 INFO org.apache.hadoop.yarn.server.resourcemanager.rmcontainer.RMContainerImpl: container_1399292339232_0001_01_000004 Container Transitioned from ACQUIRED to RUNNING
2014-05-05 12:28:07,102 INFO org.apache.hadoop.yarn.server.resourcemanager.rmcontainer.RMContainerImpl: container_1399292339232_0001_01_000005 Container Transitioned from ACQUIRED to RUNNING
2014-05-05 12:28:38,547 INFO org.apache.hadoop.yarn.server.resourcemanager.rmcontainer.RMContainerImpl: container_1399292339232_0001_01_000006 Container Transitioned from NEW to ALLOCATED
2014-05-05 12:28:38,547 INFO org.apache.hadoop.yarn.server.resourcemanager.RMAuditLogger: USER=ubuntu	OPERATION=AM Allocated Container	TARGET=SchedulerApp	RESULT=SUCCESS	APPID=application_1399292339232_0001	CONTAINERID=container_1399292339232_0001_01_000006
2014-05-05 12:28:38,548 INFO org.apache.hadoop.yarn.server.resourcemanager.scheduler.common.fica.FiCaSchedulerNode: Assigned container container_1399292339232_0001_01_000006 of capacity <memory:1024, vCores:1> on host nodee:49598, which currently has 1 containers, <memory:1024, vCores:1> used and <memory:7168, vCores:7> available
2014-05-05 12:28:38,548 INFO org.apache.hadoop.yarn.server.resourcemanager.scheduler.capacity.LeafQueue: assignedContainer application=application_1399292339232_0001 container=Container: [ContainerId: container_1399292339232_0001_01_000006, NodeId: nodee:49598, NodeHttpAddress: nodee:8042, Resource: <memory:1024, vCores:1>, Priority: 20, Token: Token { kind: ContainerToken, service: 10.0.0.198:49598 }, ] containerId=container_1399292339232_0001_01_000006 queue=default: capacity=1.0, absoluteCapacity=1.0, usedResources=<memory:6144, vCores:5>usedCapacity=0.09375, absoluteUsedCapacity=0.09375, numApps=1, numContainers=5 usedCapacity=0.09375 absoluteUsedCapacity=0.09375 used=<memory:6144, vCores:5> cluster=<memory:65536, vCores:64>
2014-05-05 12:28:38,548 INFO org.apache.hadoop.yarn.server.resourcemanager.scheduler.capacity.ParentQueue: Re-sorting assigned queue: root.default stats: default: capacity=1.0, absoluteCapacity=1.0, usedResources=<memory:7168, vCores:6>usedCapacity=0.109375, absoluteUsedCapacity=0.109375, numApps=1, numContainers=6
2014-05-05 12:28:38,548 INFO org.apache.hadoop.yarn.server.resourcemanager.scheduler.capacity.ParentQueue: assignedContainer queue=root usedCapacity=0.109375 absoluteUsedCapacity=0.109375 used=<memory:7168, vCores:6> cluster=<memory:65536, vCores:64>
2014-05-05 12:28:38,686 INFO org.apache.hadoop.yarn.server.resourcemanager.rmcontainer.RMContainerImpl: container_1399292339232_0001_01_000005 Container Transitioned from RUNNING to COMPLETED
2014-05-05 12:28:38,686 INFO org.apache.hadoop.yarn.server.resourcemanager.scheduler.common.fica.FiCaSchedulerApp: Completed container: container_1399292339232_0001_01_000005 in state: COMPLETED event:FINISHED
2014-05-05 12:28:38,686 INFO org.apache.hadoop.yarn.server.resourcemanager.RMAuditLogger: USER=ubuntu	OPERATION=AM Released Container	TARGET=SchedulerApp	RESULT=SUCCESS	APPID=application_1399292339232_0001	CONTAINERID=container_1399292339232_0001_01_000005
2014-05-05 12:28:38,686 INFO org.apache.hadoop.yarn.server.resourcemanager.scheduler.common.fica.FiCaSchedulerNode: Released container container_1399292339232_0001_01_000005 of capacity <memory:1024, vCores:1> on host nodea:51924, which currently has 3 containers, <memory:3072, vCores:3> used and <memory:5120, vCores:5> available, release resources=true
2014-05-05 12:28:38,686 INFO org.apache.hadoop.yarn.server.resourcemanager.scheduler.capacity.LeafQueue: default used=<memory:6144, vCores:5> numContainers=5 user=ubuntu user-resources=<memory:6144, vCores:5>
2014-05-05 12:28:38,687 INFO org.apache.hadoop.yarn.server.resourcemanager.scheduler.capacity.LeafQueue: completedContainer container=Container: [ContainerId: container_1399292339232_0001_01_000005, NodeId: nodea:51924, NodeHttpAddress: nodea:8042, Resource: <memory:1024, vCores:1>, Priority: 20, Token: Token { kind: ContainerToken, service: 10.0.0.195:51924 }, ] resource=<memory:1024, vCores:1> queue=default: capacity=1.0, absoluteCapacity=1.0, usedResources=<memory:6144, vCores:5>usedCapacity=0.09375, absoluteUsedCapacity=0.09375, numApps=1, numContainers=5 usedCapacity=0.09375 absoluteUsedCapacity=0.09375 used=<memory:6144, vCores:5> cluster=<memory:65536, vCores:64>
2014-05-05 12:28:38,687 INFO org.apache.hadoop.yarn.server.resourcemanager.scheduler.capacity.ParentQueue: completedContainer queue=root usedCapacity=0.09375 absoluteUsedCapacity=0.09375 used=<memory:6144, vCores:5> cluster=<memory:65536, vCores:64>
2014-05-05 12:28:38,687 INFO org.apache.hadoop.yarn.server.resourcemanager.scheduler.capacity.ParentQueue: Re-sorting completed queue: root.default stats: default: capacity=1.0, absoluteCapacity=1.0, usedResources=<memory:6144, vCores:5>usedCapacity=0.09375, absoluteUsedCapacity=0.09375, numApps=1, numContainers=5
2014-05-05 12:28:38,687 INFO org.apache.hadoop.yarn.server.resourcemanager.scheduler.capacity.CapacityScheduler: Application appattempt_1399292339232_0001_000001 released container container_1399292339232_0001_01_000005 on node: host: nodea:51924 #containers=3 available=5120 used=3072 with event: FINISHED
2014-05-05 12:28:39,336 INFO org.apache.hadoop.yarn.server.resourcemanager.rmcontainer.RMContainerImpl: container_1399292339232_0001_01_000006 Container Transitioned from ALLOCATED to ACQUIRED
2014-05-05 12:28:39,549 INFO org.apache.hadoop.yarn.server.resourcemanager.rmcontainer.RMContainerImpl: container_1399292339232_0001_01_000007 Container Transitioned from NEW to ALLOCATED
2014-05-05 12:28:39,549 INFO org.apache.hadoop.yarn.server.resourcemanager.RMAuditLogger: USER=ubuntu	OPERATION=AM Allocated Container	TARGET=SchedulerApp	RESULT=SUCCESS	APPID=application_1399292339232_0001	CONTAINERID=container_1399292339232_0001_01_000007
2014-05-05 12:28:39,549 INFO org.apache.hadoop.yarn.server.resourcemanager.scheduler.common.fica.FiCaSchedulerNode: Assigned container container_1399292339232_0001_01_000007 of capacity <memory:1024, vCores:1> on host nodee:49598, which currently has 2 containers, <memory:2048, vCores:2> used and <memory:6144, vCores:6> available
2014-05-05 12:28:39,549 INFO org.apache.hadoop.yarn.server.resourcemanager.scheduler.capacity.LeafQueue: assignedContainer application=application_1399292339232_0001 container=Container: [ContainerId: container_1399292339232_0001_01_000007, NodeId: nodee:49598, NodeHttpAddress: nodee:8042, Resource: <memory:1024, vCores:1>, Priority: 10, Token: Token { kind: ContainerToken, service: 10.0.0.198:49598 }, ] containerId=container_1399292339232_0001_01_000007 queue=default: capacity=1.0, absoluteCapacity=1.0, usedResources=<memory:6144, vCores:5>usedCapacity=0.09375, absoluteUsedCapacity=0.09375, numApps=1, numContainers=5 usedCapacity=0.09375 absoluteUsedCapacity=0.09375 used=<memory:6144, vCores:5> cluster=<memory:65536, vCores:64>
2014-05-05 12:28:39,549 INFO org.apache.hadoop.yarn.server.resourcemanager.scheduler.capacity.ParentQueue: Re-sorting assigned queue: root.default stats: default: capacity=1.0, absoluteCapacity=1.0, usedResources=<memory:7168, vCores:6>usedCapacity=0.109375, absoluteUsedCapacity=0.109375, numApps=1, numContainers=6
2014-05-05 12:28:39,549 INFO org.apache.hadoop.yarn.server.resourcemanager.scheduler.capacity.ParentQueue: assignedContainer queue=root usedCapacity=0.109375 absoluteUsedCapacity=0.109375 used=<memory:7168, vCores:6> cluster=<memory:65536, vCores:64>
2014-05-05 12:28:39,551 INFO org.apache.hadoop.yarn.server.resourcemanager.rmcontainer.RMContainerImpl: container_1399292339232_0001_01_000008 Container Transitioned from NEW to ALLOCATED
2014-05-05 12:28:39,551 INFO org.apache.hadoop.yarn.server.resourcemanager.RMAuditLogger: USER=ubuntu	OPERATION=AM Allocated Container	TARGET=SchedulerApp	RESULT=SUCCESS	APPID=application_1399292339232_0001	CONTAINERID=container_1399292339232_0001_01_000008
2014-05-05 12:28:39,551 INFO org.apache.hadoop.yarn.server.resourcemanager.scheduler.common.fica.FiCaSchedulerNode: Assigned container container_1399292339232_0001_01_000008 of capacity <memory:1024, vCores:1> on host nodeg:56763, which currently has 1 containers, <memory:1024, vCores:1> used and <memory:7168, vCores:7> available
2014-05-05 12:28:39,551 INFO org.apache.hadoop.yarn.server.resourcemanager.scheduler.capacity.LeafQueue: assignedContainer application=application_1399292339232_0001 container=Container: [ContainerId: container_1399292339232_0001_01_000008, NodeId: nodeg:56763, NodeHttpAddress: nodeg:8042, Resource: <memory:1024, vCores:1>, Priority: 10, Token: Token { kind: ContainerToken, service: 10.0.0.196:56763 }, ] containerId=container_1399292339232_0001_01_000008 queue=default: capacity=1.0, absoluteCapacity=1.0, usedResources=<memory:7168, vCores:6>usedCapacity=0.109375, absoluteUsedCapacity=0.109375, numApps=1, numContainers=6 usedCapacity=0.109375 absoluteUsedCapacity=0.109375 used=<memory:7168, vCores:6> cluster=<memory:65536, vCores:64>
2014-05-05 12:28:39,551 INFO org.apache.hadoop.yarn.server.resourcemanager.scheduler.capacity.ParentQueue: Re-sorting assigned queue: root.default stats: default: capacity=1.0, absoluteCapacity=1.0, usedResources=<memory:8192, vCores:7>usedCapacity=0.125, absoluteUsedCapacity=0.125, numApps=1, numContainers=7
2014-05-05 12:28:39,551 INFO org.apache.hadoop.yarn.server.resourcemanager.scheduler.capacity.ParentQueue: assignedContainer queue=root usedCapacity=0.125 absoluteUsedCapacity=0.125 used=<memory:8192, vCores:7> cluster=<memory:65536, vCores:64>
2014-05-05 12:28:39,678 INFO org.apache.hadoop.yarn.server.resourcemanager.rmcontainer.RMContainerImpl: container_1399292339232_0001_01_000009 Container Transitioned from NEW to ALLOCATED
2014-05-05 12:28:39,678 INFO org.apache.hadoop.yarn.server.resourcemanager.RMAuditLogger: USER=ubuntu	OPERATION=AM Allocated Container	TARGET=SchedulerApp	RESULT=SUCCESS	APPID=application_1399292339232_0001	CONTAINERID=container_1399292339232_0001_01_000009
2014-05-05 12:28:39,678 INFO org.apache.hadoop.yarn.server.resourcemanager.scheduler.common.fica.FiCaSchedulerNode: Assigned container container_1399292339232_0001_01_000009 of capacity <memory:1024, vCores:1> on host nodef:54669, which currently has 2 containers, <memory:3072, vCores:2> used and <memory:5120, vCores:6> available
2014-05-05 12:28:39,678 INFO org.apache.hadoop.yarn.server.resourcemanager.scheduler.capacity.LeafQueue: assignedContainer application=application_1399292339232_0001 container=Container: [ContainerId: container_1399292339232_0001_01_000009, NodeId: nodef:54669, NodeHttpAddress: nodef:8042, Resource: <memory:1024, vCores:1>, Priority: 10, Token: Token { kind: ContainerToken, service: 10.0.0.199:54669 }, ] containerId=container_1399292339232_0001_01_000009 queue=default: capacity=1.0, absoluteCapacity=1.0, usedResources=<memory:8192, vCores:7>usedCapacity=0.125, absoluteUsedCapacity=0.125, numApps=1, numContainers=7 usedCapacity=0.125 absoluteUsedCapacity=0.125 used=<memory:8192, vCores:7> cluster=<memory:65536, vCores:64>
2014-05-05 12:28:39,678 INFO org.apache.hadoop.yarn.server.resourcemanager.scheduler.capacity.ParentQueue: Re-sorting assigned queue: root.default stats: default: capacity=1.0, absoluteCapacity=1.0, usedResources=<memory:9216, vCores:8>usedCapacity=0.140625, absoluteUsedCapacity=0.140625, numApps=1, numContainers=8
2014-05-05 12:28:39,678 INFO org.apache.hadoop.yarn.server.resourcemanager.scheduler.capacity.ParentQueue: assignedContainer queue=root usedCapacity=0.140625 absoluteUsedCapacity=0.140625 used=<memory:9216, vCores:8> cluster=<memory:65536, vCores:64>
2014-05-05 12:28:39,689 INFO org.apache.hadoop.yarn.server.resourcemanager.rmcontainer.RMContainerImpl: container_1399292339232_0001_01_000010 Container Transitioned from NEW to ALLOCATED
2014-05-05 12:28:39,689 INFO org.apache.hadoop.yarn.server.resourcemanager.RMAuditLogger: USER=ubuntu	OPERATION=AM Allocated Container	TARGET=SchedulerApp	RESULT=SUCCESS	APPID=application_1399292339232_0001	CONTAINERID=container_1399292339232_0001_01_000010
2014-05-05 12:28:39,689 INFO org.apache.hadoop.yarn.server.resourcemanager.scheduler.common.fica.FiCaSchedulerNode: Assigned container container_1399292339232_0001_01_000010 of capacity <memory:1024, vCores:1> on host nodea:51924, which currently has 4 containers, <memory:4096, vCores:4> used and <memory:4096, vCores:4> available
2014-05-05 12:28:39,689 INFO org.apache.hadoop.yarn.server.resourcemanager.scheduler.capacity.LeafQueue: assignedContainer application=application_1399292339232_0001 container=Container: [ContainerId: container_1399292339232_0001_01_000010, NodeId: nodea:51924, NodeHttpAddress: nodea:8042, Resource: <memory:1024, vCores:1>, Priority: 10, Token: Token { kind: ContainerToken, service: 10.0.0.195:51924 }, ] containerId=container_1399292339232_0001_01_000010 queue=default: capacity=1.0, absoluteCapacity=1.0, usedResources=<memory:9216, vCores:8>usedCapacity=0.140625, absoluteUsedCapacity=0.140625, numApps=1, numContainers=8 usedCapacity=0.140625 absoluteUsedCapacity=0.140625 used=<memory:9216, vCores:8> cluster=<memory:65536, vCores:64>
2014-05-05 12:28:39,689 INFO org.apache.hadoop.yarn.server.resourcemanager.scheduler.capacity.ParentQueue: Re-sorting assigned queue: root.default stats: default: capacity=1.0, absoluteCapacity=1.0, usedResources=<memory:10240, vCores:9>usedCapacity=0.15625, absoluteUsedCapacity=0.15625, numApps=1, numContainers=9
2014-05-05 12:28:39,689 INFO org.apache.hadoop.yarn.server.resourcemanager.scheduler.capacity.ParentQueue: assignedContainer queue=root usedCapacity=0.15625 absoluteUsedCapacity=0.15625 used=<memory:10240, vCores:9> cluster=<memory:65536, vCores:64>
2014-05-05 12:28:39,837 INFO org.apache.hadoop.yarn.server.resourcemanager.rmcontainer.RMContainerImpl: container_1399292339232_0001_01_000011 Container Transitioned from NEW to ALLOCATED
2014-05-05 12:28:39,837 INFO org.apache.hadoop.yarn.server.resourcemanager.RMAuditLogger: USER=ubuntu	OPERATION=AM Allocated Container	TARGET=SchedulerApp	RESULT=SUCCESS	APPID=application_1399292339232_0001	CONTAINERID=container_1399292339232_0001_01_000011
2014-05-05 12:28:39,837 INFO org.apache.hadoop.yarn.server.resourcemanager.scheduler.common.fica.FiCaSchedulerNode: Assigned container container_1399292339232_0001_01_000011 of capacity <memory:1024, vCores:1> on host nodec:35478, which currently has 1 containers, <memory:1024, vCores:1> used and <memory:7168, vCores:7> available
2014-05-05 12:28:39,838 INFO org.apache.hadoop.yarn.server.resourcemanager.scheduler.capacity.LeafQueue: assignedContainer application=application_1399292339232_0001 container=Container: [ContainerId: container_1399292339232_0001_01_000011, NodeId: nodec:35478, NodeHttpAddress: nodec:8042, Resource: <memory:1024, vCores:1>, Priority: 10, Token: Token { kind: ContainerToken, service: 10.0.0.200:35478 }, ] containerId=container_1399292339232_0001_01_000011 queue=default: capacity=1.0, absoluteCapacity=1.0, usedResources=<memory:10240, vCores:9>usedCapacity=0.15625, absoluteUsedCapacity=0.15625, numApps=1, numContainers=9 usedCapacity=0.15625 absoluteUsedCapacity=0.15625 used=<memory:10240, vCores:9> cluster=<memory:65536, vCores:64>
2014-05-05 12:28:39,838 INFO org.apache.hadoop.yarn.server.resourcemanager.scheduler.capacity.ParentQueue: Re-sorting assigned queue: root.default stats: default: capacity=1.0, absoluteCapacity=1.0, usedResources=<memory:11264, vCores:10>usedCapacity=0.171875, absoluteUsedCapacity=0.171875, numApps=1, numContainers=10
2014-05-05 12:28:39,838 INFO org.apache.hadoop.yarn.server.resourcemanager.scheduler.capacity.ParentQueue: assignedContainer queue=root usedCapacity=0.171875 absoluteUsedCapacity=0.171875 used=<memory:11264, vCores:10> cluster=<memory:65536, vCores:64>
2014-05-05 12:28:39,842 INFO org.apache.hadoop.yarn.server.resourcemanager.rmcontainer.RMContainerImpl: container_1399292339232_0001_01_000012 Container Transitioned from NEW to ALLOCATED
2014-05-05 12:28:39,842 INFO org.apache.hadoop.yarn.server.resourcemanager.RMAuditLogger: USER=ubuntu	OPERATION=AM Allocated Container	TARGET=SchedulerApp	RESULT=SUCCESS	APPID=application_1399292339232_0001	CONTAINERID=container_1399292339232_0001_01_000012
2014-05-05 12:28:39,842 INFO org.apache.hadoop.yarn.server.resourcemanager.scheduler.common.fica.FiCaSchedulerNode: Assigned container container_1399292339232_0001_01_000012 of capacity <memory:1024, vCores:1> on host noded:39305, which currently has 1 containers, <memory:1024, vCores:1> used and <memory:7168, vCores:7> available
2014-05-05 12:28:39,842 INFO org.apache.hadoop.yarn.server.resourcemanager.scheduler.capacity.LeafQueue: assignedContainer application=application_1399292339232_0001 container=Container: [ContainerId: container_1399292339232_0001_01_000012, NodeId: noded:39305, NodeHttpAddress: noded:8042, Resource: <memory:1024, vCores:1>, Priority: 10, Token: Token { kind: ContainerToken, service: 10.0.0.193:39305 }, ] containerId=container_1399292339232_0001_01_000012 queue=default: capacity=1.0, absoluteCapacity=1.0, usedResources=<memory:11264, vCores:10>usedCapacity=0.171875, absoluteUsedCapacity=0.171875, numApps=1, numContainers=10 usedCapacity=0.171875 absoluteUsedCapacity=0.171875 used=<memory:11264, vCores:10> cluster=<memory:65536, vCores:64>
2014-05-05 12:28:39,842 INFO org.apache.hadoop.yarn.server.resourcemanager.scheduler.capacity.ParentQueue: Re-sorting assigned queue: root.default stats: default: capacity=1.0, absoluteCapacity=1.0, usedResources=<memory:12288, vCores:11>usedCapacity=0.1875, absoluteUsedCapacity=0.1875, numApps=1, numContainers=11
2014-05-05 12:28:39,842 INFO org.apache.hadoop.yarn.server.resourcemanager.scheduler.capacity.ParentQueue: assignedContainer queue=root usedCapacity=0.1875 absoluteUsedCapacity=0.1875 used=<memory:12288, vCores:11> cluster=<memory:65536, vCores:64>
2014-05-05 12:28:40,038 INFO org.apache.hadoop.yarn.server.resourcemanager.rmcontainer.RMContainerImpl: container_1399292339232_0001_01_000013 Container Transitioned from NEW to ALLOCATED
2014-05-05 12:28:40,039 INFO org.apache.hadoop.yarn.server.resourcemanager.RMAuditLogger: USER=ubuntu	OPERATION=AM Allocated Container	TARGET=SchedulerApp	RESULT=SUCCESS	APPID=application_1399292339232_0001	CONTAINERID=container_1399292339232_0001_01_000013
2014-05-05 12:28:40,039 INFO org.apache.hadoop.yarn.server.resourcemanager.scheduler.common.fica.FiCaSchedulerNode: Assigned container container_1399292339232_0001_01_000013 of capacity <memory:1024, vCores:1> on host nodeb:48885, which currently has 1 containers, <memory:1024, vCores:1> used and <memory:7168, vCores:7> available
2014-05-05 12:28:40,039 INFO org.apache.hadoop.yarn.server.resourcemanager.scheduler.capacity.LeafQueue: assignedContainer application=application_1399292339232_0001 container=Container: [ContainerId: container_1399292339232_0001_01_000013, NodeId: nodeb:48885, NodeHttpAddress: nodeb:8042, Resource: <memory:1024, vCores:1>, Priority: 10, Token: Token { kind: ContainerToken, service: 10.0.0.194:48885 }, ] containerId=container_1399292339232_0001_01_000013 queue=default: capacity=1.0, absoluteCapacity=1.0, usedResources=<memory:12288, vCores:11>usedCapacity=0.1875, absoluteUsedCapacity=0.1875, numApps=1, numContainers=11 usedCapacity=0.1875 absoluteUsedCapacity=0.1875 used=<memory:12288, vCores:11> cluster=<memory:65536, vCores:64>
2014-05-05 12:28:40,039 INFO org.apache.hadoop.yarn.server.resourcemanager.scheduler.capacity.ParentQueue: Re-sorting assigned queue: root.default stats: default: capacity=1.0, absoluteCapacity=1.0, usedResources=<memory:13312, vCores:12>usedCapacity=0.203125, absoluteUsedCapacity=0.203125, numApps=1, numContainers=12
2014-05-05 12:28:40,039 INFO org.apache.hadoop.yarn.server.resourcemanager.scheduler.capacity.ParentQueue: assignedContainer queue=root usedCapacity=0.203125 absoluteUsedCapacity=0.203125 used=<memory:13312, vCores:12> cluster=<memory:65536, vCores:64>
2014-05-05 12:28:40,040 INFO org.apache.hadoop.yarn.server.resourcemanager.rmcontainer.RMContainerImpl: container_1399292339232_0001_01_000014 Container Transitioned from NEW to ALLOCATED
2014-05-05 12:28:40,040 INFO org.apache.hadoop.yarn.server.resourcemanager.RMAuditLogger: USER=ubuntu	OPERATION=AM Allocated Container	TARGET=SchedulerApp	RESULT=SUCCESS	APPID=application_1399292339232_0001	CONTAINERID=container_1399292339232_0001_01_000014
2014-05-05 12:28:40,040 INFO org.apache.hadoop.yarn.server.resourcemanager.scheduler.common.fica.FiCaSchedulerNode: Assigned container container_1399292339232_0001_01_000014 of capacity <memory:1024, vCores:1> on host nodeh:46599, which currently has 1 containers, <memory:1024, vCores:1> used and <memory:7168, vCores:7> available
2014-05-05 12:28:40,040 INFO org.apache.hadoop.yarn.server.resourcemanager.scheduler.capacity.LeafQueue: assignedContainer application=application_1399292339232_0001 container=Container: [ContainerId: container_1399292339232_0001_01_000014, NodeId: nodeh:46599, NodeHttpAddress: nodeh:8042, Resource: <memory:1024, vCores:1>, Priority: 10, Token: Token { kind: ContainerToken, service: 10.0.0.197:46599 }, ] containerId=container_1399292339232_0001_01_000014 queue=default: capacity=1.0, absoluteCapacity=1.0, usedResources=<memory:13312, vCores:12>usedCapacity=0.203125, absoluteUsedCapacity=0.203125, numApps=1, numContainers=12 usedCapacity=0.203125 absoluteUsedCapacity=0.203125 used=<memory:13312, vCores:12> cluster=<memory:65536, vCores:64>
2014-05-05 12:28:40,040 INFO org.apache.hadoop.yarn.server.resourcemanager.scheduler.capacity.ParentQueue: Re-sorting assigned queue: root.default stats: default: capacity=1.0, absoluteCapacity=1.0, usedResources=<memory:14336, vCores:13>usedCapacity=0.21875, absoluteUsedCapacity=0.21875, numApps=1, numContainers=13
2014-05-05 12:28:40,040 INFO org.apache.hadoop.yarn.server.resourcemanager.scheduler.capacity.ParentQueue: assignedContainer queue=root usedCapacity=0.21875 absoluteUsedCapacity=0.21875 used=<memory:14336, vCores:13> cluster=<memory:65536, vCores:64>
2014-05-05 12:28:40,346 INFO org.apache.hadoop.yarn.server.resourcemanager.scheduler.AppSchedulingInfo: checking for deactivate... 
2014-05-05 12:28:40,347 INFO org.apache.hadoop.yarn.server.resourcemanager.rmcontainer.RMContainerImpl: container_1399292339232_0001_01_000007 Container Transitioned from ALLOCATED to ACQUIRED
2014-05-05 12:28:40,347 INFO org.apache.hadoop.yarn.server.resourcemanager.rmcontainer.RMContainerImpl: container_1399292339232_0001_01_000008 Container Transitioned from ALLOCATED to ACQUIRED
2014-05-05 12:28:40,348 INFO org.apache.hadoop.yarn.server.resourcemanager.rmcontainer.RMContainerImpl: container_1399292339232_0001_01_000009 Container Transitioned from ALLOCATED to ACQUIRED
2014-05-05 12:28:40,348 INFO org.apache.hadoop.yarn.server.resourcemanager.rmcontainer.RMContainerImpl: container_1399292339232_0001_01_000010 Container Transitioned from ALLOCATED to ACQUIRED
2014-05-05 12:28:40,348 INFO org.apache.hadoop.yarn.server.resourcemanager.rmcontainer.RMContainerImpl: container_1399292339232_0001_01_000011 Container Transitioned from ALLOCATED to ACQUIRED
2014-05-05 12:28:40,349 INFO org.apache.hadoop.yarn.server.resourcemanager.rmcontainer.RMContainerImpl: container_1399292339232_0001_01_000012 Container Transitioned from ALLOCATED to ACQUIRED
2014-05-05 12:28:40,349 INFO org.apache.hadoop.yarn.server.resourcemanager.rmcontainer.RMContainerImpl: container_1399292339232_0001_01_000013 Container Transitioned from ALLOCATED to ACQUIRED
2014-05-05 12:28:40,349 INFO org.apache.hadoop.yarn.server.resourcemanager.rmcontainer.RMContainerImpl: container_1399292339232_0001_01_000014 Container Transitioned from ALLOCATED to ACQUIRED
2014-05-05 12:28:40,563 INFO org.apache.hadoop.yarn.server.resourcemanager.rmcontainer.RMContainerImpl: container_1399292339232_0001_01_000006 Container Transitioned from ACQUIRED to RUNNING
2014-05-05 12:28:40,563 INFO org.apache.hadoop.yarn.server.resourcemanager.rmcontainer.RMContainerImpl: container_1399292339232_0001_01_000007 Container Transitioned from ACQUIRED to RUNNING
2014-05-05 12:28:40,680 INFO org.apache.hadoop.yarn.server.resourcemanager.rmcontainer.RMContainerImpl: container_1399292339232_0001_01_000009 Container Transitioned from ACQUIRED to RUNNING
2014-05-05 12:28:40,693 INFO org.apache.hadoop.yarn.server.resourcemanager.rmcontainer.RMContainerImpl: container_1399292339232_0001_01_000010 Container Transitioned from ACQUIRED to RUNNING
2014-05-05 12:28:40,870 INFO org.apache.hadoop.yarn.server.resourcemanager.rmcontainer.RMContainerImpl: container_1399292339232_0001_01_000011 Container Transitioned from ACQUIRED to RUNNING
2014-05-05 12:28:40,875 INFO org.apache.hadoop.yarn.server.resourcemanager.rmcontainer.RMContainerImpl: container_1399292339232_0001_01_000012 Container Transitioned from ACQUIRED to RUNNING
2014-05-05 12:28:41,054 INFO org.apache.hadoop.yarn.server.resourcemanager.rmcontainer.RMContainerImpl: container_1399292339232_0001_01_000013 Container Transitioned from ACQUIRED to RUNNING
2014-05-05 12:28:41,082 INFO org.apache.hadoop.yarn.server.resourcemanager.rmcontainer.RMContainerImpl: container_1399292339232_0001_01_000014 Container Transitioned from ACQUIRED to RUNNING
2014-05-05 12:28:41,367 INFO org.apache.hadoop.yarn.server.resourcemanager.scheduler.AppSchedulingInfo: checking for deactivate... 
2014-05-05 12:28:41,568 INFO org.apache.hadoop.yarn.server.resourcemanager.rmcontainer.RMContainerImpl: container_1399292339232_0001_01_000008 Container Transitioned from ACQUIRED to RUNNING
2014-05-05 12:28:46,439 INFO org.apache.hadoop.yarn.server.resourcemanager.rmcontainer.RMContainerImpl: container_1399292339232_0001_01_000003 Container Transitioned from RUNNING to COMPLETED
2014-05-05 12:28:46,439 INFO org.apache.hadoop.yarn.server.resourcemanager.scheduler.common.fica.FiCaSchedulerApp: Completed container: container_1399292339232_0001_01_000003 in state: COMPLETED event:FINISHED
2014-05-05 12:28:46,440 INFO org.apache.hadoop.yarn.server.resourcemanager.RMAuditLogger: USER=ubuntu	OPERATION=AM Released Container	TARGET=SchedulerApp	RESULT=SUCCESS	APPID=application_1399292339232_0001	CONTAINERID=container_1399292339232_0001_01_000003
2014-05-05 12:28:46,440 INFO org.apache.hadoop.yarn.server.resourcemanager.scheduler.common.fica.FiCaSchedulerNode: Released container container_1399292339232_0001_01_000003 of capacity <memory:1024, vCores:1> on host nodea:51924, which currently has 3 containers, <memory:3072, vCores:3> used and <memory:5120, vCores:5> available, release resources=true
2014-05-05 12:28:46,440 INFO org.apache.hadoop.yarn.server.resourcemanager.scheduler.capacity.LeafQueue: default used=<memory:13312, vCores:12> numContainers=12 user=ubuntu user-resources=<memory:13312, vCores:12>
2014-05-05 12:28:46,440 INFO org.apache.hadoop.yarn.server.resourcemanager.scheduler.capacity.LeafQueue: completedContainer container=Container: [ContainerId: container_1399292339232_0001_01_000003, NodeId: nodea:51924, NodeHttpAddress: nodea:8042, Resource: <memory:1024, vCores:1>, Priority: 20, Token: Token { kind: ContainerToken, service: 10.0.0.195:51924 }, ] resource=<memory:1024, vCores:1> queue=default: capacity=1.0, absoluteCapacity=1.0, usedResources=<memory:13312, vCores:12>usedCapacity=0.203125, absoluteUsedCapacity=0.203125, numApps=1, numContainers=12 usedCapacity=0.203125 absoluteUsedCapacity=0.203125 used=<memory:13312, vCores:12> cluster=<memory:65536, vCores:64>
2014-05-05 12:28:46,440 INFO org.apache.hadoop.yarn.server.resourcemanager.scheduler.capacity.ParentQueue: completedContainer queue=root usedCapacity=0.203125 absoluteUsedCapacity=0.203125 used=<memory:13312, vCores:12> cluster=<memory:65536, vCores:64>
2014-05-05 12:28:46,440 INFO org.apache.hadoop.yarn.server.resourcemanager.scheduler.capacity.ParentQueue: Re-sorting completed queue: root.default stats: default: capacity=1.0, absoluteCapacity=1.0, usedResources=<memory:13312, vCores:12>usedCapacity=0.203125, absoluteUsedCapacity=0.203125, numApps=1, numContainers=12
2014-05-05 12:28:46,440 INFO org.apache.hadoop.yarn.server.resourcemanager.scheduler.capacity.CapacityScheduler: Application appattempt_1399292339232_0001_000001 released container container_1399292339232_0001_01_000003 on node: host: nodea:51924 #containers=3 available=5120 used=3072 with event: FINISHED
2014-05-05 12:28:49,837 INFO org.apache.hadoop.yarn.server.resourcemanager.rmcontainer.RMContainerImpl: container_1399292339232_0001_01_000006 Container Transitioned from RUNNING to COMPLETED
2014-05-05 12:28:49,837 INFO org.apache.hadoop.yarn.server.resourcemanager.scheduler.common.fica.FiCaSchedulerApp: Completed container: container_1399292339232_0001_01_000006 in state: COMPLETED event:FINISHED
2014-05-05 12:28:49,838 INFO org.apache.hadoop.yarn.server.resourcemanager.RMAuditLogger: USER=ubuntu	OPERATION=AM Released Container	TARGET=SchedulerApp	RESULT=SUCCESS	APPID=application_1399292339232_0001	CONTAINERID=container_1399292339232_0001_01_000006
2014-05-05 12:28:49,838 INFO org.apache.hadoop.yarn.server.resourcemanager.scheduler.common.fica.FiCaSchedulerNode: Released container container_1399292339232_0001_01_000006 of capacity <memory:1024, vCores:1> on host nodee:49598, which currently has 1 containers, <memory:1024, vCores:1> used and <memory:7168, vCores:7> available, release resources=true
2014-05-05 12:28:49,838 INFO org.apache.hadoop.yarn.server.resourcemanager.scheduler.capacity.LeafQueue: default used=<memory:12288, vCores:11> numContainers=11 user=ubuntu user-resources=<memory:12288, vCores:11>
2014-05-05 12:28:49,838 INFO org.apache.hadoop.yarn.server.resourcemanager.scheduler.capacity.LeafQueue: completedContainer container=Container: [ContainerId: container_1399292339232_0001_01_000006, NodeId: nodee:49598, NodeHttpAddress: nodee:8042, Resource: <memory:1024, vCores:1>, Priority: 20, Token: Token { kind: ContainerToken, service: 10.0.0.198:49598 }, ] resource=<memory:1024, vCores:1> queue=default: capacity=1.0, absoluteCapacity=1.0, usedResources=<memory:12288, vCores:11>usedCapacity=0.1875, absoluteUsedCapacity=0.1875, numApps=1, numContainers=11 usedCapacity=0.1875 absoluteUsedCapacity=0.1875 used=<memory:12288, vCores:11> cluster=<memory:65536, vCores:64>
2014-05-05 12:28:49,838 INFO org.apache.hadoop.yarn.server.resourcemanager.scheduler.capacity.ParentQueue: completedContainer queue=root usedCapacity=0.1875 absoluteUsedCapacity=0.1875 used=<memory:12288, vCores:11> cluster=<memory:65536, vCores:64>
2014-05-05 12:28:49,838 INFO org.apache.hadoop.yarn.server.resourcemanager.scheduler.capacity.ParentQueue: Re-sorting completed queue: root.default stats: default: capacity=1.0, absoluteCapacity=1.0, usedResources=<memory:12288, vCores:11>usedCapacity=0.1875, absoluteUsedCapacity=0.1875, numApps=1, numContainers=11
2014-05-05 12:28:49,838 INFO org.apache.hadoop.yarn.server.resourcemanager.scheduler.capacity.CapacityScheduler: Application appattempt_1399292339232_0001_000001 released container container_1399292339232_0001_01_000006 on node: host: nodee:49598 #containers=1 available=7168 used=1024 with event: FINISHED
2014-05-05 12:28:49,839 INFO org.apache.hadoop.yarn.server.resourcemanager.rmcontainer.RMContainerImpl: container_1399292339232_0001_01_000004 Container Transitioned from RUNNING to COMPLETED
2014-05-05 12:28:49,839 INFO org.apache.hadoop.yarn.server.resourcemanager.scheduler.common.fica.FiCaSchedulerApp: Completed container: container_1399292339232_0001_01_000004 in state: COMPLETED event:FINISHED
2014-05-05 12:28:49,839 INFO org.apache.hadoop.yarn.server.resourcemanager.RMAuditLogger: USER=ubuntu	OPERATION=AM Released Container	TARGET=SchedulerApp	RESULT=SUCCESS	APPID=application_1399292339232_0001	CONTAINERID=container_1399292339232_0001_01_000004
2014-05-05 12:28:49,839 INFO org.apache.hadoop.yarn.server.resourcemanager.scheduler.common.fica.FiCaSchedulerNode: Released container container_1399292339232_0001_01_000004 of capacity <memory:1024, vCores:1> on host nodea:51924, which currently has 2 containers, <memory:2048, vCores:2> used and <memory:6144, vCores:6> available, release resources=true
2014-05-05 12:28:49,839 INFO org.apache.hadoop.yarn.server.resourcemanager.scheduler.capacity.LeafQueue: default used=<memory:11264, vCores:10> numContainers=10 user=ubuntu user-resources=<memory:11264, vCores:10>
2014-05-05 12:28:49,839 INFO org.apache.hadoop.yarn.server.resourcemanager.scheduler.capacity.LeafQueue: completedContainer container=Container: [ContainerId: container_1399292339232_0001_01_000004, NodeId: nodea:51924, NodeHttpAddress: nodea:8042, Resource: <memory:1024, vCores:1>, Priority: 20, Token: Token { kind: ContainerToken, service: 10.0.0.195:51924 }, ] resource=<memory:1024, vCores:1> queue=default: capacity=1.0, absoluteCapacity=1.0, usedResources=<memory:11264, vCores:10>usedCapacity=0.171875, absoluteUsedCapacity=0.171875, numApps=1, numContainers=10 usedCapacity=0.171875 absoluteUsedCapacity=0.171875 used=<memory:11264, vCores:10> cluster=<memory:65536, vCores:64>
2014-05-05 12:28:49,840 INFO org.apache.hadoop.yarn.server.resourcemanager.scheduler.capacity.ParentQueue: completedContainer queue=root usedCapacity=0.171875 absoluteUsedCapacity=0.171875 used=<memory:11264, vCores:10> cluster=<memory:65536, vCores:64>
2014-05-05 12:28:49,840 INFO org.apache.hadoop.yarn.server.resourcemanager.scheduler.capacity.ParentQueue: Re-sorting completed queue: root.default stats: default: capacity=1.0, absoluteCapacity=1.0, usedResources=<memory:11264, vCores:10>usedCapacity=0.171875, absoluteUsedCapacity=0.171875, numApps=1, numContainers=10
2014-05-05 12:28:49,840 INFO org.apache.hadoop.yarn.server.resourcemanager.scheduler.capacity.CapacityScheduler: Application appattempt_1399292339232_0001_000001 released container container_1399292339232_0001_01_000004 on node: host: nodea:51924 #containers=2 available=6144 used=2048 with event: FINISHED
2014-05-05 12:28:50,865 INFO org.apache.hadoop.yarn.server.resourcemanager.rmcontainer.RMContainerImpl: container_1399292339232_0001_01_000002 Container Transitioned from RUNNING to COMPLETED
2014-05-05 12:28:50,865 INFO org.apache.hadoop.yarn.server.resourcemanager.scheduler.common.fica.FiCaSchedulerApp: Completed container: container_1399292339232_0001_01_000002 in state: COMPLETED event:FINISHED
2014-05-05 12:28:50,865 INFO org.apache.hadoop.yarn.server.resourcemanager.RMAuditLogger: USER=ubuntu	OPERATION=AM Released Container	TARGET=SchedulerApp	RESULT=SUCCESS	APPID=application_1399292339232_0001	CONTAINERID=container_1399292339232_0001_01_000002
2014-05-05 12:28:50,866 INFO org.apache.hadoop.yarn.server.resourcemanager.scheduler.common.fica.FiCaSchedulerNode: Released container container_1399292339232_0001_01_000002 of capacity <memory:1024, vCores:1> on host nodea:51924, which currently has 1 containers, <memory:1024, vCores:1> used and <memory:7168, vCores:7> available, release resources=true
2014-05-05 12:28:50,866 INFO org.apache.hadoop.yarn.server.resourcemanager.scheduler.capacity.LeafQueue: default used=<memory:10240, vCores:9> numContainers=9 user=ubuntu user-resources=<memory:10240, vCores:9>
2014-05-05 12:28:50,866 INFO org.apache.hadoop.yarn.server.resourcemanager.scheduler.capacity.LeafQueue: completedContainer container=Container: [ContainerId: container_1399292339232_0001_01_000002, NodeId: nodea:51924, NodeHttpAddress: nodea:8042, Resource: <memory:1024, vCores:1>, Priority: 20, Token: Token { kind: ContainerToken, service: 10.0.0.195:51924 }, ] resource=<memory:1024, vCores:1> queue=default: capacity=1.0, absoluteCapacity=1.0, usedResources=<memory:10240, vCores:9>usedCapacity=0.15625, absoluteUsedCapacity=0.15625, numApps=1, numContainers=9 usedCapacity=0.15625 absoluteUsedCapacity=0.15625 used=<memory:10240, vCores:9> cluster=<memory:65536, vCores:64>
2014-05-05 12:28:50,866 INFO org.apache.hadoop.yarn.server.resourcemanager.scheduler.capacity.ParentQueue: completedContainer queue=root usedCapacity=0.15625 absoluteUsedCapacity=0.15625 used=<memory:10240, vCores:9> cluster=<memory:65536, vCores:64>
2014-05-05 12:28:50,866 INFO org.apache.hadoop.yarn.server.resourcemanager.scheduler.capacity.ParentQueue: Re-sorting completed queue: root.default stats: default: capacity=1.0, absoluteCapacity=1.0, usedResources=<memory:10240, vCores:9>usedCapacity=0.15625, absoluteUsedCapacity=0.15625, numApps=1, numContainers=9
2014-05-05 12:28:50,866 INFO org.apache.hadoop.yarn.server.resourcemanager.scheduler.capacity.CapacityScheduler: Application appattempt_1399292339232_0001_000001 released container container_1399292339232_0001_01_000002 on node: host: nodea:51924 #containers=1 available=7168 used=1024 with event: FINISHED
2014-05-05 12:29:37,722 INFO org.apache.hadoop.yarn.server.resourcemanager.rmcontainer.RMContainerImpl: container_1399292339232_0001_01_000013 Container Transitioned from RUNNING to COMPLETED
2014-05-05 12:29:37,722 INFO org.apache.hadoop.yarn.server.resourcemanager.scheduler.common.fica.FiCaSchedulerApp: Completed container: container_1399292339232_0001_01_000013 in state: COMPLETED event:FINISHED
2014-05-05 12:29:37,729 INFO org.apache.hadoop.yarn.server.resourcemanager.RMAuditLogger: USER=ubuntu	OPERATION=AM Released Container	TARGET=SchedulerApp	RESULT=SUCCESS	APPID=application_1399292339232_0001	CONTAINERID=container_1399292339232_0001_01_000013
2014-05-05 12:29:37,729 INFO org.apache.hadoop.yarn.server.resourcemanager.scheduler.common.fica.FiCaSchedulerNode: Released container container_1399292339232_0001_01_000013 of capacity <memory:1024, vCores:1> on host nodeb:48885, which currently has 0 containers, <memory:0, vCores:0> used and <memory:8192, vCores:8> available, release resources=true
2014-05-05 12:29:37,729 INFO org.apache.hadoop.yarn.server.resourcemanager.scheduler.capacity.LeafQueue: default used=<memory:9216, vCores:8> numContainers=8 user=ubuntu user-resources=<memory:9216, vCores:8>
2014-05-05 12:29:37,729 INFO org.apache.hadoop.yarn.server.resourcemanager.scheduler.capacity.LeafQueue: completedContainer container=Container: [ContainerId: container_1399292339232_0001_01_000013, NodeId: nodeb:48885, NodeHttpAddress: nodeb:8042, Resource: <memory:1024, vCores:1>, Priority: 10, Token: Token { kind: ContainerToken, service: 10.0.0.194:48885 }, ] resource=<memory:1024, vCores:1> queue=default: capacity=1.0, absoluteCapacity=1.0, usedResources=<memory:9216, vCores:8>usedCapacity=0.140625, absoluteUsedCapacity=0.140625, numApps=1, numContainers=8 usedCapacity=0.140625 absoluteUsedCapacity=0.140625 used=<memory:9216, vCores:8> cluster=<memory:65536, vCores:64>
2014-05-05 12:29:37,729 INFO org.apache.hadoop.yarn.server.resourcemanager.scheduler.capacity.ParentQueue: completedContainer queue=root usedCapacity=0.140625 absoluteUsedCapacity=0.140625 used=<memory:9216, vCores:8> cluster=<memory:65536, vCores:64>
2014-05-05 12:29:37,729 INFO org.apache.hadoop.yarn.server.resourcemanager.scheduler.capacity.ParentQueue: Re-sorting completed queue: root.default stats: default: capacity=1.0, absoluteCapacity=1.0, usedResources=<memory:9216, vCores:8>usedCapacity=0.140625, absoluteUsedCapacity=0.140625, numApps=1, numContainers=8
2014-05-05 12:29:37,729 INFO org.apache.hadoop.yarn.server.resourcemanager.scheduler.capacity.CapacityScheduler: Application appattempt_1399292339232_0001_000001 released container container_1399292339232_0001_01_000013 on node: host: nodeb:48885 #containers=0 available=8192 used=0 with event: FINISHED
2014-05-05 12:29:37,868 INFO org.apache.hadoop.yarn.server.resourcemanager.rmcontainer.RMContainerImpl: container_1399292339232_0001_01_000009 Container Transitioned from RUNNING to COMPLETED
2014-05-05 12:29:37,868 INFO org.apache.hadoop.yarn.server.resourcemanager.scheduler.common.fica.FiCaSchedulerApp: Completed container: container_1399292339232_0001_01_000009 in state: COMPLETED event:FINISHED
2014-05-05 12:29:37,868 INFO org.apache.hadoop.yarn.server.resourcemanager.RMAuditLogger: USER=ubuntu	OPERATION=AM Released Container	TARGET=SchedulerApp	RESULT=SUCCESS	APPID=application_1399292339232_0001	CONTAINERID=container_1399292339232_0001_01_000009
2014-05-05 12:29:37,868 INFO org.apache.hadoop.yarn.server.resourcemanager.scheduler.common.fica.FiCaSchedulerNode: Released container container_1399292339232_0001_01_000009 of capacity <memory:1024, vCores:1> on host nodef:54669, which currently has 1 containers, <memory:2048, vCores:1> used and <memory:6144, vCores:7> available, release resources=true
2014-05-05 12:29:37,868 INFO org.apache.hadoop.yarn.server.resourcemanager.scheduler.capacity.LeafQueue: default used=<memory:8192, vCores:7> numContainers=7 user=ubuntu user-resources=<memory:8192, vCores:7>
2014-05-05 12:29:37,868 INFO org.apache.hadoop.yarn.server.resourcemanager.scheduler.capacity.LeafQueue: completedContainer container=Container: [ContainerId: container_1399292339232_0001_01_000009, NodeId: nodef:54669, NodeHttpAddress: nodef:8042, Resource: <memory:1024, vCores:1>, Priority: 10, Token: Token { kind: ContainerToken, service: 10.0.0.199:54669 }, ] resource=<memory:1024, vCores:1> queue=default: capacity=1.0, absoluteCapacity=1.0, usedResources=<memory:8192, vCores:7>usedCapacity=0.125, absoluteUsedCapacity=0.125, numApps=1, numContainers=7 usedCapacity=0.125 absoluteUsedCapacity=0.125 used=<memory:8192, vCores:7> cluster=<memory:65536, vCores:64>
2014-05-05 12:29:37,868 INFO org.apache.hadoop.yarn.server.resourcemanager.scheduler.capacity.ParentQueue: completedContainer queue=root usedCapacity=0.125 absoluteUsedCapacity=0.125 used=<memory:8192, vCores:7> cluster=<memory:65536, vCores:64>
2014-05-05 12:29:37,868 INFO org.apache.hadoop.yarn.server.resourcemanager.scheduler.capacity.ParentQueue: Re-sorting completed queue: root.default stats: default: capacity=1.0, absoluteCapacity=1.0, usedResources=<memory:8192, vCores:7>usedCapacity=0.125, absoluteUsedCapacity=0.125, numApps=1, numContainers=7
2014-05-05 12:29:37,868 INFO org.apache.hadoop.yarn.server.resourcemanager.scheduler.capacity.CapacityScheduler: Application appattempt_1399292339232_0001_000001 released container container_1399292339232_0001_01_000009 on node: host: nodef:54669 #containers=1 available=6144 used=2048 with event: FINISHED
2014-05-05 12:29:37,903 INFO org.apache.hadoop.yarn.server.resourcemanager.rmcontainer.RMContainerImpl: container_1399292339232_0001_01_000010 Container Transitioned from RUNNING to COMPLETED
2014-05-05 12:29:37,903 INFO org.apache.hadoop.yarn.server.resourcemanager.scheduler.common.fica.FiCaSchedulerApp: Completed container: container_1399292339232_0001_01_000010 in state: COMPLETED event:FINISHED
2014-05-05 12:29:37,903 INFO org.apache.hadoop.yarn.server.resourcemanager.RMAuditLogger: USER=ubuntu	OPERATION=AM Released Container	TARGET=SchedulerApp	RESULT=SUCCESS	APPID=application_1399292339232_0001	CONTAINERID=container_1399292339232_0001_01_000010
2014-05-05 12:29:37,903 INFO org.apache.hadoop.yarn.server.resourcemanager.scheduler.common.fica.FiCaSchedulerNode: Released container container_1399292339232_0001_01_000010 of capacity <memory:1024, vCores:1> on host nodea:51924, which currently has 0 containers, <memory:0, vCores:0> used and <memory:8192, vCores:8> available, release resources=true
2014-05-05 12:29:37,903 INFO org.apache.hadoop.yarn.server.resourcemanager.scheduler.capacity.LeafQueue: default used=<memory:7168, vCores:6> numContainers=6 user=ubuntu user-resources=<memory:7168, vCores:6>
2014-05-05 12:29:37,903 INFO org.apache.hadoop.yarn.server.resourcemanager.scheduler.capacity.LeafQueue: completedContainer container=Container: [ContainerId: container_1399292339232_0001_01_000010, NodeId: nodea:51924, NodeHttpAddress: nodea:8042, Resource: <memory:1024, vCores:1>, Priority: 10, Token: Token { kind: ContainerToken, service: 10.0.0.195:51924 }, ] resource=<memory:1024, vCores:1> queue=default: capacity=1.0, absoluteCapacity=1.0, usedResources=<memory:7168, vCores:6>usedCapacity=0.109375, absoluteUsedCapacity=0.109375, numApps=1, numContainers=6 usedCapacity=0.109375 absoluteUsedCapacity=0.109375 used=<memory:7168, vCores:6> cluster=<memory:65536, vCores:64>
2014-05-05 12:29:37,903 INFO org.apache.hadoop.yarn.server.resourcemanager.scheduler.capacity.ParentQueue: completedContainer queue=root usedCapacity=0.109375 absoluteUsedCapacity=0.109375 used=<memory:7168, vCores:6> cluster=<memory:65536, vCores:64>
2014-05-05 12:29:37,903 INFO org.apache.hadoop.yarn.server.resourcemanager.scheduler.capacity.ParentQueue: Re-sorting completed queue: root.default stats: default: capacity=1.0, absoluteCapacity=1.0, usedResources=<memory:7168, vCores:6>usedCapacity=0.109375, absoluteUsedCapacity=0.109375, numApps=1, numContainers=6
2014-05-05 12:29:37,903 INFO org.apache.hadoop.yarn.server.resourcemanager.scheduler.capacity.CapacityScheduler: Application appattempt_1399292339232_0001_000001 released container container_1399292339232_0001_01_000010 on node: host: nodea:51924 #containers=0 available=8192 used=0 with event: FINISHED
2014-05-05 12:29:37,925 INFO org.apache.hadoop.yarn.server.resourcemanager.rmcontainer.RMContainerImpl: container_1399292339232_0001_01_000011 Container Transitioned from RUNNING to COMPLETED
2014-05-05 12:29:37,925 INFO org.apache.hadoop.yarn.server.resourcemanager.scheduler.common.fica.FiCaSchedulerApp: Completed container: container_1399292339232_0001_01_000011 in state: COMPLETED event:FINISHED
2014-05-05 12:29:37,926 INFO org.apache.hadoop.yarn.server.resourcemanager.RMAuditLogger: USER=ubuntu	OPERATION=AM Released Container	TARGET=SchedulerApp	RESULT=SUCCESS	APPID=application_1399292339232_0001	CONTAINERID=container_1399292339232_0001_01_000011
2014-05-05 12:29:37,926 INFO org.apache.hadoop.yarn.server.resourcemanager.scheduler.common.fica.FiCaSchedulerNode: Released container container_1399292339232_0001_01_000011 of capacity <memory:1024, vCores:1> on host nodec:35478, which currently has 0 containers, <memory:0, vCores:0> used and <memory:8192, vCores:8> available, release resources=true
2014-05-05 12:29:37,926 INFO org.apache.hadoop.yarn.server.resourcemanager.scheduler.capacity.LeafQueue: default used=<memory:6144, vCores:5> numContainers=5 user=ubuntu user-resources=<memory:6144, vCores:5>
2014-05-05 12:29:37,926 INFO org.apache.hadoop.yarn.server.resourcemanager.scheduler.capacity.LeafQueue: completedContainer container=Container: [ContainerId: container_1399292339232_0001_01_000011, NodeId: nodec:35478, NodeHttpAddress: nodec:8042, Resource: <memory:1024, vCores:1>, Priority: 10, Token: Token { kind: ContainerToken, service: 10.0.0.200:35478 }, ] resource=<memory:1024, vCores:1> queue=default: capacity=1.0, absoluteCapacity=1.0, usedResources=<memory:6144, vCores:5>usedCapacity=0.09375, absoluteUsedCapacity=0.09375, numApps=1, numContainers=5 usedCapacity=0.09375 absoluteUsedCapacity=0.09375 used=<memory:6144, vCores:5> cluster=<memory:65536, vCores:64>
2014-05-05 12:29:37,926 INFO org.apache.hadoop.yarn.server.resourcemanager.scheduler.capacity.ParentQueue: completedContainer queue=root usedCapacity=0.09375 absoluteUsedCapacity=0.09375 used=<memory:6144, vCores:5> cluster=<memory:65536, vCores:64>
2014-05-05 12:29:37,926 INFO org.apache.hadoop.yarn.server.resourcemanager.scheduler.capacity.ParentQueue: Re-sorting completed queue: root.default stats: default: capacity=1.0, absoluteCapacity=1.0, usedResources=<memory:6144, vCores:5>usedCapacity=0.09375, absoluteUsedCapacity=0.09375, numApps=1, numContainers=5
2014-05-05 12:29:37,926 INFO org.apache.hadoop.yarn.server.resourcemanager.scheduler.capacity.CapacityScheduler: Application appattempt_1399292339232_0001_000001 released container container_1399292339232_0001_01_000011 on node: host: nodec:35478 #containers=0 available=8192 used=0 with event: FINISHED
2014-05-05 12:29:37,935 INFO org.apache.hadoop.yarn.server.resourcemanager.rmcontainer.RMContainerImpl: container_1399292339232_0001_01_000007 Container Transitioned from RUNNING to COMPLETED
2014-05-05 12:29:37,935 INFO org.apache.hadoop.yarn.server.resourcemanager.scheduler.common.fica.FiCaSchedulerApp: Completed container: container_1399292339232_0001_01_000007 in state: COMPLETED event:FINISHED
2014-05-05 12:29:37,935 INFO org.apache.hadoop.yarn.server.resourcemanager.RMAuditLogger: USER=ubuntu	OPERATION=AM Released Container	TARGET=SchedulerApp	RESULT=SUCCESS	APPID=application_1399292339232_0001	CONTAINERID=container_1399292339232_0001_01_000007
2014-05-05 12:29:37,935 INFO org.apache.hadoop.yarn.server.resourcemanager.scheduler.common.fica.FiCaSchedulerNode: Released container container_1399292339232_0001_01_000007 of capacity <memory:1024, vCores:1> on host nodee:49598, which currently has 0 containers, <memory:0, vCores:0> used and <memory:8192, vCores:8> available, release resources=true
2014-05-05 12:29:37,935 INFO org.apache.hadoop.yarn.server.resourcemanager.scheduler.capacity.LeafQueue: default used=<memory:5120, vCores:4> numContainers=4 user=ubuntu user-resources=<memory:5120, vCores:4>
2014-05-05 12:29:37,935 INFO org.apache.hadoop.yarn.server.resourcemanager.scheduler.capacity.LeafQueue: completedContainer container=Container: [ContainerId: container_1399292339232_0001_01_000007, NodeId: nodee:49598, NodeHttpAddress: nodee:8042, Resource: <memory:1024, vCores:1>, Priority: 10, Token: Token { kind: ContainerToken, service: 10.0.0.198:49598 }, ] resource=<memory:1024, vCores:1> queue=default: capacity=1.0, absoluteCapacity=1.0, usedResources=<memory:5120, vCores:4>usedCapacity=0.078125, absoluteUsedCapacity=0.078125, numApps=1, numContainers=4 usedCapacity=0.078125 absoluteUsedCapacity=0.078125 used=<memory:5120, vCores:4> cluster=<memory:65536, vCores:64>
2014-05-05 12:29:37,936 INFO org.apache.hadoop.yarn.server.resourcemanager.scheduler.capacity.ParentQueue: completedContainer queue=root usedCapacity=0.078125 absoluteUsedCapacity=0.078125 used=<memory:5120, vCores:4> cluster=<memory:65536, vCores:64>
2014-05-05 12:29:37,936 INFO org.apache.hadoop.yarn.server.resourcemanager.scheduler.capacity.ParentQueue: Re-sorting completed queue: root.default stats: default: capacity=1.0, absoluteCapacity=1.0, usedResources=<memory:5120, vCores:4>usedCapacity=0.078125, absoluteUsedCapacity=0.078125, numApps=1, numContainers=4
2014-05-05 12:29:37,936 INFO org.apache.hadoop.yarn.server.resourcemanager.scheduler.capacity.CapacityScheduler: Application appattempt_1399292339232_0001_000001 released container container_1399292339232_0001_01_000007 on node: host: nodee:49598 #containers=0 available=8192 used=0 with event: FINISHED
2014-05-05 12:29:37,943 INFO org.apache.hadoop.yarn.server.resourcemanager.rmcontainer.RMContainerImpl: container_1399292339232_0001_01_000012 Container Transitioned from RUNNING to COMPLETED
2014-05-05 12:29:37,943 INFO org.apache.hadoop.yarn.server.resourcemanager.scheduler.common.fica.FiCaSchedulerApp: Completed container: container_1399292339232_0001_01_000012 in state: COMPLETED event:FINISHED
2014-05-05 12:29:37,943 INFO org.apache.hadoop.yarn.server.resourcemanager.RMAuditLogger: USER=ubuntu	OPERATION=AM Released Container	TARGET=SchedulerApp	RESULT=SUCCESS	APPID=application_1399292339232_0001	CONTAINERID=container_1399292339232_0001_01_000012
2014-05-05 12:29:37,943 INFO org.apache.hadoop.yarn.server.resourcemanager.scheduler.common.fica.FiCaSchedulerNode: Released container container_1399292339232_0001_01_000012 of capacity <memory:1024, vCores:1> on host noded:39305, which currently has 0 containers, <memory:0, vCores:0> used and <memory:8192, vCores:8> available, release resources=true
2014-05-05 12:29:37,943 INFO org.apache.hadoop.yarn.server.resourcemanager.scheduler.capacity.LeafQueue: default used=<memory:4096, vCores:3> numContainers=3 user=ubuntu user-resources=<memory:4096, vCores:3>
2014-05-05 12:29:37,944 INFO org.apache.hadoop.yarn.server.resourcemanager.scheduler.capacity.LeafQueue: completedContainer container=Container: [ContainerId: container_1399292339232_0001_01_000012, NodeId: noded:39305, NodeHttpAddress: noded:8042, Resource: <memory:1024, vCores:1>, Priority: 10, Token: Token { kind: ContainerToken, service: 10.0.0.193:39305 }, ] resource=<memory:1024, vCores:1> queue=default: capacity=1.0, absoluteCapacity=1.0, usedResources=<memory:4096, vCores:3>usedCapacity=0.0625, absoluteUsedCapacity=0.0625, numApps=1, numContainers=3 usedCapacity=0.0625 absoluteUsedCapacity=0.0625 used=<memory:4096, vCores:3> cluster=<memory:65536, vCores:64>
2014-05-05 12:29:37,944 INFO org.apache.hadoop.yarn.server.resourcemanager.scheduler.capacity.ParentQueue: completedContainer queue=root usedCapacity=0.0625 absoluteUsedCapacity=0.0625 used=<memory:4096, vCores:3> cluster=<memory:65536, vCores:64>
2014-05-05 12:29:37,944 INFO org.apache.hadoop.yarn.server.resourcemanager.scheduler.capacity.ParentQueue: Re-sorting completed queue: root.default stats: default: capacity=1.0, absoluteCapacity=1.0, usedResources=<memory:4096, vCores:3>usedCapacity=0.0625, absoluteUsedCapacity=0.0625, numApps=1, numContainers=3
2014-05-05 12:29:37,944 INFO org.apache.hadoop.yarn.server.resourcemanager.scheduler.capacity.CapacityScheduler: Application appattempt_1399292339232_0001_000001 released container container_1399292339232_0001_01_000012 on node: host: noded:39305 #containers=0 available=8192 used=0 with event: FINISHED
2014-05-05 12:29:37,944 INFO org.apache.hadoop.yarn.server.resourcemanager.rmcontainer.RMContainerImpl: container_1399292339232_0001_01_000008 Container Transitioned from RUNNING to COMPLETED
2014-05-05 12:29:37,944 INFO org.apache.hadoop.yarn.server.resourcemanager.scheduler.common.fica.FiCaSchedulerApp: Completed container: container_1399292339232_0001_01_000008 in state: COMPLETED event:FINISHED
2014-05-05 12:29:37,944 INFO org.apache.hadoop.yarn.server.resourcemanager.RMAuditLogger: USER=ubuntu	OPERATION=AM Released Container	TARGET=SchedulerApp	RESULT=SUCCESS	APPID=application_1399292339232_0001	CONTAINERID=container_1399292339232_0001_01_000008
2014-05-05 12:29:37,944 INFO org.apache.hadoop.yarn.server.resourcemanager.scheduler.common.fica.FiCaSchedulerNode: Released container container_1399292339232_0001_01_000008 of capacity <memory:1024, vCores:1> on host nodeg:56763, which currently has 0 containers, <memory:0, vCores:0> used and <memory:8192, vCores:8> available, release resources=true
2014-05-05 12:29:37,944 INFO org.apache.hadoop.yarn.server.resourcemanager.scheduler.capacity.LeafQueue: default used=<memory:3072, vCores:2> numContainers=2 user=ubuntu user-resources=<memory:3072, vCores:2>
2014-05-05 12:29:37,944 INFO org.apache.hadoop.yarn.server.resourcemanager.scheduler.capacity.LeafQueue: completedContainer container=Container: [ContainerId: container_1399292339232_0001_01_000008, NodeId: nodeg:56763, NodeHttpAddress: nodeg:8042, Resource: <memory:1024, vCores:1>, Priority: 10, Token: Token { kind: ContainerToken, service: 10.0.0.196:56763 }, ] resource=<memory:1024, vCores:1> queue=default: capacity=1.0, absoluteCapacity=1.0, usedResources=<memory:3072, vCores:2>usedCapacity=0.046875, absoluteUsedCapacity=0.046875, numApps=1, numContainers=2 usedCapacity=0.046875 absoluteUsedCapacity=0.046875 used=<memory:3072, vCores:2> cluster=<memory:65536, vCores:64>
2014-05-05 12:29:37,944 INFO org.apache.hadoop.yarn.server.resourcemanager.scheduler.capacity.ParentQueue: completedContainer queue=root usedCapacity=0.046875 absoluteUsedCapacity=0.046875 used=<memory:3072, vCores:2> cluster=<memory:65536, vCores:64>
2014-05-05 12:29:37,944 INFO org.apache.hadoop.yarn.server.resourcemanager.scheduler.capacity.ParentQueue: Re-sorting completed queue: root.default stats: default: capacity=1.0, absoluteCapacity=1.0, usedResources=<memory:3072, vCores:2>usedCapacity=0.046875, absoluteUsedCapacity=0.046875, numApps=1, numContainers=2
2014-05-05 12:29:37,945 INFO org.apache.hadoop.yarn.server.resourcemanager.scheduler.capacity.CapacityScheduler: Application appattempt_1399292339232_0001_000001 released container container_1399292339232_0001_01_000008 on node: host: nodeg:56763 #containers=0 available=8192 used=0 with event: FINISHED
2014-05-05 12:29:37,950 INFO org.apache.hadoop.yarn.server.resourcemanager.rmcontainer.RMContainerImpl: container_1399292339232_0001_01_000014 Container Transitioned from RUNNING to COMPLETED
2014-05-05 12:29:37,950 INFO org.apache.hadoop.yarn.server.resourcemanager.scheduler.common.fica.FiCaSchedulerApp: Completed container: container_1399292339232_0001_01_000014 in state: COMPLETED event:FINISHED
2014-05-05 12:29:37,951 INFO org.apache.hadoop.yarn.server.resourcemanager.RMAuditLogger: USER=ubuntu	OPERATION=AM Released Container	TARGET=SchedulerApp	RESULT=SUCCESS	APPID=application_1399292339232_0001	CONTAINERID=container_1399292339232_0001_01_000014
2014-05-05 12:29:37,951 INFO org.apache.hadoop.yarn.server.resourcemanager.scheduler.common.fica.FiCaSchedulerNode: Released container container_1399292339232_0001_01_000014 of capacity <memory:1024, vCores:1> on host nodeh:46599, which currently has 0 containers, <memory:0, vCores:0> used and <memory:8192, vCores:8> available, release resources=true
2014-05-05 12:29:37,951 INFO org.apache.hadoop.yarn.server.resourcemanager.scheduler.capacity.LeafQueue: default used=<memory:2048, vCores:1> numContainers=1 user=ubuntu user-resources=<memory:2048, vCores:1>
2014-05-05 12:29:37,951 INFO org.apache.hadoop.yarn.server.resourcemanager.scheduler.capacity.LeafQueue: completedContainer container=Container: [ContainerId: container_1399292339232_0001_01_000014, NodeId: nodeh:46599, NodeHttpAddress: nodeh:8042, Resource: <memory:1024, vCores:1>, Priority: 10, Token: Token { kind: ContainerToken, service: 10.0.0.197:46599 }, ] resource=<memory:1024, vCores:1> queue=default: capacity=1.0, absoluteCapacity=1.0, usedResources=<memory:2048, vCores:1>usedCapacity=0.03125, absoluteUsedCapacity=0.03125, numApps=1, numContainers=1 usedCapacity=0.03125 absoluteUsedCapacity=0.03125 used=<memory:2048, vCores:1> cluster=<memory:65536, vCores:64>
2014-05-05 12:29:37,951 INFO org.apache.hadoop.yarn.server.resourcemanager.scheduler.capacity.ParentQueue: completedContainer queue=root usedCapacity=0.03125 absoluteUsedCapacity=0.03125 used=<memory:2048, vCores:1> cluster=<memory:65536, vCores:64>
2014-05-05 12:29:37,951 INFO org.apache.hadoop.yarn.server.resourcemanager.scheduler.capacity.ParentQueue: Re-sorting completed queue: root.default stats: default: capacity=1.0, absoluteCapacity=1.0, usedResources=<memory:2048, vCores:1>usedCapacity=0.03125, absoluteUsedCapacity=0.03125, numApps=1, numContainers=1
2014-05-05 12:29:37,951 INFO org.apache.hadoop.yarn.server.resourcemanager.scheduler.capacity.CapacityScheduler: Application appattempt_1399292339232_0001_000001 released container container_1399292339232_0001_01_000014 on node: host: nodeh:46599 #containers=0 available=8192 used=0 with event: FINISHED
2014-05-05 12:29:38,723 INFO org.apache.hadoop.yarn.server.resourcemanager.rmcontainer.RMContainerImpl: container_1399292339232_0001_01_000015 Container Transitioned from NEW to ALLOCATED
2014-05-05 12:29:38,724 INFO org.apache.hadoop.yarn.server.resourcemanager.RMAuditLogger: USER=ubuntu	OPERATION=AM Allocated Container	TARGET=SchedulerApp	RESULT=SUCCESS	APPID=application_1399292339232_0001	CONTAINERID=container_1399292339232_0001_01_000015
2014-05-05 12:29:38,724 INFO org.apache.hadoop.yarn.server.resourcemanager.scheduler.common.fica.FiCaSchedulerNode: Assigned container container_1399292339232_0001_01_000015 of capacity <memory:1024, vCores:1> on host nodeb:48885, which currently has 1 containers, <memory:1024, vCores:1> used and <memory:7168, vCores:7> available
2014-05-05 12:29:38,724 INFO org.apache.hadoop.yarn.server.resourcemanager.scheduler.capacity.LeafQueue: assignedContainer application=application_1399292339232_0001 container=Container: [ContainerId: container_1399292339232_0001_01_000015, NodeId: nodeb:48885, NodeHttpAddress: nodeb:8042, Resource: <memory:1024, vCores:1>, Priority: 10, Token: Token { kind: ContainerToken, service: 10.0.0.194:48885 }, ] containerId=container_1399292339232_0001_01_000015 queue=default: capacity=1.0, absoluteCapacity=1.0, usedResources=<memory:2048, vCores:1>usedCapacity=0.03125, absoluteUsedCapacity=0.03125, numApps=1, numContainers=1 usedCapacity=0.03125 absoluteUsedCapacity=0.03125 used=<memory:2048, vCores:1> cluster=<memory:65536, vCores:64>
2014-05-05 12:29:38,724 INFO org.apache.hadoop.yarn.server.resourcemanager.scheduler.capacity.ParentQueue: Re-sorting assigned queue: root.default stats: default: capacity=1.0, absoluteCapacity=1.0, usedResources=<memory:3072, vCores:2>usedCapacity=0.046875, absoluteUsedCapacity=0.046875, numApps=1, numContainers=2
2014-05-05 12:29:38,724 INFO org.apache.hadoop.yarn.server.resourcemanager.scheduler.capacity.ParentQueue: assignedContainer queue=root usedCapacity=0.046875 absoluteUsedCapacity=0.046875 used=<memory:3072, vCores:2> cluster=<memory:65536, vCores:64>
2014-05-05 12:29:38,870 INFO org.apache.hadoop.yarn.server.resourcemanager.rmcontainer.RMContainerImpl: container_1399292339232_0001_01_000016 Container Transitioned from NEW to ALLOCATED
2014-05-05 12:29:38,870 INFO org.apache.hadoop.yarn.server.resourcemanager.RMAuditLogger: USER=ubuntu	OPERATION=AM Allocated Container	TARGET=SchedulerApp	RESULT=SUCCESS	APPID=application_1399292339232_0001	CONTAINERID=container_1399292339232_0001_01_000016
2014-05-05 12:29:38,870 INFO org.apache.hadoop.yarn.server.resourcemanager.scheduler.common.fica.FiCaSchedulerNode: Assigned container container_1399292339232_0001_01_000016 of capacity <memory:1024, vCores:1> on host nodef:54669, which currently has 2 containers, <memory:3072, vCores:2> used and <memory:5120, vCores:6> available
2014-05-05 12:29:38,870 INFO org.apache.hadoop.yarn.server.resourcemanager.scheduler.capacity.LeafQueue: assignedContainer application=application_1399292339232_0001 container=Container: [ContainerId: container_1399292339232_0001_01_000016, NodeId: nodef:54669, NodeHttpAddress: nodef:8042, Resource: <memory:1024, vCores:1>, Priority: 10, Token: Token { kind: ContainerToken, service: 10.0.0.199:54669 }, ] containerId=container_1399292339232_0001_01_000016 queue=default: capacity=1.0, absoluteCapacity=1.0, usedResources=<memory:3072, vCores:2>usedCapacity=0.046875, absoluteUsedCapacity=0.046875, numApps=1, numContainers=2 usedCapacity=0.046875 absoluteUsedCapacity=0.046875 used=<memory:3072, vCores:2> cluster=<memory:65536, vCores:64>
2014-05-05 12:29:38,870 INFO org.apache.hadoop.yarn.server.resourcemanager.scheduler.capacity.ParentQueue: Re-sorting assigned queue: root.default stats: default: capacity=1.0, absoluteCapacity=1.0, usedResources=<memory:4096, vCores:3>usedCapacity=0.0625, absoluteUsedCapacity=0.0625, numApps=1, numContainers=3
2014-05-05 12:29:38,870 INFO org.apache.hadoop.yarn.server.resourcemanager.scheduler.capacity.ParentQueue: assignedContainer queue=root usedCapacity=0.0625 absoluteUsedCapacity=0.0625 used=<memory:4096, vCores:3> cluster=<memory:65536, vCores:64>
2014-05-05 12:29:38,904 INFO org.apache.hadoop.yarn.server.resourcemanager.rmcontainer.RMContainerImpl: container_1399292339232_0001_01_000017 Container Transitioned from NEW to ALLOCATED
2014-05-05 12:29:38,904 INFO org.apache.hadoop.yarn.server.resourcemanager.RMAuditLogger: USER=ubuntu	OPERATION=AM Allocated Container	TARGET=SchedulerApp	RESULT=SUCCESS	APPID=application_1399292339232_0001	CONTAINERID=container_1399292339232_0001_01_000017
2014-05-05 12:29:38,904 INFO org.apache.hadoop.yarn.server.resourcemanager.scheduler.common.fica.FiCaSchedulerNode: Assigned container container_1399292339232_0001_01_000017 of capacity <memory:1024, vCores:1> on host nodea:51924, which currently has 1 containers, <memory:1024, vCores:1> used and <memory:7168, vCores:7> available
2014-05-05 12:29:38,904 INFO org.apache.hadoop.yarn.server.resourcemanager.scheduler.capacity.LeafQueue: assignedContainer application=application_1399292339232_0001 container=Container: [ContainerId: container_1399292339232_0001_01_000017, NodeId: nodea:51924, NodeHttpAddress: nodea:8042, Resource: <memory:1024, vCores:1>, Priority: 10, Token: Token { kind: ContainerToken, service: 10.0.0.195:51924 }, ] containerId=container_1399292339232_0001_01_000017 queue=default: capacity=1.0, absoluteCapacity=1.0, usedResources=<memory:4096, vCores:3>usedCapacity=0.0625, absoluteUsedCapacity=0.0625, numApps=1, numContainers=3 usedCapacity=0.0625 absoluteUsedCapacity=0.0625 used=<memory:4096, vCores:3> cluster=<memory:65536, vCores:64>
2014-05-05 12:29:38,904 INFO org.apache.hadoop.yarn.server.resourcemanager.scheduler.capacity.ParentQueue: Re-sorting assigned queue: root.default stats: default: capacity=1.0, absoluteCapacity=1.0, usedResources=<memory:5120, vCores:4>usedCapacity=0.078125, absoluteUsedCapacity=0.078125, numApps=1, numContainers=4
2014-05-05 12:29:38,904 INFO org.apache.hadoop.yarn.server.resourcemanager.scheduler.capacity.ParentQueue: assignedContainer queue=root usedCapacity=0.078125 absoluteUsedCapacity=0.078125 used=<memory:5120, vCores:4> cluster=<memory:65536, vCores:64>
2014-05-05 12:29:38,927 INFO org.apache.hadoop.yarn.server.resourcemanager.rmcontainer.RMContainerImpl: container_1399292339232_0001_01_000018 Container Transitioned from NEW to ALLOCATED
2014-05-05 12:29:38,927 INFO org.apache.hadoop.yarn.server.resourcemanager.RMAuditLogger: USER=ubuntu	OPERATION=AM Allocated Container	TARGET=SchedulerApp	RESULT=SUCCESS	APPID=application_1399292339232_0001	CONTAINERID=container_1399292339232_0001_01_000018
2014-05-05 12:29:38,927 INFO org.apache.hadoop.yarn.server.resourcemanager.scheduler.common.fica.FiCaSchedulerNode: Assigned container container_1399292339232_0001_01_000018 of capacity <memory:1024, vCores:1> on host nodec:35478, which currently has 1 containers, <memory:1024, vCores:1> used and <memory:7168, vCores:7> available
2014-05-05 12:29:38,927 INFO org.apache.hadoop.yarn.server.resourcemanager.scheduler.capacity.LeafQueue: assignedContainer application=application_1399292339232_0001 container=Container: [ContainerId: container_1399292339232_0001_01_000018, NodeId: nodec:35478, NodeHttpAddress: nodec:8042, Resource: <memory:1024, vCores:1>, Priority: 10, Token: Token { kind: ContainerToken, service: 10.0.0.200:35478 }, ] containerId=container_1399292339232_0001_01_000018 queue=default: capacity=1.0, absoluteCapacity=1.0, usedResources=<memory:5120, vCores:4>usedCapacity=0.078125, absoluteUsedCapacity=0.078125, numApps=1, numContainers=4 usedCapacity=0.078125 absoluteUsedCapacity=0.078125 used=<memory:5120, vCores:4> cluster=<memory:65536, vCores:64>
2014-05-05 12:29:38,927 INFO org.apache.hadoop.yarn.server.resourcemanager.scheduler.capacity.ParentQueue: Re-sorting assigned queue: root.default stats: default: capacity=1.0, absoluteCapacity=1.0, usedResources=<memory:6144, vCores:5>usedCapacity=0.09375, absoluteUsedCapacity=0.09375, numApps=1, numContainers=5
2014-05-05 12:29:38,927 INFO org.apache.hadoop.yarn.server.resourcemanager.scheduler.capacity.ParentQueue: assignedContainer queue=root usedCapacity=0.09375 absoluteUsedCapacity=0.09375 used=<memory:6144, vCores:5> cluster=<memory:65536, vCores:64>
2014-05-05 12:29:38,936 INFO org.apache.hadoop.yarn.server.resourcemanager.rmcontainer.RMContainerImpl: container_1399292339232_0001_01_000019 Container Transitioned from NEW to ALLOCATED
2014-05-05 12:29:38,937 INFO org.apache.hadoop.yarn.server.resourcemanager.RMAuditLogger: USER=ubuntu	OPERATION=AM Allocated Container	TARGET=SchedulerApp	RESULT=SUCCESS	APPID=application_1399292339232_0001	CONTAINERID=container_1399292339232_0001_01_000019
2014-05-05 12:29:38,937 INFO org.apache.hadoop.yarn.server.resourcemanager.scheduler.common.fica.FiCaSchedulerNode: Assigned container container_1399292339232_0001_01_000019 of capacity <memory:1024, vCores:1> on host nodee:49598, which currently has 1 containers, <memory:1024, vCores:1> used and <memory:7168, vCores:7> available
2014-05-05 12:29:38,937 INFO org.apache.hadoop.yarn.server.resourcemanager.scheduler.capacity.LeafQueue: assignedContainer application=application_1399292339232_0001 container=Container: [ContainerId: container_1399292339232_0001_01_000019, NodeId: nodee:49598, NodeHttpAddress: nodee:8042, Resource: <memory:1024, vCores:1>, Priority: 10, Token: Token { kind: ContainerToken, service: 10.0.0.198:49598 }, ] containerId=container_1399292339232_0001_01_000019 queue=default: capacity=1.0, absoluteCapacity=1.0, usedResources=<memory:6144, vCores:5>usedCapacity=0.09375, absoluteUsedCapacity=0.09375, numApps=1, numContainers=5 usedCapacity=0.09375 absoluteUsedCapacity=0.09375 used=<memory:6144, vCores:5> cluster=<memory:65536, vCores:64>
2014-05-05 12:29:38,937 INFO org.apache.hadoop.yarn.server.resourcemanager.scheduler.capacity.ParentQueue: Re-sorting assigned queue: root.default stats: default: capacity=1.0, absoluteCapacity=1.0, usedResources=<memory:7168, vCores:6>usedCapacity=0.109375, absoluteUsedCapacity=0.109375, numApps=1, numContainers=6
2014-05-05 12:29:38,937 INFO org.apache.hadoop.yarn.server.resourcemanager.scheduler.capacity.ParentQueue: assignedContainer queue=root usedCapacity=0.109375 absoluteUsedCapacity=0.109375 used=<memory:7168, vCores:6> cluster=<memory:65536, vCores:64>
2014-05-05 12:29:38,944 INFO org.apache.hadoop.yarn.server.resourcemanager.rmcontainer.RMContainerImpl: container_1399292339232_0001_01_000020 Container Transitioned from NEW to ALLOCATED
2014-05-05 12:29:38,944 INFO org.apache.hadoop.yarn.server.resourcemanager.RMAuditLogger: USER=ubuntu	OPERATION=AM Allocated Container	TARGET=SchedulerApp	RESULT=SUCCESS	APPID=application_1399292339232_0001	CONTAINERID=container_1399292339232_0001_01_000020
2014-05-05 12:29:38,944 INFO org.apache.hadoop.yarn.server.resourcemanager.scheduler.common.fica.FiCaSchedulerNode: Assigned container container_1399292339232_0001_01_000020 of capacity <memory:1024, vCores:1> on host noded:39305, which currently has 1 containers, <memory:1024, vCores:1> used and <memory:7168, vCores:7> available
2014-05-05 12:29:38,945 INFO org.apache.hadoop.yarn.server.resourcemanager.scheduler.capacity.LeafQueue: assignedContainer application=application_1399292339232_0001 container=Container: [ContainerId: container_1399292339232_0001_01_000020, NodeId: noded:39305, NodeHttpAddress: noded:8042, Resource: <memory:1024, vCores:1>, Priority: 10, Token: Token { kind: ContainerToken, service: 10.0.0.193:39305 }, ] containerId=container_1399292339232_0001_01_000020 queue=default: capacity=1.0, absoluteCapacity=1.0, usedResources=<memory:7168, vCores:6>usedCapacity=0.109375, absoluteUsedCapacity=0.109375, numApps=1, numContainers=6 usedCapacity=0.109375 absoluteUsedCapacity=0.109375 used=<memory:7168, vCores:6> cluster=<memory:65536, vCores:64>
2014-05-05 12:29:38,945 INFO org.apache.hadoop.yarn.server.resourcemanager.scheduler.capacity.ParentQueue: Re-sorting assigned queue: root.default stats: default: capacity=1.0, absoluteCapacity=1.0, usedResources=<memory:8192, vCores:7>usedCapacity=0.125, absoluteUsedCapacity=0.125, numApps=1, numContainers=7
2014-05-05 12:29:38,945 INFO org.apache.hadoop.yarn.server.resourcemanager.scheduler.capacity.ParentQueue: assignedContainer queue=root usedCapacity=0.125 absoluteUsedCapacity=0.125 used=<memory:8192, vCores:7> cluster=<memory:65536, vCores:64>
2014-05-05 12:29:38,945 INFO org.apache.hadoop.yarn.server.resourcemanager.rmcontainer.RMContainerImpl: container_1399292339232_0001_01_000021 Container Transitioned from NEW to ALLOCATED
2014-05-05 12:29:38,945 INFO org.apache.hadoop.yarn.server.resourcemanager.RMAuditLogger: USER=ubuntu	OPERATION=AM Allocated Container	TARGET=SchedulerApp	RESULT=SUCCESS	APPID=application_1399292339232_0001	CONTAINERID=container_1399292339232_0001_01_000021
2014-05-05 12:29:38,945 INFO org.apache.hadoop.yarn.server.resourcemanager.scheduler.common.fica.FiCaSchedulerNode: Assigned container container_1399292339232_0001_01_000021 of capacity <memory:1024, vCores:1> on host nodeg:56763, which currently has 1 containers, <memory:1024, vCores:1> used and <memory:7168, vCores:7> available
2014-05-05 12:29:38,946 INFO org.apache.hadoop.yarn.server.resourcemanager.scheduler.capacity.LeafQueue: assignedContainer application=application_1399292339232_0001 container=Container: [ContainerId: container_1399292339232_0001_01_000021, NodeId: nodeg:56763, NodeHttpAddress: nodeg:8042, Resource: <memory:1024, vCores:1>, Priority: 10, Token: Token { kind: ContainerToken, service: 10.0.0.196:56763 }, ] containerId=container_1399292339232_0001_01_000021 queue=default: capacity=1.0, absoluteCapacity=1.0, usedResources=<memory:8192, vCores:7>usedCapacity=0.125, absoluteUsedCapacity=0.125, numApps=1, numContainers=7 usedCapacity=0.125 absoluteUsedCapacity=0.125 used=<memory:8192, vCores:7> cluster=<memory:65536, vCores:64>
2014-05-05 12:29:38,946 INFO org.apache.hadoop.yarn.server.resourcemanager.scheduler.capacity.ParentQueue: Re-sorting assigned queue: root.default stats: default: capacity=1.0, absoluteCapacity=1.0, usedResources=<memory:9216, vCores:8>usedCapacity=0.140625, absoluteUsedCapacity=0.140625, numApps=1, numContainers=8
2014-05-05 12:29:38,946 INFO org.apache.hadoop.yarn.server.resourcemanager.scheduler.capacity.ParentQueue: assignedContainer queue=root usedCapacity=0.140625 absoluteUsedCapacity=0.140625 used=<memory:9216, vCores:8> cluster=<memory:65536, vCores:64>
2014-05-05 12:29:38,952 INFO org.apache.hadoop.yarn.server.resourcemanager.rmcontainer.RMContainerImpl: container_1399292339232_0001_01_000022 Container Transitioned from NEW to ALLOCATED
2014-05-05 12:29:38,952 INFO org.apache.hadoop.yarn.server.resourcemanager.RMAuditLogger: USER=ubuntu	OPERATION=AM Allocated Container	TARGET=SchedulerApp	RESULT=SUCCESS	APPID=application_1399292339232_0001	CONTAINERID=container_1399292339232_0001_01_000022
2014-05-05 12:29:38,952 INFO org.apache.hadoop.yarn.server.resourcemanager.scheduler.common.fica.FiCaSchedulerNode: Assigned container container_1399292339232_0001_01_000022 of capacity <memory:1024, vCores:1> on host nodeh:46599, which currently has 1 containers, <memory:1024, vCores:1> used and <memory:7168, vCores:7> available
2014-05-05 12:29:38,952 INFO org.apache.hadoop.yarn.server.resourcemanager.scheduler.capacity.LeafQueue: assignedContainer application=application_1399292339232_0001 container=Container: [ContainerId: container_1399292339232_0001_01_000022, NodeId: nodeh:46599, NodeHttpAddress: nodeh:8042, Resource: <memory:1024, vCores:1>, Priority: 10, Token: Token { kind: ContainerToken, service: 10.0.0.197:46599 }, ] containerId=container_1399292339232_0001_01_000022 queue=default: capacity=1.0, absoluteCapacity=1.0, usedResources=<memory:9216, vCores:8>usedCapacity=0.140625, absoluteUsedCapacity=0.140625, numApps=1, numContainers=8 usedCapacity=0.140625 absoluteUsedCapacity=0.140625 used=<memory:9216, vCores:8> cluster=<memory:65536, vCores:64>
2014-05-05 12:29:38,952 INFO org.apache.hadoop.yarn.server.resourcemanager.scheduler.capacity.ParentQueue: Re-sorting assigned queue: root.default stats: default: capacity=1.0, absoluteCapacity=1.0, usedResources=<memory:10240, vCores:9>usedCapacity=0.15625, absoluteUsedCapacity=0.15625, numApps=1, numContainers=9
2014-05-05 12:29:38,952 INFO org.apache.hadoop.yarn.server.resourcemanager.scheduler.capacity.ParentQueue: assignedContainer queue=root usedCapacity=0.15625 absoluteUsedCapacity=0.15625 used=<memory:10240, vCores:9> cluster=<memory:65536, vCores:64>
2014-05-05 12:29:39,479 INFO org.apache.hadoop.yarn.server.resourcemanager.rmcontainer.RMContainerImpl: container_1399292339232_0001_01_000015 Container Transitioned from ALLOCATED to ACQUIRED
2014-05-05 12:29:39,481 INFO org.apache.hadoop.yarn.server.resourcemanager.rmcontainer.RMContainerImpl: container_1399292339232_0001_01_000016 Container Transitioned from ALLOCATED to ACQUIRED
2014-05-05 12:29:39,482 INFO org.apache.hadoop.yarn.server.resourcemanager.rmcontainer.RMContainerImpl: container_1399292339232_0001_01_000017 Container Transitioned from ALLOCATED to ACQUIRED
2014-05-05 12:29:39,482 INFO org.apache.hadoop.yarn.server.resourcemanager.rmcontainer.RMContainerImpl: container_1399292339232_0001_01_000018 Container Transitioned from ALLOCATED to ACQUIRED
2014-05-05 12:29:39,482 INFO org.apache.hadoop.yarn.server.resourcemanager.rmcontainer.RMContainerImpl: container_1399292339232_0001_01_000019 Container Transitioned from ALLOCATED to ACQUIRED
2014-05-05 12:29:39,483 INFO org.apache.hadoop.yarn.server.resourcemanager.rmcontainer.RMContainerImpl: container_1399292339232_0001_01_000020 Container Transitioned from ALLOCATED to ACQUIRED
2014-05-05 12:29:39,483 INFO org.apache.hadoop.yarn.server.resourcemanager.rmcontainer.RMContainerImpl: container_1399292339232_0001_01_000021 Container Transitioned from ALLOCATED to ACQUIRED
2014-05-05 12:29:39,483 INFO org.apache.hadoop.yarn.server.resourcemanager.rmcontainer.RMContainerImpl: container_1399292339232_0001_01_000022 Container Transitioned from ALLOCATED to ACQUIRED
2014-05-05 12:29:39,726 INFO org.apache.hadoop.yarn.server.resourcemanager.rmcontainer.RMContainerImpl: container_1399292339232_0001_01_000015 Container Transitioned from ACQUIRED to RUNNING
2014-05-05 12:29:39,872 INFO org.apache.hadoop.yarn.server.resourcemanager.rmcontainer.RMContainerImpl: container_1399292339232_0001_01_000016 Container Transitioned from ACQUIRED to RUNNING
2014-05-05 12:29:39,906 INFO org.apache.hadoop.yarn.server.resourcemanager.rmcontainer.RMContainerImpl: container_1399292339232_0001_01_000017 Container Transitioned from ACQUIRED to RUNNING
2014-05-05 12:29:39,929 INFO org.apache.hadoop.yarn.server.resourcemanager.rmcontainer.RMContainerImpl: container_1399292339232_0001_01_000018 Container Transitioned from ACQUIRED to RUNNING
2014-05-05 12:29:39,938 INFO org.apache.hadoop.yarn.server.resourcemanager.rmcontainer.RMContainerImpl: container_1399292339232_0001_01_000019 Container Transitioned from ACQUIRED to RUNNING
2014-05-05 12:29:39,947 INFO org.apache.hadoop.yarn.server.resourcemanager.rmcontainer.RMContainerImpl: container_1399292339232_0001_01_000020 Container Transitioned from ACQUIRED to RUNNING
2014-05-05 12:29:39,947 INFO org.apache.hadoop.yarn.server.resourcemanager.rmcontainer.RMContainerImpl: container_1399292339232_0001_01_000021 Container Transitioned from ACQUIRED to RUNNING
2014-05-05 12:29:39,954 INFO org.apache.hadoop.yarn.server.resourcemanager.rmcontainer.RMContainerImpl: container_1399292339232_0001_01_000022 Container Transitioned from ACQUIRED to RUNNING
2014-05-05 12:29:40,489 INFO org.apache.hadoop.yarn.server.resourcemanager.scheduler.AppSchedulingInfo: checking for deactivate... 
2014-05-05 12:31:14,937 INFO org.apache.hadoop.yarn.server.resourcemanager.rmcontainer.RMContainerImpl: container_1399292339232_0001_01_000015 Container Transitioned from RUNNING to COMPLETED
2014-05-05 12:31:14,937 INFO org.apache.hadoop.yarn.server.resourcemanager.scheduler.common.fica.FiCaSchedulerApp: Completed container: container_1399292339232_0001_01_000015 in state: COMPLETED event:FINISHED
2014-05-05 12:31:14,937 INFO org.apache.hadoop.yarn.server.resourcemanager.RMAuditLogger: USER=ubuntu	OPERATION=AM Released Container	TARGET=SchedulerApp	RESULT=SUCCESS	APPID=application_1399292339232_0001	CONTAINERID=container_1399292339232_0001_01_000015
2014-05-05 12:31:14,937 INFO org.apache.hadoop.yarn.server.resourcemanager.scheduler.common.fica.FiCaSchedulerNode: Released container container_1399292339232_0001_01_000015 of capacity <memory:1024, vCores:1> on host nodeb:48885, which currently has 0 containers, <memory:0, vCores:0> used and <memory:8192, vCores:8> available, release resources=true
2014-05-05 12:31:14,937 INFO org.apache.hadoop.yarn.server.resourcemanager.scheduler.capacity.LeafQueue: default used=<memory:9216, vCores:8> numContainers=8 user=ubuntu user-resources=<memory:9216, vCores:8>
2014-05-05 12:31:14,937 INFO org.apache.hadoop.yarn.server.resourcemanager.scheduler.capacity.LeafQueue: completedContainer container=Container: [ContainerId: container_1399292339232_0001_01_000015, NodeId: nodeb:48885, NodeHttpAddress: nodeb:8042, Resource: <memory:1024, vCores:1>, Priority: 10, Token: Token { kind: ContainerToken, service: 10.0.0.194:48885 }, ] resource=<memory:1024, vCores:1> queue=default: capacity=1.0, absoluteCapacity=1.0, usedResources=<memory:9216, vCores:8>usedCapacity=0.140625, absoluteUsedCapacity=0.140625, numApps=1, numContainers=8 usedCapacity=0.140625 absoluteUsedCapacity=0.140625 used=<memory:9216, vCores:8> cluster=<memory:65536, vCores:64>
2014-05-05 12:31:14,937 INFO org.apache.hadoop.yarn.server.resourcemanager.scheduler.capacity.ParentQueue: completedContainer queue=root usedCapacity=0.140625 absoluteUsedCapacity=0.140625 used=<memory:9216, vCores:8> cluster=<memory:65536, vCores:64>
2014-05-05 12:31:14,937 INFO org.apache.hadoop.yarn.server.resourcemanager.scheduler.capacity.ParentQueue: Re-sorting completed queue: root.default stats: default: capacity=1.0, absoluteCapacity=1.0, usedResources=<memory:9216, vCores:8>usedCapacity=0.140625, absoluteUsedCapacity=0.140625, numApps=1, numContainers=8
2014-05-05 12:31:14,937 INFO org.apache.hadoop.yarn.server.resourcemanager.scheduler.capacity.CapacityScheduler: Application appattempt_1399292339232_0001_000001 released container container_1399292339232_0001_01_000015 on node: host: nodeb:48885 #containers=0 available=8192 used=0 with event: FINISHED
2014-05-05 12:31:39,944 INFO org.apache.hadoop.yarn.server.resourcemanager.rmcontainer.RMContainerImpl: container_1399292339232_0001_01_000017 Container Transitioned from RUNNING to COMPLETED
2014-05-05 12:31:39,944 INFO org.apache.hadoop.yarn.server.resourcemanager.scheduler.common.fica.FiCaSchedulerApp: Completed container: container_1399292339232_0001_01_000017 in state: COMPLETED event:FINISHED
2014-05-05 12:31:39,944 INFO org.apache.hadoop.yarn.server.resourcemanager.RMAuditLogger: USER=ubuntu	OPERATION=AM Released Container	TARGET=SchedulerApp	RESULT=SUCCESS	APPID=application_1399292339232_0001	CONTAINERID=container_1399292339232_0001_01_000017
2014-05-05 12:31:39,944 INFO org.apache.hadoop.yarn.server.resourcemanager.scheduler.common.fica.FiCaSchedulerNode: Released container container_1399292339232_0001_01_000017 of capacity <memory:1024, vCores:1> on host nodea:51924, which currently has 0 containers, <memory:0, vCores:0> used and <memory:8192, vCores:8> available, release resources=true
2014-05-05 12:31:39,944 INFO org.apache.hadoop.yarn.server.resourcemanager.scheduler.capacity.LeafQueue: default used=<memory:8192, vCores:7> numContainers=7 user=ubuntu user-resources=<memory:8192, vCores:7>
2014-05-05 12:31:39,944 INFO org.apache.hadoop.yarn.server.resourcemanager.scheduler.capacity.LeafQueue: completedContainer container=Container: [ContainerId: container_1399292339232_0001_01_000017, NodeId: nodea:51924, NodeHttpAddress: nodea:8042, Resource: <memory:1024, vCores:1>, Priority: 10, Token: Token { kind: ContainerToken, service: 10.0.0.195:51924 }, ] resource=<memory:1024, vCores:1> queue=default: capacity=1.0, absoluteCapacity=1.0, usedResources=<memory:8192, vCores:7>usedCapacity=0.125, absoluteUsedCapacity=0.125, numApps=1, numContainers=7 usedCapacity=0.125 absoluteUsedCapacity=0.125 used=<memory:8192, vCores:7> cluster=<memory:65536, vCores:64>
2014-05-05 12:31:39,944 INFO org.apache.hadoop.yarn.server.resourcemanager.scheduler.capacity.ParentQueue: completedContainer queue=root usedCapacity=0.125 absoluteUsedCapacity=0.125 used=<memory:8192, vCores:7> cluster=<memory:65536, vCores:64>
2014-05-05 12:31:39,944 INFO org.apache.hadoop.yarn.server.resourcemanager.scheduler.capacity.ParentQueue: Re-sorting completed queue: root.default stats: default: capacity=1.0, absoluteCapacity=1.0, usedResources=<memory:8192, vCores:7>usedCapacity=0.125, absoluteUsedCapacity=0.125, numApps=1, numContainers=7
2014-05-05 12:31:39,945 INFO org.apache.hadoop.yarn.server.resourcemanager.scheduler.capacity.CapacityScheduler: Application appattempt_1399292339232_0001_000001 released container container_1399292339232_0001_01_000017 on node: host: nodea:51924 #containers=0 available=8192 used=0 with event: FINISHED
2014-05-05 12:31:43,302 INFO org.apache.hadoop.yarn.server.resourcemanager.rmcontainer.RMContainerImpl: container_1399292339232_0001_01_000016 Container Transitioned from RUNNING to COMPLETED
2014-05-05 12:31:43,303 INFO org.apache.hadoop.yarn.server.resourcemanager.scheduler.common.fica.FiCaSchedulerApp: Completed container: container_1399292339232_0001_01_000016 in state: COMPLETED event:FINISHED
2014-05-05 12:31:43,303 INFO org.apache.hadoop.yarn.server.resourcemanager.RMAuditLogger: USER=ubuntu	OPERATION=AM Released Container	TARGET=SchedulerApp	RESULT=SUCCESS	APPID=application_1399292339232_0001	CONTAINERID=container_1399292339232_0001_01_000016
2014-05-05 12:31:43,303 INFO org.apache.hadoop.yarn.server.resourcemanager.scheduler.common.fica.FiCaSchedulerNode: Released container container_1399292339232_0001_01_000016 of capacity <memory:1024, vCores:1> on host nodef:54669, which currently has 1 containers, <memory:2048, vCores:1> used and <memory:6144, vCores:7> available, release resources=true
2014-05-05 12:31:43,303 INFO org.apache.hadoop.yarn.server.resourcemanager.scheduler.capacity.LeafQueue: default used=<memory:7168, vCores:6> numContainers=6 user=ubuntu user-resources=<memory:7168, vCores:6>
2014-05-05 12:31:43,303 INFO org.apache.hadoop.yarn.server.resourcemanager.scheduler.capacity.LeafQueue: completedContainer container=Container: [ContainerId: container_1399292339232_0001_01_000016, NodeId: nodef:54669, NodeHttpAddress: nodef:8042, Resource: <memory:1024, vCores:1>, Priority: 10, Token: Token { kind: ContainerToken, service: 10.0.0.199:54669 }, ] resource=<memory:1024, vCores:1> queue=default: capacity=1.0, absoluteCapacity=1.0, usedResources=<memory:7168, vCores:6>usedCapacity=0.109375, absoluteUsedCapacity=0.109375, numApps=1, numContainers=6 usedCapacity=0.109375 absoluteUsedCapacity=0.109375 used=<memory:7168, vCores:6> cluster=<memory:65536, vCores:64>
2014-05-05 12:31:43,303 INFO org.apache.hadoop.yarn.server.resourcemanager.scheduler.capacity.ParentQueue: completedContainer queue=root usedCapacity=0.109375 absoluteUsedCapacity=0.109375 used=<memory:7168, vCores:6> cluster=<memory:65536, vCores:64>
2014-05-05 12:31:43,303 INFO org.apache.hadoop.yarn.server.resourcemanager.scheduler.capacity.ParentQueue: Re-sorting completed queue: root.default stats: default: capacity=1.0, absoluteCapacity=1.0, usedResources=<memory:7168, vCores:6>usedCapacity=0.109375, absoluteUsedCapacity=0.109375, numApps=1, numContainers=6
2014-05-05 12:31:43,303 INFO org.apache.hadoop.yarn.server.resourcemanager.scheduler.capacity.CapacityScheduler: Application appattempt_1399292339232_0001_000001 released container container_1399292339232_0001_01_000016 on node: host: nodef:54669 #containers=1 available=6144 used=2048 with event: FINISHED
2014-05-05 12:31:43,609 INFO org.apache.hadoop.yarn.server.resourcemanager.rmcontainer.RMContainerImpl: container_1399292339232_0001_01_000020 Container Transitioned from RUNNING to COMPLETED
2014-05-05 12:31:43,609 INFO org.apache.hadoop.yarn.server.resourcemanager.scheduler.common.fica.FiCaSchedulerApp: Completed container: container_1399292339232_0001_01_000020 in state: COMPLETED event:FINISHED
2014-05-05 12:31:43,609 INFO org.apache.hadoop.yarn.server.resourcemanager.RMAuditLogger: USER=ubuntu	OPERATION=AM Released Container	TARGET=SchedulerApp	RESULT=SUCCESS	APPID=application_1399292339232_0001	CONTAINERID=container_1399292339232_0001_01_000020
2014-05-05 12:31:43,609 INFO org.apache.hadoop.yarn.server.resourcemanager.scheduler.common.fica.FiCaSchedulerNode: Released container container_1399292339232_0001_01_000020 of capacity <memory:1024, vCores:1> on host noded:39305, which currently has 0 containers, <memory:0, vCores:0> used and <memory:8192, vCores:8> available, release resources=true
2014-05-05 12:31:43,610 INFO org.apache.hadoop.yarn.server.resourcemanager.scheduler.capacity.LeafQueue: default used=<memory:6144, vCores:5> numContainers=5 user=ubuntu user-resources=<memory:6144, vCores:5>
2014-05-05 12:31:43,610 INFO org.apache.hadoop.yarn.server.resourcemanager.scheduler.capacity.LeafQueue: completedContainer container=Container: [ContainerId: container_1399292339232_0001_01_000020, NodeId: noded:39305, NodeHttpAddress: noded:8042, Resource: <memory:1024, vCores:1>, Priority: 10, Token: Token { kind: ContainerToken, service: 10.0.0.193:39305 }, ] resource=<memory:1024, vCores:1> queue=default: capacity=1.0, absoluteCapacity=1.0, usedResources=<memory:6144, vCores:5>usedCapacity=0.09375, absoluteUsedCapacity=0.09375, numApps=1, numContainers=5 usedCapacity=0.09375 absoluteUsedCapacity=0.09375 used=<memory:6144, vCores:5> cluster=<memory:65536, vCores:64>
2014-05-05 12:31:43,610 INFO org.apache.hadoop.yarn.server.resourcemanager.scheduler.capacity.ParentQueue: completedContainer queue=root usedCapacity=0.09375 absoluteUsedCapacity=0.09375 used=<memory:6144, vCores:5> cluster=<memory:65536, vCores:64>
2014-05-05 12:31:43,610 INFO org.apache.hadoop.yarn.server.resourcemanager.scheduler.capacity.ParentQueue: Re-sorting completed queue: root.default stats: default: capacity=1.0, absoluteCapacity=1.0, usedResources=<memory:6144, vCores:5>usedCapacity=0.09375, absoluteUsedCapacity=0.09375, numApps=1, numContainers=5
2014-05-05 12:31:43,610 INFO org.apache.hadoop.yarn.server.resourcemanager.scheduler.capacity.CapacityScheduler: Application appattempt_1399292339232_0001_000001 released container container_1399292339232_0001_01_000020 on node: host: noded:39305 #containers=0 available=8192 used=0 with event: FINISHED
2014-05-05 12:31:49,756 INFO org.apache.hadoop.yarn.server.resourcemanager.rmcontainer.RMContainerImpl: container_1399292339232_0001_01_000021 Container Transitioned from RUNNING to COMPLETED
2014-05-05 12:31:49,756 INFO org.apache.hadoop.yarn.server.resourcemanager.scheduler.common.fica.FiCaSchedulerApp: Completed container: container_1399292339232_0001_01_000021 in state: COMPLETED event:FINISHED
2014-05-05 12:31:49,756 INFO org.apache.hadoop.yarn.server.resourcemanager.RMAuditLogger: USER=ubuntu	OPERATION=AM Released Container	TARGET=SchedulerApp	RESULT=SUCCESS	APPID=application_1399292339232_0001	CONTAINERID=container_1399292339232_0001_01_000021
2014-05-05 12:31:49,756 INFO org.apache.hadoop.yarn.server.resourcemanager.scheduler.common.fica.FiCaSchedulerNode: Released container container_1399292339232_0001_01_000021 of capacity <memory:1024, vCores:1> on host nodeg:56763, which currently has 0 containers, <memory:0, vCores:0> used and <memory:8192, vCores:8> available, release resources=true
2014-05-05 12:31:49,756 INFO org.apache.hadoop.yarn.server.resourcemanager.scheduler.capacity.LeafQueue: default used=<memory:5120, vCores:4> numContainers=4 user=ubuntu user-resources=<memory:5120, vCores:4>
2014-05-05 12:31:49,757 INFO org.apache.hadoop.yarn.server.resourcemanager.scheduler.capacity.LeafQueue: completedContainer container=Container: [ContainerId: container_1399292339232_0001_01_000021, NodeId: nodeg:56763, NodeHttpAddress: nodeg:8042, Resource: <memory:1024, vCores:1>, Priority: 10, Token: Token { kind: ContainerToken, service: 10.0.0.196:56763 }, ] resource=<memory:1024, vCores:1> queue=default: capacity=1.0, absoluteCapacity=1.0, usedResources=<memory:5120, vCores:4>usedCapacity=0.078125, absoluteUsedCapacity=0.078125, numApps=1, numContainers=4 usedCapacity=0.078125 absoluteUsedCapacity=0.078125 used=<memory:5120, vCores:4> cluster=<memory:65536, vCores:64>
2014-05-05 12:31:49,757 INFO org.apache.hadoop.yarn.server.resourcemanager.scheduler.capacity.ParentQueue: completedContainer queue=root usedCapacity=0.078125 absoluteUsedCapacity=0.078125 used=<memory:5120, vCores:4> cluster=<memory:65536, vCores:64>
2014-05-05 12:31:49,757 INFO org.apache.hadoop.yarn.server.resourcemanager.scheduler.capacity.ParentQueue: Re-sorting completed queue: root.default stats: default: capacity=1.0, absoluteCapacity=1.0, usedResources=<memory:5120, vCores:4>usedCapacity=0.078125, absoluteUsedCapacity=0.078125, numApps=1, numContainers=4
2014-05-05 12:31:49,757 INFO org.apache.hadoop.yarn.server.resourcemanager.scheduler.capacity.CapacityScheduler: Application appattempt_1399292339232_0001_000001 released container container_1399292339232_0001_01_000021 on node: host: nodeg:56763 #containers=0 available=8192 used=0 with event: FINISHED
2014-05-05 12:31:52,335 INFO org.apache.hadoop.yarn.server.resourcemanager.rmcontainer.RMContainerImpl: container_1399292339232_0001_01_000022 Container Transitioned from RUNNING to COMPLETED
2014-05-05 12:31:52,335 INFO org.apache.hadoop.yarn.server.resourcemanager.scheduler.common.fica.FiCaSchedulerApp: Completed container: container_1399292339232_0001_01_000022 in state: COMPLETED event:FINISHED
2014-05-05 12:31:52,335 INFO org.apache.hadoop.yarn.server.resourcemanager.RMAuditLogger: USER=ubuntu	OPERATION=AM Released Container	TARGET=SchedulerApp	RESULT=SUCCESS	APPID=application_1399292339232_0001	CONTAINERID=container_1399292339232_0001_01_000022
2014-05-05 12:31:52,335 INFO org.apache.hadoop.yarn.server.resourcemanager.scheduler.common.fica.FiCaSchedulerNode: Released container container_1399292339232_0001_01_000022 of capacity <memory:1024, vCores:1> on host nodeh:46599, which currently has 0 containers, <memory:0, vCores:0> used and <memory:8192, vCores:8> available, release resources=true
2014-05-05 12:31:52,335 INFO org.apache.hadoop.yarn.server.resourcemanager.scheduler.capacity.LeafQueue: default used=<memory:4096, vCores:3> numContainers=3 user=ubuntu user-resources=<memory:4096, vCores:3>
2014-05-05 12:31:52,336 INFO org.apache.hadoop.yarn.server.resourcemanager.scheduler.capacity.LeafQueue: completedContainer container=Container: [ContainerId: container_1399292339232_0001_01_000022, NodeId: nodeh:46599, NodeHttpAddress: nodeh:8042, Resource: <memory:1024, vCores:1>, Priority: 10, Token: Token { kind: ContainerToken, service: 10.0.0.197:46599 }, ] resource=<memory:1024, vCores:1> queue=default: capacity=1.0, absoluteCapacity=1.0, usedResources=<memory:4096, vCores:3>usedCapacity=0.0625, absoluteUsedCapacity=0.0625, numApps=1, numContainers=3 usedCapacity=0.0625 absoluteUsedCapacity=0.0625 used=<memory:4096, vCores:3> cluster=<memory:65536, vCores:64>
2014-05-05 12:31:52,336 INFO org.apache.hadoop.yarn.server.resourcemanager.scheduler.capacity.ParentQueue: completedContainer queue=root usedCapacity=0.0625 absoluteUsedCapacity=0.0625 used=<memory:4096, vCores:3> cluster=<memory:65536, vCores:64>
2014-05-05 12:31:52,336 INFO org.apache.hadoop.yarn.server.resourcemanager.scheduler.capacity.ParentQueue: Re-sorting completed queue: root.default stats: default: capacity=1.0, absoluteCapacity=1.0, usedResources=<memory:4096, vCores:3>usedCapacity=0.0625, absoluteUsedCapacity=0.0625, numApps=1, numContainers=3
2014-05-05 12:31:52,336 INFO org.apache.hadoop.yarn.server.resourcemanager.scheduler.capacity.CapacityScheduler: Application appattempt_1399292339232_0001_000001 released container container_1399292339232_0001_01_000022 on node: host: nodeh:46599 #containers=0 available=8192 used=0 with event: FINISHED
2014-05-05 12:31:53,322 INFO org.apache.hadoop.yarn.server.resourcemanager.rmcontainer.RMContainerImpl: container_1399292339232_0001_01_000018 Container Transitioned from RUNNING to COMPLETED
2014-05-05 12:31:53,322 INFO org.apache.hadoop.yarn.server.resourcemanager.scheduler.common.fica.FiCaSchedulerApp: Completed container: container_1399292339232_0001_01_000018 in state: COMPLETED event:FINISHED
2014-05-05 12:31:53,322 INFO org.apache.hadoop.yarn.server.resourcemanager.RMAuditLogger: USER=ubuntu	OPERATION=AM Released Container	TARGET=SchedulerApp	RESULT=SUCCESS	APPID=application_1399292339232_0001	CONTAINERID=container_1399292339232_0001_01_000018
2014-05-05 12:31:53,322 INFO org.apache.hadoop.yarn.server.resourcemanager.scheduler.common.fica.FiCaSchedulerNode: Released container container_1399292339232_0001_01_000018 of capacity <memory:1024, vCores:1> on host nodec:35478, which currently has 0 containers, <memory:0, vCores:0> used and <memory:8192, vCores:8> available, release resources=true
2014-05-05 12:31:53,322 INFO org.apache.hadoop.yarn.server.resourcemanager.scheduler.capacity.LeafQueue: default used=<memory:3072, vCores:2> numContainers=2 user=ubuntu user-resources=<memory:3072, vCores:2>
2014-05-05 12:31:53,322 INFO org.apache.hadoop.yarn.server.resourcemanager.scheduler.capacity.LeafQueue: completedContainer container=Container: [ContainerId: container_1399292339232_0001_01_000018, NodeId: nodec:35478, NodeHttpAddress: nodec:8042, Resource: <memory:1024, vCores:1>, Priority: 10, Token: Token { kind: ContainerToken, service: 10.0.0.200:35478 }, ] resource=<memory:1024, vCores:1> queue=default: capacity=1.0, absoluteCapacity=1.0, usedResources=<memory:3072, vCores:2>usedCapacity=0.046875, absoluteUsedCapacity=0.046875, numApps=1, numContainers=2 usedCapacity=0.046875 absoluteUsedCapacity=0.046875 used=<memory:3072, vCores:2> cluster=<memory:65536, vCores:64>
2014-05-05 12:31:53,323 INFO org.apache.hadoop.yarn.server.resourcemanager.scheduler.capacity.ParentQueue: completedContainer queue=root usedCapacity=0.046875 absoluteUsedCapacity=0.046875 used=<memory:3072, vCores:2> cluster=<memory:65536, vCores:64>
2014-05-05 12:31:53,323 INFO org.apache.hadoop.yarn.server.resourcemanager.scheduler.capacity.ParentQueue: Re-sorting completed queue: root.default stats: default: capacity=1.0, absoluteCapacity=1.0, usedResources=<memory:3072, vCores:2>usedCapacity=0.046875, absoluteUsedCapacity=0.046875, numApps=1, numContainers=2
2014-05-05 12:31:53,323 INFO org.apache.hadoop.yarn.server.resourcemanager.scheduler.capacity.CapacityScheduler: Application appattempt_1399292339232_0001_000001 released container container_1399292339232_0001_01_000018 on node: host: nodec:35478 #containers=0 available=8192 used=0 with event: FINISHED
2014-05-05 12:31:53,333 INFO org.apache.hadoop.yarn.server.resourcemanager.rmapp.attempt.RMAppAttemptImpl: appattempt_1399292339232_0001_000001 State change from RUNNING to FINISHING
2014-05-05 12:31:53,334 INFO org.apache.hadoop.yarn.server.resourcemanager.rmapp.RMAppImpl: Removing application with id application_1399292339232_0001
2014-05-05 12:31:53,335 INFO org.apache.hadoop.yarn.server.resourcemanager.recovery.RMStateStore: Removing info for app: application_1399292339232_0001
2014-05-05 12:31:53,335 INFO org.apache.hadoop.yarn.server.resourcemanager.rmapp.RMAppImpl: application_1399292339232_0001 State change from RUNNING to REMOVING
2014-05-05 12:31:53,335 INFO org.apache.hadoop.yarn.server.resourcemanager.rmapp.RMAppImpl: application_1399292339232_0001 State change from REMOVING to FINISHING
2014-05-05 12:31:54,084 INFO org.apache.hadoop.yarn.server.resourcemanager.rmcontainer.RMContainerImpl: container_1399292339232_0001_01_000019 Container Transitioned from RUNNING to COMPLETED
2014-05-05 12:31:54,084 INFO org.apache.hadoop.yarn.server.resourcemanager.scheduler.common.fica.FiCaSchedulerApp: Completed container: container_1399292339232_0001_01_000019 in state: COMPLETED event:FINISHED
2014-05-05 12:31:54,087 INFO org.apache.hadoop.yarn.server.resourcemanager.RMAuditLogger: USER=ubuntu	OPERATION=AM Released Container	TARGET=SchedulerApp	RESULT=SUCCESS	APPID=application_1399292339232_0001	CONTAINERID=container_1399292339232_0001_01_000019
2014-05-05 12:31:54,087 INFO org.apache.hadoop.yarn.server.resourcemanager.scheduler.common.fica.FiCaSchedulerNode: Released container container_1399292339232_0001_01_000019 of capacity <memory:1024, vCores:1> on host nodee:49598, which currently has 0 containers, <memory:0, vCores:0> used and <memory:8192, vCores:8> available, release resources=true
2014-05-05 12:31:54,088 INFO org.apache.hadoop.yarn.server.resourcemanager.scheduler.capacity.LeafQueue: default used=<memory:2048, vCores:1> numContainers=1 user=ubuntu user-resources=<memory:2048, vCores:1>
2014-05-05 12:31:54,088 INFO org.apache.hadoop.yarn.server.resourcemanager.scheduler.capacity.LeafQueue: completedContainer container=Container: [ContainerId: container_1399292339232_0001_01_000019, NodeId: nodee:49598, NodeHttpAddress: nodee:8042, Resource: <memory:1024, vCores:1>, Priority: 10, Token: Token { kind: ContainerToken, service: 10.0.0.198:49598 }, ] resource=<memory:1024, vCores:1> queue=default: capacity=1.0, absoluteCapacity=1.0, usedResources=<memory:2048, vCores:1>usedCapacity=0.03125, absoluteUsedCapacity=0.03125, numApps=1, numContainers=1 usedCapacity=0.03125 absoluteUsedCapacity=0.03125 used=<memory:2048, vCores:1> cluster=<memory:65536, vCores:64>
2014-05-05 12:31:54,088 INFO org.apache.hadoop.yarn.server.resourcemanager.scheduler.capacity.ParentQueue: completedContainer queue=root usedCapacity=0.03125 absoluteUsedCapacity=0.03125 used=<memory:2048, vCores:1> cluster=<memory:65536, vCores:64>
2014-05-05 12:31:54,088 INFO org.apache.hadoop.yarn.server.resourcemanager.scheduler.capacity.ParentQueue: Re-sorting completed queue: root.default stats: default: capacity=1.0, absoluteCapacity=1.0, usedResources=<memory:2048, vCores:1>usedCapacity=0.03125, absoluteUsedCapacity=0.03125, numApps=1, numContainers=1
2014-05-05 12:31:54,088 INFO org.apache.hadoop.yarn.server.resourcemanager.scheduler.capacity.CapacityScheduler: Application appattempt_1399292339232_0001_000001 released container container_1399292339232_0001_01_000019 on node: host: nodee:49598 #containers=0 available=8192 used=0 with event: FINISHED
2014-05-05 12:32:00,334 INFO org.apache.hadoop.yarn.server.resourcemanager.rmcontainer.RMContainerImpl: container_1399292339232_0001_01_000001 Container Transitioned from RUNNING to COMPLETED
2014-05-05 12:32:00,334 INFO org.apache.hadoop.yarn.server.resourcemanager.ApplicationMasterService: Unregistering app attempt : appattempt_1399292339232_0001_000001
2014-05-05 12:32:00,334 INFO org.apache.hadoop.yarn.server.resourcemanager.scheduler.common.fica.FiCaSchedulerApp: Completed container: container_1399292339232_0001_01_000001 in state: COMPLETED event:FINISHED
2014-05-05 12:32:00,334 INFO org.apache.hadoop.yarn.server.resourcemanager.RMAuditLogger: USER=ubuntu	OPERATION=AM Released Container	TARGET=SchedulerApp	RESULT=SUCCESS	APPID=application_1399292339232_0001	CONTAINERID=container_1399292339232_0001_01_000001
2014-05-05 12:32:00,334 INFO org.apache.hadoop.yarn.server.resourcemanager.scheduler.common.fica.FiCaSchedulerNode: Released container container_1399292339232_0001_01_000001 of capacity <memory:2048, vCores:1> on host nodef:54669, which currently has 0 containers, <memory:0, vCores:0> used and <memory:8192, vCores:8> available, release resources=true
2014-05-05 12:32:00,334 INFO org.apache.hadoop.yarn.server.resourcemanager.scheduler.capacity.LeafQueue: default used=<memory:0, vCores:0> numContainers=0 user=ubuntu user-resources=<memory:0, vCores:0>
2014-05-05 12:32:00,335 INFO org.apache.hadoop.yarn.server.resourcemanager.scheduler.capacity.LeafQueue: completedContainer container=Container: [ContainerId: container_1399292339232_0001_01_000001, NodeId: nodef:54669, NodeHttpAddress: nodef:8042, Resource: <memory:2048, vCores:1>, Priority: 0, Token: Token { kind: ContainerToken, service: 10.0.0.199:54669 }, ] resource=<memory:2048, vCores:1> queue=default: capacity=1.0, absoluteCapacity=1.0, usedResources=<memory:0, vCores:0>usedCapacity=0.0, absoluteUsedCapacity=0.0, numApps=1, numContainers=0 usedCapacity=0.0 absoluteUsedCapacity=0.0 used=<memory:0, vCores:0> cluster=<memory:65536, vCores:64>
2014-05-05 12:32:00,335 INFO org.apache.hadoop.yarn.server.resourcemanager.scheduler.capacity.ParentQueue: completedContainer queue=root usedCapacity=0.0 absoluteUsedCapacity=0.0 used=<memory:0, vCores:0> cluster=<memory:65536, vCores:64>
2014-05-05 12:32:00,335 INFO org.apache.hadoop.yarn.server.resourcemanager.scheduler.capacity.ParentQueue: Re-sorting completed queue: root.default stats: default: capacity=1.0, absoluteCapacity=1.0, usedResources=<memory:0, vCores:0>usedCapacity=0.0, absoluteUsedCapacity=0.0, numApps=1, numContainers=0
2014-05-05 12:32:00,335 INFO org.apache.hadoop.yarn.server.resourcemanager.scheduler.capacity.CapacityScheduler: Application appattempt_1399292339232_0001_000001 released container container_1399292339232_0001_01_000001 on node: host: nodef:54669 #containers=0 available=8192 used=0 with event: FINISHED
2014-05-05 12:32:00,336 INFO org.apache.hadoop.yarn.server.resourcemanager.rmapp.attempt.RMAppAttemptImpl: appattempt_1399292339232_0001_000001 State change from FINISHING to FINISHED
2014-05-05 12:32:00,337 INFO org.apache.hadoop.yarn.server.resourcemanager.rmapp.RMAppImpl: application_1399292339232_0001 State change from FINISHING to FINISHED
2014-05-05 12:32:00,338 INFO org.apache.hadoop.yarn.server.resourcemanager.scheduler.capacity.CapacityScheduler: Application appattempt_1399292339232_0001_000001 is done. finalState=FINISHED
2014-05-05 12:32:00,344 INFO org.apache.hadoop.yarn.server.resourcemanager.scheduler.AppSchedulingInfo: Application application_1399292339232_0001 requests cleared
2014-05-05 12:32:00,344 INFO org.apache.hadoop.yarn.server.resourcemanager.scheduler.capacity.LeafQueue: Application removed - appId: application_1399292339232_0001 user: ubuntu queue: default #user-pending-applications: 0 #user-active-applications: 0 #queue-pending-applications: 0 #queue-active-applications: 0
2014-05-05 12:32:00,344 INFO org.apache.hadoop.yarn.server.resourcemanager.scheduler.capacity.ParentQueue: Application removed - appId: application_1399292339232_0001 user: ubuntu leaf-queue of parent: root #applications: 0
2014-05-05 12:32:00,345 INFO org.apache.hadoop.yarn.server.resourcemanager.RMAuditLogger: USER=ubuntu	OPERATION=Application Finished - Succeeded	TARGET=RMAppManager	RESULT=SUCCESS	APPID=application_1399292339232_0001
2014-05-05 12:32:00,347 INFO org.apache.hadoop.yarn.server.resourcemanager.RMAppManager$ApplicationSummary: appId=application_1399292339232_0001,name=hints||path:/in1m||num reduce:8,user=ubuntu,queue=default,state=FINISHED,trackingUrl=ec2-54-186-230-200.us-west-2.compute.amazonaws.com:8088/proxy/application_1399292339232_0001/jobhistory/job/job_1399292339232_0001,appMasterHost=ip-10-0-0-199,startTime=1399292876224,finishTime=1399293113335,finalStatus=SUCCEEDED
2014-05-05 12:32:00,345 INFO org.apache.hadoop.yarn.server.resourcemanager.amlauncher.AMLauncher: Cleaning master appattempt_1399292339232_0001_000001
2014-05-05 12:34:26,074 INFO org.apache.hadoop.yarn.server.resourcemanager.ClientRMService: Allocated new applicationId: 2
2014-05-05 12:34:27,778 INFO org.apache.hadoop.yarn.server.resourcemanager.ClientRMService: Application with id 2 submitted by user ubuntu
2014-05-05 12:34:27,778 INFO org.apache.hadoop.yarn.server.resourcemanager.rmapp.RMAppImpl: Storing application with id application_1399292339232_0002
2014-05-05 12:34:27,778 INFO org.apache.hadoop.yarn.server.resourcemanager.rmapp.RMAppImpl: application_1399292339232_0002 State change from NEW to NEW_SAVING
2014-05-05 12:34:27,778 INFO org.apache.hadoop.yarn.server.resourcemanager.RMAuditLogger: USER=ubuntu	IP=10.0.0.195	OPERATION=Submit Application Request	TARGET=ClientRMService	RESULT=SUCCESS	APPID=application_1399292339232_0002
2014-05-05 12:34:27,778 INFO org.apache.hadoop.yarn.server.resourcemanager.recovery.RMStateStore: Storing info for app: application_1399292339232_0002
2014-05-05 12:34:27,780 INFO org.apache.hadoop.yarn.server.resourcemanager.rmapp.RMAppImpl: application_1399292339232_0002 State change from NEW_SAVING to SUBMITTED
2014-05-05 12:34:27,780 INFO org.apache.hadoop.yarn.server.resourcemanager.ApplicationMasterService: Registering app attempt : appattempt_1399292339232_0002_000001
2014-05-05 12:34:27,780 INFO org.apache.hadoop.yarn.server.resourcemanager.rmapp.attempt.RMAppAttemptImpl: appattempt_1399292339232_0002_000001 State change from NEW to SUBMITTED
2014-05-05 12:34:27,780 INFO org.apache.hadoop.yarn.server.resourcemanager.scheduler.capacity.LeafQueue: Application application_1399292339232_0002 from user: ubuntu activated in queue: default
2014-05-05 12:34:27,780 INFO org.apache.hadoop.yarn.server.resourcemanager.scheduler.capacity.LeafQueue: Application added - appId: application_1399292339232_0002 user: org.apache.hadoop.yarn.server.resourcemanager.scheduler.capacity.LeafQueue$User@f94be93, leaf-queue: default #user-pending-applications: 0 #user-active-applications: 1 #queue-pending-applications: 0 #queue-active-applications: 1
2014-05-05 12:34:27,781 INFO org.apache.hadoop.yarn.server.resourcemanager.scheduler.capacity.ParentQueue: Application added - appId: application_1399292339232_0002 user: ubuntu leaf-queue of parent: root #applications: 1
2014-05-05 12:34:27,781 INFO org.apache.hadoop.yarn.server.resourcemanager.scheduler.capacity.CapacityScheduler: Application Submission: appattempt_1399292339232_0002_000001, user: ubuntu queue: default: capacity=1.0, absoluteCapacity=1.0, usedResources=<memory:0, vCores:0>usedCapacity=0.0, absoluteUsedCapacity=0.0, numApps=1, numContainers=0, currently active: 1
2014-05-05 12:34:27,781 INFO org.apache.hadoop.yarn.server.resourcemanager.rmapp.attempt.RMAppAttemptImpl: appattempt_1399292339232_0002_000001 State change from SUBMITTED to SCHEDULED
2014-05-05 12:34:27,781 INFO org.apache.hadoop.yarn.server.resourcemanager.rmapp.RMAppImpl: application_1399292339232_0002 State change from SUBMITTED to ACCEPTED
2014-05-05 12:34:27,801 INFO org.apache.hadoop.yarn.server.resourcemanager.rmcontainer.RMContainerImpl: container_1399292339232_0002_01_000001 Container Transitioned from NEW to ALLOCATED
2014-05-05 12:34:27,801 INFO org.apache.hadoop.yarn.server.resourcemanager.RMAuditLogger: USER=ubuntu	OPERATION=AM Allocated Container	TARGET=SchedulerApp	RESULT=SUCCESS	APPID=application_1399292339232_0002	CONTAINERID=container_1399292339232_0002_01_000001
2014-05-05 12:34:27,801 INFO org.apache.hadoop.yarn.server.resourcemanager.scheduler.common.fica.FiCaSchedulerNode: Assigned container container_1399292339232_0002_01_000001 of capacity <memory:2048, vCores:1> on host noded:39305, which currently has 1 containers, <memory:2048, vCores:1> used and <memory:6144, vCores:7> available
2014-05-05 12:34:27,801 INFO org.apache.hadoop.yarn.server.resourcemanager.scheduler.capacity.LeafQueue: assignedContainer application=application_1399292339232_0002 container=Container: [ContainerId: container_1399292339232_0002_01_000001, NodeId: noded:39305, NodeHttpAddress: noded:8042, Resource: <memory:2048, vCores:1>, Priority: 0, Token: Token { kind: ContainerToken, service: 10.0.0.193:39305 }, ] containerId=container_1399292339232_0002_01_000001 queue=default: capacity=1.0, absoluteCapacity=1.0, usedResources=<memory:0, vCores:0>usedCapacity=0.0, absoluteUsedCapacity=0.0, numApps=1, numContainers=0 usedCapacity=0.0 absoluteUsedCapacity=0.0 used=<memory:0, vCores:0> cluster=<memory:65536, vCores:64>
2014-05-05 12:34:27,801 INFO org.apache.hadoop.yarn.server.resourcemanager.scheduler.capacity.ParentQueue: Re-sorting assigned queue: root.default stats: default: capacity=1.0, absoluteCapacity=1.0, usedResources=<memory:2048, vCores:1>usedCapacity=0.03125, absoluteUsedCapacity=0.03125, numApps=1, numContainers=1
2014-05-05 12:34:27,801 INFO org.apache.hadoop.yarn.server.resourcemanager.scheduler.capacity.ParentQueue: assignedContainer queue=root usedCapacity=0.03125 absoluteUsedCapacity=0.03125 used=<memory:2048, vCores:1> cluster=<memory:65536, vCores:64>
2014-05-05 12:34:27,802 INFO org.apache.hadoop.yarn.server.resourcemanager.rmcontainer.RMContainerImpl: container_1399292339232_0002_01_000001 Container Transitioned from ALLOCATED to ACQUIRED
2014-05-05 12:34:27,803 INFO org.apache.hadoop.yarn.server.resourcemanager.rmapp.attempt.RMAppAttemptImpl: Storing attempt: AppId: application_1399292339232_0002 AttemptId: appattempt_1399292339232_0002_000001 MasterContainer: Container: [ContainerId: container_1399292339232_0002_01_000001, NodeId: noded:39305, NodeHttpAddress: noded:8042, Resource: <memory:2048, vCores:1>, Priority: 0, Token: Token { kind: ContainerToken, service: 10.0.0.193:39305 }, ]
2014-05-05 12:34:27,803 INFO org.apache.hadoop.yarn.server.resourcemanager.rmapp.attempt.RMAppAttemptImpl: appattempt_1399292339232_0002_000001 State change from SCHEDULED to ALLOCATED_SAVING
2014-05-05 12:34:27,803 INFO org.apache.hadoop.yarn.server.resourcemanager.recovery.RMStateStore: Storing info for attempt: appattempt_1399292339232_0002_000001
2014-05-05 12:34:27,803 INFO org.apache.hadoop.yarn.server.resourcemanager.rmapp.attempt.RMAppAttemptImpl: appattempt_1399292339232_0002_000001 State change from ALLOCATED_SAVING to ALLOCATED
2014-05-05 12:34:27,804 INFO org.apache.hadoop.yarn.server.resourcemanager.amlauncher.AMLauncher: Launching masterappattempt_1399292339232_0002_000001
2014-05-05 12:34:27,805 INFO org.apache.hadoop.yarn.server.resourcemanager.amlauncher.AMLauncher: Setting up container Container: [ContainerId: container_1399292339232_0002_01_000001, NodeId: noded:39305, NodeHttpAddress: noded:8042, Resource: <memory:2048, vCores:1>, Priority: 0, Token: Token { kind: ContainerToken, service: 10.0.0.193:39305 }, ] for AM appattempt_1399292339232_0002_000001
2014-05-05 12:34:27,805 INFO org.apache.hadoop.yarn.server.resourcemanager.amlauncher.AMLauncher: Command to launch container container_1399292339232_0002_01_000001 : $JAVA_HOME/bin/java -Dlog4j.configuration=container-log4j.properties -Dyarn.app.container.log.dir=<LOG_DIR> -Dyarn.app.container.log.filesize=0 -Dhadoop.root.logger=INFO,CLA  -Xmx1024m org.apache.hadoop.mapreduce.v2.app.MRAppMaster 1><LOG_DIR>/stdout 2><LOG_DIR>/stderr 
2014-05-05 12:34:27,835 INFO org.apache.hadoop.yarn.server.resourcemanager.amlauncher.AMLauncher: Done launching container Container: [ContainerId: container_1399292339232_0002_01_000001, NodeId: noded:39305, NodeHttpAddress: noded:8042, Resource: <memory:2048, vCores:1>, Priority: 0, Token: Token { kind: ContainerToken, service: 10.0.0.193:39305 }, ] for AM appattempt_1399292339232_0002_000001
2014-05-05 12:34:27,835 INFO org.apache.hadoop.yarn.server.resourcemanager.rmapp.attempt.RMAppAttemptImpl: appattempt_1399292339232_0002_000001 State change from ALLOCATED to LAUNCHED
2014-05-05 12:34:28,802 INFO org.apache.hadoop.yarn.server.resourcemanager.rmcontainer.RMContainerImpl: container_1399292339232_0002_01_000001 Container Transitioned from ACQUIRED to RUNNING
2014-05-05 12:34:33,857 INFO SecurityLogger.org.apache.hadoop.ipc.Server: Auth successful for appattempt_1399292339232_0002_000001 (auth:SIMPLE)
2014-05-05 12:34:33,862 INFO org.apache.hadoop.yarn.server.resourcemanager.ApplicationMasterService: AM registration appattempt_1399292339232_0002_000001
2014-05-05 12:34:33,862 INFO org.apache.hadoop.yarn.server.resourcemanager.RMAuditLogger: USER=ubuntu	IP=10.0.0.193	OPERATION=Register App Master	TARGET=ApplicationMasterService	RESULT=SUCCESS	APPID=application_1399292339232_0002	APPATTEMPTID=appattempt_1399292339232_0002_000001
2014-05-05 12:34:33,862 INFO org.apache.hadoop.yarn.server.resourcemanager.rmapp.attempt.RMAppAttemptImpl: appattempt_1399292339232_0002_000001 State change from LAUNCHED to RUNNING
2014-05-05 12:34:33,862 INFO org.apache.hadoop.yarn.server.resourcemanager.rmapp.RMAppImpl: application_1399292339232_0002 State change from ACCEPTED to RUNNING
2014-05-05 12:34:34,947 INFO org.apache.hadoop.yarn.server.resourcemanager.rmcontainer.RMContainerImpl: container_1399292339232_0002_01_000002 Container Transitioned from NEW to ALLOCATED
2014-05-05 12:34:34,947 INFO org.apache.hadoop.yarn.server.resourcemanager.RMAuditLogger: USER=ubuntu	OPERATION=AM Allocated Container	TARGET=SchedulerApp	RESULT=SUCCESS	APPID=application_1399292339232_0002	CONTAINERID=container_1399292339232_0002_01_000002
2014-05-05 12:34:34,947 INFO org.apache.hadoop.yarn.server.resourcemanager.scheduler.common.fica.FiCaSchedulerNode: Assigned container container_1399292339232_0002_01_000002 of capacity <memory:1024, vCores:1> on host nodeg:56763, which currently has 1 containers, <memory:1024, vCores:1> used and <memory:7168, vCores:7> available
2014-05-05 12:34:34,947 INFO org.apache.hadoop.yarn.server.resourcemanager.scheduler.capacity.LeafQueue: assignedContainer application=application_1399292339232_0002 container=Container: [ContainerId: container_1399292339232_0002_01_000002, NodeId: nodeg:56763, NodeHttpAddress: nodeg:8042, Resource: <memory:1024, vCores:1>, Priority: 20, Token: Token { kind: ContainerToken, service: 10.0.0.196:56763 }, ] containerId=container_1399292339232_0002_01_000002 queue=default: capacity=1.0, absoluteCapacity=1.0, usedResources=<memory:2048, vCores:1>usedCapacity=0.03125, absoluteUsedCapacity=0.03125, numApps=1, numContainers=1 usedCapacity=0.03125 absoluteUsedCapacity=0.03125 used=<memory:2048, vCores:1> cluster=<memory:65536, vCores:64>
2014-05-05 12:34:34,948 INFO org.apache.hadoop.yarn.server.resourcemanager.scheduler.capacity.ParentQueue: Re-sorting assigned queue: root.default stats: default: capacity=1.0, absoluteCapacity=1.0, usedResources=<memory:3072, vCores:2>usedCapacity=0.046875, absoluteUsedCapacity=0.046875, numApps=1, numContainers=2
2014-05-05 12:34:34,948 INFO org.apache.hadoop.yarn.server.resourcemanager.scheduler.capacity.ParentQueue: assignedContainer queue=root usedCapacity=0.046875 absoluteUsedCapacity=0.046875 used=<memory:3072, vCores:2> cluster=<memory:65536, vCores:64>
2014-05-05 12:34:34,948 INFO org.apache.hadoop.yarn.server.resourcemanager.rmcontainer.RMContainerImpl: container_1399292339232_0002_01_000003 Container Transitioned from NEW to ALLOCATED
2014-05-05 12:34:34,948 INFO org.apache.hadoop.yarn.server.resourcemanager.RMAuditLogger: USER=ubuntu	OPERATION=AM Allocated Container	TARGET=SchedulerApp	RESULT=SUCCESS	APPID=application_1399292339232_0002	CONTAINERID=container_1399292339232_0002_01_000003
2014-05-05 12:34:34,948 INFO org.apache.hadoop.yarn.server.resourcemanager.scheduler.common.fica.FiCaSchedulerNode: Assigned container container_1399292339232_0002_01_000003 of capacity <memory:1024, vCores:1> on host nodeg:56763, which currently has 2 containers, <memory:2048, vCores:2> used and <memory:6144, vCores:6> available
2014-05-05 12:34:34,948 INFO org.apache.hadoop.yarn.server.resourcemanager.scheduler.capacity.LeafQueue: assignedContainer application=application_1399292339232_0002 container=Container: [ContainerId: container_1399292339232_0002_01_000003, NodeId: nodeg:56763, NodeHttpAddress: nodeg:8042, Resource: <memory:1024, vCores:1>, Priority: 20, Token: Token { kind: ContainerToken, service: 10.0.0.196:56763 }, ] containerId=container_1399292339232_0002_01_000003 queue=default: capacity=1.0, absoluteCapacity=1.0, usedResources=<memory:3072, vCores:2>usedCapacity=0.046875, absoluteUsedCapacity=0.046875, numApps=1, numContainers=2 usedCapacity=0.046875 absoluteUsedCapacity=0.046875 used=<memory:3072, vCores:2> cluster=<memory:65536, vCores:64>
2014-05-05 12:34:34,948 INFO org.apache.hadoop.yarn.server.resourcemanager.scheduler.capacity.ParentQueue: Re-sorting assigned queue: root.default stats: default: capacity=1.0, absoluteCapacity=1.0, usedResources=<memory:4096, vCores:3>usedCapacity=0.0625, absoluteUsedCapacity=0.0625, numApps=1, numContainers=3
2014-05-05 12:34:34,948 INFO org.apache.hadoop.yarn.server.resourcemanager.scheduler.capacity.ParentQueue: assignedContainer queue=root usedCapacity=0.0625 absoluteUsedCapacity=0.0625 used=<memory:4096, vCores:3> cluster=<memory:65536, vCores:64>
2014-05-05 12:34:34,949 INFO org.apache.hadoop.yarn.server.resourcemanager.rmcontainer.RMContainerImpl: container_1399292339232_0002_01_000004 Container Transitioned from NEW to ALLOCATED
2014-05-05 12:34:34,949 INFO org.apache.hadoop.yarn.server.resourcemanager.RMAuditLogger: USER=ubuntu	OPERATION=AM Allocated Container	TARGET=SchedulerApp	RESULT=SUCCESS	APPID=application_1399292339232_0002	CONTAINERID=container_1399292339232_0002_01_000004
2014-05-05 12:34:34,949 INFO org.apache.hadoop.yarn.server.resourcemanager.scheduler.common.fica.FiCaSchedulerNode: Assigned container container_1399292339232_0002_01_000004 of capacity <memory:1024, vCores:1> on host nodeg:56763, which currently has 3 containers, <memory:3072, vCores:3> used and <memory:5120, vCores:5> available
2014-05-05 12:34:34,949 INFO org.apache.hadoop.yarn.server.resourcemanager.scheduler.capacity.LeafQueue: assignedContainer application=application_1399292339232_0002 container=Container: [ContainerId: container_1399292339232_0002_01_000004, NodeId: nodeg:56763, NodeHttpAddress: nodeg:8042, Resource: <memory:1024, vCores:1>, Priority: 20, Token: Token { kind: ContainerToken, service: 10.0.0.196:56763 }, ] containerId=container_1399292339232_0002_01_000004 queue=default: capacity=1.0, absoluteCapacity=1.0, usedResources=<memory:4096, vCores:3>usedCapacity=0.0625, absoluteUsedCapacity=0.0625, numApps=1, numContainers=3 usedCapacity=0.0625 absoluteUsedCapacity=0.0625 used=<memory:4096, vCores:3> cluster=<memory:65536, vCores:64>
2014-05-05 12:34:34,949 INFO org.apache.hadoop.yarn.server.resourcemanager.scheduler.capacity.ParentQueue: Re-sorting assigned queue: root.default stats: default: capacity=1.0, absoluteCapacity=1.0, usedResources=<memory:5120, vCores:4>usedCapacity=0.078125, absoluteUsedCapacity=0.078125, numApps=1, numContainers=4
2014-05-05 12:34:34,949 INFO org.apache.hadoop.yarn.server.resourcemanager.scheduler.capacity.ParentQueue: assignedContainer queue=root usedCapacity=0.078125 absoluteUsedCapacity=0.078125 used=<memory:5120, vCores:4> cluster=<memory:65536, vCores:64>
2014-05-05 12:34:34,949 INFO org.apache.hadoop.yarn.server.resourcemanager.rmcontainer.RMContainerImpl: container_1399292339232_0002_01_000005 Container Transitioned from NEW to ALLOCATED
2014-05-05 12:34:34,949 INFO org.apache.hadoop.yarn.server.resourcemanager.RMAuditLogger: USER=ubuntu	OPERATION=AM Allocated Container	TARGET=SchedulerApp	RESULT=SUCCESS	APPID=application_1399292339232_0002	CONTAINERID=container_1399292339232_0002_01_000005
2014-05-05 12:34:34,949 INFO org.apache.hadoop.yarn.server.resourcemanager.scheduler.common.fica.FiCaSchedulerNode: Assigned container container_1399292339232_0002_01_000005 of capacity <memory:1024, vCores:1> on host nodeg:56763, which currently has 4 containers, <memory:4096, vCores:4> used and <memory:4096, vCores:4> available
2014-05-05 12:34:34,950 INFO org.apache.hadoop.yarn.server.resourcemanager.scheduler.capacity.LeafQueue: assignedContainer application=application_1399292339232_0002 container=Container: [ContainerId: container_1399292339232_0002_01_000005, NodeId: nodeg:56763, NodeHttpAddress: nodeg:8042, Resource: <memory:1024, vCores:1>, Priority: 20, Token: Token { kind: ContainerToken, service: 10.0.0.196:56763 }, ] containerId=container_1399292339232_0002_01_000005 queue=default: capacity=1.0, absoluteCapacity=1.0, usedResources=<memory:5120, vCores:4>usedCapacity=0.078125, absoluteUsedCapacity=0.078125, numApps=1, numContainers=4 usedCapacity=0.078125 absoluteUsedCapacity=0.078125 used=<memory:5120, vCores:4> cluster=<memory:65536, vCores:64>
2014-05-05 12:34:34,950 INFO org.apache.hadoop.yarn.server.resourcemanager.scheduler.capacity.ParentQueue: Re-sorting assigned queue: root.default stats: default: capacity=1.0, absoluteCapacity=1.0, usedResources=<memory:6144, vCores:5>usedCapacity=0.09375, absoluteUsedCapacity=0.09375, numApps=1, numContainers=5
2014-05-05 12:34:34,950 INFO org.apache.hadoop.yarn.server.resourcemanager.scheduler.capacity.ParentQueue: assignedContainer queue=root usedCapacity=0.09375 absoluteUsedCapacity=0.09375 used=<memory:6144, vCores:5> cluster=<memory:65536, vCores:64>
2014-05-05 12:34:35,910 INFO org.apache.hadoop.yarn.server.resourcemanager.rmcontainer.RMContainerImpl: container_1399292339232_0002_01_000002 Container Transitioned from ALLOCATED to ACQUIRED
2014-05-05 12:34:35,910 INFO org.apache.hadoop.yarn.server.resourcemanager.rmcontainer.RMContainerImpl: container_1399292339232_0002_01_000003 Container Transitioned from ALLOCATED to ACQUIRED
2014-05-05 12:34:35,910 INFO org.apache.hadoop.yarn.server.resourcemanager.rmcontainer.RMContainerImpl: container_1399292339232_0002_01_000004 Container Transitioned from ALLOCATED to ACQUIRED
2014-05-05 12:34:35,910 INFO org.apache.hadoop.yarn.server.resourcemanager.rmcontainer.RMContainerImpl: container_1399292339232_0002_01_000005 Container Transitioned from ALLOCATED to ACQUIRED
2014-05-05 12:34:36,927 INFO org.apache.hadoop.yarn.server.resourcemanager.scheduler.AppSchedulingInfo: checking for deactivate... 
2014-05-05 12:34:36,951 INFO org.apache.hadoop.yarn.server.resourcemanager.rmcontainer.RMContainerImpl: container_1399292339232_0002_01_000002 Container Transitioned from ACQUIRED to RUNNING
2014-05-05 12:34:36,952 INFO org.apache.hadoop.yarn.server.resourcemanager.rmcontainer.RMContainerImpl: container_1399292339232_0002_01_000003 Container Transitioned from ACQUIRED to RUNNING
2014-05-05 12:34:36,952 INFO org.apache.hadoop.yarn.server.resourcemanager.rmcontainer.RMContainerImpl: container_1399292339232_0002_01_000004 Container Transitioned from ACQUIRED to RUNNING
2014-05-05 12:34:36,952 INFO org.apache.hadoop.yarn.server.resourcemanager.rmcontainer.RMContainerImpl: container_1399292339232_0002_01_000005 Container Transitioned from ACQUIRED to RUNNING
2014-05-05 12:34:57,993 INFO org.apache.hadoop.yarn.server.resourcemanager.rmcontainer.RMContainerImpl: container_1399292339232_0002_01_000005 Container Transitioned from RUNNING to COMPLETED
2014-05-05 12:34:57,994 INFO org.apache.hadoop.yarn.server.resourcemanager.scheduler.common.fica.FiCaSchedulerApp: Completed container: container_1399292339232_0002_01_000005 in state: COMPLETED event:FINISHED
2014-05-05 12:34:57,994 INFO org.apache.hadoop.yarn.server.resourcemanager.RMAuditLogger: USER=ubuntu	OPERATION=AM Released Container	TARGET=SchedulerApp	RESULT=SUCCESS	APPID=application_1399292339232_0002	CONTAINERID=container_1399292339232_0002_01_000005
2014-05-05 12:34:57,994 INFO org.apache.hadoop.yarn.server.resourcemanager.scheduler.common.fica.FiCaSchedulerNode: Released container container_1399292339232_0002_01_000005 of capacity <memory:1024, vCores:1> on host nodeg:56763, which currently has 3 containers, <memory:3072, vCores:3> used and <memory:5120, vCores:5> available, release resources=true
2014-05-05 12:34:57,994 INFO org.apache.hadoop.yarn.server.resourcemanager.scheduler.capacity.LeafQueue: default used=<memory:5120, vCores:4> numContainers=4 user=ubuntu user-resources=<memory:5120, vCores:4>
2014-05-05 12:34:57,994 INFO org.apache.hadoop.yarn.server.resourcemanager.scheduler.capacity.LeafQueue: completedContainer container=Container: [ContainerId: container_1399292339232_0002_01_000005, NodeId: nodeg:56763, NodeHttpAddress: nodeg:8042, Resource: <memory:1024, vCores:1>, Priority: 20, Token: Token { kind: ContainerToken, service: 10.0.0.196:56763 }, ] resource=<memory:1024, vCores:1> queue=default: capacity=1.0, absoluteCapacity=1.0, usedResources=<memory:5120, vCores:4>usedCapacity=0.078125, absoluteUsedCapacity=0.078125, numApps=1, numContainers=4 usedCapacity=0.078125 absoluteUsedCapacity=0.078125 used=<memory:5120, vCores:4> cluster=<memory:65536, vCores:64>
2014-05-05 12:34:57,994 INFO org.apache.hadoop.yarn.server.resourcemanager.scheduler.capacity.ParentQueue: completedContainer queue=root usedCapacity=0.078125 absoluteUsedCapacity=0.078125 used=<memory:5120, vCores:4> cluster=<memory:65536, vCores:64>
2014-05-05 12:34:57,994 INFO org.apache.hadoop.yarn.server.resourcemanager.scheduler.capacity.ParentQueue: Re-sorting completed queue: root.default stats: default: capacity=1.0, absoluteCapacity=1.0, usedResources=<memory:5120, vCores:4>usedCapacity=0.078125, absoluteUsedCapacity=0.078125, numApps=1, numContainers=4
2014-05-05 12:34:57,994 INFO org.apache.hadoop.yarn.server.resourcemanager.scheduler.capacity.CapacityScheduler: Application appattempt_1399292339232_0002_000001 released container container_1399292339232_0002_01_000005 on node: host: nodeg:56763 #containers=3 available=5120 used=3072 with event: FINISHED
2014-05-05 12:34:57,995 INFO org.apache.hadoop.yarn.server.resourcemanager.rmcontainer.RMContainerImpl: container_1399292339232_0002_01_000006 Container Transitioned from NEW to ALLOCATED
2014-05-05 12:34:57,995 INFO org.apache.hadoop.yarn.server.resourcemanager.RMAuditLogger: USER=ubuntu	OPERATION=AM Allocated Container	TARGET=SchedulerApp	RESULT=SUCCESS	APPID=application_1399292339232_0002	CONTAINERID=container_1399292339232_0002_01_000006
2014-05-05 12:34:57,995 INFO org.apache.hadoop.yarn.server.resourcemanager.scheduler.common.fica.FiCaSchedulerNode: Assigned container container_1399292339232_0002_01_000006 of capacity <memory:1024, vCores:1> on host nodeg:56763, which currently has 4 containers, <memory:4096, vCores:4> used and <memory:4096, vCores:4> available
2014-05-05 12:34:57,995 INFO org.apache.hadoop.yarn.server.resourcemanager.scheduler.capacity.LeafQueue: assignedContainer application=application_1399292339232_0002 container=Container: [ContainerId: container_1399292339232_0002_01_000006, NodeId: nodeg:56763, NodeHttpAddress: nodeg:8042, Resource: <memory:1024, vCores:1>, Priority: 20, Token: Token { kind: ContainerToken, service: 10.0.0.196:56763 }, ] containerId=container_1399292339232_0002_01_000006 queue=default: capacity=1.0, absoluteCapacity=1.0, usedResources=<memory:5120, vCores:4>usedCapacity=0.078125, absoluteUsedCapacity=0.078125, numApps=1, numContainers=4 usedCapacity=0.078125 absoluteUsedCapacity=0.078125 used=<memory:5120, vCores:4> cluster=<memory:65536, vCores:64>
2014-05-05 12:34:57,995 INFO org.apache.hadoop.yarn.server.resourcemanager.scheduler.capacity.ParentQueue: Re-sorting assigned queue: root.default stats: default: capacity=1.0, absoluteCapacity=1.0, usedResources=<memory:6144, vCores:5>usedCapacity=0.09375, absoluteUsedCapacity=0.09375, numApps=1, numContainers=5
2014-05-05 12:34:57,995 INFO org.apache.hadoop.yarn.server.resourcemanager.scheduler.capacity.ParentQueue: assignedContainer queue=root usedCapacity=0.09375 absoluteUsedCapacity=0.09375 used=<memory:6144, vCores:5> cluster=<memory:65536, vCores:64>
2014-05-05 12:34:58,978 INFO org.apache.hadoop.yarn.server.resourcemanager.rmcontainer.RMContainerImpl: container_1399292339232_0002_01_000006 Container Transitioned from ALLOCATED to ACQUIRED
2014-05-05 12:34:59,004 INFO org.apache.hadoop.yarn.server.resourcemanager.rmcontainer.RMContainerImpl: container_1399292339232_0002_01_000007 Container Transitioned from NEW to ALLOCATED
2014-05-05 12:34:59,004 INFO org.apache.hadoop.yarn.server.resourcemanager.RMAuditLogger: USER=ubuntu	OPERATION=AM Allocated Container	TARGET=SchedulerApp	RESULT=SUCCESS	APPID=application_1399292339232_0002	CONTAINERID=container_1399292339232_0002_01_000007
2014-05-05 12:34:59,004 INFO org.apache.hadoop.yarn.server.resourcemanager.scheduler.common.fica.FiCaSchedulerNode: Assigned container container_1399292339232_0002_01_000007 of capacity <memory:1024, vCores:1> on host nodeg:56763, which currently has 5 containers, <memory:5120, vCores:5> used and <memory:3072, vCores:3> available
2014-05-05 12:34:59,004 INFO org.apache.hadoop.yarn.server.resourcemanager.scheduler.capacity.LeafQueue: assignedContainer application=application_1399292339232_0002 container=Container: [ContainerId: container_1399292339232_0002_01_000007, NodeId: nodeg:56763, NodeHttpAddress: nodeg:8042, Resource: <memory:1024, vCores:1>, Priority: 10, Token: Token { kind: ContainerToken, service: 10.0.0.196:56763 }, ] containerId=container_1399292339232_0002_01_000007 queue=default: capacity=1.0, absoluteCapacity=1.0, usedResources=<memory:6144, vCores:5>usedCapacity=0.09375, absoluteUsedCapacity=0.09375, numApps=1, numContainers=5 usedCapacity=0.09375 absoluteUsedCapacity=0.09375 used=<memory:6144, vCores:5> cluster=<memory:65536, vCores:64>
2014-05-05 12:34:59,005 INFO org.apache.hadoop.yarn.server.resourcemanager.scheduler.capacity.ParentQueue: Re-sorting assigned queue: root.default stats: default: capacity=1.0, absoluteCapacity=1.0, usedResources=<memory:7168, vCores:6>usedCapacity=0.109375, absoluteUsedCapacity=0.109375, numApps=1, numContainers=6
2014-05-05 12:34:59,005 INFO org.apache.hadoop.yarn.server.resourcemanager.scheduler.capacity.ParentQueue: assignedContainer queue=root usedCapacity=0.109375 absoluteUsedCapacity=0.109375 used=<memory:7168, vCores:6> cluster=<memory:65536, vCores:64>
2014-05-05 12:34:59,166 INFO org.apache.hadoop.yarn.server.resourcemanager.rmcontainer.RMContainerImpl: container_1399292339232_0002_01_000008 Container Transitioned from NEW to ALLOCATED
2014-05-05 12:34:59,166 INFO org.apache.hadoop.yarn.server.resourcemanager.RMAuditLogger: USER=ubuntu	OPERATION=AM Allocated Container	TARGET=SchedulerApp	RESULT=SUCCESS	APPID=application_1399292339232_0002	CONTAINERID=container_1399292339232_0002_01_000008
2014-05-05 12:34:59,167 INFO org.apache.hadoop.yarn.server.resourcemanager.scheduler.common.fica.FiCaSchedulerNode: Assigned container container_1399292339232_0002_01_000008 of capacity <memory:1024, vCores:1> on host nodea:51924, which currently has 1 containers, <memory:1024, vCores:1> used and <memory:7168, vCores:7> available
2014-05-05 12:34:59,167 INFO org.apache.hadoop.yarn.server.resourcemanager.scheduler.capacity.LeafQueue: assignedContainer application=application_1399292339232_0002 container=Container: [ContainerId: container_1399292339232_0002_01_000008, NodeId: nodea:51924, NodeHttpAddress: nodea:8042, Resource: <memory:1024, vCores:1>, Priority: 10, Token: Token { kind: ContainerToken, service: 10.0.0.195:51924 }, ] containerId=container_1399292339232_0002_01_000008 queue=default: capacity=1.0, absoluteCapacity=1.0, usedResources=<memory:7168, vCores:6>usedCapacity=0.109375, absoluteUsedCapacity=0.109375, numApps=1, numContainers=6 usedCapacity=0.109375 absoluteUsedCapacity=0.109375 used=<memory:7168, vCores:6> cluster=<memory:65536, vCores:64>
2014-05-05 12:34:59,167 INFO org.apache.hadoop.yarn.server.resourcemanager.scheduler.capacity.ParentQueue: Re-sorting assigned queue: root.default stats: default: capacity=1.0, absoluteCapacity=1.0, usedResources=<memory:8192, vCores:7>usedCapacity=0.125, absoluteUsedCapacity=0.125, numApps=1, numContainers=7
2014-05-05 12:34:59,167 INFO org.apache.hadoop.yarn.server.resourcemanager.scheduler.capacity.ParentQueue: assignedContainer queue=root usedCapacity=0.125 absoluteUsedCapacity=0.125 used=<memory:8192, vCores:7> cluster=<memory:65536, vCores:64>
2014-05-05 12:34:59,220 INFO org.apache.hadoop.yarn.server.resourcemanager.rmcontainer.RMContainerImpl: container_1399292339232_0002_01_000009 Container Transitioned from NEW to ALLOCATED
2014-05-05 12:34:59,220 INFO org.apache.hadoop.yarn.server.resourcemanager.RMAuditLogger: USER=ubuntu	OPERATION=AM Allocated Container	TARGET=SchedulerApp	RESULT=SUCCESS	APPID=application_1399292339232_0002	CONTAINERID=container_1399292339232_0002_01_000009
2014-05-05 12:34:59,220 INFO org.apache.hadoop.yarn.server.resourcemanager.scheduler.common.fica.FiCaSchedulerNode: Assigned container container_1399292339232_0002_01_000009 of capacity <memory:1024, vCores:1> on host nodeb:48885, which currently has 1 containers, <memory:1024, vCores:1> used and <memory:7168, vCores:7> available
2014-05-05 12:34:59,221 INFO org.apache.hadoop.yarn.server.resourcemanager.scheduler.capacity.LeafQueue: assignedContainer application=application_1399292339232_0002 container=Container: [ContainerId: container_1399292339232_0002_01_000009, NodeId: nodeb:48885, NodeHttpAddress: nodeb:8042, Resource: <memory:1024, vCores:1>, Priority: 10, Token: Token { kind: ContainerToken, service: 10.0.0.194:48885 }, ] containerId=container_1399292339232_0002_01_000009 queue=default: capacity=1.0, absoluteCapacity=1.0, usedResources=<memory:8192, vCores:7>usedCapacity=0.125, absoluteUsedCapacity=0.125, numApps=1, numContainers=7 usedCapacity=0.125 absoluteUsedCapacity=0.125 used=<memory:8192, vCores:7> cluster=<memory:65536, vCores:64>
2014-05-05 12:34:59,221 INFO org.apache.hadoop.yarn.server.resourcemanager.scheduler.capacity.ParentQueue: Re-sorting assigned queue: root.default stats: default: capacity=1.0, absoluteCapacity=1.0, usedResources=<memory:9216, vCores:8>usedCapacity=0.140625, absoluteUsedCapacity=0.140625, numApps=1, numContainers=8
2014-05-05 12:34:59,221 INFO org.apache.hadoop.yarn.server.resourcemanager.scheduler.capacity.ParentQueue: assignedContainer queue=root usedCapacity=0.140625 absoluteUsedCapacity=0.140625 used=<memory:9216, vCores:8> cluster=<memory:65536, vCores:64>
2014-05-05 12:34:59,309 INFO org.apache.hadoop.yarn.server.resourcemanager.rmcontainer.RMContainerImpl: container_1399292339232_0002_01_000010 Container Transitioned from NEW to ALLOCATED
2014-05-05 12:34:59,309 INFO org.apache.hadoop.yarn.server.resourcemanager.RMAuditLogger: USER=ubuntu	OPERATION=AM Allocated Container	TARGET=SchedulerApp	RESULT=SUCCESS	APPID=application_1399292339232_0002	CONTAINERID=container_1399292339232_0002_01_000010
2014-05-05 12:34:59,310 INFO org.apache.hadoop.yarn.server.resourcemanager.scheduler.common.fica.FiCaSchedulerNode: Assigned container container_1399292339232_0002_01_000010 of capacity <memory:1024, vCores:1> on host nodee:49598, which currently has 1 containers, <memory:1024, vCores:1> used and <memory:7168, vCores:7> available
2014-05-05 12:34:59,310 INFO org.apache.hadoop.yarn.server.resourcemanager.scheduler.capacity.LeafQueue: assignedContainer application=application_1399292339232_0002 container=Container: [ContainerId: container_1399292339232_0002_01_000010, NodeId: nodee:49598, NodeHttpAddress: nodee:8042, Resource: <memory:1024, vCores:1>, Priority: 10, Token: Token { kind: ContainerToken, service: 10.0.0.198:49598 }, ] containerId=container_1399292339232_0002_01_000010 queue=default: capacity=1.0, absoluteCapacity=1.0, usedResources=<memory:9216, vCores:8>usedCapacity=0.140625, absoluteUsedCapacity=0.140625, numApps=1, numContainers=8 usedCapacity=0.140625 absoluteUsedCapacity=0.140625 used=<memory:9216, vCores:8> cluster=<memory:65536, vCores:64>
2014-05-05 12:34:59,310 INFO org.apache.hadoop.yarn.server.resourcemanager.scheduler.capacity.ParentQueue: Re-sorting assigned queue: root.default stats: default: capacity=1.0, absoluteCapacity=1.0, usedResources=<memory:10240, vCores:9>usedCapacity=0.15625, absoluteUsedCapacity=0.15625, numApps=1, numContainers=9
2014-05-05 12:34:59,310 INFO org.apache.hadoop.yarn.server.resourcemanager.scheduler.capacity.ParentQueue: assignedContainer queue=root usedCapacity=0.15625 absoluteUsedCapacity=0.15625 used=<memory:10240, vCores:9> cluster=<memory:65536, vCores:64>
2014-05-05 12:34:59,546 INFO org.apache.hadoop.yarn.server.resourcemanager.rmcontainer.RMContainerImpl: container_1399292339232_0002_01_000011 Container Transitioned from NEW to ALLOCATED
2014-05-05 12:34:59,546 INFO org.apache.hadoop.yarn.server.resourcemanager.RMAuditLogger: USER=ubuntu	OPERATION=AM Allocated Container	TARGET=SchedulerApp	RESULT=SUCCESS	APPID=application_1399292339232_0002	CONTAINERID=container_1399292339232_0002_01_000011
2014-05-05 12:34:59,546 INFO org.apache.hadoop.yarn.server.resourcemanager.scheduler.common.fica.FiCaSchedulerNode: Assigned container container_1399292339232_0002_01_000011 of capacity <memory:1024, vCores:1> on host nodec:35478, which currently has 1 containers, <memory:1024, vCores:1> used and <memory:7168, vCores:7> available
2014-05-05 12:34:59,546 INFO org.apache.hadoop.yarn.server.resourcemanager.scheduler.capacity.LeafQueue: assignedContainer application=application_1399292339232_0002 container=Container: [ContainerId: container_1399292339232_0002_01_000011, NodeId: nodec:35478, NodeHttpAddress: nodec:8042, Resource: <memory:1024, vCores:1>, Priority: 10, Token: Token { kind: ContainerToken, service: 10.0.0.200:35478 }, ] containerId=container_1399292339232_0002_01_000011 queue=default: capacity=1.0, absoluteCapacity=1.0, usedResources=<memory:10240, vCores:9>usedCapacity=0.15625, absoluteUsedCapacity=0.15625, numApps=1, numContainers=9 usedCapacity=0.15625 absoluteUsedCapacity=0.15625 used=<memory:10240, vCores:9> cluster=<memory:65536, vCores:64>
2014-05-05 12:34:59,546 INFO org.apache.hadoop.yarn.server.resourcemanager.scheduler.capacity.ParentQueue: Re-sorting assigned queue: root.default stats: default: capacity=1.0, absoluteCapacity=1.0, usedResources=<memory:11264, vCores:10>usedCapacity=0.171875, absoluteUsedCapacity=0.171875, numApps=1, numContainers=10
2014-05-05 12:34:59,546 INFO org.apache.hadoop.yarn.server.resourcemanager.scheduler.capacity.ParentQueue: assignedContainer queue=root usedCapacity=0.171875 absoluteUsedCapacity=0.171875 used=<memory:11264, vCores:10> cluster=<memory:65536, vCores:64>
2014-05-05 12:34:59,547 INFO org.apache.hadoop.yarn.server.resourcemanager.rmcontainer.RMContainerImpl: container_1399292339232_0002_01_000012 Container Transitioned from NEW to ALLOCATED
2014-05-05 12:34:59,547 INFO org.apache.hadoop.yarn.server.resourcemanager.RMAuditLogger: USER=ubuntu	OPERATION=AM Allocated Container	TARGET=SchedulerApp	RESULT=SUCCESS	APPID=application_1399292339232_0002	CONTAINERID=container_1399292339232_0002_01_000012
2014-05-05 12:34:59,547 INFO org.apache.hadoop.yarn.server.resourcemanager.scheduler.common.fica.FiCaSchedulerNode: Assigned container container_1399292339232_0002_01_000012 of capacity <memory:1024, vCores:1> on host nodef:54669, which currently has 1 containers, <memory:1024, vCores:1> used and <memory:7168, vCores:7> available
2014-05-05 12:34:59,547 INFO org.apache.hadoop.yarn.server.resourcemanager.scheduler.capacity.LeafQueue: assignedContainer application=application_1399292339232_0002 container=Container: [ContainerId: container_1399292339232_0002_01_000012, NodeId: nodef:54669, NodeHttpAddress: nodef:8042, Resource: <memory:1024, vCores:1>, Priority: 10, Token: Token { kind: ContainerToken, service: 10.0.0.199:54669 }, ] containerId=container_1399292339232_0002_01_000012 queue=default: capacity=1.0, absoluteCapacity=1.0, usedResources=<memory:11264, vCores:10>usedCapacity=0.171875, absoluteUsedCapacity=0.171875, numApps=1, numContainers=10 usedCapacity=0.171875 absoluteUsedCapacity=0.171875 used=<memory:11264, vCores:10> cluster=<memory:65536, vCores:64>
2014-05-05 12:34:59,547 INFO org.apache.hadoop.yarn.server.resourcemanager.scheduler.capacity.ParentQueue: Re-sorting assigned queue: root.default stats: default: capacity=1.0, absoluteCapacity=1.0, usedResources=<memory:12288, vCores:11>usedCapacity=0.1875, absoluteUsedCapacity=0.1875, numApps=1, numContainers=11
2014-05-05 12:34:59,547 INFO org.apache.hadoop.yarn.server.resourcemanager.scheduler.capacity.ParentQueue: assignedContainer queue=root usedCapacity=0.1875 absoluteUsedCapacity=0.1875 used=<memory:12288, vCores:11> cluster=<memory:65536, vCores:64>
2014-05-05 12:34:59,556 INFO org.apache.hadoop.yarn.server.resourcemanager.rmcontainer.RMContainerImpl: container_1399292339232_0002_01_000013 Container Transitioned from NEW to ALLOCATED
2014-05-05 12:34:59,556 INFO org.apache.hadoop.yarn.server.resourcemanager.RMAuditLogger: USER=ubuntu	OPERATION=AM Allocated Container	TARGET=SchedulerApp	RESULT=SUCCESS	APPID=application_1399292339232_0002	CONTAINERID=container_1399292339232_0002_01_000013
2014-05-05 12:34:59,556 INFO org.apache.hadoop.yarn.server.resourcemanager.scheduler.common.fica.FiCaSchedulerNode: Assigned container container_1399292339232_0002_01_000013 of capacity <memory:1024, vCores:1> on host nodeh:46599, which currently has 1 containers, <memory:1024, vCores:1> used and <memory:7168, vCores:7> available
2014-05-05 12:34:59,556 INFO org.apache.hadoop.yarn.server.resourcemanager.scheduler.capacity.LeafQueue: assignedContainer application=application_1399292339232_0002 container=Container: [ContainerId: container_1399292339232_0002_01_000013, NodeId: nodeh:46599, NodeHttpAddress: nodeh:8042, Resource: <memory:1024, vCores:1>, Priority: 10, Token: Token { kind: ContainerToken, service: 10.0.0.197:46599 }, ] containerId=container_1399292339232_0002_01_000013 queue=default: capacity=1.0, absoluteCapacity=1.0, usedResources=<memory:12288, vCores:11>usedCapacity=0.1875, absoluteUsedCapacity=0.1875, numApps=1, numContainers=11 usedCapacity=0.1875 absoluteUsedCapacity=0.1875 used=<memory:12288, vCores:11> cluster=<memory:65536, vCores:64>
2014-05-05 12:34:59,556 INFO org.apache.hadoop.yarn.server.resourcemanager.scheduler.capacity.ParentQueue: Re-sorting assigned queue: root.default stats: default: capacity=1.0, absoluteCapacity=1.0, usedResources=<memory:13312, vCores:12>usedCapacity=0.203125, absoluteUsedCapacity=0.203125, numApps=1, numContainers=12
2014-05-05 12:34:59,556 INFO org.apache.hadoop.yarn.server.resourcemanager.scheduler.capacity.ParentQueue: assignedContainer queue=root usedCapacity=0.203125 absoluteUsedCapacity=0.203125 used=<memory:13312, vCores:12> cluster=<memory:65536, vCores:64>
2014-05-05 12:34:59,864 INFO org.apache.hadoop.yarn.server.resourcemanager.rmcontainer.RMContainerImpl: container_1399292339232_0002_01_000014 Container Transitioned from NEW to ALLOCATED
2014-05-05 12:34:59,864 INFO org.apache.hadoop.yarn.server.resourcemanager.RMAuditLogger: USER=ubuntu	OPERATION=AM Allocated Container	TARGET=SchedulerApp	RESULT=SUCCESS	APPID=application_1399292339232_0002	CONTAINERID=container_1399292339232_0002_01_000014
2014-05-05 12:34:59,864 INFO org.apache.hadoop.yarn.server.resourcemanager.scheduler.common.fica.FiCaSchedulerNode: Assigned container container_1399292339232_0002_01_000014 of capacity <memory:1024, vCores:1> on host noded:39305, which currently has 2 containers, <memory:3072, vCores:2> used and <memory:5120, vCores:6> available
2014-05-05 12:34:59,865 INFO org.apache.hadoop.yarn.server.resourcemanager.scheduler.capacity.LeafQueue: assignedContainer application=application_1399292339232_0002 container=Container: [ContainerId: container_1399292339232_0002_01_000014, NodeId: noded:39305, NodeHttpAddress: noded:8042, Resource: <memory:1024, vCores:1>, Priority: 10, Token: Token { kind: ContainerToken, service: 10.0.0.193:39305 }, ] containerId=container_1399292339232_0002_01_000014 queue=default: capacity=1.0, absoluteCapacity=1.0, usedResources=<memory:13312, vCores:12>usedCapacity=0.203125, absoluteUsedCapacity=0.203125, numApps=1, numContainers=12 usedCapacity=0.203125 absoluteUsedCapacity=0.203125 used=<memory:13312, vCores:12> cluster=<memory:65536, vCores:64>
2014-05-05 12:34:59,865 INFO org.apache.hadoop.yarn.server.resourcemanager.scheduler.capacity.ParentQueue: Re-sorting assigned queue: root.default stats: default: capacity=1.0, absoluteCapacity=1.0, usedResources=<memory:14336, vCores:13>usedCapacity=0.21875, absoluteUsedCapacity=0.21875, numApps=1, numContainers=13
2014-05-05 12:34:59,865 INFO org.apache.hadoop.yarn.server.resourcemanager.scheduler.capacity.ParentQueue: assignedContainer queue=root usedCapacity=0.21875 absoluteUsedCapacity=0.21875 used=<memory:14336, vCores:13> cluster=<memory:65536, vCores:64>
2014-05-05 12:34:59,986 INFO org.apache.hadoop.yarn.server.resourcemanager.scheduler.AppSchedulingInfo: checking for deactivate... 
2014-05-05 12:34:59,987 INFO org.apache.hadoop.yarn.server.resourcemanager.rmcontainer.RMContainerImpl: container_1399292339232_0002_01_000007 Container Transitioned from ALLOCATED to ACQUIRED
2014-05-05 12:34:59,987 INFO org.apache.hadoop.yarn.server.resourcemanager.rmcontainer.RMContainerImpl: container_1399292339232_0002_01_000008 Container Transitioned from ALLOCATED to ACQUIRED
2014-05-05 12:34:59,987 INFO org.apache.hadoop.yarn.server.resourcemanager.rmcontainer.RMContainerImpl: container_1399292339232_0002_01_000009 Container Transitioned from ALLOCATED to ACQUIRED
2014-05-05 12:34:59,988 INFO org.apache.hadoop.yarn.server.resourcemanager.rmcontainer.RMContainerImpl: container_1399292339232_0002_01_000010 Container Transitioned from ALLOCATED to ACQUIRED
2014-05-05 12:34:59,988 INFO org.apache.hadoop.yarn.server.resourcemanager.rmcontainer.RMContainerImpl: container_1399292339232_0002_01_000011 Container Transitioned from ALLOCATED to ACQUIRED
2014-05-05 12:34:59,988 INFO org.apache.hadoop.yarn.server.resourcemanager.rmcontainer.RMContainerImpl: container_1399292339232_0002_01_000012 Container Transitioned from ALLOCATED to ACQUIRED
2014-05-05 12:34:59,988 INFO org.apache.hadoop.yarn.server.resourcemanager.rmcontainer.RMContainerImpl: container_1399292339232_0002_01_000013 Container Transitioned from ALLOCATED to ACQUIRED
2014-05-05 12:34:59,989 INFO org.apache.hadoop.yarn.server.resourcemanager.rmcontainer.RMContainerImpl: container_1399292339232_0002_01_000014 Container Transitioned from ALLOCATED to ACQUIRED
2014-05-05 12:35:00,007 INFO org.apache.hadoop.yarn.server.resourcemanager.rmcontainer.RMContainerImpl: container_1399292339232_0002_01_000006 Container Transitioned from ACQUIRED to RUNNING
2014-05-05 12:35:00,173 INFO org.apache.hadoop.yarn.server.resourcemanager.rmcontainer.RMContainerImpl: container_1399292339232_0002_01_000008 Container Transitioned from ACQUIRED to RUNNING
2014-05-05 12:35:00,222 INFO org.apache.hadoop.yarn.server.resourcemanager.rmcontainer.RMContainerImpl: container_1399292339232_0002_01_000009 Container Transitioned from ACQUIRED to RUNNING
2014-05-05 12:35:00,315 INFO org.apache.hadoop.yarn.server.resourcemanager.rmcontainer.RMContainerImpl: container_1399292339232_0002_01_000010 Container Transitioned from ACQUIRED to RUNNING
2014-05-05 12:35:00,552 INFO org.apache.hadoop.yarn.server.resourcemanager.rmcontainer.RMContainerImpl: container_1399292339232_0002_01_000012 Container Transitioned from ACQUIRED to RUNNING
2014-05-05 12:35:00,703 INFO org.apache.hadoop.yarn.server.resourcemanager.rmcontainer.RMContainerImpl: container_1399292339232_0002_01_000013 Container Transitioned from ACQUIRED to RUNNING
2014-05-05 12:35:00,703 INFO org.apache.hadoop.yarn.server.resourcemanager.rmcontainer.RMContainerImpl: container_1399292339232_0002_01_000011 Container Transitioned from ACQUIRED to RUNNING
2014-05-05 12:35:00,867 INFO org.apache.hadoop.yarn.server.resourcemanager.rmcontainer.RMContainerImpl: container_1399292339232_0002_01_000014 Container Transitioned from ACQUIRED to RUNNING
2014-05-05 12:35:00,998 INFO org.apache.hadoop.yarn.server.resourcemanager.scheduler.AppSchedulingInfo: checking for deactivate... 
2014-05-05 12:35:01,012 INFO org.apache.hadoop.yarn.server.resourcemanager.rmcontainer.RMContainerImpl: container_1399292339232_0002_01_000007 Container Transitioned from ACQUIRED to RUNNING
2014-05-05 12:35:11,821 INFO org.apache.hadoop.yarn.server.resourcemanager.rmcontainer.RMContainerImpl: container_1399292339232_0002_01_000003 Container Transitioned from RUNNING to COMPLETED
2014-05-05 12:35:11,822 INFO org.apache.hadoop.yarn.server.resourcemanager.scheduler.common.fica.FiCaSchedulerApp: Completed container: container_1399292339232_0002_01_000003 in state: COMPLETED event:FINISHED
2014-05-05 12:35:11,822 INFO org.apache.hadoop.yarn.server.resourcemanager.RMAuditLogger: USER=ubuntu	OPERATION=AM Released Container	TARGET=SchedulerApp	RESULT=SUCCESS	APPID=application_1399292339232_0002	CONTAINERID=container_1399292339232_0002_01_000003
2014-05-05 12:35:11,822 INFO org.apache.hadoop.yarn.server.resourcemanager.scheduler.common.fica.FiCaSchedulerNode: Released container container_1399292339232_0002_01_000003 of capacity <memory:1024, vCores:1> on host nodeg:56763, which currently has 4 containers, <memory:4096, vCores:4> used and <memory:4096, vCores:4> available, release resources=true
2014-05-05 12:35:11,822 INFO org.apache.hadoop.yarn.server.resourcemanager.scheduler.capacity.LeafQueue: default used=<memory:13312, vCores:12> numContainers=12 user=ubuntu user-resources=<memory:13312, vCores:12>
2014-05-05 12:35:11,822 INFO org.apache.hadoop.yarn.server.resourcemanager.scheduler.capacity.LeafQueue: completedContainer container=Container: [ContainerId: container_1399292339232_0002_01_000003, NodeId: nodeg:56763, NodeHttpAddress: nodeg:8042, Resource: <memory:1024, vCores:1>, Priority: 20, Token: Token { kind: ContainerToken, service: 10.0.0.196:56763 }, ] resource=<memory:1024, vCores:1> queue=default: capacity=1.0, absoluteCapacity=1.0, usedResources=<memory:13312, vCores:12>usedCapacity=0.203125, absoluteUsedCapacity=0.203125, numApps=1, numContainers=12 usedCapacity=0.203125 absoluteUsedCapacity=0.203125 used=<memory:13312, vCores:12> cluster=<memory:65536, vCores:64>
2014-05-05 12:35:11,822 INFO org.apache.hadoop.yarn.server.resourcemanager.scheduler.capacity.ParentQueue: completedContainer queue=root usedCapacity=0.203125 absoluteUsedCapacity=0.203125 used=<memory:13312, vCores:12> cluster=<memory:65536, vCores:64>
2014-05-05 12:35:11,822 INFO org.apache.hadoop.yarn.server.resourcemanager.scheduler.capacity.ParentQueue: Re-sorting completed queue: root.default stats: default: capacity=1.0, absoluteCapacity=1.0, usedResources=<memory:13312, vCores:12>usedCapacity=0.203125, absoluteUsedCapacity=0.203125, numApps=1, numContainers=12
2014-05-05 12:35:11,822 INFO org.apache.hadoop.yarn.server.resourcemanager.scheduler.capacity.CapacityScheduler: Application appattempt_1399292339232_0002_000001 released container container_1399292339232_0002_01_000003 on node: host: nodeg:56763 #containers=4 available=4096 used=4096 with event: FINISHED
2014-05-05 12:35:11,822 INFO org.apache.hadoop.yarn.server.resourcemanager.rmcontainer.RMContainerImpl: container_1399292339232_0002_01_000004 Container Transitioned from RUNNING to COMPLETED
2014-05-05 12:35:11,822 INFO org.apache.hadoop.yarn.server.resourcemanager.scheduler.common.fica.FiCaSchedulerApp: Completed container: container_1399292339232_0002_01_000004 in state: COMPLETED event:FINISHED
2014-05-05 12:35:11,822 INFO org.apache.hadoop.yarn.server.resourcemanager.RMAuditLogger: USER=ubuntu	OPERATION=AM Released Container	TARGET=SchedulerApp	RESULT=SUCCESS	APPID=application_1399292339232_0002	CONTAINERID=container_1399292339232_0002_01_000004
2014-05-05 12:35:11,823 INFO org.apache.hadoop.yarn.server.resourcemanager.scheduler.common.fica.FiCaSchedulerNode: Released container container_1399292339232_0002_01_000004 of capacity <memory:1024, vCores:1> on host nodeg:56763, which currently has 3 containers, <memory:3072, vCores:3> used and <memory:5120, vCores:5> available, release resources=true
2014-05-05 12:35:11,823 INFO org.apache.hadoop.yarn.server.resourcemanager.scheduler.capacity.LeafQueue: default used=<memory:12288, vCores:11> numContainers=11 user=ubuntu user-resources=<memory:12288, vCores:11>
2014-05-05 12:35:11,823 INFO org.apache.hadoop.yarn.server.resourcemanager.scheduler.capacity.LeafQueue: completedContainer container=Container: [ContainerId: container_1399292339232_0002_01_000004, NodeId: nodeg:56763, NodeHttpAddress: nodeg:8042, Resource: <memory:1024, vCores:1>, Priority: 20, Token: Token { kind: ContainerToken, service: 10.0.0.196:56763 }, ] resource=<memory:1024, vCores:1> queue=default: capacity=1.0, absoluteCapacity=1.0, usedResources=<memory:12288, vCores:11>usedCapacity=0.1875, absoluteUsedCapacity=0.1875, numApps=1, numContainers=11 usedCapacity=0.1875 absoluteUsedCapacity=0.1875 used=<memory:12288, vCores:11> cluster=<memory:65536, vCores:64>
2014-05-05 12:35:11,823 INFO org.apache.hadoop.yarn.server.resourcemanager.scheduler.capacity.ParentQueue: completedContainer queue=root usedCapacity=0.1875 absoluteUsedCapacity=0.1875 used=<memory:12288, vCores:11> cluster=<memory:65536, vCores:64>
2014-05-05 12:35:11,823 INFO org.apache.hadoop.yarn.server.resourcemanager.scheduler.capacity.ParentQueue: Re-sorting completed queue: root.default stats: default: capacity=1.0, absoluteCapacity=1.0, usedResources=<memory:12288, vCores:11>usedCapacity=0.1875, absoluteUsedCapacity=0.1875, numApps=1, numContainers=11
2014-05-05 12:35:11,823 INFO org.apache.hadoop.yarn.server.resourcemanager.scheduler.capacity.CapacityScheduler: Application appattempt_1399292339232_0002_000001 released container container_1399292339232_0002_01_000004 on node: host: nodeg:56763 #containers=3 available=5120 used=3072 with event: FINISHED
2014-05-05 12:35:13,235 INFO org.apache.hadoop.yarn.server.webproxy.WebAppProxyServlet: dr.who is accessing unchecked http://ip-10-0-0-193:44754/ which is the app master GUI of application_1399292339232_0002 owned by ubuntu
2014-05-05 12:35:13,292 INFO org.apache.hadoop.yarn.server.resourcemanager.rmcontainer.RMContainerImpl: container_1399292339232_0002_01_000002 Container Transitioned from RUNNING to COMPLETED
2014-05-05 12:35:13,292 INFO org.apache.hadoop.yarn.server.resourcemanager.scheduler.common.fica.FiCaSchedulerApp: Completed container: container_1399292339232_0002_01_000002 in state: COMPLETED event:FINISHED
2014-05-05 12:35:13,292 INFO org.apache.hadoop.yarn.server.resourcemanager.RMAuditLogger: USER=ubuntu	OPERATION=AM Released Container	TARGET=SchedulerApp	RESULT=SUCCESS	APPID=application_1399292339232_0002	CONTAINERID=container_1399292339232_0002_01_000002
2014-05-05 12:35:13,292 INFO org.apache.hadoop.yarn.server.resourcemanager.scheduler.common.fica.FiCaSchedulerNode: Released container container_1399292339232_0002_01_000002 of capacity <memory:1024, vCores:1> on host nodeg:56763, which currently has 2 containers, <memory:2048, vCores:2> used and <memory:6144, vCores:6> available, release resources=true
2014-05-05 12:35:13,292 INFO org.apache.hadoop.yarn.server.resourcemanager.scheduler.capacity.LeafQueue: default used=<memory:11264, vCores:10> numContainers=10 user=ubuntu user-resources=<memory:11264, vCores:10>
2014-05-05 12:35:13,292 INFO org.apache.hadoop.yarn.server.resourcemanager.scheduler.capacity.LeafQueue: completedContainer container=Container: [ContainerId: container_1399292339232_0002_01_000002, NodeId: nodeg:56763, NodeHttpAddress: nodeg:8042, Resource: <memory:1024, vCores:1>, Priority: 20, Token: Token { kind: ContainerToken, service: 10.0.0.196:56763 }, ] resource=<memory:1024, vCores:1> queue=default: capacity=1.0, absoluteCapacity=1.0, usedResources=<memory:11264, vCores:10>usedCapacity=0.171875, absoluteUsedCapacity=0.171875, numApps=1, numContainers=10 usedCapacity=0.171875 absoluteUsedCapacity=0.171875 used=<memory:11264, vCores:10> cluster=<memory:65536, vCores:64>
2014-05-05 12:35:13,293 INFO org.apache.hadoop.yarn.server.resourcemanager.scheduler.capacity.ParentQueue: completedContainer queue=root usedCapacity=0.171875 absoluteUsedCapacity=0.171875 used=<memory:11264, vCores:10> cluster=<memory:65536, vCores:64>
2014-05-05 12:35:13,293 INFO org.apache.hadoop.yarn.server.resourcemanager.scheduler.capacity.ParentQueue: Re-sorting completed queue: root.default stats: default: capacity=1.0, absoluteCapacity=1.0, usedResources=<memory:11264, vCores:10>usedCapacity=0.171875, absoluteUsedCapacity=0.171875, numApps=1, numContainers=10
2014-05-05 12:35:13,293 INFO org.apache.hadoop.yarn.server.resourcemanager.scheduler.capacity.CapacityScheduler: Application appattempt_1399292339232_0002_000001 released container container_1399292339232_0002_01_000002 on node: host: nodeg:56763 #containers=2 available=6144 used=2048 with event: FINISHED
2014-05-05 12:35:13,293 INFO org.apache.hadoop.yarn.server.resourcemanager.rmcontainer.RMContainerImpl: container_1399292339232_0002_01_000006 Container Transitioned from RUNNING to COMPLETED
2014-05-05 12:35:13,293 INFO org.apache.hadoop.yarn.server.resourcemanager.scheduler.common.fica.FiCaSchedulerApp: Completed container: container_1399292339232_0002_01_000006 in state: COMPLETED event:FINISHED
2014-05-05 12:35:13,293 INFO org.apache.hadoop.yarn.server.resourcemanager.RMAuditLogger: USER=ubuntu	OPERATION=AM Released Container	TARGET=SchedulerApp	RESULT=SUCCESS	APPID=application_1399292339232_0002	CONTAINERID=container_1399292339232_0002_01_000006
2014-05-05 12:35:13,293 INFO org.apache.hadoop.yarn.server.resourcemanager.scheduler.common.fica.FiCaSchedulerNode: Released container container_1399292339232_0002_01_000006 of capacity <memory:1024, vCores:1> on host nodeg:56763, which currently has 1 containers, <memory:1024, vCores:1> used and <memory:7168, vCores:7> available, release resources=true
2014-05-05 12:35:13,293 INFO org.apache.hadoop.yarn.server.resourcemanager.scheduler.capacity.LeafQueue: default used=<memory:10240, vCores:9> numContainers=9 user=ubuntu user-resources=<memory:10240, vCores:9>
2014-05-05 12:35:13,293 INFO org.apache.hadoop.yarn.server.resourcemanager.scheduler.capacity.LeafQueue: completedContainer container=Container: [ContainerId: container_1399292339232_0002_01_000006, NodeId: nodeg:56763, NodeHttpAddress: nodeg:8042, Resource: <memory:1024, vCores:1>, Priority: 20, Token: Token { kind: ContainerToken, service: 10.0.0.196:56763 }, ] resource=<memory:1024, vCores:1> queue=default: capacity=1.0, absoluteCapacity=1.0, usedResources=<memory:10240, vCores:9>usedCapacity=0.15625, absoluteUsedCapacity=0.15625, numApps=1, numContainers=9 usedCapacity=0.15625 absoluteUsedCapacity=0.15625 used=<memory:10240, vCores:9> cluster=<memory:65536, vCores:64>
2014-05-05 12:35:13,293 INFO org.apache.hadoop.yarn.server.resourcemanager.scheduler.capacity.ParentQueue: completedContainer queue=root usedCapacity=0.15625 absoluteUsedCapacity=0.15625 used=<memory:10240, vCores:9> cluster=<memory:65536, vCores:64>
2014-05-05 12:35:13,294 INFO org.apache.hadoop.yarn.server.resourcemanager.scheduler.capacity.ParentQueue: Re-sorting completed queue: root.default stats: default: capacity=1.0, absoluteCapacity=1.0, usedResources=<memory:10240, vCores:9>usedCapacity=0.15625, absoluteUsedCapacity=0.15625, numApps=1, numContainers=9
2014-05-05 12:35:13,294 INFO org.apache.hadoop.yarn.server.resourcemanager.scheduler.capacity.CapacityScheduler: Application appattempt_1399292339232_0002_000001 released container container_1399292339232_0002_01_000006 on node: host: nodeg:56763 #containers=1 available=7168 used=1024 with event: FINISHED
2014-05-05 12:35:15,804 INFO org.apache.hadoop.yarn.server.webproxy.WebAppProxyServlet: dr.who is accessing unchecked http://ip-10-0-0-193:44754/static/yarn.css which is the app master GUI of application_1399292339232_0002 owned by ubuntu
2014-05-05 12:35:15,870 INFO org.apache.hadoop.yarn.server.webproxy.WebAppProxyServlet: dr.who is accessing unchecked http://ip-10-0-0-193:44754/static/jquery/themes-1.9.1/base/jquery-ui.css which is the app master GUI of application_1399292339232_0002 owned by ubuntu
2014-05-05 12:35:15,870 INFO org.apache.hadoop.yarn.server.webproxy.WebAppProxyServlet: dr.who is accessing unchecked http://ip-10-0-0-193:44754/static/dt-1.9.4/js/jquery.dataTables.min.js which is the app master GUI of application_1399292339232_0002 owned by ubuntu
2014-05-05 12:35:15,872 INFO org.apache.hadoop.yarn.server.webproxy.WebAppProxyServlet: dr.who is accessing unchecked http://ip-10-0-0-193:44754/static/dt-1.9.4/css/jui-dt.css which is the app master GUI of application_1399292339232_0002 owned by ubuntu
2014-05-05 12:35:15,872 INFO org.apache.hadoop.yarn.server.webproxy.WebAppProxyServlet: dr.who is accessing unchecked http://ip-10-0-0-193:44754/static/jquery/jquery-ui-1.9.1.custom.min.js which is the app master GUI of application_1399292339232_0002 owned by ubuntu
2014-05-05 12:35:15,898 INFO org.apache.hadoop.yarn.server.webproxy.WebAppProxyServlet: dr.who is accessing unchecked http://ip-10-0-0-193:44754/static/jquery/jquery-1.8.2.min.js which is the app master GUI of application_1399292339232_0002 owned by ubuntu
2014-05-05 12:35:15,901 INFO org.apache.hadoop.yarn.server.webproxy.WebAppProxyServlet: dr.who is accessing unchecked http://ip-10-0-0-193:44754/static/yarn.dt.plugins.js which is the app master GUI of application_1399292339232_0002 owned by ubuntu
2014-05-05 12:35:16,246 INFO org.apache.hadoop.yarn.server.webproxy.WebAppProxyServlet: dr.who is accessing unchecked http://ip-10-0-0-193:44754/static/jquery/themes-1.9.1/base/images/ui-bg_glass_95_fef1ec_1x400.png which is the app master GUI of application_1399292339232_0002 owned by ubuntu
2014-05-05 12:35:16,248 INFO org.apache.hadoop.yarn.server.webproxy.WebAppProxyServlet: dr.who is accessing unchecked http://ip-10-0-0-193:44754/static/jquery/themes-1.9.1/base/images/ui-bg_flat_75_ffffff_40x100.png which is the app master GUI of application_1399292339232_0002 owned by ubuntu
2014-05-05 12:35:16,249 INFO org.apache.hadoop.yarn.server.webproxy.WebAppProxyServlet: dr.who is accessing unchecked http://ip-10-0-0-193:44754/static/jquery/themes-1.9.1/base/images/ui-bg_highlight-soft_75_cccccc_1x100.png which is the app master GUI of application_1399292339232_0002 owned by ubuntu
2014-05-05 12:35:16,258 INFO org.apache.hadoop.yarn.server.webproxy.WebAppProxyServlet: dr.who is accessing unchecked http://ip-10-0-0-193:44754/static/jquery/themes-1.9.1/base/images/ui-bg_glass_75_e6e6e6_1x400.png which is the app master GUI of application_1399292339232_0002 owned by ubuntu
2014-05-05 12:35:16,263 INFO org.apache.hadoop.yarn.server.webproxy.WebAppProxyServlet: dr.who is accessing unchecked http://ip-10-0-0-193:44754/static/jquery/themes-1.9.1/base/images/ui-icons_888888_256x240.png which is the app master GUI of application_1399292339232_0002 owned by ubuntu
2014-05-05 12:35:16,272 INFO org.apache.hadoop.yarn.server.webproxy.WebAppProxyServlet: dr.who is accessing unchecked http://ip-10-0-0-193:44754/static/jquery/themes-1.9.1/base/images/ui-bg_glass_65_ffffff_1x400.png which is the app master GUI of application_1399292339232_0002 owned by ubuntu
2014-05-05 12:35:16,335 INFO org.apache.hadoop.yarn.server.webproxy.WebAppProxyServlet: dr.who is accessing unchecked http://ip-10-0-0-193:44754/static/jquery/themes-1.9.1/base/images/ui-icons_454545_256x240.png which is the app master GUI of application_1399292339232_0002 owned by ubuntu
2014-05-05 12:35:17,579 INFO org.apache.hadoop.yarn.server.webproxy.WebAppProxyServlet: dr.who is accessing unchecked http://ip-10-0-0-193:44754/mapreduce/job/job_1399292339232_0002 which is the app master GUI of application_1399292339232_0002 owned by ubuntu
2014-05-05 12:35:17,800 INFO org.apache.hadoop.yarn.server.webproxy.WebAppProxyServlet: dr.who is accessing unchecked http://ip-10-0-0-193:44754/static/jquery/jquery-1.8.2.min.js which is the app master GUI of application_1399292339232_0002 owned by ubuntu
2014-05-05 12:35:17,800 INFO org.apache.hadoop.yarn.server.webproxy.WebAppProxyServlet: dr.who is accessing unchecked http://ip-10-0-0-193:44754/static/jquery/themes-1.9.1/base/jquery-ui.css which is the app master GUI of application_1399292339232_0002 owned by ubuntu
2014-05-05 12:35:17,801 INFO org.apache.hadoop.yarn.server.webproxy.WebAppProxyServlet: dr.who is accessing unchecked http://ip-10-0-0-193:44754/static/dt-1.9.4/css/jui-dt.css which is the app master GUI of application_1399292339232_0002 owned by ubuntu
2014-05-05 12:35:17,804 INFO org.apache.hadoop.yarn.server.webproxy.WebAppProxyServlet: dr.who is accessing unchecked http://ip-10-0-0-193:44754/static/yarn.css which is the app master GUI of application_1399292339232_0002 owned by ubuntu
2014-05-05 12:35:17,812 INFO org.apache.hadoop.yarn.server.webproxy.WebAppProxyServlet: dr.who is accessing unchecked http://ip-10-0-0-193:44754/static/dt-1.9.4/js/jquery.dataTables.min.js which is the app master GUI of application_1399292339232_0002 owned by ubuntu
2014-05-05 12:35:17,814 INFO org.apache.hadoop.yarn.server.webproxy.WebAppProxyServlet: dr.who is accessing unchecked http://ip-10-0-0-193:44754/static/jquery/jquery-ui-1.9.1.custom.min.js which is the app master GUI of application_1399292339232_0002 owned by ubuntu
2014-05-05 12:35:17,900 INFO org.apache.hadoop.yarn.server.webproxy.WebAppProxyServlet: dr.who is accessing unchecked http://ip-10-0-0-193:44754/static/yarn.dt.plugins.js which is the app master GUI of application_1399292339232_0002 owned by ubuntu
2014-05-05 12:35:18,136 INFO org.apache.hadoop.yarn.server.webproxy.WebAppProxyServlet: dr.who is accessing unchecked http://ip-10-0-0-193:44754/static/jquery/themes-1.9.1/base/images/ui-bg_flat_75_ffffff_40x100.png which is the app master GUI of application_1399292339232_0002 owned by ubuntu
2014-05-05 12:35:18,138 INFO org.apache.hadoop.yarn.server.webproxy.WebAppProxyServlet: dr.who is accessing unchecked http://ip-10-0-0-193:44754/static/jquery/themes-1.9.1/base/images/ui-bg_glass_95_fef1ec_1x400.png which is the app master GUI of application_1399292339232_0002 owned by ubuntu
2014-05-05 12:35:18,138 INFO org.apache.hadoop.yarn.server.webproxy.WebAppProxyServlet: dr.who is accessing unchecked http://ip-10-0-0-193:44754/static/jquery/themes-1.9.1/base/images/ui-bg_glass_75_e6e6e6_1x400.png which is the app master GUI of application_1399292339232_0002 owned by ubuntu
2014-05-05 12:35:18,141 INFO org.apache.hadoop.yarn.server.webproxy.WebAppProxyServlet: dr.who is accessing unchecked http://ip-10-0-0-193:44754/static/jquery/themes-1.9.1/base/images/ui-bg_highlight-soft_75_cccccc_1x100.png which is the app master GUI of application_1399292339232_0002 owned by ubuntu
2014-05-05 12:35:18,151 INFO org.apache.hadoop.yarn.server.webproxy.WebAppProxyServlet: dr.who is accessing unchecked http://ip-10-0-0-193:44754/static/jquery/themes-1.9.1/base/images/ui-icons_888888_256x240.png which is the app master GUI of application_1399292339232_0002 owned by ubuntu
2014-05-05 12:35:18,152 INFO org.apache.hadoop.yarn.server.webproxy.WebAppProxyServlet: dr.who is accessing unchecked http://ip-10-0-0-193:44754/static/jquery/themes-1.9.1/base/images/ui-bg_glass_65_ffffff_1x400.png which is the app master GUI of application_1399292339232_0002 owned by ubuntu
2014-05-05 12:35:18,221 INFO org.apache.hadoop.yarn.server.webproxy.WebAppProxyServlet: dr.who is accessing unchecked http://ip-10-0-0-193:44754/static/jquery/themes-1.9.1/base/images/ui-icons_454545_256x240.png which is the app master GUI of application_1399292339232_0002 owned by ubuntu
2014-05-05 12:35:51,040 INFO org.apache.hadoop.yarn.server.resourcemanager.rmcontainer.RMContainerImpl: container_1399292339232_0002_01_000014 Container Transitioned from RUNNING to COMPLETED
2014-05-05 12:35:51,040 INFO org.apache.hadoop.yarn.server.resourcemanager.scheduler.common.fica.FiCaSchedulerApp: Completed container: container_1399292339232_0002_01_000014 in state: COMPLETED event:FINISHED
2014-05-05 12:35:51,040 INFO org.apache.hadoop.yarn.server.resourcemanager.RMAuditLogger: USER=ubuntu	OPERATION=AM Released Container	TARGET=SchedulerApp	RESULT=SUCCESS	APPID=application_1399292339232_0002	CONTAINERID=container_1399292339232_0002_01_000014
2014-05-05 12:35:51,040 INFO org.apache.hadoop.yarn.server.resourcemanager.scheduler.common.fica.FiCaSchedulerNode: Released container container_1399292339232_0002_01_000014 of capacity <memory:1024, vCores:1> on host noded:39305, which currently has 1 containers, <memory:2048, vCores:1> used and <memory:6144, vCores:7> available, release resources=true
2014-05-05 12:35:51,040 INFO org.apache.hadoop.yarn.server.resourcemanager.scheduler.capacity.LeafQueue: default used=<memory:9216, vCores:8> numContainers=8 user=ubuntu user-resources=<memory:9216, vCores:8>
2014-05-05 12:35:51,040 INFO org.apache.hadoop.yarn.server.resourcemanager.scheduler.capacity.LeafQueue: completedContainer container=Container: [ContainerId: container_1399292339232_0002_01_000014, NodeId: noded:39305, NodeHttpAddress: noded:8042, Resource: <memory:1024, vCores:1>, Priority: 10, Token: Token { kind: ContainerToken, service: 10.0.0.193:39305 }, ] resource=<memory:1024, vCores:1> queue=default: capacity=1.0, absoluteCapacity=1.0, usedResources=<memory:9216, vCores:8>usedCapacity=0.140625, absoluteUsedCapacity=0.140625, numApps=1, numContainers=8 usedCapacity=0.140625 absoluteUsedCapacity=0.140625 used=<memory:9216, vCores:8> cluster=<memory:65536, vCores:64>
2014-05-05 12:35:51,040 INFO org.apache.hadoop.yarn.server.resourcemanager.scheduler.capacity.ParentQueue: completedContainer queue=root usedCapacity=0.140625 absoluteUsedCapacity=0.140625 used=<memory:9216, vCores:8> cluster=<memory:65536, vCores:64>
2014-05-05 12:35:51,041 INFO org.apache.hadoop.yarn.server.resourcemanager.scheduler.capacity.ParentQueue: Re-sorting completed queue: root.default stats: default: capacity=1.0, absoluteCapacity=1.0, usedResources=<memory:9216, vCores:8>usedCapacity=0.140625, absoluteUsedCapacity=0.140625, numApps=1, numContainers=8
2014-05-05 12:35:51,041 INFO org.apache.hadoop.yarn.server.resourcemanager.scheduler.capacity.CapacityScheduler: Application appattempt_1399292339232_0002_000001 released container container_1399292339232_0002_01_000014 on node: host: noded:39305 #containers=1 available=6144 used=2048 with event: FINISHED
2014-05-05 12:35:51,049 INFO org.apache.hadoop.yarn.server.resourcemanager.rmcontainer.RMContainerImpl: container_1399292339232_0002_01_000008 Container Transitioned from RUNNING to COMPLETED
2014-05-05 12:35:51,049 INFO org.apache.hadoop.yarn.server.resourcemanager.scheduler.common.fica.FiCaSchedulerApp: Completed container: container_1399292339232_0002_01_000008 in state: COMPLETED event:FINISHED
2014-05-05 12:35:51,049 INFO org.apache.hadoop.yarn.server.resourcemanager.RMAuditLogger: USER=ubuntu	OPERATION=AM Released Container	TARGET=SchedulerApp	RESULT=SUCCESS	APPID=application_1399292339232_0002	CONTAINERID=container_1399292339232_0002_01_000008
2014-05-05 12:35:51,049 INFO org.apache.hadoop.yarn.server.resourcemanager.scheduler.common.fica.FiCaSchedulerNode: Released container container_1399292339232_0002_01_000008 of capacity <memory:1024, vCores:1> on host nodea:51924, which currently has 0 containers, <memory:0, vCores:0> used and <memory:8192, vCores:8> available, release resources=true
2014-05-05 12:35:51,049 INFO org.apache.hadoop.yarn.server.resourcemanager.scheduler.capacity.LeafQueue: default used=<memory:8192, vCores:7> numContainers=7 user=ubuntu user-resources=<memory:8192, vCores:7>
2014-05-05 12:35:51,049 INFO org.apache.hadoop.yarn.server.resourcemanager.scheduler.capacity.LeafQueue: completedContainer container=Container: [ContainerId: container_1399292339232_0002_01_000008, NodeId: nodea:51924, NodeHttpAddress: nodea:8042, Resource: <memory:1024, vCores:1>, Priority: 10, Token: Token { kind: ContainerToken, service: 10.0.0.195:51924 }, ] resource=<memory:1024, vCores:1> queue=default: capacity=1.0, absoluteCapacity=1.0, usedResources=<memory:8192, vCores:7>usedCapacity=0.125, absoluteUsedCapacity=0.125, numApps=1, numContainers=7 usedCapacity=0.125 absoluteUsedCapacity=0.125 used=<memory:8192, vCores:7> cluster=<memory:65536, vCores:64>
2014-05-05 12:35:51,049 INFO org.apache.hadoop.yarn.server.resourcemanager.scheduler.capacity.ParentQueue: completedContainer queue=root usedCapacity=0.125 absoluteUsedCapacity=0.125 used=<memory:8192, vCores:7> cluster=<memory:65536, vCores:64>
2014-05-05 12:35:51,049 INFO org.apache.hadoop.yarn.server.resourcemanager.scheduler.capacity.ParentQueue: Re-sorting completed queue: root.default stats: default: capacity=1.0, absoluteCapacity=1.0, usedResources=<memory:8192, vCores:7>usedCapacity=0.125, absoluteUsedCapacity=0.125, numApps=1, numContainers=7
2014-05-05 12:35:51,050 INFO org.apache.hadoop.yarn.server.resourcemanager.scheduler.capacity.CapacityScheduler: Application appattempt_1399292339232_0002_000001 released container container_1399292339232_0002_01_000008 on node: host: nodea:51924 #containers=0 available=8192 used=0 with event: FINISHED
2014-05-05 12:35:51,096 INFO org.apache.hadoop.yarn.server.resourcemanager.rmcontainer.RMContainerImpl: container_1399292339232_0002_01_000013 Container Transitioned from RUNNING to COMPLETED
2014-05-05 12:35:51,096 INFO org.apache.hadoop.yarn.server.resourcemanager.scheduler.common.fica.FiCaSchedulerApp: Completed container: container_1399292339232_0002_01_000013 in state: COMPLETED event:FINISHED
2014-05-05 12:35:51,096 INFO org.apache.hadoop.yarn.server.resourcemanager.RMAuditLogger: USER=ubuntu	OPERATION=AM Released Container	TARGET=SchedulerApp	RESULT=SUCCESS	APPID=application_1399292339232_0002	CONTAINERID=container_1399292339232_0002_01_000013
2014-05-05 12:35:51,096 INFO org.apache.hadoop.yarn.server.resourcemanager.scheduler.common.fica.FiCaSchedulerNode: Released container container_1399292339232_0002_01_000013 of capacity <memory:1024, vCores:1> on host nodeh:46599, which currently has 0 containers, <memory:0, vCores:0> used and <memory:8192, vCores:8> available, release resources=true
2014-05-05 12:35:51,096 INFO org.apache.hadoop.yarn.server.resourcemanager.scheduler.capacity.LeafQueue: default used=<memory:7168, vCores:6> numContainers=6 user=ubuntu user-resources=<memory:7168, vCores:6>
2014-05-05 12:35:51,096 INFO org.apache.hadoop.yarn.server.resourcemanager.scheduler.capacity.LeafQueue: completedContainer container=Container: [ContainerId: container_1399292339232_0002_01_000013, NodeId: nodeh:46599, NodeHttpAddress: nodeh:8042, Resource: <memory:1024, vCores:1>, Priority: 10, Token: Token { kind: ContainerToken, service: 10.0.0.197:46599 }, ] resource=<memory:1024, vCores:1> queue=default: capacity=1.0, absoluteCapacity=1.0, usedResources=<memory:7168, vCores:6>usedCapacity=0.109375, absoluteUsedCapacity=0.109375, numApps=1, numContainers=6 usedCapacity=0.109375 absoluteUsedCapacity=0.109375 used=<memory:7168, vCores:6> cluster=<memory:65536, vCores:64>
2014-05-05 12:35:51,096 INFO org.apache.hadoop.yarn.server.resourcemanager.scheduler.capacity.ParentQueue: completedContainer queue=root usedCapacity=0.109375 absoluteUsedCapacity=0.109375 used=<memory:7168, vCores:6> cluster=<memory:65536, vCores:64>
2014-05-05 12:35:51,096 INFO org.apache.hadoop.yarn.server.resourcemanager.scheduler.capacity.ParentQueue: Re-sorting completed queue: root.default stats: default: capacity=1.0, absoluteCapacity=1.0, usedResources=<memory:7168, vCores:6>usedCapacity=0.109375, absoluteUsedCapacity=0.109375, numApps=1, numContainers=6
2014-05-05 12:35:51,096 INFO org.apache.hadoop.yarn.server.resourcemanager.scheduler.capacity.CapacityScheduler: Application appattempt_1399292339232_0002_000001 released container container_1399292339232_0002_01_000013 on node: host: nodeh:46599 #containers=0 available=8192 used=0 with event: FINISHED
2014-05-05 12:35:51,100 INFO org.apache.hadoop.yarn.server.resourcemanager.rmcontainer.RMContainerImpl: container_1399292339232_0002_01_000012 Container Transitioned from RUNNING to COMPLETED
2014-05-05 12:35:51,100 INFO org.apache.hadoop.yarn.server.resourcemanager.scheduler.common.fica.FiCaSchedulerApp: Completed container: container_1399292339232_0002_01_000012 in state: COMPLETED event:FINISHED
2014-05-05 12:35:51,101 INFO org.apache.hadoop.yarn.server.resourcemanager.RMAuditLogger: USER=ubuntu	OPERATION=AM Released Container	TARGET=SchedulerApp	RESULT=SUCCESS	APPID=application_1399292339232_0002	CONTAINERID=container_1399292339232_0002_01_000012
2014-05-05 12:35:51,101 INFO org.apache.hadoop.yarn.server.resourcemanager.scheduler.common.fica.FiCaSchedulerNode: Released container container_1399292339232_0002_01_000012 of capacity <memory:1024, vCores:1> on host nodef:54669, which currently has 0 containers, <memory:0, vCores:0> used and <memory:8192, vCores:8> available, release resources=true
2014-05-05 12:35:51,101 INFO org.apache.hadoop.yarn.server.resourcemanager.scheduler.capacity.LeafQueue: default used=<memory:6144, vCores:5> numContainers=5 user=ubuntu user-resources=<memory:6144, vCores:5>
2014-05-05 12:35:51,101 INFO org.apache.hadoop.yarn.server.resourcemanager.scheduler.capacity.LeafQueue: completedContainer container=Container: [ContainerId: container_1399292339232_0002_01_000012, NodeId: nodef:54669, NodeHttpAddress: nodef:8042, Resource: <memory:1024, vCores:1>, Priority: 10, Token: Token { kind: ContainerToken, service: 10.0.0.199:54669 }, ] resource=<memory:1024, vCores:1> queue=default: capacity=1.0, absoluteCapacity=1.0, usedResources=<memory:6144, vCores:5>usedCapacity=0.09375, absoluteUsedCapacity=0.09375, numApps=1, numContainers=5 usedCapacity=0.09375 absoluteUsedCapacity=0.09375 used=<memory:6144, vCores:5> cluster=<memory:65536, vCores:64>
2014-05-05 12:35:51,101 INFO org.apache.hadoop.yarn.server.resourcemanager.scheduler.capacity.ParentQueue: completedContainer queue=root usedCapacity=0.09375 absoluteUsedCapacity=0.09375 used=<memory:6144, vCores:5> cluster=<memory:65536, vCores:64>
2014-05-05 12:35:51,101 INFO org.apache.hadoop.yarn.server.resourcemanager.scheduler.capacity.ParentQueue: Re-sorting completed queue: root.default stats: default: capacity=1.0, absoluteCapacity=1.0, usedResources=<memory:6144, vCores:5>usedCapacity=0.09375, absoluteUsedCapacity=0.09375, numApps=1, numContainers=5
2014-05-05 12:35:51,101 INFO org.apache.hadoop.yarn.server.resourcemanager.scheduler.capacity.CapacityScheduler: Application appattempt_1399292339232_0002_000001 released container container_1399292339232_0002_01_000012 on node: host: nodef:54669 #containers=0 available=8192 used=0 with event: FINISHED
2014-05-05 12:35:51,112 INFO org.apache.hadoop.yarn.server.resourcemanager.rmcontainer.RMContainerImpl: container_1399292339232_0002_01_000007 Container Transitioned from RUNNING to COMPLETED
2014-05-05 12:35:51,112 INFO org.apache.hadoop.yarn.server.resourcemanager.scheduler.common.fica.FiCaSchedulerApp: Completed container: container_1399292339232_0002_01_000007 in state: COMPLETED event:FINISHED
2014-05-05 12:35:51,112 INFO org.apache.hadoop.yarn.server.resourcemanager.RMAuditLogger: USER=ubuntu	OPERATION=AM Released Container	TARGET=SchedulerApp	RESULT=SUCCESS	APPID=application_1399292339232_0002	CONTAINERID=container_1399292339232_0002_01_000007
2014-05-05 12:35:51,112 INFO org.apache.hadoop.yarn.server.resourcemanager.scheduler.common.fica.FiCaSchedulerNode: Released container container_1399292339232_0002_01_000007 of capacity <memory:1024, vCores:1> on host nodeg:56763, which currently has 0 containers, <memory:0, vCores:0> used and <memory:8192, vCores:8> available, release resources=true
2014-05-05 12:35:51,112 INFO org.apache.hadoop.yarn.server.resourcemanager.scheduler.capacity.LeafQueue: default used=<memory:5120, vCores:4> numContainers=4 user=ubuntu user-resources=<memory:5120, vCores:4>
2014-05-05 12:35:51,113 INFO org.apache.hadoop.yarn.server.resourcemanager.scheduler.capacity.LeafQueue: completedContainer container=Container: [ContainerId: container_1399292339232_0002_01_000007, NodeId: nodeg:56763, NodeHttpAddress: nodeg:8042, Resource: <memory:1024, vCores:1>, Priority: 10, Token: Token { kind: ContainerToken, service: 10.0.0.196:56763 }, ] resource=<memory:1024, vCores:1> queue=default: capacity=1.0, absoluteCapacity=1.0, usedResources=<memory:5120, vCores:4>usedCapacity=0.078125, absoluteUsedCapacity=0.078125, numApps=1, numContainers=4 usedCapacity=0.078125 absoluteUsedCapacity=0.078125 used=<memory:5120, vCores:4> cluster=<memory:65536, vCores:64>
2014-05-05 12:35:51,113 INFO org.apache.hadoop.yarn.server.resourcemanager.scheduler.capacity.ParentQueue: completedContainer queue=root usedCapacity=0.078125 absoluteUsedCapacity=0.078125 used=<memory:5120, vCores:4> cluster=<memory:65536, vCores:64>
2014-05-05 12:35:51,113 INFO org.apache.hadoop.yarn.server.resourcemanager.scheduler.capacity.ParentQueue: Re-sorting completed queue: root.default stats: default: capacity=1.0, absoluteCapacity=1.0, usedResources=<memory:5120, vCores:4>usedCapacity=0.078125, absoluteUsedCapacity=0.078125, numApps=1, numContainers=4
2014-05-05 12:35:51,113 INFO org.apache.hadoop.yarn.server.resourcemanager.scheduler.capacity.CapacityScheduler: Application appattempt_1399292339232_0002_000001 released container container_1399292339232_0002_01_000007 on node: host: nodeg:56763 #containers=0 available=8192 used=0 with event: FINISHED
2014-05-05 12:35:51,113 INFO org.apache.hadoop.yarn.server.resourcemanager.rmcontainer.RMContainerImpl: container_1399292339232_0002_01_000015 Container Transitioned from NEW to ALLOCATED
2014-05-05 12:35:51,113 INFO org.apache.hadoop.yarn.server.resourcemanager.RMAuditLogger: USER=ubuntu	OPERATION=AM Allocated Container	TARGET=SchedulerApp	RESULT=SUCCESS	APPID=application_1399292339232_0002	CONTAINERID=container_1399292339232_0002_01_000015
2014-05-05 12:35:51,113 INFO org.apache.hadoop.yarn.server.resourcemanager.scheduler.common.fica.FiCaSchedulerNode: Assigned container container_1399292339232_0002_01_000015 of capacity <memory:1024, vCores:1> on host nodeg:56763, which currently has 1 containers, <memory:1024, vCores:1> used and <memory:7168, vCores:7> available
2014-05-05 12:35:51,114 INFO org.apache.hadoop.yarn.server.resourcemanager.scheduler.capacity.LeafQueue: assignedContainer application=application_1399292339232_0002 container=Container: [ContainerId: container_1399292339232_0002_01_000015, NodeId: nodeg:56763, NodeHttpAddress: nodeg:8042, Resource: <memory:1024, vCores:1>, Priority: 10, Token: Token { kind: ContainerToken, service: 10.0.0.196:56763 }, ] containerId=container_1399292339232_0002_01_000015 queue=default: capacity=1.0, absoluteCapacity=1.0, usedResources=<memory:5120, vCores:4>usedCapacity=0.078125, absoluteUsedCapacity=0.078125, numApps=1, numContainers=4 usedCapacity=0.078125 absoluteUsedCapacity=0.078125 used=<memory:5120, vCores:4> cluster=<memory:65536, vCores:64>
2014-05-05 12:35:51,114 INFO org.apache.hadoop.yarn.server.resourcemanager.scheduler.capacity.ParentQueue: Re-sorting assigned queue: root.default stats: default: capacity=1.0, absoluteCapacity=1.0, usedResources=<memory:6144, vCores:5>usedCapacity=0.09375, absoluteUsedCapacity=0.09375, numApps=1, numContainers=5
2014-05-05 12:35:51,114 INFO org.apache.hadoop.yarn.server.resourcemanager.scheduler.capacity.ParentQueue: assignedContainer queue=root usedCapacity=0.09375 absoluteUsedCapacity=0.09375 used=<memory:6144, vCores:5> cluster=<memory:65536, vCores:64>
2014-05-05 12:35:51,116 INFO org.apache.hadoop.yarn.server.resourcemanager.rmcontainer.RMContainerImpl: container_1399292339232_0002_01_000010 Container Transitioned from RUNNING to COMPLETED
2014-05-05 12:35:51,116 INFO org.apache.hadoop.yarn.server.resourcemanager.scheduler.common.fica.FiCaSchedulerApp: Completed container: container_1399292339232_0002_01_000010 in state: COMPLETED event:FINISHED
2014-05-05 12:35:51,116 INFO org.apache.hadoop.yarn.server.resourcemanager.RMAuditLogger: USER=ubuntu	OPERATION=AM Released Container	TARGET=SchedulerApp	RESULT=SUCCESS	APPID=application_1399292339232_0002	CONTAINERID=container_1399292339232_0002_01_000010
2014-05-05 12:35:51,116 INFO org.apache.hadoop.yarn.server.resourcemanager.scheduler.common.fica.FiCaSchedulerNode: Released container container_1399292339232_0002_01_000010 of capacity <memory:1024, vCores:1> on host nodee:49598, which currently has 0 containers, <memory:0, vCores:0> used and <memory:8192, vCores:8> available, release resources=true
2014-05-05 12:35:51,116 INFO org.apache.hadoop.yarn.server.resourcemanager.scheduler.capacity.LeafQueue: default used=<memory:5120, vCores:4> numContainers=4 user=ubuntu user-resources=<memory:5120, vCores:4>
2014-05-05 12:35:51,117 INFO org.apache.hadoop.yarn.server.resourcemanager.scheduler.capacity.LeafQueue: completedContainer container=Container: [ContainerId: container_1399292339232_0002_01_000010, NodeId: nodee:49598, NodeHttpAddress: nodee:8042, Resource: <memory:1024, vCores:1>, Priority: 10, Token: Token { kind: ContainerToken, service: 10.0.0.198:49598 }, ] resource=<memory:1024, vCores:1> queue=default: capacity=1.0, absoluteCapacity=1.0, usedResources=<memory:5120, vCores:4>usedCapacity=0.078125, absoluteUsedCapacity=0.078125, numApps=1, numContainers=4 usedCapacity=0.078125 absoluteUsedCapacity=0.078125 used=<memory:5120, vCores:4> cluster=<memory:65536, vCores:64>
2014-05-05 12:35:51,117 INFO org.apache.hadoop.yarn.server.resourcemanager.scheduler.capacity.ParentQueue: completedContainer queue=root usedCapacity=0.078125 absoluteUsedCapacity=0.078125 used=<memory:5120, vCores:4> cluster=<memory:65536, vCores:64>
2014-05-05 12:35:51,117 INFO org.apache.hadoop.yarn.server.resourcemanager.scheduler.capacity.ParentQueue: Re-sorting completed queue: root.default stats: default: capacity=1.0, absoluteCapacity=1.0, usedResources=<memory:5120, vCores:4>usedCapacity=0.078125, absoluteUsedCapacity=0.078125, numApps=1, numContainers=4
2014-05-05 12:35:51,117 INFO org.apache.hadoop.yarn.server.resourcemanager.scheduler.capacity.CapacityScheduler: Application appattempt_1399292339232_0002_000001 released container container_1399292339232_0002_01_000010 on node: host: nodee:49598 #containers=0 available=8192 used=0 with event: FINISHED
2014-05-05 12:35:51,117 INFO org.apache.hadoop.yarn.server.resourcemanager.rmcontainer.RMContainerImpl: container_1399292339232_0002_01_000016 Container Transitioned from NEW to ALLOCATED
2014-05-05 12:35:51,117 INFO org.apache.hadoop.yarn.server.resourcemanager.RMAuditLogger: USER=ubuntu	OPERATION=AM Allocated Container	TARGET=SchedulerApp	RESULT=SUCCESS	APPID=application_1399292339232_0002	CONTAINERID=container_1399292339232_0002_01_000016
2014-05-05 12:35:51,117 INFO org.apache.hadoop.yarn.server.resourcemanager.scheduler.common.fica.FiCaSchedulerNode: Assigned container container_1399292339232_0002_01_000016 of capacity <memory:1024, vCores:1> on host nodee:49598, which currently has 1 containers, <memory:1024, vCores:1> used and <memory:7168, vCores:7> available
2014-05-05 12:35:51,117 INFO org.apache.hadoop.yarn.server.resourcemanager.scheduler.capacity.LeafQueue: assignedContainer application=application_1399292339232_0002 container=Container: [ContainerId: container_1399292339232_0002_01_000016, NodeId: nodee:49598, NodeHttpAddress: nodee:8042, Resource: <memory:1024, vCores:1>, Priority: 10, Token: Token { kind: ContainerToken, service: 10.0.0.198:49598 }, ] containerId=container_1399292339232_0002_01_000016 queue=default: capacity=1.0, absoluteCapacity=1.0, usedResources=<memory:5120, vCores:4>usedCapacity=0.078125, absoluteUsedCapacity=0.078125, numApps=1, numContainers=4 usedCapacity=0.078125 absoluteUsedCapacity=0.078125 used=<memory:5120, vCores:4> cluster=<memory:65536, vCores:64>
2014-05-05 12:35:51,117 INFO org.apache.hadoop.yarn.server.resourcemanager.scheduler.capacity.ParentQueue: Re-sorting assigned queue: root.default stats: default: capacity=1.0, absoluteCapacity=1.0, usedResources=<memory:6144, vCores:5>usedCapacity=0.09375, absoluteUsedCapacity=0.09375, numApps=1, numContainers=5
2014-05-05 12:35:51,117 INFO org.apache.hadoop.yarn.server.resourcemanager.scheduler.capacity.ParentQueue: assignedContainer queue=root usedCapacity=0.09375 absoluteUsedCapacity=0.09375 used=<memory:6144, vCores:5> cluster=<memory:65536, vCores:64>
2014-05-05 12:35:51,125 INFO org.apache.hadoop.yarn.server.resourcemanager.rmcontainer.RMContainerImpl: container_1399292339232_0002_01_000011 Container Transitioned from RUNNING to COMPLETED
2014-05-05 12:35:51,125 INFO org.apache.hadoop.yarn.server.resourcemanager.scheduler.common.fica.FiCaSchedulerApp: Completed container: container_1399292339232_0002_01_000011 in state: COMPLETED event:FINISHED
2014-05-05 12:35:51,125 INFO org.apache.hadoop.yarn.server.resourcemanager.RMAuditLogger: USER=ubuntu	OPERATION=AM Released Container	TARGET=SchedulerApp	RESULT=SUCCESS	APPID=application_1399292339232_0002	CONTAINERID=container_1399292339232_0002_01_000011
2014-05-05 12:35:51,125 INFO org.apache.hadoop.yarn.server.resourcemanager.scheduler.common.fica.FiCaSchedulerNode: Released container container_1399292339232_0002_01_000011 of capacity <memory:1024, vCores:1> on host nodec:35478, which currently has 0 containers, <memory:0, vCores:0> used and <memory:8192, vCores:8> available, release resources=true
2014-05-05 12:35:51,125 INFO org.apache.hadoop.yarn.server.resourcemanager.scheduler.capacity.LeafQueue: default used=<memory:5120, vCores:4> numContainers=4 user=ubuntu user-resources=<memory:5120, vCores:4>
2014-05-05 12:35:51,125 INFO org.apache.hadoop.yarn.server.resourcemanager.scheduler.capacity.LeafQueue: completedContainer container=Container: [ContainerId: container_1399292339232_0002_01_000011, NodeId: nodec:35478, NodeHttpAddress: nodec:8042, Resource: <memory:1024, vCores:1>, Priority: 10, Token: Token { kind: ContainerToken, service: 10.0.0.200:35478 }, ] resource=<memory:1024, vCores:1> queue=default: capacity=1.0, absoluteCapacity=1.0, usedResources=<memory:5120, vCores:4>usedCapacity=0.078125, absoluteUsedCapacity=0.078125, numApps=1, numContainers=4 usedCapacity=0.078125 absoluteUsedCapacity=0.078125 used=<memory:5120, vCores:4> cluster=<memory:65536, vCores:64>
2014-05-05 12:35:51,125 INFO org.apache.hadoop.yarn.server.resourcemanager.scheduler.capacity.ParentQueue: completedContainer queue=root usedCapacity=0.078125 absoluteUsedCapacity=0.078125 used=<memory:5120, vCores:4> cluster=<memory:65536, vCores:64>
2014-05-05 12:35:51,125 INFO org.apache.hadoop.yarn.server.resourcemanager.scheduler.capacity.ParentQueue: Re-sorting completed queue: root.default stats: default: capacity=1.0, absoluteCapacity=1.0, usedResources=<memory:5120, vCores:4>usedCapacity=0.078125, absoluteUsedCapacity=0.078125, numApps=1, numContainers=4
2014-05-05 12:35:51,125 INFO org.apache.hadoop.yarn.server.resourcemanager.scheduler.capacity.CapacityScheduler: Application appattempt_1399292339232_0002_000001 released container container_1399292339232_0002_01_000011 on node: host: nodec:35478 #containers=0 available=8192 used=0 with event: FINISHED
2014-05-05 12:35:52,109 INFO org.apache.hadoop.yarn.server.resourcemanager.rmcontainer.RMContainerImpl: container_1399292339232_0002_01_000015 Container Transitioned from ALLOCATED to ACQUIRED
2014-05-05 12:35:52,109 INFO org.apache.hadoop.yarn.server.resourcemanager.rmcontainer.RMContainerImpl: container_1399292339232_0002_01_000016 Container Transitioned from ALLOCATED to ACQUIRED
2014-05-05 12:35:52,113 INFO org.apache.hadoop.yarn.server.resourcemanager.rmcontainer.RMContainerImpl: container_1399292339232_0002_01_000017 Container Transitioned from NEW to ALLOCATED
2014-05-05 12:35:52,113 INFO org.apache.hadoop.yarn.server.resourcemanager.RMAuditLogger: USER=ubuntu	OPERATION=AM Allocated Container	TARGET=SchedulerApp	RESULT=SUCCESS	APPID=application_1399292339232_0002	CONTAINERID=container_1399292339232_0002_01_000017
2014-05-05 12:35:52,113 INFO org.apache.hadoop.yarn.server.resourcemanager.scheduler.common.fica.FiCaSchedulerNode: Assigned container container_1399292339232_0002_01_000017 of capacity <memory:1024, vCores:1> on host nodeg:56763, which currently has 2 containers, <memory:2048, vCores:2> used and <memory:6144, vCores:6> available
2014-05-05 12:35:52,114 INFO org.apache.hadoop.yarn.server.resourcemanager.scheduler.capacity.LeafQueue: assignedContainer application=application_1399292339232_0002 container=Container: [ContainerId: container_1399292339232_0002_01_000017, NodeId: nodeg:56763, NodeHttpAddress: nodeg:8042, Resource: <memory:1024, vCores:1>, Priority: 10, Token: Token { kind: ContainerToken, service: 10.0.0.196:56763 }, ] containerId=container_1399292339232_0002_01_000017 queue=default: capacity=1.0, absoluteCapacity=1.0, usedResources=<memory:5120, vCores:4>usedCapacity=0.078125, absoluteUsedCapacity=0.078125, numApps=1, numContainers=4 usedCapacity=0.078125 absoluteUsedCapacity=0.078125 used=<memory:5120, vCores:4> cluster=<memory:65536, vCores:64>
2014-05-05 12:35:52,114 INFO org.apache.hadoop.yarn.server.resourcemanager.scheduler.capacity.ParentQueue: Re-sorting assigned queue: root.default stats: default: capacity=1.0, absoluteCapacity=1.0, usedResources=<memory:6144, vCores:5>usedCapacity=0.09375, absoluteUsedCapacity=0.09375, numApps=1, numContainers=5
2014-05-05 12:35:52,114 INFO org.apache.hadoop.yarn.server.resourcemanager.scheduler.capacity.ParentQueue: assignedContainer queue=root usedCapacity=0.09375 absoluteUsedCapacity=0.09375 used=<memory:6144, vCores:5> cluster=<memory:65536, vCores:64>
2014-05-05 12:35:52,117 INFO org.apache.hadoop.yarn.server.resourcemanager.rmcontainer.RMContainerImpl: container_1399292339232_0002_01_000018 Container Transitioned from NEW to ALLOCATED
2014-05-05 12:35:52,118 INFO org.apache.hadoop.yarn.server.resourcemanager.RMAuditLogger: USER=ubuntu	OPERATION=AM Allocated Container	TARGET=SchedulerApp	RESULT=SUCCESS	APPID=application_1399292339232_0002	CONTAINERID=container_1399292339232_0002_01_000018
2014-05-05 12:35:52,118 INFO org.apache.hadoop.yarn.server.resourcemanager.scheduler.common.fica.FiCaSchedulerNode: Assigned container container_1399292339232_0002_01_000018 of capacity <memory:1024, vCores:1> on host nodee:49598, which currently has 2 containers, <memory:2048, vCores:2> used and <memory:6144, vCores:6> available
2014-05-05 12:35:52,118 INFO org.apache.hadoop.yarn.server.resourcemanager.scheduler.capacity.LeafQueue: assignedContainer application=application_1399292339232_0002 container=Container: [ContainerId: container_1399292339232_0002_01_000018, NodeId: nodee:49598, NodeHttpAddress: nodee:8042, Resource: <memory:1024, vCores:1>, Priority: 10, Token: Token { kind: ContainerToken, service: 10.0.0.198:49598 }, ] containerId=container_1399292339232_0002_01_000018 queue=default: capacity=1.0, absoluteCapacity=1.0, usedResources=<memory:6144, vCores:5>usedCapacity=0.09375, absoluteUsedCapacity=0.09375, numApps=1, numContainers=5 usedCapacity=0.09375 absoluteUsedCapacity=0.09375 used=<memory:6144, vCores:5> cluster=<memory:65536, vCores:64>
2014-05-05 12:35:52,118 INFO org.apache.hadoop.yarn.server.resourcemanager.scheduler.capacity.ParentQueue: Re-sorting assigned queue: root.default stats: default: capacity=1.0, absoluteCapacity=1.0, usedResources=<memory:7168, vCores:6>usedCapacity=0.109375, absoluteUsedCapacity=0.109375, numApps=1, numContainers=6
2014-05-05 12:35:52,118 INFO org.apache.hadoop.yarn.server.resourcemanager.scheduler.capacity.ParentQueue: assignedContainer queue=root usedCapacity=0.109375 absoluteUsedCapacity=0.109375 used=<memory:7168, vCores:6> cluster=<memory:65536, vCores:64>
2014-05-05 12:35:52,126 INFO org.apache.hadoop.yarn.server.resourcemanager.rmcontainer.RMContainerImpl: container_1399292339232_0002_01_000019 Container Transitioned from NEW to ALLOCATED
2014-05-05 12:35:52,126 INFO org.apache.hadoop.yarn.server.resourcemanager.RMAuditLogger: USER=ubuntu	OPERATION=AM Allocated Container	TARGET=SchedulerApp	RESULT=SUCCESS	APPID=application_1399292339232_0002	CONTAINERID=container_1399292339232_0002_01_000019
2014-05-05 12:35:52,126 INFO org.apache.hadoop.yarn.server.resourcemanager.scheduler.common.fica.FiCaSchedulerNode: Assigned container container_1399292339232_0002_01_000019 of capacity <memory:1024, vCores:1> on host nodec:35478, which currently has 1 containers, <memory:1024, vCores:1> used and <memory:7168, vCores:7> available
2014-05-05 12:35:52,127 INFO org.apache.hadoop.yarn.server.resourcemanager.scheduler.capacity.LeafQueue: assignedContainer application=application_1399292339232_0002 container=Container: [ContainerId: container_1399292339232_0002_01_000019, NodeId: nodec:35478, NodeHttpAddress: nodec:8042, Resource: <memory:1024, vCores:1>, Priority: 10, Token: Token { kind: ContainerToken, service: 10.0.0.200:35478 }, ] containerId=container_1399292339232_0002_01_000019 queue=default: capacity=1.0, absoluteCapacity=1.0, usedResources=<memory:7168, vCores:6>usedCapacity=0.109375, absoluteUsedCapacity=0.109375, numApps=1, numContainers=6 usedCapacity=0.109375 absoluteUsedCapacity=0.109375 used=<memory:7168, vCores:6> cluster=<memory:65536, vCores:64>
2014-05-05 12:35:52,127 INFO org.apache.hadoop.yarn.server.resourcemanager.scheduler.capacity.ParentQueue: Re-sorting assigned queue: root.default stats: default: capacity=1.0, absoluteCapacity=1.0, usedResources=<memory:8192, vCores:7>usedCapacity=0.125, absoluteUsedCapacity=0.125, numApps=1, numContainers=7
2014-05-05 12:35:52,127 INFO org.apache.hadoop.yarn.server.resourcemanager.scheduler.capacity.ParentQueue: assignedContainer queue=root usedCapacity=0.125 absoluteUsedCapacity=0.125 used=<memory:8192, vCores:7> cluster=<memory:65536, vCores:64>
2014-05-05 12:35:52,914 INFO org.apache.hadoop.yarn.server.resourcemanager.rmcontainer.RMContainerImpl: container_1399292339232_0002_01_000020 Container Transitioned from NEW to ALLOCATED
2014-05-05 12:35:52,914 INFO org.apache.hadoop.yarn.server.resourcemanager.RMAuditLogger: USER=ubuntu	OPERATION=AM Allocated Container	TARGET=SchedulerApp	RESULT=SUCCESS	APPID=application_1399292339232_0002	CONTAINERID=container_1399292339232_0002_01_000020
2014-05-05 12:35:52,914 INFO org.apache.hadoop.yarn.server.resourcemanager.scheduler.common.fica.FiCaSchedulerNode: Assigned container container_1399292339232_0002_01_000020 of capacity <memory:1024, vCores:1> on host nodeb:48885, which currently has 2 containers, <memory:2048, vCores:2> used and <memory:6144, vCores:6> available
2014-05-05 12:35:52,914 INFO org.apache.hadoop.yarn.server.resourcemanager.scheduler.capacity.LeafQueue: assignedContainer application=application_1399292339232_0002 container=Container: [ContainerId: container_1399292339232_0002_01_000020, NodeId: nodeb:48885, NodeHttpAddress: nodeb:8042, Resource: <memory:1024, vCores:1>, Priority: 10, Token: Token { kind: ContainerToken, service: 10.0.0.194:48885 }, ] containerId=container_1399292339232_0002_01_000020 queue=default: capacity=1.0, absoluteCapacity=1.0, usedResources=<memory:8192, vCores:7>usedCapacity=0.125, absoluteUsedCapacity=0.125, numApps=1, numContainers=7 usedCapacity=0.125 absoluteUsedCapacity=0.125 used=<memory:8192, vCores:7> cluster=<memory:65536, vCores:64>
2014-05-05 12:35:52,914 INFO org.apache.hadoop.yarn.server.resourcemanager.scheduler.capacity.ParentQueue: Re-sorting assigned queue: root.default stats: default: capacity=1.0, absoluteCapacity=1.0, usedResources=<memory:9216, vCores:8>usedCapacity=0.140625, absoluteUsedCapacity=0.140625, numApps=1, numContainers=8
2014-05-05 12:35:52,914 INFO org.apache.hadoop.yarn.server.resourcemanager.scheduler.capacity.ParentQueue: assignedContainer queue=root usedCapacity=0.140625 absoluteUsedCapacity=0.140625 used=<memory:9216, vCores:8> cluster=<memory:65536, vCores:64>
2014-05-05 12:35:53,043 INFO org.apache.hadoop.yarn.server.resourcemanager.rmcontainer.RMContainerImpl: container_1399292339232_0002_01_000021 Container Transitioned from NEW to ALLOCATED
2014-05-05 12:35:53,044 INFO org.apache.hadoop.yarn.server.resourcemanager.RMAuditLogger: USER=ubuntu	OPERATION=AM Allocated Container	TARGET=SchedulerApp	RESULT=SUCCESS	APPID=application_1399292339232_0002	CONTAINERID=container_1399292339232_0002_01_000021
2014-05-05 12:35:53,044 INFO org.apache.hadoop.yarn.server.resourcemanager.scheduler.common.fica.FiCaSchedulerNode: Assigned container container_1399292339232_0002_01_000021 of capacity <memory:1024, vCores:1> on host noded:39305, which currently has 2 containers, <memory:3072, vCores:2> used and <memory:5120, vCores:6> available
2014-05-05 12:35:53,044 INFO org.apache.hadoop.yarn.server.resourcemanager.scheduler.capacity.LeafQueue: assignedContainer application=application_1399292339232_0002 container=Container: [ContainerId: container_1399292339232_0002_01_000021, NodeId: noded:39305, NodeHttpAddress: noded:8042, Resource: <memory:1024, vCores:1>, Priority: 10, Token: Token { kind: ContainerToken, service: 10.0.0.193:39305 }, ] containerId=container_1399292339232_0002_01_000021 queue=default: capacity=1.0, absoluteCapacity=1.0, usedResources=<memory:9216, vCores:8>usedCapacity=0.140625, absoluteUsedCapacity=0.140625, numApps=1, numContainers=8 usedCapacity=0.140625 absoluteUsedCapacity=0.140625 used=<memory:9216, vCores:8> cluster=<memory:65536, vCores:64>
2014-05-05 12:35:53,044 INFO org.apache.hadoop.yarn.server.resourcemanager.scheduler.capacity.ParentQueue: Re-sorting assigned queue: root.default stats: default: capacity=1.0, absoluteCapacity=1.0, usedResources=<memory:10240, vCores:9>usedCapacity=0.15625, absoluteUsedCapacity=0.15625, numApps=1, numContainers=9
2014-05-05 12:35:53,044 INFO org.apache.hadoop.yarn.server.resourcemanager.scheduler.capacity.ParentQueue: assignedContainer queue=root usedCapacity=0.15625 absoluteUsedCapacity=0.15625 used=<memory:10240, vCores:9> cluster=<memory:65536, vCores:64>
2014-05-05 12:35:53,051 INFO org.apache.hadoop.yarn.server.resourcemanager.rmcontainer.RMContainerImpl: container_1399292339232_0002_01_000022 Container Transitioned from NEW to ALLOCATED
2014-05-05 12:35:53,051 INFO org.apache.hadoop.yarn.server.resourcemanager.RMAuditLogger: USER=ubuntu	OPERATION=AM Allocated Container	TARGET=SchedulerApp	RESULT=SUCCESS	APPID=application_1399292339232_0002	CONTAINERID=container_1399292339232_0002_01_000022
2014-05-05 12:35:53,051 INFO org.apache.hadoop.yarn.server.resourcemanager.scheduler.common.fica.FiCaSchedulerNode: Assigned container container_1399292339232_0002_01_000022 of capacity <memory:1024, vCores:1> on host nodea:51924, which currently has 1 containers, <memory:1024, vCores:1> used and <memory:7168, vCores:7> available
2014-05-05 12:35:53,051 INFO org.apache.hadoop.yarn.server.resourcemanager.scheduler.capacity.LeafQueue: assignedContainer application=application_1399292339232_0002 container=Container: [ContainerId: container_1399292339232_0002_01_000022, NodeId: nodea:51924, NodeHttpAddress: nodea:8042, Resource: <memory:1024, vCores:1>, Priority: 10, Token: Token { kind: ContainerToken, service: 10.0.0.195:51924 }, ] containerId=container_1399292339232_0002_01_000022 queue=default: capacity=1.0, absoluteCapacity=1.0, usedResources=<memory:10240, vCores:9>usedCapacity=0.15625, absoluteUsedCapacity=0.15625, numApps=1, numContainers=9 usedCapacity=0.15625 absoluteUsedCapacity=0.15625 used=<memory:10240, vCores:9> cluster=<memory:65536, vCores:64>
2014-05-05 12:35:53,052 INFO org.apache.hadoop.yarn.server.resourcemanager.scheduler.capacity.ParentQueue: Re-sorting assigned queue: root.default stats: default: capacity=1.0, absoluteCapacity=1.0, usedResources=<memory:11264, vCores:10>usedCapacity=0.171875, absoluteUsedCapacity=0.171875, numApps=1, numContainers=10
2014-05-05 12:35:53,052 INFO org.apache.hadoop.yarn.server.resourcemanager.scheduler.capacity.ParentQueue: assignedContainer queue=root usedCapacity=0.171875 absoluteUsedCapacity=0.171875 used=<memory:11264, vCores:10> cluster=<memory:65536, vCores:64>
2014-05-05 12:35:53,098 INFO org.apache.hadoop.yarn.server.resourcemanager.rmcontainer.RMContainerImpl: container_1399292339232_0002_01_000023 Container Transitioned from NEW to ALLOCATED
2014-05-05 12:35:53,099 INFO org.apache.hadoop.yarn.server.resourcemanager.RMAuditLogger: USER=ubuntu	OPERATION=AM Allocated Container	TARGET=SchedulerApp	RESULT=SUCCESS	APPID=application_1399292339232_0002	CONTAINERID=container_1399292339232_0002_01_000023
2014-05-05 12:35:53,099 INFO org.apache.hadoop.yarn.server.resourcemanager.scheduler.common.fica.FiCaSchedulerNode: Assigned container container_1399292339232_0002_01_000023 of capacity <memory:1024, vCores:1> on host nodeh:46599, which currently has 1 containers, <memory:1024, vCores:1> used and <memory:7168, vCores:7> available
2014-05-05 12:35:53,099 INFO org.apache.hadoop.yarn.server.resourcemanager.scheduler.capacity.LeafQueue: assignedContainer application=application_1399292339232_0002 container=Container: [ContainerId: container_1399292339232_0002_01_000023, NodeId: nodeh:46599, NodeHttpAddress: nodeh:8042, Resource: <memory:1024, vCores:1>, Priority: 10, Token: Token { kind: ContainerToken, service: 10.0.0.197:46599 }, ] containerId=container_1399292339232_0002_01_000023 queue=default: capacity=1.0, absoluteCapacity=1.0, usedResources=<memory:11264, vCores:10>usedCapacity=0.171875, absoluteUsedCapacity=0.171875, numApps=1, numContainers=10 usedCapacity=0.171875 absoluteUsedCapacity=0.171875 used=<memory:11264, vCores:10> cluster=<memory:65536, vCores:64>
2014-05-05 12:35:53,099 INFO org.apache.hadoop.yarn.server.resourcemanager.scheduler.capacity.ParentQueue: Re-sorting assigned queue: root.default stats: default: capacity=1.0, absoluteCapacity=1.0, usedResources=<memory:12288, vCores:11>usedCapacity=0.1875, absoluteUsedCapacity=0.1875, numApps=1, numContainers=11
2014-05-05 12:35:53,099 INFO org.apache.hadoop.yarn.server.resourcemanager.scheduler.capacity.ParentQueue: assignedContainer queue=root usedCapacity=0.1875 absoluteUsedCapacity=0.1875 used=<memory:12288, vCores:11> cluster=<memory:65536, vCores:64>
2014-05-05 12:35:53,113 INFO org.apache.hadoop.yarn.server.resourcemanager.rmcontainer.RMContainerImpl: container_1399292339232_0002_01_000017 Container Transitioned from ALLOCATED to ACQUIRED
2014-05-05 12:35:53,114 INFO org.apache.hadoop.yarn.server.resourcemanager.rmcontainer.RMContainerImpl: container_1399292339232_0002_01_000018 Container Transitioned from ALLOCATED to ACQUIRED
2014-05-05 12:35:53,114 INFO org.apache.hadoop.yarn.server.resourcemanager.rmcontainer.RMContainerImpl: container_1399292339232_0002_01_000019 Container Transitioned from ALLOCATED to ACQUIRED
2014-05-05 12:35:53,115 INFO org.apache.hadoop.yarn.server.resourcemanager.rmcontainer.RMContainerImpl: container_1399292339232_0002_01_000020 Container Transitioned from ALLOCATED to ACQUIRED
2014-05-05 12:35:53,115 INFO org.apache.hadoop.yarn.server.resourcemanager.rmcontainer.RMContainerImpl: container_1399292339232_0002_01_000021 Container Transitioned from ALLOCATED to ACQUIRED
2014-05-05 12:35:53,115 INFO org.apache.hadoop.yarn.server.resourcemanager.rmcontainer.RMContainerImpl: container_1399292339232_0002_01_000022 Container Transitioned from ALLOCATED to ACQUIRED
2014-05-05 12:35:53,115 INFO org.apache.hadoop.yarn.server.resourcemanager.rmcontainer.RMContainerImpl: container_1399292339232_0002_01_000023 Container Transitioned from ALLOCATED to ACQUIRED
2014-05-05 12:35:53,116 INFO org.apache.hadoop.yarn.server.resourcemanager.rmcontainer.RMContainerImpl: container_1399292339232_0002_01_000015 Container Transitioned from ACQUIRED to RUNNING
2014-05-05 12:35:53,117 INFO org.apache.hadoop.yarn.server.resourcemanager.rmcontainer.RMContainerImpl: container_1399292339232_0002_01_000024 Container Transitioned from NEW to ALLOCATED
2014-05-05 12:35:53,117 INFO org.apache.hadoop.yarn.server.resourcemanager.RMAuditLogger: USER=ubuntu	OPERATION=AM Allocated Container	TARGET=SchedulerApp	RESULT=SUCCESS	APPID=application_1399292339232_0002	CONTAINERID=container_1399292339232_0002_01_000024
2014-05-05 12:35:53,117 INFO org.apache.hadoop.yarn.server.resourcemanager.scheduler.common.fica.FiCaSchedulerNode: Assigned container container_1399292339232_0002_01_000024 of capacity <memory:1024, vCores:1> on host nodeg:56763, which currently has 3 containers, <memory:3072, vCores:3> used and <memory:5120, vCores:5> available
2014-05-05 12:35:53,117 INFO org.apache.hadoop.yarn.server.resourcemanager.scheduler.capacity.LeafQueue: assignedContainer application=application_1399292339232_0002 container=Container: [ContainerId: container_1399292339232_0002_01_000024, NodeId: nodeg:56763, NodeHttpAddress: nodeg:8042, Resource: <memory:1024, vCores:1>, Priority: 10, Token: Token { kind: ContainerToken, service: 10.0.0.196:56763 }, ] containerId=container_1399292339232_0002_01_000024 queue=default: capacity=1.0, absoluteCapacity=1.0, usedResources=<memory:12288, vCores:11>usedCapacity=0.1875, absoluteUsedCapacity=0.1875, numApps=1, numContainers=11 usedCapacity=0.1875 absoluteUsedCapacity=0.1875 used=<memory:12288, vCores:11> cluster=<memory:65536, vCores:64>
2014-05-05 12:35:53,117 INFO org.apache.hadoop.yarn.server.resourcemanager.scheduler.capacity.ParentQueue: Re-sorting assigned queue: root.default stats: default: capacity=1.0, absoluteCapacity=1.0, usedResources=<memory:13312, vCores:12>usedCapacity=0.203125, absoluteUsedCapacity=0.203125, numApps=1, numContainers=12
2014-05-05 12:35:53,117 INFO org.apache.hadoop.yarn.server.resourcemanager.scheduler.capacity.ParentQueue: assignedContainer queue=root usedCapacity=0.203125 absoluteUsedCapacity=0.203125 used=<memory:13312, vCores:12> cluster=<memory:65536, vCores:64>
2014-05-05 12:35:53,119 INFO org.apache.hadoop.yarn.server.resourcemanager.rmcontainer.RMContainerImpl: container_1399292339232_0002_01_000016 Container Transitioned from ACQUIRED to RUNNING
2014-05-05 12:35:53,120 INFO org.apache.hadoop.yarn.server.resourcemanager.rmcontainer.RMContainerImpl: container_1399292339232_0002_01_000025 Container Transitioned from NEW to ALLOCATED
2014-05-05 12:35:53,120 INFO org.apache.hadoop.yarn.server.resourcemanager.RMAuditLogger: USER=ubuntu	OPERATION=AM Allocated Container	TARGET=SchedulerApp	RESULT=SUCCESS	APPID=application_1399292339232_0002	CONTAINERID=container_1399292339232_0002_01_000025
2014-05-05 12:35:53,120 INFO org.apache.hadoop.yarn.server.resourcemanager.scheduler.common.fica.FiCaSchedulerNode: Assigned container container_1399292339232_0002_01_000025 of capacity <memory:1024, vCores:1> on host nodee:49598, which currently has 3 containers, <memory:3072, vCores:3> used and <memory:5120, vCores:5> available
2014-05-05 12:35:53,120 INFO org.apache.hadoop.yarn.server.resourcemanager.scheduler.capacity.LeafQueue: assignedContainer application=application_1399292339232_0002 container=Container: [ContainerId: container_1399292339232_0002_01_000025, NodeId: nodee:49598, NodeHttpAddress: nodee:8042, Resource: <memory:1024, vCores:1>, Priority: 10, Token: Token { kind: ContainerToken, service: 10.0.0.198:49598 }, ] containerId=container_1399292339232_0002_01_000025 queue=default: capacity=1.0, absoluteCapacity=1.0, usedResources=<memory:13312, vCores:12>usedCapacity=0.203125, absoluteUsedCapacity=0.203125, numApps=1, numContainers=12 usedCapacity=0.203125 absoluteUsedCapacity=0.203125 used=<memory:13312, vCores:12> cluster=<memory:65536, vCores:64>
2014-05-05 12:35:53,120 INFO org.apache.hadoop.yarn.server.resourcemanager.scheduler.capacity.ParentQueue: Re-sorting assigned queue: root.default stats: default: capacity=1.0, absoluteCapacity=1.0, usedResources=<memory:14336, vCores:13>usedCapacity=0.21875, absoluteUsedCapacity=0.21875, numApps=1, numContainers=13
2014-05-05 12:35:53,120 INFO org.apache.hadoop.yarn.server.resourcemanager.scheduler.capacity.ParentQueue: assignedContainer queue=root usedCapacity=0.21875 absoluteUsedCapacity=0.21875 used=<memory:14336, vCores:13> cluster=<memory:65536, vCores:64>
2014-05-05 12:35:53,128 INFO org.apache.hadoop.yarn.server.resourcemanager.rmcontainer.RMContainerImpl: container_1399292339232_0002_01_000026 Container Transitioned from NEW to ALLOCATED
2014-05-05 12:35:53,128 INFO org.apache.hadoop.yarn.server.resourcemanager.RMAuditLogger: USER=ubuntu	OPERATION=AM Allocated Container	TARGET=SchedulerApp	RESULT=SUCCESS	APPID=application_1399292339232_0002	CONTAINERID=container_1399292339232_0002_01_000026
2014-05-05 12:35:53,128 INFO org.apache.hadoop.yarn.server.resourcemanager.scheduler.common.fica.FiCaSchedulerNode: Assigned container container_1399292339232_0002_01_000026 of capacity <memory:1024, vCores:1> on host nodec:35478, which currently has 2 containers, <memory:2048, vCores:2> used and <memory:6144, vCores:6> available
2014-05-05 12:35:53,128 INFO org.apache.hadoop.yarn.server.resourcemanager.scheduler.capacity.LeafQueue: assignedContainer application=application_1399292339232_0002 container=Container: [ContainerId: container_1399292339232_0002_01_000026, NodeId: nodec:35478, NodeHttpAddress: nodec:8042, Resource: <memory:1024, vCores:1>, Priority: 10, Token: Token { kind: ContainerToken, service: 10.0.0.200:35478 }, ] containerId=container_1399292339232_0002_01_000026 queue=default: capacity=1.0, absoluteCapacity=1.0, usedResources=<memory:14336, vCores:13>usedCapacity=0.21875, absoluteUsedCapacity=0.21875, numApps=1, numContainers=13 usedCapacity=0.21875 absoluteUsedCapacity=0.21875 used=<memory:14336, vCores:13> cluster=<memory:65536, vCores:64>
2014-05-05 12:35:53,128 INFO org.apache.hadoop.yarn.server.resourcemanager.scheduler.capacity.ParentQueue: Re-sorting assigned queue: root.default stats: default: capacity=1.0, absoluteCapacity=1.0, usedResources=<memory:15360, vCores:14>usedCapacity=0.234375, absoluteUsedCapacity=0.234375, numApps=1, numContainers=14
2014-05-05 12:35:53,128 INFO org.apache.hadoop.yarn.server.resourcemanager.scheduler.capacity.ParentQueue: assignedContainer queue=root usedCapacity=0.234375 absoluteUsedCapacity=0.234375 used=<memory:15360, vCores:14> cluster=<memory:65536, vCores:64>
2014-05-05 12:35:53,917 INFO org.apache.hadoop.yarn.server.resourcemanager.rmcontainer.RMContainerImpl: container_1399292339232_0002_01_000020 Container Transitioned from ACQUIRED to RUNNING
2014-05-05 12:35:53,917 INFO org.apache.hadoop.yarn.server.resourcemanager.rmcontainer.RMContainerImpl: container_1399292339232_0002_01_000027 Container Transitioned from NEW to ALLOCATED
2014-05-05 12:35:53,917 INFO org.apache.hadoop.yarn.server.resourcemanager.RMAuditLogger: USER=ubuntu	OPERATION=AM Allocated Container	TARGET=SchedulerApp	RESULT=SUCCESS	APPID=application_1399292339232_0002	CONTAINERID=container_1399292339232_0002_01_000027
2014-05-05 12:35:53,917 INFO org.apache.hadoop.yarn.server.resourcemanager.scheduler.common.fica.FiCaSchedulerNode: Assigned container container_1399292339232_0002_01_000027 of capacity <memory:1024, vCores:1> on host nodeb:48885, which currently has 3 containers, <memory:3072, vCores:3> used and <memory:5120, vCores:5> available
2014-05-05 12:35:53,917 INFO org.apache.hadoop.yarn.server.resourcemanager.scheduler.capacity.LeafQueue: assignedContainer application=application_1399292339232_0002 container=Container: [ContainerId: container_1399292339232_0002_01_000027, NodeId: nodeb:48885, NodeHttpAddress: nodeb:8042, Resource: <memory:1024, vCores:1>, Priority: 10, Token: Token { kind: ContainerToken, service: 10.0.0.194:48885 }, ] containerId=container_1399292339232_0002_01_000027 queue=default: capacity=1.0, absoluteCapacity=1.0, usedResources=<memory:15360, vCores:14>usedCapacity=0.234375, absoluteUsedCapacity=0.234375, numApps=1, numContainers=14 usedCapacity=0.234375 absoluteUsedCapacity=0.234375 used=<memory:15360, vCores:14> cluster=<memory:65536, vCores:64>
2014-05-05 12:35:53,918 INFO org.apache.hadoop.yarn.server.resourcemanager.scheduler.capacity.ParentQueue: Re-sorting assigned queue: root.default stats: default: capacity=1.0, absoluteCapacity=1.0, usedResources=<memory:16384, vCores:15>usedCapacity=0.25, absoluteUsedCapacity=0.25, numApps=1, numContainers=15
2014-05-05 12:35:53,918 INFO org.apache.hadoop.yarn.server.resourcemanager.scheduler.capacity.ParentQueue: assignedContainer queue=root usedCapacity=0.25 absoluteUsedCapacity=0.25 used=<memory:16384, vCores:15> cluster=<memory:65536, vCores:64>
2014-05-05 12:35:54,046 INFO org.apache.hadoop.yarn.server.resourcemanager.rmcontainer.RMContainerImpl: container_1399292339232_0002_01_000021 Container Transitioned from ACQUIRED to RUNNING
2014-05-05 12:35:54,047 INFO org.apache.hadoop.yarn.server.resourcemanager.rmcontainer.RMContainerImpl: container_1399292339232_0002_01_000028 Container Transitioned from NEW to ALLOCATED
2014-05-05 12:35:54,047 INFO org.apache.hadoop.yarn.server.resourcemanager.RMAuditLogger: USER=ubuntu	OPERATION=AM Allocated Container	TARGET=SchedulerApp	RESULT=SUCCESS	APPID=application_1399292339232_0002	CONTAINERID=container_1399292339232_0002_01_000028
2014-05-05 12:35:54,047 INFO org.apache.hadoop.yarn.server.resourcemanager.scheduler.common.fica.FiCaSchedulerNode: Assigned container container_1399292339232_0002_01_000028 of capacity <memory:1024, vCores:1> on host noded:39305, which currently has 3 containers, <memory:4096, vCores:3> used and <memory:4096, vCores:5> available
2014-05-05 12:35:54,047 INFO org.apache.hadoop.yarn.server.resourcemanager.scheduler.capacity.LeafQueue: assignedContainer application=application_1399292339232_0002 container=Container: [ContainerId: container_1399292339232_0002_01_000028, NodeId: noded:39305, NodeHttpAddress: noded:8042, Resource: <memory:1024, vCores:1>, Priority: 10, Token: Token { kind: ContainerToken, service: 10.0.0.193:39305 }, ] containerId=container_1399292339232_0002_01_000028 queue=default: capacity=1.0, absoluteCapacity=1.0, usedResources=<memory:16384, vCores:15>usedCapacity=0.25, absoluteUsedCapacity=0.25, numApps=1, numContainers=15 usedCapacity=0.25 absoluteUsedCapacity=0.25 used=<memory:16384, vCores:15> cluster=<memory:65536, vCores:64>
2014-05-05 12:35:54,047 INFO org.apache.hadoop.yarn.server.resourcemanager.scheduler.capacity.ParentQueue: Re-sorting assigned queue: root.default stats: default: capacity=1.0, absoluteCapacity=1.0, usedResources=<memory:17408, vCores:16>usedCapacity=0.265625, absoluteUsedCapacity=0.265625, numApps=1, numContainers=16
2014-05-05 12:35:54,047 INFO org.apache.hadoop.yarn.server.resourcemanager.scheduler.capacity.ParentQueue: assignedContainer queue=root usedCapacity=0.265625 absoluteUsedCapacity=0.265625 used=<memory:17408, vCores:16> cluster=<memory:65536, vCores:64>
2014-05-05 12:35:54,118 INFO org.apache.hadoop.yarn.server.resourcemanager.rmcontainer.RMContainerImpl: container_1399292339232_0002_01_000017 Container Transitioned from ACQUIRED to RUNNING
2014-05-05 12:35:54,122 INFO org.apache.hadoop.yarn.server.resourcemanager.rmcontainer.RMContainerImpl: container_1399292339232_0002_01_000022 Container Transitioned from ACQUIRED to RELEASED
2014-05-05 12:35:54,123 INFO org.apache.hadoop.yarn.server.resourcemanager.scheduler.common.fica.FiCaSchedulerApp: Completed container: container_1399292339232_0002_01_000022 in state: RELEASED event:RELEASED
2014-05-05 12:35:54,123 INFO org.apache.hadoop.yarn.server.resourcemanager.RMAuditLogger: USER=ubuntu	IP=10.0.0.193	OPERATION=AM Released Container	TARGET=SchedulerApp	RESULT=SUCCESS	APPID=application_1399292339232_0002	CONTAINERID=container_1399292339232_0002_01_000022
2014-05-05 12:35:54,123 INFO org.apache.hadoop.yarn.server.resourcemanager.scheduler.common.fica.FiCaSchedulerNode: Released container container_1399292339232_0002_01_000022 of capacity <memory:1024, vCores:1> on host nodea:51924, which currently has 0 containers, <memory:0, vCores:0> used and <memory:8192, vCores:8> available, release resources=true
2014-05-05 12:35:54,124 INFO org.apache.hadoop.yarn.server.resourcemanager.scheduler.capacity.LeafQueue: default used=<memory:16384, vCores:15> numContainers=15 user=ubuntu user-resources=<memory:16384, vCores:15>
2014-05-05 12:35:54,124 INFO org.apache.hadoop.yarn.server.resourcemanager.scheduler.capacity.LeafQueue: completedContainer container=Container: [ContainerId: container_1399292339232_0002_01_000022, NodeId: nodea:51924, NodeHttpAddress: nodea:8042, Resource: <memory:1024, vCores:1>, Priority: 10, Token: Token { kind: ContainerToken, service: 10.0.0.195:51924 }, ] resource=<memory:1024, vCores:1> queue=default: capacity=1.0, absoluteCapacity=1.0, usedResources=<memory:16384, vCores:15>usedCapacity=0.25, absoluteUsedCapacity=0.25, numApps=1, numContainers=15 usedCapacity=0.25 absoluteUsedCapacity=0.25 used=<memory:16384, vCores:15> cluster=<memory:65536, vCores:64>
2014-05-05 12:35:54,124 INFO org.apache.hadoop.yarn.server.resourcemanager.scheduler.capacity.ParentQueue: completedContainer queue=root usedCapacity=0.25 absoluteUsedCapacity=0.25 used=<memory:16384, vCores:15> cluster=<memory:65536, vCores:64>
2014-05-05 12:35:54,124 INFO org.apache.hadoop.yarn.server.resourcemanager.scheduler.capacity.ParentQueue: Re-sorting completed queue: root.default stats: default: capacity=1.0, absoluteCapacity=1.0, usedResources=<memory:16384, vCores:15>usedCapacity=0.25, absoluteUsedCapacity=0.25, numApps=1, numContainers=15
2014-05-05 12:35:54,124 INFO org.apache.hadoop.yarn.server.resourcemanager.scheduler.capacity.CapacityScheduler: Application appattempt_1399292339232_0002_000001 released container container_1399292339232_0002_01_000022 on node: host: nodea:51924 #containers=0 available=8192 used=0 with event: RELEASED
2014-05-05 12:35:54,124 INFO org.apache.hadoop.yarn.server.resourcemanager.rmcontainer.RMContainerImpl: container_1399292339232_0002_01_000018 Container Transitioned from ACQUIRED to RUNNING
2014-05-05 12:35:54,125 INFO org.apache.hadoop.yarn.server.resourcemanager.rmcontainer.RMContainerImpl: container_1399292339232_0002_01_000023 Container Transitioned from ACQUIRED to RELEASED
2014-05-05 12:35:54,125 INFO org.apache.hadoop.yarn.server.resourcemanager.scheduler.common.fica.FiCaSchedulerApp: Completed container: container_1399292339232_0002_01_000023 in state: RELEASED event:RELEASED
2014-05-05 12:35:54,125 INFO org.apache.hadoop.yarn.server.resourcemanager.RMAuditLogger: USER=ubuntu	IP=10.0.0.193	OPERATION=AM Released Container	TARGET=SchedulerApp	RESULT=SUCCESS	APPID=application_1399292339232_0002	CONTAINERID=container_1399292339232_0002_01_000023
2014-05-05 12:35:54,125 INFO org.apache.hadoop.yarn.server.resourcemanager.scheduler.common.fica.FiCaSchedulerNode: Released container container_1399292339232_0002_01_000023 of capacity <memory:1024, vCores:1> on host nodeh:46599, which currently has 0 containers, <memory:0, vCores:0> used and <memory:8192, vCores:8> available, release resources=true
2014-05-05 12:35:54,125 INFO org.apache.hadoop.yarn.server.resourcemanager.scheduler.capacity.LeafQueue: default used=<memory:15360, vCores:14> numContainers=14 user=ubuntu user-resources=<memory:15360, vCores:14>
2014-05-05 12:35:54,125 INFO org.apache.hadoop.yarn.server.resourcemanager.scheduler.capacity.LeafQueue: completedContainer container=Container: [ContainerId: container_1399292339232_0002_01_000023, NodeId: nodeh:46599, NodeHttpAddress: nodeh:8042, Resource: <memory:1024, vCores:1>, Priority: 10, Token: Token { kind: ContainerToken, service: 10.0.0.197:46599 }, ] resource=<memory:1024, vCores:1> queue=default: capacity=1.0, absoluteCapacity=1.0, usedResources=<memory:15360, vCores:14>usedCapacity=0.234375, absoluteUsedCapacity=0.234375, numApps=1, numContainers=14 usedCapacity=0.234375 absoluteUsedCapacity=0.234375 used=<memory:15360, vCores:14> cluster=<memory:65536, vCores:64>
2014-05-05 12:35:54,125 INFO org.apache.hadoop.yarn.server.resourcemanager.scheduler.capacity.ParentQueue: completedContainer queue=root usedCapacity=0.234375 absoluteUsedCapacity=0.234375 used=<memory:15360, vCores:14> cluster=<memory:65536, vCores:64>
2014-05-05 12:35:54,125 INFO org.apache.hadoop.yarn.server.resourcemanager.scheduler.capacity.ParentQueue: Re-sorting completed queue: root.default stats: default: capacity=1.0, absoluteCapacity=1.0, usedResources=<memory:15360, vCores:14>usedCapacity=0.234375, absoluteUsedCapacity=0.234375, numApps=1, numContainers=14
2014-05-05 12:35:54,126 INFO org.apache.hadoop.yarn.server.resourcemanager.scheduler.capacity.CapacityScheduler: Application appattempt_1399292339232_0002_000001 released container container_1399292339232_0002_01_000023 on node: host: nodeh:46599 #containers=0 available=8192 used=0 with event: RELEASED
2014-05-05 12:35:54,126 INFO org.apache.hadoop.yarn.server.resourcemanager.scheduler.AppSchedulingInfo: checking for deactivate... 
2014-05-05 12:35:54,126 INFO org.apache.hadoop.yarn.server.resourcemanager.rmcontainer.RMContainerImpl: container_1399292339232_0002_01_000024 Container Transitioned from ALLOCATED to ACQUIRED
2014-05-05 12:35:54,126 INFO org.apache.hadoop.yarn.server.resourcemanager.rmcontainer.RMContainerImpl: container_1399292339232_0002_01_000025 Container Transitioned from ALLOCATED to ACQUIRED
2014-05-05 12:35:54,126 INFO org.apache.hadoop.yarn.server.resourcemanager.rmcontainer.RMContainerImpl: container_1399292339232_0002_01_000026 Container Transitioned from ALLOCATED to ACQUIRED
2014-05-05 12:35:54,127 INFO org.apache.hadoop.yarn.server.resourcemanager.rmcontainer.RMContainerImpl: container_1399292339232_0002_01_000027 Container Transitioned from ALLOCATED to ACQUIRED
2014-05-05 12:35:54,127 INFO org.apache.hadoop.yarn.server.resourcemanager.rmcontainer.RMContainerImpl: container_1399292339232_0002_01_000028 Container Transitioned from ALLOCATED to ACQUIRED
2014-05-05 12:35:54,130 INFO org.apache.hadoop.yarn.server.resourcemanager.rmcontainer.RMContainerImpl: container_1399292339232_0002_01_000019 Container Transitioned from ACQUIRED to RUNNING
2014-05-05 12:35:55,132 INFO org.apache.hadoop.yarn.server.resourcemanager.rmcontainer.RMContainerImpl: container_1399292339232_0002_01_000024 Container Transitioned from ACQUIRED to RELEASED
2014-05-05 12:35:55,132 INFO org.apache.hadoop.yarn.server.resourcemanager.scheduler.common.fica.FiCaSchedulerApp: Completed container: container_1399292339232_0002_01_000024 in state: RELEASED event:RELEASED
2014-05-05 12:35:55,132 INFO org.apache.hadoop.yarn.server.resourcemanager.RMAuditLogger: USER=ubuntu	IP=10.0.0.193	OPERATION=AM Released Container	TARGET=SchedulerApp	RESULT=SUCCESS	APPID=application_1399292339232_0002	CONTAINERID=container_1399292339232_0002_01_000024
2014-05-05 12:35:55,133 INFO org.apache.hadoop.yarn.server.resourcemanager.scheduler.common.fica.FiCaSchedulerNode: Released container container_1399292339232_0002_01_000024 of capacity <memory:1024, vCores:1> on host nodeg:56763, which currently has 2 containers, <memory:2048, vCores:2> used and <memory:6144, vCores:6> available, release resources=true
2014-05-05 12:35:55,133 INFO org.apache.hadoop.yarn.server.resourcemanager.scheduler.capacity.LeafQueue: default used=<memory:14336, vCores:13> numContainers=13 user=ubuntu user-resources=<memory:14336, vCores:13>
2014-05-05 12:35:55,133 INFO org.apache.hadoop.yarn.server.resourcemanager.scheduler.capacity.LeafQueue: completedContainer container=Container: [ContainerId: container_1399292339232_0002_01_000024, NodeId: nodeg:56763, NodeHttpAddress: nodeg:8042, Resource: <memory:1024, vCores:1>, Priority: 10, Token: Token { kind: ContainerToken, service: 10.0.0.196:56763 }, ] resource=<memory:1024, vCores:1> queue=default: capacity=1.0, absoluteCapacity=1.0, usedResources=<memory:14336, vCores:13>usedCapacity=0.21875, absoluteUsedCapacity=0.21875, numApps=1, numContainers=13 usedCapacity=0.21875 absoluteUsedCapacity=0.21875 used=<memory:14336, vCores:13> cluster=<memory:65536, vCores:64>
2014-05-05 12:35:55,133 INFO org.apache.hadoop.yarn.server.resourcemanager.scheduler.capacity.ParentQueue: completedContainer queue=root usedCapacity=0.21875 absoluteUsedCapacity=0.21875 used=<memory:14336, vCores:13> cluster=<memory:65536, vCores:64>
2014-05-05 12:35:55,133 INFO org.apache.hadoop.yarn.server.resourcemanager.scheduler.capacity.ParentQueue: Re-sorting completed queue: root.default stats: default: capacity=1.0, absoluteCapacity=1.0, usedResources=<memory:14336, vCores:13>usedCapacity=0.21875, absoluteUsedCapacity=0.21875, numApps=1, numContainers=13
2014-05-05 12:35:55,133 INFO org.apache.hadoop.yarn.server.resourcemanager.scheduler.capacity.CapacityScheduler: Application appattempt_1399292339232_0002_000001 released container container_1399292339232_0002_01_000024 on node: host: nodeg:56763 #containers=2 available=6144 used=2048 with event: RELEASED
2014-05-05 12:35:55,133 INFO org.apache.hadoop.yarn.server.resourcemanager.rmcontainer.RMContainerImpl: container_1399292339232_0002_01_000025 Container Transitioned from ACQUIRED to RELEASED
2014-05-05 12:35:55,133 INFO org.apache.hadoop.yarn.server.resourcemanager.scheduler.common.fica.FiCaSchedulerApp: Completed container: container_1399292339232_0002_01_000025 in state: RELEASED event:RELEASED
2014-05-05 12:35:55,133 INFO org.apache.hadoop.yarn.server.resourcemanager.RMAuditLogger: USER=ubuntu	IP=10.0.0.193	OPERATION=AM Released Container	TARGET=SchedulerApp	RESULT=SUCCESS	APPID=application_1399292339232_0002	CONTAINERID=container_1399292339232_0002_01_000025
2014-05-05 12:35:55,133 INFO org.apache.hadoop.yarn.server.resourcemanager.scheduler.common.fica.FiCaSchedulerNode: Released container container_1399292339232_0002_01_000025 of capacity <memory:1024, vCores:1> on host nodee:49598, which currently has 2 containers, <memory:2048, vCores:2> used and <memory:6144, vCores:6> available, release resources=true
2014-05-05 12:35:55,134 INFO org.apache.hadoop.yarn.server.resourcemanager.scheduler.capacity.LeafQueue: default used=<memory:13312, vCores:12> numContainers=12 user=ubuntu user-resources=<memory:13312, vCores:12>
2014-05-05 12:35:55,134 INFO org.apache.hadoop.yarn.server.resourcemanager.scheduler.capacity.LeafQueue: completedContainer container=Container: [ContainerId: container_1399292339232_0002_01_000025, NodeId: nodee:49598, NodeHttpAddress: nodee:8042, Resource: <memory:1024, vCores:1>, Priority: 10, Token: Token { kind: ContainerToken, service: 10.0.0.198:49598 }, ] resource=<memory:1024, vCores:1> queue=default: capacity=1.0, absoluteCapacity=1.0, usedResources=<memory:13312, vCores:12>usedCapacity=0.203125, absoluteUsedCapacity=0.203125, numApps=1, numContainers=12 usedCapacity=0.203125 absoluteUsedCapacity=0.203125 used=<memory:13312, vCores:12> cluster=<memory:65536, vCores:64>
2014-05-05 12:35:55,134 INFO org.apache.hadoop.yarn.server.resourcemanager.scheduler.capacity.ParentQueue: completedContainer queue=root usedCapacity=0.203125 absoluteUsedCapacity=0.203125 used=<memory:13312, vCores:12> cluster=<memory:65536, vCores:64>
2014-05-05 12:35:55,134 INFO org.apache.hadoop.yarn.server.resourcemanager.scheduler.capacity.ParentQueue: Re-sorting completed queue: root.default stats: default: capacity=1.0, absoluteCapacity=1.0, usedResources=<memory:13312, vCores:12>usedCapacity=0.203125, absoluteUsedCapacity=0.203125, numApps=1, numContainers=12
2014-05-05 12:35:55,134 INFO org.apache.hadoop.yarn.server.resourcemanager.scheduler.capacity.CapacityScheduler: Application appattempt_1399292339232_0002_000001 released container container_1399292339232_0002_01_000025 on node: host: nodee:49598 #containers=2 available=6144 used=2048 with event: RELEASED
2014-05-05 12:35:55,134 INFO org.apache.hadoop.yarn.server.resourcemanager.rmcontainer.RMContainerImpl: container_1399292339232_0002_01_000026 Container Transitioned from ACQUIRED to RELEASED
2014-05-05 12:35:55,134 INFO org.apache.hadoop.yarn.server.resourcemanager.scheduler.common.fica.FiCaSchedulerApp: Completed container: container_1399292339232_0002_01_000026 in state: RELEASED event:RELEASED
2014-05-05 12:35:55,134 INFO org.apache.hadoop.yarn.server.resourcemanager.RMAuditLogger: USER=ubuntu	IP=10.0.0.193	OPERATION=AM Released Container	TARGET=SchedulerApp	RESULT=SUCCESS	APPID=application_1399292339232_0002	CONTAINERID=container_1399292339232_0002_01_000026
2014-05-05 12:35:55,134 INFO org.apache.hadoop.yarn.server.resourcemanager.scheduler.common.fica.FiCaSchedulerNode: Released container container_1399292339232_0002_01_000026 of capacity <memory:1024, vCores:1> on host nodec:35478, which currently has 1 containers, <memory:1024, vCores:1> used and <memory:7168, vCores:7> available, release resources=true
2014-05-05 12:35:55,134 INFO org.apache.hadoop.yarn.server.resourcemanager.scheduler.capacity.LeafQueue: default used=<memory:12288, vCores:11> numContainers=11 user=ubuntu user-resources=<memory:12288, vCores:11>
2014-05-05 12:35:55,134 INFO org.apache.hadoop.yarn.server.resourcemanager.scheduler.capacity.LeafQueue: completedContainer container=Container: [ContainerId: container_1399292339232_0002_01_000026, NodeId: nodec:35478, NodeHttpAddress: nodec:8042, Resource: <memory:1024, vCores:1>, Priority: 10, Token: Token { kind: ContainerToken, service: 10.0.0.200:35478 }, ] resource=<memory:1024, vCores:1> queue=default: capacity=1.0, absoluteCapacity=1.0, usedResources=<memory:12288, vCores:11>usedCapacity=0.1875, absoluteUsedCapacity=0.1875, numApps=1, numContainers=11 usedCapacity=0.1875 absoluteUsedCapacity=0.1875 used=<memory:12288, vCores:11> cluster=<memory:65536, vCores:64>
2014-05-05 12:35:55,134 INFO org.apache.hadoop.yarn.server.resourcemanager.scheduler.capacity.ParentQueue: completedContainer queue=root usedCapacity=0.1875 absoluteUsedCapacity=0.1875 used=<memory:12288, vCores:11> cluster=<memory:65536, vCores:64>
2014-05-05 12:35:55,135 INFO org.apache.hadoop.yarn.server.resourcemanager.scheduler.capacity.ParentQueue: Re-sorting completed queue: root.default stats: default: capacity=1.0, absoluteCapacity=1.0, usedResources=<memory:12288, vCores:11>usedCapacity=0.1875, absoluteUsedCapacity=0.1875, numApps=1, numContainers=11
2014-05-05 12:35:55,135 INFO org.apache.hadoop.yarn.server.resourcemanager.scheduler.capacity.CapacityScheduler: Application appattempt_1399292339232_0002_000001 released container container_1399292339232_0002_01_000026 on node: host: nodec:35478 #containers=1 available=7168 used=1024 with event: RELEASED
2014-05-05 12:35:55,135 INFO org.apache.hadoop.yarn.server.resourcemanager.rmcontainer.RMContainerImpl: container_1399292339232_0002_01_000027 Container Transitioned from ACQUIRED to RELEASED
2014-05-05 12:35:55,135 INFO org.apache.hadoop.yarn.server.resourcemanager.scheduler.common.fica.FiCaSchedulerApp: Completed container: container_1399292339232_0002_01_000027 in state: RELEASED event:RELEASED
2014-05-05 12:35:55,135 INFO org.apache.hadoop.yarn.server.resourcemanager.RMAuditLogger: USER=ubuntu	IP=10.0.0.193	OPERATION=AM Released Container	TARGET=SchedulerApp	RESULT=SUCCESS	APPID=application_1399292339232_0002	CONTAINERID=container_1399292339232_0002_01_000027
2014-05-05 12:35:55,135 INFO org.apache.hadoop.yarn.server.resourcemanager.scheduler.common.fica.FiCaSchedulerNode: Released container container_1399292339232_0002_01_000027 of capacity <memory:1024, vCores:1> on host nodeb:48885, which currently has 2 containers, <memory:2048, vCores:2> used and <memory:6144, vCores:6> available, release resources=true
2014-05-05 12:35:55,135 INFO org.apache.hadoop.yarn.server.resourcemanager.scheduler.capacity.LeafQueue: default used=<memory:11264, vCores:10> numContainers=10 user=ubuntu user-resources=<memory:11264, vCores:10>
2014-05-05 12:35:55,135 INFO org.apache.hadoop.yarn.server.resourcemanager.scheduler.capacity.LeafQueue: completedContainer container=Container: [ContainerId: container_1399292339232_0002_01_000027, NodeId: nodeb:48885, NodeHttpAddress: nodeb:8042, Resource: <memory:1024, vCores:1>, Priority: 10, Token: Token { kind: ContainerToken, service: 10.0.0.194:48885 }, ] resource=<memory:1024, vCores:1> queue=default: capacity=1.0, absoluteCapacity=1.0, usedResources=<memory:11264, vCores:10>usedCapacity=0.171875, absoluteUsedCapacity=0.171875, numApps=1, numContainers=10 usedCapacity=0.171875 absoluteUsedCapacity=0.171875 used=<memory:11264, vCores:10> cluster=<memory:65536, vCores:64>
2014-05-05 12:35:55,135 INFO org.apache.hadoop.yarn.server.resourcemanager.scheduler.capacity.ParentQueue: completedContainer queue=root usedCapacity=0.171875 absoluteUsedCapacity=0.171875 used=<memory:11264, vCores:10> cluster=<memory:65536, vCores:64>
2014-05-05 12:35:55,135 INFO org.apache.hadoop.yarn.server.resourcemanager.scheduler.capacity.ParentQueue: Re-sorting completed queue: root.default stats: default: capacity=1.0, absoluteCapacity=1.0, usedResources=<memory:11264, vCores:10>usedCapacity=0.171875, absoluteUsedCapacity=0.171875, numApps=1, numContainers=10
2014-05-05 12:35:55,135 INFO org.apache.hadoop.yarn.server.resourcemanager.scheduler.capacity.CapacityScheduler: Application appattempt_1399292339232_0002_000001 released container container_1399292339232_0002_01_000027 on node: host: nodeb:48885 #containers=2 available=6144 used=2048 with event: RELEASED
2014-05-05 12:35:55,135 INFO org.apache.hadoop.yarn.server.resourcemanager.rmcontainer.RMContainerImpl: container_1399292339232_0002_01_000028 Container Transitioned from ACQUIRED to RELEASED
2014-05-05 12:35:55,136 INFO org.apache.hadoop.yarn.server.resourcemanager.scheduler.common.fica.FiCaSchedulerApp: Completed container: container_1399292339232_0002_01_000028 in state: RELEASED event:RELEASED
2014-05-05 12:35:55,136 INFO org.apache.hadoop.yarn.server.resourcemanager.RMAuditLogger: USER=ubuntu	IP=10.0.0.193	OPERATION=AM Released Container	TARGET=SchedulerApp	RESULT=SUCCESS	APPID=application_1399292339232_0002	CONTAINERID=container_1399292339232_0002_01_000028
2014-05-05 12:35:55,136 INFO org.apache.hadoop.yarn.server.resourcemanager.scheduler.common.fica.FiCaSchedulerNode: Released container container_1399292339232_0002_01_000028 of capacity <memory:1024, vCores:1> on host noded:39305, which currently has 2 containers, <memory:3072, vCores:2> used and <memory:5120, vCores:6> available, release resources=true
2014-05-05 12:35:55,136 INFO org.apache.hadoop.yarn.server.resourcemanager.scheduler.capacity.LeafQueue: default used=<memory:10240, vCores:9> numContainers=9 user=ubuntu user-resources=<memory:10240, vCores:9>
2014-05-05 12:35:55,136 INFO org.apache.hadoop.yarn.server.resourcemanager.scheduler.capacity.LeafQueue: completedContainer container=Container: [ContainerId: container_1399292339232_0002_01_000028, NodeId: noded:39305, NodeHttpAddress: noded:8042, Resource: <memory:1024, vCores:1>, Priority: 10, Token: Token { kind: ContainerToken, service: 10.0.0.193:39305 }, ] resource=<memory:1024, vCores:1> queue=default: capacity=1.0, absoluteCapacity=1.0, usedResources=<memory:10240, vCores:9>usedCapacity=0.15625, absoluteUsedCapacity=0.15625, numApps=1, numContainers=9 usedCapacity=0.15625 absoluteUsedCapacity=0.15625 used=<memory:10240, vCores:9> cluster=<memory:65536, vCores:64>
2014-05-05 12:35:55,136 INFO org.apache.hadoop.yarn.server.resourcemanager.scheduler.capacity.ParentQueue: completedContainer queue=root usedCapacity=0.15625 absoluteUsedCapacity=0.15625 used=<memory:10240, vCores:9> cluster=<memory:65536, vCores:64>
2014-05-05 12:35:55,136 INFO org.apache.hadoop.yarn.server.resourcemanager.scheduler.capacity.ParentQueue: Re-sorting completed queue: root.default stats: default: capacity=1.0, absoluteCapacity=1.0, usedResources=<memory:10240, vCores:9>usedCapacity=0.15625, absoluteUsedCapacity=0.15625, numApps=1, numContainers=9
2014-05-05 12:35:55,136 INFO org.apache.hadoop.yarn.server.resourcemanager.scheduler.capacity.CapacityScheduler: Application appattempt_1399292339232_0002_000001 released container container_1399292339232_0002_01_000028 on node: host: noded:39305 #containers=2 available=5120 used=3072 with event: RELEASED
2014-05-05 12:36:24,561 INFO org.apache.hadoop.yarn.server.webproxy.WebAppProxyServlet: dr.who is accessing unchecked http://ip-10-0-0-193:44754/mapreduce/job/job_1399292339232_0002 which is the app master GUI of application_1399292339232_0002 owned by ubuntu
2014-05-05 12:36:24,790 INFO org.apache.hadoop.yarn.server.webproxy.WebAppProxyServlet: dr.who is accessing unchecked http://ip-10-0-0-193:44754/static/jquery/jquery-1.8.2.min.js which is the app master GUI of application_1399292339232_0002 owned by ubuntu
2014-05-05 12:36:24,790 INFO org.apache.hadoop.yarn.server.webproxy.WebAppProxyServlet: dr.who is accessing unchecked http://ip-10-0-0-193:44754/static/jquery/jquery-ui-1.9.1.custom.min.js which is the app master GUI of application_1399292339232_0002 owned by ubuntu
2014-05-05 12:36:24,790 INFO org.apache.hadoop.yarn.server.webproxy.WebAppProxyServlet: dr.who is accessing unchecked http://ip-10-0-0-193:44754/static/dt-1.9.4/css/jui-dt.css which is the app master GUI of application_1399292339232_0002 owned by ubuntu
2014-05-05 12:36:24,791 INFO org.apache.hadoop.yarn.server.webproxy.WebAppProxyServlet: dr.who is accessing unchecked http://ip-10-0-0-193:44754/static/jquery/themes-1.9.1/base/jquery-ui.css which is the app master GUI of application_1399292339232_0002 owned by ubuntu
2014-05-05 12:36:24,793 INFO org.apache.hadoop.yarn.server.webproxy.WebAppProxyServlet: dr.who is accessing unchecked http://ip-10-0-0-193:44754/static/yarn.css which is the app master GUI of application_1399292339232_0002 owned by ubuntu
2014-05-05 12:36:24,795 INFO org.apache.hadoop.yarn.server.webproxy.WebAppProxyServlet: dr.who is accessing unchecked http://ip-10-0-0-193:44754/static/dt-1.9.4/js/jquery.dataTables.min.js which is the app master GUI of application_1399292339232_0002 owned by ubuntu
2014-05-05 12:36:24,872 INFO org.apache.hadoop.yarn.server.webproxy.WebAppProxyServlet: dr.who is accessing unchecked http://ip-10-0-0-193:44754/static/yarn.dt.plugins.js which is the app master GUI of application_1399292339232_0002 owned by ubuntu
2014-05-05 12:36:25,126 INFO org.apache.hadoop.yarn.server.webproxy.WebAppProxyServlet: dr.who is accessing unchecked http://ip-10-0-0-193:44754/static/jquery/themes-1.9.1/base/images/ui-bg_glass_95_fef1ec_1x400.png which is the app master GUI of application_1399292339232_0002 owned by ubuntu
2014-05-05 12:36:25,129 INFO org.apache.hadoop.yarn.server.webproxy.WebAppProxyServlet: dr.who is accessing unchecked http://ip-10-0-0-193:44754/static/jquery/themes-1.9.1/base/images/ui-bg_glass_75_e6e6e6_1x400.png which is the app master GUI of application_1399292339232_0002 owned by ubuntu
2014-05-05 12:36:25,130 INFO org.apache.hadoop.yarn.server.webproxy.WebAppProxyServlet: dr.who is accessing unchecked http://ip-10-0-0-193:44754/static/jquery/themes-1.9.1/base/images/ui-bg_flat_75_ffffff_40x100.png which is the app master GUI of application_1399292339232_0002 owned by ubuntu
2014-05-05 12:36:25,133 INFO org.apache.hadoop.yarn.server.webproxy.WebAppProxyServlet: dr.who is accessing unchecked http://ip-10-0-0-193:44754/static/jquery/themes-1.9.1/base/images/ui-bg_highlight-soft_75_cccccc_1x100.png which is the app master GUI of application_1399292339232_0002 owned by ubuntu
2014-05-05 12:36:25,146 INFO org.apache.hadoop.yarn.server.webproxy.WebAppProxyServlet: dr.who is accessing unchecked http://ip-10-0-0-193:44754/static/jquery/themes-1.9.1/base/images/ui-icons_888888_256x240.png which is the app master GUI of application_1399292339232_0002 owned by ubuntu
2014-05-05 12:36:25,152 INFO org.apache.hadoop.yarn.server.webproxy.WebAppProxyServlet: dr.who is accessing unchecked http://ip-10-0-0-193:44754/static/jquery/themes-1.9.1/base/images/ui-bg_glass_65_ffffff_1x400.png which is the app master GUI of application_1399292339232_0002 owned by ubuntu
2014-05-05 12:36:25,205 INFO org.apache.hadoop.yarn.server.webproxy.WebAppProxyServlet: dr.who is accessing unchecked http://ip-10-0-0-193:44754/static/jquery/themes-1.9.1/base/images/ui-icons_454545_256x240.png which is the app master GUI of application_1399292339232_0002 owned by ubuntu
2014-05-05 12:36:28,967 INFO org.apache.hadoop.yarn.server.webproxy.WebAppProxyServlet: dr.who is accessing unchecked http://ip-10-0-0-193:44754/mapreduce/attempts/job_1399292339232_0002/r/FAILED which is the app master GUI of application_1399292339232_0002 owned by ubuntu
2014-05-05 12:36:29,153 INFO org.apache.hadoop.yarn.server.webproxy.WebAppProxyServlet: dr.who is accessing unchecked http://ip-10-0-0-193:44754/static/yarn.css which is the app master GUI of application_1399292339232_0002 owned by ubuntu
2014-05-05 12:36:29,154 INFO org.apache.hadoop.yarn.server.webproxy.WebAppProxyServlet: dr.who is accessing unchecked http://ip-10-0-0-193:44754/static/dt-1.9.4/js/jquery.dataTables.min.js which is the app master GUI of application_1399292339232_0002 owned by ubuntu
2014-05-05 12:36:29,155 INFO org.apache.hadoop.yarn.server.webproxy.WebAppProxyServlet: dr.who is accessing unchecked http://ip-10-0-0-193:44754/static/jquery/jquery-ui-1.9.1.custom.min.js which is the app master GUI of application_1399292339232_0002 owned by ubuntu
2014-05-05 12:36:29,156 INFO org.apache.hadoop.yarn.server.webproxy.WebAppProxyServlet: dr.who is accessing unchecked http://ip-10-0-0-193:44754/static/jquery/themes-1.9.1/base/jquery-ui.css which is the app master GUI of application_1399292339232_0002 owned by ubuntu
2014-05-05 12:36:29,156 INFO org.apache.hadoop.yarn.server.webproxy.WebAppProxyServlet: dr.who is accessing unchecked http://ip-10-0-0-193:44754/static/jquery/jquery-1.8.2.min.js which is the app master GUI of application_1399292339232_0002 owned by ubuntu
2014-05-05 12:36:29,153 INFO org.apache.hadoop.yarn.server.webproxy.WebAppProxyServlet: dr.who is accessing unchecked http://ip-10-0-0-193:44754/static/dt-1.9.4/css/jui-dt.css which is the app master GUI of application_1399292339232_0002 owned by ubuntu
2014-05-05 12:36:29,269 INFO org.apache.hadoop.yarn.server.webproxy.WebAppProxyServlet: dr.who is accessing unchecked http://ip-10-0-0-193:44754/static/yarn.dt.plugins.js which is the app master GUI of application_1399292339232_0002 owned by ubuntu
2014-05-05 12:36:29,510 INFO org.apache.hadoop.yarn.server.webproxy.WebAppProxyServlet: dr.who is accessing unchecked http://ip-10-0-0-193:44754/static/jquery/themes-1.9.1/base/images/ui-bg_glass_95_fef1ec_1x400.png which is the app master GUI of application_1399292339232_0002 owned by ubuntu
2014-05-05 12:36:29,511 INFO org.apache.hadoop.yarn.server.webproxy.WebAppProxyServlet: dr.who is accessing unchecked http://ip-10-0-0-193:44754/static/jquery/themes-1.9.1/base/images/ui-bg_flat_75_ffffff_40x100.png which is the app master GUI of application_1399292339232_0002 owned by ubuntu
2014-05-05 12:36:29,519 INFO org.apache.hadoop.yarn.server.webproxy.WebAppProxyServlet: dr.who is accessing unchecked http://ip-10-0-0-193:44754/static/jquery/themes-1.9.1/base/images/ui-bg_glass_75_e6e6e6_1x400.png which is the app master GUI of application_1399292339232_0002 owned by ubuntu
2014-05-05 12:36:29,524 INFO org.apache.hadoop.yarn.server.webproxy.WebAppProxyServlet: dr.who is accessing unchecked http://ip-10-0-0-193:44754/static/jquery/themes-1.9.1/base/images/ui-bg_glass_65_ffffff_1x400.png which is the app master GUI of application_1399292339232_0002 owned by ubuntu
2014-05-05 12:36:29,525 INFO org.apache.hadoop.yarn.server.webproxy.WebAppProxyServlet: dr.who is accessing unchecked http://ip-10-0-0-193:44754/static/jquery/themes-1.9.1/base/images/ui-icons_454545_256x240.png which is the app master GUI of application_1399292339232_0002 owned by ubuntu
2014-05-05 12:36:29,525 INFO org.apache.hadoop.yarn.server.webproxy.WebAppProxyServlet: dr.who is accessing unchecked http://ip-10-0-0-193:44754/static/jquery/themes-1.9.1/base/images/ui-icons_888888_256x240.png which is the app master GUI of application_1399292339232_0002 owned by ubuntu
2014-05-05 12:36:29,589 INFO org.apache.hadoop.yarn.server.webproxy.WebAppProxyServlet: dr.who is accessing unchecked http://ip-10-0-0-193:44754/static/jquery/themes-1.9.1/base/images/ui-bg_highlight-soft_75_cccccc_1x100.png which is the app master GUI of application_1399292339232_0002 owned by ubuntu
2014-05-05 12:36:58,741 INFO org.apache.hadoop.yarn.server.resourcemanager.rmcontainer.RMContainerImpl: container_1399292339232_0002_01_000009 Container Transitioned from RUNNING to COMPLETED
2014-05-05 12:36:58,741 INFO org.apache.hadoop.yarn.server.resourcemanager.scheduler.common.fica.FiCaSchedulerApp: Completed container: container_1399292339232_0002_01_000009 in state: COMPLETED event:FINISHED
2014-05-05 12:36:58,741 INFO org.apache.hadoop.yarn.server.resourcemanager.RMAuditLogger: USER=ubuntu	OPERATION=AM Released Container	TARGET=SchedulerApp	RESULT=SUCCESS	APPID=application_1399292339232_0002	CONTAINERID=container_1399292339232_0002_01_000009
2014-05-05 12:36:58,741 INFO org.apache.hadoop.yarn.server.resourcemanager.scheduler.common.fica.FiCaSchedulerNode: Released container container_1399292339232_0002_01_000009 of capacity <memory:1024, vCores:1> on host nodeb:48885, which currently has 1 containers, <memory:1024, vCores:1> used and <memory:7168, vCores:7> available, release resources=true
2014-05-05 12:36:58,741 INFO org.apache.hadoop.yarn.server.resourcemanager.scheduler.capacity.LeafQueue: default used=<memory:9216, vCores:8> numContainers=8 user=ubuntu user-resources=<memory:9216, vCores:8>
2014-05-05 12:36:58,741 INFO org.apache.hadoop.yarn.server.resourcemanager.scheduler.capacity.LeafQueue: completedContainer container=Container: [ContainerId: container_1399292339232_0002_01_000009, NodeId: nodeb:48885, NodeHttpAddress: nodeb:8042, Resource: <memory:1024, vCores:1>, Priority: 10, Token: Token { kind: ContainerToken, service: 10.0.0.194:48885 }, ] resource=<memory:1024, vCores:1> queue=default: capacity=1.0, absoluteCapacity=1.0, usedResources=<memory:9216, vCores:8>usedCapacity=0.140625, absoluteUsedCapacity=0.140625, numApps=1, numContainers=8 usedCapacity=0.140625 absoluteUsedCapacity=0.140625 used=<memory:9216, vCores:8> cluster=<memory:65536, vCores:64>
2014-05-05 12:36:58,741 INFO org.apache.hadoop.yarn.server.resourcemanager.scheduler.capacity.ParentQueue: completedContainer queue=root usedCapacity=0.140625 absoluteUsedCapacity=0.140625 used=<memory:9216, vCores:8> cluster=<memory:65536, vCores:64>
2014-05-05 12:36:58,741 INFO org.apache.hadoop.yarn.server.resourcemanager.scheduler.capacity.ParentQueue: Re-sorting completed queue: root.default stats: default: capacity=1.0, absoluteCapacity=1.0, usedResources=<memory:9216, vCores:8>usedCapacity=0.140625, absoluteUsedCapacity=0.140625, numApps=1, numContainers=8
2014-05-05 12:36:58,741 INFO org.apache.hadoop.yarn.server.resourcemanager.scheduler.capacity.CapacityScheduler: Application appattempt_1399292339232_0002_000001 released container container_1399292339232_0002_01_000009 on node: host: nodeb:48885 #containers=1 available=7168 used=1024 with event: FINISHED
2014-05-05 12:37:39,213 INFO org.apache.hadoop.yarn.server.resourcemanager.rmcontainer.RMContainerImpl: container_1399292339232_0002_01_000020 Container Transitioned from RUNNING to COMPLETED
2014-05-05 12:37:39,213 INFO org.apache.hadoop.yarn.server.resourcemanager.scheduler.common.fica.FiCaSchedulerApp: Completed container: container_1399292339232_0002_01_000020 in state: COMPLETED event:FINISHED
2014-05-05 12:37:39,213 INFO org.apache.hadoop.yarn.server.resourcemanager.RMAuditLogger: USER=ubuntu	OPERATION=AM Released Container	TARGET=SchedulerApp	RESULT=SUCCESS	APPID=application_1399292339232_0002	CONTAINERID=container_1399292339232_0002_01_000020
2014-05-05 12:37:39,214 INFO org.apache.hadoop.yarn.server.resourcemanager.scheduler.common.fica.FiCaSchedulerNode: Released container container_1399292339232_0002_01_000020 of capacity <memory:1024, vCores:1> on host nodeb:48885, which currently has 0 containers, <memory:0, vCores:0> used and <memory:8192, vCores:8> available, release resources=true
2014-05-05 12:37:39,214 INFO org.apache.hadoop.yarn.server.resourcemanager.scheduler.capacity.LeafQueue: default used=<memory:8192, vCores:7> numContainers=7 user=ubuntu user-resources=<memory:8192, vCores:7>
2014-05-05 12:37:39,214 INFO org.apache.hadoop.yarn.server.resourcemanager.scheduler.capacity.LeafQueue: completedContainer container=Container: [ContainerId: container_1399292339232_0002_01_000020, NodeId: nodeb:48885, NodeHttpAddress: nodeb:8042, Resource: <memory:1024, vCores:1>, Priority: 10, Token: Token { kind: ContainerToken, service: 10.0.0.194:48885 }, ] resource=<memory:1024, vCores:1> queue=default: capacity=1.0, absoluteCapacity=1.0, usedResources=<memory:8192, vCores:7>usedCapacity=0.125, absoluteUsedCapacity=0.125, numApps=1, numContainers=7 usedCapacity=0.125 absoluteUsedCapacity=0.125 used=<memory:8192, vCores:7> cluster=<memory:65536, vCores:64>
2014-05-05 12:37:39,214 INFO org.apache.hadoop.yarn.server.resourcemanager.scheduler.capacity.ParentQueue: completedContainer queue=root usedCapacity=0.125 absoluteUsedCapacity=0.125 used=<memory:8192, vCores:7> cluster=<memory:65536, vCores:64>
2014-05-05 12:37:39,214 INFO org.apache.hadoop.yarn.server.resourcemanager.scheduler.capacity.ParentQueue: Re-sorting completed queue: root.default stats: default: capacity=1.0, absoluteCapacity=1.0, usedResources=<memory:8192, vCores:7>usedCapacity=0.125, absoluteUsedCapacity=0.125, numApps=1, numContainers=7
2014-05-05 12:37:39,214 INFO org.apache.hadoop.yarn.server.resourcemanager.scheduler.capacity.CapacityScheduler: Application appattempt_1399292339232_0002_000001 released container container_1399292339232_0002_01_000020 on node: host: nodeb:48885 #containers=0 available=8192 used=0 with event: FINISHED
2014-05-05 12:37:46,629 INFO org.apache.hadoop.yarn.server.webproxy.WebAppProxyServlet: dr.who is accessing unchecked http://ip-10-0-0-193:44754/mapreduce/job/job_1399292339232_0002 which is the app master GUI of application_1399292339232_0002 owned by ubuntu
2014-05-05 12:37:46,851 INFO org.apache.hadoop.yarn.server.webproxy.WebAppProxyServlet: dr.who is accessing unchecked http://ip-10-0-0-193:44754/static/yarn.css which is the app master GUI of application_1399292339232_0002 owned by ubuntu
2014-05-05 12:37:46,853 INFO org.apache.hadoop.yarn.server.webproxy.WebAppProxyServlet: dr.who is accessing unchecked http://ip-10-0-0-193:44754/static/dt-1.9.4/css/jui-dt.css which is the app master GUI of application_1399292339232_0002 owned by ubuntu
2014-05-05 12:37:46,854 INFO org.apache.hadoop.yarn.server.webproxy.WebAppProxyServlet: dr.who is accessing unchecked http://ip-10-0-0-193:44754/static/jquery/jquery-1.8.2.min.js which is the app master GUI of application_1399292339232_0002 owned by ubuntu
2014-05-05 12:37:46,855 INFO org.apache.hadoop.yarn.server.webproxy.WebAppProxyServlet: dr.who is accessing unchecked http://ip-10-0-0-193:44754/static/jquery/themes-1.9.1/base/jquery-ui.css which is the app master GUI of application_1399292339232_0002 owned by ubuntu
2014-05-05 12:37:46,861 INFO org.apache.hadoop.yarn.server.webproxy.WebAppProxyServlet: dr.who is accessing unchecked http://ip-10-0-0-193:44754/static/dt-1.9.4/js/jquery.dataTables.min.js which is the app master GUI of application_1399292339232_0002 owned by ubuntu
2014-05-05 12:37:46,862 INFO org.apache.hadoop.yarn.server.webproxy.WebAppProxyServlet: dr.who is accessing unchecked http://ip-10-0-0-193:44754/static/jquery/jquery-ui-1.9.1.custom.min.js which is the app master GUI of application_1399292339232_0002 owned by ubuntu
2014-05-05 12:37:46,942 INFO org.apache.hadoop.yarn.server.webproxy.WebAppProxyServlet: dr.who is accessing unchecked http://ip-10-0-0-193:44754/static/yarn.dt.plugins.js which is the app master GUI of application_1399292339232_0002 owned by ubuntu
2014-05-05 12:37:47,206 INFO org.apache.hadoop.yarn.server.webproxy.WebAppProxyServlet: dr.who is accessing unchecked http://ip-10-0-0-193:44754/static/jquery/themes-1.9.1/base/images/ui-bg_flat_75_ffffff_40x100.png which is the app master GUI of application_1399292339232_0002 owned by ubuntu
2014-05-05 12:37:47,208 INFO org.apache.hadoop.yarn.server.webproxy.WebAppProxyServlet: dr.who is accessing unchecked http://ip-10-0-0-193:44754/static/jquery/themes-1.9.1/base/images/ui-bg_glass_95_fef1ec_1x400.png which is the app master GUI of application_1399292339232_0002 owned by ubuntu
2014-05-05 12:37:47,217 INFO org.apache.hadoop.yarn.server.webproxy.WebAppProxyServlet: dr.who is accessing unchecked http://ip-10-0-0-193:44754/static/jquery/themes-1.9.1/base/images/ui-bg_glass_75_e6e6e6_1x400.png which is the app master GUI of application_1399292339232_0002 owned by ubuntu
2014-05-05 12:37:47,219 INFO org.apache.hadoop.yarn.server.webproxy.WebAppProxyServlet: dr.who is accessing unchecked http://ip-10-0-0-193:44754/static/jquery/themes-1.9.1/base/images/ui-bg_highlight-soft_75_cccccc_1x100.png which is the app master GUI of application_1399292339232_0002 owned by ubuntu
2014-05-05 12:37:47,225 INFO org.apache.hadoop.yarn.server.webproxy.WebAppProxyServlet: dr.who is accessing unchecked http://ip-10-0-0-193:44754/static/jquery/themes-1.9.1/base/images/ui-bg_glass_65_ffffff_1x400.png which is the app master GUI of application_1399292339232_0002 owned by ubuntu
2014-05-05 12:37:47,227 INFO org.apache.hadoop.yarn.server.webproxy.WebAppProxyServlet: dr.who is accessing unchecked http://ip-10-0-0-193:44754/static/jquery/themes-1.9.1/base/images/ui-icons_888888_256x240.png which is the app master GUI of application_1399292339232_0002 owned by ubuntu
2014-05-05 12:37:47,287 INFO org.apache.hadoop.yarn.server.webproxy.WebAppProxyServlet: dr.who is accessing unchecked http://ip-10-0-0-193:44754/static/jquery/themes-1.9.1/base/images/ui-icons_454545_256x240.png which is the app master GUI of application_1399292339232_0002 owned by ubuntu
2014-05-05 12:38:15,419 INFO org.apache.hadoop.yarn.server.resourcemanager.rmcontainer.RMContainerImpl: container_1399292339232_0002_01_000019 Container Transitioned from RUNNING to COMPLETED
2014-05-05 12:38:15,420 INFO org.apache.hadoop.yarn.server.resourcemanager.scheduler.common.fica.FiCaSchedulerApp: Completed container: container_1399292339232_0002_01_000019 in state: COMPLETED event:FINISHED
2014-05-05 12:38:15,420 INFO org.apache.hadoop.yarn.server.resourcemanager.RMAuditLogger: USER=ubuntu	OPERATION=AM Released Container	TARGET=SchedulerApp	RESULT=SUCCESS	APPID=application_1399292339232_0002	CONTAINERID=container_1399292339232_0002_01_000019
2014-05-05 12:38:15,420 INFO org.apache.hadoop.yarn.server.resourcemanager.scheduler.common.fica.FiCaSchedulerNode: Released container container_1399292339232_0002_01_000019 of capacity <memory:1024, vCores:1> on host nodec:35478, which currently has 0 containers, <memory:0, vCores:0> used and <memory:8192, vCores:8> available, release resources=true
2014-05-05 12:38:15,420 INFO org.apache.hadoop.yarn.server.resourcemanager.scheduler.capacity.LeafQueue: default used=<memory:7168, vCores:6> numContainers=6 user=ubuntu user-resources=<memory:7168, vCores:6>
2014-05-05 12:38:15,420 INFO org.apache.hadoop.yarn.server.resourcemanager.scheduler.capacity.LeafQueue: completedContainer container=Container: [ContainerId: container_1399292339232_0002_01_000019, NodeId: nodec:35478, NodeHttpAddress: nodec:8042, Resource: <memory:1024, vCores:1>, Priority: 10, Token: Token { kind: ContainerToken, service: 10.0.0.200:35478 }, ] resource=<memory:1024, vCores:1> queue=default: capacity=1.0, absoluteCapacity=1.0, usedResources=<memory:7168, vCores:6>usedCapacity=0.109375, absoluteUsedCapacity=0.109375, numApps=1, numContainers=6 usedCapacity=0.109375 absoluteUsedCapacity=0.109375 used=<memory:7168, vCores:6> cluster=<memory:65536, vCores:64>
2014-05-05 12:38:15,420 INFO org.apache.hadoop.yarn.server.resourcemanager.scheduler.capacity.ParentQueue: completedContainer queue=root usedCapacity=0.109375 absoluteUsedCapacity=0.109375 used=<memory:7168, vCores:6> cluster=<memory:65536, vCores:64>
2014-05-05 12:38:15,420 INFO org.apache.hadoop.yarn.server.resourcemanager.scheduler.capacity.ParentQueue: Re-sorting completed queue: root.default stats: default: capacity=1.0, absoluteCapacity=1.0, usedResources=<memory:7168, vCores:6>usedCapacity=0.109375, absoluteUsedCapacity=0.109375, numApps=1, numContainers=6
2014-05-05 12:38:15,420 INFO org.apache.hadoop.yarn.server.resourcemanager.scheduler.capacity.CapacityScheduler: Application appattempt_1399292339232_0002_000001 released container container_1399292339232_0002_01_000019 on node: host: nodec:35478 #containers=0 available=8192 used=0 with event: FINISHED
2014-05-05 12:38:15,439 INFO org.apache.hadoop.yarn.server.resourcemanager.rmcontainer.RMContainerImpl: container_1399292339232_0002_01_000016 Container Transitioned from RUNNING to COMPLETED
2014-05-05 12:38:15,439 INFO org.apache.hadoop.yarn.server.resourcemanager.scheduler.common.fica.FiCaSchedulerApp: Completed container: container_1399292339232_0002_01_000016 in state: COMPLETED event:FINISHED
2014-05-05 12:38:15,439 INFO org.apache.hadoop.yarn.server.resourcemanager.RMAuditLogger: USER=ubuntu	OPERATION=AM Released Container	TARGET=SchedulerApp	RESULT=SUCCESS	APPID=application_1399292339232_0002	CONTAINERID=container_1399292339232_0002_01_000016
2014-05-05 12:38:15,439 INFO org.apache.hadoop.yarn.server.resourcemanager.scheduler.common.fica.FiCaSchedulerNode: Released container container_1399292339232_0002_01_000016 of capacity <memory:1024, vCores:1> on host nodee:49598, which currently has 1 containers, <memory:1024, vCores:1> used and <memory:7168, vCores:7> available, release resources=true
2014-05-05 12:38:15,439 INFO org.apache.hadoop.yarn.server.resourcemanager.scheduler.capacity.LeafQueue: default used=<memory:6144, vCores:5> numContainers=5 user=ubuntu user-resources=<memory:6144, vCores:5>
2014-05-05 12:38:15,439 INFO org.apache.hadoop.yarn.server.resourcemanager.scheduler.capacity.LeafQueue: completedContainer container=Container: [ContainerId: container_1399292339232_0002_01_000016, NodeId: nodee:49598, NodeHttpAddress: nodee:8042, Resource: <memory:1024, vCores:1>, Priority: 10, Token: Token { kind: ContainerToken, service: 10.0.0.198:49598 }, ] resource=<memory:1024, vCores:1> queue=default: capacity=1.0, absoluteCapacity=1.0, usedResources=<memory:6144, vCores:5>usedCapacity=0.09375, absoluteUsedCapacity=0.09375, numApps=1, numContainers=5 usedCapacity=0.09375 absoluteUsedCapacity=0.09375 used=<memory:6144, vCores:5> cluster=<memory:65536, vCores:64>
2014-05-05 12:38:15,439 INFO org.apache.hadoop.yarn.server.resourcemanager.scheduler.capacity.ParentQueue: completedContainer queue=root usedCapacity=0.09375 absoluteUsedCapacity=0.09375 used=<memory:6144, vCores:5> cluster=<memory:65536, vCores:64>
2014-05-05 12:38:15,440 INFO org.apache.hadoop.yarn.server.resourcemanager.scheduler.capacity.ParentQueue: Re-sorting completed queue: root.default stats: default: capacity=1.0, absoluteCapacity=1.0, usedResources=<memory:6144, vCores:5>usedCapacity=0.09375, absoluteUsedCapacity=0.09375, numApps=1, numContainers=5
2014-05-05 12:38:15,440 INFO org.apache.hadoop.yarn.server.resourcemanager.scheduler.capacity.CapacityScheduler: Application appattempt_1399292339232_0002_000001 released container container_1399292339232_0002_01_000016 on node: host: nodee:49598 #containers=1 available=7168 used=1024 with event: FINISHED
2014-05-05 12:38:15,440 INFO org.apache.hadoop.yarn.server.resourcemanager.rmcontainer.RMContainerImpl: container_1399292339232_0002_01_000018 Container Transitioned from RUNNING to COMPLETED
2014-05-05 12:38:15,440 INFO org.apache.hadoop.yarn.server.resourcemanager.scheduler.common.fica.FiCaSchedulerApp: Completed container: container_1399292339232_0002_01_000018 in state: COMPLETED event:FINISHED
2014-05-05 12:38:15,440 INFO org.apache.hadoop.yarn.server.resourcemanager.RMAuditLogger: USER=ubuntu	OPERATION=AM Released Container	TARGET=SchedulerApp	RESULT=SUCCESS	APPID=application_1399292339232_0002	CONTAINERID=container_1399292339232_0002_01_000018
2014-05-05 12:38:15,440 INFO org.apache.hadoop.yarn.server.resourcemanager.scheduler.common.fica.FiCaSchedulerNode: Released container container_1399292339232_0002_01_000018 of capacity <memory:1024, vCores:1> on host nodee:49598, which currently has 0 containers, <memory:0, vCores:0> used and <memory:8192, vCores:8> available, release resources=true
2014-05-05 12:38:15,440 INFO org.apache.hadoop.yarn.server.resourcemanager.scheduler.capacity.LeafQueue: default used=<memory:5120, vCores:4> numContainers=4 user=ubuntu user-resources=<memory:5120, vCores:4>
2014-05-05 12:38:15,440 INFO org.apache.hadoop.yarn.server.resourcemanager.scheduler.capacity.LeafQueue: completedContainer container=Container: [ContainerId: container_1399292339232_0002_01_000018, NodeId: nodee:49598, NodeHttpAddress: nodee:8042, Resource: <memory:1024, vCores:1>, Priority: 10, Token: Token { kind: ContainerToken, service: 10.0.0.198:49598 }, ] resource=<memory:1024, vCores:1> queue=default: capacity=1.0, absoluteCapacity=1.0, usedResources=<memory:5120, vCores:4>usedCapacity=0.078125, absoluteUsedCapacity=0.078125, numApps=1, numContainers=4 usedCapacity=0.078125 absoluteUsedCapacity=0.078125 used=<memory:5120, vCores:4> cluster=<memory:65536, vCores:64>
2014-05-05 12:38:15,440 INFO org.apache.hadoop.yarn.server.resourcemanager.scheduler.capacity.ParentQueue: completedContainer queue=root usedCapacity=0.078125 absoluteUsedCapacity=0.078125 used=<memory:5120, vCores:4> cluster=<memory:65536, vCores:64>
2014-05-05 12:38:15,440 INFO org.apache.hadoop.yarn.server.resourcemanager.scheduler.capacity.ParentQueue: Re-sorting completed queue: root.default stats: default: capacity=1.0, absoluteCapacity=1.0, usedResources=<memory:5120, vCores:4>usedCapacity=0.078125, absoluteUsedCapacity=0.078125, numApps=1, numContainers=4
2014-05-05 12:38:15,440 INFO org.apache.hadoop.yarn.server.resourcemanager.scheduler.capacity.CapacityScheduler: Application appattempt_1399292339232_0002_000001 released container container_1399292339232_0002_01_000018 on node: host: nodee:49598 #containers=0 available=8192 used=0 with event: FINISHED
2014-05-05 12:38:15,441 INFO org.apache.hadoop.yarn.server.resourcemanager.rmcontainer.RMContainerImpl: container_1399292339232_0002_01_000015 Container Transitioned from RUNNING to COMPLETED
2014-05-05 12:38:15,441 INFO org.apache.hadoop.yarn.server.resourcemanager.scheduler.common.fica.FiCaSchedulerApp: Completed container: container_1399292339232_0002_01_000015 in state: COMPLETED event:FINISHED
2014-05-05 12:38:15,441 INFO org.apache.hadoop.yarn.server.resourcemanager.RMAuditLogger: USER=ubuntu	OPERATION=AM Released Container	TARGET=SchedulerApp	RESULT=SUCCESS	APPID=application_1399292339232_0002	CONTAINERID=container_1399292339232_0002_01_000015
2014-05-05 12:38:15,441 INFO org.apache.hadoop.yarn.server.resourcemanager.scheduler.common.fica.FiCaSchedulerNode: Released container container_1399292339232_0002_01_000015 of capacity <memory:1024, vCores:1> on host nodeg:56763, which currently has 1 containers, <memory:1024, vCores:1> used and <memory:7168, vCores:7> available, release resources=true
2014-05-05 12:38:15,441 INFO org.apache.hadoop.yarn.server.resourcemanager.scheduler.capacity.LeafQueue: default used=<memory:4096, vCores:3> numContainers=3 user=ubuntu user-resources=<memory:4096, vCores:3>
2014-05-05 12:38:15,441 INFO org.apache.hadoop.yarn.server.resourcemanager.scheduler.capacity.LeafQueue: completedContainer container=Container: [ContainerId: container_1399292339232_0002_01_000015, NodeId: nodeg:56763, NodeHttpAddress: nodeg:8042, Resource: <memory:1024, vCores:1>, Priority: 10, Token: Token { kind: ContainerToken, service: 10.0.0.196:56763 }, ] resource=<memory:1024, vCores:1> queue=default: capacity=1.0, absoluteCapacity=1.0, usedResources=<memory:4096, vCores:3>usedCapacity=0.0625, absoluteUsedCapacity=0.0625, numApps=1, numContainers=3 usedCapacity=0.0625 absoluteUsedCapacity=0.0625 used=<memory:4096, vCores:3> cluster=<memory:65536, vCores:64>
2014-05-05 12:38:15,441 INFO org.apache.hadoop.yarn.server.resourcemanager.scheduler.capacity.ParentQueue: completedContainer queue=root usedCapacity=0.0625 absoluteUsedCapacity=0.0625 used=<memory:4096, vCores:3> cluster=<memory:65536, vCores:64>
2014-05-05 12:38:15,442 INFO org.apache.hadoop.yarn.server.resourcemanager.scheduler.capacity.ParentQueue: Re-sorting completed queue: root.default stats: default: capacity=1.0, absoluteCapacity=1.0, usedResources=<memory:4096, vCores:3>usedCapacity=0.0625, absoluteUsedCapacity=0.0625, numApps=1, numContainers=3
2014-05-05 12:38:15,442 INFO org.apache.hadoop.yarn.server.resourcemanager.scheduler.capacity.CapacityScheduler: Application appattempt_1399292339232_0002_000001 released container container_1399292339232_0002_01_000015 on node: host: nodeg:56763 #containers=1 available=7168 used=1024 with event: FINISHED
2014-05-05 12:38:15,442 INFO org.apache.hadoop.yarn.server.resourcemanager.rmcontainer.RMContainerImpl: container_1399292339232_0002_01_000017 Container Transitioned from RUNNING to COMPLETED
2014-05-05 12:38:15,442 INFO org.apache.hadoop.yarn.server.resourcemanager.scheduler.common.fica.FiCaSchedulerApp: Completed container: container_1399292339232_0002_01_000017 in state: COMPLETED event:FINISHED
2014-05-05 12:38:15,442 INFO org.apache.hadoop.yarn.server.resourcemanager.RMAuditLogger: USER=ubuntu	OPERATION=AM Released Container	TARGET=SchedulerApp	RESULT=SUCCESS	APPID=application_1399292339232_0002	CONTAINERID=container_1399292339232_0002_01_000017
2014-05-05 12:38:15,442 INFO org.apache.hadoop.yarn.server.resourcemanager.scheduler.common.fica.FiCaSchedulerNode: Released container container_1399292339232_0002_01_000017 of capacity <memory:1024, vCores:1> on host nodeg:56763, which currently has 0 containers, <memory:0, vCores:0> used and <memory:8192, vCores:8> available, release resources=true
2014-05-05 12:38:15,442 INFO org.apache.hadoop.yarn.server.resourcemanager.scheduler.capacity.LeafQueue: default used=<memory:3072, vCores:2> numContainers=2 user=ubuntu user-resources=<memory:3072, vCores:2>
2014-05-05 12:38:15,442 INFO org.apache.hadoop.yarn.server.resourcemanager.scheduler.capacity.LeafQueue: completedContainer container=Container: [ContainerId: container_1399292339232_0002_01_000017, NodeId: nodeg:56763, NodeHttpAddress: nodeg:8042, Resource: <memory:1024, vCores:1>, Priority: 10, Token: Token { kind: ContainerToken, service: 10.0.0.196:56763 }, ] resource=<memory:1024, vCores:1> queue=default: capacity=1.0, absoluteCapacity=1.0, usedResources=<memory:3072, vCores:2>usedCapacity=0.046875, absoluteUsedCapacity=0.046875, numApps=1, numContainers=2 usedCapacity=0.046875 absoluteUsedCapacity=0.046875 used=<memory:3072, vCores:2> cluster=<memory:65536, vCores:64>
2014-05-05 12:38:15,442 INFO org.apache.hadoop.yarn.server.resourcemanager.scheduler.capacity.ParentQueue: completedContainer queue=root usedCapacity=0.046875 absoluteUsedCapacity=0.046875 used=<memory:3072, vCores:2> cluster=<memory:65536, vCores:64>
2014-05-05 12:38:15,442 INFO org.apache.hadoop.yarn.server.resourcemanager.scheduler.capacity.ParentQueue: Re-sorting completed queue: root.default stats: default: capacity=1.0, absoluteCapacity=1.0, usedResources=<memory:3072, vCores:2>usedCapacity=0.046875, absoluteUsedCapacity=0.046875, numApps=1, numContainers=2
2014-05-05 12:38:15,442 INFO org.apache.hadoop.yarn.server.resourcemanager.scheduler.capacity.CapacityScheduler: Application appattempt_1399292339232_0002_000001 released container container_1399292339232_0002_01_000017 on node: host: nodeg:56763 #containers=0 available=8192 used=0 with event: FINISHED
2014-05-05 12:38:15,448 INFO org.apache.hadoop.yarn.server.resourcemanager.rmcontainer.RMContainerImpl: container_1399292339232_0002_01_000021 Container Transitioned from RUNNING to COMPLETED
2014-05-05 12:38:15,448 INFO org.apache.hadoop.yarn.server.resourcemanager.scheduler.common.fica.FiCaSchedulerApp: Completed container: container_1399292339232_0002_01_000021 in state: COMPLETED event:FINISHED
2014-05-05 12:38:15,448 INFO org.apache.hadoop.yarn.server.resourcemanager.RMAuditLogger: USER=ubuntu	OPERATION=AM Released Container	TARGET=SchedulerApp	RESULT=SUCCESS	APPID=application_1399292339232_0002	CONTAINERID=container_1399292339232_0002_01_000021
2014-05-05 12:38:15,448 INFO org.apache.hadoop.yarn.server.resourcemanager.scheduler.common.fica.FiCaSchedulerNode: Released container container_1399292339232_0002_01_000021 of capacity <memory:1024, vCores:1> on host noded:39305, which currently has 1 containers, <memory:2048, vCores:1> used and <memory:6144, vCores:7> available, release resources=true
2014-05-05 12:38:15,448 INFO org.apache.hadoop.yarn.server.resourcemanager.scheduler.capacity.LeafQueue: default used=<memory:2048, vCores:1> numContainers=1 user=ubuntu user-resources=<memory:2048, vCores:1>
2014-05-05 12:38:15,448 INFO org.apache.hadoop.yarn.server.resourcemanager.scheduler.capacity.LeafQueue: completedContainer container=Container: [ContainerId: container_1399292339232_0002_01_000021, NodeId: noded:39305, NodeHttpAddress: noded:8042, Resource: <memory:1024, vCores:1>, Priority: 10, Token: Token { kind: ContainerToken, service: 10.0.0.193:39305 }, ] resource=<memory:1024, vCores:1> queue=default: capacity=1.0, absoluteCapacity=1.0, usedResources=<memory:2048, vCores:1>usedCapacity=0.03125, absoluteUsedCapacity=0.03125, numApps=1, numContainers=1 usedCapacity=0.03125 absoluteUsedCapacity=0.03125 used=<memory:2048, vCores:1> cluster=<memory:65536, vCores:64>
2014-05-05 12:38:15,448 INFO org.apache.hadoop.yarn.server.resourcemanager.scheduler.capacity.ParentQueue: completedContainer queue=root usedCapacity=0.03125 absoluteUsedCapacity=0.03125 used=<memory:2048, vCores:1> cluster=<memory:65536, vCores:64>
2014-05-05 12:38:15,448 INFO org.apache.hadoop.yarn.server.resourcemanager.scheduler.capacity.ParentQueue: Re-sorting completed queue: root.default stats: default: capacity=1.0, absoluteCapacity=1.0, usedResources=<memory:2048, vCores:1>usedCapacity=0.03125, absoluteUsedCapacity=0.03125, numApps=1, numContainers=1
2014-05-05 12:38:15,448 INFO org.apache.hadoop.yarn.server.resourcemanager.scheduler.capacity.CapacityScheduler: Application appattempt_1399292339232_0002_000001 released container container_1399292339232_0002_01_000021 on node: host: noded:39305 #containers=1 available=6144 used=2048 with event: FINISHED
2014-05-05 12:38:16,421 INFO org.apache.hadoop.yarn.server.resourcemanager.rmcontainer.RMContainerImpl: container_1399292339232_0002_01_000029 Container Transitioned from NEW to ALLOCATED
2014-05-05 12:38:16,421 INFO org.apache.hadoop.yarn.server.resourcemanager.RMAuditLogger: USER=ubuntu	OPERATION=AM Allocated Container	TARGET=SchedulerApp	RESULT=SUCCESS	APPID=application_1399292339232_0002	CONTAINERID=container_1399292339232_0002_01_000029
2014-05-05 12:38:16,421 INFO org.apache.hadoop.yarn.server.resourcemanager.scheduler.common.fica.FiCaSchedulerNode: Assigned container container_1399292339232_0002_01_000029 of capacity <memory:1024, vCores:1> on host nodec:35478, which currently has 1 containers, <memory:1024, vCores:1> used and <memory:7168, vCores:7> available
2014-05-05 12:38:16,421 INFO org.apache.hadoop.yarn.server.resourcemanager.scheduler.capacity.LeafQueue: assignedContainer application=application_1399292339232_0002 container=Container: [ContainerId: container_1399292339232_0002_01_000029, NodeId: nodec:35478, NodeHttpAddress: nodec:8042, Resource: <memory:1024, vCores:1>, Priority: 10, Token: Token { kind: ContainerToken, service: 10.0.0.200:35478 }, ] containerId=container_1399292339232_0002_01_000029 queue=default: capacity=1.0, absoluteCapacity=1.0, usedResources=<memory:2048, vCores:1>usedCapacity=0.03125, absoluteUsedCapacity=0.03125, numApps=1, numContainers=1 usedCapacity=0.03125 absoluteUsedCapacity=0.03125 used=<memory:2048, vCores:1> cluster=<memory:65536, vCores:64>
2014-05-05 12:38:16,421 INFO org.apache.hadoop.yarn.server.resourcemanager.scheduler.capacity.ParentQueue: Re-sorting assigned queue: root.default stats: default: capacity=1.0, absoluteCapacity=1.0, usedResources=<memory:3072, vCores:2>usedCapacity=0.046875, absoluteUsedCapacity=0.046875, numApps=1, numContainers=2
2014-05-05 12:38:16,421 INFO org.apache.hadoop.yarn.server.resourcemanager.scheduler.capacity.ParentQueue: assignedContainer queue=root usedCapacity=0.046875 absoluteUsedCapacity=0.046875 used=<memory:3072, vCores:2> cluster=<memory:65536, vCores:64>
2014-05-05 12:38:16,449 INFO org.apache.hadoop.yarn.server.resourcemanager.rmcontainer.RMContainerImpl: container_1399292339232_0002_01_000030 Container Transitioned from NEW to ALLOCATED
2014-05-05 12:38:16,449 INFO org.apache.hadoop.yarn.server.resourcemanager.RMAuditLogger: USER=ubuntu	OPERATION=AM Allocated Container	TARGET=SchedulerApp	RESULT=SUCCESS	APPID=application_1399292339232_0002	CONTAINERID=container_1399292339232_0002_01_000030
2014-05-05 12:38:16,450 INFO org.apache.hadoop.yarn.server.resourcemanager.scheduler.common.fica.FiCaSchedulerNode: Assigned container container_1399292339232_0002_01_000030 of capacity <memory:1024, vCores:1> on host noded:39305, which currently has 2 containers, <memory:3072, vCores:2> used and <memory:5120, vCores:6> available
2014-05-05 12:38:16,450 INFO org.apache.hadoop.yarn.server.resourcemanager.scheduler.capacity.LeafQueue: assignedContainer application=application_1399292339232_0002 container=Container: [ContainerId: container_1399292339232_0002_01_000030, NodeId: noded:39305, NodeHttpAddress: noded:8042, Resource: <memory:1024, vCores:1>, Priority: 10, Token: Token { kind: ContainerToken, service: 10.0.0.193:39305 }, ] containerId=container_1399292339232_0002_01_000030 queue=default: capacity=1.0, absoluteCapacity=1.0, usedResources=<memory:3072, vCores:2>usedCapacity=0.046875, absoluteUsedCapacity=0.046875, numApps=1, numContainers=2 usedCapacity=0.046875 absoluteUsedCapacity=0.046875 used=<memory:3072, vCores:2> cluster=<memory:65536, vCores:64>
2014-05-05 12:38:16,450 INFO org.apache.hadoop.yarn.server.resourcemanager.scheduler.capacity.ParentQueue: Re-sorting assigned queue: root.default stats: default: capacity=1.0, absoluteCapacity=1.0, usedResources=<memory:4096, vCores:3>usedCapacity=0.0625, absoluteUsedCapacity=0.0625, numApps=1, numContainers=3
2014-05-05 12:38:16,450 INFO org.apache.hadoop.yarn.server.resourcemanager.scheduler.capacity.ParentQueue: assignedContainer queue=root usedCapacity=0.0625 absoluteUsedCapacity=0.0625 used=<memory:4096, vCores:3> cluster=<memory:65536, vCores:64>
2014-05-05 12:38:17,234 INFO org.apache.hadoop.yarn.server.resourcemanager.rmcontainer.RMContainerImpl: container_1399292339232_0002_01_000031 Container Transitioned from NEW to ALLOCATED
2014-05-05 12:38:17,234 INFO org.apache.hadoop.yarn.server.resourcemanager.RMAuditLogger: USER=ubuntu	OPERATION=AM Allocated Container	TARGET=SchedulerApp	RESULT=SUCCESS	APPID=application_1399292339232_0002	CONTAINERID=container_1399292339232_0002_01_000031
2014-05-05 12:38:17,234 INFO org.apache.hadoop.yarn.server.resourcemanager.scheduler.common.fica.FiCaSchedulerNode: Assigned container container_1399292339232_0002_01_000031 of capacity <memory:1024, vCores:1> on host nodea:51924, which currently has 1 containers, <memory:1024, vCores:1> used and <memory:7168, vCores:7> available
2014-05-05 12:38:17,234 INFO org.apache.hadoop.yarn.server.resourcemanager.scheduler.capacity.LeafQueue: assignedContainer application=application_1399292339232_0002 container=Container: [ContainerId: container_1399292339232_0002_01_000031, NodeId: nodea:51924, NodeHttpAddress: nodea:8042, Resource: <memory:1024, vCores:1>, Priority: 10, Token: Token { kind: ContainerToken, service: 10.0.0.195:51924 }, ] containerId=container_1399292339232_0002_01_000031 queue=default: capacity=1.0, absoluteCapacity=1.0, usedResources=<memory:4096, vCores:3>usedCapacity=0.0625, absoluteUsedCapacity=0.0625, numApps=1, numContainers=3 usedCapacity=0.0625 absoluteUsedCapacity=0.0625 used=<memory:4096, vCores:3> cluster=<memory:65536, vCores:64>
2014-05-05 12:38:17,234 INFO org.apache.hadoop.yarn.server.resourcemanager.scheduler.capacity.ParentQueue: Re-sorting assigned queue: root.default stats: default: capacity=1.0, absoluteCapacity=1.0, usedResources=<memory:5120, vCores:4>usedCapacity=0.078125, absoluteUsedCapacity=0.078125, numApps=1, numContainers=4
2014-05-05 12:38:17,234 INFO org.apache.hadoop.yarn.server.resourcemanager.scheduler.capacity.ParentQueue: assignedContainer queue=root usedCapacity=0.078125 absoluteUsedCapacity=0.078125 used=<memory:5120, vCores:4> cluster=<memory:65536, vCores:64>
2014-05-05 12:38:17,266 INFO org.apache.hadoop.yarn.server.resourcemanager.rmcontainer.RMContainerImpl: container_1399292339232_0002_01_000032 Container Transitioned from NEW to ALLOCATED
2014-05-05 12:38:17,266 INFO org.apache.hadoop.yarn.server.resourcemanager.RMAuditLogger: USER=ubuntu	OPERATION=AM Allocated Container	TARGET=SchedulerApp	RESULT=SUCCESS	APPID=application_1399292339232_0002	CONTAINERID=container_1399292339232_0002_01_000032
2014-05-05 12:38:17,266 INFO org.apache.hadoop.yarn.server.resourcemanager.scheduler.common.fica.FiCaSchedulerNode: Assigned container container_1399292339232_0002_01_000032 of capacity <memory:1024, vCores:1> on host nodeb:48885, which currently has 1 containers, <memory:1024, vCores:1> used and <memory:7168, vCores:7> available
2014-05-05 12:38:17,266 INFO org.apache.hadoop.yarn.server.resourcemanager.scheduler.capacity.LeafQueue: assignedContainer application=application_1399292339232_0002 container=Container: [ContainerId: container_1399292339232_0002_01_000032, NodeId: nodeb:48885, NodeHttpAddress: nodeb:8042, Resource: <memory:1024, vCores:1>, Priority: 10, Token: Token { kind: ContainerToken, service: 10.0.0.194:48885 }, ] containerId=container_1399292339232_0002_01_000032 queue=default: capacity=1.0, absoluteCapacity=1.0, usedResources=<memory:5120, vCores:4>usedCapacity=0.078125, absoluteUsedCapacity=0.078125, numApps=1, numContainers=4 usedCapacity=0.078125 absoluteUsedCapacity=0.078125 used=<memory:5120, vCores:4> cluster=<memory:65536, vCores:64>
2014-05-05 12:38:17,266 INFO org.apache.hadoop.yarn.server.resourcemanager.scheduler.capacity.ParentQueue: Re-sorting assigned queue: root.default stats: default: capacity=1.0, absoluteCapacity=1.0, usedResources=<memory:6144, vCores:5>usedCapacity=0.09375, absoluteUsedCapacity=0.09375, numApps=1, numContainers=5
2014-05-05 12:38:17,266 INFO org.apache.hadoop.yarn.server.resourcemanager.scheduler.capacity.ParentQueue: assignedContainer queue=root usedCapacity=0.09375 absoluteUsedCapacity=0.09375 used=<memory:6144, vCores:5> cluster=<memory:65536, vCores:64>
2014-05-05 12:38:17,284 INFO org.apache.hadoop.yarn.server.resourcemanager.rmcontainer.RMContainerImpl: container_1399292339232_0002_01_000033 Container Transitioned from NEW to ALLOCATED
2014-05-05 12:38:17,284 INFO org.apache.hadoop.yarn.server.resourcemanager.RMAuditLogger: USER=ubuntu	OPERATION=AM Allocated Container	TARGET=SchedulerApp	RESULT=SUCCESS	APPID=application_1399292339232_0002	CONTAINERID=container_1399292339232_0002_01_000033
2014-05-05 12:38:17,284 INFO org.apache.hadoop.yarn.server.resourcemanager.scheduler.common.fica.FiCaSchedulerNode: Assigned container container_1399292339232_0002_01_000033 of capacity <memory:1024, vCores:1> on host nodeh:46599, which currently has 1 containers, <memory:1024, vCores:1> used and <memory:7168, vCores:7> available
2014-05-05 12:38:17,284 INFO org.apache.hadoop.yarn.server.resourcemanager.scheduler.capacity.LeafQueue: assignedContainer application=application_1399292339232_0002 container=Container: [ContainerId: container_1399292339232_0002_01_000033, NodeId: nodeh:46599, NodeHttpAddress: nodeh:8042, Resource: <memory:1024, vCores:1>, Priority: 10, Token: Token { kind: ContainerToken, service: 10.0.0.197:46599 }, ] containerId=container_1399292339232_0002_01_000033 queue=default: capacity=1.0, absoluteCapacity=1.0, usedResources=<memory:6144, vCores:5>usedCapacity=0.09375, absoluteUsedCapacity=0.09375, numApps=1, numContainers=5 usedCapacity=0.09375 absoluteUsedCapacity=0.09375 used=<memory:6144, vCores:5> cluster=<memory:65536, vCores:64>
2014-05-05 12:38:17,284 INFO org.apache.hadoop.yarn.server.resourcemanager.scheduler.capacity.ParentQueue: Re-sorting assigned queue: root.default stats: default: capacity=1.0, absoluteCapacity=1.0, usedResources=<memory:7168, vCores:6>usedCapacity=0.109375, absoluteUsedCapacity=0.109375, numApps=1, numContainers=6
2014-05-05 12:38:17,284 INFO org.apache.hadoop.yarn.server.resourcemanager.scheduler.capacity.ParentQueue: assignedContainer queue=root usedCapacity=0.109375 absoluteUsedCapacity=0.109375 used=<memory:7168, vCores:6> cluster=<memory:65536, vCores:64>
2014-05-05 12:38:17,286 INFO org.apache.hadoop.yarn.server.resourcemanager.rmcontainer.RMContainerImpl: container_1399292339232_0002_01_000034 Container Transitioned from NEW to ALLOCATED
2014-05-05 12:38:17,286 INFO org.apache.hadoop.yarn.server.resourcemanager.RMAuditLogger: USER=ubuntu	OPERATION=AM Allocated Container	TARGET=SchedulerApp	RESULT=SUCCESS	APPID=application_1399292339232_0002	CONTAINERID=container_1399292339232_0002_01_000034
2014-05-05 12:38:17,286 INFO org.apache.hadoop.yarn.server.resourcemanager.scheduler.common.fica.FiCaSchedulerNode: Assigned container container_1399292339232_0002_01_000034 of capacity <memory:1024, vCores:1> on host nodef:54669, which currently has 1 containers, <memory:1024, vCores:1> used and <memory:7168, vCores:7> available
2014-05-05 12:38:17,286 INFO org.apache.hadoop.yarn.server.resourcemanager.scheduler.capacity.LeafQueue: assignedContainer application=application_1399292339232_0002 container=Container: [ContainerId: container_1399292339232_0002_01_000034, NodeId: nodef:54669, NodeHttpAddress: nodef:8042, Resource: <memory:1024, vCores:1>, Priority: 10, Token: Token { kind: ContainerToken, service: 10.0.0.199:54669 }, ] containerId=container_1399292339232_0002_01_000034 queue=default: capacity=1.0, absoluteCapacity=1.0, usedResources=<memory:7168, vCores:6>usedCapacity=0.109375, absoluteUsedCapacity=0.109375, numApps=1, numContainers=6 usedCapacity=0.109375 absoluteUsedCapacity=0.109375 used=<memory:7168, vCores:6> cluster=<memory:65536, vCores:64>
2014-05-05 12:38:17,287 INFO org.apache.hadoop.yarn.server.resourcemanager.scheduler.capacity.ParentQueue: Re-sorting assigned queue: root.default stats: default: capacity=1.0, absoluteCapacity=1.0, usedResources=<memory:8192, vCores:7>usedCapacity=0.125, absoluteUsedCapacity=0.125, numApps=1, numContainers=7
2014-05-05 12:38:17,287 INFO org.apache.hadoop.yarn.server.resourcemanager.scheduler.capacity.ParentQueue: assignedContainer queue=root usedCapacity=0.125 absoluteUsedCapacity=0.125 used=<memory:8192, vCores:7> cluster=<memory:65536, vCores:64>
2014-05-05 12:38:17,363 INFO org.apache.hadoop.yarn.server.resourcemanager.rmcontainer.RMContainerImpl: container_1399292339232_0002_01_000029 Container Transitioned from ALLOCATED to ACQUIRED
2014-05-05 12:38:17,363 INFO org.apache.hadoop.yarn.server.resourcemanager.rmcontainer.RMContainerImpl: container_1399292339232_0002_01_000030 Container Transitioned from ALLOCATED to ACQUIRED
2014-05-05 12:38:17,363 INFO org.apache.hadoop.yarn.server.resourcemanager.rmcontainer.RMContainerImpl: container_1399292339232_0002_01_000031 Container Transitioned from ALLOCATED to ACQUIRED
2014-05-05 12:38:17,364 INFO org.apache.hadoop.yarn.server.resourcemanager.rmcontainer.RMContainerImpl: container_1399292339232_0002_01_000032 Container Transitioned from ALLOCATED to ACQUIRED
2014-05-05 12:38:17,364 INFO org.apache.hadoop.yarn.server.resourcemanager.rmcontainer.RMContainerImpl: container_1399292339232_0002_01_000033 Container Transitioned from ALLOCATED to ACQUIRED
2014-05-05 12:38:17,364 INFO org.apache.hadoop.yarn.server.resourcemanager.rmcontainer.RMContainerImpl: container_1399292339232_0002_01_000034 Container Transitioned from ALLOCATED to ACQUIRED
2014-05-05 12:38:17,423 INFO org.apache.hadoop.yarn.server.resourcemanager.rmcontainer.RMContainerImpl: container_1399292339232_0002_01_000029 Container Transitioned from ACQUIRED to RUNNING
2014-05-05 12:38:17,451 INFO org.apache.hadoop.yarn.server.resourcemanager.rmcontainer.RMContainerImpl: container_1399292339232_0002_01_000030 Container Transitioned from ACQUIRED to RUNNING
2014-05-05 12:38:18,236 INFO org.apache.hadoop.yarn.server.resourcemanager.rmcontainer.RMContainerImpl: container_1399292339232_0002_01_000031 Container Transitioned from ACQUIRED to RUNNING
2014-05-05 12:38:18,268 INFO org.apache.hadoop.yarn.server.resourcemanager.rmcontainer.RMContainerImpl: container_1399292339232_0002_01_000032 Container Transitioned from ACQUIRED to RUNNING
2014-05-05 12:38:18,287 INFO org.apache.hadoop.yarn.server.resourcemanager.rmcontainer.RMContainerImpl: container_1399292339232_0002_01_000033 Container Transitioned from ACQUIRED to RUNNING
2014-05-05 12:38:18,288 INFO org.apache.hadoop.yarn.server.resourcemanager.rmcontainer.RMContainerImpl: container_1399292339232_0002_01_000034 Container Transitioned from ACQUIRED to RUNNING
2014-05-05 12:38:18,369 INFO org.apache.hadoop.yarn.server.resourcemanager.scheduler.AppSchedulingInfo: checking for deactivate... 
2014-05-05 12:38:24,438 INFO org.apache.hadoop.yarn.server.resourcemanager.rmcontainer.RMContainerImpl: container_1399292339232_0002_01_000035 Container Transitioned from NEW to ALLOCATED
2014-05-05 12:38:24,438 INFO org.apache.hadoop.yarn.server.resourcemanager.RMAuditLogger: USER=ubuntu	OPERATION=AM Allocated Container	TARGET=SchedulerApp	RESULT=SUCCESS	APPID=application_1399292339232_0002	CONTAINERID=container_1399292339232_0002_01_000035
2014-05-05 12:38:24,438 INFO org.apache.hadoop.yarn.server.resourcemanager.scheduler.common.fica.FiCaSchedulerNode: Assigned container container_1399292339232_0002_01_000035 of capacity <memory:1024, vCores:1> on host nodec:35478, which currently has 2 containers, <memory:2048, vCores:2> used and <memory:6144, vCores:6> available
2014-05-05 12:38:24,438 INFO org.apache.hadoop.yarn.server.resourcemanager.scheduler.capacity.LeafQueue: assignedContainer application=application_1399292339232_0002 container=Container: [ContainerId: container_1399292339232_0002_01_000035, NodeId: nodec:35478, NodeHttpAddress: nodec:8042, Resource: <memory:1024, vCores:1>, Priority: 10, Token: Token { kind: ContainerToken, service: 10.0.0.200:35478 }, ] containerId=container_1399292339232_0002_01_000035 queue=default: capacity=1.0, absoluteCapacity=1.0, usedResources=<memory:8192, vCores:7>usedCapacity=0.125, absoluteUsedCapacity=0.125, numApps=1, numContainers=7 usedCapacity=0.125 absoluteUsedCapacity=0.125 used=<memory:8192, vCores:7> cluster=<memory:65536, vCores:64>
2014-05-05 12:38:24,439 INFO org.apache.hadoop.yarn.server.resourcemanager.scheduler.capacity.ParentQueue: Re-sorting assigned queue: root.default stats: default: capacity=1.0, absoluteCapacity=1.0, usedResources=<memory:9216, vCores:8>usedCapacity=0.140625, absoluteUsedCapacity=0.140625, numApps=1, numContainers=8
2014-05-05 12:38:24,439 INFO org.apache.hadoop.yarn.server.resourcemanager.scheduler.capacity.ParentQueue: assignedContainer queue=root usedCapacity=0.140625 absoluteUsedCapacity=0.140625 used=<memory:9216, vCores:8> cluster=<memory:65536, vCores:64>
2014-05-05 12:38:25,384 INFO org.apache.hadoop.yarn.server.resourcemanager.rmcontainer.RMContainerImpl: container_1399292339232_0002_01_000035 Container Transitioned from ALLOCATED to ACQUIRED
2014-05-05 12:38:25,441 INFO org.apache.hadoop.yarn.server.resourcemanager.rmcontainer.RMContainerImpl: container_1399292339232_0002_01_000035 Container Transitioned from ACQUIRED to RUNNING
2014-05-05 12:38:26,388 INFO org.apache.hadoop.yarn.server.resourcemanager.scheduler.AppSchedulingInfo: checking for deactivate... 
2014-05-05 12:38:57,801 INFO org.apache.hadoop.yarn.server.webproxy.WebAppProxyServlet: dr.who is accessing unchecked http://ip-10-0-0-193:44754/mapreduce/job/job_1399292339232_0002 which is the app master GUI of application_1399292339232_0002 owned by ubuntu
2014-05-05 12:38:58,082 INFO org.apache.hadoop.yarn.server.webproxy.WebAppProxyServlet: dr.who is accessing unchecked http://ip-10-0-0-193:44754/static/jquery/jquery-ui-1.9.1.custom.min.js which is the app master GUI of application_1399292339232_0002 owned by ubuntu
2014-05-05 12:38:58,084 INFO org.apache.hadoop.yarn.server.webproxy.WebAppProxyServlet: dr.who is accessing unchecked http://ip-10-0-0-193:44754/static/jquery/themes-1.9.1/base/jquery-ui.css which is the app master GUI of application_1399292339232_0002 owned by ubuntu
2014-05-05 12:38:58,084 INFO org.apache.hadoop.yarn.server.webproxy.WebAppProxyServlet: dr.who is accessing unchecked http://ip-10-0-0-193:44754/static/dt-1.9.4/js/jquery.dataTables.min.js which is the app master GUI of application_1399292339232_0002 owned by ubuntu
2014-05-05 12:38:58,085 INFO org.apache.hadoop.yarn.server.webproxy.WebAppProxyServlet: dr.who is accessing unchecked http://ip-10-0-0-193:44754/static/dt-1.9.4/css/jui-dt.css which is the app master GUI of application_1399292339232_0002 owned by ubuntu
2014-05-05 12:38:58,082 INFO org.apache.hadoop.yarn.server.webproxy.WebAppProxyServlet: dr.who is accessing unchecked http://ip-10-0-0-193:44754/static/jquery/jquery-1.8.2.min.js which is the app master GUI of application_1399292339232_0002 owned by ubuntu
2014-05-05 12:38:58,088 INFO org.apache.hadoop.yarn.server.webproxy.WebAppProxyServlet: dr.who is accessing unchecked http://ip-10-0-0-193:44754/static/yarn.css which is the app master GUI of application_1399292339232_0002 owned by ubuntu
2014-05-05 12:38:58,163 INFO org.apache.hadoop.yarn.server.webproxy.WebAppProxyServlet: dr.who is accessing unchecked http://ip-10-0-0-193:44754/static/yarn.dt.plugins.js which is the app master GUI of application_1399292339232_0002 owned by ubuntu
2014-05-05 12:38:58,497 INFO org.apache.hadoop.yarn.server.webproxy.WebAppProxyServlet: dr.who is accessing unchecked http://ip-10-0-0-193:44754/static/jquery/themes-1.9.1/base/images/ui-bg_glass_95_fef1ec_1x400.png which is the app master GUI of application_1399292339232_0002 owned by ubuntu
2014-05-05 12:38:58,498 INFO org.apache.hadoop.yarn.server.webproxy.WebAppProxyServlet: dr.who is accessing unchecked http://ip-10-0-0-193:44754/static/jquery/themes-1.9.1/base/images/ui-bg_flat_75_ffffff_40x100.png which is the app master GUI of application_1399292339232_0002 owned by ubuntu
2014-05-05 12:38:58,505 INFO org.apache.hadoop.yarn.server.webproxy.WebAppProxyServlet: dr.who is accessing unchecked http://ip-10-0-0-193:44754/static/jquery/themes-1.9.1/base/images/ui-bg_highlight-soft_75_cccccc_1x100.png which is the app master GUI of application_1399292339232_0002 owned by ubuntu
2014-05-05 12:38:58,505 INFO org.apache.hadoop.yarn.server.webproxy.WebAppProxyServlet: dr.who is accessing unchecked http://ip-10-0-0-193:44754/static/jquery/themes-1.9.1/base/images/ui-bg_glass_75_e6e6e6_1x400.png which is the app master GUI of application_1399292339232_0002 owned by ubuntu
2014-05-05 12:38:58,516 INFO org.apache.hadoop.yarn.server.webproxy.WebAppProxyServlet: dr.who is accessing unchecked http://ip-10-0-0-193:44754/static/jquery/themes-1.9.1/base/images/ui-bg_glass_65_ffffff_1x400.png which is the app master GUI of application_1399292339232_0002 owned by ubuntu
2014-05-05 12:38:58,519 INFO org.apache.hadoop.yarn.server.webproxy.WebAppProxyServlet: dr.who is accessing unchecked http://ip-10-0-0-193:44754/static/jquery/themes-1.9.1/base/images/ui-icons_888888_256x240.png which is the app master GUI of application_1399292339232_0002 owned by ubuntu
2014-05-05 12:38:58,575 INFO org.apache.hadoop.yarn.server.webproxy.WebAppProxyServlet: dr.who is accessing unchecked http://ip-10-0-0-193:44754/static/jquery/themes-1.9.1/base/images/ui-icons_454545_256x240.png which is the app master GUI of application_1399292339232_0002 owned by ubuntu
2014-05-05 12:39:07,692 INFO org.apache.hadoop.yarn.server.resourcemanager.rmcontainer.RMContainerImpl: container_1399292339232_0002_01_000030 Container Transitioned from RUNNING to COMPLETED
2014-05-05 12:39:07,692 INFO org.apache.hadoop.yarn.server.resourcemanager.scheduler.common.fica.FiCaSchedulerApp: Completed container: container_1399292339232_0002_01_000030 in state: COMPLETED event:FINISHED
2014-05-05 12:39:07,692 INFO org.apache.hadoop.yarn.server.resourcemanager.RMAuditLogger: USER=ubuntu	OPERATION=AM Released Container	TARGET=SchedulerApp	RESULT=SUCCESS	APPID=application_1399292339232_0002	CONTAINERID=container_1399292339232_0002_01_000030
2014-05-05 12:39:07,693 INFO org.apache.hadoop.yarn.server.resourcemanager.scheduler.common.fica.FiCaSchedulerNode: Released container container_1399292339232_0002_01_000030 of capacity <memory:1024, vCores:1> on host noded:39305, which currently has 1 containers, <memory:2048, vCores:1> used and <memory:6144, vCores:7> available, release resources=true
2014-05-05 12:39:07,693 INFO org.apache.hadoop.yarn.server.resourcemanager.scheduler.capacity.LeafQueue: default used=<memory:8192, vCores:7> numContainers=7 user=ubuntu user-resources=<memory:8192, vCores:7>
2014-05-05 12:39:07,693 INFO org.apache.hadoop.yarn.server.resourcemanager.scheduler.capacity.LeafQueue: completedContainer container=Container: [ContainerId: container_1399292339232_0002_01_000030, NodeId: noded:39305, NodeHttpAddress: noded:8042, Resource: <memory:1024, vCores:1>, Priority: 10, Token: Token { kind: ContainerToken, service: 10.0.0.193:39305 }, ] resource=<memory:1024, vCores:1> queue=default: capacity=1.0, absoluteCapacity=1.0, usedResources=<memory:8192, vCores:7>usedCapacity=0.125, absoluteUsedCapacity=0.125, numApps=1, numContainers=7 usedCapacity=0.125 absoluteUsedCapacity=0.125 used=<memory:8192, vCores:7> cluster=<memory:65536, vCores:64>
2014-05-05 12:39:07,693 INFO org.apache.hadoop.yarn.server.resourcemanager.scheduler.capacity.ParentQueue: completedContainer queue=root usedCapacity=0.125 absoluteUsedCapacity=0.125 used=<memory:8192, vCores:7> cluster=<memory:65536, vCores:64>
2014-05-05 12:39:07,693 INFO org.apache.hadoop.yarn.server.resourcemanager.scheduler.capacity.ParentQueue: Re-sorting completed queue: root.default stats: default: capacity=1.0, absoluteCapacity=1.0, usedResources=<memory:8192, vCores:7>usedCapacity=0.125, absoluteUsedCapacity=0.125, numApps=1, numContainers=7
2014-05-05 12:39:07,693 INFO org.apache.hadoop.yarn.server.resourcemanager.scheduler.capacity.CapacityScheduler: Application appattempt_1399292339232_0002_000001 released container container_1399292339232_0002_01_000030 on node: host: noded:39305 #containers=1 available=6144 used=2048 with event: FINISHED
2014-05-05 12:39:08,059 INFO org.apache.hadoop.yarn.server.resourcemanager.rmapp.attempt.RMAppAttemptImpl: appattempt_1399292339232_0002_000001 State change from RUNNING to FINISHING
2014-05-05 12:39:08,059 INFO org.apache.hadoop.yarn.server.resourcemanager.rmapp.RMAppImpl: Removing application with id application_1399292339232_0002
2014-05-05 12:39:08,059 INFO org.apache.hadoop.yarn.server.resourcemanager.rmapp.RMAppImpl: application_1399292339232_0002 State change from RUNNING to REMOVING
2014-05-05 12:39:08,059 INFO org.apache.hadoop.yarn.server.resourcemanager.recovery.RMStateStore: Removing info for app: application_1399292339232_0002
2014-05-05 12:39:08,059 INFO org.apache.hadoop.yarn.server.resourcemanager.rmapp.RMAppImpl: application_1399292339232_0002 State change from REMOVING to FINISHING
2014-05-05 12:39:08,678 INFO org.apache.hadoop.yarn.server.resourcemanager.rmcontainer.RMContainerImpl: container_1399292339232_0002_01_000033 Container Transitioned from RUNNING to COMPLETED
2014-05-05 12:39:08,678 INFO org.apache.hadoop.yarn.server.resourcemanager.scheduler.common.fica.FiCaSchedulerApp: Completed container: container_1399292339232_0002_01_000033 in state: COMPLETED event:FINISHED
2014-05-05 12:39:08,678 INFO org.apache.hadoop.yarn.server.resourcemanager.RMAuditLogger: USER=ubuntu	OPERATION=AM Released Container	TARGET=SchedulerApp	RESULT=SUCCESS	APPID=application_1399292339232_0002	CONTAINERID=container_1399292339232_0002_01_000033
2014-05-05 12:39:08,678 INFO org.apache.hadoop.yarn.server.resourcemanager.scheduler.common.fica.FiCaSchedulerNode: Released container container_1399292339232_0002_01_000033 of capacity <memory:1024, vCores:1> on host nodeh:46599, which currently has 0 containers, <memory:0, vCores:0> used and <memory:8192, vCores:8> available, release resources=true
2014-05-05 12:39:08,678 INFO org.apache.hadoop.yarn.server.resourcemanager.scheduler.capacity.LeafQueue: default used=<memory:7168, vCores:6> numContainers=6 user=ubuntu user-resources=<memory:7168, vCores:6>
2014-05-05 12:39:08,678 INFO org.apache.hadoop.yarn.server.resourcemanager.scheduler.capacity.LeafQueue: completedContainer container=Container: [ContainerId: container_1399292339232_0002_01_000033, NodeId: nodeh:46599, NodeHttpAddress: nodeh:8042, Resource: <memory:1024, vCores:1>, Priority: 10, Token: Token { kind: ContainerToken, service: 10.0.0.197:46599 }, ] resource=<memory:1024, vCores:1> queue=default: capacity=1.0, absoluteCapacity=1.0, usedResources=<memory:7168, vCores:6>usedCapacity=0.109375, absoluteUsedCapacity=0.109375, numApps=1, numContainers=6 usedCapacity=0.109375 absoluteUsedCapacity=0.109375 used=<memory:7168, vCores:6> cluster=<memory:65536, vCores:64>
2014-05-05 12:39:08,678 INFO org.apache.hadoop.yarn.server.resourcemanager.scheduler.capacity.ParentQueue: completedContainer queue=root usedCapacity=0.109375 absoluteUsedCapacity=0.109375 used=<memory:7168, vCores:6> cluster=<memory:65536, vCores:64>
2014-05-05 12:39:08,678 INFO org.apache.hadoop.yarn.server.resourcemanager.scheduler.capacity.ParentQueue: Re-sorting completed queue: root.default stats: default: capacity=1.0, absoluteCapacity=1.0, usedResources=<memory:7168, vCores:6>usedCapacity=0.109375, absoluteUsedCapacity=0.109375, numApps=1, numContainers=6
2014-05-05 12:39:08,678 INFO org.apache.hadoop.yarn.server.resourcemanager.scheduler.capacity.CapacityScheduler: Application appattempt_1399292339232_0002_000001 released container container_1399292339232_0002_01_000033 on node: host: nodeh:46599 #containers=0 available=8192 used=0 with event: FINISHED
2014-05-05 12:39:08,685 INFO org.apache.hadoop.yarn.server.resourcemanager.rmcontainer.RMContainerImpl: container_1399292339232_0002_01_000029 Container Transitioned from RUNNING to COMPLETED
2014-05-05 12:39:08,685 INFO org.apache.hadoop.yarn.server.resourcemanager.scheduler.common.fica.FiCaSchedulerApp: Completed container: container_1399292339232_0002_01_000029 in state: COMPLETED event:FINISHED
2014-05-05 12:39:08,685 INFO org.apache.hadoop.yarn.server.resourcemanager.RMAuditLogger: USER=ubuntu	OPERATION=AM Released Container	TARGET=SchedulerApp	RESULT=SUCCESS	APPID=application_1399292339232_0002	CONTAINERID=container_1399292339232_0002_01_000029
2014-05-05 12:39:08,685 INFO org.apache.hadoop.yarn.server.resourcemanager.scheduler.common.fica.FiCaSchedulerNode: Released container container_1399292339232_0002_01_000029 of capacity <memory:1024, vCores:1> on host nodec:35478, which currently has 1 containers, <memory:1024, vCores:1> used and <memory:7168, vCores:7> available, release resources=true
2014-05-05 12:39:08,685 INFO org.apache.hadoop.yarn.server.resourcemanager.scheduler.capacity.LeafQueue: default used=<memory:6144, vCores:5> numContainers=5 user=ubuntu user-resources=<memory:6144, vCores:5>
2014-05-05 12:39:08,685 INFO org.apache.hadoop.yarn.server.resourcemanager.scheduler.capacity.LeafQueue: completedContainer container=Container: [ContainerId: container_1399292339232_0002_01_000029, NodeId: nodec:35478, NodeHttpAddress: nodec:8042, Resource: <memory:1024, vCores:1>, Priority: 10, Token: Token { kind: ContainerToken, service: 10.0.0.200:35478 }, ] resource=<memory:1024, vCores:1> queue=default: capacity=1.0, absoluteCapacity=1.0, usedResources=<memory:6144, vCores:5>usedCapacity=0.09375, absoluteUsedCapacity=0.09375, numApps=1, numContainers=5 usedCapacity=0.09375 absoluteUsedCapacity=0.09375 used=<memory:6144, vCores:5> cluster=<memory:65536, vCores:64>
2014-05-05 12:39:08,686 INFO org.apache.hadoop.yarn.server.resourcemanager.scheduler.capacity.ParentQueue: completedContainer queue=root usedCapacity=0.09375 absoluteUsedCapacity=0.09375 used=<memory:6144, vCores:5> cluster=<memory:65536, vCores:64>
2014-05-05 12:39:08,686 INFO org.apache.hadoop.yarn.server.resourcemanager.scheduler.capacity.ParentQueue: Re-sorting completed queue: root.default stats: default: capacity=1.0, absoluteCapacity=1.0, usedResources=<memory:6144, vCores:5>usedCapacity=0.09375, absoluteUsedCapacity=0.09375, numApps=1, numContainers=5
2014-05-05 12:39:08,686 INFO org.apache.hadoop.yarn.server.resourcemanager.scheduler.capacity.CapacityScheduler: Application appattempt_1399292339232_0002_000001 released container container_1399292339232_0002_01_000029 on node: host: nodec:35478 #containers=1 available=7168 used=1024 with event: FINISHED
2014-05-05 12:39:08,686 INFO org.apache.hadoop.yarn.server.resourcemanager.rmcontainer.RMContainerImpl: container_1399292339232_0002_01_000035 Container Transitioned from RUNNING to COMPLETED
2014-05-05 12:39:08,686 INFO org.apache.hadoop.yarn.server.resourcemanager.scheduler.common.fica.FiCaSchedulerApp: Completed container: container_1399292339232_0002_01_000035 in state: COMPLETED event:FINISHED
2014-05-05 12:39:08,686 INFO org.apache.hadoop.yarn.server.resourcemanager.RMAuditLogger: USER=ubuntu	OPERATION=AM Released Container	TARGET=SchedulerApp	RESULT=SUCCESS	APPID=application_1399292339232_0002	CONTAINERID=container_1399292339232_0002_01_000035
2014-05-05 12:39:08,686 INFO org.apache.hadoop.yarn.server.resourcemanager.scheduler.common.fica.FiCaSchedulerNode: Released container container_1399292339232_0002_01_000035 of capacity <memory:1024, vCores:1> on host nodec:35478, which currently has 0 containers, <memory:0, vCores:0> used and <memory:8192, vCores:8> available, release resources=true
2014-05-05 12:39:08,686 INFO org.apache.hadoop.yarn.server.resourcemanager.scheduler.capacity.LeafQueue: default used=<memory:5120, vCores:4> numContainers=4 user=ubuntu user-resources=<memory:5120, vCores:4>
2014-05-05 12:39:08,686 INFO org.apache.hadoop.yarn.server.resourcemanager.scheduler.capacity.LeafQueue: completedContainer container=Container: [ContainerId: container_1399292339232_0002_01_000035, NodeId: nodec:35478, NodeHttpAddress: nodec:8042, Resource: <memory:1024, vCores:1>, Priority: 10, Token: Token { kind: ContainerToken, service: 10.0.0.200:35478 }, ] resource=<memory:1024, vCores:1> queue=default: capacity=1.0, absoluteCapacity=1.0, usedResources=<memory:5120, vCores:4>usedCapacity=0.078125, absoluteUsedCapacity=0.078125, numApps=1, numContainers=4 usedCapacity=0.078125 absoluteUsedCapacity=0.078125 used=<memory:5120, vCores:4> cluster=<memory:65536, vCores:64>
2014-05-05 12:39:08,686 INFO org.apache.hadoop.yarn.server.resourcemanager.scheduler.capacity.ParentQueue: completedContainer queue=root usedCapacity=0.078125 absoluteUsedCapacity=0.078125 used=<memory:5120, vCores:4> cluster=<memory:65536, vCores:64>
2014-05-05 12:39:08,686 INFO org.apache.hadoop.yarn.server.resourcemanager.scheduler.capacity.ParentQueue: Re-sorting completed queue: root.default stats: default: capacity=1.0, absoluteCapacity=1.0, usedResources=<memory:5120, vCores:4>usedCapacity=0.078125, absoluteUsedCapacity=0.078125, numApps=1, numContainers=4
2014-05-05 12:39:08,686 INFO org.apache.hadoop.yarn.server.resourcemanager.scheduler.capacity.CapacityScheduler: Application appattempt_1399292339232_0002_000001 released container container_1399292339232_0002_01_000035 on node: host: nodec:35478 #containers=0 available=8192 used=0 with event: FINISHED
2014-05-05 12:39:08,692 INFO org.apache.hadoop.yarn.server.resourcemanager.rmcontainer.RMContainerImpl: container_1399292339232_0002_01_000034 Container Transitioned from RUNNING to COMPLETED
2014-05-05 12:39:08,692 INFO org.apache.hadoop.yarn.server.resourcemanager.scheduler.common.fica.FiCaSchedulerApp: Completed container: container_1399292339232_0002_01_000034 in state: COMPLETED event:FINISHED
2014-05-05 12:39:08,692 INFO org.apache.hadoop.yarn.server.resourcemanager.RMAuditLogger: USER=ubuntu	OPERATION=AM Released Container	TARGET=SchedulerApp	RESULT=SUCCESS	APPID=application_1399292339232_0002	CONTAINERID=container_1399292339232_0002_01_000034
2014-05-05 12:39:08,692 INFO org.apache.hadoop.yarn.server.resourcemanager.scheduler.common.fica.FiCaSchedulerNode: Released container container_1399292339232_0002_01_000034 of capacity <memory:1024, vCores:1> on host nodef:54669, which currently has 0 containers, <memory:0, vCores:0> used and <memory:8192, vCores:8> available, release resources=true
2014-05-05 12:39:08,692 INFO org.apache.hadoop.yarn.server.resourcemanager.scheduler.capacity.LeafQueue: default used=<memory:4096, vCores:3> numContainers=3 user=ubuntu user-resources=<memory:4096, vCores:3>
2014-05-05 12:39:08,692 INFO org.apache.hadoop.yarn.server.resourcemanager.scheduler.capacity.LeafQueue: completedContainer container=Container: [ContainerId: container_1399292339232_0002_01_000034, NodeId: nodef:54669, NodeHttpAddress: nodef:8042, Resource: <memory:1024, vCores:1>, Priority: 10, Token: Token { kind: ContainerToken, service: 10.0.0.199:54669 }, ] resource=<memory:1024, vCores:1> queue=default: capacity=1.0, absoluteCapacity=1.0, usedResources=<memory:4096, vCores:3>usedCapacity=0.0625, absoluteUsedCapacity=0.0625, numApps=1, numContainers=3 usedCapacity=0.0625 absoluteUsedCapacity=0.0625 used=<memory:4096, vCores:3> cluster=<memory:65536, vCores:64>
2014-05-05 12:39:08,692 INFO org.apache.hadoop.yarn.server.resourcemanager.scheduler.capacity.ParentQueue: completedContainer queue=root usedCapacity=0.0625 absoluteUsedCapacity=0.0625 used=<memory:4096, vCores:3> cluster=<memory:65536, vCores:64>
2014-05-05 12:39:08,692 INFO org.apache.hadoop.yarn.server.resourcemanager.scheduler.capacity.ParentQueue: Re-sorting completed queue: root.default stats: default: capacity=1.0, absoluteCapacity=1.0, usedResources=<memory:4096, vCores:3>usedCapacity=0.0625, absoluteUsedCapacity=0.0625, numApps=1, numContainers=3
2014-05-05 12:39:08,692 INFO org.apache.hadoop.yarn.server.resourcemanager.scheduler.capacity.CapacityScheduler: Application appattempt_1399292339232_0002_000001 released container container_1399292339232_0002_01_000034 on node: host: nodef:54669 #containers=0 available=8192 used=0 with event: FINISHED
2014-05-05 12:39:08,693 INFO org.apache.hadoop.yarn.server.resourcemanager.rmcontainer.RMContainerImpl: container_1399292339232_0002_01_000031 Container Transitioned from RUNNING to COMPLETED
2014-05-05 12:39:08,693 INFO org.apache.hadoop.yarn.server.resourcemanager.scheduler.common.fica.FiCaSchedulerApp: Completed container: container_1399292339232_0002_01_000031 in state: COMPLETED event:FINISHED
2014-05-05 12:39:08,693 INFO org.apache.hadoop.yarn.server.resourcemanager.RMAuditLogger: USER=ubuntu	OPERATION=AM Released Container	TARGET=SchedulerApp	RESULT=SUCCESS	APPID=application_1399292339232_0002	CONTAINERID=container_1399292339232_0002_01_000031
2014-05-05 12:39:08,693 INFO org.apache.hadoop.yarn.server.resourcemanager.scheduler.common.fica.FiCaSchedulerNode: Released container container_1399292339232_0002_01_000031 of capacity <memory:1024, vCores:1> on host nodea:51924, which currently has 0 containers, <memory:0, vCores:0> used and <memory:8192, vCores:8> available, release resources=true
2014-05-05 12:39:08,693 INFO org.apache.hadoop.yarn.server.resourcemanager.scheduler.capacity.LeafQueue: default used=<memory:3072, vCores:2> numContainers=2 user=ubuntu user-resources=<memory:3072, vCores:2>
2014-05-05 12:39:08,694 INFO org.apache.hadoop.yarn.server.resourcemanager.scheduler.capacity.LeafQueue: completedContainer container=Container: [ContainerId: container_1399292339232_0002_01_000031, NodeId: nodea:51924, NodeHttpAddress: nodea:8042, Resource: <memory:1024, vCores:1>, Priority: 10, Token: Token { kind: ContainerToken, service: 10.0.0.195:51924 }, ] resource=<memory:1024, vCores:1> queue=default: capacity=1.0, absoluteCapacity=1.0, usedResources=<memory:3072, vCores:2>usedCapacity=0.046875, absoluteUsedCapacity=0.046875, numApps=1, numContainers=2 usedCapacity=0.046875 absoluteUsedCapacity=0.046875 used=<memory:3072, vCores:2> cluster=<memory:65536, vCores:64>
2014-05-05 12:39:08,694 INFO org.apache.hadoop.yarn.server.resourcemanager.scheduler.capacity.ParentQueue: completedContainer queue=root usedCapacity=0.046875 absoluteUsedCapacity=0.046875 used=<memory:3072, vCores:2> cluster=<memory:65536, vCores:64>
2014-05-05 12:39:08,694 INFO org.apache.hadoop.yarn.server.resourcemanager.scheduler.capacity.ParentQueue: Re-sorting completed queue: root.default stats: default: capacity=1.0, absoluteCapacity=1.0, usedResources=<memory:3072, vCores:2>usedCapacity=0.046875, absoluteUsedCapacity=0.046875, numApps=1, numContainers=2
2014-05-05 12:39:08,694 INFO org.apache.hadoop.yarn.server.resourcemanager.scheduler.capacity.CapacityScheduler: Application appattempt_1399292339232_0002_000001 released container container_1399292339232_0002_01_000031 on node: host: nodea:51924 #containers=0 available=8192 used=0 with event: FINISHED
2014-05-05 12:39:08,889 INFO org.apache.hadoop.yarn.server.resourcemanager.rmcontainer.RMContainerImpl: container_1399292339232_0002_01_000032 Container Transitioned from RUNNING to COMPLETED
2014-05-05 12:39:08,889 INFO org.apache.hadoop.yarn.server.resourcemanager.scheduler.common.fica.FiCaSchedulerApp: Completed container: container_1399292339232_0002_01_000032 in state: COMPLETED event:FINISHED
2014-05-05 12:39:08,889 INFO org.apache.hadoop.yarn.server.resourcemanager.RMAuditLogger: USER=ubuntu	OPERATION=AM Released Container	TARGET=SchedulerApp	RESULT=SUCCESS	APPID=application_1399292339232_0002	CONTAINERID=container_1399292339232_0002_01_000032
2014-05-05 12:39:08,889 INFO org.apache.hadoop.yarn.server.resourcemanager.scheduler.common.fica.FiCaSchedulerNode: Released container container_1399292339232_0002_01_000032 of capacity <memory:1024, vCores:1> on host nodeb:48885, which currently has 0 containers, <memory:0, vCores:0> used and <memory:8192, vCores:8> available, release resources=true
2014-05-05 12:39:08,889 INFO org.apache.hadoop.yarn.server.resourcemanager.scheduler.capacity.LeafQueue: default used=<memory:2048, vCores:1> numContainers=1 user=ubuntu user-resources=<memory:2048, vCores:1>
2014-05-05 12:39:08,889 INFO org.apache.hadoop.yarn.server.resourcemanager.scheduler.capacity.LeafQueue: completedContainer container=Container: [ContainerId: container_1399292339232_0002_01_000032, NodeId: nodeb:48885, NodeHttpAddress: nodeb:8042, Resource: <memory:1024, vCores:1>, Priority: 10, Token: Token { kind: ContainerToken, service: 10.0.0.194:48885 }, ] resource=<memory:1024, vCores:1> queue=default: capacity=1.0, absoluteCapacity=1.0, usedResources=<memory:2048, vCores:1>usedCapacity=0.03125, absoluteUsedCapacity=0.03125, numApps=1, numContainers=1 usedCapacity=0.03125 absoluteUsedCapacity=0.03125 used=<memory:2048, vCores:1> cluster=<memory:65536, vCores:64>
2014-05-05 12:39:08,889 INFO org.apache.hadoop.yarn.server.resourcemanager.scheduler.capacity.ParentQueue: completedContainer queue=root usedCapacity=0.03125 absoluteUsedCapacity=0.03125 used=<memory:2048, vCores:1> cluster=<memory:65536, vCores:64>
2014-05-05 12:39:08,889 INFO org.apache.hadoop.yarn.server.resourcemanager.scheduler.capacity.ParentQueue: Re-sorting completed queue: root.default stats: default: capacity=1.0, absoluteCapacity=1.0, usedResources=<memory:2048, vCores:1>usedCapacity=0.03125, absoluteUsedCapacity=0.03125, numApps=1, numContainers=1
2014-05-05 12:39:08,889 INFO org.apache.hadoop.yarn.server.resourcemanager.scheduler.capacity.CapacityScheduler: Application appattempt_1399292339232_0002_000001 released container container_1399292339232_0002_01_000032 on node: host: nodeb:48885 #containers=0 available=8192 used=0 with event: FINISHED
2014-05-05 12:39:14,703 INFO org.apache.hadoop.yarn.server.resourcemanager.rmcontainer.RMContainerImpl: container_1399292339232_0002_01_000001 Container Transitioned from RUNNING to COMPLETED
2014-05-05 12:39:14,703 INFO org.apache.hadoop.yarn.server.resourcemanager.ApplicationMasterService: Unregistering app attempt : appattempt_1399292339232_0002_000001
2014-05-05 12:39:14,703 INFO org.apache.hadoop.yarn.server.resourcemanager.scheduler.common.fica.FiCaSchedulerApp: Completed container: container_1399292339232_0002_01_000001 in state: COMPLETED event:FINISHED
2014-05-05 12:39:14,703 INFO org.apache.hadoop.yarn.server.resourcemanager.rmapp.attempt.RMAppAttemptImpl: appattempt_1399292339232_0002_000001 State change from FINISHING to FINISHED
2014-05-05 12:39:14,703 INFO org.apache.hadoop.yarn.server.resourcemanager.RMAuditLogger: USER=ubuntu	OPERATION=AM Released Container	TARGET=SchedulerApp	RESULT=SUCCESS	APPID=application_1399292339232_0002	CONTAINERID=container_1399292339232_0002_01_000001
2014-05-05 12:39:14,703 INFO org.apache.hadoop.yarn.server.resourcemanager.rmapp.RMAppImpl: application_1399292339232_0002 State change from FINISHING to FINISHED
2014-05-05 12:39:14,703 INFO org.apache.hadoop.yarn.server.resourcemanager.scheduler.common.fica.FiCaSchedulerNode: Released container container_1399292339232_0002_01_000001 of capacity <memory:2048, vCores:1> on host noded:39305, which currently has 0 containers, <memory:0, vCores:0> used and <memory:8192, vCores:8> available, release resources=true
2014-05-05 12:39:14,703 INFO org.apache.hadoop.yarn.server.resourcemanager.scheduler.capacity.LeafQueue: default used=<memory:0, vCores:0> numContainers=0 user=ubuntu user-resources=<memory:0, vCores:0>
2014-05-05 12:39:14,704 INFO org.apache.hadoop.yarn.server.resourcemanager.scheduler.capacity.LeafQueue: completedContainer container=Container: [ContainerId: container_1399292339232_0002_01_000001, NodeId: noded:39305, NodeHttpAddress: noded:8042, Resource: <memory:2048, vCores:1>, Priority: 0, Token: Token { kind: ContainerToken, service: 10.0.0.193:39305 }, ] resource=<memory:2048, vCores:1> queue=default: capacity=1.0, absoluteCapacity=1.0, usedResources=<memory:0, vCores:0>usedCapacity=0.0, absoluteUsedCapacity=0.0, numApps=1, numContainers=0 usedCapacity=0.0 absoluteUsedCapacity=0.0 used=<memory:0, vCores:0> cluster=<memory:65536, vCores:64>
2014-05-05 12:39:14,704 INFO org.apache.hadoop.yarn.server.resourcemanager.RMAuditLogger: USER=ubuntu	OPERATION=Application Finished - Succeeded	TARGET=RMAppManager	RESULT=SUCCESS	APPID=application_1399292339232_0002
2014-05-05 12:39:14,704 INFO org.apache.hadoop.yarn.server.resourcemanager.scheduler.capacity.ParentQueue: completedContainer queue=root usedCapacity=0.0 absoluteUsedCapacity=0.0 used=<memory:0, vCores:0> cluster=<memory:65536, vCores:64>
2014-05-05 12:39:14,708 INFO org.apache.hadoop.yarn.server.resourcemanager.scheduler.capacity.ParentQueue: Re-sorting completed queue: root.default stats: default: capacity=1.0, absoluteCapacity=1.0, usedResources=<memory:0, vCores:0>usedCapacity=0.0, absoluteUsedCapacity=0.0, numApps=1, numContainers=0
2014-05-05 12:39:14,708 INFO org.apache.hadoop.yarn.server.resourcemanager.scheduler.capacity.CapacityScheduler: Application appattempt_1399292339232_0002_000001 released container container_1399292339232_0002_01_000001 on node: host: noded:39305 #containers=0 available=8192 used=0 with event: FINISHED
2014-05-05 12:39:14,708 INFO org.apache.hadoop.yarn.server.resourcemanager.scheduler.capacity.CapacityScheduler: Application appattempt_1399292339232_0002_000001 is done. finalState=FINISHED
2014-05-05 12:39:14,708 INFO org.apache.hadoop.yarn.server.resourcemanager.scheduler.AppSchedulingInfo: Application application_1399292339232_0002 requests cleared
2014-05-05 12:39:14,708 INFO org.apache.hadoop.yarn.server.resourcemanager.scheduler.capacity.LeafQueue: Application removed - appId: application_1399292339232_0002 user: ubuntu queue: default #user-pending-applications: 0 #user-active-applications: 0 #queue-pending-applications: 0 #queue-active-applications: 0
2014-05-05 12:39:14,708 INFO org.apache.hadoop.yarn.server.resourcemanager.scheduler.capacity.ParentQueue: Application removed - appId: application_1399292339232_0002 user: ubuntu leaf-queue of parent: root #applications: 0
2014-05-05 12:39:14,708 INFO org.apache.hadoop.yarn.server.resourcemanager.RMAppManager$ApplicationSummary: appId=application_1399292339232_0002,name=base||path:/in1m||num reduce:8,user=ubuntu,queue=default,state=FINISHED,trackingUrl=ec2-54-186-230-200.us-west-2.compute.amazonaws.com:8088/proxy/application_1399292339232_0002/jobhistory/job/job_1399292339232_0002,appMasterHost=ip-10-0-0-193,startTime=1399293267778,finishTime=1399293548059,finalStatus=FAILED
2014-05-05 12:39:14,708 INFO org.apache.hadoop.yarn.server.resourcemanager.amlauncher.AMLauncher: Cleaning master appattempt_1399292339232_0002_000001
2014-05-05 12:44:40,345 INFO org.apache.hadoop.yarn.server.resourcemanager.ClientRMService: Allocated new applicationId: 3
2014-05-05 12:44:41,698 INFO org.apache.hadoop.yarn.server.resourcemanager.ClientRMService: Application with id 3 submitted by user ubuntu
2014-05-05 12:44:41,698 INFO org.apache.hadoop.yarn.server.resourcemanager.rmapp.RMAppImpl: Storing application with id application_1399292339232_0003
2014-05-05 12:44:41,698 INFO org.apache.hadoop.yarn.server.resourcemanager.rmapp.RMAppImpl: application_1399292339232_0003 State change from NEW to NEW_SAVING
2014-05-05 12:44:41,698 INFO org.apache.hadoop.yarn.server.resourcemanager.recovery.RMStateStore: Storing info for app: application_1399292339232_0003
2014-05-05 12:44:41,698 INFO org.apache.hadoop.yarn.server.resourcemanager.RMAuditLogger: USER=ubuntu	IP=10.0.0.195	OPERATION=Submit Application Request	TARGET=ClientRMService	RESULT=SUCCESS	APPID=application_1399292339232_0003
2014-05-05 12:44:41,700 INFO org.apache.hadoop.yarn.server.resourcemanager.rmapp.RMAppImpl: application_1399292339232_0003 State change from NEW_SAVING to SUBMITTED
2014-05-05 12:44:41,700 INFO org.apache.hadoop.yarn.server.resourcemanager.ApplicationMasterService: Registering app attempt : appattempt_1399292339232_0003_000001
2014-05-05 12:44:41,700 INFO org.apache.hadoop.yarn.server.resourcemanager.rmapp.attempt.RMAppAttemptImpl: appattempt_1399292339232_0003_000001 State change from NEW to SUBMITTED
2014-05-05 12:44:41,701 INFO org.apache.hadoop.yarn.server.resourcemanager.scheduler.capacity.LeafQueue: Application application_1399292339232_0003 from user: ubuntu activated in queue: default
2014-05-05 12:44:41,701 INFO org.apache.hadoop.yarn.server.resourcemanager.scheduler.capacity.LeafQueue: Application added - appId: application_1399292339232_0003 user: org.apache.hadoop.yarn.server.resourcemanager.scheduler.capacity.LeafQueue$User@61439efc, leaf-queue: default #user-pending-applications: 0 #user-active-applications: 1 #queue-pending-applications: 0 #queue-active-applications: 1
2014-05-05 12:44:41,701 INFO org.apache.hadoop.yarn.server.resourcemanager.scheduler.capacity.ParentQueue: Application added - appId: application_1399292339232_0003 user: ubuntu leaf-queue of parent: root #applications: 1
2014-05-05 12:44:41,701 INFO org.apache.hadoop.yarn.server.resourcemanager.scheduler.capacity.CapacityScheduler: Application Submission: appattempt_1399292339232_0003_000001, user: ubuntu queue: default: capacity=1.0, absoluteCapacity=1.0, usedResources=<memory:0, vCores:0>usedCapacity=0.0, absoluteUsedCapacity=0.0, numApps=1, numContainers=0, currently active: 1
2014-05-05 12:44:41,701 INFO org.apache.hadoop.yarn.server.resourcemanager.rmapp.attempt.RMAppAttemptImpl: appattempt_1399292339232_0003_000001 State change from SUBMITTED to SCHEDULED
2014-05-05 12:44:41,701 INFO org.apache.hadoop.yarn.server.resourcemanager.rmapp.RMAppImpl: application_1399292339232_0003 State change from SUBMITTED to ACCEPTED
2014-05-05 12:44:41,910 INFO org.apache.hadoop.yarn.server.resourcemanager.rmcontainer.RMContainerImpl: container_1399292339232_0003_01_000001 Container Transitioned from NEW to ALLOCATED
2014-05-05 12:44:41,910 INFO org.apache.hadoop.yarn.server.resourcemanager.RMAuditLogger: USER=ubuntu	OPERATION=AM Allocated Container	TARGET=SchedulerApp	RESULT=SUCCESS	APPID=application_1399292339232_0003	CONTAINERID=container_1399292339232_0003_01_000001
2014-05-05 12:44:41,910 INFO org.apache.hadoop.yarn.server.resourcemanager.scheduler.common.fica.FiCaSchedulerNode: Assigned container container_1399292339232_0003_01_000001 of capacity <memory:2048, vCores:1> on host nodee:49598, which currently has 1 containers, <memory:2048, vCores:1> used and <memory:6144, vCores:7> available
2014-05-05 12:44:41,910 INFO org.apache.hadoop.yarn.server.resourcemanager.scheduler.capacity.LeafQueue: assignedContainer application=application_1399292339232_0003 container=Container: [ContainerId: container_1399292339232_0003_01_000001, NodeId: nodee:49598, NodeHttpAddress: nodee:8042, Resource: <memory:2048, vCores:1>, Priority: 0, Token: Token { kind: ContainerToken, service: 10.0.0.198:49598 }, ] containerId=container_1399292339232_0003_01_000001 queue=default: capacity=1.0, absoluteCapacity=1.0, usedResources=<memory:0, vCores:0>usedCapacity=0.0, absoluteUsedCapacity=0.0, numApps=1, numContainers=0 usedCapacity=0.0 absoluteUsedCapacity=0.0 used=<memory:0, vCores:0> cluster=<memory:65536, vCores:64>
2014-05-05 12:44:41,910 INFO org.apache.hadoop.yarn.server.resourcemanager.scheduler.capacity.ParentQueue: Re-sorting assigned queue: root.default stats: default: capacity=1.0, absoluteCapacity=1.0, usedResources=<memory:2048, vCores:1>usedCapacity=0.03125, absoluteUsedCapacity=0.03125, numApps=1, numContainers=1
2014-05-05 12:44:41,911 INFO org.apache.hadoop.yarn.server.resourcemanager.rmcontainer.RMContainerImpl: container_1399292339232_0003_01_000001 Container Transitioned from ALLOCATED to ACQUIRED
2014-05-05 12:44:41,911 INFO org.apache.hadoop.yarn.server.resourcemanager.rmapp.attempt.RMAppAttemptImpl: Storing attempt: AppId: application_1399292339232_0003 AttemptId: appattempt_1399292339232_0003_000001 MasterContainer: Container: [ContainerId: container_1399292339232_0003_01_000001, NodeId: nodee:49598, NodeHttpAddress: nodee:8042, Resource: <memory:2048, vCores:1>, Priority: 0, Token: Token { kind: ContainerToken, service: 10.0.0.198:49598 }, ]
2014-05-05 12:44:41,911 INFO org.apache.hadoop.yarn.server.resourcemanager.rmapp.attempt.RMAppAttemptImpl: appattempt_1399292339232_0003_000001 State change from SCHEDULED to ALLOCATED_SAVING
2014-05-05 12:44:41,911 INFO org.apache.hadoop.yarn.server.resourcemanager.recovery.RMStateStore: Storing info for attempt: appattempt_1399292339232_0003_000001
2014-05-05 12:44:41,911 INFO org.apache.hadoop.yarn.server.resourcemanager.scheduler.capacity.ParentQueue: assignedContainer queue=root usedCapacity=0.03125 absoluteUsedCapacity=0.03125 used=<memory:2048, vCores:1> cluster=<memory:65536, vCores:64>
2014-05-05 12:44:41,912 INFO org.apache.hadoop.yarn.server.resourcemanager.rmapp.attempt.RMAppAttemptImpl: appattempt_1399292339232_0003_000001 State change from ALLOCATED_SAVING to ALLOCATED
2014-05-05 12:44:41,912 INFO org.apache.hadoop.yarn.server.resourcemanager.amlauncher.AMLauncher: Launching masterappattempt_1399292339232_0003_000001
2014-05-05 12:44:41,913 INFO org.apache.hadoop.yarn.server.resourcemanager.amlauncher.AMLauncher: Setting up container Container: [ContainerId: container_1399292339232_0003_01_000001, NodeId: nodee:49598, NodeHttpAddress: nodee:8042, Resource: <memory:2048, vCores:1>, Priority: 0, Token: Token { kind: ContainerToken, service: 10.0.0.198:49598 }, ] for AM appattempt_1399292339232_0003_000001
2014-05-05 12:44:41,913 INFO org.apache.hadoop.yarn.server.resourcemanager.amlauncher.AMLauncher: Command to launch container container_1399292339232_0003_01_000001 : $JAVA_HOME/bin/java -Dlog4j.configuration=container-log4j.properties -Dyarn.app.container.log.dir=<LOG_DIR> -Dyarn.app.container.log.filesize=0 -Dhadoop.root.logger=INFO,CLA  -Xmx1024m org.apache.hadoop.mapreduce.v2.app.MRAppMaster 1><LOG_DIR>/stdout 2><LOG_DIR>/stderr 
2014-05-05 12:44:41,927 INFO org.apache.hadoop.yarn.server.resourcemanager.amlauncher.AMLauncher: Done launching container Container: [ContainerId: container_1399292339232_0003_01_000001, NodeId: nodee:49598, NodeHttpAddress: nodee:8042, Resource: <memory:2048, vCores:1>, Priority: 0, Token: Token { kind: ContainerToken, service: 10.0.0.198:49598 }, ] for AM appattempt_1399292339232_0003_000001
2014-05-05 12:44:41,927 INFO org.apache.hadoop.yarn.server.resourcemanager.rmapp.attempt.RMAppAttemptImpl: appattempt_1399292339232_0003_000001 State change from ALLOCATED to LAUNCHED
2014-05-05 12:44:42,914 INFO org.apache.hadoop.yarn.server.resourcemanager.rmcontainer.RMContainerImpl: container_1399292339232_0003_01_000001 Container Transitioned from ACQUIRED to RUNNING
2014-05-05 12:44:47,575 INFO SecurityLogger.org.apache.hadoop.ipc.Server: Auth successful for appattempt_1399292339232_0003_000001 (auth:SIMPLE)
2014-05-05 12:44:47,579 INFO org.apache.hadoop.yarn.server.resourcemanager.ApplicationMasterService: AM registration appattempt_1399292339232_0003_000001
2014-05-05 12:44:47,579 INFO org.apache.hadoop.yarn.server.resourcemanager.RMAuditLogger: USER=ubuntu	IP=10.0.0.198	OPERATION=Register App Master	TARGET=ApplicationMasterService	RESULT=SUCCESS	APPID=application_1399292339232_0003	APPATTEMPTID=appattempt_1399292339232_0003_000001
